Workbook
Name \A: '[1]טורים 98'!$HJ$133
Name \B: #REF!
Name \B: #REF!
Name \B: #REF!
Name \C: '[1]טורים 98'!$HJ$154
Name \D: '[1]טורים 98'!#REF!
Name \D: '[1]טורים 98'!#REF!
Name \D: '[1]טורים 98'!#REF!
Name \E: '[1]טורים 98'!$HJ$155
Name \F: '[1]טורים 98'!$GS$2
Name \H: '[1]טורים 98'!$B$336
Name \J: '[1]טורים 98'!$HJ$164
Name \K: '[1]טורים 98'!$HJ$166
Name \L: '[1]טורים 98'!$HJ$124
Name \M: '[1]טורים 98'!$HJ$121
Name \O: '[1]טורים 98'!$HJ$144
Name \P: '[1]טורים 98'!$GT$13
Name \Q: '[1]טורים 98'!$HJ$127
Name \R: '[1]טורים 98'!$HJ$118
Name \S: '[1]טורים 98'!$HJ$151
Name \U: '[1]טורים 98'!$HJ$116
Name \W: '[1]טורים 98'!$HJ$113
Name \X: '[1]טורים 98'!$HJ$146
Name \Y: '[1]טורים 98'!$GT$6
Name \Z: '[1]טורים 98'!$HJ$129
Name _______DAT1: #REF!
Name _______DAT1: #REF!
Name _______DAT1: #REF!
Name _______DAT10: #REF!
Name _______DAT10: #REF!
Name _______DAT10: #REF!
Name _______DAT11: #REF!
Name _______DAT11: #REF!
Name _______DAT11: #REF!
Name _______DAT12: #REF!
Name _______DAT12: #REF!
Name _______DAT12: #REF!
Name _______DAT13: #REF!
Name _______DAT13: #REF!
Name _______DAT13: #REF!
Name _______DAT14: #REF!
Name _______DAT14: #REF!
Name _______DAT14: #REF!
Name _______DAT15: #REF!
Name _______DAT15: #REF!
Name _______DAT15: #REF!
Name _______DAT2: #REF!
Name _______DAT2: #REF!
Name _______DAT2: #REF!
Name _______DAT3: #REF!
Name _______DAT3: #REF!
Name _______DAT3: #REF!
Name _______DAT4: #REF!
Name _______DAT4: #REF!
Name _______DAT4: #REF!
Name _______DAT5: #REF!
Name _______DAT5: #REF!
Name _______DAT5: #REF!
Name _______DAT6: #REF!
Name _______DAT6: #REF!

Sheet BS
B2: (IL) Ltd | C2: INC | D2: Consolidated | G2: s (IL) Ltd
B3: U S D O L L A R S | G3: Shekels | I3: הערת חשב
A4: Current Assets
A5: Cash & cash equivalents ISRAEL | B5: =SUMIF('TB - Ltd'!C:C,A5,'TB - Ltd'!J:J) -> 95452260 | C5: =SUMIF('TB - Inc'!C:C,A5,'TB - Inc'!F:F) -> 0 | D5: =SUM(B5:C5) -> 95452260 | G5: =SUMIF('TB - Ltd'!C:C,A5,'TB - Ltd'!G:G) -> 3.4620535e+08 | H5: =G5/B5 -> 3.627 | I5: אישורי יתרה
A6: Cash & cash equivalents US | B6: =SUMIF('TB - Ltd'!C:C,A6,'TB - Ltd'!J:J) -> 0 | C6: =SUMIF('TB - Inc'!C:C,A6,'TB - Inc'!F:F) -> 973689.67 | D6: =SUM(B6:C6) -> 973689.67 | G6: =SUMIF('TB - Ltd'!C:C,A6,'TB - Ltd'!G:G) -> 0
A7: Accounts receivable | B7: =SUMIF('TB - Ltd'!C:C,A7,'TB - Ltd'!J:J) -> 114017.44 | C7: =SUMIF('TB - Inc'!C:C,A7,'TB - Inc'!F:F) -> 808996.95 | D7: =SUM(B7:C7) -> 923014.39 | G7: =SUMIF('TB - Ltd'!C:C,A7,'TB - Ltd'!G:G) -> 413541.27 | H7: =G7/B7 -> 3.6270001 | I7: גיול לקוחות
A8: Accounts receivable - Sublease | B8: =SUMIF('TB - Ltd'!C:C,A8,'TB - Ltd'!J:J) -> 48986.45 | C8: =SUMIF('TB - Inc'!C:C,A8,'TB - Inc'!F:F) -> 0 | D8: =SUM(B8:C8) -> 48986.45 | G8: =SUMIF('TB - Ltd'!C:C,A8,'TB - Ltd'!G:G) -> 177673.86 | I8: יתרות משכירות משנה
A9: Prepaid Expenses | B9: =SUMIF('TB - Ltd'!C:C,A9,'TB - Ltd'!J:J) -> 362325.82 | C9: =SUMIF('TB - Inc'!C:C,A9,'TB - Inc'!F:F) -> 36085.73 | D9: =SUM(B9:C9) -> 398411.55 | G9: =SUMIF('TB - Ltd'!C:C,A9,'TB - Ltd'!G:G) -> 1365414.8 | H9: =G9/B9 -> 3.7684724 | I9: הרכב
A10: Intercompany | B10: =SUMIF('TB - Ltd'!C:C,A10,'TB - Ltd'!J:J) -> 531531.97 | C10: =SUMIF('TB - Inc'!C:C,A10,'TB - Inc'!F:F) -> -531532.06 | D10: =SUM(B10:C10) -> -0.088104535 | G10: =SUMIF('TB - Ltd'!C:C,A10,'TB - Ltd'!G:G) -> 1159373.9 | H10: =G10/B10 -> 2.1811931 | I10: מצורף חישוב בינחברתי
A11: Other Current Assets | B11: =SUMIF('TB - Ltd'!C:C,A11,'TB - Ltd'!J:J) -> 496783.84 | C11: =SUMIF('TB - Inc'!C:C,A11,'TB - Inc'!F:F) -> 0 | D11: =SUM(B11:C11) -> 496783.84 | G11: =SUMIF('TB - Ltd'!C:C,A11,'TB - Ltd'!G:G) -> 1801835 | H11: =G11/B11 -> 3.627 | I11: מע"מ - נובמבר+דצמבר ,מצורף אישור דיווח
A12: Total Current Assets | B12: =SUM(B5:B11) -> 97005905 | C12: =SUM(C5:C11) -> 1287240.3 | D12: =SUM(D5:D11) -> 98293145 | G12: =SUM(G5:G11) -> 3.5112318e+08 | I12: מצורף נייר ניכוי מס מפקדונות + פקדון DEEL
A14: Fixed Assets
A15: Short term bank credit | B15: =SUMIF('TB - Ltd'!#REF!,BS!#REF!,'TB - Ltd'!$J$4:$J$153) -> #REF! | C15: =SUMIF('TB - Inc'!#REF!,BS!#REF!,'TB - Inc'!#REF!) -> #REF! | D15: =SUM(B15:C15) -> #REF! | G15: =SUMIF('TB - Ltd'!#REF!,BS!#REF!,'TB - Ltd'!$G$4:$G$139) -> #REF!
A16: Computer equipment & software | B16: =SUMIF('TB - Ltd'!C:C,A16,'TB - Ltd'!J:J) -> 425011.87 | C16: =SUMIF('TB - Inc'!C:C,A16,'TB - Inc'!F:F) -> 57005.59 | D16: =SUM(B16:C16) -> 482017.46 | G16: =SUMIF('TB - Ltd'!C:C,A16,'TB - Ltd'!G:G) -> 1455299.6 | H16: =G16/B16 -> 3.4241388 | I16: טופס פחת מפורט
A17: Office furniture and equipment | B17: =SUMIF('TB - Ltd'!C:C,A17,'TB - Ltd'!J:J) -> 206676.16 | C17: =SUMIF('TB - Inc'!C:C,A17,'TB - Inc'!F:F) -> 0 | D17: =SUM(B17:C17) -> 206676.16 | G17: =SUMIF('TB - Ltd'!C:C,A17,'TB - Ltd'!G:G) -> 697676.2 | H17: =G17/B17 -> 3.3756975
A18: Lab equipments | B18: =SUMIF('TB - Ltd'!C:C,A18,'TB - Ltd'!J:J) -> 0 | C18: =SUMIF('TB - Inc'!C:C,A18,'TB - Inc'!F:F) -> 0 | D18: =SUM(B18:C18) -> 0 | G18: =SUMIF('TB - Ltd'!C:C,A18,'TB - Ltd'!G:G) -> 0
A19: Leasehold Improvements | B19: =SUMIF('TB - Ltd'!C:C,A19,'TB - Ltd'!J:J) -> 451119.09 | C19: =SUMIF('TB - Inc'!C:C,A19,'TB - Inc'!F:F) -> 0 | D19: =SUM(B19:C19) -> 451119.09 | G19: =SUMIF('TB - Ltd'!C:C,A19,'TB - Ltd'!G:G) -> 1529963.2 | H19: =G19/B19 -> 3.3914841
A20: Less accumulated depreciation | B20: =SUMIF('TB - Ltd'!C:C,A20,'TB - Ltd'!J:J) -> -281400.98 | C20: =SUMIF('TB - Inc'!C:C,A20,'TB - Inc'!F:F) -> -17730.99 | D20: =SUM(B20:C20) -> -299131.97 | G20: =SUMIF('TB - Ltd'!C:C,A20,'TB - Ltd'!G:G) -> -938083.8 | H20: =G20/B20 -> 3.3336195
A21: Total Fixed assets | B21: =SUM(B16:B20) -> 801406.14 | C21: =SUM(C16:C20) -> 39274.6 | D21: =SUM(D16:D20) -> 840680.74 | G21: =SUM(G16:G20) -> 2744855.2
A23: Other Long term Assets
A24: Operating lease ROU asset | B24: =SUMIF('TB - Ltd'!C:C,A24,'TB - Ltd'!J:J) -> 0 | C24: =SUMIF('TB - Inc'!C:C,A24,'TB - Inc'!F:F) -> 0 | D24: =SUM(B24:C24) -> 0 | G24: =SUMIF('TB - Ltd'!C:C,A24,'TB - Ltd'!G:G) -> 0
A25: Investment in subsidiary | B25: =SUMIF('TB - Ltd'!C:C,A25,'TB - Ltd'!J:J) -> 0 | C25: =SUMIF('TB - Inc'!C:C,A25,'TB - Inc'!F:F) -> 0 | D25: =SUM(B25:C25) -> 0
A26: Total Other Long term Assets | B26: =SUM(B24:B25) -> 0 | C26: =SUM(C24:C25) -> 0 | D26: =SUM(D24:D25) -> 0 | G26: =SUM(G24:G25) -> 0
A28: TOTAL ASSETS | B28: =B21+B12+B26 -> 97807311 | C28: =C21+C12+C26 -> 1326514.9 | D28: =D21+D12+D26 -> 99133826 | G28: =G21+G12+G26 -> 3.5386804e+08
A30: LIABILITIES & SHAREHOLDERS' EQUITY
A31: Current Liabilities
A32: Other short term loans | B32: =-SUMIF('TB - Ltd'!C:C,A32,'TB - Ltd'!J:J) -> 0 | C32: =-SUMIF('TB - Inc'!C:C,A32,'TB - Inc'!F:F) -> 0 | D32: =SUM(B32:C32) -> 0 | G32: =-SUMIF('TB - Ltd'!C:C,A32,'TB - Ltd'!G:G) -> 0
A33: Accounts payable | B33: =-SUMIF('TB - Ltd'!C:C,A33,'TB - Ltd'!J:J) -> -260809.43 | C33: =-SUMIF('TB - Inc'!C:C,A33,'TB - Inc'!F:F) -> 0 | D33: =SUM(B33:C33) -> -260809.43 | G33: =-SUMIF('TB - Ltd'!C:C,A33,'TB - Ltd'!G:G) -> -945955.84 | H33: =G33/B33 -> 3.6270001
A34: Accrued expenses | B34: =-SUMIF('TB - Ltd'!C:C,A34,'TB - Ltd'!J:J) -> 252626.47 | C34: =-SUMIF('TB - Inc'!C:C,A34,'TB - Inc'!F:F) -> 0 | D34: =SUM(B34:C34) -> 252626.47 | G34: =-SUMIF('TB - Ltd'!C:C,A34,'TB - Ltd'!G:G) -> 916277.88 | H34: =G34/B34 -> 3.6270066 | I34: הרכב
A35: Employee payables | B35: =-SUMIF('TB - Ltd'!C:C,A35,'TB - Ltd'!J:J) -> 690702.23 | C35: =-SUMIF('TB - Inc'!C:C,A35,'TB - Inc'!F:F) -> 169.6 | D35: =SUM(B35:C35) -> 690871.83 | G35: =-SUMIF('TB - Ltd'!C:C,A35,'TB - Ltd'!G:G) -> 2505177 | H35: =G35/B35 -> 3.627 | I35: פקודת שכר 12.23
A36: Employee institution | B36: =-SUMIF('TB - Ltd'!C:C,A36,'TB - Ltd'!J:J) -> 768178.1 | C36: =-SUMIF('TB - Inc'!C:C,A36,'TB - Inc'!F:F) -> 0 | D36: =SUM(B36:C36) -> 768178.1 | G36: =-SUMIF('TB - Ltd'!C:C,A36,'TB - Ltd'!G:G) -> 2786182 | H36: =G36/B36 -> 3.627 | I36: 102 + נייר עבודה
A37: Short term provisions - holiday accrual | B37: =-SUMIF('TB - Ltd'!C:C,A37,'TB - Ltd'!J:J) -> 504905.91 | C37: =-SUMIF('TB - Inc'!C:C,A37,'TB - Inc'!F:F) -> 0 | D37: =SUM(B37:C37) -> 504905.91 | G37: =-SUMIF('TB - Ltd'!C:C,A37,'TB - Ltd'!G:G) -> 1831293.7 | H37: =G37/B37 -> 3.627 | I37: דוח עתודה לחופשה והבראה
A38: Deffered revenues | B38: =-SUMIF('TB - Ltd'!C:C,A38,'TB - Ltd'!J:J) -> 131737 | C38: =-SUMIF('TB - Inc'!C:C,A38,'TB - Inc'!F:F) -> 1068361 | D38: =SUM(B38:C38) -> 1200098 | G38: =-SUMIF('TB - Ltd'!C:C,A38,'TB - Ltd'!G:G) -> 477810.46 | H38: =G38/B38 -> 3.6270027 | I38: נייר עבודה הכנסות נדחות
A39: Other short term liabilities | B39: =-SUMIF('TB - Ltd'!C:C,A39,'TB - Ltd'!J:J) -> 0 | C39: =-SUMIF('TB - Inc'!C:C,A39,'TB - Inc'!F:F) -> 0 | D39: =SUM(B39:C39) -> 0 | G39: =-SUMIF('TB - Ltd'!C:C,A39,'TB - Ltd'!G:G) -> 0
A40: Total Current Liabilities | B40: =SUM(B32:B39) -> 2087340.3 | C40: =SUM(C32:C39) -> 1068530.6 | D40: =SUM(D32:D39) -> 3155870.9 | G40: =SUM(G32:G39) -> 7570785.2
A42: Long term Liabilities
A43: Other long term liabilities | B43: =-SUMIF('TB - Ltd'!C:C,A43,'TB - Ltd'!J:J) -> 0 | C43: =-SUMIF('TB - Inc'!C:C,A43,'TB - Inc'!F:F) -> 0 | D43: =SUM(B43:C43) -> 0 | G43: =-SUMIF('TB - Ltd'!C:C,A43,'TB - Ltd'!G:G) -> 0
A45: Shareholders equity
A47: Preferred & Common Stock | B47: =-SUMIF('TB - Ltd'!C:C,A47,'TB - Ltd'!J:J) -> 0 | C47: =-SUMIF('TB - Inc'!C:C,A47,'TB - Inc'!F:F) -> 0 | D47: =SUM(B47:C47) -> 0 | G47: =-SUMIF('TB - Ltd'!C:C,A47,'TB - Ltd'!G:G) -> 0
A48: Additional paid in capital | B48: =-SUMIF('TB - Ltd'!C:C,A48,'TB - Ltd'!J:J) -> 1.3747636e+08 | C48: =-SUMIF('TB - Inc'!C:C,A48,'TB - Inc'!F:F) -> 1535 | D48: =SUM(B48:C48) -> 1.3747789e+08 | G48: =-SUMIF('TB - Ltd'!C:C,A48,'TB - Ltd'!G:G) -> 4.6306972e+08 | H48: =G48/B48 -> 3.368359
...

Sheet P&L
B2: (IL) Ltd | C2: INC | D2: Consolidated | G2: s (IL) Ltd
B3: U S D O L L A R S | G3: Shekels
A5: Revenues - Income | B5: =-SUMIF('TB - Ltd'!C:C,A5,'TB - Ltd'!J:J) -> 204524.12 | C5: =-SUMIF('TB - Inc'!C:C,A5,'TB - Inc'!F:F) -> 964580.05 | D5: =SUM(B5:C5) -> 1169104.2 | G5: =-SUMIF('TB - Ltd'!C:C,A5,'TB - Ltd'!G:G) -> 770610.31
A6: Intercompany - P&L | B6: =-SUMIF('TB - Ltd'!C:C,A6,'TB - Ltd'!J:J) -> -8084166.7 | C6: =-SUMIF('TB - Inc'!C:C,A6,'TB - Inc'!F:F) -> 8084166.7 | D6: =SUM(B6:C6) -> 0 | G6: =-SUMIF('TB - Ltd'!C:C,A6,'TB - Ltd'!G:G) -> -30062412
B7: =SUM(B5:B6) -> -7879642.6 | C7: =SUM(C5:C6) -> 9048746.8 | D7: =SUM(D5:D6) -> 1169104.2 | G7: =SUM(G5:G6) -> -29291801
A10: Short term bank credit | B10: =SUMIF('TB - Ltd'!#REF!,'P&L'!#REF!,'TB - Ltd'!$J$4:$J$153) -> #REF! | C10: =SUMIF('TB - Inc'!#REF!,'P&L'!#REF!,'TB - Inc'!#REF!) -> #REF! | D10: =SUM(B10:C10) -> #REF! | G10: =SUMIF('TB - Ltd'!#REF!,'P&L'!#REF!,'TB - Ltd'!$G$4:$G$139) -> #REF!
A11: COS - Hosting | B11: =SUMIF('TB - Ltd'!C:C,A11,'TB - Ltd'!J:J) -> 164759.95 | C11: =SUMIF('TB - Inc'!C:C,A11,'TB - Inc'!F:F) -> 0 | D11: =SUM(B11:C11) -> 164759.95 | G11: =SUMIF('TB - Ltd'!C:C,A11,'TB - Ltd'!G:G) -> 597584.52
A12: COS - SW (product -variable) | B12: =SUMIF('TB - Ltd'!C:C,A12,'TB - Ltd'!J:J) -> 234738.46 | C12: =SUMIF('TB - Inc'!C:C,A12,'TB - Inc'!F:F) -> 0 | D12: =SUM(B12:C12) -> 234738.46 | G12: =SUMIF('TB - Ltd'!C:C,A12,'TB - Ltd'!G:G) -> 869455.83
A13: COS - SW (product-fixed) | B13: =SUMIF('TB - Ltd'!C:C,A13,'TB - Ltd'!J:J) -> 10944.46 | C13: =SUMIF('TB - Inc'!C:C,A13,'TB - Inc'!F:F) -> 0 | D13: =SUM(B13:C13) -> 10944.46 | G13: =SUMIF('TB - Ltd'!C:C,A13,'TB - Ltd'!G:G) -> 41182.09
A14: COS - Allocation from Support | B14: =SUMIF('TB - Ltd'!C:C,A14,'TB - Ltd'!J:J) -> 171469.77 | C14: =SUMIF('TB - Inc'!C:C,A14,'TB - Inc'!F:F) -> 0 | D14: =SUM(B14:C14) -> 171469.77 | G14: =SUMIF('TB - Ltd'!C:C,A14,'TB - Ltd'!G:G) -> 621921.69
A15: COS - Contingency (on expenses only) | B15: =SUMIF('TB - Ltd'!C:C,A15,'TB - Ltd'!J:J) -> 0 | C15: =SUMIF('TB - Inc'!C:C,A15,'TB - Inc'!F:F) -> 0 | D15: =SUM(B15:C15) -> 0 | G15: =SUMIF('TB - Ltd'!C:C,A15,'TB - Ltd'!G:G) -> 0
B16: =SUM(B11:B15) -> 581912.64 | C16: =SUM(C11:C15) -> 0 | D16: =SUM(D11:D15) -> 581912.64 | G16: =SUM(G11:G15) -> 2130144.1
B18: =B7-B16 -> -8461555.2 | C18: =C7-C16 -> 9048746.8 | D18: =D7-D16 -> 587191.53 | G18: =G7-G16 -> -31421946
B19: =B18/B7 -> 1.0738501 | C19: =C18/C7 -> 1 | D19: =D18/D7 -> 0.50225766 | G19: =G18/G7 -> 1.0727215
A21: Support
A22: Support - Salaries and social benefits | B22: =SUMIF('TB - Ltd'!C:C,A22,'TB - Ltd'!J:J) -> 164918.07 | C22: =SUMIF('TB - Inc'!C:C,A22,'TB - Inc'!F:F) -> 0 | D22: =SUM(B22:C22) -> 164918.07 | G22: =SUMIF('TB - Ltd'!C:C,A22,'TB - Ltd'!G:G) -> 610227.82
A23: Support - Recruiting | B23: =SUMIF('TB - Ltd'!C:C,A23,'TB - Ltd'!J:J) -> 0 | C23: =SUMIF('TB - Inc'!C:C,A23,'TB - Inc'!F:F) -> 0 | D23: =SUM(B23:C23) -> 0 | G23: =SUMIF('TB - Ltd'!C:C,A23,'TB - Ltd'!G:G) -> 0
A24: Support - Total Support MBO and social benefits ($) | B24: =SUMIF('TB - Ltd'!C:C,A24,'TB - Ltd'!J:J) -> 2403 | C24: =SUMIF('TB - Inc'!C:C,A24,'TB - Inc'!F:F) -> 0 | D24: =SUM(B24:C24) -> 2403 | G24: =SUMIF('TB - Ltd'!C:C,A24,'TB - Ltd'!G:G) -> 8715.681
A25: Support - Software Tools | B25: =SUMIF('TB - Ltd'!C:C,A25,'TB - Ltd'!J:J) -> 4148.4 | C25: =SUMIF('TB - Inc'!C:C,A25,'TB - Inc'!F:F) -> 0 | D25: =SUM(B25:C25) -> 4148.4 | G25: =SUMIF('TB - Ltd'!C:C,A25,'TB - Ltd'!G:G) -> 15737.38
A26: Support - Contingency | B26: =SUMIF('TB - Ltd'!C:C,A26,'TB - Ltd'!J:J) -> 12757.502 | C26: =SUMIF('TB - Inc'!C:C,A26,'TB - Inc'!F:F) -> 0 | D26: =SUM(B26:C26) -> 12757.502 | G26: =SUMIF('TB - Ltd'!C:C,A26,'TB - Ltd'!G:G) -> 37856.484
A27: Support - Allocation to COS | B27: =SUMIF('TB - Ltd'!C:C,A27,'TB - Ltd'!J:J) -> -171469.77 | C27: =SUMIF('TB - Inc'!C:C,A27,'TB - Inc'!F:F) -> 0 | D27: =SUM(B27:C27) -> -171469.77 | G27: =SUMIF('TB - Ltd'!C:C,A27,'TB - Ltd'!G:G) -> -621921.69
B28: =SUM(B22:B27) -> 12757.202 | C28: =SUM(C22:C27) -> 0 | D28: =SUM(D22:D27) -> 12757.202 | G28: =SUM(G22:G27) -> 50615.674
A30: Engineering | B30: `
A31: Engineering - Salaries and social benefits | B31: =SUMIF('TB - Ltd'!C:C,A31,'TB - Ltd'!J:J) -> 10085869 | C31: =SUMIF('TB - Inc'!C:C,A31,'TB - Inc'!F:F) -> 135469.86 | D31: =SUM(B31:C31) -> 10221339 | G31: =SUMIF('TB - Ltd'!C:C,A31,'TB - Ltd'!G:G) -> 37399383
A32: Engineering - Recruiting | B32: =SUMIF('TB - Ltd'!C:C,A32,'TB - Ltd'!J:J) -> 22237.83 | C32: =SUMIF('TB - Inc'!C:C,A32,'TB - Inc'!F:F) -> 0 | D32: =SUM(B32:C32) -> 22237.83 | G32: =SUMIF('TB - Ltd'!C:C,A32,'TB - Ltd'!G:G) -> 79000
A33: Engineering - Total Engineering MBO and social benefits ($) | B33: =SUMIF('TB - Ltd'!C:C,A33,'TB - Ltd'!J:J) -> 643 | C33: =SUMIF('TB - Inc'!C:C,A33,'TB - Inc'!F:F) -> 0 | D33: =SUM(B33:C33) -> 643 | G33: =SUMIF('TB - Ltd'!C:C,A33,'TB - Ltd'!G:G) -> 2332.161
A34: Engineering - Ongoing/random outsourced | B34: =SUMIF('TB - Ltd'!C:C,A34,'TB - Ltd'!J:J) -> 148951.75 | C34: =SUMIF('TB - Inc'!C:C,A34,'TB - Inc'!F:F) -> 0 | D34: =SUM(B34:C34) -> 148951.75 | G34: =SUMIF('TB - Ltd'!C:C,A34,'TB - Ltd'!G:G) -> 560627.71
A35: Engineering - Options | B35: =SUMIF('TB - Ltd'!C:C,A35,'TB - Ltd'!J:J) -> 384964.66 | C35: =SUMIF('TB - Inc'!C:C,A35,'TB - Inc'!F:F) -> 26607.4 | D35: =SUM(B35:C35) -> 411572.06 | G35: =SUMIF('TB - Ltd'!C:C,A35,'TB - Ltd'!G:G) -> 1395111.9
A36: Engineering - Hosting | B36: =SUMIF('TB - Ltd'!C:C,A36,'TB - Ltd'!J:J) -> 442474.5 | C36: =SUMIF('TB - Inc'!C:C,A36,'TB - Inc'!F:F) -> 40000 | D36: =SUM(B36:C36) -> 482474.5 | G36: =SUMIF('TB - Ltd'!C:C,A36,'TB - Ltd'!G:G) -> 1662016.5
A37: Engineering - Development software tools | B37: =SUMIF('TB - Ltd'!C:C,A37,'TB - Ltd'!J:J) -> 288287.64 | C37: =SUMIF('TB - Inc'!C:C,A37,'TB - Inc'!F:F) -> 4500 | D37: =SUM(B37:C37) -> 292787.64 | G37: =SUMIF('TB - Ltd'!C:C,A37,'TB - Ltd'!G:G) -> 1026197.1
A38: Engineering - Training / Professional courses | B38: =SUMIF('TB - Ltd'!C:C,A38,'TB - Ltd'!J:J) -> 7020.1 | C38: =SUMIF('TB - Inc'!C:C,A38,'TB - Inc'!F:F) -> 0 | D38: =SUM(B38:C38) -> 7020.1 | G38: =SUMIF('TB - Ltd'!C:C,A38,'TB - Ltd'!G:G) -> 25550
A39: Engineering - Guest/Client hospitality | B39: =SUMIF('TB - Ltd'!C:C,A39,'TB - Ltd'!J:J) -> 83.44 | C39: =SUMIF('TB - Inc'!C:C,A39,'TB - Inc'!F:F) -> 0 | D39: =SUM(B39:C39) -> 83.44 | G39: =SUMIF('TB - Ltd'!C:C,A39,'TB - Ltd'!G:G) -> 297
A40: Engineering - Travel | B40: =SUMIF('TB - Ltd'!C:C,A40,'TB - Ltd'!J:J) -> 20326.1 | C40: =SUMIF('TB - Inc'!C:C,A40,'TB - Inc'!F:F) -> 0 | D40: =SUM(B40:C40) -> 20326.1 | G40: =SUMIF('TB - Ltd'!C:C,A40,'TB - Ltd'!G:G) -> 77438.98
A41: Engineering - Contingency | B41: =SUMIF('TB - Ltd'!C:C,A41,'TB - Ltd'!J:J) -> 880267.65 | C41: =SUMIF('TB - Inc'!C:C,A41,'TB - Inc'!F:F) -> 0 | D41: =SUM(B41:C41) -> 880267.65 | G41: =SUMIF('TB - Ltd'!C:C,A41,'TB - Ltd'!G:G) -> 2612097.4
B42: =SUM(B31:B41) -> 12281126 | C42: =SUM(C31:C41) -> 206577.26 | D42: =SUM(D31:D41) -> 12487703 | G42: =SUM(G31:G41) -> 44840052
A44: Product
A45: Product - Salaries and social benefits | B45: =SUMIF('TB - Ltd'!C:C,A45,'TB - Ltd'!J:J) -> 2111370 | C45: =SUMIF('TB - Inc'!C:C,A45,'TB - Inc'!F:F) -> 0 | D45: =SUM(B45:C45) -> 2111370 | G45: =SUMIF('TB - Ltd'!C:C,A45,'TB - Ltd'!G:G) -> 7809642.5
A46: Product - Recruiting | B46: =SUMIF('TB - Ltd'!C:C,A46,'TB - Ltd'!J:J) -> 112.99 | C46: =SUMIF('TB - Inc'!C:C,A46,'TB - Inc'!F:F) -> 0 | D46: =SUM(B46:C46) -> 112.99 | G46: =SUMIF('TB - Ltd'!C:C,A46,'TB - Ltd'!G:G) -> 413.46
A47: Product - Ongoing/random outsourced | B47: =SUMIF('TB - Ltd'!C:C,A47,'TB - Ltd'!J:J) -> 6385.7 | C47: =SUMIF('TB - Inc'!C:C,A47,'TB - Inc'!F:F) -> 0 | D47: =SUM(B47:C47) -> 6385.7 | G47: =SUMIF('TB - Ltd'!C:C,A47,'TB - Ltd'!G:G) -> 24572.16
A48: Product - Product certification & compliance | B48: =SUMIF('TB - Ltd'!C:C,A48,'TB - Ltd'!J:J) -> 38687.72 | C48: =SUMIF('TB - Inc'!C:C,A48,'TB - Inc'!F:F) -> 0 | D48: =SUM(B48:C48) -> 38687.72 | G48: =SUMIF('TB - Ltd'!C:C,A48,'TB - Ltd'!G:G) -> 138112.29
...

Sheet TB - Ltd
E1: =SUM(E3:E537) -> -9.5560608e-08 | F1: =SUM(F3:F537) -> 1.8626451e-09 | G1: =SUM(G3:G537) -> 5.0295057e-09 | H1: =SUM(H3:H537) -> -2.0207381e-08 | I1: =SUM(I3:I537) -> 0 | J1: =SUM(J3:J537) -> -3.4435743e-09
A2: חשבון | B2: תאור החשבון | D2: BS/PL | E2: ספרים - ש"ח | F2: פ"נ ש"ח | G2: סופי - ש"ח | H2: ספרים - דולר | I2: פ"נ - דולר | J2: סופי - דולר
A3: 10001 | B3: בנק הפועלים 174/9550 $ | C3: Cash & cash equivalents ISRAEL | D3: BS | E3: 1.6487672e+08 | F3: =SUMIF('JE - LTD '!A:A,'TB - Ltd'!A3,'JE - LTD '!D:D) -> 0 | G3: =E3+F3 -> 1.6487672e+08 | H3: 45458154 | I3: =SUMIF('JE - LTD '!A:A,'TB - Ltd'!A3,'JE - LTD '!C:C) -> 0 | J3: =H3+I3 -> 45458154 | K3: =G3/J3 -> 3.627
A4: 10002 | B4: בנק הפועלים 174/9550 יורו | C4: Cash & cash equivalents ISRAEL | D4: BS | E4: -278046.44 | F4: =SUMIF('JE - LTD '!A:A,'TB - Ltd'!A4,'JE - LTD '!D:D) -> 0 | G4: =E4+F4 -> -278046.44 | H4: -76660.17 | I4: =SUMIF('JE - LTD '!A:A,'TB - Ltd'!A4,'JE - LTD '!C:C) -> 0 | J4: =H4+I4 -> -76660.17 | K4: =G4/J4 -> 3.627
A5: 10322 | B5: פקדון $ בנק הפועלים 356789013 | C5: Cash & cash equivalents ISRAEL | D5: BS | E5: 679272.29 | F5: =SUMIF('JE - LTD '!A:A,'TB - Ltd'!A5,'JE - LTD '!D:D) -> 0 | G5: =E5+F5 -> 679272.29 | H5: 187282.13 | I5: =SUMIF('JE - LTD '!A:A,'TB - Ltd'!A5,'JE - LTD '!C:C) -> 0 | J5: =H5+I5 -> 187282.13 | K5: =G5/J5 -> 3.627
A6: 10300 | B6: פקדון ש"ח בנק הפועלים | C6: Cash & cash equivalents ISRAEL | D6: BS | E6: 25401555 | F6: =SUMIF('JE - LTD '!A:A,'TB - Ltd'!A6,'JE - LTD '!D:D) -> 0 | G6: =E6+F6 -> 25401555 | H6: 7003461.4 | I6: =SUMIF('JE - LTD '!A:A,'TB - Ltd'!A6,'JE - LTD '!C:C) -> 0 | J6: =H6+I6 -> 7003461.4 | K6: =G6/J6 -> 3.627
A7: 10207 | B7: MESH | C7: Other Current Assets | D7: BS | E7: 480633.03 | F7: =SUMIF('JE - LTD '!A:A,'TB - Ltd'!A7,'JE - LTD '!D:D) -> 0 | G7: =E7+F7 -> 480633.03 | H7: 132515.31 | I7: =SUMIF('JE - LTD '!A:A,'TB - Ltd'!A7,'JE - LTD '!C:C) -> 0 | J7: =H7+I7 -> 132515.31 | K7: =G7/J7 -> 3.627
A8: 10200 | B8: כרטיס אשראי 1784 ש"ח | C8: Accounts payable | D8: BS | E8: -4936.29 | F8: =SUMIF('JE - LTD '!A:A,'TB - Ltd'!A8,'JE - LTD '!D:D) -> 0 | G8: =E8+F8 -> -4936.29 | H8: -1360.98 | I8: =SUMIF('JE - LTD '!A:A,'TB - Ltd'!A8,'JE - LTD '!C:C) -> 0 | J8: =H8+I8 -> -1360.98 | K8: =G8/J8 -> 3.6270114
A9: 10202 | B9: כרטיס אשראי 9518 MAX ש"ח | C9: Accounts payable | D9: BS | E9: -3559.12 | F9: =SUMIF('JE - LTD '!A:A,'TB - Ltd'!A9,'JE - LTD '!D:D) -> 0 | G9: =E9+F9 -> -3559.12 | H9: -981.28 | I9: =SUMIF('JE - LTD '!A:A,'TB - Ltd'!A9,'JE - LTD '!C:C) -> 0 | J9: =H9+I9 -> -981.28 | K9: =G9/J9 -> 3.6270178
A10: 10204 | B10: כרטיס אשראי 9419 MAX ש"ח | C10: Accounts payable | D10: BS | E10: -23565.61 | F10: =SUMIF('JE - LTD '!A:A,'TB - Ltd'!A10,'JE - LTD '!D:D) -> 0 | G10: =E10+F10 -> -23565.61 | H10: -6497.27 | I10: =SUMIF('JE - LTD '!A:A,'TB - Ltd'!A10,'JE - LTD '!C:C) -> 0 | J10: =H10+I10 -> -6497.27 | K10: =G10/J10 -> 3.6270018
A11: 10502 | B11: פקדון DEEL | C11: Other current assets | D11: BS | E11: 476733.37 | F11: =SUMIF('JE - LTD '!A:A,'TB - Ltd'!A11,'JE - LTD '!D:D) -> 0 | G11: =E11+F11 -> 476733.37 | H11: 131440.13 | I11: =SUMIF('JE - LTD '!A:A,'TB - Ltd'!A11,'JE - LTD '!C:C) -> 0 | J11: =H11+I11 -> 131440.13 | K11: =G11/J11 -> 3.6270001
A12: 106001 | B12: וויזור איי אי בע"מ | C12: Accounts receivable - Sublease | D12: BS | E12: -3494.79 | F12: =SUMIF('JE - LTD '!A:A,'TB - Ltd'!A12,'JE - LTD '!D:D) -> 0 | G12: =E12+F12 -> -3494.79 | H12: -963.55 | I12: =SUMIF('JE - LTD '!A:A,'TB - Ltd'!A12,'JE - LTD '!C:C) -> 0 | J12: =H12+I12 -> -963.55 | K12: =G12/J12 -> 3.6269939
A13: 106002 | B13: קופלי זיפ בע"מ | C13: Accounts receivable - Sublease | D13: BS | E13: 181168.65 | F13: =SUMIF('JE - LTD '!A:A,'TB - Ltd'!A13,'JE - LTD '!D:D) -> 0 | G13: =E13+F13 -> 181168.65 | H13: 49950 | I13: =SUMIF('JE - LTD '!A:A,'TB - Ltd'!A13,'JE - LTD '!C:C) -> 0 | J13: =H13+I13 -> 49950 | K13: =G13/J13 -> 3.627
A14: 106000 | B14: Location World Colombia S.A.S | C14: Accounts receivable | D14: BS | E14: 5386.09 | F14: =SUMIF('JE - LTD '!A:A,'TB - Ltd'!A14,'JE - LTD '!D:D) -> 0 | G14: =E14+F14 -> 5386.09 | H14: 1485 | I14: =SUMIF('JE - LTD '!A:A,'TB - Ltd'!A14,'JE - LTD '!C:C) -> 0 | J14: =H14+I14 -> 1485 | K14: =G14/J14 -> 3.6269966
... A18: 10800 | B18: הוצאות מראש | C18: Prepaid Expenses | D18: BS | E18: 1294552.8 | F18: =SUMIF('JE - LTD '!A:A,'TB - Ltd'!A18,'JE - LTD '!D:D) -> 70862.01 | G18: =E18+F18 -> 1365414.8 | H18: 365325.82 | I18: =SUMIF('JE - LTD '!A:A,'TB - Ltd'!A18,'JE - LTD '!C:C) -> -3000 | J18: =H18+I18 -> 362325.82 | K18: =G18/J18 -> 3.7684724
A19: 15001 | B19: ריהוט וציוד | C19: Office furniture and equipment | D19: BS | E19: 606307.32 | F19: =SUMIF('JE - LTD '!A:A,'TB - Ltd'!A20,'JE - LTD '!D:D) -> 0 | G19: =E19+F19 -> 606307.32 | H19: 180121.26 | I19: =SUMIF('JE - LTD '!A:A,'TB - Ltd'!A20,'JE - LTD '!C:C) -> 0 | J19: =H19+I19 -> 180121.26 | K19: =G19/J19 -> 3.3661064
A20: 15002 | B20: ציוד אלקטרוני | C20: Office furniture and equipment | D20: BS | E20: 91368.88 | F20: =SUMIF('JE - LTD '!A:A,'TB - Ltd'!A22,'JE - LTD '!D:D) -> 0 | G20: =E20+F20 -> 91368.88 | H20: 26554.9 | I20: =SUMIF('JE - LTD '!A:A,'TB - Ltd'!A22,'JE - LTD '!C:C) -> 0 | J20: =H20+I20 -> 26554.9 | K20: =G20/J20 -> 3.4407541
A21: 15003 | B21: שיפורים במושכר | C21: Leasehold Improvements | D21: BS | E21: 1529963.2 | F21: =SUMIF('JE - LTD '!A:A,'TB - Ltd'!A21,'JE - LTD '!D:D) -> 0 | G21: =E21+F21 -> 1529963.2 | H21: 451119.09 | I21: =SUMIF('JE - LTD '!A:A,'TB - Ltd'!A21,'JE - LTD '!C:C) -> 0 | J21: =H21+I21 -> 451119.09 | K21: =G21/J21 -> 3.3914841
A22: 15103 | B22: פחת נצבר שפורים במושכר | C22: Less accumulated depreciation | D22: BS | E22: -197360.14 | F22: =SUMIF('JE - LTD '!A:A,'TB - Ltd'!A26,'JE - LTD '!D:D) -> 0 | G22: =E22+F22 -> -197360.14 | H22: -59330.23 | I22: =SUMIF('JE - LTD '!A:A,'TB - Ltd'!A26,'JE - LTD '!C:C) -> 0 | J22: =H22+I22 -> -59330.23 | K22: =G22/J22 -> 3.3264685
A23: 15101 | B23: פחת נצבר ריהוט וציוד | C23: Less accumulated depreciation | D23: BS | E23: -59053.53 | F23: =SUMIF('JE - LTD '!A:A,'TB - Ltd'!A25,'JE - LTD '!D:D) -> 0 | G23: =E23+F23 -> -59053.53 | H23: -17661.48 | I23: =SUMIF('JE - LTD '!A:A,'TB - Ltd'!A25,'JE - LTD '!C:C) -> 0 | J23: =H23+I23 -> -17661.48 | K23: =G23/J23 -> 3.3436343
A24: 15102 | B24: פחת נצבר ציוד אלקטרוני | C24: Less accumulated depreciation | D24: BS | E24: -12800.94 | F24: =SUMIF('JE - LTD '!A:A,'TB - Ltd'!A23,'JE - LTD '!D:D) -> 0 | G24: =E24+F24 -> -12800.94 | H24: -3755.9 | I24: =SUMIF('JE - LTD '!A:A,'TB - Ltd'!A23,'JE - LTD '!C:C) -> 0 | J24: =H24+I24 -> -3755.9 | K24: =G24/J24 -> 3.4082217
A25: 15100 | B25: פחת נצבר מחשבים | C25: Less accumulated depreciation | D25: BS | E25: -668869.19 | F25: =SUMIF('JE - LTD '!A:A,'TB - Ltd'!A24,'JE - LTD '!D:D) -> 0 | G25: =E25+F25 -> -668869.19 | H25: -200653.37 | I25: =SUMIF('JE - LTD '!A:A,'TB - Ltd'!A24,'JE - LTD '!C:C) -> 0 | J25: =H25+I25 -> -200653.37 | K25: =G25/J25 -> 3.333456
A26: 15000 | B26: מחשבים ותוכנות | C26: Computer equipment & software | D26: BS | E26: 1455299.6 | F26: =SUMIF('JE - LTD '!A:A,'TB - Ltd'!A19,'JE - LTD '!D:D) -> 0 | G26: =E26+F26 -> 1455299.6 | H26: 425011.87 | I26: =SUMIF('JE - LTD '!A:A,'TB - Ltd'!A19,'JE - LTD '!C:C) -> 0 | J26: =H26+I26 -> 425011.87 | K26: =G26/J26 -> 3.4241388
A27: 200017 | B27: מטריקס אי.טי. אינטגרציה ותשתיות בע"מ | C27: Accounts payable | D27: BS | E27: 13381 | F27: =SUMIF('JE - LTD '!A:A,'TB - Ltd'!A27,'JE - LTD '!D:D) -> 0 | G27: =E27+F27 -> 13381 | H27: 3689.27 | I27: =SUMIF('JE - LTD '!A:A,'TB - Ltd'!A27,'JE - LTD '!C:C) -> 0 | J27: =H27+I27 -> 3689.27 | K27: =G27/J27 -> 3.6270048
A28: 200053 | B28: פון פלוס בע"מ | C28: Accounts payable | D28: BS | E28: 39 | F28: =SUMIF('JE - LTD '!A:A,'TB - Ltd'!A28,'JE - LTD '!D:D) -> 0 | G28: =E28+F28 -> 39 | H28: 10.75 | I28: =SUMIF('JE - LTD '!A:A,'TB - Ltd'!A28,'JE - LTD '!C:C) -> 0 | J28: =H28+I28 -> 10.75 | K28: =G28/J28 -> 3.627907
A29: 200126 | B29: אופיר טורס בע"מ | C29: Accounts payable | D29: BS | E29: -10455.22 | F29: =SUMIF('JE - LTD '!A:A,'TB - Ltd'!A29,'JE - LTD '!D:D) -> 0 | G29: =E29+F29 -> -10455.22 | H29: -2882.61 | I29: =SUMIF('JE - LTD '!A:A,'TB - Ltd'!A29,'JE - LTD '!C:C) -> 0 | J29: =H29+I29 -> -2882.61 | K29: =G29/J29 -> 3.6269978
A30: 200105 | B30: נאביטק בע"מ | C30: Accounts payable | D30: BS | E30: -35276 | F30: =SUMIF('JE - LTD '!A:A,'TB - Ltd'!A30,'JE - LTD '!D:D) -> 0 | G30: =E30+F30 -> -35276 | H30: -9725.94 | I30: =SUMIF('JE - LTD '!A:A,'TB - Ltd'!A30,'JE - LTD '!C:C) -> 0 | J30: =H30+I30 -> -9725.94 | K30: =G30/J30 -> 3.6270016
A31: 200130 | B31: אקורן נכסים והשקעות בע"מ | C31: Accounts payable | D31: BS | E31: 563037.11 | F31: =SUMIF('JE - LTD '!A:A,'TB - Ltd'!A31,'JE - LTD '!D:D) -> 0 | G31: =E31+F31 -> 563037.11 | H31: 155234.94 | I31: =SUMIF('JE - LTD '!A:A,'TB - Ltd'!A31,'JE - LTD '!C:C) -> 0 | J31: =H31+I31 -> 155234.94 | K31: =G31/J31 -> 3.6269999
A32: 200049 | B32: WOLT וואלט אנטרפריזס | C32: Accounts payable | D32: BS | E32: 1215.15 | F32: =SUMIF('JE - LTD '!A:A,'TB - Ltd'!A32,'JE - LTD '!D:D) -> 0 | G32: =E32+F32 -> 1215.15 | H32: 335.03 | I32: =SUMIF('JE - LTD '!A:A,'TB - Ltd'!A32,'JE - LTD '!C:C) -> 0 | J32: =H32+I32 -> 335.03 | K32: =G32/J32 -> 3.6269886
A33: 200148 | B33: פליקאן גרופ א.י. בע"מ | C33: Accounts payable | D33: BS | E33: 94862.92 | F33: =SUMIF('JE - LTD '!A:A,'TB - Ltd'!A33,'JE - LTD '!D:D) -> 0 | G33: =E33+F33 -> 94862.92 | H33: 26154.63 | I33: =SUMIF('JE - LTD '!A:A,'TB - Ltd'!A33,'JE - LTD '!C:C) -> 0 | J33: =H33+I33 -> 26154.63 | K33: =G33/J33 -> 3.6270029
A34: 20003 | B34: עירייה | C34: Accounts payable | D34: BS | E34: 111171.77 | F34: =SUMIF('JE - LTD '!A:A,'TB - Ltd'!A34,'JE - LTD '!D:D) -> 0 | G34: =E34+F34 -> 111171.77 | H34: 30651.16 | I34: =SUMIF('JE - LTD '!A:A,'TB - Ltd'!A34,'JE - LTD '!C:C) -> 0 | J34: =H34+I34 -> 30651.16 | K34: =G34/J34 -> 3.6270004
A35: 200118 | B35: תגמול סוכנות לביטוח חיים(2002) בע"מ | C35: Accounts payable | D35: BS | E35: 5884.59 | F35: =SUMIF('JE - LTD '!A:A,'TB - Ltd'!A35,'JE - LTD '!D:D) -> 0 | G35: =E35+F35 -> 5884.59 | H35: 1622.44 | I35: =SUMIF('JE - LTD '!A:A,'TB - Ltd'!A35,'JE - LTD '!C:C) -> 0 | J35: =H35+I35 -> 1622.44 | K35: =G35/J35 -> 3.6270001
A36: 200127 | B36: חברת פרטנר תקשורת בע"מ | C36: Accounts payable | D36: BS | E36: 4897.04 | F36: =SUMIF('JE - LTD '!A:A,'TB - Ltd'!A36,'JE - LTD '!D:D) -> 0 | G36: =E36+F36 -> 4897.04 | H36: 1350.16 | I36: =SUMIF('JE - LTD '!A:A,'TB - Ltd'!A36,'JE - LTD '!C:C) -> 0 | J36: =H36+I36 -> 1350.16 | K36: =G36/J36 -> 3.6270072
A37: 200160 | B37: ש.ר מודוס אופוס בע"מ | C37: Accounts payable | D37: BS | E37: 6435 | F37: =SUMIF('JE - LTD '!A:A,'TB - Ltd'!A37,'JE - LTD '!D:D) -> 0 | G37: =E37+F37 -> 6435 | H37: 1774.19 | I37: =SUMIF('JE - LTD '!A:A,'TB - Ltd'!A37,'JE - LTD '!C:C) -> 0 | J37: =H37+I37 -> 1774.19 | K37: =G37/J37 -> 3.6270073
A38: 200200 | B38: DEEL-LDEEL PROLL, S.L | C38: Accounts payable | D38: BS | E38: 90338.99 | F38: =SUMIF('JE - LTD '!A:A,'TB - Ltd'!A38,'JE - LTD '!D:D) -> 0 | G38: =E38+F38 -> 90338.99 | H38: 24907.36 | I38: =SUMIF('JE - LTD '!A:A,'TB - Ltd'!A38,'JE - LTD '!C:C) -> 0 | J38: =H38+I38 -> 24907.36 | K38: =G38/J38 -> 3.6269998
... A371: 1-11173027 | B371: עופר בן נון 2022.04 ארה"ב | C371: G&A - Travel | D371: P&L | E371: 1119 | F371: =SUMIF('JE - LTD '!A:A,'TB - Ltd'!A371,'JE - LTD '!D:D) -> 0 | G371: =E371+F371 -> 1119 | H371: 306 | I371: =SUMIF('JE - LTD '!A:A,'TB - Ltd'!A371,'JE - LTD '!C:C) -> 0 | J371: =H371+I371 -> 306 | K371: =G371/J371 -> 3.6568627
A372: 74003 | B372: הוצאות פחת שיפורים במושכר | C372: Non cash expense - Depreciation of fixed assets | D372: P&L | E372: 133592.26 | F372: =SUMIF('JE - LTD '!A:A,'TB - Ltd'!A374,'JE - LTD '!D:D) -> 0 | G372: =E372+F372 -> 133592.26 | H372: 39855.92 | I372: =SUMIF('JE - LTD '!A:A,'TB - Ltd'!A374,'JE - LTD '!C:C) -> 0 | J372: =H372+I372 -> 39855.92 | K372: =G372/J372 -> 3.35188
A373: 74001 | B373: הוצאות פחת ריהוט וציוד | C373: Non cash expense - Depreciation of fixed assets | D373: P&L | E373: 42376.21 | F373: =SUMIF('JE - LTD '!A:A,'TB - Ltd'!A373,'JE - LTD '!D:D) -> 0 | G373: =E373+F373 -> 42376.21 | H373: 12597.28 | I373: =SUMIF('JE - LTD '!A:A,'TB - Ltd'!A373,'JE - LTD '!C:C) -> 0 | J373: =H373+I373 -> 12597.28 | K373: =G373/J373 -> 3.3639174
A374: 74002 | B374: הוצאות פחת ציוד אלקטרוני | C374: Non cash expense - Depreciation of fixed assets | D374: P&L | E374: 11401.91 | F374: =SUMIF('JE - LTD '!A:A,'TB - Ltd'!A375,'JE - LTD '!D:D) -> 0 | G374: =E374+F374 -> 11401.91 | H374: 3355.57 | I374: =SUMIF('JE - LTD '!A:A,'TB - Ltd'!A375,'JE - LTD '!C:C) -> 0 | J374: =H374+I374 -> 3355.57 | K374: =G374/J374 -> 3.3979056
A375: 74000 | B375: הוצאות פחת מחשבים ותוכנה | C375: Non cash expense - Depreciation of fixed assets | D375: P&L | E375: 414864.93 | F375: =SUMIF('JE - LTD '!A:A,'TB - Ltd'!A372,'JE - LTD '!D:D) -> 0 | G375: =E375+F375 -> 414864.93 | H375: 122872.23 | I375: =SUMIF('JE - LTD '!A:A,'TB - Ltd'!A372,'JE - LTD '!C:C) -> 0 | J375: =H375+I375 -> 122872.23 | K375: =G375/J375 -> 3.3763929
...

Sheet JE - LTD 
A2: Acc # | B2: Acc Name | C2: US$ | D2: NIS | E2: 3.627 | F2: מהות הפקודה
A4: 25100 | B4: =VLOOKUP(A4,'TB - Ltd'!A:B,2,0) -> ביטול הוצ שכירות יישום תקן ASC842 הקטנת התחייבות | C4: -1
A5: 25102 | B5: =VLOOKUP(A5,'TB - Ltd'!A:B,2,0) -> Owned asset | C5: -2687944 | D5: -8707035 | F5: ביטול יתרות חכירה
A6: 20202 | B6: =VLOOKUP(A6,'TB - Ltd'!A:B,2,0) -> Owned liability- short term | C6: 358997 | D6: 1302082.1
A7: 25101 | B7: =VLOOKUP(A7,'TB - Ltd'!A:B,2,0) -> Owned liability- long term | C7: 2004123 | D7: 7069213
A8: 1-11370005 | B8: =VLOOKUP(A8,'TB - Ltd'!A:B,2,0) -> Office rent | C8: =-SUM(C4:C7) -> 324825 | D8: =-SUM(D4:D7) -> 335739.88
A10: New64 | B10: =VLOOKUP(A10,'TB - Ltd'!A:B,2,0) -> הוצאות בגין אופציות- פיתוח | C10: 384964.66 | D10: =C10*$E$10 -> 1395111.9 | E10: 3.624 | F10: פקודת אופציות 27/12 ישראל
A11: New48 | B11: =VLOOKUP(A11,'TB - Ltd'!A:B,2,0) -> הוצאות בגין אופציות- Customer Success | C11: 21805.907 | D11: =C11*$E$10 -> 79024.608
A12: New61 | B12: =VLOOKUP(A12,'TB - Ltd'!A:B,2,0) -> הוצאות בגין אופציות- שיווק | C12: 2889.6321 | D12: =C12*$E$10 -> 10472.027
A13: New65 | B13: =VLOOKUP(A13,'TB - Ltd'!A:B,2,0) -> הוצאות בגין אופציות-מוצר | C13: 72510.852 | D13: =C13*$E$10 -> 262779.33
A14: New47 | B14: =VLOOKUP(A14,'TB - Ltd'!A:B,2,0) -> הוצאות בגין אופציות-פיתוח עסקי | C14: 9141.8349 | D14: =C14*$E$10 -> 33130.01
A15: New78 | B15: =VLOOKUP(A15,'TB - Ltd'!A:B,2,0) -> הוצאות בגין אופציות- מכירות | C15: 28650.655 | D15: =C15*$E$10 -> 103829.97
A16: New66 | B16: =VLOOKUP(A16,'TB - Ltd'!A:B,2,0) -> הוצאות בגין אופציות- משאבי אנוש | C16: 4109.5808 | D16: =C16*$E$10 -> 14893.121
A17: New79 | B17: =VLOOKUP(A17,'TB - Ltd'!A:B,2,0) -> הוצאות בגין אופציות- Business Operations | C17: 5253.5372 | D17: =C17*$E$10 -> 19038.819
A18: New46 | B18: =VLOOKUP(A18,'TB - Ltd'!A:B,2,0) -> הוצאות בגין אופציות- הנהכ | C18: 6693.9341 | D18: =C18*$E$10 -> 24258.817
A19: 30080 | B19: =VLOOKUP(A19,'TB - Ltd'!A:B,2,0) -> קרן הון בגין הוצ' בגין אופציות | C19: =-SUM(C10:C18) -> -536020.6 | D19: =C19*$E$10 -> -1942538.6
A21: 30080 | B21: =VLOOKUP(A21,'TB - Ltd'!A:B,2,0) -> קרן הון בגין הוצ' בגין אופציות | C21: =-C22 -> 5362.98 | D21: =C21*E2 -> 19451.528 | F21: פקודת אופציות INC
A22: 25200 | B22: =VLOOKUP(A22,'TB - Ltd'!A:B,2,0) -> חו"ז בינחברתי | C22: -5362.98 | D22: =-D21 -> -19451.528
A25: 700104 | B25: =VLOOKUP(A25,'TB - Ltd'!A:B,2,0) -> הוצאות בינחברתי | C25: 2586533.7 | D25: =C25*E2 -> 9381357.8 | F25: פקודה בינחברתית
A26: 25200 | B26: =VLOOKUP(A26,'TB - Ltd'!A:B,2,0) -> חו"ז בינחברתי | C26: =-C25 -> -2586533.7 | D26: =-D25 -> -9381357.8
A28: New1 | B28: =VLOOKUP(A28,'TB - Ltd'!A:B,2,0) -> אלוקציה מופ | C28: 880267.65 | D28: 2612097.4 | F28: פקודת אלוקציה
A29: New2 | B29: =VLOOKUP(A29,'TB - Ltd'!A:B,2,0) -> אלוקציה הנהכ | C29: =-C28-C30-C31-C32-C33 -> -969570.16 | D29: =-D28-D30-D31-D32-D33 -> -2877092.8
A30: New3 | B30: =VLOOKUP(A30,'TB - Ltd'!A:B,2,0) -> אלוקציה שיווק | C30: 38272.506 | D30: 113569.45
A31: New4 | B31: =VLOOKUP(A31,'TB - Ltd'!A:B,2,0) -> אלוקציה מכירות | C31: 12757.502 | D31: 37856.484
A32: New5 | B32: =VLOOKUP(A32,'TB - Ltd'!A:B,2,0) -> אלוקציה CS | C32: 25515.004 | D32: 75712.968
A33: New6 | B33: =VLOOKUP(A33,'TB - Ltd'!A:B,2,0) -> אלוקציה SUPPORT | C33: 12757.502 | D33: 37856.484
A36: 1-10870089 | B36: =VLOOKUP(A36,'TB - Ltd'!A:B,2,0) -> US EVENTS | C36: 3000 | F36: העמדת הוצאות מראש כראוי בגין מנוי Influ2
A37: 10800 | B37: =VLOOKUP(A37,'TB - Ltd'!A:B,2,0) -> הוצאות מראש | C37: =-C36 -> -3000
A39: 10800 | B39: =VLOOKUP(A39,'TB - Ltd'!A:B,2,0) -> הוצאות מראש | D39: =-D40-D41 -> 70862.01 | F39: פקודה שעברה רק בדולר, להעביר גם בשקל
A40: 1-10870089 | B40: =VLOOKUP(A40,'TB - Ltd'!A:B,2,0) -> US EVENTS | D40: -11601
A41: 1-108700131 | B41: =VLOOKUP(A41,'TB - Ltd'!A:B,2,0) -> Events - EMEA | D41: -59261.01
A43: 20200 | B43: =VLOOKUP(A43,'TB - Ltd'!A:B,2,0) -> הוצאות לשלם | D43: 9147.294 | F43: פקודה שעברה רק בדולר, להעביר גם בשקל
A44: 1-10870062 | B44: =VLOOKUP(A44,'TB - Ltd'!A:B,2,0) -> Swag- Employee | D44: =-D43 -> -9147.294 | F44: נטרול רכיב המע"מ מההפרשה לספק מיתוגון
A46: 20800 | B46: =VLOOKUP(A46,'TB - Ltd'!A:B,2,0) -> הכנסות נדחות | D46: 11587.9 | F46: הפרשי שער על הכנסות נדחות
A47: 90002 | B47: =VLOOKUP(A47,'TB - Ltd'!A:B,2,0) -> הפרשי שער | D47: =-D46 -> -11587.9
A49: 1-10070014 | B49: =VLOOKUP(A49,'TB - Ltd'!A:B,2,0) -> Hosting | D49: =164760*3.627 -> 597584.52 | F49: פקודה שעברה רק בדולר, להעביר גם בשקל
A50: 1-10270014 | B50: =VLOOKUP(A50,'TB - Ltd'!A:B,2,0) -> Hosting | D50: =-D49 -> -597584.52
A52: new1242 | B52: =VLOOKUP(A52,'TB - Ltd'!A:B,2,0) -> COS - Allocation from Support | D52: =171470*3.627 -> 621921.69 | F52: פקודה שעברה רק בדולר, להעביר גם בשקל
A53: new1243 | B53: =VLOOKUP(A53,'TB - Ltd'!A:B,2,0) -> Support - Allocation to CoS | D53: =-D52 -> -621921.69
A55: new70 | B55: =VLOOKUP(A55,'TB - Ltd'!A:B,2,0) -> בונוס | D55: =643*3.627 -> 2332.161 | F55: פקודה שעברה רק בדולר, להעביר גם בשקל
...

Sheet TB - Inc
D1: =SUM(D3:D165) -> -7.7125151e-10 | E1: =SUM(E3:E166) -> 0 | F1: =SUM(F3:F166) -> -1.1641532e-09
A2: חשבון | B2: תאור החשבון | D2: ספרים - דולר | E2: פ"נ - דולר | F2: סופי - דולר
A3: 10000 | B3: Analysis Checking (8992) - 1 | C3: Cash & cash equivalents US | D3: 883967.03 | E3: =SUMIF('JE - Inc'!A:A,'TB - Inc'!A3,'JE - Inc'!D:D) -> 0 | F3: =IFERROR(E3+D3,0) -> 883967.03
A4: 12000 | B4: Account Receivable | C4: Accounts receivable | D4: 808996.95 | E4: =SUMIF('JE - Inc'!A:A,'TB - Inc'!A4,'JE - Inc'!D:D) -> 0 | F4: =IFERROR(E4+D4,0) -> 808996.95
A5: 13000 | B5: Prepaid Expenses | C5: Prepaid Expenses | D5: 36085.73 | E5: =SUMIF('JE - Inc'!A:A,'TB - Inc'!A5,'JE - Inc'!D:D) -> 0 | F5: =IFERROR(E5+D5,0) -> 36085.73
A6: 14500 | B6: Mesh Pay | C6: Cash & cash equivalents US | D6: 89722.64 | E6: =SUMIF('JE - Inc'!A:A,'TB - Inc'!A6,'JE - Inc'!D:D) -> 0 | F6: =IFERROR(E6+D6,0) -> 89722.64
A7: 16100 | B7: Fixed Assets:Fixed Assets - Computer | C7: Computer equipment & software | D7: 57005.59 | E7: =SUMIF('JE - Inc'!A:A,'TB - Inc'!A7,'JE - Inc'!D:D) -> 0 | F7: =IFERROR(E7+D7,0) -> 57005.59
A8: 16200 | B8: Fixed Assets:Accumulated Depreciation - Computer | C8: Less accumulated depreciation | D8: -17730.99 | E8: =SUMIF('JE - Inc'!A:A,'TB - Inc'!A8,'JE - Inc'!D:D) -> 0 | F8: =IFERROR(E8+D8,0) -> -17730.99
A9: 23500 | B9: Other current Liabilities:Employees Reimbursements | C9: Employee payables | D9: -99.6 | E9: =SUMIF('JE - Inc'!A:A,'TB - Inc'!A9,'JE - Inc'!D:D) -> 0 | F9: =IFERROR(E9+D9,0) -> -99.6
A10: 24000 | B10: Deferred Revenue | C10: Deffered revenues | D10: -1068361 | E10: =SUMIF('JE - Inc'!A:A,'TB - Inc'!A10,'JE - Inc'!D:D) -> 0 | F10: =IFERROR(E10+D10,0) -> -1068361
A11: 25000 | B11: Intercompany- Talon Cyber Security LTD | C11: Intercompany | D11: -5426998.8 | E11: =SUMIF('JE - Inc'!A:A,'TB - Inc'!A11,'JE - Inc'!D:D) -> 2591896.7 | F11: =IFERROR(E11+D11,0) -> -2835102.1
A12: 60110 | B12: Sales Expenses:Salaries and Related Expenses:Gross Salary | C12: Sales - Salaries and social benefits | D12: 1824047.4 | E12: =SUMIF('JE - Inc'!A:A,'TB - Inc'!A12,'JE - Inc'!D:D) -> 0 | F12: =IFERROR(E12+D12,0) -> 1824047.4
A13: 60120 | B13: Sales Expenses:Salaries and Related Expenses:Vacation/PTO Expenses | C13: Sales - Salaries and social benefits | D13: 2746.51 | E13: =SUMIF('JE - Inc'!A:A,'TB - Inc'!A13,'JE - Inc'!D:D) -> 0 | F13: =IFERROR(E13+D13,0) -> 2746.51
A14: 60130 | B14: Sales Expenses:Salaries and Related Expenses:Employer Taxes | C14: Sales - Salaries and social benefits | D14: 211656.28 | E14: =SUMIF('JE - Inc'!A:A,'TB - Inc'!A14,'JE - Inc'!D:D) -> 0 | F14: =IFERROR(E14+D14,0) -> 211656.28
... A165: new85 | B165: TASKRAY | C165: Customer Success - Software Tools | D165: 9720 | E165: =SUMIF('JE - Inc'!A:A,'TB - Inc'!A165,'JE - Inc'!D:D) -> 0 | F165: =IFERROR(E165+D165,0) -> 9720
A166: New49 | B166: Subcontractors & Consulting | C166: G&A - Ongoing/random outsourced | E166: =SUMIF('JE - Inc'!A:A,'TB - Inc'!A166,'JE - Inc'!D:D) -> 100000 | F166: =IFERROR(E166+D166,0) -> 100000

Sheet JE - Inc
A2: Acc # | B2: Acc Name | D2: US$ | E2: מהות הפקודה
A4: 100201 | B4: =VLOOKUP(A4,'TB - Inc'!A:B,2,0) -> Engineering Expenses:Options - Engineering | D4: -1443.6 | E4: פקודת אופציות
A5: 62195 | B5: =VLOOKUP(A5,'TB - Inc'!A:B,2,0) -> Sales Expenses:Other:Sales - Options | D5: -1751
A6: 66165 | B6: =VLOOKUP(A6,'TB - Inc'!A:B,2,0) -> Business Operations Expenses:Other:Business Operations - Options | D6: 11.42
A7: 72275 | B7: =VLOOKUP(A7,'TB - Inc'!A:B,2,0) -> Marketing Expenses:Other:Marketing - Options | D7: -5021
A8: 82165 | B8: =VLOOKUP(A8,'TB - Inc'!A:B,2,0) -> Customer Success Expenses:Other:Customer Success - Options | D8: 2841.2
A9: 25000 | B9: =VLOOKUP(A9,'TB - Inc'!A:B,2,0) -> Intercompany- Talon Cyber Security LTD | D9: =-SUM(D4:D8) -> 5362.98
A11: New49 | B11: =VLOOKUP(A11,'TB - Inc'!A:B,2,0) -> Subcontractors & Consulting | D11: 100000 | E11: מיון הוצאה - ייעוץ פטנטים מארה"ב
A12: 93140 | B12: =VLOOKUP(A12,'TB - Inc'!A:B,2,0) -> G&A Expenses:Consultants & Service Providers:Consulting Expenes | D12: -100000
A14: 25000 | B14: =VLOOKUP(A14,'TB - Inc'!A:B,2,0) -> Intercompany- Talon Cyber Security LTD | D14: 2586533.7 | E14: Intercompany Q4
A15: 40500 | B15: =VLOOKUP(A15,'TB - Inc'!A:B,2,0) -> Revenue:Intercompany Revenue | D15: =-D14 -> -2586533.7

Sheet נסיעות לחו"ל
E2: Sensible
E3: 2013
E4: קובץ חישוב הוצאות לא מוכרות לצורך מס - נסיעות לחו"ל
E5: ב - $ של ארה"ב
E6: ראה תקרות למטה
I9: Total | J9: Car | K9: Hotel | U9: meals/ | W9: Hotel | X9: other | Y9: car | Z9: car
A10: Card No. | C10: Name | D10: תעריפים רגילים או תוספת 25% | E10: Country | F10: Departure date | G10: Return date | I10: days | J10: days | K10: days | L10: Hotel $ | M10: Telephone | N10: Transportation | O10: Meals | P10: אירוח | Q10: Other | R10: Other - ALLOWED EXPENSES | S10: Car | T10: מיון | U10: other | V10: Total | W10: disa | X10: disa | Y10: diss | Z10: days | AA10: Ticket | AB10: Total | AC10: Total NIS
V11: =SUM(L11:T11) -> 0 | AB11: =+AA11+V11 -> 0
A12: ="81700" -> 81700 | D12: רגיל | E12: USA | F12: 41522 | G12: 41527 | I12: =G12-F12+1 -> 6 | K12: =+I12-1 -> 5 | R12: =#REF! -> #REF! | U12: =O12+Q12 -> 0 | V12: =SUM(L12:T12) -> #REF! | W12: =IF(F12>0,ROUND(IF(K12<=7,IF(L12/K12<=תקרת_מלון_ל___7_ראשונים,0,L12-K12*תקרת_מלון_ל___7_ראשונים),IF(L12/K12<=תקרת_מלון_נמוכה,0,IF(L12/K12<=תקרת_מלון_גבוה,L12-7*L12/K12-(K12-7)*MAXA(תקרת_מלון_נמוכה,75%*L12/K12),(L12-7*MINA(L12/K12,תקרת_מלון_ל___7_ראשונים)-(K12-7)*MINA(75%*L12/K12,תקרת_מלון_גבוה))))),0),0) -> 0 | X12: =IF(L12>0,IF(U12/I12<תקרת_אשל_ליום___עם_לינה,0,U12-I12*תקרת_אשל_ליום___עם_לינה),IF(U12/I12<תקרת_אשל_ליום___ללא_לינה,0,U12-I12*תקרת_אשל_ליום___ללא_לינה)) -> 0 | Y12: =IF((S12-($E$66*Z12))>0,(S12-($E$66*Z12)),0) -> 0 | Z12: =J12 -> 0 | AB12: =+AA12+V12 -> #REF! | AC12: 783 | AD12: =AC12/AB12 -> #REF!
D13: רגיל | E13: USA | F13: 41522 | G13: 41527 | I13: =G13-F13+1 -> 6 | K13: =+I13-1 -> 5 | Q13: =#REF! -> #REF! | U13: =O13+Q13 -> #REF! | V13: =SUM(L13:T13) -> #REF! | W13: =IF(F13>0,ROUND(IF(K13<=7,IF(L13/K13<=תקרת_מלון_ל___7_ראשונים,0,L13-K13*תקרת_מלון_ל___7_ראשונים),IF(L13/K13<=תקרת_מלון_נמוכה,0,IF(L13/K13<=תקרת_מלון_גבוה,L13-7*L13/K13-(K13-7)*MAXA(תקרת_מלון_נמוכה,75%*L13/K13),(L13-7*MINA(L13/K13,תקרת_מלון_ל___7_ראשונים)-(K13-7)*MINA(75%*L13/K13,תקרת_מלון_גבוה))))),0),0) -> 0 | X13: =IF(L13>0,IF(U13/I13<תקרת_אשל_ליום___עם_לינה,0,U13-I13*תקרת_אשל_ליום___עם_לינה),IF(U13/I13<תקרת_אשל_ליום___ללא_לינה,0,U13-I13*תקרת_אשל_ליום___ללא_לינה)) -> #REF! | Y13: =IF((S13-($E$66*Z13))>0,(S13-($E$66*Z13)),0) -> 0 | Z13: =J13 -> 0 | AA13: =#REF!+#REF! -> #REF! | AB13: =+AA13+V13 -> #REF! | AC13: 11567 | AD13: =AC13/AB13 -> #REF!
D14: 25% יותר | E14: Italy, Germany | F14: 41297 | G14: 41301 | I14: =G14-F14+1 -> 5 | K14: =+I14-1 -> 4 | N14: =#REF! -> #REF! | Q14: =#REF!+#REF! -> #REF! | R14: =#REF! -> #REF! | U14: =O14+Q14 -> #REF! | V14: =SUM(L14:T14) -> #REF! | W14: =IF(F14>0,ROUND(IF(K14<=7,IF(L14/K14<=תקרת_מלון_ל___7_ראשונים,0,L14-K14*תקרת_מלון_ל___7_ראשונים),IF(L14/K14<=תקרת_מלון_נמוכה,0,IF(L14/K14<=תקרת_מלון_גבוה,L14-7*L14/K14-(K14-7)*MAXA(תקרת_מלון_נמוכה,75%*L14/K14),(L14-7*MINA(L14/K14,תקרת_מלון_ל___7_ראשונים)-(K14-7)*MINA(75%*L14/K14,תקרת_מלון_גבוה))))),0),0) -> 0 | X14: =IF(L14>0,IF(U14/I14<תקרת_אשל_ליום___עם_לינה,0,U14-I14*תקרת_אשל_ליום___עם_לינה),IF(U14/I14<תקרת_אשל_ליום___ללא_לינה,0,U14-I14*תקרת_אשל_ליום___ללא_לינה)) -> #REF! | Y14: =IF((S14-($E$66*Z14))>0,(S14-($E$66*Z14)),0) -> 0 | Z14: =J14 -> 0 | AA14: =#REF! -> #REF! | AB14: =+AA14+V14 -> #REF! | AC14: 6416 | AD14: =AC14/AB14 -> #REF!
D15: 25% יותר | E15: Germany, Spain | F15: 41319 | G15: 41326 | I15: =G15-F15+1 -> 8 | K15: =+I15-1 -> 7 | L15: =#REF!+#REF!+#REF!+#REF!+#REF! -> #REF! | M15: =#REF! -> #REF! | N15: =#REF! -> #REF! | Q15: =#REF! -> #REF! | U15: =O15+Q15 -> #REF! | V15: =SUM(L15:T15) -> #REF! | W15: =IF(F15>0,ROUND(IF(K15<=7,IF(L15/K15<=תקרת_מלון_ל___7_ראשונים,0,L15-K15*תקרת_מלון_ל___7_ראשונים),IF(L15/K15<=תקרת_מלון_נמוכה,0,IF(L15/K15<=תקרת_מלון_גבוה,L15-7*L15/K15-(K15-7)*MAXA(תקרת_מלון_נמוכה,75%*L15/K15),(L15-7*MINA(L15/K15,תקרת_מלון_ל___7_ראשונים)-(K15-7)*MINA(75%*L15/K15,תקרת_מלון_גבוה))))),0),0) -> #REF! | X15: =IF(L15>0,IF(U15/I15<תקרת_אשל_ליום___עם_לינה,0,U15-I15*תקרת_אשל_ליום___עם_לינה),IF(U15/I15<תקרת_אשל_ליום___ללא_לינה,0,U15-I15*תקרת_אשל_ליום___ללא_לינה)) -> #REF! | Y15: =IF((S15-($E$66*Z15))>0,(S15-($E$66*Z15)),0) -> 0 | Z15: =J15 -> 0 | AA15: =#REF!+#REF! -> #REF! | AB15: =+AA15+V15 -> #REF! | AC15: 12151 | AD15: =AC15/AB15 -> #REF!
D16: 25% יותר | E16: Germany | F16: 41382 | G16: 41389 | I16: =G16-F16+1 -> 8 | J16: 7 | K16: =+I16-1 -> 7 | N16: =#REF! -> #REF! | Q16: =#REF! -> #REF! | S16: =#REF! -> #REF! | U16: =O16+Q16 -> #REF! | V16: =SUM(L16:T16) -> #REF! | W16: =IF(F16>0,ROUND(IF(K16<=7,IF(L16/K16<=תקרת_מלון_ל___7_ראשונים,0,L16-K16*תקרת_מלון_ל___7_ראשונים),IF(L16/K16<=תקרת_מלון_נמוכה,0,IF(L16/K16<=תקרת_מלון_גבוה,L16-7*L16/K16-(K16-7)*MAXA(תקרת_מלון_נמוכה,75%*L16/K16),(L16-7*MINA(L16/K16,תקרת_מלון_ל___7_ראשונים)-(K16-7)*MINA(75%*L16/K16,תקרת_מלון_גבוה))))),0),0) -> 0 | X16: =IF(L16>0,IF(U16/I16<תקרת_אשל_ליום___עם_לינה,0,U16-I16*תקרת_אשל_ליום___עם_לינה),IF(U16/I16<תקרת_אשל_ליום___ללא_לינה,0,U16-I16*תקרת_אשל_ליום___ללא_לינה)) -> #REF! | Y16: =IF((S16-($E$66*Z16))>0,(S16-($E$66*Z16)),0) -> #REF! | Z16: =J16 -> 7 | AA16: =#REF! -> #REF! | AB16: =+AA16+V16 -> #REF! | AC16: 7574 | AD16: =AC16/AB16 -> #REF!
D17: 25% יותר | E17: Germany | F17: 41441 | G17: 41445 | I17: =G17-F17+1 -> 5 | J17: 4 | K17: =+I17-1 -> 4 | L17: =#REF! -> #REF! | Q17: =#REF! -> #REF! | S17: =#REF!+#REF! -> #REF! | U17: =O17+Q17 -> #REF! | V17: =SUM(L17:T17) -> #REF! | W17: =IF(F17>0,ROUND(IF(K17<=7,IF(L17/K17<=תקרת_מלון_ל___7_ראשונים,0,L17-K17*תקרת_מלון_ל___7_ראשונים),IF(L17/K17<=תקרת_מלון_נמוכה,0,IF(L17/K17<=תקרת_מלון_גבוה,L17-7*L17/K17-(K17-7)*MAXA(תקרת_מלון_נמוכה,75%*L17/K17),(L17-7*MINA(L17/K17,תקרת_מלון_ל___7_ראשונים)-(K17-7)*MINA(75%*L17/K17,תקרת_מלון_גבוה))))),0),0) -> #REF! | X17: =IF(L17>0,IF(U17/I17<תקרת_אשל_ליום___עם_לינה,0,U17-I17*תקרת_אשל_ליום___עם_לינה),IF(U17/I17<תקרת_אשל_ליום___ללא_לינה,0,U17-I17*תקרת_אשל_ליום___ללא_לינה)) -> #REF! | Y17: =IF((S17-($E$66*Z17))>0,(S17-($E$66*Z17)),0) -> #REF! | Z17: =J17 -> 4 | AA17: =#REF! -> #REF! | AB17: =+AA17+V17 -> #REF! | AC17: 6689 | AD17: =AC17/AB17 -> #REF!
D18: 25% יותר | E18: Germany | F18: 41485 | G18: 41488 | I18: =G18-F18+1 -> 4 | J18: 3 | K18: =+I18-1 -> 3 | L18: =#REF! -> #REF! | N18: =#REF! -> #REF! | Q18: =#REF!+#REF!+#REF! -> #REF! | S18: =#REF!+#REF! -> #REF! | U18: =O18+Q18 -> #REF! | V18: =SUM(L18:T18) -> #REF! | W18: =IF(F18>0,ROUND(IF(K18<=7,IF(L18/K18<=תקרת_מלון_ל___7_ראשונים,0,L18-K18*תקרת_מלון_ל___7_ראשונים),IF(L18/K18<=תקרת_מלון_נמוכה,0,IF(L18/K18<=תקרת_מלון_גבוה,L18-7*L18/K18-(K18-7)*MAXA(תקרת_מלון_נמוכה,75%*L18/K18),(L18-7*MINA(L18/K18,תקרת_מלון_ל___7_ראשונים)-(K18-7)*MINA(75%*L18/K18,תקרת_מלון_גבוה))))),0),0) -> #REF! | X18: =IF(L18>0,IF(U18/I18<תקרת_אשל_ליום___עם_לינה,0,U18-I18*תקרת_אשל_ליום___עם_לינה),IF(U18/I18<תקרת_אשל_ליום___ללא_לינה,0,U18-I18*תקרת_אשל_ליום___ללא_לינה)) -> #REF! | Y18: =IF((S18-($E$66*Z18))>0,(S18-($E$66*Z18)),0) -> #REF! | Z18: =J18 -> 3 | AA18: =#REF! -> #REF! | AB18: =+AA18+V18 -> #REF! | AC18: 8995 | AD18: =AC18/AB18 -> #REF!
D19: 25% יותר | E19: Germany | F19: 41532 | G19: 41536 | I19: =G19-F19+1 -> 5 | K19: =+I19-1 -> 4 | L19: =#REF! -> #REF! | R19: =#REF! -> #REF! | U19: =O19+Q19 -> 0 | V19: =SUM(L19:T19) -> #REF! | W19: =IF(F19>0,ROUND(IF(K19<=7,IF(L19/K19<=תקרת_מלון_ל___7_ראשונים,0,L19-K19*תקרת_מלון_ל___7_ראשונים),IF(L19/K19<=תקרת_מלון_נמוכה,0,IF(L19/K19<=תקרת_מלון_גבוה,L19-7*L19/K19-(K19-7)*MAXA(תקרת_מלון_נמוכה,75%*L19/K19),(L19-7*MINA(L19/K19,תקרת_מלון_ל___7_ראשונים)-(K19-7)*MINA(75%*L19/K19,תקרת_מלון_גבוה))))),0),0) -> #REF! | X19: =IF(L19>0,IF(U19/I19<תקרת_אשל_ליום___עם_לינה,0,U19-I19*תקרת_אשל_ליום___עם_לינה),IF(U19/I19<תקרת_אשל_ליום___ללא_לינה,0,U19-I19*תקרת_אשל_ליום___ללא_לינה)) -> #REF! | Y19: =IF((S19-($E$66*Z19))>0,(S19-($E$66*Z19)),0) -> 0 | Z19: =J19 -> 0 | AA19: =#REF!+#REF! -> #REF! | AB19: =+AA19+V19 -> #REF! | AC19: 4497 | AD19: =AC19/AB19 -> #REF!
D20: רגיל | E20: USA | F20: 41545 | G20: 41554 | I20: =G20-F20+1 -> 10 | K20: =+I20-1 -> 9 | L20: =#REF! -> #REF! | N20: =#REF! -> #REF! | Q20: =#REF! -> #REF! | U20: =O20+Q20 -> #REF! | V20: =SUM(L20:T20) -> #REF! | W20: =IF(F20>0,ROUND(IF(K20<=7,IF(L20/K20<=תקרת_מלון_ל___7_ראשונים,0,L20-K20*תקרת_מלון_ל___7_ראשונים),IF(L20/K20<=תקרת_מלון_נמוכה,0,IF(L20/K20<=תקרת_מלון_גבוה,L20-7*L20/K20-(K20-7)*MAXA(תקרת_מלון_נמוכה,75%*L20/K20),(L20-7*MINA(L20/K20,תקרת_מלון_ל___7_ראשונים)-(K20-7)*MINA(75%*L20/K20,תקרת_מלון_גבוה))))),0),0) -> #REF! | X20: =IF(L20>0,IF(U20/I20<תקרת_אשל_ליום___עם_לינה,0,U20-I20*תקרת_אשל_ליום___עם_לינה),IF(U20/I20<תקרת_אשל_ליום___ללא_לינה,0,U20-I20*תקרת_אשל_ליום___ללא_לינה)) -> #REF! | Y20: =IF((S20-($E$66*Z20))>0,(S20-($E$66*Z20)),0) -> 0 | Z20: =J20 -> 0 | AA20: =#REF! -> #REF! | AB20: =+AA20+V20 -> #REF! | AC20: 12549 | AD20: =AC20/AB20 -> #REF!
D21: 25% יותר | E21: Austria | F21: 41622 | G21: 41627 | I21: =G21-F21+1 -> 6 | J21: 5 | K21: =+I21-1 -> 5 | L21: =#REF! -> #REF! | R21: 860.83 | S21: =#REF! -> #REF! | U21: =O21+Q21 -> 0 | V21: =SUM(L21:T21) -> #REF! | W21: =IF(F21>0,ROUND(IF(K21<=7,IF(L21/K21<=תקרת_מלון_ל___7_ראשונים,0,L21-K21*תקרת_מלון_ל___7_ראשונים),IF(L21/K21<=תקרת_מלון_נמוכה,0,IF(L21/K21<=תקרת_מלון_גבוה,L21-7*L21/K21-(K21-7)*MAXA(תקרת_מלון_נמוכה,75%*L21/K21),(L21-7*MINA(L21/K21,תקרת_מלון_ל___7_ראשונים)-(K21-7)*MINA(75%*L21/K21,תקרת_מלון_גבוה))))),0),0) -> #REF! | X21: =IF(L21>0,IF(U21/I21<תקרת_אשל_ליום___עם_לינה,0,U21-I21*תקרת_אשל_ליום___עם_לינה),IF(U21/I21<תקרת_אשל_ליום___ללא_לינה,0,U21-I21*תקרת_אשל_ליום___ללא_לינה)) -> #REF! | Y21: =IF((S21-($E$66*Z21))>0,(S21-($E$66*Z21)),0) -> #REF! | Z21: =J21 -> 5 | AB21: =+AA21+V21 -> #REF! | AC21: 4072 | AD21: =AC21/AB21 -> #REF!
D22: 25% יותר | E22: Germany | F22: 41619 | G22: 41625 | I22: =G22-F22+1 -> 7 | J22: 6 | K22: =+I22-1 -> 6 | L22: =#REF! -> #REF! | M22: =#REF! -> #REF! | Q22: =#REF!+#REF! -> #REF! | S22: =#REF!+#REF! -> #REF! | U22: =O22+Q22 -> #REF! | V22: =SUM(L22:T22) -> #REF! | W22: =IF(F22>0,ROUND(IF(K22<=7,IF(L22/K22<=תקרת_מלון_ל___7_ראשונים,0,L22-K22*תקרת_מלון_ל___7_ראשונים),IF(L22/K22<=תקרת_מלון_נמוכה,0,IF(L22/K22<=תקרת_מלון_גבוה,L22-7*L22/K22-(K22-7)*MAXA(תקרת_מלון_נמוכה,75%*L22/K22),(L22-7*MINA(L22/K22,תקרת_מלון_ל___7_ראשונים)-(K22-7)*MINA(75%*L22/K22,תקרת_מלון_גבוה))))),0),0) -> #REF! | X22: =IF(L22>0,IF(U22/I22<תקרת_אשל_ליום___עם_לינה,0,U22-I22*תקרת_אשל_ליום___עם_לינה),IF(U22/I22<תקרת_אשל_ליום___ללא_לינה,0,U22-I22*תקרת_אשל_ליום___ללא_לינה)) -> #REF! | Y22: =IF((S22-($E$66*Z22))>0,(S22-($E$66*Z22)),0) -> #REF! | Z22: =J22 -> 6 | AB22: =+AA22+V22 -> #REF! | AC22: 5143 | AD22: =AC22/AB22 -> #REF!
D23: רגיל | E23: USA | F23: 41287 | G23: 41288 | I23: =G23-F23+1 -> 2 | K23: =+I23-1 -> 1 | L23: =#REF! -> #REF! | N23: =#REF! -> #REF! | O23: =#REF! -> #REF! | Q23: =#REF! -> #REF! | U23: =O23+Q23 -> #REF! | V23: =SUM(L23:T23) -> #REF! | W23: =IF(F23>0,ROUND(IF(K23<=7,IF(L23/K23<=תקרת_מלון_ל___7_ראשונים,0,L23-K23*תקרת_מלון_ל___7_ראשונים),IF(L23/K23<=תקרת_מלון_נמוכה,0,IF(L23/K23<=תקרת_מלון_גבוה,L23-7*L23/K23-(K23-7)*MAXA(תקרת_מלון_נמוכה,75%*L23/K23),(L23-7*MINA(L23/K23,תקרת_מלון_ל___7_ראשונים)-(K23-7)*MINA(75%*L23/K23,תקרת_מלון_גבוה))))),0),0) -> #REF! | X23: =IF(L23>0,IF(U23/I23<תקרת_אשל_ליום___עם_לינה,0,U23-I23*תקרת_אשל_ליום___עם_לינה),IF(U23/I23<תקרת_אשל_ליום___ללא_לינה,0,U23-I23*תקרת_אשל_ליום___ללא_לינה)) -> #REF! | Y23: =IF((S23-($E$66*Z23))>0,(S23-($E$66*Z23)),0) -> 0 | Z23: =J23 -> 0 | AA23: =#REF! -> #REF! | AB23: =+AA23+V23 -> #REF! | AC23: 11782 | AD23: =AC23/AB23 -> #REF!
D24: רגיל | E24: USA | F24: 41368 | G24: 41375 | I24: =G24-F24+1 -> 8 | J24: 7 | K24: =+I24-1 -> 7 | L24: =#REF!+#REF!+#REF! -> #REF! | M24: =#REF! -> #REF! | Q24: =#REF!+#REF! -> #REF! | S24: =#REF! -> #REF! | U24: =O24+Q24 -> #REF! | V24: =SUM(L24:T24) -> #REF! | W24: =IF(F24>0,ROUND(IF(K24<=7,IF(L24/K24<=תקרת_מלון_ל___7_ראשונים,0,L24-K24*תקרת_מלון_ל___7_ראשונים),IF(L24/K24<=תקרת_מלון_נמוכה,0,IF(L24/K24<=תקרת_מלון_גבוה,L24-7*L24/K24-(K24-7)*MAXA(תקרת_מלון_נמוכה,75%*L24/K24),(L24-7*MINA(L24/K24,תקרת_מלון_ל___7_ראשונים)-(K24-7)*MINA(75%*L24/K24,תקרת_מלון_גבוה))))),0),0) -> #REF! | X24: =IF(L24>0,IF(U24/I24<תקרת_אשל_ליום___עם_לינה,0,U24-I24*תקרת_אשל_ליום___עם_לינה),IF(U24/I24<תקרת_אשל_ליום___ללא_לינה,0,U24-I24*תקרת_אשל_ליום___ללא_לינה)) -> #REF! | Y24: =IF((S24-($E$66*Z24))>0,(S24-($E$66*Z24)),0) -> #REF! | Z24: =J24 -> 7 | AA24: =#REF! -> #REF! | AB24: =+AA24+V24 -> #REF! | AC24: 15834 | AD24: =AC24/AB24 -> #REF!
D25: רגיל | E25: USA | F25: 41492 | G25: 41495 | I25: =G25-F25+1 -> 4 | K25: =+I25-1 -> 3 | L25: =#REF!+#REF! -> #REF! | O25: =#REF! -> #REF! | Q25: =#REF! -> #REF! | U25: =O25+Q25 -> #REF! | V25: =SUM(L25:T25) -> #REF! | W25: =IF(F25>0,ROUND(IF(K25<=7,IF(L25/K25<=תקרת_מלון_ל___7_ראשונים,0,L25-K25*תקרת_מלון_ל___7_ראשונים),IF(L25/K25<=תקרת_מלון_נמוכה,0,IF(L25/K25<=תקרת_מלון_גבוה,L25-7*L25/K25-(K25-7)*MAXA(תקרת_מלון_נמוכה,75%*L25/K25),(L25-7*MINA(L25/K25,תקרת_מלון_ל___7_ראשונים)-(K25-7)*MINA(75%*L25/K25,תקרת_מלון_גבוה))))),0),0) -> #REF! | X25: =IF(L25>0,IF(U25/I25<תקרת_אשל_ליום___עם_לינה,0,U25-I25*תקרת_אשל_ליום___עם_לינה),IF(U25/I25<תקרת_אשל_ליום___ללא_לינה,0,U25-I25*תקרת_אשל_ליום___ללא_לינה)) -> #REF! | Y25: =IF((S25-($E$66*Z25))>0,(S25-($E$66*Z25)),0) -> 0 | Z25: =J25 -> 0 | AA25: =#REF!+#REF!+#REF!+#REF! -> #REF! | AB25: =+AA25+V25 -> #REF! | AC25: 15204 | AD25: =AC25/AB25 -> #REF!
D26: רגיל | E26: USA | F26: 41602 | G26: 41605 | I26: =G26-F26+1 -> 4 | K26: =+I26-1 -> 3 | L26: =#REF! -> #REF! | N26: =#REF! -> #REF! | Q26: =#REF! -> #REF! | U26: =O26+Q26 -> #REF! | V26: =SUM(L26:T26) -> #REF! | W26: =IF(F26>0,ROUND(IF(K26<=7,IF(L26/K26<=תקרת_מלון_ל___7_ראשונים,0,L26-K26*תקרת_מלון_ל___7_ראשונים),IF(L26/K26<=תקרת_מלון_נמוכה,0,IF(L26/K26<=תקרת_מלון_גבוה,L26-7*L26/K26-(K26-7)*MAXA(תקרת_מלון_נמוכה,75%*L26/K26),(L26-7*MINA(L26/K26,תקרת_מלון_ל___7_ראשונים)-(K26-7)*MINA(75%*L26/K26,תקרת_מלון_גבוה))))),0),0) -> #REF! | X26: =IF(L26>0,IF(U26/I26<תקרת_אשל_ליום___עם_לינה,0,U26-I26*תקרת_אשל_ליום___עם_לינה),IF(U26/I26<תקרת_אשל_ליום___ללא_לינה,0,U26-I26*תקרת_אשל_ליום___ללא_לינה)) -> #REF! | Y26: =IF((S26-($E$66*Z26))>0,(S26-($E$66*Z26)),0) -> 0 | Z26: =J26 -> 0 | AA26: =#REF! -> #REF! | AB26: =+AA26+V26 -> #REF! | AC26: 10679 | AD26: =AC26/AB26 -> #REF!
D27: רגיל | E27: USA | F27: 41592 | G27: 41594 | I27: =G27-F27+1 -> 3 | K27: =+I27-1 -> 2 | R27: =#REF! -> #REF! | U27: =O27+Q27 -> 0 | V27: =SUM(L27:T27) -> #REF! | W27: =IF(F27>0,ROUND(IF(K27<=7,IF(L27/K27<=תקרת_מלון_ל___7_ראשונים,0,L27-K27*תקרת_מלון_ל___7_ראשונים),IF(L27/K27<=תקרת_מלון_נמוכה,0,IF(L27/K27<=תקרת_מלון_גבוה,L27-7*L27/K27-(K27-7)*MAXA(תקרת_מלון_נמוכה,75%*L27/K27),(L27-7*MINA(L27/K27,תקרת_מלון_ל___7_ראשונים)-(K27-7)*MINA(75%*L27/K27,תקרת_מלון_גבוה))))),0),0) -> 0 | X27: =IF(L27>0,IF(U27/I27<תקרת_אשל_ליום___עם_לינה,0,U27-I27*תקרת_אשל_ליום___עם_לינה),IF(U27/I27<תקרת_אשל_ליום___ללא_לינה,0,U27-I27*תקרת_אשל_ליום___ללא_לינה)) -> 0 | Y27: =IF((S27-($E$66*Z27))>0,(S27-($E$66*Z27)),0) -> 0 | Z27: =J27 -> 0 | AB27: =AA27+V27 -> #REF! | AC27: 3054.54 | AD27: =AC27/AB27 -> #REF!
D28: רגיל | E28: USA | F28: 41287 | G28: 41290 | I28: =G28-F28+1 -> 4 | K28: =+I28-1 -> 3 | L28: =#REF! -> #REF! | N28: =#REF!+#REF!+#REF! -> #REF! | O28: =#REF! -> #REF! | Q28: =#REF!+#REF!+#REF! -> #REF! | R28: =#REF!+#REF!+#REF! -> #REF! | U28: =O28+Q28 -> #REF! | V28: =SUM(L28:T28) -> #REF! | W28: =IF(F28>0,ROUND(IF(K28<=7,IF(L28/K28<=תקרת_מלון_ל___7_ראשונים,0,L28-K28*תקרת_מלון_ל___7_ראשונים),IF(L28/K28<=תקרת_מלון_נמוכה,0,IF(L28/K28<=תקרת_מלון_גבוה,L28-7*L28/K28-(K28-7)*MAXA(תקרת_מלון_נמוכה,75%*L28/K28),(L28-7*MINA(L28/K28,תקרת_מלון_ל___7_ראשונים)-(K28-7)*MINA(75%*L28/K28,תקרת_מלון_גבוה))))),0),0) -> #REF! | X28: =IF(L28>0,IF(U28/I28<תקרת_אשל_ליום___עם_לינה,0,U28-I28*תקרת_אשל_ליום___עם_לינה),IF(U28/I28<תקרת_אשל_ליום___ללא_לינה,0,U28-I28*תקרת_אשל_ליום___ללא_לינה)) -> #REF! | Y28: =IF((S28-($E$66*Z28))>0,(S28-($E$66*Z28)),0) -> 0 | Z28: =J28 -> 0 | AA28: =#REF! -> #REF! | AB28: =+AA28+V28 -> #REF! | AC28: 18233 | AD28: =AC28/AB28 -> #REF!
D29: 25% יותר | E29: Italy, Germany | F29: 41297 | G29: 41301 | I29: =G29-F29+1 -> 5 | J29: 4 | K29: =+I29-1 -> 4 | L29: =#REF!+#REF!+#REF!+#REF!+#REF! -> #REF! | N29: =#REF!+#REF! -> #REF! | O29: =#REF!+#REF!+#REF! -> #REF! | P29: =#REF! -> #REF! | Q29: =#REF! -> #REF! | R29: =#REF! -> #REF! | S29: =#REF! -> #REF! | U29: =O29+Q29 -> #REF! | V29: =SUM(L29:T29) -> #REF! | W29: =IF(F29>0,ROUND(IF(K29<=7,IF(L29/K29<=תקרת_מלון_ל___7_ראשונים,0,L29-K29*תקרת_מלון_ל___7_ראשונים),IF(L29/K29<=תקרת_מלון_נמוכה,0,IF(L29/K29<=תקרת_מלון_גבוה,L29-7*L29/K29-(K29-7)*MAXA(תקרת_מלון_נמוכה,75%*L29/K29),(L29-7*MINA(L29/K29,תקרת_מלון_ל___7_ראשונים)-(K29-7)*MINA(75%*L29/K29,תקרת_מלון_גבוה))))),0),0) -> #REF! | X29: =IF(L29>0,IF(U29/I29<תקרת_אשל_ליום___עם_לינה,0,U29-I29*תקרת_אשל_ליום___עם_לינה),IF(U29/I29<תקרת_אשל_ליום___ללא_לינה,0,U29-I29*תקרת_אשל_ליום___ללא_לינה)) -> #REF! | Y29: =IF((S29-($E$66*Z29))>0,(S29-($E$66*Z29)),0) -> #REF! | Z29: =J29 -> 4 | AA29: =#REF!+#REF! -> #REF! | AB29: =+AA29+V29 -> #REF! | AC29: 14562 | AD29: =AC29/AB29 -> #REF!
D30: 25% יותר | E30: Italy, Germany | F30: 41296 | G30: 41300 | I30: =G30-F30+1 -> 5 | J30: 4 | K30: =+I30-1 -> 4 | N30: =#REF! -> #REF! | Q30: =#REF!+#REF! -> #REF! | R30: =#REF! -> #REF! | S30: =#REF! -> #REF! | U30: =O30+Q30 -> #REF! | V30: =SUM(L30:T30) -> #REF! | W30: =IF(F30>0,ROUND(IF(K30<=7,IF(L30/K30<=תקרת_מלון_ל___7_ראשונים,0,L30-K30*תקרת_מלון_ל___7_ראשונים),IF(L30/K30<=תקרת_מלון_נמוכה,0,IF(L30/K30<=תקרת_מלון_גבוה,L30-7*L30/K30-(K30-7)*MAXA(תקרת_מלון_נמוכה,75%*L30/K30),(L30-7*MINA(L30/K30,תקרת_מלון_ל___7_ראשונים)-(K30-7)*MINA(75%*L30/K30,תקרת_מלון_גבוה))))),0),0) -> 0 | X30: =IF(L30>0,IF(U30/I30<תקרת_אשל_ליום___עם_לינה,0,U30-I30*תקרת_אשל_ליום___עם_לינה),IF(U30/I30<תקרת_אשל_ליום___ללא_לינה,0,U30-I30*תקרת_אשל_ליום___ללא_לינה)) -> #REF! | Y30: =IF((S30-($E$66*Z30))>0,(S30-($E$66*Z30)),0) -> #REF! | Z30: =J30 -> 4 | AA30: =#REF! -> #REF! | AB30: =+AA30+V30 -> #REF! | AC30: 6552 | AD30: =AC30/AB30 -> #REF!
D31: 25% יותר | E31: Italy, Germany | F31: 41319 | G31: 41327 | I31: =G31-F31+1 -> 9 | J31: 8 | K31: =+I31-1 -> 8 | L31: =#REF!+#REF!+#REF!+#REF! -> #REF! | N31: =#REF! -> #REF! | O31: =#REF! -> #REF! | P31: =#REF!+#REF!+#REF! -> #REF! | Q31: =#REF!+#REF!+#REF! -> #REF! | R31: =#REF! -> #REF! | S31: =#REF!+#REF!+#REF! -> #REF! | U31: =O31+Q31 -> #REF! | V31: =SUM(L31:T31) -> #REF! | W31: =IF(F31>0,ROUND(IF(K31<=7,IF(L31/K31<=תקרת_מלון_ל___7_ראשונים,0,L31-K31*תקרת_מלון_ל___7_ראשונים),IF(L31/K31<=תקרת_מלון_נמוכה,0,IF(L31/K31<=תקרת_מלון_גבוה,L31-7*L31/K31-(K31-7)*MAXA(תקרת_מלון_נמוכה,75%*L31/K31),(L31-7*MINA(L31/K31,תקרת_מלון_ל___7_ראשונים)-(K31-7)*MINA(75%*L31/K31,תקרת_מלון_גבוה))))),0),0) -> #REF! | X31: =IF(L31>0,IF(U31/I31<תקרת_אשל_ליום___עם_לינה,0,U31-I31*תקרת_אשל_ליום___עם_לינה),IF(U31/I31<תקרת_אשל_ליום___ללא_לינה,0,U31-I31*תקרת_אשל_ליום___ללא_לינה)) -> #REF! | Y31: =IF((S31-($E$66*Z31))>0,(S31-($E$66*Z31)),0) -> #REF! | Z31: =J31 -> 8 | AA31: =#REF!+#REF! -> #REF! | AB31: =+AA31+V31 -> #REF! | AC31: 17873 | AD31: =AC31/AB31 -> #REF!
D32: 25% יותר | E32: Germany, Spain | F32: 41319 | G32: 41327 | I32: =G32-F32+1 -> 9 | J32: 8 | K32: =+I32-1 -> 8 | L32: =#REF!+#REF!+#REF!+#REF! -> #REF! | Q32: =#REF! -> #REF! | R32: =#REF! -> #REF! | S32: =#REF! -> #REF! | U32: =O32+Q32 -> #REF! | V32: =SUM(L32:T32) -> #REF! | W32: =IF(F32>0,ROUND(IF(K32<=7,IF(L32/K32<=תקרת_מלון_ל___7_ראשונים,0,L32-K32*תקרת_מלון_ל___7_ראשונים),IF(L32/K32<=תקרת_מלון_נמוכה,0,IF(L32/K32<=תקרת_מלון_גבוה,L32-7*L32/K32-(K32-7)*MAXA(תקרת_מלון_נמוכה,75%*L32/K32),(L32-7*MINA(L32/K32,תקרת_מלון_ל___7_ראשונים)-(K32-7)*MINA(75%*L32/K32,תקרת_מלון_גבוה))))),0),0) -> #REF! | X32: =IF(L32>0,IF(U32/I32<תקרת_אשל_ליום___עם_לינה,0,U32-I32*תקרת_אשל_ליום___עם_לינה),IF(U32/I32<תקרת_אשל_ליום___ללא_לינה,0,U32-I32*תקרת_אשל_ליום___ללא_לינה)) -> #REF! | Y32: =IF((S32-($E$66*Z32))>0,(S32-($E$66*Z32)),0) -> #REF! | Z32: =J32 -> 8 | AA32: =#REF!+#REF! -> #REF! | AB32: =+AA32+V32 -> #REF! | AC32: 13118 | AD32: =AC32/AB32 -> #REF!
