Workbook
Name \0: #REF!
Name \a: #REF!
Name \B: #REF!
Name \C: '[1]טורים 98'!$HJ$154
Name \D: #REF!
Name \E: '[1]טורים 98'!$HJ$155
Name \F: #REF!
Name \G: #REF!
Name \H: #REF!
Name \I: #REF!
Name \J: #REF!
Name \K: #REF!
Name \L: #REF!
Name \M: #REF!
Name \M2: #REF!
Name \N: #REF!
Name \O: #REF!
Name \P: #REF!
Name \Q: '[1]טורים 98'!$HJ$127
Name \R: #REF!
Name \S: #REF!
Name \T: #REF!
Name \U: #REF!
Name \V: #REF!
Name \W: #REF!
Name \X: '[1]טורים 98'!$HJ$146
Name \Y: #REF!
Name \Z: #REF!
Name _____________YR5: '[2]T3.1 Comp Allocation-FY 99'!#REF!
Name ____________YR5: '[2]T3.1 Comp Allocation-FY 99'!#REF!
Name ___________YR5: '[2]T3.1 Comp Allocation-FY 99'!#REF!
Name __________YR5: '[2]T3.1 Comp Allocation-FY 99'!#REF!
Name _________YR5: '[2]T3.1 Comp Allocation-FY 99'!#REF!
Name ________YR5: '[2]T3.1 Comp Allocation-FY 99'!#REF!
Name ______YR5: '[2]T3.1 Comp Allocation-FY 99'!#REF!
Name ____YR5: '[2]T3.1 Comp Allocation-FY 99'!#REF!
Name ___A1: #N/A
Name ___A2: #N/A
Name ___A3: #N/A
Name ___A4: #N/A
Name ___A5: #N/A
Name ___A6: #N/A
Name ___A7: #N/A
Name ___fsi1: #REF!
Name ___fsi10: #REF!
Name ___fsi11: #REF!
Name ___fsi19: #REF!
Name ___fsi2: #REF!
Name ___fsi20: #REF!
Name ___fsi3: #REF!
Name ___fsi30: #REF!
Name ___fsi5: #REF!
Name ___HOA1: #N/A
Name ___HOA2: #N/A
Name ___HOA3: #N/A
Name ___HOA4: #N/A
Name ___HOA5: #N/A
Name ___HOA6: #N/A
Name ___HOA7: #N/A
Name ___ILF2000: #REF!

Sheet Index
A1: Entity # | B1: Entity | D1: Account # | E1: Accounts | G1: Sub-Account # | H1: Sub-Account | J1: Sub-Department # | K1: Sub-Department | M1: Entity # | N1: Entity | O1: TB # | P1: Account/Department | Q1: Account # | R1: Sub-Account | S1: Sub-Account # | T1: Sub-Department | U1: Sub-Department # | V1: GL # | X1: Entity # | Y1: Entity | Z1: TB # | AA1: Account/Department | AB1: Account # | AC1: Sub-Account | AD1: Sub-Account # | AE1: Sub-Department | AF1: Sub-Department # | AG1: GL #
A2: 1 | B2: Ltd | D2: 1 | E2: Cash and Cash Equivalents | G2: 100 | H2: Accrued Expenses | J2: 41 | K2: Dev | M2: =_xlfn.SINGLE(_xlfn.XLOOKUP(N2,B:B,A:A,0,0,1)) -> 1 | N2: Ltd | O2: 10002 | P2: Cash and Cash Equivalents | Q2: =_xlfn.SINGLE(_xlfn.XLOOKUP(P2,E:E,D:D,0,0,1)) -> 1 | S2: =_xlfn.SINGLE(_xlfn.XLOOKUP(R2,H:H,G:G,0,0,1)) -> 0 | U2: =_xlfn.SINGLE(_xlfn.XLOOKUP(T2,K:K,J:J,0,0,1)) -> 0 | V2: =M2&O2&Q2&S2&U2 -> 110002100 | X2: =_xlfn.SINGLE(_xlfn.XLOOKUP(Y2,B:B,A:A,0,0,1)) -> 2 | Y2: Inc | Z2: 10000 | AA2: Cash and Cash Equivalents | AB2: =_xlfn.SINGLE(_xlfn.XLOOKUP(AA2,E:E,D:D,0,0,1)) -> 1 | AD2: =_xlfn.SINGLE(_xlfn.XLOOKUP(AC2,H:H,G:G,0,0,1)) -> 0 | AF2: =_xlfn.SINGLE(_xlfn.XLOOKUP(AE2,K:K,J:J,0,0,1)) -> 0 | AG2: =X2&Z2&AB2&AD2&AF2 -> 210000100
A3: 2 | B3: Inc | D3: 2 | E3: Accounts Receivable | G3: 101 | H3: Channel Marketing | J3: 42 | K3: Product | M3: =_xlfn.SINGLE(_xlfn.XLOOKUP(N3,B:B,A:A,0,0,1)) -> 1 | N3: Ltd | O3: 10003 | P3: Cash and Cash Equivalents | Q3: =_xlfn.SINGLE(_xlfn.XLOOKUP(P3,E:E,D:D,0,0,1)) -> 1 | S3: =_xlfn.SINGLE(_xlfn.XLOOKUP(R3,H:H,G:G,0,0,1)) -> 0 | U3: =_xlfn.SINGLE(_xlfn.XLOOKUP(T3,K:K,J:J,0,0,1)) -> 0 | V3: =M3&O3&Q3&S3&U3 -> 110003100 | X3: =_xlfn.SINGLE(_xlfn.XLOOKUP(Y3,B:B,A:A,0,0,1)) -> 2 | Y3: Inc | Z3: 10005 | AA3: Cash and Cash Equivalents | AB3: =_xlfn.SINGLE(_xlfn.XLOOKUP(AA3,E:E,D:D,0,0,1)) -> 1 | AC3: Restricted Cash | AD3: =_xlfn.SINGLE(_xlfn.XLOOKUP(AC3,H:H,G:G,0,0,1)) -> 120 | AF3: =_xlfn.SINGLE(_xlfn.XLOOKUP(AE3,K:K,J:J,0,0,1)) -> 0 | AG3: =X3&Z3&AB3&AD3&AF3 -> 21000511200
D4: 3 | E4: Prepaid expenses and other receivable | G4: 102 | H4: Contractors & Services | J4: 43 | K4: Labs | M4: =_xlfn.SINGLE(_xlfn.XLOOKUP(N4,B:B,A:A,0,0,1)) -> 1 | N4: Ltd | O4: 10004 | P4: Cash and Cash Equivalents | Q4: =_xlfn.SINGLE(_xlfn.XLOOKUP(P4,E:E,D:D,0,0,1)) -> 1 | S4: =_xlfn.SINGLE(_xlfn.XLOOKUP(R4,H:H,G:G,0,0,1)) -> 0 | U4: =_xlfn.SINGLE(_xlfn.XLOOKUP(T4,K:K,J:J,0,0,1)) -> 0 | V4: =M4&O4&Q4&S4&U4 -> 110004100 | X4: =_xlfn.SINGLE(_xlfn.XLOOKUP(Y4,B:B,A:A,0,0,1)) -> 2 | Y4: Inc | Z4: 10010 | AA4: Cash and Cash Equivalents | AB4: =_xlfn.SINGLE(_xlfn.XLOOKUP(AA4,E:E,D:D,0,0,1)) -> 1 | AC4: Short Term Deposits | AD4: =_xlfn.SINGLE(_xlfn.XLOOKUP(AC4,H:H,G:G,0,0,1)) -> 122 | AF4: =_xlfn.SINGLE(_xlfn.XLOOKUP(AE4,K:K,J:J,0,0,1)) -> 0 | AG4: =X4&Z4&AB4&AD4&AF4 -> 21001011220
D5: 4 | E5: Fixed Assets | G5: 103 | H5: Credit Cards | M5: =_xlfn.SINGLE(_xlfn.XLOOKUP(N5,B:B,A:A,0,0,1)) -> 1 | N5: Ltd | O5: 10007 | P5: Cash and Cash Equivalents | Q5: =_xlfn.SINGLE(_xlfn.XLOOKUP(P5,E:E,D:D,0,0,1)) -> 1 | S5: =_xlfn.SINGLE(_xlfn.XLOOKUP(R5,H:H,G:G,0,0,1)) -> 0 | U5: =_xlfn.SINGLE(_xlfn.XLOOKUP(T5,K:K,J:J,0,0,1)) -> 0 | V5: =M5&O5&Q5&S5&U5 -> 110007100 | X5: =_xlfn.SINGLE(_xlfn.XLOOKUP(Y5,B:B,A:A,0,0,1)) -> 2 | Y5: Inc | Z5: 10011 | AA5: Cash and Cash Equivalents | AB5: =_xlfn.SINGLE(_xlfn.XLOOKUP(AA5,E:E,D:D,0,0,1)) -> 1 | AC5: Short Term Deposits | AD5: =_xlfn.SINGLE(_xlfn.XLOOKUP(AC5,H:H,G:G,0,0,1)) -> 122 | AF5: =_xlfn.SINGLE(_xlfn.XLOOKUP(AE5,K:K,J:J,0,0,1)) -> 0 | AG5: =X5&Z5&AB5&AD5&AF5 -> 21001111220
D6: 5 | E6: Intercompany | G6: 104 | H6: Deposits | M6: =_xlfn.SINGLE(_xlfn.XLOOKUP(N6,B:B,A:A,0,0,1)) -> 1 | N6: Ltd | O6: 10008 | P6: Prepaid expenses and other receivable | Q6: =_xlfn.SINGLE(_xlfn.XLOOKUP(P6,E:E,D:D,0,0,1)) -> 3 | R6: Deposits | S6: =_xlfn.SINGLE(_xlfn.XLOOKUP(R6,H:H,G:G,0,0,1)) -> 104 | U6: =_xlfn.SINGLE(_xlfn.XLOOKUP(T6,K:K,J:J,0,0,1)) -> 0 | V6: =M6&O6&Q6&S6&U6 -> 11000831040 | X6: =_xlfn.SINGLE(_xlfn.XLOOKUP(Y6,B:B,A:A,0,0,1)) -> 2 | Y6: Inc | Z6: 10999 | AA6: Overhead | AB6: =_xlfn.SINGLE(_xlfn.XLOOKUP(AA6,E:E,D:D,0,0,1)) -> 99 | AD6: =_xlfn.SINGLE(_xlfn.XLOOKUP(AC6,H:H,G:G,0,0,1)) -> 0 | AF6: =_xlfn.SINGLE(_xlfn.XLOOKUP(AE6,K:K,J:J,0,0,1)) -> 0 | AG6: =X6&Z6&AB6&AD6&AF6 -> 2109999900
D7: 6 | E7: Accounts Payable | G7: 105 | H7: Digital Marketing | M7: =_xlfn.SINGLE(_xlfn.XLOOKUP(N7,B:B,A:A,0,0,1)) -> 1 | N7: Ltd | O7: 10012 | P7: Prepaid expenses and other receivable | Q7: =_xlfn.SINGLE(_xlfn.XLOOKUP(P7,E:E,D:D,0,0,1)) -> 3 | R7: Deposits | S7: =_xlfn.SINGLE(_xlfn.XLOOKUP(R7,H:H,G:G,0,0,1)) -> 104 | U7: =_xlfn.SINGLE(_xlfn.XLOOKUP(T7,K:K,J:J,0,0,1)) -> 0 | V7: =M7&O7&Q7&S7&U7 -> 11001231040 | X7: =_xlfn.SINGLE(_xlfn.XLOOKUP(Y7,B:B,A:A,0,0,1)) -> 2 | Y7: Inc | Z7: 11000 | AA7: Accounts Receivable | AB7: =_xlfn.SINGLE(_xlfn.XLOOKUP(AA7,E:E,D:D,0,0,1)) -> 2 | AD7: =_xlfn.SINGLE(_xlfn.XLOOKUP(AC7,H:H,G:G,0,0,1)) -> 0 | AF7: =_xlfn.SINGLE(_xlfn.XLOOKUP(AE7,K:K,J:J,0,0,1)) -> 0 | AG7: =X7&Z7&AB7&AD7&AF7 -> 211000200
D8: 7 | E8: Accrued expenses and other payable | G8: 106 | H8: Events & Conferences | M8: =_xlfn.SINGLE(_xlfn.XLOOKUP(N8,B:B,A:A,0,0,1)) -> 1 | N8: Ltd | O8: 10013 | P8: Prepaid expenses and other receivable | Q8: =_xlfn.SINGLE(_xlfn.XLOOKUP(P8,E:E,D:D,0,0,1)) -> 3 | R8: Deposits | S8: =_xlfn.SINGLE(_xlfn.XLOOKUP(R8,H:H,G:G,0,0,1)) -> 104 | U8: =_xlfn.SINGLE(_xlfn.XLOOKUP(T8,K:K,J:J,0,0,1)) -> 0 | V8: =M8&O8&Q8&S8&U8 -> 11001331040 | X8: =_xlfn.SINGLE(_xlfn.XLOOKUP(Y8,B:B,A:A,0,0,1)) -> 2 | Y8: Inc | Z8: 12500 | AA8: Prepaid expenses and other receivable | AB8: =_xlfn.SINGLE(_xlfn.XLOOKUP(AA8,E:E,D:D,0,0,1)) -> 3 | AC8: Prepaid Expenses | AD8: =_xlfn.SINGLE(_xlfn.XLOOKUP(AC8,H:H,G:G,0,0,1)) -> 118 | AF8: =_xlfn.SINGLE(_xlfn.XLOOKUP(AE8,K:K,J:J,0,0,1)) -> 0 | AG8: =X8&Z8&AB8&AD8&AF8 -> 21250031180
D9: 8 | E9: Employees Payable | G9: 107 | H9: Field Marketing | M9: =_xlfn.SINGLE(_xlfn.XLOOKUP(N9,B:B,A:A,0,0,1)) -> 1 | N9: Ltd | O9: 10014 | P9: Cash and Cash Equivalents | Q9: =_xlfn.SINGLE(_xlfn.XLOOKUP(P9,E:E,D:D,0,0,1)) -> 1 | S9: =_xlfn.SINGLE(_xlfn.XLOOKUP(R9,H:H,G:G,0,0,1)) -> 0 | U9: =_xlfn.SINGLE(_xlfn.XLOOKUP(T9,K:K,J:J,0,0,1)) -> 0 | V9: =M9&O9&Q9&S9&U9 -> 110014100 | X9: =_xlfn.SINGLE(_xlfn.XLOOKUP(Y9,B:B,A:A,0,0,1)) -> 2 | Y9: Inc | Z9: 12505 | AA9: Prepaid expenses and other receivable | AB9: =_xlfn.SINGLE(_xlfn.XLOOKUP(AA9,E:E,D:D,0,0,1)) -> 3 | AC9: Prepaid Expenses | AD9: =_xlfn.SINGLE(_xlfn.XLOOKUP(AC9,H:H,G:G,0,0,1)) -> 118 | AF9: =_xlfn.SINGLE(_xlfn.XLOOKUP(AE9,K:K,J:J,0,0,1)) -> 0 | AG9: =X9&Z9&AB9&AD9&AF9 -> 21250531180
D10: 9 | E10: Deferred Revenue | G10: 108 | H10: Hosting | M10: =_xlfn.SINGLE(_xlfn.XLOOKUP(N10,B:B,A:A,0,0,1)) -> 1 | N10: Ltd | O10: 10016 | P10: Cash and Cash Equivalents | Q10: =_xlfn.SINGLE(_xlfn.XLOOKUP(P10,E:E,D:D,0,0,1)) -> 1 | R10: Short Term deposits | S10: =_xlfn.SINGLE(_xlfn.XLOOKUP(R10,H:H,G:G,0,0,1)) -> 122 | U10: =_xlfn.SINGLE(_xlfn.XLOOKUP(T10,K:K,J:J,0,0,1)) -> 0 | V10: =M10&O10&Q10&S10&U10 -> 11001611220 | X10: =_xlfn.SINGLE(_xlfn.XLOOKUP(Y10,B:B,A:A,0,0,1)) -> 2 | Y10: Inc | Z10: 12510 | AA10: Prepaid expenses and other receivable | AB10: =_xlfn.SINGLE(_xlfn.XLOOKUP(AA10,E:E,D:D,0,0,1)) -> 3 | AC10: Prepaid Expenses | AD10: =_xlfn.SINGLE(_xlfn.XLOOKUP(AC10,H:H,G:G,0,0,1)) -> 118 | AF10: =_xlfn.SINGLE(_xlfn.XLOOKUP(AE10,K:K,J:J,0,0,1)) -> 0 | AG10: =X10&Z10&AB10&AD10&AF10 -> 21251031180
D11: 10 | E11: Capital Stock | G11: 109 | H11: Institutions | M11: =_xlfn.SINGLE(_xlfn.XLOOKUP(N11,B:B,A:A,0,0,1)) -> 1 | N11: Ltd | O11: 10017 | P11: Prepaid expenses and other receivable | Q11: =_xlfn.SINGLE(_xlfn.XLOOKUP(P11,E:E,D:D,0,0,1)) -> 3 | R11: Deposits | S11: =_xlfn.SINGLE(_xlfn.XLOOKUP(R11,H:H,G:G,0,0,1)) -> 104 | U11: =_xlfn.SINGLE(_xlfn.XLOOKUP(T11,K:K,J:J,0,0,1)) -> 0 | V11: =M11&O11&Q11&S11&U11 -> 11001731040 | X11: =_xlfn.SINGLE(_xlfn.XLOOKUP(Y11,B:B,A:A,0,0,1)) -> 2 | Y11: Inc | Z11: 12515 | AA11: Prepaid expenses and other receivable | AB11: =_xlfn.SINGLE(_xlfn.XLOOKUP(AA11,E:E,D:D,0,0,1)) -> 3 | AC11: Prepaid Expenses | AD11: =_xlfn.SINGLE(_xlfn.XLOOKUP(AC11,H:H,G:G,0,0,1)) -> 118 | AF11: =_xlfn.SINGLE(_xlfn.XLOOKUP(AE11,K:K,J:J,0,0,1)) -> 0 | AG11: =X11&Z11&AB11&AD11&AF11 -> 21251531180
D12: 11 | E12: Additional Paid In Capital | G12: 110 | H12: Legal Services | M12: =_xlfn.SINGLE(_xlfn.XLOOKUP(N12,B:B,A:A,0,0,1)) -> 1 | N12: Ltd | O12: 10018 | P12: Prepaid expenses and other receivable | Q12: =_xlfn.SINGLE(_xlfn.XLOOKUP(P12,E:E,D:D,0,0,1)) -> 3 | R12: Deposits | S12: =_xlfn.SINGLE(_xlfn.XLOOKUP(R12,H:H,G:G,0,0,1)) -> 104 | U12: =_xlfn.SINGLE(_xlfn.XLOOKUP(T12,K:K,J:J,0,0,1)) -> 0 | V12: =M12&O12&Q12&S12&U12 -> 11001831040 | X12: =_xlfn.SINGLE(_xlfn.XLOOKUP(Y12,B:B,A:A,0,0,1)) -> 2 | Y12: Inc | Z12: 12516 | AA12: Prepaid expenses and other receivable | AB12: =_xlfn.SINGLE(_xlfn.XLOOKUP(AA12,E:E,D:D,0,0,1)) -> 3 | AC12: Prepaid R&D exp. | AD12: =_xlfn.SINGLE(_xlfn.XLOOKUP(AC12,H:H,G:G,0,0,1)) -> 129 | AF12: =_xlfn.SINGLE(_xlfn.XLOOKUP(AE12,K:K,J:J,0,0,1)) -> 0 | AG12: =X12&Z12&AB12&AD12&AF12 -> 21251631290
D13: 12 | E13: Accumulated Comprehensive Income | G13: 111 | H13: Other Finance | M13: =_xlfn.SINGLE(_xlfn.XLOOKUP(N13,B:B,A:A,0,0,1)) -> 1 | N13: Ltd | O13: 10019 | P13: Prepaid expenses and other receivable | Q13: =_xlfn.SINGLE(_xlfn.XLOOKUP(P13,E:E,D:D,0,0,1)) -> 3 | R13: Deposits | S13: =_xlfn.SINGLE(_xlfn.XLOOKUP(R13,H:H,G:G,0,0,1)) -> 104 | U13: =_xlfn.SINGLE(_xlfn.XLOOKUP(T13,K:K,J:J,0,0,1)) -> 0 | V13: =M13&O13&Q13&S13&U13 -> 11001931040 | X13: =_xlfn.SINGLE(_xlfn.XLOOKUP(Y13,B:B,A:A,0,0,1)) -> 2 | Y13: Inc | Z13: 16000 | AA13: Intercompany | AB13: =_xlfn.SINGLE(_xlfn.XLOOKUP(AA13,E:E,D:D,0,0,1)) -> 5 | AD13: =_xlfn.SINGLE(_xlfn.XLOOKUP(AC13,H:H,G:G,0,0,1)) -> 0 | AF13: =_xlfn.SINGLE(_xlfn.XLOOKUP(AE13,K:K,J:J,0,0,1)) -> 0 | AG13: =X13&Z13&AB13&AD13&AF13 -> 216000500
D14: 13 | E14: Retained Loss | G14: 112 | H14: Other HR | M14: =_xlfn.SINGLE(_xlfn.XLOOKUP(N14,B:B,A:A,0,0,1)) -> 1 | N14: Ltd | O14: 10020 | P14: Prepaid expenses and other receivable | Q14: =_xlfn.SINGLE(_xlfn.XLOOKUP(P14,E:E,D:D,0,0,1)) -> 3 | R14: Deposits | S14: =_xlfn.SINGLE(_xlfn.XLOOKUP(R14,H:H,G:G,0,0,1)) -> 104 | U14: =_xlfn.SINGLE(_xlfn.XLOOKUP(T14,K:K,J:J,0,0,1)) -> 0 | V14: =M14&O14&Q14&S14&U14 -> 11002031040 | X14: =_xlfn.SINGLE(_xlfn.XLOOKUP(Y14,B:B,A:A,0,0,1)) -> 2 | Y14: Inc | Z14: 16025 | AA14: Intercompany | AB14: =_xlfn.SINGLE(_xlfn.XLOOKUP(AA14,E:E,D:D,0,0,1)) -> 5 | AD14: =_xlfn.SINGLE(_xlfn.XLOOKUP(AC14,H:H,G:G,0,0,1)) -> 0 | AF14: =_xlfn.SINGLE(_xlfn.XLOOKUP(AE14,K:K,J:J,0,0,1)) -> 0 | AG14: =X14&Z14&AB14&AD14&AF14 -> 216025500
D15: 14 | E15: Other long term liabilities | G15: 113 | H15: Other Marketing | M15: =_xlfn.SINGLE(_xlfn.XLOOKUP(N15,B:B,A:A,0,0,1)) -> 1 | N15: Ltd | O15: 10023 | P15: Cash and Cash Equivalents | Q15: =_xlfn.SINGLE(_xlfn.XLOOKUP(P15,E:E,D:D,0,0,1)) -> 1 | S15: =_xlfn.SINGLE(_xlfn.XLOOKUP(R15,H:H,G:G,0,0,1)) -> 0 | U15: =_xlfn.SINGLE(_xlfn.XLOOKUP(T15,K:K,J:J,0,0,1)) -> 0 | V15: =M15&O15&Q15&S15&U15 -> 110023100 | X15: =_xlfn.SINGLE(_xlfn.XLOOKUP(Y15,B:B,A:A,0,0,1)) -> 2 | Y15: Inc | Z15: 16030 | AA15: Capital Stock | AB15: =_xlfn.SINGLE(_xlfn.XLOOKUP(AA15,E:E,D:D,0,0,1)) -> 10 | AD15: =_xlfn.SINGLE(_xlfn.XLOOKUP(AC15,H:H,G:G,0,0,1)) -> 0 | AF15: =_xlfn.SINGLE(_xlfn.XLOOKUP(AE15,K:K,J:J,0,0,1)) -> 0 | AG15: =X15&Z15&AB15&AD15&AF15 -> 2160301000
D16: 15 | E16: Long term deferred revenue | G16: 114 | H16: Other R&D | M16: =_xlfn.SINGLE(_xlfn.XLOOKUP(N16,B:B,A:A,0,0,1)) -> 1 | N16: Ltd | O16: 10024 | P16: Cash and Cash Equivalents | Q16: =_xlfn.SINGLE(_xlfn.XLOOKUP(P16,E:E,D:D,0,0,1)) -> 1 | S16: =_xlfn.SINGLE(_xlfn.XLOOKUP(R16,H:H,G:G,0,0,1)) -> 0 | U16: =_xlfn.SINGLE(_xlfn.XLOOKUP(T16,K:K,J:J,0,0,1)) -> 0 | V16: =M16&O16&Q16&S16&U16 -> 110024100 | X16: =_xlfn.SINGLE(_xlfn.XLOOKUP(Y16,B:B,A:A,0,0,1)) -> 2 | Y16: Inc | Z16: 16050 | AA16: Intercompany | AB16: =_xlfn.SINGLE(_xlfn.XLOOKUP(AA16,E:E,D:D,0,0,1)) -> 5 | AD16: =_xlfn.SINGLE(_xlfn.XLOOKUP(AC16,H:H,G:G,0,0,1)) -> 0 | AF16: =_xlfn.SINGLE(_xlfn.XLOOKUP(AE16,K:K,J:J,0,0,1)) -> 0 | AG16: =X16&Z16&AB16&AD16&AF16 -> 216050500
D17: 16 | E17: Current Right-of-use asset | G17: 115 | H17: Patent | M17: =_xlfn.SINGLE(_xlfn.XLOOKUP(N17,B:B,A:A,0,0,1)) -> 1 | N17: Ltd | O17: 10025 | P17: Cash and Cash Equivalents | Q17: =_xlfn.SINGLE(_xlfn.XLOOKUP(P17,E:E,D:D,0,0,1)) -> 1 | S17: =_xlfn.SINGLE(_xlfn.XLOOKUP(R17,H:H,G:G,0,0,1)) -> 0 | U17: =_xlfn.SINGLE(_xlfn.XLOOKUP(T17,K:K,J:J,0,0,1)) -> 0 | V17: =M17&O17&Q17&S17&U17 -> 110025100 | X17: =_xlfn.SINGLE(_xlfn.XLOOKUP(Y17,B:B,A:A,0,0,1)) -> 2 | Y17: Inc | Z17: 20000 | AA17: Accounts Payable | AB17: =_xlfn.SINGLE(_xlfn.XLOOKUP(AA17,E:E,D:D,0,0,1)) -> 6 | AD17: =_xlfn.SINGLE(_xlfn.XLOOKUP(AC17,H:H,G:G,0,0,1)) -> 0 | AF17: =_xlfn.SINGLE(_xlfn.XLOOKUP(AE17,K:K,J:J,0,0,1)) -> 0 | AG17: =X17&Z17&AB17&AD17&AF17 -> 220000600
D18: 17 | E18: Long-term Right-of-use asset | G18: 116 | H18: Payroll & Payroll related | M18: =_xlfn.SINGLE(_xlfn.XLOOKUP(N18,B:B,A:A,0,0,1)) -> 1 | N18: Ltd | O18: 11001 | P18: Cash and Cash Equivalents | Q18: =_xlfn.SINGLE(_xlfn.XLOOKUP(P18,E:E,D:D,0,0,1)) -> 1 | S18: =_xlfn.SINGLE(_xlfn.XLOOKUP(R18,H:H,G:G,0,0,1)) -> 0 | U18: =_xlfn.SINGLE(_xlfn.XLOOKUP(T18,K:K,J:J,0,0,1)) -> 0 | V18: =M18&O18&Q18&S18&U18 -> 111001100 | X18: =_xlfn.SINGLE(_xlfn.XLOOKUP(Y18,B:B,A:A,0,0,1)) -> 2 | Y18: Inc | Z18: 20105 | AA18: Accounts Payable | AB18: =_xlfn.SINGLE(_xlfn.XLOOKUP(AA18,E:E,D:D,0,0,1)) -> 6 | AC18: Credit Cards | AD18: =_xlfn.SINGLE(_xlfn.XLOOKUP(AC18,H:H,G:G,0,0,1)) -> 103 | AF18: =_xlfn.SINGLE(_xlfn.XLOOKUP(AE18,K:K,J:J,0,0,1)) -> 0 | AG18: =X18&Z18&AB18&AD18&AF18 -> 22010561030
D19: 18 | E19: Current Lease liability | G19: 117 | H19: Prepaid Commissions | M19: =_xlfn.SINGLE(_xlfn.XLOOKUP(N19,B:B,A:A,0,0,1)) -> 1 | N19: Ltd | O19: 11002 | P19: Cash and Cash Equivalents | Q19: =_xlfn.SINGLE(_xlfn.XLOOKUP(P19,E:E,D:D,0,0,1)) -> 1 | S19: =_xlfn.SINGLE(_xlfn.XLOOKUP(R19,H:H,G:G,0,0,1)) -> 0 | U19: =_xlfn.SINGLE(_xlfn.XLOOKUP(T19,K:K,J:J,0,0,1)) -> 0 | V19: =M19&O19&Q19&S19&U19 -> 111002100 | X19: =_xlfn.SINGLE(_xlfn.XLOOKUP(Y19,B:B,A:A,0,0,1)) -> 2 | Y19: Inc | Z19: 21010 | AA19: Employees Payable | AB19: =_xlfn.SINGLE(_xlfn.XLOOKUP(AA19,E:E,D:D,0,0,1)) -> 8 | AD19: =_xlfn.SINGLE(_xlfn.XLOOKUP(AC19,H:H,G:G,0,0,1)) -> 0 | AF19: =_xlfn.SINGLE(_xlfn.XLOOKUP(AE19,K:K,J:J,0,0,1)) -> 0 | AG19: =X19&Z19&AB19&AD19&AF19 -> 221010800
D20: 19 | E20: Long-term Lease liability | G20: 118 | H20: Prepaid Expenses | M20: =_xlfn.SINGLE(_xlfn.XLOOKUP(N20,B:B,A:A,0,0,1)) -> 1 | N20: Ltd | O20: 11010 | P20: Cash and Cash Equivalents | Q20: =_xlfn.SINGLE(_xlfn.XLOOKUP(P20,E:E,D:D,0,0,1)) -> 1 | S20: =_xlfn.SINGLE(_xlfn.XLOOKUP(R20,H:H,G:G,0,0,1)) -> 0 | U20: =_xlfn.SINGLE(_xlfn.XLOOKUP(T20,K:K,J:J,0,0,1)) -> 0 | V20: =M20&O20&Q20&S20&U20 -> 111010100 | X20: =_xlfn.SINGLE(_xlfn.XLOOKUP(Y20,B:B,A:A,0,0,1)) -> 2 | Y20: Inc | Z20: 21020 | AA20: Employees Payable | AB20: =_xlfn.SINGLE(_xlfn.XLOOKUP(AA20,E:E,D:D,0,0,1)) -> 8 | AD20: =_xlfn.SINGLE(_xlfn.XLOOKUP(AC20,H:H,G:G,0,0,1)) -> 0 | AF20: =_xlfn.SINGLE(_xlfn.XLOOKUP(AE20,K:K,J:J,0,0,1)) -> 0 | AG20: =X20&Z20&AB20&AD20&AF20 -> 221020800
D21: 20 | E21: Revenue | G21: 119 | H21: Recruiting | M21: =_xlfn.SINGLE(_xlfn.XLOOKUP(N21,B:B,A:A,0,0,1)) -> 1 | N21: Ltd | O21: 11011 | P21: Cash and Cash Equivalents | Q21: =_xlfn.SINGLE(_xlfn.XLOOKUP(P21,E:E,D:D,0,0,1)) -> 1 | S21: =_xlfn.SINGLE(_xlfn.XLOOKUP(R21,H:H,G:G,0,0,1)) -> 0 | U21: =_xlfn.SINGLE(_xlfn.XLOOKUP(T21,K:K,J:J,0,0,1)) -> 0 | V21: =M21&O21&Q21&S21&U21 -> 111011100 | X21: =_xlfn.SINGLE(_xlfn.XLOOKUP(Y21,B:B,A:A,0,0,1)) -> 2 | Y21: Inc | Z21: 21025 | AA21: Employees Payable | AB21: =_xlfn.SINGLE(_xlfn.XLOOKUP(AA21,E:E,D:D,0,0,1)) -> 8 | AD21: =_xlfn.SINGLE(_xlfn.XLOOKUP(AC21,H:H,G:G,0,0,1)) -> 0 | AF21: =_xlfn.SINGLE(_xlfn.XLOOKUP(AE21,K:K,J:J,0,0,1)) -> 0 | AG21: =X21&Z21&AB21&AD21&AF21 -> 221025800
D22: 30 | E22: Cost of Sales | G22: 120 | H22: Restricted Cash | M22: =_xlfn.SINGLE(_xlfn.XLOOKUP(N22,B:B,A:A,0,0,1)) -> 1 | N22: Ltd | O22: 11012 | P22: Cash and Cash Equivalents | Q22: =_xlfn.SINGLE(_xlfn.XLOOKUP(P22,E:E,D:D,0,0,1)) -> 1 | S22: =_xlfn.SINGLE(_xlfn.XLOOKUP(R22,H:H,G:G,0,0,1)) -> 0 | U22: =_xlfn.SINGLE(_xlfn.XLOOKUP(T22,K:K,J:J,0,0,1)) -> 0 | V22: =M22&O22&Q22&S22&U22 -> 111012100 | X22: =_xlfn.SINGLE(_xlfn.XLOOKUP(Y22,B:B,A:A,0,0,1)) -> 2 | Y22: Inc | Z22: 21030 | AA22: Accrued expenses and other payable | AB22: =_xlfn.SINGLE(_xlfn.XLOOKUP(AA22,E:E,D:D,0,0,1)) -> 7 | AD22: =_xlfn.SINGLE(_xlfn.XLOOKUP(AC22,H:H,G:G,0,0,1)) -> 0 | AF22: =_xlfn.SINGLE(_xlfn.XLOOKUP(AE22,K:K,J:J,0,0,1)) -> 0 | AG22: =X22&Z22&AB22&AD22&AF22 -> 221030700
D23: 40 | E23: R&D | G23: 121 | H23: Security | M23: =_xlfn.SINGLE(_xlfn.XLOOKUP(N23,B:B,A:A,0,0,1)) -> 1 | N23: Ltd | O23: 11013 | P23: Cash and Cash Equivalents | Q23: =_xlfn.SINGLE(_xlfn.XLOOKUP(P23,E:E,D:D,0,0,1)) -> 1 | S23: =_xlfn.SINGLE(_xlfn.XLOOKUP(R23,H:H,G:G,0,0,1)) -> 0 | U23: =_xlfn.SINGLE(_xlfn.XLOOKUP(T23,K:K,J:J,0,0,1)) -> 0 | V23: =M23&O23&Q23&S23&U23 -> 111013100 | X23: =_xlfn.SINGLE(_xlfn.XLOOKUP(Y23,B:B,A:A,0,0,1)) -> 2 | Y23: Inc | Z23: 22005 | AA23: Deferred Revenue | AB23: =_xlfn.SINGLE(_xlfn.XLOOKUP(AA23,E:E,D:D,0,0,1)) -> 9 | AD23: =_xlfn.SINGLE(_xlfn.XLOOKUP(AC23,H:H,G:G,0,0,1)) -> 0 | AF23: =_xlfn.SINGLE(_xlfn.XLOOKUP(AE23,K:K,J:J,0,0,1)) -> 0 | AG23: =X23&Z23&AB23&AD23&AF23 -> 222005900
D24: 50 | E24: Sales | G24: 122 | H24: Short Term deposits | M24: =_xlfn.SINGLE(_xlfn.XLOOKUP(N24,B:B,A:A,0,0,1)) -> 1 | N24: Ltd | O24: 11014 | P24: Cash and Cash Equivalents | Q24: =_xlfn.SINGLE(_xlfn.XLOOKUP(P24,E:E,D:D,0,0,1)) -> 1 | S24: =_xlfn.SINGLE(_xlfn.XLOOKUP(R24,H:H,G:G,0,0,1)) -> 0 | U24: =_xlfn.SINGLE(_xlfn.XLOOKUP(T24,K:K,J:J,0,0,1)) -> 0 | V24: =M24&O24&Q24&S24&U24 -> 111014100 | X24: 2 | Y24: Inc | Z24: 27100 | AA24: Long term deferred revenue | AB24: =_xlfn.SINGLE(_xlfn.XLOOKUP(AA24,E:E,D:D,0,0,1)) -> 15 | AD24: 0 | AF24: 0 | AG24: =X24&Z24&AB24&AD24&AF24 -> 2271001500
D25: 60 | E25: Marketing | G25: 123 | H25: Software | M25: =_xlfn.SINGLE(_xlfn.XLOOKUP(N25,B:B,A:A,0,0,1)) -> 1 | N25: Ltd | O25: 21002 | P25: Accounts Payable | Q25: =_xlfn.SINGLE(_xlfn.XLOOKUP(P25,E:E,D:D,0,0,1)) -> 6 | R25: Credit Cards | S25: =_xlfn.SINGLE(_xlfn.XLOOKUP(R25,H:H,G:G,0,0,1)) -> 103 | U25: =_xlfn.SINGLE(_xlfn.XLOOKUP(T25,K:K,J:J,0,0,1)) -> 0 | V25: =M25&O25&Q25&S25&U25 -> 12100261030 | X25: =_xlfn.SINGLE(_xlfn.XLOOKUP(Y25,B:B,A:A,0,0,1)) -> 2 | Y25: Inc | Z25: 24000 | AA25: Employees Payable | AB25: =_xlfn.SINGLE(_xlfn.XLOOKUP(AA25,E:E,D:D,0,0,1)) -> 8 | AD25: =_xlfn.SINGLE(_xlfn.XLOOKUP(AC25,H:H,G:G,0,0,1)) -> 0 | AF25: =_xlfn.SINGLE(_xlfn.XLOOKUP(AE25,K:K,J:J,0,0,1)) -> 0 | AG25: =X25&Z25&AB25&AD25&AF25 -> 224000800
D26: 70 | E26: G&A | G26: 124 | H26: T&E | M26: =_xlfn.SINGLE(_xlfn.XLOOKUP(N26,B:B,A:A,0,0,1)) -> 1 | N26: Ltd | O26: 21003 | P26: Accounts Payable | Q26: =_xlfn.SINGLE(_xlfn.XLOOKUP(P26,E:E,D:D,0,0,1)) -> 6 | R26: Credit Cards | S26: =_xlfn.SINGLE(_xlfn.XLOOKUP(R26,H:H,G:G,0,0,1)) -> 103 | U26: =_xlfn.SINGLE(_xlfn.XLOOKUP(T26,K:K,J:J,0,0,1)) -> 0 | V26: =M26&O26&Q26&S26&U26 -> 12100361030 | X26: =_xlfn.SINGLE(_xlfn.XLOOKUP(Y26,B:B,A:A,0,0,1)) -> 2 | Y26: Inc | Z26: 24017 | AA26: Employees Payable | AB26: =_xlfn.SINGLE(_xlfn.XLOOKUP(AA26,E:E,D:D,0,0,1)) -> 8 | AD26: =_xlfn.SINGLE(_xlfn.XLOOKUP(AC26,H:H,G:G,0,0,1)) -> 0 | AF26: =_xlfn.SINGLE(_xlfn.XLOOKUP(AE26,K:K,J:J,0,0,1)) -> 0 | AG26: =X26&Z26&AB26&AD26&AF26 -> 224017800
D27: 80 | E27: Other | G27: 125 | H27: Other Sales | M27: =_xlfn.SINGLE(_xlfn.XLOOKUP(N27,B:B,A:A,0,0,1)) -> 1 | N27: Ltd | O27: 21006 | P27: Accounts Payable | Q27: =_xlfn.SINGLE(_xlfn.XLOOKUP(P27,E:E,D:D,0,0,1)) -> 6 | R27: Credit Cards | S27: =_xlfn.SINGLE(_xlfn.XLOOKUP(R27,H:H,G:G,0,0,1)) -> 103 | U27: =_xlfn.SINGLE(_xlfn.XLOOKUP(T27,K:K,J:J,0,0,1)) -> 0 | V27: =M27&O27&Q27&S27&U27 -> 12100661030 | X27: =_xlfn.SINGLE(_xlfn.XLOOKUP(Y27,B:B,A:A,0,0,1)) -> 2 | Y27: Inc | Z27: 24018 | AA27: Employees Payable | AB27: =_xlfn.SINGLE(_xlfn.XLOOKUP(AA27,E:E,D:D,0,0,1)) -> 8 | AD27: =_xlfn.SINGLE(_xlfn.XLOOKUP(AC27,H:H,G:G,0,0,1)) -> 0 | AF27: =_xlfn.SINGLE(_xlfn.XLOOKUP(AE27,K:K,J:J,0,0,1)) -> 0 | AG27: =X27&Z27&AB27&AD27&AF27 -> 224018800
D28: 90 | E28: Finance | G28: 126 | H28: Referral Fees | M28: =_xlfn.SINGLE(_xlfn.XLOOKUP(N28,B:B,A:A,0,0,1)) -> 1 | N28: Ltd | O28: 21007 | P28: Accounts Payable | Q28: =_xlfn.SINGLE(_xlfn.XLOOKUP(P28,E:E,D:D,0,0,1)) -> 6 | R28: Credit Cards | S28: =_xlfn.SINGLE(_xlfn.XLOOKUP(R28,H:H,G:G,0,0,1)) -> 103 | U28: =_xlfn.SINGLE(_xlfn.XLOOKUP(T28,K:K,J:J,0,0,1)) -> 0 | V28: =M28&O28&Q28&S28&U28 -> 12100761030 | X28: =_xlfn.SINGLE(_xlfn.XLOOKUP(Y28,B:B,A:A,0,0,1)) -> 2 | Y28: Inc | Z28: 25503 | AA28: Accrued expenses and other payable | AB28: =_xlfn.SINGLE(_xlfn.XLOOKUP(AA28,E:E,D:D,0,0,1)) -> 7 | AC28: Institutions | AD28: =_xlfn.SINGLE(_xlfn.XLOOKUP(AC28,H:H,G:G,0,0,1)) -> 109 | AF28: =_xlfn.SINGLE(_xlfn.XLOOKUP(AE28,K:K,J:J,0,0,1)) -> 0 | AG28: =X28&Z28&AB28&AD28&AF28 -> 22550371090
D29: 88 | E29: Tax | G29: 127 | H29: Other CoS | M29: =_xlfn.SINGLE(_xlfn.XLOOKUP(N29,B:B,A:A,0,0,1)) -> 1 | N29: Ltd | O29: 21008 | P29: Accounts Payable | Q29: =_xlfn.SINGLE(_xlfn.XLOOKUP(P29,E:E,D:D,0,0,1)) -> 6 | R29: Credit Cards | S29: =_xlfn.SINGLE(_xlfn.XLOOKUP(R29,H:H,G:G,0,0,1)) -> 103 | U29: =_xlfn.SINGLE(_xlfn.XLOOKUP(T29,K:K,J:J,0,0,1)) -> 0 | V29: =M29&O29&Q29&S29&U29 -> 12100861030 | X29: =_xlfn.SINGLE(_xlfn.XLOOKUP(Y29,B:B,A:A,0,0,1)) -> 2 | Y29: Inc | Z29: 25504 | AA29: Accrued expenses and other payable | AB29: =_xlfn.SINGLE(_xlfn.XLOOKUP(AA29,E:E,D:D,0,0,1)) -> 7 | AC29: Institutions | AD29: =_xlfn.SINGLE(_xlfn.XLOOKUP(AC29,H:H,G:G,0,0,1)) -> 109 | AF29: =_xlfn.SINGLE(_xlfn.XLOOKUP(AE29,K:K,J:J,0,0,1)) -> 0 | AG29: =X29&Z29&AB29&AD29&AF29 -> 22550471090
D30: 99 | E30: Overhead | G30: 128 | H30: Other G&A | M30: =_xlfn.SINGLE(_xlfn.XLOOKUP(N30,B:B,A:A,0,0,1)) -> 1 | N30: Ltd | O30: 21009 | P30: Accounts Payable | Q30: =_xlfn.SINGLE(_xlfn.XLOOKUP(P30,E:E,D:D,0,0,1)) -> 6 | R30: Credit Cards | S30: =_xlfn.SINGLE(_xlfn.XLOOKUP(R30,H:H,G:G,0,0,1)) -> 103 | U30: =_xlfn.SINGLE(_xlfn.XLOOKUP(T30,K:K,J:J,0,0,1)) -> 0 | V30: =M30&O30&Q30&S30&U30 -> 12100961030 | X30: =_xlfn.SINGLE(_xlfn.XLOOKUP(Y30,B:B,A:A,0,0,1)) -> 2 | Y30: Inc | Z30: 25505 | AA30: Accrued expenses and other payable | AB30: =_xlfn.SINGLE(_xlfn.XLOOKUP(AA30,E:E,D:D,0,0,1)) -> 7 | AC30: Institutions | AD30: =_xlfn.SINGLE(_xlfn.XLOOKUP(AC30,H:H,G:G,0,0,1)) -> 109 | AF30: =_xlfn.SINGLE(_xlfn.XLOOKUP(AE30,K:K,J:J,0,0,1)) -> 0 | AG30: =X30&Z30&AB30&AD30&AF30 -> 22550571090
G31: 129 | H31: Prepaid R&D exp. | M31: =_xlfn.SINGLE(_xlfn.XLOOKUP(N31,B:B,A:A,0,0,1)) -> 1 | N31: Ltd | O31: 21010 | P31: Accounts Payable | Q31: =_xlfn.SINGLE(_xlfn.XLOOKUP(P31,E:E,D:D,0,0,1)) -> 6 | R31: Credit Cards | S31: =_xlfn.SINGLE(_xlfn.XLOOKUP(R31,H:H,G:G,0,0,1)) -> 103 | U31: =_xlfn.SINGLE(_xlfn.XLOOKUP(T31,K:K,J:J,0,0,1)) -> 0 | V31: =M31&O31&Q31&S31&U31 -> 12101061030 | X31: =_xlfn.SINGLE(_xlfn.XLOOKUP(Y31,B:B,A:A,0,0,1)) -> 2 | Y31: Inc | Z31: 25506 | AA31: Accrued expenses and other payable | AB31: =_xlfn.SINGLE(_xlfn.XLOOKUP(AA31,E:E,D:D,0,0,1)) -> 7 | AC31: Institutions | AD31: =_xlfn.SINGLE(_xlfn.XLOOKUP(AC31,H:H,G:G,0,0,1)) -> 109 | AF31: =_xlfn.SINGLE(_xlfn.XLOOKUP(AE31,K:K,J:J,0,0,1)) -> 0 | AG31: =X31&Z31&AB31&AD31&AF31 -> 22550671090
M32: =_xlfn.SINGLE(_xlfn.XLOOKUP(N32,B:B,A:A,0,0,1)) -> 1 | N32: Ltd | O32: 21011 | P32: Accounts Payable | Q32: =_xlfn.SINGLE(_xlfn.XLOOKUP(P32,E:E,D:D,0,0,1)) -> 6 | R32: Credit Cards | S32: =_xlfn.SINGLE(_xlfn.XLOOKUP(R32,H:H,G:G,0,0,1)) -> 103 | U32: =_xlfn.SINGLE(_xlfn.XLOOKUP(T32,K:K,J:J,0,0,1)) -> 0 | V32: =M32&O32&Q32&S32&U32 -> 12101161030 | X32: =_xlfn.SINGLE(_xlfn.XLOOKUP(Y32,B:B,A:A,0,0,1)) -> 2 | Y32: Inc | Z32: 25507 | AA32: Accrued expenses and other payable | AB32: =_xlfn.SINGLE(_xlfn.XLOOKUP(AA32,E:E,D:D,0,0,1)) -> 7 | AC32: Institutions | AD32: =_xlfn.SINGLE(_xlfn.XLOOKUP(AC32,H:H,G:G,0,0,1)) -> 109 | AF32: =_xlfn.SINGLE(_xlfn.XLOOKUP(AE32,K:K,J:J,0,0,1)) -> 0 | AG32: =X32&Z32&AB32&AD32&AF32 -> 22550771090
M33: =_xlfn.SINGLE(_xlfn.XLOOKUP(N33,B:B,A:A,0,0,1)) -> 1 | N33: Ltd | O33: 21014 | P33: Accounts Payable | Q33: =_xlfn.SINGLE(_xlfn.XLOOKUP(P33,E:E,D:D,0,0,1)) -> 6 | R33: Credit Cards | S33: =_xlfn.SINGLE(_xlfn.XLOOKUP(R33,H:H,G:G,0,0,1)) -> 103 | U33: =_xlfn.SINGLE(_xlfn.XLOOKUP(T33,K:K,J:J,0,0,1)) -> 0 | V33: =M33&O33&Q33&S33&U33 -> 12101461030 | X33: =_xlfn.SINGLE(_xlfn.XLOOKUP(Y33,B:B,A:A,0,0,1)) -> 2 | Y33: Inc | Z33: 25508 | AA33: Accrued expenses and other payable | AB33: =_xlfn.SINGLE(_xlfn.XLOOKUP(AA33,E:E,D:D,0,0,1)) -> 7 | AC33: Institutions | AD33: =_xlfn.SINGLE(_xlfn.XLOOKUP(AC33,H:H,G:G,0,0,1)) -> 109 | AF33: =_xlfn.SINGLE(_xlfn.XLOOKUP(AE33,K:K,J:J,0,0,1)) -> 0 | AG33: =X33&Z33&AB33&AD33&AF33 -> 22550871090
M34: =_xlfn.SINGLE(_xlfn.XLOOKUP(N34,B:B,A:A,0,0,1)) -> 1 | N34: Ltd | O34: 21015 | P34: Accounts Payable | Q34: =_xlfn.SINGLE(_xlfn.XLOOKUP(P34,E:E,D:D,0,0,1)) -> 6 | R34: Credit Cards | S34: =_xlfn.SINGLE(_xlfn.XLOOKUP(R34,H:H,G:G,0,0,1)) -> 103 | U34: =_xlfn.SINGLE(_xlfn.XLOOKUP(T34,K:K,J:J,0,0,1)) -> 0 | V34: =M34&O34&Q34&S34&U34 -> 12101561030 | X34: =_xlfn.SINGLE(_xlfn.XLOOKUP(Y34,B:B,A:A,0,0,1)) -> 2 | Y34: Inc | Z34: 25509 | AA34: Accrued expenses and other payable | AB34: =_xlfn.SINGLE(_xlfn.XLOOKUP(AA34,E:E,D:D,0,0,1)) -> 7 | AC34: Institutions | AD34: =_xlfn.SINGLE(_xlfn.XLOOKUP(AC34,H:H,G:G,0,0,1)) -> 109 | AF34: =_xlfn.SINGLE(_xlfn.XLOOKUP(AE34,K:K,J:J,0,0,1)) -> 0 | AG34: =X34&Z34&AB34&AD34&AF34 -> 22550971090
M35: =_xlfn.SINGLE(_xlfn.XLOOKUP(N35,B:B,A:A,0,0,1)) -> 1 | N35: Ltd | O35: 21020 | P35: Accounts Payable | Q35: =_xlfn.SINGLE(_xlfn.XLOOKUP(P35,E:E,D:D,0,0,1)) -> 6 | R35: Credit Cards | S35: =_xlfn.SINGLE(_xlfn.XLOOKUP(R35,H:H,G:G,0,0,1)) -> 103 | U35: =_xlfn.SINGLE(_xlfn.XLOOKUP(T35,K:K,J:J,0,0,1)) -> 0 | V35: =M35&O35&Q35&S35&U35 -> 12102061030 | X35: =_xlfn.SINGLE(_xlfn.XLOOKUP(Y35,B:B,A:A,0,0,1)) -> 2 | Y35: Inc | Z35: 25510 | AA35: Accrued expenses and other payable | AB35: =_xlfn.SINGLE(_xlfn.XLOOKUP(AA35,E:E,D:D,0,0,1)) -> 7 | AC35: Institutions | AD35: =_xlfn.SINGLE(_xlfn.XLOOKUP(AC35,H:H,G:G,0,0,1)) -> 109 | AF35: =_xlfn.SINGLE(_xlfn.XLOOKUP(AE35,K:K,J:J,0,0,1)) -> 0 | AG35: =X35&Z35&AB35&AD35&AF35 -> 22551071090
M36: =_xlfn.SINGLE(_xlfn.XLOOKUP(N36,B:B,A:A,0,0,1)) -> 1 | N36: Ltd | O36: 22260 | P36: Accounts Receivable | Q36: =_xlfn.SINGLE(_xlfn.XLOOKUP(P36,E:E,D:D,0,0,1)) -> 2 | S36: =_xlfn.SINGLE(_xlfn.XLOOKUP(R36,H:H,G:G,0,0,1)) -> 0 | U36: =_xlfn.SINGLE(_xlfn.XLOOKUP(T36,K:K,J:J,0,0,1)) -> 0 | V36: =M36&O36&Q36&S36&U36 -> 122260200 | X36: =_xlfn.SINGLE(_xlfn.XLOOKUP(Y36,B:B,A:A,0,0,1)) -> 2 | Y36: Inc | Z36: 25511 | AA36: Accrued expenses and other payable | AB36: =_xlfn.SINGLE(_xlfn.XLOOKUP(AA36,E:E,D:D,0,0,1)) -> 7 | AC36: Institutions | AD36: =_xlfn.SINGLE(_xlfn.XLOOKUP(AC36,H:H,G:G,0,0,1)) -> 109 | AF36: =_xlfn.SINGLE(_xlfn.XLOOKUP(AE36,K:K,J:J,0,0,1)) -> 0 | AG36: =X36&Z36&AB36&AD36&AF36 -> 22551171090
M37: =_xlfn.SINGLE(_xlfn.XLOOKUP(N37,B:B,A:A,0,0,1)) -> 1 | N37: Ltd | O37: 22263 | P37: Accounts Receivable | Q37: =_xlfn.SINGLE(_xlfn.XLOOKUP(P37,E:E,D:D,0,0,1)) -> 2 | S37: =_xlfn.SINGLE(_xlfn.XLOOKUP(R37,H:H,G:G,0,0,1)) -> 0 | U37: =_xlfn.SINGLE(_xlfn.XLOOKUP(T37,K:K,J:J,0,0,1)) -> 0 | V37: =M37&O37&Q37&S37&U37 -> 122263200 | X37: =_xlfn.SINGLE(_xlfn.XLOOKUP(Y37,B:B,A:A,0,0,1)) -> 2 | Y37: Inc | Z37: 25512 | AA37: Accrued expenses and other payable | AB37: =_xlfn.SINGLE(_xlfn.XLOOKUP(AA37,E:E,D:D,0,0,1)) -> 7 | AC37: Institutions | AD37: =_xlfn.SINGLE(_xlfn.XLOOKUP(AC37,H:H,G:G,0,0,1)) -> 109 | AF37: =_xlfn.SINGLE(_xlfn.XLOOKUP(AE37,K:K,J:J,0,0,1)) -> 0 | AG37: =X37&Z37&AB37&AD37&AF37 -> 22551271090
M38: =_xlfn.SINGLE(_xlfn.XLOOKUP(N38,B:B,A:A,0,0,1)) -> 1 | N38: Ltd | O38: 22264 | P38: Accounts Receivable | Q38: =_xlfn.SINGLE(_xlfn.XLOOKUP(P38,E:E,D:D,0,0,1)) -> 2 | S38: =_xlfn.SINGLE(_xlfn.XLOOKUP(R38,H:H,G:G,0,0,1)) -> 0 | U38: =_xlfn.SINGLE(_xlfn.XLOOKUP(T38,K:K,J:J,0,0,1)) -> 0 | V38: =M38&O38&Q38&S38&U38 -> 122264200 | X38: =_xlfn.SINGLE(_xlfn.XLOOKUP(Y38,B:B,A:A,0,0,1)) -> 2 | Y38: Inc | Z38: 25513 | AA38: Accrued expenses and other payable | AB38: =_xlfn.SINGLE(_xlfn.XLOOKUP(AA38,E:E,D:D,0,0,1)) -> 7 | AC38: Institutions | AD38: =_xlfn.SINGLE(_xlfn.XLOOKUP(AC38,H:H,G:G,0,0,1)) -> 109 | AF38: =_xlfn.SINGLE(_xlfn.XLOOKUP(AE38,K:K,J:J,0,0,1)) -> 0 | AG38: =X38&Z38&AB38&AD38&AF38 -> 22551371090
M39: =_xlfn.SINGLE(_xlfn.XLOOKUP(N39,B:B,A:A,0,0,1)) -> 1 | N39: Ltd | O39: 22268 | P39: Accounts Receivable | Q39: =_xlfn.SINGLE(_xlfn.XLOOKUP(P39,E:E,D:D,0,0,1)) -> 2 | S39: =_xlfn.SINGLE(_xlfn.XLOOKUP(R39,H:H,G:G,0,0,1)) -> 0 | U39: =_xlfn.SINGLE(_xlfn.XLOOKUP(T39,K:K,J:J,0,0,1)) -> 0 | V39: =M39&O39&Q39&S39&U39 -> 122268200 | X39: =_xlfn.SINGLE(_xlfn.XLOOKUP(Y39,B:B,A:A,0,0,1)) -> 2 | Y39: Inc | Z39: 27020 | AA39: Employees Payable | AB39: =_xlfn.SINGLE(_xlfn.XLOOKUP(AA39,E:E,D:D,0,0,1)) -> 8 | AD39: =_xlfn.SINGLE(_xlfn.XLOOKUP(AC39,H:H,G:G,0,0,1)) -> 0 | AF39: =_xlfn.SINGLE(_xlfn.XLOOKUP(AE39,K:K,J:J,0,0,1)) -> 0 | AG39: =X39&Z39&AB39&AD39&AF39 -> 227020800
M40: =_xlfn.SINGLE(_xlfn.XLOOKUP(N40,B:B,A:A,0,0,1)) -> 1 | N40: Ltd | O40: 22270 | P40: Accounts Receivable | Q40: =_xlfn.SINGLE(_xlfn.XLOOKUP(P40,E:E,D:D,0,0,1)) -> 2 | S40: =_xlfn.SINGLE(_xlfn.XLOOKUP(R40,H:H,G:G,0,0,1)) -> 0 | U40: =_xlfn.SINGLE(_xlfn.XLOOKUP(T40,K:K,J:J,0,0,1)) -> 0 | V40: =M40&O40&Q40&S40&U40 -> 122270200 | X40: =_xlfn.SINGLE(_xlfn.XLOOKUP(Y40,B:B,A:A,0,0,1)) -> 2 | Y40: Inc | Z40: 30000 | AA40: Capital Stock | AB40: =_xlfn.SINGLE(_xlfn.XLOOKUP(AA40,E:E,D:D,0,0,1)) -> 10 | AD40: =_xlfn.SINGLE(_xlfn.XLOOKUP(AC40,H:H,G:G,0,0,1)) -> 0 | AF40: =_xlfn.SINGLE(_xlfn.XLOOKUP(AE40,K:K,J:J,0,0,1)) -> 0 | AG40: =X40&Z40&AB40&AD40&AF40 -> 2300001000
...

Sheet GL 12.22
A1: =SUM(L:L) -> 2.5494955e-08 | I1: YTD 2022
A2: Account Index | B2: FS Account | C2: Entity | D2: GL Account # | E2: Account Name | F2: Sub Account | G2: Sub Department | I2: Balance in USD | J2: AJE | K2: Allocation | L2: Balance | M2: Con. entry | N2: Reported balance (consolidated)
A3: =_xlfn.XLOOKUP($B3,Index!$E:$E,Index!$D:$D,) -> 1 | B3: =IF($C3="Ltd",_xlfn.XLOOKUP($D3,Index!$V:$V,Index!$P:$P,),_xlfn.XLOOKUP($D3,Index!$AG:$AG,Index!$AA:$AA,)) -> Cash and Cash Equivalents | C3: =IF(LEFT(D3)="1","Ltd","Inc") -> Ltd | D3: 110004100 | E3: =_xlfn.XLOOKUP(_xlfn.NUMBERVALUE(MID(D3,2,5)),'TB LTD 12.22'!$E:$E,'TB LTD 12.22'!$F:$F,) -> פקדון אשראי 1 1670001+3000001 | F3: =IF(C3="Ltd",_xlfn.XLOOKUP(D3,Index!V:V,Index!R:R,),_xlfn.XLOOKUP(D3,Index!AG:AG,Index!AC:AC,)) -> 0 | G3: =IF(C3="Ltd",_xlfn.XLOOKUP(D3,Index!V:V,Index!T:T,),_xlfn.XLOOKUP(D3,Index!AG:AG,Index!AE:AE,)) -> 0 | I3: =_xlfn.XLOOKUP(_xlfn.NUMBERVALUE(MID(D3,2,5)),'TB LTD 12.22'!E:E,'TB LTD 12.22'!H:H,0,0,1) -> 202311.56 | J3: =SUMIF(AJE!$E:$E,D3,AJE!$H:$H) -> 0 | K3: =SUMIF(AJE!$Q:$Q,D3,AJE!$T:$T) -> 0 | L3: =I3+J3+K3 -> 202311.56 | M3: =SUMIF(AJE!$AB:$AB,D3,AJE!$AE:$AE) -> 0 | N3: =L3+M3 -> 202311.56 | R3: =L3*3.519 -> 711934.38
A4: =_xlfn.XLOOKUP($B4,Index!$E:$E,Index!$D:$D,) -> 1 | B4: =IF($C4="Ltd",_xlfn.XLOOKUP($D4,Index!$V:$V,Index!$P:$P,),_xlfn.XLOOKUP($D4,Index!$AG:$AG,Index!$AA:$AA,)) -> Cash and Cash Equivalents | C4: =IF(LEFT(D4)="1","Ltd","Inc") -> Ltd | D4: 110007100 | E4: =_xlfn.XLOOKUP(_xlfn.NUMBERVALUE(MID(D4,2,5)),'TB LTD 12.22'!$E:$E,'TB LTD 12.22'!$F:$F,) -> פקדון דולרי 356924992 | F4: =IF(C4="Ltd",_xlfn.XLOOKUP(D4,Index!V:V,Index!R:R,),_xlfn.XLOOKUP(D4,Index!AG:AG,Index!AC:AC,)) -> 0 | G4: =IF(C4="Ltd",_xlfn.XLOOKUP(D4,Index!V:V,Index!T:T,),_xlfn.XLOOKUP(D4,Index!AG:AG,Index!AE:AE,)) -> 0 | I4: =_xlfn.XLOOKUP(_xlfn.NUMBERVALUE(MID(D4,2,5)),'TB LTD 12.22'!E:E,'TB LTD 12.22'!H:H,0,0,1) -> 5075011.6 | J4: =SUMIF(AJE!$E:$E,D4,AJE!$H:$H) -> 0 | K4: =SUMIF(AJE!$Q:$Q,D4,AJE!$T:$T) -> 0 | L4: =I4+J4+K4 -> 5075011.6 | M4: =SUMIF(AJE!$AB:$AB,D4,AJE!$AE:$AE) -> 0 | N4: =L4+M4 -> 5075011.6 | R4: =L4*3.519 -> 17858966
A5: =_xlfn.XLOOKUP($B5,Index!$E:$E,Index!$D:$D,) -> 3 | B5: =IF($C5="Ltd",_xlfn.XLOOKUP($D5,Index!$V:$V,Index!$P:$P,),_xlfn.XLOOKUP($D5,Index!$AG:$AG,Index!$AA:$AA,)) -> Prepaid expenses and other receivable | C5: =IF(LEFT(D5)="1","Ltd","Inc") -> Ltd | D5: 11000831040 | E5: =_xlfn.XLOOKUP(_xlfn.NUMBERVALUE(MID(D5,2,5)),'TB LTD 12.22'!$E:$E,'TB LTD 12.22'!$F:$F,) -> Deposit Papaya Global USD כללי עד 8.22 | F5: =IF(C5="Ltd",_xlfn.XLOOKUP(D5,Index!V:V,Index!R:R,),_xlfn.XLOOKUP(D5,Index!AG:AG,Index!AC:AC,)) -> Deposits | G5: =IF(C5="Ltd",_xlfn.XLOOKUP(D5,Index!V:V,Index!T:T,),_xlfn.XLOOKUP(D5,Index!AG:AG,Index!AE:AE,)) -> 0 | I5: =_xlfn.XLOOKUP(_xlfn.NUMBERVALUE(MID(D5,2,5)),'TB LTD 12.22'!E:E,'TB LTD 12.22'!H:H,0,0,1) -> 398459.46 | J5: =SUMIF(AJE!$E:$E,D5,AJE!$H:$H) -> 0 | K5: =SUMIF(AJE!$Q:$Q,D5,AJE!$T:$T) -> 0 | L5: =I5+J5+K5 -> 398459.46 | M5: =SUMIF(AJE!$AB:$AB,D5,AJE!$AE:$AE) -> 0 | N5: =L5+M5 -> 398459.46
A6: =_xlfn.XLOOKUP($B6,Index!$E:$E,Index!$D:$D,) -> 3 | B6: =IF($C6="Ltd",_xlfn.XLOOKUP($D6,Index!$V:$V,Index!$P:$P,),_xlfn.XLOOKUP($D6,Index!$AG:$AG,Index!$AA:$AA,)) -> Prepaid expenses and other receivable | C6: =IF(LEFT(D6)="1","Ltd","Inc") -> Ltd | D6: 11001231040 | E6: =_xlfn.XLOOKUP(_xlfn.NUMBERVALUE(MID(D6,2,5)),'TB LTD 12.22'!$E:$E,'TB LTD 12.22'!$F:$F,) -> פקדון שכ"ד שותפות נכסי הארבעה | F6: =IF(C6="Ltd",_xlfn.XLOOKUP(D6,Index!V:V,Index!R:R,),_xlfn.XLOOKUP(D6,Index!AG:AG,Index!AC:AC,)) -> Deposits | G6: =IF(C6="Ltd",_xlfn.XLOOKUP(D6,Index!V:V,Index!T:T,),_xlfn.XLOOKUP(D6,Index!AG:AG,Index!AE:AE,)) -> 0 | I6: =_xlfn.XLOOKUP(_xlfn.NUMBERVALUE(MID(D6,2,5)),'TB LTD 12.22'!E:E,'TB LTD 12.22'!H:H,0,0,1) -> 20940.49 | J6: =SUMIF(AJE!$E:$E,D6,AJE!$H:$H) -> 0 | K6: =SUMIF(AJE!$Q:$Q,D6,AJE!$T:$T) -> 0 | L6: =I6+J6+K6 -> 20940.49 | M6: =SUMIF(AJE!$AB:$AB,D6,AJE!$AE:$AE) -> 0 | N6: =L6+M6 -> 20940.49
A7: =_xlfn.XLOOKUP($B7,Index!$E:$E,Index!$D:$D,) -> 3 | B7: =IF($C7="Ltd",_xlfn.XLOOKUP($D7,Index!$V:$V,Index!$P:$P,),_xlfn.XLOOKUP($D7,Index!$AG:$AG,Index!$AA:$AA,)) -> Prepaid expenses and other receivable | C7: =IF(LEFT(D7)="1","Ltd","Inc") -> Ltd | D7: 11001331040 | E7: =_xlfn.XLOOKUP(_xlfn.NUMBERVALUE(MID(D7,2,5)),'TB LTD 12.22'!$E:$E,'TB LTD 12.22'!$F:$F,) -> פקדון שכ"ד GEGR LTD | F7: =IF(C7="Ltd",_xlfn.XLOOKUP(D7,Index!V:V,Index!R:R,),_xlfn.XLOOKUP(D7,Index!AG:AG,Index!AC:AC,)) -> Deposits | G7: =IF(C7="Ltd",_xlfn.XLOOKUP(D7,Index!V:V,Index!T:T,),_xlfn.XLOOKUP(D7,Index!AG:AG,Index!AE:AE,)) -> 0 | I7: =_xlfn.XLOOKUP(_xlfn.NUMBERVALUE(MID(D7,2,5)),'TB LTD 12.22'!E:E,'TB LTD 12.22'!H:H,0,0,1) -> 272833.76 | J7: =SUMIF(AJE!$E:$E,D7,AJE!$H:$H) -> 0 | K7: =SUMIF(AJE!$Q:$Q,D7,AJE!$T:$T) -> 0 | L7: =I7+J7+K7 -> 272833.76 | M7: =SUMIF(AJE!$AB:$AB,D7,AJE!$AE:$AE) -> 0 | N7: =L7+M7 -> 272833.76
A8: =_xlfn.XLOOKUP($B8,Index!$E:$E,Index!$D:$D,) -> 1 | B8: =IF($C8="Ltd",_xlfn.XLOOKUP($D8,Index!$V:$V,Index!$P:$P,),_xlfn.XLOOKUP($D8,Index!$AG:$AG,Index!$AA:$AA,)) -> Cash and Cash Equivalents | C8: =IF(LEFT(D8)="1","Ltd","Inc") -> Ltd | D8: 110014100 | E8: =_xlfn.XLOOKUP(_xlfn.NUMBERVALUE(MID(D8,2,5)),'TB LTD 12.22'!$E:$E,'TB LTD 12.22'!$F:$F,) -> פקדון אשראי 2 1230001 | F8: =IF(C8="Ltd",_xlfn.XLOOKUP(D8,Index!V:V,Index!R:R,),_xlfn.XLOOKUP(D8,Index!AG:AG,Index!AC:AC,)) -> 0 | G8: =IF(C8="Ltd",_xlfn.XLOOKUP(D8,Index!V:V,Index!T:T,),_xlfn.XLOOKUP(D8,Index!AG:AG,Index!AE:AE,)) -> 0 | I8: =_xlfn.XLOOKUP(_xlfn.NUMBERVALUE(MID(D8,2,5)),'TB LTD 12.22'!E:E,'TB LTD 12.22'!H:H,0,0,1) -> 19732.15 | J8: =SUMIF(AJE!$E:$E,D8,AJE!$H:$H) -> 0 | K8: =SUMIF(AJE!$Q:$Q,D8,AJE!$T:$T) -> 0 | L8: =I8+J8+K8 -> 19732.15 | M8: =SUMIF(AJE!$AB:$AB,D8,AJE!$AE:$AE) -> 0 | N8: =L8+M8 -> 19732.15 | R8: =L8*3.519 -> 69437.436
A9: =_xlfn.XLOOKUP($B9,Index!$E:$E,Index!$D:$D,) -> 1 | B9: =IF($C9="Ltd",_xlfn.XLOOKUP($D9,Index!$V:$V,Index!$P:$P,),_xlfn.XLOOKUP($D9,Index!$AG:$AG,Index!$AA:$AA,)) -> Cash and Cash Equivalents | C9: =IF(LEFT(D9)="1","Ltd","Inc") -> Ltd | D9: 11001611220 | E9: =_xlfn.XLOOKUP(_xlfn.NUMBERVALUE(MID(D9,2,5)),'TB LTD 12.22'!$E:$E,'TB LTD 12.22'!$F:$F,) -> פקדון דולרי | F9: =IF(C9="Ltd",_xlfn.XLOOKUP(D9,Index!V:V,Index!R:R,),_xlfn.XLOOKUP(D9,Index!AG:AG,Index!AC:AC,)) -> Short Term deposits | G9: =IF(C9="Ltd",_xlfn.XLOOKUP(D9,Index!V:V,Index!T:T,),_xlfn.XLOOKUP(D9,Index!AG:AG,Index!AE:AE,)) -> 0 | I9: =_xlfn.XLOOKUP(_xlfn.NUMBERVALUE(MID(D9,2,5)),'TB LTD 12.22'!E:E,'TB LTD 12.22'!H:H,0,0,1) -> 10166887 | J9: =SUMIF(AJE!$E:$E,D9,AJE!$H:$H) -> 0 | K9: =SUMIF(AJE!$Q:$Q,D9,AJE!$T:$T) -> 0 | L9: =I9+J9+K9 -> 10166887 | M9: =SUMIF(AJE!$AB:$AB,D9,AJE!$AE:$AE) -> 0 | N9: =L9+M9 -> 10166887 | R9: =L9*3.519 -> 35777276
A10: =_xlfn.XLOOKUP($B10,Index!$E:$E,Index!$D:$D,) -> 3 | B10: =IF($C10="Ltd",_xlfn.XLOOKUP($D10,Index!$V:$V,Index!$P:$P,),_xlfn.XLOOKUP($D10,Index!$AG:$AG,Index!$AA:$AA,)) -> Prepaid expenses and other receivable | C10: =IF(LEFT(D10)="1","Ltd","Inc") -> Ltd | D10: 11001731040 | E10: =_xlfn.XLOOKUP(_xlfn.NUMBERVALUE(MID(D10,2,5)),'TB LTD 12.22'!$E:$E,'TB LTD 12.22'!$F:$F,) -> Deposit Papaya Global EUR | F10: =IF(C10="Ltd",_xlfn.XLOOKUP(D10,Index!V:V,Index!R:R,),_xlfn.XLOOKUP(D10,Index!AG:AG,Index!AC:AC,)) -> Deposits | G10: =IF(C10="Ltd",_xlfn.XLOOKUP(D10,Index!V:V,Index!T:T,),_xlfn.XLOOKUP(D10,Index!AG:AG,Index!AE:AE,)) -> 0 | I10: =_xlfn.XLOOKUP(_xlfn.NUMBERVALUE(MID(D10,2,5)),'TB LTD 12.22'!E:E,'TB LTD 12.22'!H:H,0,0,1) -> 92428.98 | J10: =SUMIF(AJE!$E:$E,D10,AJE!$H:$H) -> 0 | K10: =SUMIF(AJE!$Q:$Q,D10,AJE!$T:$T) -> 0 | L10: =I10+J10+K10 -> 92428.98 | M10: =SUMIF(AJE!$AB:$AB,D10,AJE!$AE:$AE) -> 0 | N10: =L10+M10 -> 92428.98
A11: =_xlfn.XLOOKUP($B11,Index!$E:$E,Index!$D:$D,) -> 3 | B11: =IF($C11="Ltd",_xlfn.XLOOKUP($D11,Index!$V:$V,Index!$P:$P,),_xlfn.XLOOKUP($D11,Index!$AG:$AG,Index!$AA:$AA,)) -> Prepaid expenses and other receivable | C11: =IF(LEFT(D11)="1","Ltd","Inc") -> Ltd | D11: 11001831040 | E11: =_xlfn.XLOOKUP(_xlfn.NUMBERVALUE(MID(D11,2,5)),'TB LTD 12.22'!$E:$E,'TB LTD 12.22'!$F:$F,) -> Deposit Papaya Global GBP | F11: =IF(C11="Ltd",_xlfn.XLOOKUP(D11,Index!V:V,Index!R:R,),_xlfn.XLOOKUP(D11,Index!AG:AG,Index!AC:AC,)) -> Deposits | G11: =IF(C11="Ltd",_xlfn.XLOOKUP(D11,Index!V:V,Index!T:T,),_xlfn.XLOOKUP(D11,Index!AG:AG,Index!AE:AE,)) -> 0 | I11: =_xlfn.XLOOKUP(_xlfn.NUMBERVALUE(MID(D11,2,5)),'TB LTD 12.22'!E:E,'TB LTD 12.22'!H:H,0,0,1) -> 28298.83 | J11: =SUMIF(AJE!$E:$E,D11,AJE!$H:$H) -> 0 | K11: =SUMIF(AJE!$Q:$Q,D11,AJE!$T:$T) -> 0 | L11: =I11+J11+K11 -> 28298.83 | M11: =SUMIF(AJE!$AB:$AB,D11,AJE!$AE:$AE) -> 0 | N11: =L11+M11 -> 28298.83
A12: =_xlfn.XLOOKUP($B12,Index!$E:$E,Index!$D:$D,) -> 3 | B12: =IF($C12="Ltd",_xlfn.XLOOKUP($D12,Index!$V:$V,Index!$P:$P,),_xlfn.XLOOKUP($D12,Index!$AG:$AG,Index!$AA:$AA,)) -> Prepaid expenses and other receivable | C12: =IF(LEFT(D12)="1","Ltd","Inc") -> Ltd | D12: 11001931040 | E12: =_xlfn.XLOOKUP(_xlfn.NUMBERVALUE(MID(D12,2,5)),'TB LTD 12.22'!$E:$E,'TB LTD 12.22'!$F:$F,) -> Deposit Papaya Global SGD | F12: =IF(C12="Ltd",_xlfn.XLOOKUP(D12,Index!V:V,Index!R:R,),_xlfn.XLOOKUP(D12,Index!AG:AG,Index!AC:AC,)) -> Deposits | G12: =IF(C12="Ltd",_xlfn.XLOOKUP(D12,Index!V:V,Index!T:T,),_xlfn.XLOOKUP(D12,Index!AG:AG,Index!AE:AE,)) -> 0 | I12: =_xlfn.XLOOKUP(_xlfn.NUMBERVALUE(MID(D12,2,5)),'TB LTD 12.22'!E:E,'TB LTD 12.22'!H:H,0,0,1) -> 22336.74 | J12: =SUMIF(AJE!$E:$E,D12,AJE!$H:$H) -> 0 | K12: =SUMIF(AJE!$Q:$Q,D12,AJE!$T:$T) -> 0 | L12: =I12+J12+K12 -> 22336.74 | M12: =SUMIF(AJE!$AB:$AB,D12,AJE!$AE:$AE) -> 0 | N12: =L12+M12 -> 22336.74
A13: =_xlfn.XLOOKUP($B13,Index!$E:$E,Index!$D:$D,) -> 3 | B13: =IF($C13="Ltd",_xlfn.XLOOKUP($D13,Index!$V:$V,Index!$P:$P,),_xlfn.XLOOKUP($D13,Index!$AG:$AG,Index!$AA:$AA,)) -> Prepaid expenses and other receivable | C13: =IF(LEFT(D13)="1","Ltd","Inc") -> Ltd | D13: 11002031040 | E13: =_xlfn.XLOOKUP(_xlfn.NUMBERVALUE(MID(D13,2,5)),'TB LTD 12.22'!$E:$E,'TB LTD 12.22'!$F:$F,) -> Deposit Papaya Global AUD | F13: =IF(C13="Ltd",_xlfn.XLOOKUP(D13,Index!V:V,Index!R:R,),_xlfn.XLOOKUP(D13,Index!AG:AG,Index!AC:AC,)) -> Deposits | G13: =IF(C13="Ltd",_xlfn.XLOOKUP(D13,Index!V:V,Index!T:T,),_xlfn.XLOOKUP(D13,Index!AG:AG,Index!AE:AE,)) -> 0 | I13: =_xlfn.XLOOKUP(_xlfn.NUMBERVALUE(MID(D13,2,5)),'TB LTD 12.22'!E:E,'TB LTD 12.22'!H:H,0,0,1) -> 46548.47 | J13: =SUMIF(AJE!$E:$E,D13,AJE!$H:$H) -> 0 | K13: =SUMIF(AJE!$Q:$Q,D13,AJE!$T:$T) -> 0 | L13: =I13+J13+K13 -> 46548.47 | M13: =SUMIF(AJE!$AB:$AB,D13,AJE!$AE:$AE) -> 0 | N13: =L13+M13 -> 46548.47
A14: =_xlfn.XLOOKUP($B14,Index!$E:$E,Index!$D:$D,) -> 1 | B14: =IF($C14="Ltd",_xlfn.XLOOKUP($D14,Index!$V:$V,Index!$P:$P,),_xlfn.XLOOKUP($D14,Index!$AG:$AG,Index!$AA:$AA,)) -> Cash and Cash Equivalents | C14: =IF(LEFT(D14)="1","Ltd","Inc") -> Ltd | D14: 110023100 | E14: =_xlfn.XLOOKUP(_xlfn.NUMBERVALUE(MID(D14,2,5)),'TB LTD 12.22'!$E:$E,'TB LTD 12.22'!$F:$F,) -> פקדון שווה מזומנים עד 3 חודשים | F14: =IF(C14="Ltd",_xlfn.XLOOKUP(D14,Index!V:V,Index!R:R,),_xlfn.XLOOKUP(D14,Index!AG:AG,Index!AC:AC,)) -> 0 | G14: =IF(C14="Ltd",_xlfn.XLOOKUP(D14,Index!V:V,Index!T:T,),_xlfn.XLOOKUP(D14,Index!AG:AG,Index!AE:AE,)) -> 0 | I14: =_xlfn.XLOOKUP(_xlfn.NUMBERVALUE(MID(D14,2,5)),'TB LTD 12.22'!E:E,'TB LTD 12.22'!H:H,0,0,1) -> 2847895.3 | J14: =SUMIF(AJE!$E:$E,D14,AJE!$H:$H) -> 0 | K14: =SUMIF(AJE!$Q:$Q,D14,AJE!$T:$T) -> 0 | L14: =I14+J14+K14 -> 2847895.3 | M14: =SUMIF(AJE!$AB:$AB,D14,AJE!$AE:$AE) -> 0 | N14: =L14+M14 -> 2847895.3 | R14: =L14*3.519 -> 10021744
A15: =_xlfn.XLOOKUP($B15,Index!$E:$E,Index!$D:$D,) -> 1 | B15: =IF($C15="Ltd",_xlfn.XLOOKUP($D15,Index!$V:$V,Index!$P:$P,),_xlfn.XLOOKUP($D15,Index!$AG:$AG,Index!$AA:$AA,)) -> Cash and Cash Equivalents | C15: =IF(LEFT(D15)="1","Ltd","Inc") -> Ltd | D15: 110024100 | E15: =_xlfn.XLOOKUP(_xlfn.NUMBERVALUE(MID(D15,2,5)),'TB LTD 12.22'!$E:$E,'TB LTD 12.22'!$F:$F,) -> פקדון דולרי 357119482 6.12תאריך פתיחה | F15: =IF(C15="Ltd",_xlfn.XLOOKUP(D15,Index!V:V,Index!R:R,),_xlfn.XLOOKUP(D15,Index!AG:AG,Index!AC:AC,)) -> 0 | G15: =IF(C15="Ltd",_xlfn.XLOOKUP(D15,Index!V:V,Index!T:T,),_xlfn.XLOOKUP(D15,Index!AG:AG,Index!AE:AE,)) -> 0 | I15: =_xlfn.XLOOKUP(_xlfn.NUMBERVALUE(MID(D15,2,5)),'TB LTD 12.22'!E:E,'TB LTD 12.22'!H:H,0,0,1) -> 3010935.4 | J15: =SUMIF(AJE!$E:$E,D15,AJE!$H:$H) -> 0 | K15: =SUMIF(AJE!$Q:$Q,D15,AJE!$T:$T) -> 0 | L15: =I15+J15+K15 -> 3010935.4 | M15: =SUMIF(AJE!$AB:$AB,D15,AJE!$AE:$AE) -> 0 | N15: =L15+M15 -> 3010935.4 | R15: =L15*3.519 -> 10595482
A16: =_xlfn.XLOOKUP($B16,Index!$E:$E,Index!$D:$D,) -> 1 | B16: =IF($C16="Ltd",_xlfn.XLOOKUP($D16,Index!$V:$V,Index!$P:$P,),_xlfn.XLOOKUP($D16,Index!$AG:$AG,Index!$AA:$AA,)) -> Cash and Cash Equivalents | C16: =IF(LEFT(D16)="1","Ltd","Inc") -> Ltd | D16: 110025100 | E16: =_xlfn.XLOOKUP(_xlfn.NUMBERVALUE(MID(D16,2,5)),'TB LTD 12.22'!$E:$E,'TB LTD 12.22'!$F:$F,) -> פקדון דולרי 357119493 6.12תאריך פתיחה | F16: =IF(C16="Ltd",_xlfn.XLOOKUP(D16,Index!V:V,Index!R:R,),_xlfn.XLOOKUP(D16,Index!AG:AG,Index!AC:AC,)) -> 0 | G16: =IF(C16="Ltd",_xlfn.XLOOKUP(D16,Index!V:V,Index!T:T,),_xlfn.XLOOKUP(D16,Index!AG:AG,Index!AE:AE,)) -> 0 | I16: =_xlfn.XLOOKUP(_xlfn.NUMBERVALUE(MID(D16,2,5)),'TB LTD 12.22'!E:E,'TB LTD 12.22'!H:H,0,0,1) -> 4015429 | J16: =SUMIF(AJE!$E:$E,D16,AJE!$H:$H) -> 0 | K16: =SUMIF(AJE!$Q:$Q,D16,AJE!$T:$T) -> 0 | L16: =I16+J16+K16 -> 4015429 | M16: =SUMIF(AJE!$AB:$AB,D16,AJE!$AE:$AE) -> 0 | N16: =L16+M16 -> 4015429 | R16: =L16*3.519 -> 14130295
A17: =_xlfn.XLOOKUP($B17,Index!$E:$E,Index!$D:$D,) -> 1 | B17: =IF($C17="Ltd",_xlfn.XLOOKUP($D17,Index!$V:$V,Index!$P:$P,),_xlfn.XLOOKUP($D17,Index!$AG:$AG,Index!$AA:$AA,)) -> Cash and Cash Equivalents | C17: =IF(LEFT(D17)="1","Ltd","Inc") -> Ltd | D17: 111001100 | E17: =_xlfn.XLOOKUP(_xlfn.NUMBERVALUE(MID(D17,2,5)),'TB LTD 12.22'!$E:$E,'TB LTD 12.22'!$F:$F,) -> בנק הפועלים ש"ח חדש | F17: =IF(C17="Ltd",_xlfn.XLOOKUP(D17,Index!V:V,Index!R:R,),_xlfn.XLOOKUP(D17,Index!AG:AG,Index!AC:AC,)) -> 0 | G17: =IF(C17="Ltd",_xlfn.XLOOKUP(D17,Index!V:V,Index!T:T,),_xlfn.XLOOKUP(D17,Index!AG:AG,Index!AE:AE,)) -> 0 | I17: =_xlfn.XLOOKUP(_xlfn.NUMBERVALUE(MID(D17,2,5)),'TB LTD 12.22'!E:E,'TB LTD 12.22'!H:H,0,0,1) -> 4710236.8 | J17: =SUMIF(AJE!$E:$E,D17,AJE!$H:$H) -> 0 | K17: =SUMIF(AJE!$Q:$Q,D17,AJE!$T:$T) -> 0 | L17: =I17+J17+K17 -> 4710236.8 | M17: =SUMIF(AJE!$AB:$AB,D17,AJE!$AE:$AE) -> 0 | N17: =L17+M17 -> 4710236.8 | R17: =L17*3.519 -> 16575323
A18: =_xlfn.XLOOKUP($B18,Index!$E:$E,Index!$D:$D,) -> 1 | B18: =IF($C18="Ltd",_xlfn.XLOOKUP($D18,Index!$V:$V,Index!$P:$P,),_xlfn.XLOOKUP($D18,Index!$AG:$AG,Index!$AA:$AA,)) -> Cash and Cash Equivalents | C18: =IF(LEFT(D18)="1","Ltd","Inc") -> Ltd | D18: 111002100 | E18: =_xlfn.XLOOKUP(_xlfn.NUMBERVALUE(MID(D18,2,5)),'TB LTD 12.22'!$E:$E,'TB LTD 12.22'!$F:$F,) -> בנק הפועלים $ חדש | F18: =IF(C18="Ltd",_xlfn.XLOOKUP(D18,Index!V:V,Index!R:R,),_xlfn.XLOOKUP(D18,Index!AG:AG,Index!AC:AC,)) -> 0 | G18: =IF(C18="Ltd",_xlfn.XLOOKUP(D18,Index!V:V,Index!T:T,),_xlfn.XLOOKUP(D18,Index!AG:AG,Index!AE:AE,)) -> 0 | I18: =_xlfn.XLOOKUP(_xlfn.NUMBERVALUE(MID(D18,2,5)),'TB LTD 12.22'!E:E,'TB LTD 12.22'!H:H,0,0,1) -> 833462.03 | J18: =SUMIF(AJE!$E:$E,D18,AJE!$H:$H) -> 0 | K18: =SUMIF(AJE!$Q:$Q,D18,AJE!$T:$T) -> 0 | L18: =I18+J18+K18 -> 833462.03 | M18: =SUMIF(AJE!$AB:$AB,D18,AJE!$AE:$AE) -> 0 | N18: =L18+M18 -> 833462.03 | R18: =L18*3.519 -> 2932952.9
A19: =_xlfn.XLOOKUP($B19,Index!$E:$E,Index!$D:$D,) -> 1 | B19: =IF($C19="Ltd",_xlfn.XLOOKUP($D19,Index!$V:$V,Index!$P:$P,),_xlfn.XLOOKUP($D19,Index!$AG:$AG,Index!$AA:$AA,)) -> Cash and Cash Equivalents | C19: =IF(LEFT(D19)="1","Ltd","Inc") -> Ltd | D19: 111010100 | E19: =_xlfn.XLOOKUP(_xlfn.NUMBERVALUE(MID(D19,2,5)),'TB LTD 12.22'!$E:$E,'TB LTD 12.22'!$F:$F,) -> בנק הפועלים EUR יורו חדש | F19: =IF(C19="Ltd",_xlfn.XLOOKUP(D19,Index!V:V,Index!R:R,),_xlfn.XLOOKUP(D19,Index!AG:AG,Index!AC:AC,)) -> 0 | G19: =IF(C19="Ltd",_xlfn.XLOOKUP(D19,Index!V:V,Index!T:T,),_xlfn.XLOOKUP(D19,Index!AG:AG,Index!AE:AE,)) -> 0 | I19: =_xlfn.XLOOKUP(_xlfn.NUMBERVALUE(MID(D19,2,5)),'TB LTD 12.22'!E:E,'TB LTD 12.22'!H:H,0,0,1) -> 299801.79 | J19: =SUMIF(AJE!$E:$E,D19,AJE!$H:$H) -> 0 | K19: =SUMIF(AJE!$Q:$Q,D19,AJE!$T:$T) -> 0 | L19: =I19+J19+K19 -> 299801.79 | M19: =SUMIF(AJE!$AB:$AB,D19,AJE!$AE:$AE) -> 0 | N19: =L19+M19 -> 299801.79 | R19: =L19*3.519 -> 1055002.5
A20: =_xlfn.XLOOKUP($B20,Index!$E:$E,Index!$D:$D,) -> 1 | B20: =IF($C20="Ltd",_xlfn.XLOOKUP($D20,Index!$V:$V,Index!$P:$P,),_xlfn.XLOOKUP($D20,Index!$AG:$AG,Index!$AA:$AA,)) -> Cash and Cash Equivalents | C20: =IF(LEFT(D20)="1","Ltd","Inc") -> Ltd | D20: 111011100 | E20: =_xlfn.XLOOKUP(_xlfn.NUMBERVALUE(MID(D20,2,5)),'TB LTD 12.22'!$E:$E,'TB LTD 12.22'!$F:$F,) -> בנק פועלים GBP לירה שטרלינג חדש | F20: =IF(C20="Ltd",_xlfn.XLOOKUP(D20,Index!V:V,Index!R:R,),_xlfn.XLOOKUP(D20,Index!AG:AG,Index!AC:AC,)) -> 0 | G20: =IF(C20="Ltd",_xlfn.XLOOKUP(D20,Index!V:V,Index!T:T,),_xlfn.XLOOKUP(D20,Index!AG:AG,Index!AE:AE,)) -> 0 | I20: =_xlfn.XLOOKUP(_xlfn.NUMBERVALUE(MID(D20,2,5)),'TB LTD 12.22'!E:E,'TB LTD 12.22'!H:H,0,0,1) -> 415656.53 | J20: =SUMIF(AJE!$E:$E,D20,AJE!$H:$H) -> 0 | K20: =SUMIF(AJE!$Q:$Q,D20,AJE!$T:$T) -> 0 | L20: =I20+J20+K20 -> 415656.53 | M20: =SUMIF(AJE!$AB:$AB,D20,AJE!$AE:$AE) -> 0 | N20: =L20+M20 -> 415656.53 | R20: =L20*3.519 -> 1462695.3
A21: =_xlfn.XLOOKUP($B21,Index!$E:$E,Index!$D:$D,) -> 1 | B21: =IF($C21="Ltd",_xlfn.XLOOKUP($D21,Index!$V:$V,Index!$P:$P,),_xlfn.XLOOKUP($D21,Index!$AG:$AG,Index!$AA:$AA,)) -> Cash and Cash Equivalents | C21: =IF(LEFT(D21)="1","Ltd","Inc") -> Ltd | D21: 111012100 | E21: =_xlfn.XLOOKUP(_xlfn.NUMBERVALUE(MID(D21,2,5)),'TB LTD 12.22'!$E:$E,'TB LTD 12.22'!$F:$F,) -> בנק הפועלים AUD | F21: =IF(C21="Ltd",_xlfn.XLOOKUP(D21,Index!V:V,Index!R:R,),_xlfn.XLOOKUP(D21,Index!AG:AG,Index!AC:AC,)) -> 0 | G21: =IF(C21="Ltd",_xlfn.XLOOKUP(D21,Index!V:V,Index!T:T,),_xlfn.XLOOKUP(D21,Index!AG:AG,Index!AE:AE,)) -> 0 | I21: =_xlfn.XLOOKUP(_xlfn.NUMBERVALUE(MID(D21,2,5)),'TB LTD 12.22'!E:E,'TB LTD 12.22'!H:H,0,0,1) -> 220454.23 | J21: =SUMIF(AJE!$E:$E,D21,AJE!$H:$H) -> 0 | K21: =SUMIF(AJE!$Q:$Q,D21,AJE!$T:$T) -> 0 | L21: =I21+J21+K21 -> 220454.23 | M21: =SUMIF(AJE!$AB:$AB,D21,AJE!$AE:$AE) -> 0 | N21: =L21+M21 -> 220454.23 | R21: =L21*3.519 -> 775778.44
A22: =_xlfn.XLOOKUP($B22,Index!$E:$E,Index!$D:$D,) -> 1 | B22: =IF($C22="Ltd",_xlfn.XLOOKUP($D22,Index!$V:$V,Index!$P:$P,),_xlfn.XLOOKUP($D22,Index!$AG:$AG,Index!$AA:$AA,)) -> Cash and Cash Equivalents | C22: =IF(LEFT(D22)="1","Ltd","Inc") -> Ltd | D22: 111013100 | E22: =_xlfn.XLOOKUP(_xlfn.NUMBERVALUE(MID(D22,2,5)),'TB LTD 12.22'!$E:$E,'TB LTD 12.22'!$F:$F,) -> בנק הפועלים SGD | F22: =IF(C22="Ltd",_xlfn.XLOOKUP(D22,Index!V:V,Index!R:R,),_xlfn.XLOOKUP(D22,Index!AG:AG,Index!AC:AC,)) -> 0 | G22: =IF(C22="Ltd",_xlfn.XLOOKUP(D22,Index!V:V,Index!T:T,),_xlfn.XLOOKUP(D22,Index!AG:AG,Index!AE:AE,)) -> 0 | I22: =_xlfn.XLOOKUP(_xlfn.NUMBERVALUE(MID(D22,2,5)),'TB LTD 12.22'!E:E,'TB LTD 12.22'!H:H,0,0,1) -> 478724.33 | J22: =SUMIF(AJE!$E:$E,D22,AJE!$H:$H) -> 0 | K22: =SUMIF(AJE!$Q:$Q,D22,AJE!$T:$T) -> 0 | L22: =I22+J22+K22 -> 478724.33 | M22: =SUMIF(AJE!$AB:$AB,D22,AJE!$AE:$AE) -> 0 | N22: =L22+M22 -> 478724.33 | R22: =L22*3.519 -> 1684630.9
A23: =_xlfn.XLOOKUP($B23,Index!$E:$E,Index!$D:$D,) -> 1 | B23: =IF($C23="Ltd",_xlfn.XLOOKUP($D23,Index!$V:$V,Index!$P:$P,),_xlfn.XLOOKUP($D23,Index!$AG:$AG,Index!$AA:$AA,)) -> Cash and Cash Equivalents | C23: =IF(LEFT(D23)="1","Ltd","Inc") -> Ltd | D23: 111014100 | E23: =_xlfn.XLOOKUP(_xlfn.NUMBERVALUE(MID(D23,2,5)),'TB LTD 12.22'!$E:$E,'TB LTD 12.22'!$F:$F,) -> בנק SVB USD | F23: =IF(C23="Ltd",_xlfn.XLOOKUP(D23,Index!V:V,Index!R:R,),_xlfn.XLOOKUP(D23,Index!AG:AG,Index!AC:AC,)) -> 0 | G23: =IF(C23="Ltd",_xlfn.XLOOKUP(D23,Index!V:V,Index!T:T,),_xlfn.XLOOKUP(D23,Index!AG:AG,Index!AE:AE,)) -> 0 | I23: =_xlfn.XLOOKUP(_xlfn.NUMBERVALUE(MID(D23,2,5)),'TB LTD 12.22'!E:E,'TB LTD 12.22'!H:H,0,0,1) -> 1000000 | J23: =SUMIF(AJE!$E:$E,D23,AJE!$H:$H) -> 0 | K23: =SUMIF(AJE!$Q:$Q,D23,AJE!$T:$T) -> 0 | L23: =I23+J23+K23 -> 1000000 | M23: =SUMIF(AJE!$AB:$AB,D23,AJE!$AE:$AE) -> 0 | N23: =L23+M23 -> 1000000 | R23: =L23*3.519 -> 3519000
A24: =_xlfn.XLOOKUP($B24,Index!$E:$E,Index!$D:$D,) -> 6 | B24: =IF($C24="Ltd",_xlfn.XLOOKUP($D24,Index!$V:$V,Index!$P:$P,),_xlfn.XLOOKUP($D24,Index!$AG:$AG,Index!$AA:$AA,)) -> Accounts Payable | C24: =IF(LEFT(D24)="1","Ltd","Inc") -> Ltd | D24: 12100261030 | E24: =_xlfn.XLOOKUP(_xlfn.NUMBERVALUE(MID(D24,2,5)),'TB LTD 12.22'!$E:$E,'TB LTD 12.22'!$F:$F,) -> ישראכרט 0237 הד | F24: =IF(C24="Ltd",_xlfn.XLOOKUP(D24,Index!V:V,Index!R:R,),_xlfn.XLOOKUP(D24,Index!AG:AG,Index!AC:AC,)) -> Credit Cards | G24: =IF(C24="Ltd",_xlfn.XLOOKUP(D24,Index!V:V,Index!T:T,),_xlfn.XLOOKUP(D24,Index!AG:AG,Index!AE:AE,)) -> 0 | I24: =_xlfn.XLOOKUP(_xlfn.NUMBERVALUE(MID(D24,2,5)),'TB LTD 12.22'!E:E,'TB LTD 12.22'!H:H,0,0,1) -> -318.2 | J24: =SUMIF(AJE!$E:$E,D24,AJE!$H:$H) -> 0 | K24: =SUMIF(AJE!$Q:$Q,D24,AJE!$T:$T) -> 0 | L24: =I24+J24+K24 -> -318.2 | M24: =SUMIF(AJE!$AB:$AB,D24,AJE!$AE:$AE) -> 0 | N24: =L24+M24 -> -318.2
A25: =_xlfn.XLOOKUP($B25,Index!$E:$E,Index!$D:$D,) -> 6 | B25: =IF($C25="Ltd",_xlfn.XLOOKUP($D25,Index!$V:$V,Index!$P:$P,),_xlfn.XLOOKUP($D25,Index!$AG:$AG,Index!$AA:$AA,)) -> Accounts Payable | C25: =IF(LEFT(D25)="1","Ltd","Inc") -> Ltd | D25: 12100361030 | E25: =_xlfn.XLOOKUP(_xlfn.NUMBERVALUE(MID(D25,2,5)),'TB LTD 12.22'!$E:$E,'TB LTD 12.22'!$F:$F,) -> ישראכרט 4510 ירון | F25: =IF(C25="Ltd",_xlfn.XLOOKUP(D25,Index!V:V,Index!R:R,),_xlfn.XLOOKUP(D25,Index!AG:AG,Index!AC:AC,)) -> Credit Cards | G25: =IF(C25="Ltd",_xlfn.XLOOKUP(D25,Index!V:V,Index!T:T,),_xlfn.XLOOKUP(D25,Index!AG:AG,Index!AE:AE,)) -> 0 | I25: =_xlfn.XLOOKUP(_xlfn.NUMBERVALUE(MID(D25,2,5)),'TB LTD 12.22'!E:E,'TB LTD 12.22'!H:H,0,0,1) -> -69.35 | J25: =SUMIF(AJE!$E:$E,D25,AJE!$H:$H) -> 0 | K25: =SUMIF(AJE!$Q:$Q,D25,AJE!$T:$T) -> 0 | L25: =I25+J25+K25 -> -69.35 | M25: =SUMIF(AJE!$AB:$AB,D25,AJE!$AE:$AE) -> 0 | N25: =L25+M25 -> -69.35
A26: =_xlfn.XLOOKUP($B26,Index!$E:$E,Index!$D:$D,) -> 6 | B26: =IF($C26="Ltd",_xlfn.XLOOKUP($D26,Index!$V:$V,Index!$P:$P,),_xlfn.XLOOKUP($D26,Index!$AG:$AG,Index!$AA:$AA,)) -> Accounts Payable | C26: =IF(LEFT(D26)="1","Ltd","Inc") -> Ltd | D26: 12100661030 | E26: =_xlfn.XLOOKUP(_xlfn.NUMBERVALUE(MID(D26,2,5)),'TB LTD 12.22'!$E:$E,'TB LTD 12.22'!$F:$F,) -> ישרכארט ירון 4510 $ | F26: =IF(C26="Ltd",_xlfn.XLOOKUP(D26,Index!V:V,Index!R:R,),_xlfn.XLOOKUP(D26,Index!AG:AG,Index!AC:AC,)) -> Credit Cards | G26: =IF(C26="Ltd",_xlfn.XLOOKUP(D26,Index!V:V,Index!T:T,),_xlfn.XLOOKUP(D26,Index!AG:AG,Index!AE:AE,)) -> 0 | I26: =_xlfn.XLOOKUP(_xlfn.NUMBERVALUE(MID(D26,2,5)),'TB LTD 12.22'!E:E,'TB LTD 12.22'!H:H,0,0,1) -> -66.11 | J26: =SUMIF(AJE!$E:$E,D26,AJE!$H:$H) -> 0 | K26: =SUMIF(AJE!$Q:$Q,D26,AJE!$T:$T) -> 0 | L26: =I26+J26+K26 -> -66.11 | M26: =SUMIF(AJE!$AB:$AB,D26,AJE!$AE:$AE) -> 0 | N26: =L26+M26 -> -66.11
A27: =_xlfn.XLOOKUP($B27,Index!$E:$E,Index!$D:$D,) -> 6 | B27: =IF($C27="Ltd",_xlfn.XLOOKUP($D27,Index!$V:$V,Index!$P:$P,),_xlfn.XLOOKUP($D27,Index!$AG:$AG,Index!$AA:$AA,)) -> Accounts Payable | C27: =IF(LEFT(D27)="1","Ltd","Inc") -> Ltd | D27: 12100761030 | E27: =_xlfn.XLOOKUP(_xlfn.NUMBERVALUE(MID(D27,2,5)),'TB LTD 12.22'!$E:$E,'TB LTD 12.22'!$F:$F,) -> ישראכרט הד 0237 $ | F27: =IF(C27="Ltd",_xlfn.XLOOKUP(D27,Index!V:V,Index!R:R,),_xlfn.XLOOKUP(D27,Index!AG:AG,Index!AC:AC,)) -> Credit Cards | G27: =IF(C27="Ltd",_xlfn.XLOOKUP(D27,Index!V:V,Index!T:T,),_xlfn.XLOOKUP(D27,Index!AG:AG,Index!AE:AE,)) -> 0 | I27: =_xlfn.XLOOKUP(_xlfn.NUMBERVALUE(MID(D27,2,5)),'TB LTD 12.22'!E:E,'TB LTD 12.22'!H:H,0,0,1) -> -1534.11 | J27: =SUMIF(AJE!$E:$E,D27,AJE!$H:$H) -> 0 | K27: =SUMIF(AJE!$Q:$Q,D27,AJE!$T:$T) -> 0 | L27: =I27+J27+K27 -> -1534.11 | M27: =SUMIF(AJE!$AB:$AB,D27,AJE!$AE:$AE) -> 0 | N27: =L27+M27 -> -1534.11
A28: =_xlfn.XLOOKUP($B28,Index!$E:$E,Index!$D:$D,) -> 6 | B28: =IF($C28="Ltd",_xlfn.XLOOKUP($D28,Index!$V:$V,Index!$P:$P,),_xlfn.XLOOKUP($D28,Index!$AG:$AG,Index!$AA:$AA,)) -> Accounts Payable | C28: =IF(LEFT(D28)="1","Ltd","Inc") -> Ltd | D28: 12100861030 | E28: =_xlfn.XLOOKUP(_xlfn.NUMBERVALUE(MID(D28,2,5)),'TB LTD 12.22'!$E:$E,'TB LTD 12.22'!$F:$F,) -> ישראכרט 1943 | F28: =IF(C28="Ltd",_xlfn.XLOOKUP(D28,Index!V:V,Index!R:R,),_xlfn.XLOOKUP(D28,Index!AG:AG,Index!AC:AC,)) -> Credit Cards | G28: =IF(C28="Ltd",_xlfn.XLOOKUP(D28,Index!V:V,Index!T:T,),_xlfn.XLOOKUP(D28,Index!AG:AG,Index!AE:AE,)) -> 0 | I28: =_xlfn.XLOOKUP(_xlfn.NUMBERVALUE(MID(D28,2,5)),'TB LTD 12.22'!E:E,'TB LTD 12.22'!H:H,0,0,1) -> -9691.33 | J28: =SUMIF(AJE!$E:$E,D28,AJE!$H:$H) -> 0 | K28: =SUMIF(AJE!$Q:$Q,D28,AJE!$T:$T) -> 0 | L28: =I28+J28+K28 -> -9691.33 | M28: =SUMIF(AJE!$AB:$AB,D28,AJE!$AE:$AE) -> 0 | N28: =L28+M28 -> -9691.33
A29: =_xlfn.XLOOKUP($B29,Index!$E:$E,Index!$D:$D,) -> 6 | B29: =IF($C29="Ltd",_xlfn.XLOOKUP($D29,Index!$V:$V,Index!$P:$P,),_xlfn.XLOOKUP($D29,Index!$AG:$AG,Index!$AA:$AA,)) -> Accounts Payable | C29: =IF(LEFT(D29)="1","Ltd","Inc") -> Ltd | D29: 12100961030 | E29: =_xlfn.XLOOKUP(_xlfn.NUMBERVALUE(MID(D29,2,5)),'TB LTD 12.22'!$E:$E,'TB LTD 12.22'!$F:$F,) -> ישראכרט 1943 $ | F29: =IF(C29="Ltd",_xlfn.XLOOKUP(D29,Index!V:V,Index!R:R,),_xlfn.XLOOKUP(D29,Index!AG:AG,Index!AC:AC,)) -> Credit Cards | G29: =IF(C29="Ltd",_xlfn.XLOOKUP(D29,Index!V:V,Index!T:T,),_xlfn.XLOOKUP(D29,Index!AG:AG,Index!AE:AE,)) -> 0 | I29: =_xlfn.XLOOKUP(_xlfn.NUMBERVALUE(MID(D29,2,5)),'TB LTD 12.22'!E:E,'TB LTD 12.22'!H:H,0,0,1) -> -8574.42 | J29: =SUMIF(AJE!$E:$E,D29,AJE!$H:$H) -> 0 | K29: =SUMIF(AJE!$Q:$Q,D29,AJE!$T:$T) -> 0 | L29: =I29+J29+K29 -> -8574.42 | M29: =SUMIF(AJE!$AB:$AB,D29,AJE!$AE:$AE) -> 0 | N29: =L29+M29 -> -8574.42
A30: =_xlfn.XLOOKUP($B30,Index!$E:$E,Index!$D:$D,) -> 6 | B30: =IF($C30="Ltd",_xlfn.XLOOKUP($D30,Index!$V:$V,Index!$P:$P,),_xlfn.XLOOKUP($D30,Index!$AG:$AG,Index!$AA:$AA,)) -> Accounts Payable | C30: =IF(LEFT(D30)="1","Ltd","Inc") -> Ltd | D30: 12101061030 | E30: =_xlfn.XLOOKUP(_xlfn.NUMBERVALUE(MID(D30,2,5)),'TB LTD 12.22'!$E:$E,'TB LTD 12.22'!$F:$F,) -> ישראכרט 1943 EUR | F30: =IF(C30="Ltd",_xlfn.XLOOKUP(D30,Index!V:V,Index!R:R,),_xlfn.XLOOKUP(D30,Index!AG:AG,Index!AC:AC,)) -> Credit Cards | G30: =IF(C30="Ltd",_xlfn.XLOOKUP(D30,Index!V:V,Index!T:T,),_xlfn.XLOOKUP(D30,Index!AG:AG,Index!AE:AE,)) -> 0 | I30: =_xlfn.XLOOKUP(_xlfn.NUMBERVALUE(MID(D30,2,5)),'TB LTD 12.22'!E:E,'TB LTD 12.22'!H:H,0,0,1) -> -438.8 | J30: =SUMIF(AJE!$E:$E,D30,AJE!$H:$H) -> 0 | K30: =SUMIF(AJE!$Q:$Q,D30,AJE!$T:$T) -> 0 | L30: =I30+J30+K30 -> -438.8 | M30: =SUMIF(AJE!$AB:$AB,D30,AJE!$AE:$AE) -> 0 | N30: =L30+M30 -> -438.8
A31: =_xlfn.XLOOKUP($B31,Index!$E:$E,Index!$D:$D,) -> 6 | B31: =IF($C31="Ltd",_xlfn.XLOOKUP($D31,Index!$V:$V,Index!$P:$P,),_xlfn.XLOOKUP($D31,Index!$AG:$AG,Index!$AA:$AA,)) -> Accounts Payable | C31: =IF(LEFT(D31)="1","Ltd","Inc") -> Ltd | D31: 12101161030 | E31: =_xlfn.XLOOKUP(_xlfn.NUMBERVALUE(MID(D31,2,5)),'TB LTD 12.22'!$E:$E,'TB LTD 12.22'!$F:$F,) -> מסטרקרד 5930 | F31: =IF(C31="Ltd",_xlfn.XLOOKUP(D31,Index!V:V,Index!R:R,),_xlfn.XLOOKUP(D31,Index!AG:AG,Index!AC:AC,)) -> Credit Cards | G31: =IF(C31="Ltd",_xlfn.XLOOKUP(D31,Index!V:V,Index!T:T,),_xlfn.XLOOKUP(D31,Index!AG:AG,Index!AE:AE,)) -> 0 | I31: =_xlfn.XLOOKUP(_xlfn.NUMBERVALUE(MID(D31,2,5)),'TB LTD 12.22'!E:E,'TB LTD 12.22'!H:H,0,0,1) -> -3947.88 | J31: =SUMIF(AJE!$E:$E,D31,AJE!$H:$H) -> 0 | K31: =SUMIF(AJE!$Q:$Q,D31,AJE!$T:$T) -> 0 | L31: =I31+J31+K31 -> -3947.88 | M31: =SUMIF(AJE!$AB:$AB,D31,AJE!$AE:$AE) -> 0 | N31: =L31+M31 -> -3947.88
A32: =_xlfn.XLOOKUP($B32,Index!$E:$E,Index!$D:$D,) -> 6 | B32: =IF($C32="Ltd",_xlfn.XLOOKUP($D32,Index!$V:$V,Index!$P:$P,),_xlfn.XLOOKUP($D32,Index!$AG:$AG,Index!$AA:$AA,)) -> Accounts Payable | C32: =IF(LEFT(D32)="1","Ltd","Inc") -> Ltd | D32: 12101361030 | E32: =_xlfn.XLOOKUP(_xlfn.NUMBERVALUE(MID(D32,2,5)),'TB LTD 12.22'!$E:$E,'TB LTD 12.22'!$F:$F,) -> מסטרקרד 5930 $ | F32: =IF(C32="Ltd",_xlfn.XLOOKUP(D32,Index!V:V,Index!R:R,),_xlfn.XLOOKUP(D32,Index!AG:AG,Index!AC:AC,)) -> Credit Cards | G32: =IF(C32="Ltd",_xlfn.XLOOKUP(D32,Index!V:V,Index!T:T,),_xlfn.XLOOKUP(D32,Index!AG:AG,Index!AE:AE,)) -> 0 | I32: =_xlfn.XLOOKUP(_xlfn.NUMBERVALUE(MID(D32,2,5)),'TB LTD 12.22'!E:E,'TB LTD 12.22'!H:H,0,0,1) -> -349.31 | J32: =SUMIF(AJE!$E:$E,D32,AJE!$H:$H) -> 0 | K32: =SUMIF(AJE!$Q:$Q,D32,AJE!$T:$T) -> 0 | L32: =I32+J32+K32 -> -349.31 | M32: =SUMIF(AJE!$AB:$AB,D32,AJE!$AE:$AE) -> 0 | N32: =L32+M32 -> -349.31
