Workbook

Sheet דוח התאמה למס
B2: Papaya Gaming LTD | C2: דוח התאמה 2021
B6: רווח לפני מס 2021 | E6: ='P&L LTD USD'!J83-'P&L LTD USD'!J81 -> -53596018
B8: תיאום הוצאות עודפות:
B9: מחקר ופיתוח - דחיית הוצאות | E9: ='R&D 20A'!G8+'R&D 20A'!G9+'R&D 20A'!H9 -> 23487602 | F9: פריסה על פני 3 שנים
B10: מחקר ופיתוח - הכרה בהוצאות ש"ק | E10: ='R&D 20A'!F7+'R&D 20A'!F8 -> 2898754.6 | F10: בגין הוצאות שמקורן ב 2018-2019
A11: 23031 | B11: הוצאות בגין תשלום מבוסס מניות | E11: =VLOOKUP(A12,'TB LTD 12.21'!D:F,3,0) -> 88061.77
A12: 20060 | B12: הוצאות בגין תשלום מבוסס מניות | E12: =VLOOKUP(A13,'TB LTD 12.21'!D:F,3,0) -> 592674.04
A13: 20048 | B13: הוצאות בגין תשלום מבוסס מניות | E13: =VLOOKUP(A14,'TB LTD 12.21'!D:F,3,0) -> -939915.53
A14: 90017 | B14: גידול בהפרשה לחופשה | E14: =VLOOKUP(A15,'TB LTD 12.21'!D:F,3,0) -> -87155.72
A15: 90018 | B15: גידול בהפרשה להבראה | E15: =VLOOKUP(A16,'TB LTD 12.21'!D:F,3,0) -> 778158.31
A16: 20024 | B16: ארוחות | E16: =VLOOKUP(A17,'TB LTD 12.21'!D:F,3,0) -> 129166.79 | F16: 100% מתואם
A17: ='[1]TB 12.2018'!C7 -> 20001 | B17: כיבודים
B18: עודפות
B19: רווחי אקוויטי | E19: =-'[2]FS ILS 12.20'!E72 -> 0
A20: 20039 | B20: תרומות | E20: =VLOOKUP(A20,'[2]TB LTD 12.20'!$D:$F,3,FALSE)-17586.4 -> #N/A
A21: 20035 | B21: קנסות | E21: =+VLOOKUP(A21,'[2]TB LTD 12.20'!$D:$F,3,FALSE) -> #N/A | F21: קנסות תנועה + מוסדות
E23: =SUM(E9:E21) -> #N/A
N24: כרטיס | O24: תאור | Q24: סה"כ הוצאה | R24: שויים | S24: הוצאה עודפת
B25: הפסד מועבר משנת 2019 | E25: -4245210 | N25: 20014 | O25: מצרכים וכיבודים | Q25: #REF! | S25: =+Q25*0.2 -> #VALUE!
N26: 20021 | O26: מתנות | P26: 90015 | Q26: #REF! | R26: #REF! | S26: =+Q26-R26 -> #VALUE!
B27: הפסד לצרכי מס - מועבר לשנת 2021 | E27: =E6+E23+E25 -> #N/A | F27: =-E27+E25 -> #N/A | N27: 20024 | O27: ארוחות | P27: 90012 | Q27: #REF! | R27: #REF! | S27: =+Q27-R27 -> #VALUE!
N28: 20036 | O28: אירוע חברה | Q28: #REF! | S28: =+Q28 -> #REF!
B29: תרומה להעברה לשנים הבאות לשם קבלת הזיכוי | E29: =+E20 -> #N/A | F29: =+E27-E29 -> #N/A | N29: 20041 | O29: מתנות לעובדים חד פעמי | Q29: #REF! | S29: =+Q29 -> #REF!
S30: =0.45*SUM(S25:S29) -> #VALUE!
C32: USD | D32: NIS | E32: שיעור המס לפי מפעל טכנולוגי מועדף (גישה שמרנית)
B33: נכס מס נדחה בגין הפסד להעברה | C33: =+D33/'[2]FS USD 12.20'!$I$1 -> #N/A | D33: =-E27*E33 -> #N/A | E33: 0.12
A34: 90017 | B34: נכס מס נדחה בגין הפרשה לחופשה | C34: #REF! | D34: =-VLOOKUP(A34,'[2]TB LTD 12.20'!$D:$F,3,FALSE)*$E$34 -> #N/A | E34: 0.12 | O34: התאמת מו"פ
A35: 90018 | B35: נכס מס נדחה בגין הפרשה להבראה | C35: #REF! | D35: =-VLOOKUP(A35,'[2]TB LTD 12.20'!$D:$F,3,FALSE)*$E$35 -> #N/A | E35: 0.12
B36: הוצאות מו״פ שנדחו | C36: =+D36/'[2]FS USD 12.20'!$I$1 -> #DIV/0! | D36: =+SUM(M9:N10)*E36 -> 0 | E36: 0.12 | N36: הוצאות מו"פ | O36: =-'[2]FS ILS 12.20'!E60 -> 0
M38: 23012 | N38: הוצאות הפרשה להבראה מופ | O38: #REF!
M39: 23011 | N39: הוצאות חופשה מופ | O39: #REF!
M40: SBC Expenses R&D | N40: הוצאות בגין תשלום מבוסס מניות | O40: =-E11 -> -88061.77
O41: =SUM(O36:O40) -> -88061.77

Sheet Exp By type
C2: 1
B4: Total revenue
B6: Ua | C6: =SUMIFS('P&L LTD USD'!F:F,'P&L LTD USD'!A:A,'Exp By type'!B6)+SUMIFS('BS & P&L INC '!H:H,'BS & P&L INC '!B:B,'Exp By type'!B6) -> 1.2202517e+08
B7: Fee | C7: =SUMIFS('P&L LTD USD'!F:F,'P&L LTD USD'!A:A,'Exp By type'!B7)+SUMIFS('BS & P&L INC '!H:H,'BS & P&L INC '!B:B,'Exp By type'!B7) -> 9974297.2
B8: Payroll | C8: =SUMIFS('P&L LTD USD'!F:F,'P&L LTD USD'!A:A,'Exp By type'!B8)+SUMIFS('BS & P&L INC '!H:H,'BS & P&L INC '!B:B,'Exp By type'!B8) -> 10705311
B9: Options | C9: =SUMIFS('P&L LTD USD'!F:F,'P&L LTD USD'!A:A,'Exp By type'!B9)+SUMIFS('BS & P&L INC '!H:H,'BS & P&L INC '!B:B,'Exp By type'!B9) -> 1799715.3
B10: Overheads | C10: =SUMIFS('P&L LTD USD'!F:F,'P&L LTD USD'!A:A,'Exp By type'!B10)+SUMIFS('BS & P&L INC '!H:H,'BS & P&L INC '!B:B,'Exp By type'!B10) -> 5791686.4
B11: Financial expenses | C11: =SUMIFS('P&L LTD USD'!F:F,'P&L LTD USD'!A:A,'Exp By type'!B11)+SUMIFS('BS & P&L INC '!H:H,'BS & P&L INC '!B:B,'Exp By type'!B11) -> 2096047.3
B12: Taxes | C12: =SUMIFS('P&L LTD USD'!F:F,'P&L LTD USD'!A:A,'Exp By type'!B12)+SUMIFS('BS & P&L INC '!H:H,'BS & P&L INC '!B:B,'Exp By type'!B12) -> 1430649.1
B13: Ua Indirect | C13: =SUMIFS('P&L LTD USD'!F:F,'P&L LTD USD'!A:A,'Exp By type'!B13)+SUMIFS('BS & P&L INC '!H:H,'BS & P&L INC '!B:B,'Exp By type'!B13) -> 1095956
B14: Depreciation | C14: =SUMIFS('P&L LTD USD'!F:F,'P&L LTD USD'!A:A,'Exp By type'!B14)+SUMIFS('BS & P&L INC '!H:H,'BS & P&L INC '!B:B,'Exp By type'!B14) -> 83930.85
C15: =SUM(C6:C14) -> 1.5500277e+08
C16: =('P&L USD CONS'!I9+'P&L USD CONS'!I13+'P&L USD CONS'!I16+'P&L USD CONS'!I19+'P&L USD CONS'!I27+'P&L USD CONS'!I35)*1000 -> 1.5500277e+08
C17: =C15-C16 -> -0.38000005

Sheet Summary 
B4: Revenues | C4: 2021 | K4: =-4903754 -> -4903754 | L4: SALES TAX
B5: Revenues from commissions | C5: =(K5+K6+K9)*-1 -> -1.6990715e+08 | E5: commissions+ withdrawals | G5: =SUM('BS & P&L INC '!H40:H44) -> 1.7281009e+08 | K5: =SUM('BS & P&L INC '!H40:H44) -> 1.7281009e+08 | L5: commissions
B6: ADJ | C6: =-K4-K7-K8 -> 6836904.5 | G6: ='P&L LTD USD'!F6+'P&L LTD USD'!F7+'BS & P&L INC '!H45 -> -2970603.9 | K6: =-'P&L LTD USD'!F8 -> -3028063.4 | L6: withdrawals
B7: Total revenues | C7: =SUM(C5:C6) -> -1.6307024e+08 | K7: =-'P&L LTD USD'!F7 -> -3485732 | L7: NET CASH
K8: =-'P&L LTD USD'!F6 -> 1552581.5 | L8: ADD
B9: UA- Direct | C9: ='Exp By type'!C6 -> 1.2202517e+08 | K9: 125124 | L9: lasr year
B10: UA -Indirect | C10: ='Exp By type'!C13 -> 1095956
B11: Total Marketing | C11: =SUM(C9:C10) -> 1.2312113e+08
B13: GP | C13: =C7+C11 -> -39949114
B14: % | C14: =C13/C7 -> 0.24498102
B16: Clearing fees | C16: ='Exp By type'!C7 -> 9974297.2
B17: Payroll | C17: ='Exp By type'!C8 -> 10705311
B18: OverHeads | C18: ='Exp By type'!C10 -> 5791686.4
B20: EBITDA (Loss) | C20: =C13+C16+C17+C18 -> -13477820
B21: Options | C21: ='Exp By type'!C9 -> 1799715.3
B22: Depreciation | C22: ='Exp By type'!C14 -> 83930.85
B23: Financial Exp, net | C23: ='Exp By type'!C11 -> 2096047.3
B25: Tax | C25: ='Exp By type'!C12 -> 1430649.1
B27: Net profit (Loss) | C27: =C20+C22+C21+C23+C25 -> -8067477.5

Sheet COA1
A1: כותרת ראשית; | B1: כותרת משנה; | C1: סעיף; | D1: חשבון | E1: תאור חשבון
A2: **1.נכסים | B2: *10.רכוש שוטף | C2: 100.מזומנים ושווי מזומנים | D2: 80020 | E2: בנק לאומי 568400 | F2: BS | G2: Cash
A3: **1.נכסים | B3: *10.רכוש שוטף | C3: 100.מזומנים ושווי מזומנים | D3: 80021 | E3: בנק לאומי 568400 דולרי $ | F3: BS | G3: Cash
A4: **1.נכסים | B4: *10.רכוש שוטף | C4: 100.מזומנים ושווי מזומנים | D4: 80022 | E4: בנק PAYPAL דולרי $ | F4: BS | G4: Cash
A5: **1.נכסים | B5: *10.רכוש שוטף | C5: 100.מזומנים ושווי מזומנים | D5: 80024 | E5: בנק לאומי 568400 אירו E | F5: BS | G5: Cash
A6: **1.נכסים | B6: *10.רכוש שוטף | C6: 100.מזומנים ושווי מזומנים | D6: 80026 | E6: בנק אמריקאי LTD SVB | F6: BS | G6: Cash
A7: **1.נכסים | B7: *10.רכוש שוטף | C7: 100.מזומנים ושווי מזומנים | D7: 80027 | E7: בנק לאומי 568400 לירה שטרלניג | F7: BS | G7: Cash
A8: **1.נכסים | B8: *10.רכוש שוטף | C8: 106.לקוחות | D8: 100000 | E8: לקוחות מזדמנים חול | F8: BS | G8: Account receivable
A9: **1.נכסים | B9: *10.רכוש שוטף | C9: 106.לקוחות | D9: 100001 | E9: FACEBOOK לקוח | F9: BS | G9: Account receivable
A10: **1.נכסים | B10: *10.רכוש שוטף | C10: 106.לקוחות | D10: 100002 | E10: Unity Technologies לקוח | F10: BS | G10: Account receivable
A11: **1.נכסים | B11: *10.רכוש שוטף | C11: 106.לקוחות | D11: 100003 | E11: IronSource Mobile LTD | F11: BS | G11: Account receivable
A12: **1.נכסים | B12: *10.רכוש שוטף | C12: 106.לקוחות | D12: 100004 | E12: ADCOLONY INC לקוח | F12: BS | G12: Account receivable
A13: **1.נכסים | B13: *10.רכוש שוטף | C13: 106.לקוחות | D13: 100005 | E13: Applovin | F13: BS | G13: Account receivable
... A193: **2.התחייבויות | B193: *20.התחייבויות שוטפות | C193: 201.ספקי חו"ל | D193: 200269 | E193: DLA PIPER LLP | F193: BS | G193: Trade payables
A194: **2.התחייבויות | B194: *20.התחייבויות שוטפות | C194: 202.הוצאות לשלם | D194: 204-0 | E194: המחאות לפרעון | F194: BS | G194: Other accounts payable
A195: **2.התחייבויות | B195: *20.התחייבויות שוטפות | C195: 202.הוצאות לשלם | D195: 79999 | E195: הוצאות לשלם | F195: BS | G195: Accrued Expenses
A196: **2.התחייבויות | B196: *20.התחייבויות שוטפות | C196: 207.כרטיסי אשראי | D196: 80005 | E196: ויזה 8214 שקלי | F196: BS | G196: Trade payables
A197: **2.התחייבויות | B197: *20.התחייבויות שוטפות | C197: 207.כרטיסי אשראי | D197: 80006 | E197: ויזה 3711 שקלי | F197: BS | G197: Trade payables
A198: **2.התחייבויות | B198: *20.התחייבויות שוטפות | C198: 207.כרטיסי אשראי | D198: 80007 | E198: ויזה 3612 שקלי | F198: BS | G198: Trade payables
A199: **2.התחייבויות | B199: *20.התחייבויות שוטפות | C199: 207.כרטיסי אשראי | D199: 80008 | E199: ויזה 3612 דולרי | F199: BS | G199: Trade payables
A200: **2.התחייבויות | B200: *20.התחייבויות שוטפות | C200: 207.כרטיסי אשראי | D200: 80010 | E200: ויזה 8214 דולרי | F200: BS | G200: Trade payables
A201: **2.התחייבויות | B201: *20.התחייבויות שוטפות | C201: 208.זכאים אחרים | D201: 51002 | E201: הלוואה SVB 800K | F201: BS | G201: Loan-Long term
A202: **2.התחייבויות | B202: *20.התחייבויות שוטפות | C202: 208.זכאים אחרים | D202: 51018 | E202: הלוואה שנייה SVB 800K | F202: BS | G202: Loan-Long term
A203: **2.התחייבויות | B203: *20.התחייבויות שוטפות | C203: 208.זכאים אחרים | D203: 51019 | E203: הלוואה שלישית $16M | F203: BS | G203: Loan-Short term
A204: **2.התחייבויות | B204: *25.התחייבויות לטווח ארוך | C204: 250.הלוואות לזמן ארוך | D204: 25001 | E204: חלויות שוטפות - הלוואה 1 SVB 800K | F204: BS | G204: Loan-Short term
A205: **2.התחייבויות | B205: *25.התחייבויות לטווח ארוך | C205: 251.צדדים קשורים | D205: 45000 | E205: אוריאל בכר | F205: BS | G205: Other accounts payable
A206: **2.התחייבויות | B206: *25.התחייבויות לטווח ארוך | C206: 251.צדדים קשורים | D206: 51000 | E206: אוריאל בכר חוז בעלים | F206: BS | G206: Shareholders' loan
... A245: **3.הון עצמי | B245: *30.הון עצמי | C245: 304.פרמיה | D245: 80001 | E245: חייבים על חשבון מניות | F245: BS | G245: Other accounts receivable
A246: **4.הכנסות | B246: *40.הכנסות | C246: 400.הכנסות ממכירות בארץ | D246: 4000 | E246: הכנסות מפרסום חייבות במעמ | F246: PL | G246: Revenues | H246: ads revenue
A247: **4.הכנסות | B247: *40.הכנסות | C247: 400.הכנסות ממכירות בארץ | D247: 4001 | E247: הכנסות פטורות ממע'מ | F247: PL | G247: Revenues | H247: ads revenue
A248: **4.הכנסות | B248: *40.הכנסות | C248: 401.הכנסות מיצוא | D248: 4002 | E248: הכנסות פטורות מעמ - פרסום | F248: PL | G248: Revenues | H248: ads revenue
A249: **4.הכנסות | B249: *40.הכנסות | C249: 401.הכנסות מיצוא | D249: 4005 | E249: הכנסות לקבל -תוצאתי | F249: PL | G249: Revenues | H249: =G249 -> Revenues
A250: **5.הוצאות מו"פ | B250: *50.הוצאות מו"פ | C250: 500.עלות מכירות | D250: 21001 | E250: COGS Salary : Support | F250: PL | G250: Cost of revenues | H250: Salary
A251: **5.הוצאות מו"פ | B251: *50.הוצאות מו"פ | C251: 500.עלות מכירות | D251: 21002 | E251: COGS Education fund : Support | F251: PL | G251: Cost of revenues | H251: Salary
A252: **5.הוצאות מו"פ | B252: *50.הוצאות מו"פ | C252: 500.עלות מכירות | D252: 21003 | E252: COGS Social security : Support | F252: PL | G252: Cost of revenues | H252: Salary
A253: **5.הוצאות מו"פ | B253: *50.הוצאות מו"פ | C253: 500.עלות מכירות | D253: 21004 | E253: COGS Gemel : Support | F253: PL | G253: Cost of revenues | H253: Salary
A254: **5.הוצאות מו"פ | B254: *50.הוצאות מו"פ | C254: 500.עלות מכירות | D254: 21005 | E254: COGS Salary : VIP | F254: PL | G254: Marketing expenses | H254: Salary
A255: **5.הוצאות מו"פ | B255: *50.הוצאות מו"פ | C255: 500.עלות מכירות | D255: 21006 | E255: COGS Education fund : VIP | F255: PL | G255: Marketing expenses | H255: Salary
A256: **5.הוצאות מו"פ | B256: *50.הוצאות מו"פ | C256: 500.עלות מכירות | D256: 21007 | E256: COGS Social security : VIP | F256: PL | G256: Marketing expenses | H256: Salary
A257: **5.הוצאות מו"פ | B257: *50.הוצאות מו"פ | C257: 500.עלות מכירות | D257: 21008 | E257: COGS Gemel : VIP | F257: PL | G257: Marketing expenses | H257: Salary
...

Sheet FS
A1: 44561
A2: FS
A3: Papaya Gaming Ltd
A4: USD
A7: BS | F7: PL
C10: 44561 | H10: 44561
C11: Consolidated | H11: Consolidated
B14: CURRENT ASSETS | G14: Total Revenues | H14: ='P&L USD CONS'!I7 -> -163070.24
B16: Cash | C16: =(SUMIF('BS LTD USD '!B:B,$B16,'BS LTD USD '!F:F)+SUMIF('BS & P&L INC '!D:D,$B16,'BS & P&L INC '!H:H))/1000 -> 48515.492 | G16: Cost of revenues | H16: ='P&L USD CONS'!I9 -> 12204.051
A17: Deposit | B17: Restricted cash | C17: =(SUMIF('BS LTD USD '!B:B,$A17,'BS LTD USD '!F:F)+SUMIF('BS & P&L INC '!D:D,$A17,'BS & P&L INC '!H:H))/1000 -> 16.07717 | G17: Gross loss (profit) | H17: ='P&L USD CONS'!I10 -> -150866.19
B18: Account receivable | C18: =(SUMIF('BS LTD USD '!B:B,$B18,'BS LTD USD '!F:F)+SUMIF('BS & P&L INC '!D:D,$B18,'BS & P&L INC '!H:H))/1000 -> 1196.0119
B19: Shareholders' loan | C19: =(SUMIF('BS LTD USD '!B:B,$B19,'BS LTD USD '!F:F)+SUMIF('BS & P&L INC '!D:D,$B19,'BS & P&L INC '!H:H))/1000 -> 0
A20: Other accounts receivable | B20: Prepaid exepnses and other current assets | C20: =(SUMIF('BS LTD USD '!B:B,$A20,'BS LTD USD '!F:F)+SUMIF('BS & P&L INC '!D:D,$A20,'BS & P&L INC '!H:H))/1000+'BS USD CONS '!L16 -> 2484.7225 | G20: Research and development expenses, net | H20: ='P&L USD CONS'!I13 -> 11109.841
C21: =SUM(C16:C20) -> 52212.304
B23: NON-CURRENT ASSETS | G23: Marketing expenses | H23: ='P&L USD CONS'!I16 -> 124286.33
B25: Property and equipment, net | C25: =(SUMIF('BS LTD USD '!B:B,$A26,'BS LTD USD '!F:F)+SUMIF('BS & P&L INC '!D:D,$A26,'BS & P&L INC '!H:H))/1000 -> 501.8953
A26: Fixed assets, net | B26: ROU Assets | C26: ='BS USD CONS '!L23 -> 409.12167 | G26: General and administrative expenses | H26: ='P&L USD CONS'!I19 -> 3875.8447
A27: Reserve - Wordpay | B27: Long term restricted cash | C27: =+(SUMIF('BS LTD USD '!B:B,$A27,'BS LTD USD '!F:F)+SUMIF('BS & P&L INC '!D:D,$A27,'BS & P&L INC '!H:H))/1000 -> 199.999
B28: Deffered Tax | C28: ='BS USD CONS '!L24 -> 939.40895
C29: =SUM(C25:C28) -> 2050.4249
G30: Operating expenses | H30: ='P&L USD CONS'!I23 -> 139272.02
B31: Total Assets | C31: =C29+C21 -> 54262.729
G32: Operating loss (profit) | H32: ='P&L USD CONS'!I25 -> -11594.171
B34: CURRENT LIABILITIES | G34: Financial expenses, net | H34: ='P&L USD CONS'!I27 -> 2096.0473
A36: Trade payables | B36: Account payables | C36: =(SUMIF('BS LTD USD '!B:B,$A36,'BS LTD USD '!F:F)+SUMIF('BS & P&L INC '!D:D,$A36,'BS & P&L INC '!H:H))/1000 -> -13433.835 | G36: TP Expenses | H36: ='P&L USD CONS'!I29 -> 0
A37: Loan-Short Term | B37: Current maurities of short term loan | C37: =(SUMIF('BS LTD USD '!B:B,$A37,'BS LTD USD '!F:F)+SUMIF('BS & P&L INC '!D:D,$A37,'BS & P&L INC '!H:H))/1000 -> -2033.334
B38: Contract liability | C38: =(SUMIF('BS LTD USD '!B:B,$B38,'BS LTD USD '!F:F)+SUMIF('BS & P&L INC '!D:D,$B38,'BS & P&L INC '!H:H))/1000 -> -4087.657 | G38: Equity | H38: ='P&L USD CONS'!I31 -> 0
B39: Related Party-AP | C39: =(SUMIF('BS LTD USD '!B:B,$B39,'BS LTD USD '!F:F)+SUMIF('BS & P&L INC '!D:D,$B39,'BS & P&L INC '!H:H))/1000 -> 0
A40: Accrued expenses | B40: ROA Liability | C40: =(SUMIF('BS LTD USD '!B:B,$B40,'BS LTD USD '!F:F)+SUMIF('BS & P&L INC '!D:D,$B40,'BS & P&L INC '!H:H))/1000 -> -385.35969 | G40: loss before taxes | H40: ='P&L USD CONS'!I33 -> -9498.1238
A41: Other accounts payable | B41: Other accounts payable and accrued expenses | C41: =(SUMIF('BS LTD USD '!B:B,$A41,'BS LTD USD '!F:F)+SUMIF('BS & P&L INC '!D:D,$A41,'BS & P&L INC '!H:H))/1000+(SUMIF('BS LTD USD '!B:B,$A40,'BS LTD USD '!F:F)+SUMIF('BS & P&L INC '!D:D,$A40,'BS & P&L INC '!H:H))/1000+'BS USD CONS '!L38 -> -20587.203
C42: =SUM(C36:C41) -> -40527.389 | G42: Tax expenses | H42: ='P&L USD CONS'!I35 -> 1430.6491
A44: Loan-Long Term | B44: Current maurities of long term loan | C44: =(SUMIF('BS LTD USD '!B:B,$A44,'BS LTD USD '!F:F)+SUMIF('BS & P&L INC '!D:D,$A44,'BS & P&L INC '!H:H))/1000 -> -533.33272 | G44: Net loss ( profit ) | H44: ='P&L USD CONS'!I37 -> -8067.4747
B45: Shareholders | C45: =(SUMIF('BS LTD USD '!B:B,$B45,'BS LTD USD '!F:F)+SUMIF('BS & P&L INC '!D:D,$B45,'BS & P&L INC '!H:H))/1000 -> -500
B46: Convertible Loan | C46: =(SUMIF('BS LTD USD '!B:B,$B46,'BS LTD USD '!F:F)+SUMIF('BS & P&L INC '!D:D,$B46,'BS & P&L INC '!H:H))/1000 -> 0
C47: =SUM(C44:C46) -> -1033.3327
B49: Total liabilities | C49: =C47+C42 -> -41560.722
B51: SHAREHOLDERS' EQUITY
B53: Share capital - Ordinary Shares | C53: =(SUMIF('BS LTD USD '!B:B,$B53,'BS LTD USD '!F:F)+SUMIF('BS & P&L INC '!D:D,$B53,'BS & P&L INC '!H:H))/1000 -> -0.41892
B54: Share capital - Preferred Seed-1 | C54: =(SUMIF('BS LTD USD '!B:B,$B54,'BS LTD USD '!F:F)+SUMIF('BS & P&L INC '!D:D,$B54,'BS & P&L INC '!H:H))/1000 -> -0.191
A55: PL | B55: Share capital - Preferred Seed | C55: =(SUMIF('BS LTD USD '!B:B,$B55,'BS LTD USD '!F:F)+SUMIF('BS & P&L INC '!D:D,$B55,'BS & P&L INC '!H:H))/1000 -> -0.04924
...

Sheet FS Notes
A1: 44561
A2: FS Notes
A3: Papaya Gaming Ltd
A4: USD
B7: Note 3 - Property and Equipment, Net
F8: Signed FS
B9: Group | D9: 44561 | F9: 44196
B10: Computers and electronic equipment | D10: ='TB LTD 12.21'!G33/1000 -> 367.919 | F10: 96
B11: Vehicles | D11: ='TB LTD 12.21'!G31/1000 -> 2.80932 | F11: 3
B12: Office furniture and equipment | D12: =('TB LTD 12.21'!G35+'TB LTD 12.21'!G40)/1000 -> 204.18 | F12: 10
B13: Leasehold improvements | D13: ='TB LTD 12.21'!G36/1000 -> 36.289 | F13: 3
D14: =SUM(D10:D13) -> 611.19732 | F14: =SUM(F10:F13) -> 112
B15: Less – accumulated depreciation | D15: =SUM('TB LTD 12.21'!G32,'TB LTD 12.21'!G34,'TB LTD 12.21'!G37,'TB LTD 12.21'!G38,'TB LTD 12.21'!G39)/1000-'AJE 2021'!H75/1000 -> -169.28042 | F15: -31
B16: Total property and equipment, net | D16: =SUM(D14:D15) -> 441.9169 | F16: =SUM(F14:F15) -> 81
B20: Note 5 - Other current Liabilities
F21: Signed FS
B22: Group | D22: 44561 | F22: 44196 | I22: Other current liabilities INC
B23: Accrued expenses | D23: =-'TB LTD 12.21'!G105/1000-(O25+O24+O26)/1000 -> 11178.135 | F23: 622 | I23: Entity | K23: Account | M23: 44196 | O23: 44561
B24: Payroll and related expenses | D24: =-SUM('TB LTD 12.21'!G19:G28)/1000 -> 787.95071 | F24: 372 | I24: INC | K24: SVB Commission | M24: -125276.67 | O24: -518442.74
B25: WHT | D25: =-'TB LTD 12.21'!G9/1000 -> 123.88293 | F25: 0 | I25: INC | K25: WorldPay Commission | M25: 0 | O25: -35916.02
B26: Income tax payable | D26: =-O27/1000 -> 101.4614 | F26: 0 | I26: INC | K26: James Kong | M26: 0 | O26: -8333.33
B27: Sales Tax | D27: ='AJE 2021'!H80/1000 -> 4903.7544 | F27: 0 | I27: INC | K27: Income tax payable | M27: 714 | O27: -101461.4
D28: =SUM(D23:D27) -> 17095.185 | F28: =SUM(F23:F27) -> 994
B31: Note 11 - Supplementary statements of operation information
F32: Signed FS
B33: a. Research and development expenses: | D33: 44561 | F33: 44196
B34: Payroll and related expenses | D34: =SUM('TB LTD 12.21'!G173,'TB LTD 12.21'!G187:G232,'TB LTD 12.21'!G249,'TB LTD 12.21'!G251,'TB LTD 12.21'!G253)/1000 -> 7099.7379 | F34: 1089
B35: Computer Maintenance | D35: =('TB LTD 12.21'!G350)/1000 -> 85.34424 | F35: 159
B36: Software subscription | D36: =SUM('TB LTD 12.21'!G238,'TB LTD 12.21'!G241,'TB LTD 12.21'!G243:G244,'TB LTD 12.21'!G247,'TB LTD 12.21'!G250)/1000 -> 928.35154 | F36: 0
B37: Professional consulting | D37: =SUM('TB LTD 12.21'!G239+'TB LTD 12.21'!G240+'TB LTD 12.21'!G254+'TB LTD 12.21'!G236)/1000 -> 325.46562 | F37: 535
B38: Share-based compensation | D38: ='TB LTD 12.21'!G245/1000+'P&L LTD USD'!E30/1000 -> 1013.82 | F38: 370
B39: Hosting and Servers | D39: ='TB LTD 12.21'!G252/1000 -> 683.8814 | F39: 0
B40: Other | D40: =SUM('TB LTD 12.21'!G233,'TB LTD 12.21'!G234,'TB LTD 12.21'!G237,'TB LTD 12.21'!G242,'TB LTD 12.21'!G246,'TB LTD 12.21'!G248)/1000 -> 973.24008 | F40: 144
D41: =SUM(D34:D40) -> 11109.841 | F41: =SUM(F34:F40) -> 2297
F43: Signed FS
B44: b. Marketing expenses: | D44: 44561 | F44: 44196
B45: Payroll and related expenses | D45: =SUM('TB LTD 12.21'!G255:G260,'TB LTD 12.21'!G262:G269,'TB LTD 12.21'!G279)/1000 -> 993.65178 | F45: 314
B46: Marketing and Advertising | D46: =SUM('TB LTD 12.21'!G270,'TB LTD 12.21'!G273,'TB LTD 12.21'!G275:G277,'TB LTD 12.21'!G329)/1000 -> 122701.85 | F46: 12695
B47: Software subscription | D47: =SUM('TB LTD 12.21'!G271:G272,'TB LTD 12.21'!G280)/1000 -> 419.27489 | F47: 0
B48: Share-based compensation | D48: ='TB LTD 12.21'!G281/1000+'P&L LTD USD'!E41/1000 -> 4.8493898 | F48: 0
...

Sheet P&L USD CONS
D3: 44561 | F3: 44561 | G3: Cons | I3: 44561
D4: LTD | F4: INC | I4: Consolidated
I5: $ In thousands
B7: Total Revenues | D7: =SUMIF('P&L LTD USD'!C:C,B:B,'P&L LTD USD'!F:F) -> -1.6307024e+08 | F7: =-SUMIF('BS & P&L INC '!C:C,'P&L USD CONS'!$B:$B,'BS & P&L INC '!H:H) -> -1.9482323e+08 | G7: =-F7 -> 1.9482323e+08 | I7: =(+F7+D7+G7)/1000 -> -163070.24
B9: Cost of revenues | D9: =SUMIF('P&L LTD USD'!C:C,B:B,'P&L LTD USD'!F:F) -> 12753463 | F9: =SUMIF('BS & P&L INC '!C:C,'P&L USD CONS'!$B:$B,'BS & P&L INC '!H:H) -> 10174297 | G9: =-F9*1.054 -> -10723709 | I9: =(+F9+D9+G9)/1000 -> 12204.051 | J9: =-I9+12732 -> 527.94924
B10: Gross loss (profit) | D10: =D9+D7 -> -1.5031678e+08 | F10: =F9+F7 -> -1.8464893e+08 | G10: =G9+G7 -> 1.8409952e+08 | I10: =I9+I7 -> -150866.19
I11: =-I9/I7 -> 0.074839227
B13: Research and development expenses, net | D13: =SUMIF('P&L LTD USD'!C:C,B:B,'P&L LTD USD'!F:F) -> 11109841 | F13: =SUMIF('BS & P&L INC '!C:C,'P&L USD CONS'!$B:$B,'BS & P&L INC '!H:H) -> 0 | I13: =(+F13+D13+G13)/1000 -> 11109.841
I14: =-I13/I7 -> 0.068129174
B16: Marketing expenses | D16: =SUMIF('P&L LTD USD'!C:C,B:B,'P&L LTD USD'!F:F) -> 1.2428633e+08 | F16: =SUMIF('BS & P&L INC '!C:C,'P&L USD CONS'!$B:$B,'BS & P&L INC '!H:H) -> 16152223 | G16: =-F16 -> -16152223 | I16: =(+F16+D16+G16)/1000 -> 124286.33
I17: =-I16/I7 -> 0.76216441
B19: General and administrative expenses | D19: =SUMIF('P&L LTD USD'!C:C,B:B,'P&L LTD USD'!F:F) -> 3877943.4 | F19: =SUMIF('BS & P&L INC '!C:C,'P&L USD CONS'!$B:$B,'BS & P&L INC '!H:H) -> 38866.25 | G19: =-F19*1.054 -> -40965.028 | I19: =(+F19+D19+G19)/1000 -> 3875.8447 | J19: =-I19+3238 -> -637.84466
I21: =-I19/I7 -> 0.023767946
B23: Operating expenses | D23: =+D19+D16+D13 -> 1.3927412e+08 | E23: =+E19+E16+E13 -> 0 | F23: =+F19+F16+F13 -> 16191089 | G23: =+G19+G16+G13 -> -16193188 | I23: =+I19+I16+I13 -> 139272.02
B25: Operating loss (pprofit) | D25: =SUMIF('P&L LTD USD'!C:C,B:B,'P&L LTD USD'!F:F) -> -11042660 | F25: =F10+F23 -> -1.6845784e+08 | G25: =G10+G23 -> 1.6790633e+08 | I25: =I23+I10 -> -11594.171
B27: Financial expenses, net | D27: =SUMIF('P&L LTD USD'!C:C,B:B,'P&L LTD USD'!F:F) -> 1934278.3 | F27: =SUMIF('BS & P&L INC '!C:C,'P&L USD CONS'!$B:$B,'BS & P&L INC '!H:H) -> 161769.01 | I27: =(+F27+D27+G27)/1000 -> 2096.0473 | J27: =-I27+483 -> -1613.0473
B29: TP Expenses | D29: =SUMIF('P&L LTD USD'!C:C,B:B,'P&L LTD USD'!F:F) -> 0 | F29: =SUMIF('BS & P&L INC '!C:C,'P&L USD CONS'!$B:$B,'BS & P&L INC '!H:H) -> 1.6790633e+08 | G29: =-F29 -> -1.6790633e+08 | I29: =(+F29+D29+G29)/1000 -> 0
B31: Equity | D31: =SUMIF('P&L LTD USD'!C:C,B:B,'P&L LTD USD'!F:F) -> -258145.04 | F31: =-SUMIF('BS & P&L INC '!C:C,'P&L USD CONS'!$B:$B,'BS & P&L INC '!F:F) -> 0 | G31: =-D31 -> 258145.04 | I31: =(+F31+D31+G31)/1000 -> 0
M32: Exchange rate | N32: -30318.74 | P32: -30318.74
B33: loss before taxes | D33: =SUM(D25:D31) -> -9366527.1 | F33: =SUM(F25:F31) -> -389741.81 | G33: =SUM(G25:G31) -> 258145.04 | I33: =SUM(I25:I31) -> -9498.1238 | J33: =I33+17352 -> 7853.8762 | M33: Financial expenses | N33: 0 | O33: 1286.6572 | P33: 1286.6572
B35: Tax expenses | D35: =SUMIF('P&L LTD USD'!C:C,B:B,'P&L LTD USD'!F:F) -> 1299052.3 | F35: =SUMIF('BS & P&L INC '!C:C,'P&L USD CONS'!$B:$B,'BS & P&L INC '!H:H) -> 131596.77 | I35: =(+F35+D35+G35)/1000 -> 1430.6491 | J35: =-I35+2266 -> 835.3509 | M35: Epricing Fee -Currency difference | N35: 111676 | P35: 111676
M36: Exchange rate paypal | N36: 48647 | P36: 48647
B37: Net loss ( profit ) | D37: =+D33+D35 -> -8067474.7 | F37: =+F35+F33 -> -258145.04 | G37: =+G35+G33 -> 258145.04 | I37: =+I33+I35 -> -8067.4747 | J37: =I37+15086 -> 7018.5253
K38: =I35+I27+I19+I16+I13+I9 -> 155002.77
D39: ='P&L LTD USD'!AD83 -> 0 | G39: Old Arkava | I39: -14564.324
G41: GAP | I41: =I37-I39 -> 6496.8494
D43: =('P&L USD CONS'!I9+'P&L USD CONS'!I13+'P&L USD CONS'!I16+'P&L USD CONS'!I19+'P&L USD CONS'!I27+'P&L USD CONS'!I35)*1000 -> 1.5500277e+08 | I43: ='BS & P&L INC '!H45/1000 -> -4903.7544 | K43: Sales Tax
I44: =-'AJE 2021'!G48/1000 -> -225.333 | K44: Net cash
I45: -156 | K45: Option
I46: ='AJE 2021'!H89/1000 -> 0 | K46: Israeli Tax
G47: Check | I47: =SUM(I43:I46)+I41 -> 1211.762

Sheet BS USD CONS 
D3: 44561 | F3: =D3 -> 44561 | H3: איחוד | J3: =F3 -> 44561 | L3: =J3 -> 44561
D4: LTD | F4: INC | J4: Consolidated | L4: Consolidated
D5: USD | F5: USD | J5: $ round | L5: $ In thousands
B6: CURRENT ASSETS
B8: Cash | D8: =SUMIF('BS LTD USD '!B:B,'BS USD CONS '!$B8,'BS LTD USD '!F:F) -> 12155821 | F8: =SUMIF('BS & P&L INC '!D:D,'BS USD CONS '!$B8,'BS & P&L INC '!H:H) -> 36359671 | J8: =+F8+D8 -> 48515492 | L8: =J8/1000 -> 48515.492
B9: Account receivable | D9: =SUMIF('BS LTD USD '!B:B,'BS USD CONS '!$B9,'BS LTD USD '!F:F) -> 1196011.9 | F9: =SUMIF('BS & P&L INC '!D:D,'BS USD CONS '!$B9,'BS & P&L INC '!H:H) -> 0 | J9: =+F9+D9 -> 1196011.9 | L9: =J9/1000 -> 1196.0119
B10: Related Party | D10: =SUMIF('BS LTD USD '!B:B,'BS USD CONS '!$B10,'BS LTD USD '!F:F) -> 32471839 | F10: =SUMIF('BS & P&L INC '!D:D,'BS USD CONS '!$B10,'BS & P&L INC '!H:H) -> -32471840 | J10: =+F10+D10 -> -1.38 | L10: =J10/1000 -> -0.00138
B11: Related Party-AR | D11: =SUMIF('BS LTD USD '!B:B,'BS USD CONS '!$B11,'BS LTD USD '!F:F) -> 0 | F11: =SUMIF('BS & P&L INC '!D:D,'BS USD CONS '!$B11,'BS & P&L INC '!H:H) -> 0 | J11: =+F11+D11 -> 0 | L11: =J11/1000 -> 0
B12: Related Party-AP | D12: =SUMIF('BS LTD USD '!B:B,'BS USD CONS '!$B12,'BS LTD USD '!F:F) -> 0 | F12: =SUMIF('BS & P&L INC '!D:D,'BS USD CONS '!$B12,'BS & P&L INC '!H:H) -> 0 | J12: =+F12+D12 -> 0 | L12: =J12/1000 -> 0
B13: Temporary account | D13: =SUMIF('BS LTD USD '!B:B,'BS USD CONS '!$B13,'BS LTD USD '!F:F) -> 0 | F13: =SUMIF('BS & P&L INC '!D:D,'BS USD CONS '!$B13,'BS & P&L INC '!H:H) -> 0 | J13: =+F13+D13 -> 0 | L13: =J13/1000 -> 0
B14: Deposit | D14: =SUMIF('BS LTD USD '!B:B,'BS USD CONS '!$B14,'BS LTD USD '!F:F) -> 16077.17 | F14: =SUMIF('BS & P&L INC '!D:D,'BS USD CONS '!$B14,'BS & P&L INC '!H:H) -> 0 | J14: =+F14+D14 -> 16077.17 | L14: =J14/1000 -> 16.07717
B15: Shareholders' loan | D15: =SUMIF('BS LTD USD '!B:B,'BS USD CONS '!$B15,'BS LTD USD '!F:F) -> 0 | F15: =SUMIF('BS & P&L INC '!D:D,'BS USD CONS '!$B15,'BS & P&L INC '!H:H) -> 0 | J15: =+F15+D15 -> 0 | L15: =J15/1000 -> 0
B16: Prepaid | D16: =SUMIF('BS LTD USD '!B:B,'BS USD CONS '!$B16,'BS LTD USD '!F:F) -> 1034254.4 | F16: =SUMIF('BS & P&L INC '!D:D,'BS USD CONS '!$B16,'BS & P&L INC '!H:H) -> 0 | J16: =+F16+D16 -> 1034254.4 | L16: =J16/1000 -> 1034.2544
B17: Other accounts receivable | D17: =SUMIF('BS LTD USD '!B:B,'BS USD CONS '!$B17,'BS LTD USD '!F:F) -> 1450468.1 | F17: =SUMIF('BS & P&L INC '!D:D,'BS USD CONS '!$B17,'BS & P&L INC '!H:H) -> 0 | J17: =+F17+D17 -> 1450468.1 | L17: =J17/1000 -> 1450.4681
D18: =SUM(D8:D17) -> 48324471 | F18: =SUM(F8:F17) -> 3887831 | H18: =SUM(H8:H17) -> 0 | J18: =+F18+D18 -> 52212302 | L18: =J18/1000 -> 52212.302
B20: NON-CURRENT ASSETS
B22: Investment | D22: =SUMIF('BS LTD USD '!B:B,'BS USD CONS '!$B22,'BS LTD USD '!F:F) -> 297519.04 | F22: =SUMIF('BS & P&L INC '!D:D,'BS USD CONS '!$B22,'BS & P&L INC '!H:H) -> 0 | H22: =-D22 -> -297519.04 | J22: =+F22+D22+H22 -> 0 | L22: =J22/1000 -> 0
B23: ROA Assets | D23: =SUMIF('BS LTD USD '!B:B,'BS USD CONS '!$B23,'BS LTD USD '!F:F) -> 409121.67 | F23: =SUMIF('BS & P&L INC '!D:D,'BS USD CONS '!$B23,'BS & P&L INC '!H:H) -> 0 | J23: =+F23+D23+H23 -> 409121.67 | L23: =J23/1000 -> 409.12167
B24: Deferred tax assets | D24: =SUMIF('BS LTD USD '!B:B,'BS USD CONS '!$B24,'BS LTD USD '!F:F) -> 939408.95 | J24: =+F24+D24+H24 -> 939408.95 | L24: =J24/1000 -> 939.40895
B25: Reserve - Wordpay | D25: =SUMIF('BS LTD USD '!B:B,'BS USD CONS '!$B25,'BS LTD USD '!F:F) -> 0 | F25: =SUMIF('BS & P&L INC '!D:D,'BS USD CONS '!$B25,'BS & P&L INC '!H:H) -> 199999 | J25: =+F25+D25+H25 -> 199999 | L25: =J25/1000 -> 199.999
B26: Fixed assets, net | D26: =SUMIF('BS LTD USD '!B:B,'BS USD CONS '!$B26,'BS LTD USD '!F:F) -> 501895.3 | F26: =SUMIF('BS & P&L INC '!D:D,'BS USD CONS '!$B26,'BS & P&L INC '!H:H) -> 0 | J26: =+F26+D26 -> 501895.3 | L26: =J26/1000 -> 501.8953
D27: =SUM(D22:D26) -> 2147945 | F27: =SUM(F22:F26) -> 199999 | H27: =SUM(H22:H26) -> -297519.04 | J27: =SUM(J22:J26) -> 2050424.9 | L27: =J27/1000 -> 2050.4249
B29: Total Assets | D29: =+D27+D18 -> 50472416 | F29: =+F27+F18 -> 4087830 | H29: =+H27+H18 -> -297519.04 | J29: =J18+J27 -> 54262727 | L29: =J29/1000 -> 54262.727
B32: CURRENT LIABILITIES
B34: Trade payables | D34: =SUMIF('BS LTD USD '!B:B,'BS USD CONS '!$B34,'BS LTD USD '!F:F) -> -10307676 | F34: =SUMIF('BS & P&L INC '!D:D,'BS USD CONS '!$B34,'BS & P&L INC '!H:H) -> -3126158.6 | J34: =+F34+D34 -> -13433835 | L34: =J34/1000 -> -13433.835
B35: Accrued Expenses | D35: =SUMIF('BS LTD USD '!B:B,'BS USD CONS '!$B35,'BS LTD USD '!F:F) -> -10629163 | F35: =SUMIF('BS & P&L INC '!D:D,'BS USD CONS '!$B35,'BS & P&L INC '!H:H) -> -562692.19 | J35: =+F35+D35 -> -11191856 | L35: =J35/1000 -> -11191.856
B36: Loan-Short Term | D36: =SUMIF('BS LTD USD '!B:B,'BS USD CONS '!$B36,'BS LTD USD '!F:F) -> -2033334 | F36: =SUMIF('BS & P&L INC '!D:D,'BS USD CONS '!$B36,'BS & P&L INC '!H:H) -> 0 | J36: =+F36+D36 -> -2033334 | L36: =J36/1000 -> -2033.334
B37: Contract liability | D37: =SUMIF('BS LTD USD '!B:B,'BS USD CONS '!$B37,'BS LTD USD '!F:F) -> -4087657 | F37: =SUMIF('BS & P&L INC '!D:D,'BS USD CONS '!$B37,'BS & P&L INC '!H:H) -> 0 | J37: =+F37+D37 -> -4087657 | L37: =J37/1000 -> -4087.657
B38: Tax provision | D38: =SUMIF('BS LTD USD '!B:B,'BS USD CONS '!$B38,'BS LTD USD '!F:F) -> -1881953.5 | J38: =+F38+D38 -> -1881953.5 | L38: =J38/1000 -> -1881.9535
B39: Related Party-AP | D39: =SUMIF('BS LTD USD '!B:B,'BS USD CONS '!$B39,'BS LTD USD '!F:F) -> 0 | F39: =SUMIF('BS & P&L INC '!D:D,'BS USD CONS '!$B39,'BS & P&L INC '!H:H) -> 0 | J39: =+F39+D39 -> 0 | L39: =J39/1000 -> 0
B40: ROA Liability | D40: =SUMIF('BS LTD USD '!B:B,'BS USD CONS '!$B40,'BS LTD USD '!F:F) -> -385359.69 | F40: =SUMIF('BS & P&L INC '!D:D,'BS USD CONS '!$B40,'BS & P&L INC '!H:H) -> 0 | J40: =+F40+D40 -> -385359.69 | L40: =J40/1000 -> -385.35969
B41: Deferred tax liability | D41: =SUMIF('BS LTD USD '!B:B,'BS USD CONS '!$B41,'BS LTD USD '!F:F) -> 0 | F41: =SUMIF('BS & P&L INC '!D:D,'BS USD CONS '!$B41,'BS & P&L INC '!H:H) -> 0 | J41: =+F41+D41 -> 0 | L41: =J41/1000 -> 0
B42: Other accounts payable | D42: =SUMIF('BS LTD USD '!B:B,'BS USD CONS '!$B42,'BS LTD USD '!F:F) -> -7411932.8 | F42: =SUMIF('BS & P&L INC '!D:D,'BS USD CONS '!$B42,'BS & P&L INC '!H:H) -> -101461.4 | J42: =+F42+D42 -> -7513394.2 | L42: =J42/1000 -> -7513.3942
D43: =SUM(D34:D42) -> -36737077 | F43: =SUM(F32:F42) -> -3790312.2 | H43: =SUM(H32:H42) -> 0 | J43: =+F43+D43 -> -40527389 | L43: =J43/1000 -> -40527.389
J44: =+F44+D44 -> 0
B45: Loan-Long Term | D45: =SUMIF('BS LTD USD '!B:B,'BS USD CONS '!$B45,'BS LTD USD '!F:F) -> -533332.72 | F45: =SUMIF('BS & P&L INC '!D:D,'BS USD CONS '!$B45,'BS & P&L INC '!F:F) -> 0 | J45: =+F45+D45 -> -533332.72 | L45: =J45/1000 -> -533.33272
B46: Shareholders | D46: =SUMIF('BS LTD USD '!B:B,'BS USD CONS '!$B46,'BS LTD USD '!F:F) -> -500000 | F46: =SUMIF('BS & P&L INC '!D:D,'BS USD CONS '!$B46,'BS & P&L INC '!F:F) -> 0 | J46: =+F46+D46 -> -500000 | L46: =J46/1000 -> -500
B47: Convertible Loan | D47: =SUMIF('BS LTD USD '!B:B,'BS USD CONS '!$B47,'BS LTD USD '!F:F) -> 0 | F47: =SUMIF('BS & P&L INC '!D:D,'BS USD CONS '!$B47,'BS & P&L INC '!F:F) -> 0 | J47: =+F47+D47 -> 0 | L47: =J47/1000 -> 0
D48: =SUM(D45:D47) -> -1033332.7 | F48: =SUM(F46:F47) -> 0 | J48: =+F48+D48 -> -1033332.7 | L48: =J48/1000 -> -1033.3327
B50: Total liabilities | D50: =+D48+D43 -> -37770409 | F50: =+F48+F43 -> -3790312.2 | H50: =+H48+H43 -> 0 | J50: =+F50+D50 -> -41560722 | L50: =J50/1000 -> -41560.722
...

Sheet BS LTD USD 
D1: USD -LTD | J1: ILS -LTD
D3: 44561 | F3: 44561 | J3: 44561 | L3: 44561
E4: JE | F4: AJE | K4: JE | L4: AJE
B6: CURRENT ASSETS
B8: Cash | D8: =SUMIF('TB LTD 12.21'!I:I,B8,'TB LTD 12.21'!G:G) -> 12155821 | F8: =D8+E8 -> 12155821 | J8: =SUMIF('TB LTD 12.21'!I:I,B8,'TB LTD 12.21'!F:F) -> 37804603 | L8: =J8+K8 -> 37804603 | N8: =L8/1000 -> 37804.603
B9: Account receivable | D9: =SUMIF('TB LTD 12.21'!I:I,B9,'TB LTD 12.21'!G:G) -> 156494 | E9: ='AJE 2021'!G25 -> 1039517.9 | F9: =D9+E9 -> 1196011.9 | J9: =SUMIF('TB LTD 12.21'!I:I,B9,'TB LTD 12.21'!F:F) -> 486696.34 | K9: ='AJE 2021'!J25 -> 3232900.7 | L9: =J9+K9 -> 3719597 | M9: =K9/E9 -> 3.11 | N9: =L9/1000 -> 3719.597
B10: Related Party | D10: =SUMIF('TB LTD 12.21'!I:I,B10,'TB LTD 12.21'!G:G) -> 33417475 | E10: ='AJE 2021'!G53-'AJE 2021'!H26-'AJE 2021'!G64+'AJE 2021'!G81 -> -945636.64 | F10: =D10+E10 -> 32471839 | J10: =SUMIF('TB LTD 12.21'!I:I,B10,'TB LTD 12.21'!F:F) -> 1.0392835e+08 | K10: ='AJE 2021'!J53-'AJE 2021'!K26-'AJE 2021'!J64+'AJE 2021'!J81 -> -3514747.8 | L10: =J10+K10 -> 1.004136e+08 | M10: =K10/E10 -> 3.7168059 | N10: =L10/1000 -> 100413.6
B11: Deposit | D11: =SUMIF('TB LTD 12.21'!I:I,B11,'TB LTD 12.21'!G:G) -> 16077.17 | F11: =D11+E11 -> 16077.17 | J11: =SUMIF('TB LTD 12.21'!I:I,B11,'TB LTD 12.21'!F:F) -> 50000 | L11: =J11+K11 -> 50000 | N11: =L11/1000 -> 50
B12: Shareholders' loan | D12: =SUMIF('TB LTD 12.21'!I:I,B12,'TB LTD 12.21'!G:G) -> 0 | F12: =D12+E12 -> 0 | J12: =SUMIF('TB LTD 12.21'!I:I,B12,'TB LTD 12.21'!F:F) -> 0 | L12: =J12+K12 -> 0 | N12: =L12/1000 -> 0
B13: Prepaid | D13: =SUMIF('TB LTD 12.21'!I:I,B13,'TB LTD 12.21'!G:G) -> 1076626.7 | E13: =-'AJE 2021'!H75+'AJE 2021'!G31 -> -42372.32 | F13: =D13+E13 -> 1034254.4 | J13: =SUMIF('TB LTD 12.21'!I:I,B13,'TB LTD 12.21'!F:F) -> 3348309.1 | K13: =-'AJE 2021'!K75 -> -186398.21 | L13: =J13+K13 -> 3161910.9 | N13: =L13/1000 -> 3161.9109
B14: Other accounts receivable | D14: =SUMIF('TB LTD 12.21'!I:I,B14,'TB LTD 12.21'!G:G) -> 1438335.1 | E14: ='AJE 2021'!G100 -> 12133 | F14: =D14+E14 -> 1450468.1 | J14: =SUMIF('TB LTD 12.21'!I:I,B14,'TB LTD 12.21'!F:F) -> 4488222 | K14: ='AJE 2021'!J31+'AJE 2021'!J100 -> 97368 | L14: =J14+K14 -> 4585590 | M14: =K14/E14 -> 8.0250556 | N14: =L14/1000 -> 4585.59
D15: =SUM(D8:D14) -> 48260829 | E15: =SUM(E8:E14) -> 63641.946 | F15: =SUM(F8:F14) -> 48324471 | J15: =SUM(J8:J14) -> 1.5010618e+08 | K15: =SUM(K8:K14) -> -370877.34 | L15: =SUM(L8:L14) -> 1.497353e+08 | M15: =K15/E15 -> -5.8275612 | N15: =L15/1000 -> 149735.3
N16: =L16/1000 -> 0
B17: NON-CURRENT ASSETS | N17: =L17/1000 -> 0
N18: =L18/1000 -> 0
B19: Investment | D19: =SUMIF('TB LTD 12.21'!I:I,B19,'TB LTD 12.21'!G:G) -> 391399.71 | E19: =-'AJE 2021'!G59 -> -93880.666 | F19: =D19+E19 -> 297519.04 | J19: =SUMIF('TB LTD 12.21'!I:I,B19,'TB LTD 12.21'!F:F) -> 1231494.2 | K19: =-'AJE 2021'!J59 -> -303168.84 | L19: =J19+K19 -> 928325.41 | M19: =K19/E19 -> 3.2293 | N19: =L19/1000 -> 928.32541
B20: ROA Assets | D20: =SUMIF('TB LTD 12.21'!I:I,B20,'TB LTD 12.21'!G:G) -> 0 | E20: ='AJE 2021'!G72 -> 409121.67 | F20: =D20+E20 -> 409121.67 | K20: ='AJE 2021'!J72 -> 1306529.9 | L20: =J20+K20 -> 1306529.9 | M20: =K20/E20 -> 3.1934996 | N20: =L20/1000 -> 1306.5299
B21: Fixed assets, net | D21: =SUMIF('TB LTD 12.21'!I:I,B21,'TB LTD 12.21'!G:G) -> 501895.3 | F21: =D21+E21 -> 501895.3 | J21: =SUMIF('TB LTD 12.21'!I:I,B21,'TB LTD 12.21'!F:F) -> 1630942.9 | L21: =J21+K21 -> 1630942.9 | N21: =L21/1000 -> 1630.9429
B22: Deferred tax assets | D22: =SUMIF('TB LTD 12.21'!I:I,B22,'TB LTD 12.21'!G:G) -> -1766750.1 | E22: ='AJE 2021'!G85+'AJE 2021'!G94 -> 2706159 | F22: =D22+E22 -> 939408.95 | J22: =SUMIF('TB LTD 12.21'!I:I,B22,'TB LTD 12.21'!F:F) -> -5494592.8 | K22: ='AJE 2021'!J85+'AJE 2021'!J94 -> 8420180.7 | L22: =J22+K22 -> 2925588 | N22: =L22/1000 -> 2925.588
D23: =SUM(D17:D22) -> -873455.07 | E23: =SUM(E17:E22) -> 3021400 | F23: =SUM(F17:F22) -> 2147945 | J23: =SUM(J17:J22) -> -2632155.6 | K23: =SUM(K17:K22) -> 9423541.8 | L23: =SUM(L17:L22) -> 6791386.1 | M23: =K23/E23 -> 3.1189322 | N23: =L23/1000 -> 6791.3861
N24: =L24/1000 -> 0
B25: Total Assets | D25: =+D23+D15 -> 47387374 | E25: =+E23+E15 -> 3085042 | F25: =+F23+F15 -> 50472416 | J25: =+J23+J15 -> 1.4747402e+08 | K25: =+K23+K15 -> 9052664.5 | L25: =+L23+L15 -> 1.5652669e+08 | M25: =K25/E25 -> 2.9343732 | N25: =L25/1000 -> 156526.69
N26: =L26/1000 -> 0
N27: =L27/1000 -> 0
B28: CURRENT LIABILITIES | N28: =L28/1000 -> 0
N29: =L29/1000 -> 0
B30: Trade payables | D30: =SUMIF('TB LTD 12.21'!I:I,B30,'TB LTD 12.21'!G:G) -> -10271695 | E30: =-'AJE 2021'!H42 -> -35980.71 | F30: =D30+E30 -> -10307676 | J30: =SUMIF('TB LTD 12.21'!I:I,B30,'TB LTD 12.21'!F:F) -> -31944972 | K30: =-'AJE 2021'!K42 -> -111900 | L30: =J30+K30 -> -32056872 | M30: =K30/E30 -> 3.1099998 | N30: =L30/1000 -> -32056.872
B31: Accrued Expenses | D31: =SUMIF('TB LTD 12.21'!I:I,B31,'TB LTD 12.21'!G:G) -> -10615443 | E31: =-'AJE 2021'!H36 -> -13720.37 | F31: =D31+E31 -> -10629163 | J31: =SUMIF('TB LTD 12.21'!I:I,B31,'TB LTD 12.21'!F:F) -> -33014028 | K31: =-'AJE 2021'!K36 -> -42670.352 | L31: =J31+K31 -> -33056698 | N31: =L31/1000 -> -33056.698
B32: Loan-Short Term | D32: =SUMIF('TB LTD 12.21'!I:I,B32,'TB LTD 12.21'!G:G) -> -2033334 | F32: =D32+E32 -> -2033334 | J32: =SUMIF('TB LTD 12.21'!I:I,B32,'TB LTD 12.21'!F:F) -> -6323668.7 | L32: =J32+K32 -> -6323668.7 | N32: =L32/1000 -> -6323.6687
B33: Contract liability | D33: =SUMIF('TB LTD 12.21'!I:I,B33,'TB LTD 12.21'!G:G) -> -3862324 | E33: =-'AJE 2021'!H47 -> -225333 | F33: =D33+E33 -> -4087657 | J33: =SUMIF('TB LTD 12.21'!I:I,B33,'TB LTD 12.21'!F:F) -> -12011828 | K33: =-'AJE 2021'!K47 -> -700785.63 | L33: =J33+K33 -> -12712613 | M33: =K33/E33 -> 3.11 | N33: =L33/1000 -> -12712.613
B34: Tax provision | D34: =SUMIF('TB LTD 12.21'!I:I,B34,'TB LTD 12.21'!G:G) -> 0 | E34: =-'AJE 2021'!H86+'AJE 2021'!G89 -> -1881953.5 | F34: =D34+E34 -> -1881953.5 | J34: =SUMIF('TB LTD 12.21'!I:I,B34,'TB LTD 12.21'!F:F) -> 0 | K34: =-'AJE 2021'!K86+'AJE 2021'!J89 -> -5900052 | L34: =J34+K34 -> -5900052 | N34: =L34/1000 -> -5900.052
B35: ROA Liability | D35: =SUMIF('TB LTD 12.21'!I:I,B35,'TB LTD 12.21'!G:G) -> 0 | E35: =-'AJE 2021'!H73 -> -385359.69 | F35: =D35+E35 -> -385359.69 | K35: =-'AJE 2021'!K73 -> -1196813.8 | L35: =J35+K35 -> -1196813.8 | M35: =K35/E35 -> 3.1057058 | N35: =L35/1000 -> -1196.8138
B36: Other accounts payable | D36: =SUMIF('TB LTD 12.21'!I:I,B36,'TB LTD 12.21'!G:G) -> -911211.56 | E36: =-'AJE 2021'!H80-'AJE 2021'!H105 -> -6500721.2 | F36: =D36+E36 -> -7411932.8 | J36: =SUMIF('TB LTD 12.21'!I:I,B36,'TB LTD 12.21'!F:F) -> -2833802.6 | K36: =-'AJE 2021'!K80-'AJE 2021'!K105 -> -20217243 | L36: =J36+K36 -> -23051046 | M36: =K36/E36 -> 3.11 | N36: =L36/1000 -> -23051.046
N37: =L37/1000 -> 0
D38: =SUM(D30:D37) -> -27694008 | E38: =SUM(E30:E37) -> -9043068.5 | F38: =SUM(F30:F37) -> -36737077 | J38: =SUM(J30:J37) -> -86128299 | K38: =SUM(K30:K37) -> -28169465 | L38: =SUM(L30:L37) -> -1.1429776e+08 | N38: =L38/1000 -> -114297.76
N39: =L39/1000 -> 0
B40: Loan-Long Term | D40: =SUMIF('TB LTD 12.21'!I:I,B40,'TB LTD 12.21'!G:G) -> -533332.72 | F40: =D40+E40 -> -533332.72 | J40: =SUMIF('TB LTD 12.21'!I:I,B40,'TB LTD 12.21'!F:F) -> -1658672 | L40: =J40+K40 -> -1658672 | N40: =L40/1000 -> -1658.672
B41: Shareholders | D41: =SUMIF('TB LTD 12.21'!I:I,B41,'TB LTD 12.21'!G:G) -> -500000 | F41: =D41+E41 -> -500000 | J41: =SUMIF('TB LTD 12.21'!I:I,B41,'TB LTD 12.21'!F:F) -> -1722778.6 | L41: =J41+K41 -> -1722778.6 | N41: =L41/1000 -> -1722.7786
B42: Convertible Loan | D42: =SUMIF('TB LTD 12.21'!I:I,B42,'TB LTD 12.21'!G:G) -> 0 | J42: =SUMIF('TB LTD 12.21'!I:I,B42,'TB LTD 12.21'!F:F) -> 0 | N42: =L42/1000 -> 0
D43: =SUM(D40:D42) -> -1033332.7 | E43: =SUM(E40:E42) -> 0 | F43: =SUM(F40:F42) -> -1033332.7 | J43: =SUM(J40:J42) -> -3381450.5 | K43: =SUM(K40:K42) -> 0 | L43: =SUM(L40:L42) -> -3381450.5 | N43: =L43/1000 -> -3381.4506
...

Sheet P&L LTD  USD
D1: USD -LTD | J1: ILS -LTD
D3: 44561 | F3: 44561 | J3: 44561 | L3: 44561
E4: JE | F4: AJE | J4: LTD | K4: JE | L4: AJE
B5: Revenues | C5: Revenues | D5: =SUMIFS('TB LTD 12.21'!G:G,'TB LTD 12.21'!I:I,$B5,'TB LTD 12.21'!J:J,$C5) -> -1.7342077e+08 | E5: ='AJE 2021'!G64 -> 5389318.2 | F5: =D5+E5 -> -1.6803145e+08 | J5: =SUMIFS('TB LTD 12.21'!F:F,'TB LTD 12.21'!I:I,$B5,'TB LTD 12.21'!J:J,$C5) -> -5.5200045e+08 | K5: ='AJE 2021'!J64 -> 17403725 | L5: =J5+K5 -> -5.3459672e+08
B6: Revenues | C6: ads revenue | D6: =SUMIFS('TB LTD 12.21'!G:G,'TB LTD 12.21'!I:I,$B6,'TB LTD 12.21'!J:J,$C6) -> -1552581.5 | F6: =D6+E6 -> -1552581.5 | J6: =SUMIFS('TB LTD 12.21'!F:F,'TB LTD 12.21'!I:I,$B6,'TB LTD 12.21'!J:J,$C6) -> -5007210.9 | L6: =J6+K6 -> -5007210.9
B7: Revenues | C7: Net Cash | D7: =SUMIFS('TB LTD 12.21'!G:G,'TB LTD 12.21'!I:I,$B7,'TB LTD 12.21'!J:J,$C7) -> 3260399 | E7: ='AJE 2021'!G48 -> 225333 | F7: =D7+E7 -> 3485732 | J7: =SUMIFS('TB LTD 12.21'!F:F,'TB LTD 12.21'!I:I,$B7,'TB LTD 12.21'!J:J,$C7) -> 10470022 | K7: ='AJE 2021'!J48 -> 700785.63 | L7: =J7+K7 -> 11170808
B8: Revenues | C8: withdrawals | D8: =SUMIFS('TB LTD 12.21'!G:G,'TB LTD 12.21'!I:I,$B8,'TB LTD 12.21'!J:J,$C8) -> 3028063.4 | F8: =D8+E8 -> 3028063.4 | J8: =SUMIFS('TB LTD 12.21'!F:F,'TB LTD 12.21'!I:I,$B8,'TB LTD 12.21'!J:J,$C8) -> 9740065.6 | L8: =J8+K8 -> 9740065.6
B9: Revenues | C9: Total Revenues | D9: =SUM(D5:D8) -> -1.6868489e+08 | E9: =SUM(E5:E8) -> 5614651.2 | F9: =SUM(F5:F8) -> -1.6307024e+08 | J9: =SUM(J5:J8) -> -5.3679757e+08 | K9: =SUM(K5:K8) -> 18104511 | L9: =SUM(L5:L8) -> -5.1869306e+08
B11: Cost of revenues | C11: Cost of revenues | D11: =SUM(D12:D21) -> 13306626 | E11: =SUM(E12:E21) -> -553163.28 | F11: =SUM(F12:F21) -> 12753463 | J11: =SUM(J12:J21) -> 42709721 | K11: =SUM(K12:K21) -> -1786330.2 | L11: =SUM(L12:L21) -> 40923391
A12: Overheads | B12: Cost of revenues | C12: professional fees | D12: =SUMIFS('TB LTD 12.21'!G:G,'TB LTD 12.21'!I:I,$B12,'TB LTD 12.21'!J:J,$C12) -> 107488.35 | F12: =D12+E12 -> 107488.35 | J12: =SUMIFS('TB LTD 12.21'!F:F,'TB LTD 12.21'!I:I,$B12,'TB LTD 12.21'!J:J,$C12) -> 348109.55 | L12: =J12+K12 -> 348109.55
A13: Payroll | B13: Cost of revenues | C13: Salary | D13: =SUMIFS('TB LTD 12.21'!G:G,'TB LTD 12.21'!I:I,$B13,'TB LTD 12.21'!J:J,$C13) -> 698868.45 | F13: =D13+E13 -> 698868.45 | J13: =SUMIFS('TB LTD 12.21'!F:F,'TB LTD 12.21'!I:I,$B13,'TB LTD 12.21'!J:J,$C13) -> 2241056.4 | L13: =J13+K13 -> 2241056.4
A14: Overheads | B14: Cost of revenues | C14: Softwere subscription | D14: =SUMIFS('TB LTD 12.21'!G:G,'TB LTD 12.21'!I:I,$B14,'TB LTD 12.21'!J:J,$C14) -> 35022.79 | F14: =D14+E14 -> 35022.79 | J14: =SUMIFS('TB LTD 12.21'!F:F,'TB LTD 12.21'!I:I,$B14,'TB LTD 12.21'!J:J,$C14) -> 113025.94 | L14: =J14+K14 -> 113025.94
A15: Overheads | B15: Cost of revenues | C15: Hosting and Servers | D15: =SUMIFS('TB LTD 12.21'!G:G,'TB LTD 12.21'!I:I,$B15,'TB LTD 12.21'!J:J,$C15) -> 938775.14 | F15: =D15+E15 -> 938775.14 | J15: =SUMIFS('TB LTD 12.21'!F:F,'TB LTD 12.21'!I:I,$B15,'TB LTD 12.21'!J:J,$C15) -> 3105388.1 | L15: =J15+K15 -> 3105388.1
A16: Overheads | B16: Cost of revenues | C16: Fee | D16: =SUMIFS('TB LTD 12.21'!G:G,'TB LTD 12.21'!I:I,$B16,'TB LTD 12.21'!J:J,$C16) -> 0 | F16: =D16+E16 -> 0 | J16: =SUMIFS('TB LTD 12.21'!F:F,'TB LTD 12.21'!I:I,$B16,'TB LTD 12.21'!J:J,$C16) -> 0 | L16: =J16+K16 -> 0
B17: Cost of revenues | C17: withdrawals | D17: =SUMIFS('TB LTD 12.21'!G:G,'TB LTD 12.21'!I:I,$B17,'TB LTD 12.21'!J:J,$C17) -> 0 | F17: =D17+E17 -> 0 | J17: =SUMIFS('TB LTD 12.21'!F:F,'TB LTD 12.21'!I:I,$B17,'TB LTD 12.21'!J:J,$C17) -> 0 | L17: =J17+K17 -> 0
A18: Options | B18: Cost of revenues | C18: option expenses | D18: =SUMIFS('TB LTD 12.21'!G:G,'TB LTD 12.21'!I:I,$B18,'TB LTD 12.21'!J:J,$C18) -> 21364 | E18: ='AJE 2021'!G18 -> -6811.1171 | F18: =D18+E18 -> 14552.883 | J18: =SUMIFS('TB LTD 12.21'!F:F,'TB LTD 12.21'!I:I,$B18,'TB LTD 12.21'!J:J,$C18) -> 68611.74 | K18: ='AJE 2021'!J18 -> -21995.14 | L18: =J18+K18 -> 46616.6
A19: Overheads | B19: Cost of revenues | C19: Allocation exp | D19: =SUMIFS('TB LTD 12.21'!G:G,'TB LTD 12.21'!I:I,$B19,'TB LTD 12.21'!J:J,$C19) -> 220446 | F19: =D19+E19 -> 220446 | J19: =SUMIFS('TB LTD 12.21'!F:F,'TB LTD 12.21'!I:I,$B19,'TB LTD 12.21'!J:J,$C19) -> 692152.93 | L19: =J19+K19 -> 692152.93
B20: Cost of revenues | C20: IC expenses | D20: =SUMIFS('TB LTD 12.21'!G:G,'TB LTD 12.21'!I:I,$B20,'TB LTD 12.21'!J:J,$C20) -> 11270061 | E20: =-'AJE 2021'!H54 -> -546352.16 | F20: =D20+E20 -> 10723709 | J20: =SUMIFS('TB LTD 12.21'!F:F,'TB LTD 12.21'!I:I,$B20,'TB LTD 12.21'!J:J,$C20) -> 36093860 | K20: =-'AJE 2021'!K54 -> -1764335 | L20: =J20+K20 -> 34329525
A21: Overheads | B21: Cost of revenues | C21: recruitment | D21: =SUMIFS('TB LTD 12.21'!G:G,'TB LTD 12.21'!I:I,$B21,'TB LTD 12.21'!J:J,$C21) -> 14600 | F21: =D21+E21 -> 14600 | J21: =SUMIFS('TB LTD 12.21'!F:F,'TB LTD 12.21'!I:I,$B21,'TB LTD 12.21'!J:J,$C21) -> 47516.2 | L21: =J21+K21 -> 47516.2
C22: Gross loss (profit) | D22: =D9+D11 -> -1.5537827e+08 | E22: =E9+E11 -> 5061487.9 | F22: =F9+F11 -> -1.5031678e+08 | J22: =J9+J11 -> -4.9408785e+08 | K22: =K9+K11 -> 16318181 | L22: =L9+L11 -> -4.7776967e+08
B25: Research and development expenses, net | C25: Research and development expenses, net | D25: =SUM(D26:D35) -> 10570627 | E25: =SUM(E26:E35) -> 539214 | F25: =SUM(F26:F35) -> 11109841 | J25: =SUM(J26:J35) -> 33751918 | K25: =SUM(K26:K35) -> 1741283.8 | L25: =SUM(L26:L35) -> 35493202
A26: Overheads | B26: Research and development expenses, net | C26: professional fees | D26: =SUMIFS('TB LTD 12.21'!G:G,'TB LTD 12.21'!I:I,$B26,'TB LTD 12.21'!J:J,$C26) -> 325465.62 | F26: =D26+E26 -> 325465.62 | J26: =SUMIFS('TB LTD 12.21'!F:F,'TB LTD 12.21'!I:I,$B26,'TB LTD 12.21'!J:J,$C26) -> 1179403.1 | L26: =J26+K26 -> 1179403.1
A27: Payroll | B27: Research and development expenses, net | C27: Salary | D27: =SUMIFS('TB LTD 12.21'!G:G,'TB LTD 12.21'!I:I,$B27,'TB LTD 12.21'!J:J,$C27) -> 7099737.9 | F27: =D27+E27 -> 7099737.9 | J27: =SUMIFS('TB LTD 12.21'!F:F,'TB LTD 12.21'!I:I,$B27,'TB LTD 12.21'!J:J,$C27) -> 22611084 | L27: =J27+K27 -> 22611084
A28: Overheads | B28: Research and development expenses, net | C28: Softwere subscription | D28: =SUMIFS('TB LTD 12.21'!G:G,'TB LTD 12.21'!I:I,$B28,'TB LTD 12.21'!J:J,$C28) -> 1018247.6 | F28: =D28+E28 -> 1018247.6 | J28: =SUMIFS('TB LTD 12.21'!F:F,'TB LTD 12.21'!I:I,$B28,'TB LTD 12.21'!J:J,$C28) -> 3294839.1 | L28: =J28+K28 -> 3294839.1
A29: Overheads | B29: Research and development expenses, net | C29: Hosting and Servers | D29: =SUMIFS('TB LTD 12.21'!G:G,'TB LTD 12.21'!I:I,$B29,'TB LTD 12.21'!J:J,$C29) -> 683881.4 | F29: =D29+E29 -> 683881.4 | J29: =SUMIFS('TB LTD 12.21'!F:F,'TB LTD 12.21'!I:I,$B29,'TB LTD 12.21'!J:J,$C29) -> 2126871.1 | L29: =J29+K29 -> 2126871.1
A30: Options | B30: Research and development expenses, net | C30: option expenses | D30: =SUMIFS('TB LTD 12.21'!G:G,'TB LTD 12.21'!I:I,$B30,'TB LTD 12.21'!J:J,$C30) -> 474606 | E30: ='AJE 2021'!G19 -> 539214 | F30: =D30+E30 -> 1013820 | J30: =SUMIFS('TB LTD 12.21'!F:F,'TB LTD 12.21'!I:I,$B30,'TB LTD 12.21'!J:J,$C30) -> 1523877.4 | K30: ='AJE 2021'!J19 -> 1741283.8 | L30: =J30+K30 -> 3265161.2
A31: Overheads | B31: Research and development expenses, net | C31: communication | D31: =SUMIFS('TB LTD 12.21'!G:G,'TB LTD 12.21'!I:I,$B31,'TB LTD 12.21'!J:J,$C31) -> 0 | F31: =D31+E31 -> 0 | J31: =SUMIFS('TB LTD 12.21'!F:F,'TB LTD 12.21'!I:I,$B31,'TB LTD 12.21'!J:J,$C31) -> 0 | L31: =J31+K31 -> 0
A32: Overheads | B32: Research and development expenses, net | C32: Allocation exp | D32: =SUMIFS('TB LTD 12.21'!G:G,'TB LTD 12.21'!I:I,$B32,'TB LTD 12.21'!J:J,$C32) -> 840030 | F32: =D32+E32 -> 840030 | J32: =SUMIFS('TB LTD 12.21'!F:F,'TB LTD 12.21'!I:I,$B32,'TB LTD 12.21'!J:J,$C32) -> 2604306.4 | L32: =J32+K32 -> 2604306.4
A33: Overheads | B33: Research and development expenses, net | C33: recruitment | D33: =SUMIFS('TB LTD 12.21'!G:G,'TB LTD 12.21'!I:I,$B33,'TB LTD 12.21'!J:J,$C33) -> 124269.3 | F33: =D33+E33 -> 124269.3 | J33: =SUMIFS('TB LTD 12.21'!F:F,'TB LTD 12.21'!I:I,$B33,'TB LTD 12.21'!J:J,$C33) -> 397758.91 | L33: =J33+K33 -> 397758.91
A34: Overheads | B34: Research and development expenses, net | C34: Travel Parking and transportation | D34: =SUMIFS('TB LTD 12.21'!G:G,'TB LTD 12.21'!I:I,$B34,'TB LTD 12.21'!J:J,$C34) -> 4388.97 | F34: =D34+E34 -> 4388.97 | J34: =SUMIFS('TB LTD 12.21'!F:F,'TB LTD 12.21'!I:I,$B34,'TB LTD 12.21'!J:J,$C34) -> 13778.18 | L34: =J34+K34 -> 13778.18
B35: Research and development expenses, net | C35: IC expenses | D35: =SUMIFS('TB LTD 12.21'!G:G,'TB LTD 12.21'!I:I,$B35,'TB LTD 12.21'!J:J,$C35) -> 0 | F35: =D35+E35 -> 0 | J35: =SUMIFS('TB LTD 12.21'!F:F,'TB LTD 12.21'!I:I,$B35,'TB LTD 12.21'!J:J,$C35) -> 0 | L35: =J35+K35 -> 0
C37: Marketing expenses | D37: =SUM(D38:D47) -> 1.2430914e+08 | E37: =SUM(E38:E47) -> -22807.61 | F37: =SUM(F38:F47) -> 1.2428633e+08 | J37: =SUM(J38:J47) -> 3.9774217e+08 | K37: =SUM(K38:K47) -> -73652.616 | L37: =SUM(L38:L47) -> 3.9766852e+08
A38: Payroll | B38: Marketing expenses | C38: Salary | D38: =SUMIFS('TB LTD 12.21'!G:G,'TB LTD 12.21'!I:I,$B38,'TB LTD 12.21'!J:J,$C38) -> 993651.78 | F38: =D38+E38 -> 993651.78 | J38: =SUMIFS('TB LTD 12.21'!F:F,'TB LTD 12.21'!I:I,$B38,'TB LTD 12.21'!J:J,$C38) -> 3186571.4 | L38: =J38+K38 -> 3186571.4
A39: Ua | B39: Marketing expenses | C39: User Acquisition | D39: =SUMIFS('TB LTD 12.21'!G:G,'TB LTD 12.21'!I:I,$B39,'TB LTD 12.21'!J:J,$C39) -> 1.0587177e+08 | F39: =D39+E39 -> 1.0587177e+08 | J39: =SUMIFS('TB LTD 12.21'!F:F,'TB LTD 12.21'!I:I,$B39,'TB LTD 12.21'!J:J,$C39) -> 3.3866468e+08 | L39: =J39+K39 -> 3.3866468e+08
A40: Ua Indirect | B40: Marketing expenses | C40: Softwere subscription | D40: =SUMIFS('TB LTD 12.21'!G:G,'TB LTD 12.21'!I:I,$B40,'TB LTD 12.21'!J:J,$C40) -> 419274.89 | F40: =D40+E40 -> 419274.89 | J40: =SUMIFS('TB LTD 12.21'!F:F,'TB LTD 12.21'!I:I,$B40,'TB LTD 12.21'!J:J,$C40) -> 1357908.9 | L40: =J40+K40 -> 1357908.9
A41: Options | B41: Marketing expenses | C41: option expenses | D41: =SUMIFS('TB LTD 12.21'!G:G,'TB LTD 12.21'!I:I,$B41,'TB LTD 12.21'!J:J,$C41) -> 27657 | E41: ='AJE 2021'!G20 -> -22807.61 | F41: =D41+E41 -> 4849.3898 | J41: =SUMIFS('TB LTD 12.21'!F:F,'TB LTD 12.21'!I:I,$B41,'TB LTD 12.21'!J:J,$C41) -> 88061.77 | K41: ='AJE 2021'!J20 -> -73652.616 | L41: =J41+K41 -> 14409.154
A42: Ua Indirect | B42: Marketing expenses | C42: PR | D42: =SUMIFS('TB LTD 12.21'!G:G,'TB LTD 12.21'!I:I,$B42,'TB LTD 12.21'!J:J,$C42) -> 533167.79 | F42: =D42+E42 -> 533167.79 | J42: =SUMIFS('TB LTD 12.21'!F:F,'TB LTD 12.21'!I:I,$B42,'TB LTD 12.21'!J:J,$C42) -> 1708666.7 | L42: =J42+K42 -> 1708666.7
A43: Ua Indirect | B43: Marketing expenses | C43: Gift to Users | D43: =SUMIFS('TB LTD 12.21'!G:G,'TB LTD 12.21'!I:I,$B43,'TB LTD 12.21'!J:J,$C43) -> 65345.8 | F43: =D43+E43 -> 65345.8 | J43: =SUMIFS('TB LTD 12.21'!F:F,'TB LTD 12.21'!I:I,$B43,'TB LTD 12.21'!J:J,$C43) -> 201944.48 | L43: =J43+K43 -> 201944.48
A44: Overheads | B44: Marketing expenses | C44: Allocation exp | D44: =SUMIFS('TB LTD 12.21'!G:G,'TB LTD 12.21'!I:I,$B44,'TB LTD 12.21'!J:J,$C44) -> 143693 | F44: =D44+E44 -> 143693 | J44: =SUMIFS('TB LTD 12.21'!F:F,'TB LTD 12.21'!I:I,$B44,'TB LTD 12.21'!J:J,$C44) -> 427219.73 | L44: =J44+K44 -> 427219.73
A45: Ua Indirect | B45: Marketing expenses | C45: Copywriting expenses | D45: =SUMIFS('TB LTD 12.21'!G:G,'TB LTD 12.21'!I:I,$B45,'TB LTD 12.21'!J:J,$C45) -> 79348.76 | F45: =D45+E45 -> 79348.76 | J45: =SUMIFS('TB LTD 12.21'!F:F,'TB LTD 12.21'!I:I,$B45,'TB LTD 12.21'!J:J,$C45) -> 254800 | L45: =J45+K45 -> 254800
...

Sheet BS & P&L INC 
E1: Papaya Gaming Inc
E2: Balance Sheet
F3: 44561 | G3: JE | H3: 44561
E5: Assets
E6: Current Assets
D7: Cash | E7: Paypal US | F7: 205675.8 | H7: =F7+G7 -> 205675.8
D8: Cash | E8: SVB - 80025 | F8: =36153995.34 -> 36153995 | H8: =F8+G8 -> 36153995 | I8: 7300 | J8: 19907
D9: Related Party | E9: Accounts Receivable (A/R) | F9: 29975832 | G9: ='AJE 2021'!W17+'AJE 2021'!V31-'AJE 2021'!W36-'AJE 2021'!V27 -> 945637.24 | H9: =F9+G9 -> 30921470
D10: Account receivable | E10: Other Accounts Receivable | F10: 1039517.9 | G10: =-'AJE 2021'!V16 -> -1039517.9 | H10: =F10+G10 -> 0
D11: Reserve - Wordpay | E11: Reserve - Wordpay | F11: =199999 -> 199999 | H11: =F11+G11 -> 199999
E12: Total Assets | F12: =SUM(F7:F11) -> 67575020 | H12: =SUM(H7:H11) -> 67481140
E13: Liabilities and shareholder's equity
E14: Current liabilities:
E15: Accounts payable
D16: Trade payables | E16: Accounts Payable (A/P) | F16: 0 | H16: 0
D17: Trade payables | E17: Accounts Payable (A/P) | F17: -2510837 | H17: =F17+G17 -> -2510837
E18: Total Accounts payable | F18: =F17+F15+F16 -> -2510837 | H18: =H17+H15+H16 -> -2510837
D19: Trade payables | E19: SVB - MasterCard | F19: =-615321.52 -> -615321.52 | H19: =F19+G19 -> -615321.52
D20: Accrued Expenses | E20: Accrued liabilities | F20: -562692.19 | H20: =F20+G20 -> -562692.19
D21: Related Party | E21: Due to/from Papaya LTD | F21: 1.2365046e+08 | H21: =F21+G21 -> 1.2365046e+08
D22: Other accounts payable | E22: Sales tax Provision | G22: =-'AJE 2021'!V23+'AJE 2021'!V27 -> 0 | H22: =F22+G22 -> 0
D23: Other accounts payable | E23: Income tax payable | F23: -101461.4 | H23: =F23+G23 -> -101461.4 | I23: 7300
D24: Related Party | E24: Other Accounts payable | F24: -1.8704377e+08 | H24: =F24+G24 -> -1.8704377e+08
E25: Total current liabilities | F25: =(((F18)+(F20))+(F21))+(F23)+F24+F19+F22 -> -67183622 | H25: =(((H18)+(H20))+(H21))+(H23)+H24+H19+H22 -> -67183622
E26: Shareholders' equity:
D27: PL | E27: Net Income | F27: -352025.71 | H27: =-H82 -> -258145.04
D28: Accumulated deficit | E28: Retained Earnings | F28: =-39372.79 -> -39372.79 | H28: =F28+G28 -> -39372.79
E29: Total shareholders' equity | F29: =(F27)+(F28) -> -391398.5 | H29: =(H27)+(H28) -> -297517.83
E30: Total liabilities and equity | F30: =(F25)+(F29) -> -67575020 | H30: =(H25)+(H29) -> -67481140
F31: =F30+F12 -> 0 | H31: =H30+H12 -> 0
C35: Profit and Loss
F37: Total | H37: Total
E38: Income
E39: IC Revenues | F39: =27496341.36 -> 27496341 | G39: =-'AJE 2021'!V35 -> -579444.48 | H39: =F39+G39 -> 26916897
E40: Revenue - Cyber Source | F40: 88038642 | G40: =-'AJE 2021'!V86 -> -328087 | H40: =F40+G40 -> 87710555
E41: Revenue - PayPal | F41: 53900734 | G41: =-'AJE 2021'!V87 -> -34927 | H41: =F41+G41 -> 53865807
E42: Revenue - Paypal US | F42: 219465.75 | G42: =-'AJE 2021'!V11 -> -1253.84 | H42: =F42+G42 -> 218211.91
E43: Revenue - T1 | F43: 406507.57 | H43: =F43+G43 -> 406507.57
E44: Revenue - Wordpay | F44: 30730303 | G44: =-'AJE 2021'!V12 -> -121298 | H44: =F44+G44 -> 30609005
E45: Revenue - Sales Tax | F45: 0 | G45: =-'AJE 2021'!W24 -> -4903754.4 | H45: =F45+G45 -> -4903754.4
...

Sheet Tech Plant Check
C1: 2018 | D1: 2019 | E1: 2020 | G1: 2021
B2: Opening Balance | D2: =+C5 -> 299492.06 | E2: =+D5 -> 1188415 | G2: =+E5 -> 2792020
B3: Expected Loss (Revenue) | E3: =2173604.92192246-570000 -> 1603604.9 | G3: =-4850953*4 -> -19403812
B4: Carryforward losses | C4: =1076644/3.5949 -> 299492.06 | D4: =3168566/3.5645 -> 888922.99
B5: Ending Balance | C5: =+SUM(C2:C4) -> 299492.06 | D5: =+SUM(D2:D4) -> 1188415 | E5: =+SUM(E2:E4) -> 2792020 | G5: =+SUM(G2:G4) -> -16611792
B10: Requirements
B12: R&D Expenses test (7%/75M NIS) | C12: 2018 | D12: 2019 | E12: 2020 | F12: 2021
B13: Revenues | C13: 0 | D13: 866635 | E13: 15116394 | F13: =-'P&L USD CONS'!I7*1000 -> 1.6307024e+08 | K13: missing
B14: R&D Expenses | C14: 201051 | D14: 692900 | E14: 2297223 | F14: ='P&L USD CONS'!I13*1000 -> 11109841 | J14: =I13*0.07 -> 0 | K14: =J14-I14 -> 0
B15: R&D Expenses\Revenues Ratio | D15: =+D14/D13 -> 0.79952921 | E15: =+E14/E13 -> 0.15196898 | F15: =+F14/F13 -> 0.068129174
B16: R&D Expenses\Revenues Ratio - 3Y AVG | E16: =+AVERAGE(C14:E14)/AVERAGE(C13:E13) -> 0.19966015 | F16: =+AVERAGE(D14:F14)/AVERAGE(D13:F13) -> 0.078747313 | K16: =J14/I13 -> #DIV/0!
B17: Missing R&D Expenses to reach the ratio | F17: =AVERAGE(D13:F13)*0.07 -> 4177909.6
B18: R&D Expenses Non GAAP | F18: =AVERAGE(D14:F14) -> 4699987.9 | J18: =+G18/0.04 -> 0 | K18: Break even point | L18: Net Income in 2022
F19: =F17-F18 -> -522078.31 | G19: =F19*3 -> -1566234.9 | H19: missing exp | K19: Above this point Its better to Increase our R&D Spend to reach the ratio
B21: Investment from VC in USD | C21: 500000 | E21: 5748600
B22: AVERAGE NIS/USD Exchange rate | C22: 3.5949 | D22: 3.5645 | E22: 3.4424 | G22: 3.2549
B23: Investment - 8M NIS investment from VC | C23: =+C21*C22 -> 1797450 | E23: =+E21*E22 -> 19788981
K24: 993 | L24: ספטמבר R&D
B25: 25% Increase in AVG revenues Yearly | C25: 0 | D25: 0 | E25: =+E13/D13-1 -> 16.44263 | K25: -181 | L25: founder Bonus
K26: =-(150+86)/3.25 -> -72.615385 | L26: Emp Bonus
B27: 25% Increase in AVG number of employees + at least 50 employees
B28: Number of employees | C28: 3 | D28: 13 | E28: 33 | G28: 67 | H28: 13 | I28: =G28+H28 -> 80 | K28: =K24+K25+K26 -> 739.38462
B29: HC Increase ratio | C29: 0 | D29: =+D28/C28-1 -> 3.3333333 | E29: =+E28/D28-1 -> 1.5384615 | G29: =+G28/E28-1 -> 1.030303 | I29: =G29+H29 -> 1.030303
I30: =G30+H30 -> 0 | L30: רועי
B31: 20% of the Company's employees expenses listed as R&D or At least 200 Employees | I31: =G31+H31 -> 0 | K31: 3461 | L31: יולי V2
B32: R&D Payroll | C32: =(330825+326191)/C22 -> 182763.36 | D32: =449059+791642/$D$22 -> 671149.62 | E32: 1527152 | G32: 5994309 | I32: =G32+H32 -> 5994309
B33: R&D HC | C33: 2 | D33: 9 | E33: 23 | G33: 40 | H33: 6 | I33: =G33+H33 -> 46 | K33: =651*5 -> 3255 | L33: הערכה
B34: Total Payroll | C34: =+(142534+73203)+C32 -> 398500.36 | D34: =958816+791642/$D$22+358000/$D$22 -> 1281341.5 | E34: 2005609 | G34: 9020947 | I34: =G34+H34 -> 9020947
B35: Total HC | C35: =+C28 -> 3 | D35: =+D28 -> 13 | E35: =+E28 -> 33 | G35: =+G28 -> 67 | H35: 13 | I35: =G35+H35 -> 80
B36: R&D Payroll expenses ratio | C36: =+C32/C34 -> 0.45862784 | D36: =+D32/D34 -> 0.5237867 | E36: =+E32/E34 -> 0.76144054 | G36: =+G32/G34 -> 0.66448778 | I36: =G36+H36 -> 0.66448778
B37: R&D HC ratio | C37: =+C33/C35 -> 0.66666667 | D37: =+D33/D35 -> 0.69230769 | E37: =+E33/E35 -> 0.6969697 | G37: =+G33/G35 -> 0.59701493 | H37: =+H33/H35 -> 0.46153846 | I37: =G37+H37 -> 1.0585534 | K37: =K31+K33 -> 6716 | L37: סה״כ RD
B39: מפעל מועדף - תנאים | C39: 0.16
B40: מפעל תעשייתי - בית תכנה נחשב מפעל תעשייתי
B41: מפעל בר תחרות - רוב ההכנסות נובעות מייצוא
C44: 3.597 | D44: 3.5643 | E44: 3.4367 | G44: 3.5882
B45: R&D Expenses test (7%/75M NIS) | C45: 2018 | D45: 2019 | E45: 2020 | G45: 2021 - ytd 9.21 | H45: Oct-Dec 2021 estimeted | I45: Total 2021
B46: Revenues | D46: =D13*D44 -> 3088947.1 | E46: =E13*3.4367 -> 51950511 | G46: =G13*3.4367 -> 0 | H46: =17500000*3*G44 -> 188380500 | I46: =G46+H46 -> 188380500
B47: R&D Expenses | C47: =C14*C44 -> 723180.45 | D47: =D14*D44 -> 2469703.5 | E47: =E14*E44 -> 7894866.3 | G47: =G14*G44 -> 0 | H47: =(993000-200000)*3*G44 -> 8536327.8 | I47: =G47+H47 -> 8536327.8
B48: R&D Expenses\Revenues Ratio | D48: =+D47/D46 -> 0.79952921 | E48: =+E47/E46 -> 0.15196898 | G48: =+G47/G46 -> #DIV/0! | H48: =+H47/H46 -> 0.045314286 | I48: =+I47/I46 -> 0.045314286
B49: R&D Expenses\Revenues Ratio - 3Y AVG | E49: =+AVERAGE(C47:E47)/AVERAGE(C46:E46) -> 0.13430062 | G49: =+AVERAGE(D47:G47)/AVERAGE(D46:G46) -> 0.18831162 | H49: =+AVERAGE(E47:H47)/AVERAGE(E46:H46) -> 0.068369013 | I49: =+AVERAGE(G47:I47)/AVERAGE(G46:I46) -> 0.045314286
...

Sheet R&D 20A
C1: 3 | D1: =+C1+1 -> 4 | E1: =+D1+1 -> 5 | F1: =+E1+1 -> 6 | G1: =+F1+1 -> 7 | H1: =+G1+1 -> 8 | I1: =+H1+1 -> 9
A3: Research and development expenses, net | D3: פריסת הוצאות מו"פ
B4: 2017 | C4: 2018 | D4: 2019 | E4: 2020 | F4: 2021 | G4: 2022 | H4: 2023 | I4: סך הוצאה
A5: 2017 | B5: =I5/3 -> 53630.333 | C5: =B5 -> 53630.333 | D5: =C5 -> 53630.333 | I5: 160891
A6: 2018 | C6: =I6/3 -> 241060.77 | D6: =C6 -> 241060.77 | E6: =D6 -> 241060.77 | I6: 723182.3
A7: 2019 | D7: =+$I$7/3 -> 813428.31 | E7: =+$I$7/3 -> 813428.31 | F7: =+$I$7/3 -> 813428.31 | I7: 2440284.9
A8: 2020 | E8: =+$I$8/3 -> 2085326.3 | F8: =+$I$8/3 -> 2085326.3 | G8: =+$I$8/3 -> 2085326.3 | I8: 6255979
