Workbook
Name _Hlk8837652: 'Payroll analytics'!$C$75
Name Account_num: 'Trial balance'!$B$4:$B$1762
Name balance_bbs_01: [1]BBS!$J$12:$J$70
Name balance_bbs_01: BBS!$J$12:$J$69
Name balance_bbs_02: [1]BBS!$K$12:$K$70
Name balance_bbs_02: BBS!$K$12:$K$69
Name balance_bbs_03: [1]BBS!$L$12:$L$70
Name balance_bbs_03: BBS!$L$12:$L$69
Name balance_bbs_04: [1]BBS!$M$12:$M$70
Name balance_bbs_04: BBS!$M$12:$M$69
Name balance_bbs_05: [1]BBS!$N$12:$N$70
Name balance_bbs_05: BBS!$N$12:$N$69
Name balance_bbs_06: [1]BBS!$O$12:$O$70
Name balance_bbs_06: BBS!$O$12:$O$69
Name balance_bbs_07: [1]BBS!$P$12:$P$70
Name balance_bbs_07: BBS!$P$12:$P$69
Name balance_bbs_08: [1]BBS!$Q$12:$Q$70
Name balance_bbs_08: BBS!$Q$12:$Q$69
Name balance_bbs_09: [1]BBS!$R$12:$R$70
Name balance_bbs_09: BBS!$R$12:$R$69
Name balance_bbs_10: [1]BBS!$S$12:$S$70
Name balance_bbs_10: BBS!$S$12:$S$69
Name balance_bbs_11: [1]BBS!$T$12:$T$70
Name balance_bbs_11: BBS!$T$12:$T$69
Name balance_bbs_12: [1]BBS!$U$12:$U$70
Name balance_bbs_12: BBS!$U$12:$U$69
Name Balance_bpl_01: '[1]P&L'!$BS$8:$BS$436
Name Balance_bpl_01: 'P&L'!$BS$8:$BS$277
Name Balance_bpl_02: '[1]P&L'!$BT$8:$BT$436
Name Balance_bpl_02: 'P&L'!$BT$8:$BT$277
Name Balance_bpl_03: '[1]P&L'!$BV$8:$BV$436
Name Balance_bpl_03: 'P&L'!$BV$8:$BV$277
Name Balance_bpl_04: '[1]P&L'!$BX$8:$BX$436
Name Balance_bpl_04: 'P&L'!$BX$8:$BX$277
Name Balance_bpl_05: '[1]P&L'!$BZ$8:$BZ$436
Name Balance_bpl_05: 'P&L'!$BZ$8:$BZ$277
Name Balance_bpl_06: '[1]P&L'!$CB$8:$CB$436
Name Balance_bpl_06: 'P&L'!$CB$8:$CB$277
Name Balance_bpl_07: '[1]P&L'!$CD$8:$CD$436
Name Balance_bpl_07: 'P&L'!$CD$8:$CD$277
Name Balance_bpl_08: '[1]P&L'!$CF$8:$CF$436
Name Balance_bpl_08: 'P&L'!$CF$8:$CF$277
Name Balance_bpl_09: '[1]P&L'!$CH$8:$CH$436
Name Balance_bpl_09: 'P&L'!$CH$8:$CH$277
Name Balance_bpl_10: '[1]P&L'!$CJ$8:$CJ$436
Name Balance_bpl_10: 'P&L'!$CJ$8:$CJ$277
Name Balance_bpl_11: '[1]P&L'!$CL$8:$CL$436
Name Balance_bpl_11: 'P&L'!$CL$8:$CL$277
Name Balance_bpl_12: '[1]P&L'!$CN$8:$CN$436
Name Balance_bpl_12: 'P&L'!$CN$8:$CN$277
Name Balance_bplm_01: 'P&L'!$BS$8:$BS$277
Name Balance_bplm_02: 'P&L'!$BU$8:$BU$277
Name Balance_bplm_03: '[1]P&L'!$BW$8:$BW$436
Name Balance_bplm_03: 'P&L'!$BW$8:$BW$277
Name Balance_bplm_04: 'P&L'!$BY$8:$BY$277
Name Balance_bplm_05: 'P&L'!$CA$8:$CA$277
Name Balance_bplm_06: '[1]P&L'!$CC$8:$CC$436
Name Balance_bplm_06: 'P&L'!$CC$8:$CC$277
Name Balance_bplm_07: 'P&L'!$CE$8:$CE$277
Name Balance_bplm_08: 'P&L'!$CG$8:$CG$277

Sheet Template version managment
B4: Version | C4: Release Date | D4: Type | E4: Modifications
B5: V4 | C5: 43139 | E5: Original
B6: V5 | C6: 43142 | E6: BBS (update the index) + (cashflow move the interst&currncie to finance) +(BS update the long term liabilities ) + (opex type updated)
B7: V6 | C7: 43143 | E7: Entity added to the JE Tab+BS Index fixed
B8: V6 | C8: 43143 | E8: Adding 'Inventory' to the BS index ( not added to the BS itself )
B9: V7 | C9: 43144 | E9: Changes in the charts' title+Update the balance sheet index & cashflow
B10: v8 | C10: 43149 | E10: expend the P&L Department in the index + change fourmula in cs

Sheet Executive summary
A2: ='Actual vs Budget'!A7 -> $ | C2: ='P&L'!E2 -> Pocket Pie Studios Ltd.
A3: =IF(A2="$",1,IF(A2="$k",1000,1000000)) -> 1 | C3: Executive Summary
C5: Executive summary | D5: =EOMONTH(E5,-2)+1 -> 43466 | E5: =EOMONTH(F5,-2)+1 -> 43497 | F5: 43525 | H5: =YEAR(F5) -> 2019
C6: =A2 -> $ | D6: Actual | E6: Actual | F6: Actual | H6: YTD
C7: KPI
C8: # of customers
C9: MRR
C10: ARR
C11: ACV
C13: P&L Summary
C14: Revenue | D14: =INDEX('Financial highlights'!$D$13:$Q$13,MATCH(D$5,'Financial highlights'!$D$5:$Q$5,0)) -> #N/A | E14: =INDEX('Financial highlights'!$D$13:$Q$13,MATCH(E$5,'Financial highlights'!$D$5:$Q$5,0)) -> #N/A | F14: =INDEX('Financial highlights'!$D$13:$Q$13,MATCH(F$5,'Financial highlights'!$D$5:$Q$5,0)) -> #N/A | H14: =INDEX('Financial highlights'!$D$13:$Q$13,MATCH(H$5&" "&H$6,'Financial highlights'!$D$5:$Q$5,0)) -> #N/A
C15: COS | D15: =INDEX('Financial highlights'!$D$14:$Q$14,,MATCH(D$5,'Financial highlights'!$D$5:$Q$5,0)) -> #N/A | E15: =INDEX('Financial highlights'!$D$14:$Q$14,,MATCH(E$5,'Financial highlights'!$D$5:$Q$5,0)) -> #N/A | F15: =INDEX('Financial highlights'!$D$14:$Q$14,,MATCH(F$5,'Financial highlights'!$D$5:$Q$5,0)) -> #N/A | H15: =INDEX('Financial highlights'!$D$14:$Q$14,MATCH(H$5&" "&H$6,'Financial highlights'!$D$5:$Q$5,0)) -> #N/A
C16: Gross Profit | D16: =D14-D15 -> #N/A | E16: =E14-E15 -> #N/A | F16: =F14-F15 -> #N/A | H16: =H14-H15 -> #N/A
C17: Gross margin | D17: =IFERROR(+D16/D14,0) -> 0 | E17: =IFERROR(+E16/E14,0) -> 0 | F17: =IFERROR(+F16/F14,0) -> 0 | H17: =IFERROR(+H16/H14,0) -> 0
C18: Opex | D18: =INDEX('Financial highlights'!$D$25:$Q$25,,MATCH(D$5,'Financial highlights'!$D$5:$Q$5,0)) -> #N/A | E18: =INDEX('Financial highlights'!$D$25:$Q$25,,MATCH(E$5,'Financial highlights'!$D$5:$Q$5,0)) -> #N/A | F18: =INDEX('Financial highlights'!$D$25:$Q$25,,MATCH(F$5,'Financial highlights'!$D$5:$Q$5,0)) -> #N/A | H18: =INDEX('Financial highlights'!$D$25:$Q$25,,MATCH(H$5&" "&H$6,'Financial highlights'!$D$5:$Q$5,0)) -> #N/A
C19: EBITDA | D19: =D16-D18 -> #N/A | E19: =E16-E18 -> #N/A | F19: =F16-F18 -> #N/A | H19: =H16-H18 -> #N/A
C21: Cash flow Summary
C22: Collection | D22: =(INDEX(BS!$P$13:$AB$68,MATCH("Accounts receivable",BS!$F$13:$F$68,0),MATCH(D$5,BS!$P$9:$AB$9,0)-1)-INDEX(BS!$P$13:$AB$68,MATCH("Accounts receivable",BS!$F$13:$F$68,0),MATCH(D$5,BS!$P$9:$AB$9,0))+INDEX('P&L'!$W$13:$AI$13,MATCH(D$5,'P&L'!$W$6:$AI$6,0))+INDEX(BS!$P$13:$AB$68,MATCH("Deferred revenues",BS!$F$13:$F$68,0),MATCH(D$5,BS!$P$9:$AB$9,0))-INDEX(BS!$P$13:$AB$68,MATCH("Deferred revenues",BS!$F$13:$F$68,0),MATCH(D$5,BS!$P$9:$AB$9,0)-1))/$A$3 -> #N/A | E22: =(INDEX(BS!$P$13:$AB$68,MATCH("Accounts receivable",BS!$F$13:$F$68,0),MATCH(E$5,BS!$P$9:$AB$9,0)-1)-INDEX(BS!$P$13:$AB$68,MATCH("Accounts receivable",BS!$F$13:$F$68,0),MATCH(E$5,BS!$P$9:$AB$9,0))+INDEX('P&L'!$W$13:$AI$13,MATCH(E$5,'P&L'!$W$6:$AI$6,0))+INDEX(BS!$P$13:$AB$68,MATCH("Deferred revenues",BS!$F$13:$F$68,0),MATCH(E$5,BS!$P$9:$AB$9,0))-INDEX(BS!$P$13:$AB$68,MATCH("Deferred revenues",BS!$F$13:$F$68,0),MATCH(E$5,BS!$P$9:$AB$9,0)-1))/$A$3 -> #N/A | F22: =(INDEX(BS!$P$13:$AB$68,MATCH("Accounts receivable",BS!$F$13:$F$68,0),MATCH(F$5,BS!$P$9:$AB$9,0)-1)-INDEX(BS!$P$13:$AB$68,MATCH("Accounts receivable",BS!$F$13:$F$68,0),MATCH(F$5,BS!$P$9:$AB$9,0))+INDEX('P&L'!$W$13:$AI$13,MATCH(F$5,'P&L'!$W$6:$AI$6,0))+INDEX(BS!$P$13:$AB$68,MATCH("Deferred revenues",BS!$F$13:$F$68,0),MATCH(F$5,BS!$P$9:$AB$9,0))-INDEX(BS!$P$13:$AB$68,MATCH("Deferred revenues",BS!$F$13:$F$68,0),MATCH(F$5,BS!$P$9:$AB$9,0)-1))/$A$3 -> #N/A | H22: =(INDEX(BS!$P$13:$P$70,MATCH("Accounts receivable",BS!$F$13:$F$70,0))-INDEX(BS!$J$13:$J$70,MATCH("Accounts receivable",BS!$F$13:$F$70,0))+'P&L'!P13+INDEX(BS!$P$13:$P$70,MATCH("Deferred revenues",BS!$F$13:$F$70,0))-INDEX(BS!$J$13:$J$70,MATCH("Deferred revenues",BS!$F$13:$F$70,0)))/$A$3 -> 0
C23: Payments Payroll | D23: =(-INDEX(BS!$P$13:$AB$68,MATCH("Employee payables",BS!$F$13:$F$68,0),MATCH(D$5,BS!$P$9:$AB$9,0)-1)+INDEX(BS!$P$13:$AB$68,MATCH("Employee payables",BS!$F$13:$F$68,0),MATCH(D$5,BS!$P$9:$AB$9,0))-INDEX(BS!$P$13:$AB$68,MATCH("Employee institution",BS!$F$13:$F$68,0),MATCH(D$5,BS!$P$9:$AB$9,0)-1)+INDEX(BS!$P$13:$AB$68,MATCH("Employee institution",BS!$F$13:$F$68,0),MATCH(D$5,BS!$P$9:$AB$9,0))-INDEX(BS!$P$13:$AB$68,MATCH("Short term provisions - holiday accrual",BS!$F$13:$F$68,0),MATCH(D$5,BS!$P$9:$AB$9,0)-1)+INDEX(BS!$P$13:$AB$68,MATCH("Short term provisions - holiday accrual",BS!$F$13:$F$68,0),MATCH(D$5,BS!$P$9:$AB$9,0))-SUMIFS(INDEX('P&L'!$V$8:$AI$277,,MATCH(D$5,'P&L'!$V$6:$AI$6,0)-1),'P&L'!$D$8:$D$277,"Payroll")-SUMIFS(INDEX('P&L'!$V$8:$AI$277,,MATCH(D$5,'P&L'!$V$6:$AI$6,0)-1),'P&L'!$D$8:$D$277,"Recruitment"))/$A$3 -> #N/A | E23: =(-INDEX(BS!$P$13:$AB$68,MATCH("Employee payables",BS!$F$13:$F$68,0),MATCH(E$5,BS!$P$9:$AB$9,0)-1)+INDEX(BS!$P$13:$AB$68,MATCH("Employee payables",BS!$F$13:$F$68,0),MATCH(E$5,BS!$P$9:$AB$9,0))-INDEX(BS!$P$13:$AB$68,MATCH("Employee institution",BS!$F$13:$F$68,0),MATCH(E$5,BS!$P$9:$AB$9,0)-1)+INDEX(BS!$P$13:$AB$68,MATCH("Employee institution",BS!$F$13:$F$68,0),MATCH(E$5,BS!$P$9:$AB$9,0))-INDEX(BS!$P$13:$AB$68,MATCH("Short term provisions - holiday accrual",BS!$F$13:$F$68,0),MATCH(E$5,BS!$P$9:$AB$9,0)-1)+INDEX(BS!$P$13:$AB$68,MATCH("Short term provisions - holiday accrual",BS!$F$13:$F$68,0),MATCH(E$5,BS!$P$9:$AB$9,0))-SUMIFS(INDEX('P&L'!$V$8:$AI$277,,MATCH(E$5,'P&L'!$V$6:$AI$6,0)-1),'P&L'!$D$8:$D$277,"Payroll")-SUMIFS(INDEX('P&L'!$V$8:$AI$277,,MATCH(E$5,'P&L'!$V$6:$AI$6,0)-1),'P&L'!$D$8:$D$277,"Recruitment"))/$A$3 -> #N/A | F23: =(-INDEX(BS!$P$13:$AB$68,MATCH("Employee payables",BS!$F$13:$F$68,0),MATCH(F$5,BS!$P$9:$AB$9,0)-1)+INDEX(BS!$P$13:$AB$68,MATCH("Employee payables",BS!$F$13:$F$68,0),MATCH(F$5,BS!$P$9:$AB$9,0))-INDEX(BS!$P$13:$AB$68,MATCH("Employee institution",BS!$F$13:$F$68,0),MATCH(F$5,BS!$P$9:$AB$9,0)-1)+INDEX(BS!$P$13:$AB$68,MATCH("Employee institution",BS!$F$13:$F$68,0),MATCH(F$5,BS!$P$9:$AB$9,0))-INDEX(BS!$P$13:$AB$68,MATCH("Short term provisions - holiday accrual",BS!$F$13:$F$68,0),MATCH(F$5,BS!$P$9:$AB$9,0)-1)+INDEX(BS!$P$13:$AB$68,MATCH("Short term provisions - holiday accrual",BS!$F$13:$F$68,0),MATCH(F$5,BS!$P$9:$AB$9,0))-SUMIFS(INDEX('P&L'!$V$8:$AI$277,,MATCH(F$5,'P&L'!$V$6:$AI$6,0)-1),'P&L'!$D$8:$D$277,"Payroll")-SUMIFS(INDEX('P&L'!$V$8:$AI$277,,MATCH(F$5,'P&L'!$V$6:$AI$6,0)-1),'P&L'!$D$8:$D$277,"Recruitment"))/$A$3 -> #N/A | H23: =(-INDEX(BS!$P$13:$AB$68,MATCH("Employee payables",BS!$F$13:$F$63,0),MATCH(BS!$P$9,BS!$P$9:$AB$9,0))+INDEX(BS!$J$13:$J$68,MATCH("Employee payables",BS!$F$13:$F$68,0))-INDEX(BS!$P$13:$AB$68,MATCH("Employee institution",BS!$F$13:$F$63,0),MATCH(BS!$P$9,BS!$P$9:$AB$9,0))+INDEX(BS!$J$13:$J$68,MATCH("Employee institution",BS!$F$13:$F$68,0))-INDEX(BS!$P$13:$AB$68,MATCH("Short term provisions - holiday accrual",BS!$F$13:$F$63,0),MATCH(BS!$P$9,BS!$P$9:$AB$9,0))+INDEX(BS!$J$13:$J$68,MATCH("Short term provisions - holiday accrual",BS!$F$13:$F$68,0))-SUMIFS('P&L'!$W$8:$W$277,'P&L'!$D$8:$D$277,"Payroll")-SUMIFS('P&L'!$W$8:$W$277,'P&L'!$D$8:$D$277,"Recruitment"))/$A$3 -> 208543.7
C24: Payments Vendors | D24: =(D26-D22-D23-D25)/$A$3 -> #N/A | E24: =(E26-E22-E23-E25)/$A$3 -> #N/A | F24: =(F26-F22-F23-F25)/$A$3 -> #N/A | H24: =(H26-H22-H23-H25)/$A$3 -> #N/A
C25: Financing | D25: =INDEX(CF!$Y$57:$AK$57,MATCH(D$5,CF!$Y$7:$AK$7,0))/$A$3 -> #N/A | E25: =INDEX(CF!$Y$57:$AK$57,MATCH(E$5,CF!$Y$7:$AK$7,0))/$A$3 -> #N/A | F25: =INDEX(CF!$Y$57:$AK$57,MATCH(F$5,CF!$Y$7:$AK$7,0))/$A$3 -> #N/A | H25: =CF!S57/$A$3 -> 8627433.5
C26: Net burn | D26: =INDEX('Financial highlights'!$D$36:$Q$36,MATCH(D$5,'Financial highlights'!$D$29:$Q$29,0)) -> #N/A | E26: =INDEX('Financial highlights'!$D$36:$Q$36,MATCH(E$5,'Financial highlights'!$D$29:$Q$29,0)) -> #N/A | F26: =INDEX('Financial highlights'!$D$36:$Q$36,MATCH(F$5,'Financial highlights'!$D$29:$Q$29,0)) -> #N/A | H26: =INDEX('Financial highlights'!$D$36:$Q$36,MATCH(H$5&" "&H$6,'Financial highlights'!$D$29:$Q$29,0)) -> #N/A
C27: Cash end of period | D27: =INDEX('Financial highlights'!$D$37:$Q$37,MATCH(D$5,'Financial highlights'!$D$5:$Q$5,0)) -> #N/A | E27: =INDEX('Financial highlights'!$D$37:$Q$37,MATCH(E$5,'Financial highlights'!$D$5:$Q$5,0)) -> #N/A | F27: =INDEX('Financial highlights'!$D$37:$Q$37,MATCH(F$5,'Financial highlights'!$D$5:$Q$5,0)) -> #N/A | H27: =INDEX('Financial highlights'!$D$37:$Q$37,MATCH(H$5&" "&H$6,'Financial highlights'!$D$5:$Q$5,0)) -> #N/A
C29: HC Summary
C30: HC | D30: =INDEX('Financial highlights'!$D$50:$Q$50,,MATCH(D$5,'Financial highlights'!$D$40:$Q$40,0)) -> #N/A | E30: =INDEX('Financial highlights'!$D$50:$Q$50,,MATCH(E$5,'Financial highlights'!$D$40:$Q$40,0)) -> #N/A | F30: =INDEX('Financial highlights'!$D$50:$Q$50,,MATCH(F$5,'Financial highlights'!$D$40:$Q$40,0)) -> #N/A | H30: =INDEX('Financial highlights'!$D$50:$Q$50,,MATCH(H$5&" "&H$6,'Financial highlights'!$D$40:$Q$40,0)) -> #N/A
C31: Opex + COS / HC | D31: =IFERROR((D15+D18)/D30,0) -> 0 | E31: =IFERROR((E15+E18)/E30,0) -> 0 | F31: =IFERROR((F15+F18)/F30,0) -> 0 | H31: =IFERROR((H15+H18)/H30,0) -> 0
C33: Balance Sheet Summary
C34: Net working capital | D34: =(INDEX(BS!$P$12:$AB$70,MATCH("Total Current Assets",BS!$E$12:$E$70,0),MATCH(D$5,BS!$P$9:$AB$9,0))-INDEX(BS!$P$12:$AB$70,MATCH("Total Current Liabilities",BS!$E$12:$E$70,0),MATCH(D$5,BS!$P$9:$AB$9,0)))/$A$3 -> #N/A | E34: =(INDEX(BS!$P$12:$AB$70,MATCH("Total Current Assets",BS!$E$12:$E$70,0),MATCH(E$5,BS!$P$9:$AB$9,0))-INDEX(BS!$P$12:$AB$70,MATCH("Total Current Liabilities",BS!$E$12:$E$70,0),MATCH(E$5,BS!$P$9:$AB$9,0)))/$A$3 -> #N/A | F34: =(INDEX(BS!$P$12:$AB$70,MATCH("Total Current Assets",BS!$E$12:$E$70,0),MATCH(F$5,BS!$P$9:$AB$9,0))-INDEX(BS!$P$12:$AB$70,MATCH("Total Current Liabilities",BS!$E$12:$E$70,0),MATCH(F$5,BS!$P$9:$AB$9,0)))/$A$3 -> #N/A | H34: =(INDEX(BS!$J$12:$J$70,MATCH("Total Current Assets",BS!$E$12:$E$70,0))-INDEX(BS!$J$12:$J$70,MATCH("Total Current Liabilities",BS!$E$12:$E$70,0)))/$A$3 -> 6524305.4
C35: Outstanding Loans / long term liabilities | D35: =INDEX(BS!$P$55:$AB$55,MATCH(D$5,BS!$P$9:$AB$9,0))/$A$3 -> #N/A | E35: =INDEX(BS!$P$55:$AB$55,MATCH(E$5,BS!$P$9:$AB$9,0))/$A$3 -> #N/A | F35: =INDEX(BS!$P$55:$AB$55,MATCH(F$5,BS!$P$9:$AB$9,0))/$A$3 -> #N/A | H35: =BS!J55/$A$3 -> 0

Sheet Actual vs Budget
A2: Errors in this sheet: | C2: ='P&L'!E2 -> Pocket Pie Studios Ltd.
A3: =COUNTIF(D28:O28,"error")+COUNTIF(D37:O37,"error")+COUNTIF(D50:O50,"error")+COUNTIF(D93:O93,"error") -> 0 | C3: Actual vs Budget
A4: General errors in file:
A5: =A3+'Financial highlights'!A3+'P&L'!CU2+'P&L'!M2+BS!J2+BS!AQ2+CF!AS2+CF!M2+JE!C1+'Trial balance'!C1 -> 5
A6: Scale | C6: ="Month "&$A$7 -> Month $ | D6: =month_of_report -> 44531 | H6: ="Quarter "&$A$7 -> Quarter $ | I6: ="Q"&ROUNDUP(MONTH(month_of_report)/3,0)&"-"&YEAR(month_of_report)-2000 -> Q4-21 | M6: =$A$7&" YTD "&YEAR(month_of_report) -> $ YTD 2021 | N6: =RIGHT(M6,4) -> 2021
A7: ='Financial highlights'!E3 -> $ | D7: Actual | E7: Budget | F7: Variance | I7: Actual | J7: Budget | K7: Variance | N7: Actual | O7: Budget | P7: Variance
A8: =IF(A7="$",1,IF(A7="$k",1000,1000000)) -> 1 | C8: KPI | H8: =C8 -> KPI | M8: =H8 -> KPI
C9: KPI | H9: =C9 -> KPI | M9: =H9 -> KPI
C10: MRR | H10: =C10 -> MRR | M10: =H10 -> MRR
C11: ARR | H11: =C11 -> ARR | M11: =H11 -> ARR
C13: ="P&L Summary "&$A$7 -> P&L Summary $ | H13: =C13 -> P&L Summary $ | M13: =H13 -> P&L Summary $
A14: 1 | C14: Revenues | D14: =IFERROR(INDEX('P&L'!H$8:H$278,MATCH($A14,'P&L'!$C$8:$C$278,0),),0)/$A$8 -> 0 | E14: =IFERROR(INDEX('P&L'!I$8:I$278,MATCH($A14,'P&L'!$C$8:$C$278,0),),0)/$A$8 -> 0 | F14: =IFERROR(INDEX('P&L'!J$8:J$278,MATCH($A14,'P&L'!$C$8:$C$278,0),),0)/$A$8 -> 0 | H14: =C14 -> Revenues | I14: =IFERROR(INDEX('P&L'!L$8:L$278,MATCH($A14,'P&L'!$C$8:$C$278,0),),0)/$A$8 -> 0 | J14: =IFERROR(INDEX('P&L'!M$8:M$278,MATCH($A14,'P&L'!$C$8:$C$278,0),),0)/$A$8 -> 0 | K14: =IFERROR(INDEX('P&L'!N$8:N$278,MATCH($A14,'P&L'!$C$8:$C$278,0),),0)/$A$8 -> 0 | M14: =H14 -> Revenues | N14: =IFERROR(INDEX('P&L'!P$8:P$278,MATCH($A14,'P&L'!$C$8:$C$278,0),),0)/$A$8 -> 0 | O14: =IFERROR(INDEX('P&L'!Q$8:Q$278,MATCH($A14,'P&L'!$C$8:$C$278,0),),0)/$A$8 -> 0 | P14: =IFERROR(INDEX('P&L'!R$8:R$278,MATCH($A14,'P&L'!$C$8:$C$278,0),),0)/$A$8 -> 0
A15: 2 | C15: Cost of Sales | D15: =IFERROR(INDEX('P&L'!H$8:H$278,MATCH($A15,'P&L'!$C$8:$C$278,0),),0)/$A$8 -> 0 | E15: =IFERROR(INDEX('P&L'!I$8:I$278,MATCH($A15,'P&L'!$C$8:$C$278,0),),0)/$A$8 -> 0 | F15: =IFERROR(INDEX('P&L'!J$8:J$278,MATCH($A15,'P&L'!$C$8:$C$278,0),),0)/$A$8 -> 0 | H15: =C15 -> Cost of Sales | I15: =IFERROR(INDEX('P&L'!L$8:L$278,MATCH($A15,'P&L'!$C$8:$C$278,0),),0)/$A$8 -> 0 | J15: =IFERROR(INDEX('P&L'!M$8:M$278,MATCH($A15,'P&L'!$C$8:$C$278,0),),0)/$A$8 -> 0 | K15: =IFERROR(INDEX('P&L'!N$8:N$278,MATCH($A15,'P&L'!$C$8:$C$278,0),),0)/$A$8 -> 0 | M15: =H15 -> Cost of Sales | N15: =IFERROR(INDEX('P&L'!P$8:P$278,MATCH($A15,'P&L'!$C$8:$C$278,0),),0)/$A$8 -> 0 | O15: =IFERROR(INDEX('P&L'!Q$8:Q$278,MATCH($A15,'P&L'!$C$8:$C$278,0),),0)/$A$8 -> 0 | P15: =IFERROR(INDEX('P&L'!R$8:R$278,MATCH($A15,'P&L'!$C$8:$C$278,0),),0)/$A$8 -> 0
C16: Gross profit | D16: =D14-D15 -> 0 | E16: =E14-E15 -> 0 | F16: =F14+F15 -> 0 | H16: =C16 -> Gross profit | I16: =I14-I15 -> 0 | J16: =J14-J15 -> 0 | K16: =K14+K15 -> 0 | M16: =H16 -> Gross profit | N16: =N14-N15 -> 0 | O16: =O14-O15 -> 0 | P16: =P14+P15 -> 0
C17: Gross margin | D17: =IFERROR(+D16/D14,0) -> 0 | E17: =IFERROR(+E16/E14,0) -> 0 | F17: =IFERROR(+F16/F14,0) -> 0 | H17: =C17 -> Gross margin | I17: =IFERROR(+I16/I14,0) -> 0 | J17: =IFERROR(+J16/J14,0) -> 0 | K17: =IFERROR(+K16/K14,0) -> 0 | M17: =H17 -> Gross margin | N17: =IFERROR(+N16/N14,0) -> 0 | O17: =IFERROR(+O16/O14,0) -> 0 | P17: =IFERROR(+P16/P14,0) -> 0
C18: Opex: | H18: =C18 -> Opex: | M18: =H18 -> Opex:
A19: 11 | C19: ='Financial highlights'!C18 -> R&D | D19: =IFERROR(INDEX('P&L'!H$8:H$278,MATCH($A19,'P&L'!$C$8:$C$278,0),),0)/$A$8 -> 669810.02 | E19: =IFERROR(INDEX('P&L'!I$8:I$278,MATCH($A19,'P&L'!$C$8:$C$278,0),),0)/$A$8 -> 77241.456 | F19: =IFERROR(INDEX('P&L'!J$8:J$278,MATCH($A19,'P&L'!$C$8:$C$278,0),),0)/$A$8 -> -592568.57 | H19: =C19 -> R&D | I19: =IFERROR(INDEX('P&L'!L$8:L$278,MATCH($A19,'P&L'!$C$8:$C$278,0),),0)/$A$8 -> 669810.02 | J19: =IFERROR(INDEX('P&L'!M$8:M$278,MATCH($A19,'P&L'!$C$8:$C$278,0),),0)/$A$8 -> 231724.37 | K19: =IFERROR(INDEX('P&L'!N$8:N$278,MATCH($A19,'P&L'!$C$8:$C$278,0),),0)/$A$8 -> -438085.66 | M19: =H19 -> R&D | N19: =IFERROR(INDEX('P&L'!P$8:P$278,MATCH($A19,'P&L'!$C$8:$C$278,0),),0)/$A$8 -> 669810.02 | O19: =IFERROR(INDEX('P&L'!Q$8:Q$278,MATCH($A19,'P&L'!$C$8:$C$278,0),),0)/$A$8 -> 654302.04 | P19: =IFERROR(INDEX('P&L'!R$8:R$278,MATCH($A19,'P&L'!$C$8:$C$278,0),),0)/$A$8 -> -15507.983
A20: 12 | C20: ='Financial highlights'!C19 -> Product | D20: =IFERROR(INDEX('P&L'!H$8:H$278,MATCH($A20,'P&L'!$C$8:$C$278,0),),0)/$A$8 -> 326761.88 | E20: =IFERROR(INDEX('P&L'!I$8:I$278,MATCH($A20,'P&L'!$C$8:$C$278,0),),0)/$A$8 -> 29147.848 | F20: =IFERROR(INDEX('P&L'!J$8:J$278,MATCH($A20,'P&L'!$C$8:$C$278,0),),0)/$A$8 -> -297614.03 | H20: =C20 -> Product | I20: =IFERROR(INDEX('P&L'!L$8:L$278,MATCH($A20,'P&L'!$C$8:$C$278,0),),0)/$A$8 -> 326761.88 | J20: =IFERROR(INDEX('P&L'!M$8:M$278,MATCH($A20,'P&L'!$C$8:$C$278,0),),0)/$A$8 -> 87443.544 | K20: =IFERROR(INDEX('P&L'!N$8:N$278,MATCH($A20,'P&L'!$C$8:$C$278,0),),0)/$A$8 -> -239318.33 | M20: =H20 -> Product | N20: =IFERROR(INDEX('P&L'!P$8:P$278,MATCH($A20,'P&L'!$C$8:$C$278,0),),0)/$A$8 -> 326761.88 | O20: =IFERROR(INDEX('P&L'!Q$8:Q$278,MATCH($A20,'P&L'!$C$8:$C$278,0),),0)/$A$8 -> 251033.92 | P20: =IFERROR(INDEX('P&L'!R$8:R$278,MATCH($A20,'P&L'!$C$8:$C$278,0),),0)/$A$8 -> -75727.952
A21: 13 | C21: ='Financial highlights'!C20 -> Art | D21: =IFERROR(INDEX('P&L'!H$8:H$278,MATCH($A21,'P&L'!$C$8:$C$278,0),),0)/$A$8 -> 664947.33 | E21: =IFERROR(INDEX('P&L'!I$8:I$278,MATCH($A21,'P&L'!$C$8:$C$278,0),),0)/$A$8 -> 53061.835 | F21: =IFERROR(INDEX('P&L'!J$8:J$278,MATCH($A21,'P&L'!$C$8:$C$278,0),),0)/$A$8 -> -611885.5 | H21: =C21 -> Art | I21: =IFERROR(INDEX('P&L'!L$8:L$278,MATCH($A21,'P&L'!$C$8:$C$278,0),),0)/$A$8 -> 664947.33 | J21: =IFERROR(INDEX('P&L'!M$8:M$278,MATCH($A21,'P&L'!$C$8:$C$278,0),),0)/$A$8 -> 159185.51 | K21: =IFERROR(INDEX('P&L'!N$8:N$278,MATCH($A21,'P&L'!$C$8:$C$278,0),),0)/$A$8 -> -505761.82 | M21: =H21 -> Art | N21: =IFERROR(INDEX('P&L'!P$8:P$278,MATCH($A21,'P&L'!$C$8:$C$278,0),),0)/$A$8 -> 664947.33 | O21: =IFERROR(INDEX('P&L'!Q$8:Q$278,MATCH($A21,'P&L'!$C$8:$C$278,0),),0)/$A$8 -> 577647.58 | P21: =IFERROR(INDEX('P&L'!R$8:R$278,MATCH($A21,'P&L'!$C$8:$C$278,0),),0)/$A$8 -> -87299.75
A22: 14 | C22: ='Financial highlights'!C21 -> Sales Costs | D22: =IFERROR(INDEX('P&L'!H$8:H$278,MATCH($A22,'P&L'!$C$8:$C$278,0),),0)/$A$8 -> 0 | E22: =IFERROR(INDEX('P&L'!I$8:I$278,MATCH($A22,'P&L'!$C$8:$C$278,0),),0)/$A$8 -> 0 | F22: =IFERROR(INDEX('P&L'!J$8:J$278,MATCH($A22,'P&L'!$C$8:$C$278,0),),0)/$A$8 -> 0 | H22: =C22 -> Sales Costs | I22: =IFERROR(INDEX('P&L'!L$8:L$278,MATCH($A22,'P&L'!$C$8:$C$278,0),),0)/$A$8 -> 0 | J22: =IFERROR(INDEX('P&L'!M$8:M$278,MATCH($A22,'P&L'!$C$8:$C$278,0),),0)/$A$8 -> 40000 | K22: =IFERROR(INDEX('P&L'!N$8:N$278,MATCH($A22,'P&L'!$C$8:$C$278,0),),0)/$A$8 -> 40000 | M22: =H22 -> Sales Costs | N22: =IFERROR(INDEX('P&L'!P$8:P$278,MATCH($A22,'P&L'!$C$8:$C$278,0),),0)/$A$8 -> 0 | O22: =IFERROR(INDEX('P&L'!Q$8:Q$278,MATCH($A22,'P&L'!$C$8:$C$278,0),),0)/$A$8 -> 128000 | P22: =IFERROR(INDEX('P&L'!R$8:R$278,MATCH($A22,'P&L'!$C$8:$C$278,0),),0)/$A$8 -> 128000
A23: 15 | C23: ='Financial highlights'!C22 -> Marketing Costs | D23: =IFERROR(INDEX('P&L'!H$8:H$278,MATCH($A23,'P&L'!$C$8:$C$278,0),),0)/$A$8 -> 6018.94 | E23: =IFERROR(INDEX('P&L'!I$8:I$278,MATCH($A23,'P&L'!$C$8:$C$278,0),),0)/$A$8 -> 39162.468 | F23: =IFERROR(INDEX('P&L'!J$8:J$278,MATCH($A23,'P&L'!$C$8:$C$278,0),),0)/$A$8 -> 33143.528 | H23: =C23 -> Marketing Costs | I23: =IFERROR(INDEX('P&L'!L$8:L$278,MATCH($A23,'P&L'!$C$8:$C$278,0),),0)/$A$8 -> 6018.94 | J23: =IFERROR(INDEX('P&L'!M$8:M$278,MATCH($A23,'P&L'!$C$8:$C$278,0),),0)/$A$8 -> 117487.41 | K23: =IFERROR(INDEX('P&L'!N$8:N$278,MATCH($A23,'P&L'!$C$8:$C$278,0),),0)/$A$8 -> 111468.47 | M23: =H23 -> Marketing Costs | N23: =IFERROR(INDEX('P&L'!P$8:P$278,MATCH($A23,'P&L'!$C$8:$C$278,0),),0)/$A$8 -> 6018.94 | O23: =IFERROR(INDEX('P&L'!Q$8:Q$278,MATCH($A23,'P&L'!$C$8:$C$278,0),),0)/$A$8 -> 199137.28 | P23: =IFERROR(INDEX('P&L'!R$8:R$278,MATCH($A23,'P&L'!$C$8:$C$278,0),),0)/$A$8 -> 193118.34
A24: 16 | C24: ='Financial highlights'!C23 -> G&A | D24: =IFERROR(INDEX('P&L'!H$8:H$278,MATCH($A24,'P&L'!$C$8:$C$278,0),),0)/$A$8 -> 265069.35 | E24: =IFERROR(INDEX('P&L'!I$8:I$278,MATCH($A24,'P&L'!$C$8:$C$278,0),),0)/$A$8 -> 25440.492 | F24: =IFERROR(INDEX('P&L'!J$8:J$278,MATCH($A24,'P&L'!$C$8:$C$278,0),),0)/$A$8 -> -239628.86 | H24: =C24 -> G&A | I24: =IFERROR(INDEX('P&L'!L$8:L$278,MATCH($A24,'P&L'!$C$8:$C$278,0),),0)/$A$8 -> 265069.35 | J24: =IFERROR(INDEX('P&L'!M$8:M$278,MATCH($A24,'P&L'!$C$8:$C$278,0),),0)/$A$8 -> 70030.337 | K24: =IFERROR(INDEX('P&L'!N$8:N$278,MATCH($A24,'P&L'!$C$8:$C$278,0),),0)/$A$8 -> -195039.01 | M24: =H24 -> G&A | N24: =IFERROR(INDEX('P&L'!P$8:P$278,MATCH($A24,'P&L'!$C$8:$C$278,0),),0)/$A$8 -> 265069.35 | O24: =IFERROR(INDEX('P&L'!Q$8:Q$278,MATCH($A24,'P&L'!$C$8:$C$278,0),),0)/$A$8 -> 254084.76 | P24: =IFERROR(INDEX('P&L'!R$8:R$278,MATCH($A24,'P&L'!$C$8:$C$278,0),),0)/$A$8 -> -10984.584
C25: ='Financial highlights'!C24 -> #N/A | D25: =IFERROR(INDEX('P&L'!H$8:H$278,MATCH($A25,'P&L'!$C$8:$C$278,0),),0)/$A$8 -> 0 | E25: =IFERROR(INDEX('P&L'!I$8:I$278,MATCH($A25,'P&L'!$C$8:$C$278,0),),0)/$A$8 -> 0 | F25: =IFERROR(INDEX('P&L'!J$8:J$278,MATCH($A25,'P&L'!$C$8:$C$278,0),),0)/$A$8 -> 0 | H25: =C25 -> #N/A | I25: =IFERROR(INDEX('P&L'!L$8:L$278,MATCH($A25,'P&L'!$C$8:$C$278,0),),0)/$A$8 -> 0 | J25: =IFERROR(INDEX('P&L'!M$8:M$278,MATCH($A25,'P&L'!$C$8:$C$278,0),),0)/$A$8 -> 0 | K25: =IFERROR(INDEX('P&L'!N$8:N$278,MATCH($A25,'P&L'!$C$8:$C$278,0),),0)/$A$8 -> 0 | M25: =H25 -> #N/A | N25: =IFERROR(INDEX('P&L'!P$8:P$278,MATCH($A25,'P&L'!$C$8:$C$278,0),),0)/$A$8 -> 0 | O25: =IFERROR(INDEX('P&L'!Q$8:Q$278,MATCH($A25,'P&L'!$C$8:$C$278,0),),0)/$A$8 -> 0 | P25: =IFERROR(INDEX('P&L'!R$8:R$278,MATCH($A25,'P&L'!$C$8:$C$278,0),),0)/$A$8 -> 0
C26: Total OPEX | D26: =SUM(D19:D25) -> 1932607.5 | E26: =SUM(E19:E25) -> 224054.1 | F26: =SUM(F19:F25) -> -1708553.4 | H26: =C26 -> Total OPEX | I26: =SUM(I19:I25) -> 1932607.5 | J26: =SUM(J19:J25) -> 705871.16 | K26: =SUM(K19:K25) -> -1226736.4 | M26: =H26 -> Total OPEX | N26: =SUM(N19:N25) -> 1932607.5 | O26: =SUM(O19:O25) -> 2064205.6 | P26: =SUM(P19:P25) -> 131598.07
C27: EBITDA | D27: =D16-D26 -> -1932607.5 | E27: =E16-E26 -> -224054.1 | F27: =F16+F26 -> -1708553.4 | H27: =C27 -> EBITDA | I27: =I16-I26 -> -1932607.5 | J27: =J16-J26 -> -705871.16 | K27: =K16+K26 -> -1226736.4 | M27: =H27 -> EBITDA | N27: =N16-N26 -> -1932607.5 | O27: =O16-O26 -> -2064205.6 | P27: =P16+P26 -> 131598.07
D28: =IF(ROUND(D26*$A$8,0)=ROUND('P&L'!H249,0),"","Error") | E28: =IF(ROUND(E26*$A$8,0)=ROUND('P&L'!I249,0),"","Error") | I28: =IF(ROUND(I26*$A$8,0)=ROUND('P&L'!L249,0),"","Error") | J28: =IF(ROUND(J26*$A$8,0)=ROUND('P&L'!M249,0),"","Error") | N28: =IF(ROUND(N26*$A$8,0)=ROUND('P&L'!P249,0),"","Error") | O28: =IF(ROUND(O26*$A$8,0)=ROUND('P&L'!Q249,0),"","Error")
C29: ="Cash flow "&$A$7 -> Cash flow $ | D29: =D7 -> Actual | E29: =E7 -> Budget | F29: =F7 -> Variance | H29: =C29 -> Cash flow $ | I29: =I7 -> Actual | J29: =J7 -> Budget | K29: =K7 -> Variance | M29: =H29 -> Cash flow $ | N29: =N7 -> Actual | O29: =O7 -> Budget | P29: =P7 -> Variance
C30: Cash at Beginning of Period | D30: =INDEX(CF!K$11:K$65,MATCH($C30,CF!$I$11:$I$65,0))/$A$8 -> 1663501.8 | E30: =INDEX(CF!L$11:L$65,MATCH($C30,CF!$I$11:$I$65,0))/$A$8 -> 3868873.2 | F30: =INDEX(CF!M$11:M$65,MATCH($C30,CF!$I$11:$I$65,0))/$A$8 -> -2205371.4 | H30: =C30 -> Cash at Beginning of Period | I30: =INDEX(CF!O$11:O$65,MATCH($C30,CF!$I$11:$I$65,0))/$A$8 -> 1663501.8 | J30: =INDEX(CF!P$11:P$65,MATCH($C30,CF!$I$11:$I$65,0))/$A$8 -> 4341021.4 | K30: =INDEX(CF!Q$11:Q$65,MATCH($C30,CF!$I$11:$I$65,0))/$A$8 -> -2677519.6 | M30: =H30 -> Cash at Beginning of Period | N30: =INDEX(CF!S$11:S$65,MATCH($C30,CF!$I$11:$I$65,0))/$A$8 -> 1663501.8 | O30: =INDEX(CF!T$11:T$65,MATCH($C30,CF!$I$11:$I$65,0))/$A$8 -> 1667734.9 | P30: =INDEX(CF!U$11:U$65,MATCH($C30,CF!$I$11:$I$65,0))/$A$8 -> -4233.1061
C31: Net Operating Cash Flow | D31: =INDEX(CF!K$11:K$65,MATCH($C31,CF!$I$11:$I$65,0))/$A$8 -> -1560685.8 | E31: =INDEX(CF!L$11:L$65,MATCH($C31,CF!$I$11:$I$65,0))/$A$8 -> -238402.53 | F31: =INDEX(CF!M$11:M$65,MATCH($C31,CF!$I$11:$I$65,0))/$A$8 -> -1322283.3 | H31: =C31 -> Net Operating Cash Flow | I31: =INDEX(CF!O$11:O$65,MATCH($C31,CF!$I$11:$I$65,0))/$A$8 -> -1560685.8 | J31: =INDEX(CF!P$11:P$65,MATCH($C31,CF!$I$11:$I$65,0))/$A$8 -> -704340.6 | K31: =INDEX(CF!Q$11:Q$65,MATCH($C31,CF!$I$11:$I$65,0))/$A$8 -> -856345.19 | M31: =H31 -> Net Operating Cash Flow | N31: =INDEX(CF!S$11:S$65,MATCH($C31,CF!$I$11:$I$65,0))/$A$8 -> -1560685.8 | O31: =INDEX(CF!T$11:T$65,MATCH($C31,CF!$I$11:$I$65,0))/$A$8 -> -1896076.1 | P31: =INDEX(CF!U$11:U$65,MATCH($C31,CF!$I$11:$I$65,0))/$A$8 -> 335390.27
C32: Total Capital Expenditure | D32: =INDEX(CF!K$11:K$65,MATCH($C32,CF!$I$11:$I$65,0))/$A$8 -> -106525.99 | E32: =INDEX(CF!L$11:L$65,MATCH($C32,CF!$I$11:$I$65,0))/$A$8 -> 0 | F32: =INDEX(CF!M$11:M$65,MATCH($C32,CF!$I$11:$I$65,0))/$A$8 -> -106525.99 | H32: =C32 -> Total Capital Expenditure | I32: =INDEX(CF!O$11:O$65,MATCH($C32,CF!$I$11:$I$65,0))/$A$8 -> -106525.99 | J32: =INDEX(CF!P$11:P$65,MATCH($C32,CF!$I$11:$I$65,0))/$A$8 -> -6210.1266 | K32: =INDEX(CF!Q$11:Q$65,MATCH($C32,CF!$I$11:$I$65,0))/$A$8 -> -100315.86 | M32: =H32 -> Total Capital Expenditure | N32: =INDEX(CF!S$11:S$65,MATCH($C32,CF!$I$11:$I$65,0))/$A$8 -> -106525.99 | O32: =INDEX(CF!T$11:T$65,MATCH($C32,CF!$I$11:$I$65,0))/$A$8 -> -74521.519 | P32: =INDEX(CF!U$11:U$65,MATCH($C32,CF!$I$11:$I$65,0))/$A$8 -> -32004.471
C33: Total Financing | D33: =INDEX(CF!K$11:K$65,MATCH($C33,CF!$I$11:$I$65,0))/$A$8 -> 8627433.5 | E33: =INDEX(CF!L$11:L$65,MATCH($C33,CF!$I$11:$I$65,0))/$A$8 -> -3.4924597e-10 | F33: =INDEX(CF!M$11:M$65,MATCH($C33,CF!$I$11:$I$65,0))/$A$8 -> 8627433.5 | H33: =C33 -> Total Financing | I33: =INDEX(CF!O$11:O$65,MATCH($C33,CF!$I$11:$I$65,0))/$A$8 -> 8627433.5 | J33: =INDEX(CF!P$11:P$65,MATCH($C33,CF!$I$11:$I$65,0))/$A$8 -> -1.0477379e-09 | K33: =INDEX(CF!Q$11:Q$65,MATCH($C33,CF!$I$11:$I$65,0))/$A$8 -> 8627433.5 | M33: =H33 -> Total Financing | N33: =INDEX(CF!S$11:S$65,MATCH($C33,CF!$I$11:$I$65,0))/$A$8 -> 8627433.5 | O33: =INDEX(CF!T$11:T$65,MATCH($C33,CF!$I$11:$I$65,0))/$A$8 -> 3933333.3 | P33: =INDEX(CF!U$11:U$65,MATCH($C33,CF!$I$11:$I$65,0))/$A$8 -> 4694100.1
C34: Taxation Paid | D34: =INDEX(CF!K$11:K$65,MATCH($C34,CF!$I$11:$I$65,0))/$A$8 -> 0 | E34: =INDEX(CF!L$11:L$65,MATCH($C34,CF!$I$11:$I$65,0))/$A$8 -> 0 | F34: =INDEX(CF!M$11:M$65,MATCH($C34,CF!$I$11:$I$65,0))/$A$8 -> 0 | H34: =C34 -> Taxation Paid | I34: =INDEX(CF!O$11:O$65,MATCH($C34,CF!$I$11:$I$65,0))/$A$8 -> 0 | J34: =INDEX(CF!P$11:P$65,MATCH($C34,CF!$I$11:$I$65,0))/$A$8 -> 0 | K34: =INDEX(CF!Q$11:Q$65,MATCH($C34,CF!$I$11:$I$65,0))/$A$8 -> 0 | M34: =H34 -> Taxation Paid | N34: =INDEX(CF!S$11:S$65,MATCH($C34,CF!$I$11:$I$65,0))/$A$8 -> 0 | O34: =INDEX(CF!T$11:T$65,MATCH($C34,CF!$I$11:$I$65,0))/$A$8 -> 0 | P34: =INDEX(CF!U$11:U$65,MATCH($C34,CF!$I$11:$I$65,0))/$A$8 -> 0
C35: Net Cash Inflow / (Outflow) | D35: =INDEX(CF!K$11:K$65,MATCH($C35,CF!$I$11:$I$65,0))/$A$8 -> 6960221.7 | E35: =INDEX(CF!L$11:L$65,MATCH($C35,CF!$I$11:$I$65,0))/$A$8 -> -238402.53 | F35: =INDEX(CF!M$11:M$65,MATCH($C35,CF!$I$11:$I$65,0))/$A$8 -> 7198624.2 | H35: =C35 -> Net Cash Inflow / (Outflow) | I35: =INDEX(CF!O$11:O$65,MATCH($C35,CF!$I$11:$I$65,0))/$A$8 -> 6960221.7 | J35: =INDEX(CF!P$11:P$65,MATCH($C35,CF!$I$11:$I$65,0))/$A$8 -> -710550.72 | K35: =INDEX(CF!Q$11:Q$65,MATCH($C35,CF!$I$11:$I$65,0))/$A$8 -> 7670772.4 | M35: =H35 -> Net Cash Inflow / (Outflow) | N35: =INDEX(CF!S$11:S$65,MATCH($C35,CF!$I$11:$I$65,0))/$A$8 -> 6960221.7 | O35: =INDEX(CF!T$11:T$65,MATCH($C35,CF!$I$11:$I$65,0))/$A$8 -> 1962735.8 | P35: =INDEX(CF!U$11:U$65,MATCH($C35,CF!$I$11:$I$65,0))/$A$8 -> 4997485.9
C36: Cash End Of Period | D36: =INDEX(CF!K$11:K$65,MATCH($C36,CF!$I$11:$I$65,0))/$A$8 -> 8623723.5 | E36: =INDEX(CF!L$11:L$65,MATCH($C36,CF!$I$11:$I$65,0))/$A$8 -> 3630470.6 | F36: =INDEX(CF!M$11:M$65,MATCH($C36,CF!$I$11:$I$65,0))/$A$8 -> 4993252.8 | H36: =C36 -> Cash End Of Period | I36: =INDEX(CF!O$11:O$65,MATCH($C36,CF!$I$11:$I$65,0))/$A$8 -> 8623723.5 | J36: =INDEX(CF!P$11:P$65,MATCH($C36,CF!$I$11:$I$65,0))/$A$8 -> 3630470.6 | K36: =INDEX(CF!Q$11:Q$65,MATCH($C36,CF!$I$11:$I$65,0))/$A$8 -> 4993252.8 | M36: =H36 -> Cash End Of Period | N36: =INDEX(CF!S$11:S$65,MATCH($C36,CF!$I$11:$I$65,0))/$A$8 -> 8623723.5 | O36: =INDEX(CF!T$11:T$65,MATCH($C36,CF!$I$11:$I$65,0))/$A$8 -> 3630470.6 | P36: =INDEX(CF!U$11:U$65,MATCH($C36,CF!$I$11:$I$65,0))/$A$8 -> 4993252.8
D37: =IF(ROUND(D36*$A$8,0)=ROUND(CF!K63,0),"","Error") | E37: =IF(ROUND(E36*$A$8,0)=ROUND(CF!L63,0),"","Error") | I37: =IF(ROUND(I36*$A$8,0)=ROUND(CF!O63,0),"","Error") | J37: =IF(ROUND(J36*$A$8,0)=ROUND(CF!P63,0),"","Error") | N37: =IF(ROUND(N36*$A$8,0)=ROUND(CF!S63,0),"","Error") | O37: =IF(ROUND(O36*$A$8,0)=ROUND(CF!T63,0),"","Error")
C39: HC | D39: =D6 -> 44531 | H39: =C39 -> HC | I39: =I6 -> Q4-21 | M39: =H39 -> HC | N39: =N6 -> 2021
D40: =D7 -> Actual | E40: =E7 -> Budget | F40: =F7 -> Variance | I40: =I7 -> Actual | J40: =J7 -> Budget | K40: =K7 -> Variance | N40: =N7 -> Actual | O40: =O7 -> Budget | P40: =P7 -> Variance
A41: 22302 | C41: =C15 -> Cost of Sales | D41: =IFERROR(INDEX('P&L'!H$8:H$278,MATCH($A41,'P&L'!$C$8:$C$278,0),),0) -> 0 | E41: =IFERROR(INDEX('P&L'!I$8:I$278,MATCH($A41,'P&L'!$C$8:$C$278,0),),0) -> 0 | F41: =IFERROR(INDEX('P&L'!J$8:J$278,MATCH($A41,'P&L'!$C$8:$C$278,0),),0) -> 0 | H41: =C41 -> Cost of Sales | I41: =IFERROR(INDEX('P&L'!L$8:L$278,MATCH($A41,'P&L'!$C$8:$C$278,0),),0) -> 0 | J41: =IFERROR(INDEX('P&L'!M$8:M$278,MATCH($A41,'P&L'!$C$8:$C$278,0),),0) -> 0 | K41: =IFERROR(INDEX('P&L'!N$8:N$278,MATCH($A41,'P&L'!$C$8:$C$278,0),),0) -> 0 | M41: =H41 -> Cost of Sales | N41: =IFERROR(INDEX('P&L'!P$8:P$278,MATCH($A41,'P&L'!$C$8:$C$278,0),),0) -> 0 | O41: =IFERROR(INDEX('P&L'!Q$8:Q$278,MATCH($A41,'P&L'!$C$8:$C$278,0),),0) -> 0 | P41: =IFERROR(INDEX('P&L'!R$8:R$278,MATCH($A41,'P&L'!$C$8:$C$278,0),),0) -> 0
A42: 23203 | C42: =C19 -> R&D | D42: =IFERROR(INDEX('P&L'!H$8:H$278,MATCH($A42,'P&L'!$C$8:$C$278,0),),0) -> 8 | E42: =IFERROR(INDEX('P&L'!I$8:I$278,MATCH($A42,'P&L'!$C$8:$C$278,0),),0) -> 9 | F42: =IFERROR(INDEX('P&L'!J$8:J$278,MATCH($A42,'P&L'!$C$8:$C$278,0),),0) -> 1 | H42: =C42 -> R&D | I42: =IFERROR(INDEX('P&L'!L$8:L$278,MATCH($A42,'P&L'!$C$8:$C$278,0),),0) -> 8 | J42: =IFERROR(INDEX('P&L'!M$8:M$278,MATCH($A42,'P&L'!$C$8:$C$278,0),),0) -> 9 | K42: =IFERROR(INDEX('P&L'!N$8:N$278,MATCH($A42,'P&L'!$C$8:$C$278,0),),0) -> 1 | M42: =H42 -> R&D | N42: =IFERROR(INDEX('P&L'!P$8:P$278,MATCH($A42,'P&L'!$C$8:$C$278,0),),0) -> 8 | O42: =IFERROR(INDEX('P&L'!Q$8:Q$278,MATCH($A42,'P&L'!$C$8:$C$278,0),),0) -> 9 | P42: =IFERROR(INDEX('P&L'!R$8:R$278,MATCH($A42,'P&L'!$C$8:$C$278,0),),0) -> 1
A43: 23208 | C43: =C20 -> Product | D43: =IFERROR(INDEX('P&L'!H$8:H$278,MATCH($A43,'P&L'!$C$8:$C$278,0),),0) -> 2 | E43: =IFERROR(INDEX('P&L'!I$8:I$278,MATCH($A43,'P&L'!$C$8:$C$278,0),),0) -> 3 | F43: =IFERROR(INDEX('P&L'!J$8:J$278,MATCH($A43,'P&L'!$C$8:$C$278,0),),0) -> 1 | H43: =C43 -> Product | I43: =IFERROR(INDEX('P&L'!L$8:L$278,MATCH($A43,'P&L'!$C$8:$C$278,0),),0) -> 2 | J43: =IFERROR(INDEX('P&L'!M$8:M$278,MATCH($A43,'P&L'!$C$8:$C$278,0),),0) -> 3 | K43: =IFERROR(INDEX('P&L'!N$8:N$278,MATCH($A43,'P&L'!$C$8:$C$278,0),),0) -> 1 | M43: =H43 -> Product | N43: =IFERROR(INDEX('P&L'!P$8:P$278,MATCH($A43,'P&L'!$C$8:$C$278,0),),0) -> 2 | O43: =IFERROR(INDEX('P&L'!Q$8:Q$278,MATCH($A43,'P&L'!$C$8:$C$278,0),),0) -> 3 | P43: =IFERROR(INDEX('P&L'!R$8:R$278,MATCH($A43,'P&L'!$C$8:$C$278,0),),0) -> 1
...

Sheet Financial highlights
A1: =IF(E3="$",1,IF(E3="$k",1000,1000000)) -> 1
A2: Errors in this sheet: | C2: ='P&L'!E2 -> Pocket Pie Studios Ltd.
A3: =COUNTIF(D28:R28,"error")+COUNTIF(D38:R38,"error")+COUNTIF(D51:R51,"error")+COUNTIF(D104:R104,"error") -> 0 | C3: Financial Highlights | E3: $
A4: General errors in file:
A5: ='Actual vs Budget'!A5 -> 5 | C5: Financial highlights | D5: 44197 | E5: 44228 | F5: 44256 | G5: 44287 | H5: 44317 | I5: 44348 | J5: 44378 | K5: 44409 | L5: 44440 | M5: 44470 | N5: 44501 | O5: 44531 | Q5: 2021 YTD
C6: $K | D6: Actual | E6: Actual | F6: Actual | G6: Actual | H6: Actual | I6: Actual | J6: Actual | K6: Actual | L6: Actual | M6: Actual | N6: Actual | O6: Actual | Q6: Actual | R6: Budget
C7: KPI
C8: # of customers
C9: MRR
C10: ARR
C12: P&L Summary
A13: 1 | C13: Revenues | D13: =SUMIFS('P&L'!X$8:X$276,'P&L'!$C$8:$C$276,$A13)/$A$1 -> 0 | E13: =SUMIFS('P&L'!Y$8:Y$276,'P&L'!$C$8:$C$276,$A13)/$A$1 -> 0 | F13: =SUMIFS('P&L'!Z$8:Z$276,'P&L'!$C$8:$C$276,$A13)/$A$1 -> 0 | H13: =SUMIFS('P&L'!AB$8:AB$276,'P&L'!$C$8:$C$276,$A13)/$A$1 -> 0 | I13: =SUMIFS('P&L'!AC$8:AC$276,'P&L'!$C$8:$C$276,$A13)/$A$1 -> 0 | J13: =SUMIFS('P&L'!AD$8:AD$276,'P&L'!$C$8:$C$276,$A13)/$A$1 -> 0 | K13: =SUMIFS('P&L'!AE$8:AE$276,'P&L'!$C$8:$C$276,$A13)/$A$1 -> 0 | L13: =SUMIFS('P&L'!AF$8:AF$276,'P&L'!$C$8:$C$276,$A13)/$A$1 -> 0 | M13: =SUMIFS('P&L'!AG$8:AG$276,'P&L'!$C$8:$C$276,$A13)/$A$1 -> 0 | N13: =SUMIFS('P&L'!AH$8:AH$276,'P&L'!$C$8:$C$276,$A13)/$A$1 -> 0 | O13: =SUMIFS('P&L'!AI$8:AI$276,'P&L'!$C$8:$C$276,$A13)/$A$1 -> 0 | Q13: =F13+I13+L13+O13 -> 0 | R13: =IFERROR(INDEX('P&L'!$Q$8:$Q$278,MATCH($A13,'P&L'!$C$8:$C$278,0)),0)/$A$1 -> 0
A14: 2 | C14: COS | D14: =SUMIFS('P&L'!X$8:X$276,'P&L'!$C$8:$C$276,$A14)/$A$1 -> 0 | E14: =SUMIFS('P&L'!Y$8:Y$276,'P&L'!$C$8:$C$276,$A14)/$A$1 -> 0 | F14: =SUMIFS('P&L'!Z$8:Z$276,'P&L'!$C$8:$C$276,$A14)/$A$1 -> 0 | G14: =SUMIFS('P&L'!AA$8:AA$276,'P&L'!$C$8:$C$276,$A14)/$A$1 -> 0 | H14: =SUMIFS('P&L'!AB$8:AB$276,'P&L'!$C$8:$C$276,$A14)/$A$1 -> 0 | I14: =SUMIFS('P&L'!AC$8:AC$276,'P&L'!$C$8:$C$276,$A14)/$A$1 -> 0 | J14: =SUMIFS('P&L'!AD$8:AD$276,'P&L'!$C$8:$C$276,$A14)/$A$1 -> 0 | K14: =SUMIFS('P&L'!AE$8:AE$276,'P&L'!$C$8:$C$276,$A14)/$A$1 -> 0 | ... O14: =SUMIFS('P&L'!AI$8:AI$276,'P&L'!$C$8:$C$276,$A14)/$A$1 -> 0 | Q14: =IFERROR(INDEX('P&L'!$P$8:$P$278,MATCH($A14,'P&L'!$C$8:$C$278,0)),0)/$A$1 -> 0 | R14: =IFERROR(INDEX('P&L'!$Q$8:$Q$278,MATCH($A14,'P&L'!$C$8:$C$278,0)),0)/$A$1 -> 0
C15: Gross Profit | D15: =D13-D14 -> 0 | E15: =E13-E14 -> 0 | F15: =F13-F14 -> 0 | G15: =G13-G14 -> 0 | H15: =H13-H14 -> 0 | I15: =I13-I14 -> 0 | J15: =J13-J14 -> 0 | K15: =K13-K14 -> 0 | ... O15: =O13-O14 -> 0 | Q15: =Q13-Q14 -> 0 | R15: =R13-R14 -> 0
C16: Gross margin | D16: =IFERROR(+D15/D13,0) -> 0 | E16: =IFERROR(+E15/E13,0) -> 0 | F16: =IFERROR(+F15/F13,0) -> 0 | G16: =IFERROR(+G15/G13,0) -> 0 | H16: =IFERROR(+H15/H13,0) -> 0 | I16: =IFERROR(+I15/I13,0) -> 0 | J16: =IFERROR(+J15/J13,0) -> 0 | K16: =IFERROR(+K15/K13,0) -> 0 | ... O16: =IFERROR(+O15/O13,0) -> 0 | Q16: =IFERROR(+Q15/Q13,0) -> 0 | R16: =IFERROR(+R15/R13,0) -> 0
C17: Operational costs
A18: 11 | C18: =RIGHT(INDEX('P&L'!$E$5:$E$275,MATCH($A18,'P&L'!$C$5:$C$275,0)),LEN(INDEX('P&L'!$E$5:$E$275,MATCH($A18,'P&L'!$C$5:$C$275,0)))-6) -> R&D | D18: =SUMIFS('P&L'!X$8:X$276,'P&L'!$C$8:$C$276,$A18)/$A$1 -> 0 | E18: =SUMIFS('P&L'!Y$8:Y$276,'P&L'!$C$8:$C$276,$A18)/$A$1 -> 0 | F18: =SUMIFS('P&L'!Z$8:Z$276,'P&L'!$C$8:$C$276,$A18)/$A$1 -> 0 | H18: =SUMIFS('P&L'!AB$8:AB$276,'P&L'!$C$8:$C$276,$A18)/$A$1 -> 0 | I18: =SUMIFS('P&L'!AC$8:AC$276,'P&L'!$C$8:$C$276,$A18)/$A$1 -> 0 | J18: =SUMIFS('P&L'!AD$8:AD$276,'P&L'!$C$8:$C$276,$A18)/$A$1 -> 0 | K18: =SUMIFS('P&L'!AE$8:AE$276,'P&L'!$C$8:$C$276,$A18)/$A$1 -> 0 | L18: =SUMIFS('P&L'!AF$8:AF$276,'P&L'!$C$8:$C$276,$A18)/$A$1 -> 0 | M18: =SUMIFS('P&L'!AG$8:AG$276,'P&L'!$C$8:$C$276,$A18)/$A$1 -> 0 | N18: =SUMIFS('P&L'!AH$8:AH$276,'P&L'!$C$8:$C$276,$A18)/$A$1 -> 0 | O18: =SUMIFS('P&L'!AI$8:AI$276,'P&L'!$C$8:$C$276,$A18)/$A$1 -> 669810.02 | Q18: =F18+I18+L18+O18 -> 669810.02 | R18: =IFERROR(INDEX('P&L'!$Q$8:$Q$278,MATCH($A18,'P&L'!$C$8:$C$278,0)),0)/$A$1 -> 654302.04
A19: 12 | C19: =RIGHT(INDEX('P&L'!$E$5:$E$275,MATCH($A19,'P&L'!$C$5:$C$275,0)),LEN(INDEX('P&L'!$E$5:$E$275,MATCH($A19,'P&L'!$C$5:$C$275,0)))-6) -> Product | D19: =SUMIFS('P&L'!X$8:X$276,'P&L'!$C$8:$C$276,$A19)/$A$1 -> 0 | E19: =SUMIFS('P&L'!Y$8:Y$276,'P&L'!$C$8:$C$276,$A19)/$A$1 -> 0 | F19: =SUMIFS('P&L'!Z$8:Z$276,'P&L'!$C$8:$C$276,$A19)/$A$1 -> 0 | H19: =SUMIFS('P&L'!AB$8:AB$276,'P&L'!$C$8:$C$276,$A19)/$A$1 -> 0 | I19: =SUMIFS('P&L'!AC$8:AC$276,'P&L'!$C$8:$C$276,$A19)/$A$1 -> 0 | J19: =SUMIFS('P&L'!AD$8:AD$276,'P&L'!$C$8:$C$276,$A19)/$A$1 -> 0 | K19: =SUMIFS('P&L'!AE$8:AE$276,'P&L'!$C$8:$C$276,$A19)/$A$1 -> 0 | L19: =SUMIFS('P&L'!AF$8:AF$276,'P&L'!$C$8:$C$276,$A19)/$A$1 -> 0 | M19: =SUMIFS('P&L'!AG$8:AG$276,'P&L'!$C$8:$C$276,$A19)/$A$1 -> 0 | N19: =SUMIFS('P&L'!AH$8:AH$276,'P&L'!$C$8:$C$276,$A19)/$A$1 -> 0 | O19: =SUMIFS('P&L'!AI$8:AI$276,'P&L'!$C$8:$C$276,$A19)/$A$1 -> 326761.88 | Q19: =F19+I19+L19+O19 -> 326761.88 | R19: =IFERROR(INDEX('P&L'!$Q$8:$Q$278,MATCH($A19,'P&L'!$C$8:$C$278,0)),0)/$A$1 -> 251033.92
A20: 13 | C20: =RIGHT(INDEX('P&L'!$E$5:$E$275,MATCH($A20,'P&L'!$C$5:$C$275,0)),LEN(INDEX('P&L'!$E$5:$E$275,MATCH($A20,'P&L'!$C$5:$C$275,0)))-6) -> Art | D20: =SUMIFS('P&L'!X$8:X$276,'P&L'!$C$8:$C$276,$A20)/$A$1 -> 0 | E20: =SUMIFS('P&L'!Y$8:Y$276,'P&L'!$C$8:$C$276,$A20)/$A$1 -> 0 | F20: =SUMIFS('P&L'!Z$8:Z$276,'P&L'!$C$8:$C$276,$A20)/$A$1 -> 0 | H20: =SUMIFS('P&L'!AB$8:AB$276,'P&L'!$C$8:$C$276,$A20)/$A$1 -> 0 | I20: =SUMIFS('P&L'!AC$8:AC$276,'P&L'!$C$8:$C$276,$A20)/$A$1 -> 0 | J20: =SUMIFS('P&L'!AD$8:AD$276,'P&L'!$C$8:$C$276,$A20)/$A$1 -> 0 | K20: =SUMIFS('P&L'!AE$8:AE$276,'P&L'!$C$8:$C$276,$A20)/$A$1 -> 0 | L20: =SUMIFS('P&L'!AF$8:AF$276,'P&L'!$C$8:$C$276,$A20)/$A$1 -> 0 | M20: =SUMIFS('P&L'!AG$8:AG$276,'P&L'!$C$8:$C$276,$A20)/$A$1 -> 0 | N20: =SUMIFS('P&L'!AH$8:AH$276,'P&L'!$C$8:$C$276,$A20)/$A$1 -> 0 | O20: =SUMIFS('P&L'!AI$8:AI$276,'P&L'!$C$8:$C$276,$A20)/$A$1 -> 664947.33 | Q20: =F20+I20+L20+O20 -> 664947.33 | R20: =IFERROR(INDEX('P&L'!$Q$8:$Q$278,MATCH($A20,'P&L'!$C$8:$C$278,0)),0)/$A$1 -> 577647.58
A21: 14 | C21: =RIGHT(INDEX('P&L'!$E$5:$E$275,MATCH($A21,'P&L'!$C$5:$C$275,0)),LEN(INDEX('P&L'!$E$5:$E$275,MATCH($A21,'P&L'!$C$5:$C$275,0)))-6) -> Sales Costs | D21: =SUMIFS('P&L'!X$8:X$276,'P&L'!$C$8:$C$276,$A21)/$A$1 -> 0 | E21: =SUMIFS('P&L'!Y$8:Y$276,'P&L'!$C$8:$C$276,$A21)/$A$1 -> 0 | F21: =SUMIFS('P&L'!Z$8:Z$276,'P&L'!$C$8:$C$276,$A21)/$A$1 -> 0 | H21: =SUMIFS('P&L'!AB$8:AB$276,'P&L'!$C$8:$C$276,$A21)/$A$1 -> 0 | I21: =SUMIFS('P&L'!AC$8:AC$276,'P&L'!$C$8:$C$276,$A21)/$A$1 -> 0 | J21: =SUMIFS('P&L'!AD$8:AD$276,'P&L'!$C$8:$C$276,$A21)/$A$1 -> 0 | K21: =SUMIFS('P&L'!AE$8:AE$276,'P&L'!$C$8:$C$276,$A21)/$A$1 -> 0 | L21: =SUMIFS('P&L'!AF$8:AF$276,'P&L'!$C$8:$C$276,$A21)/$A$1 -> 0 | M21: =SUMIFS('P&L'!AG$8:AG$276,'P&L'!$C$8:$C$276,$A21)/$A$1 -> 0 | N21: =SUMIFS('P&L'!AH$8:AH$276,'P&L'!$C$8:$C$276,$A21)/$A$1 -> 0 | O21: =SUMIFS('P&L'!AI$8:AI$276,'P&L'!$C$8:$C$276,$A21)/$A$1 -> 0 | Q21: =F21+I21+L21+O21 -> 0 | R21: =IFERROR(INDEX('P&L'!$Q$8:$Q$278,MATCH($A21,'P&L'!$C$8:$C$278,0)),0)/$A$1 -> 128000
A22: 15 | C22: =RIGHT(INDEX('P&L'!$E$5:$E$275,MATCH($A22,'P&L'!$C$5:$C$275,0)),LEN(INDEX('P&L'!$E$5:$E$275,MATCH($A22,'P&L'!$C$5:$C$275,0)))-6) -> Marketing Costs | D22: =SUMIFS('P&L'!X$8:X$276,'P&L'!$C$8:$C$276,$A22)/$A$1 -> 0 | E22: =SUMIFS('P&L'!Y$8:Y$276,'P&L'!$C$8:$C$276,$A22)/$A$1 -> 0 | F22: =SUMIFS('P&L'!Z$8:Z$276,'P&L'!$C$8:$C$276,$A22)/$A$1 -> 0 | G22: =SUMIFS('P&L'!AA$8:AA$276,'P&L'!$C$8:$C$276,$A22)/$A$1 -> 0 | H22: =SUMIFS('P&L'!AB$8:AB$276,'P&L'!$C$8:$C$276,$A22)/$A$1 -> 0 | I22: =SUMIFS('P&L'!AC$8:AC$276,'P&L'!$C$8:$C$276,$A22)/$A$1 -> 0 | J22: =SUMIFS('P&L'!AD$8:AD$276,'P&L'!$C$8:$C$276,$A22)/$A$1 -> 0 | K22: =SUMIFS('P&L'!AE$8:AE$276,'P&L'!$C$8:$C$276,$A22)/$A$1 -> 0 | ... O22: =SUMIFS('P&L'!AI$8:AI$276,'P&L'!$C$8:$C$276,$A22)/$A$1 -> 6018.94 | Q22: =IFERROR(INDEX('P&L'!$P$8:$P$278,MATCH($A22,'P&L'!$C$8:$C$278,0)),0)/$A$1 -> 6018.94 | R22: =IFERROR(INDEX('P&L'!$Q$8:$Q$278,MATCH($A22,'P&L'!$C$8:$C$278,0)),0)/$A$1 -> 199137.28
A23: 16 | C23: =RIGHT(INDEX('P&L'!$E$5:$E$275,MATCH($A23,'P&L'!$C$5:$C$275,0)),LEN(INDEX('P&L'!$E$5:$E$275,MATCH($A23,'P&L'!$C$5:$C$275,0)))-6) -> G&A | D23: =SUMIFS('P&L'!X$8:X$276,'P&L'!$C$8:$C$276,$A23)/$A$1 -> 0 | E23: =SUMIFS('P&L'!Y$8:Y$276,'P&L'!$C$8:$C$276,$A23)/$A$1 -> 0 | F23: =SUMIFS('P&L'!Z$8:Z$276,'P&L'!$C$8:$C$276,$A23)/$A$1 -> 0 | G23: =SUMIFS('P&L'!AA$8:AA$276,'P&L'!$C$8:$C$276,$A23)/$A$1 -> 0 | H23: =SUMIFS('P&L'!AB$8:AB$276,'P&L'!$C$8:$C$276,$A23)/$A$1 -> 0 | I23: =SUMIFS('P&L'!AC$8:AC$276,'P&L'!$C$8:$C$276,$A23)/$A$1 -> 0 | J23: =SUMIFS('P&L'!AD$8:AD$276,'P&L'!$C$8:$C$276,$A23)/$A$1 -> 0 | K23: =SUMIFS('P&L'!AE$8:AE$276,'P&L'!$C$8:$C$276,$A23)/$A$1 -> 0 | ... O23: =SUMIFS('P&L'!AI$8:AI$276,'P&L'!$C$8:$C$276,$A23)/$A$1 -> 265069.35 | Q23: =IFERROR(INDEX('P&L'!$P$8:$P$278,MATCH($A23,'P&L'!$C$8:$C$278,0)),0)/$A$1 -> 265069.35 | R23: =IFERROR(INDEX('P&L'!$Q$8:$Q$278,MATCH($A23,'P&L'!$C$8:$C$278,0)),0)/$A$1 -> 254084.76
C24: =RIGHT(INDEX('P&L'!$E$5:$E$275,MATCH($A24,'P&L'!$C$5:$C$275,0)),LEN(INDEX('P&L'!$E$5:$E$275,MATCH($A24,'P&L'!$C$5:$C$275,0)))-6) -> #N/A | D24: =SUMIFS('P&L'!X$8:X$276,'P&L'!$C$8:$C$276,$A24)/$A$1 -> 0 | E24: =SUMIFS('P&L'!Y$8:Y$276,'P&L'!$C$8:$C$276,$A24)/$A$1 -> 0 | F24: =SUMIFS('P&L'!Z$8:Z$276,'P&L'!$C$8:$C$276,$A24)/$A$1 -> 0 | G24: =SUMIFS('P&L'!AA$8:AA$276,'P&L'!$C$8:$C$276,$A24)/$A$1 -> 0 | H24: =SUMIFS('P&L'!AB$8:AB$276,'P&L'!$C$8:$C$276,$A24)/$A$1 -> 0 | I24: =SUMIFS('P&L'!AC$8:AC$276,'P&L'!$C$8:$C$276,$A24)/$A$1 -> 0 | J24: =SUMIFS('P&L'!AD$8:AD$276,'P&L'!$C$8:$C$276,$A24)/$A$1 -> 0 | K24: =SUMIFS('P&L'!AE$8:AE$276,'P&L'!$C$8:$C$276,$A24)/$A$1 -> 0 | ... O24: =SUMIFS('P&L'!AI$8:AI$276,'P&L'!$C$8:$C$276,$A24)/$A$1 -> 0 | Q24: =IFERROR(INDEX('P&L'!$P$8:$P$278,MATCH($A24,'P&L'!$C$8:$C$278,0)),0)/$A$1 -> 0 | R24: =IFERROR(INDEX('P&L'!$Q$8:$Q$278,MATCH($A24,'P&L'!$C$8:$C$278,0)),0)/$A$1 -> 0
C25: Total Opex | D25: =SUM(D18:D24) -> 0 | E25: =SUM(E18:E24) -> 0 | F25: =SUM(F18:F24) -> 0 | G25: =SUM(G18:G24) -> 0 | H25: =SUM(H18:H24) -> 0 | I25: =SUM(I18:I24) -> 0 | J25: =SUM(J18:J24) -> 0 | K25: =SUM(K18:K24) -> 0 | ... O25: =SUM(O18:O24) -> 1932607.5 | Q25: =SUM(Q18:Q24) -> 1932607.5 | R25: =SUM(R18:R24) -> 2064205.6
C27: EBITDA | D27: =D15-D25 -> 0 | E27: =E15-E25 -> 0 | F27: =F15-F25 -> 0 | G27: =G15-G25 -> 0 | H27: =H15-H25 -> 0 | I27: =I15-I25 -> 0 | J27: =J15-J25 -> 0 | K27: =K15-K25 -> 0 | ... O27: =O15-O25 -> -1932607.5 | Q27: =Q15-Q25 -> -1932607.5 | R27: =R15-R25 -> -2064205.6
F28: =IF(ROUND(F25*$A$1,0)=ROUND(INDEX('P&L'!$X$249:$AI$249,MATCH(F5,'P&L'!$X$6:$AI$6,0)),0),"","Error") | H28: =IF(ROUND(H25*$A$1,0)=ROUND(INDEX('P&L'!$X$249:$AI$249,MATCH(H5,'P&L'!$X$6:$AI$6,0)),0),"","Error") | I28: =IF(ROUND(I25*$A$1,0)=ROUND(INDEX('P&L'!$X$249:$AI$249,MATCH(I5,'P&L'!$X$6:$AI$6,0)),0),"","Error") | J28: =IF(ROUND(J25*$A$1,0)=ROUND(INDEX('P&L'!$X$249:$AI$249,MATCH(J5,'P&L'!$X$6:$AI$6,0)),0),"","Error") | K28: =IF(ROUND(K25*$A$1,0)=ROUND(INDEX('P&L'!$X$249:$AI$249,MATCH(K5,'P&L'!$X$6:$AI$6,0)),0),"","Error") | L28: =IF(ROUND(L25*$A$1,0)=ROUND(INDEX('P&L'!$X$249:$AI$249,MATCH(L5,'P&L'!$X$6:$AI$6,0)),0),"","Error") | M28: =IF(ROUND(M25*$A$1,0)=ROUND(INDEX('P&L'!$X$249:$AI$249,MATCH(M5,'P&L'!$X$6:$AI$6,0)),0),"","Error") | N28: =IF(ROUND(N25*$A$1,0)=ROUND(INDEX('P&L'!$X$249:$AI$249,MATCH(N5,'P&L'!$X$6:$AI$6,0)),0),"","Error") | O28: =IF(ROUND(O25*$A$1,0)=ROUND(INDEX('P&L'!$X$249:$AI$249,MATCH(O5,'P&L'!$X$6:$AI$6,0)),0),"","Error") | R28: =IF(ROUND(R25*$A$1,0)=ROUND('P&L'!Q249,0),"","Error")
C29: Cash Flow Summary | D29: =D5 -> 44197 | E29: =E5 -> 44228 | F29: =F5 -> 44256 | G29: =G5 -> 44287 | H29: =H5 -> 44317 | I29: =I5 -> 44348 | J29: =J5 -> 44378 | K29: =K5 -> 44409 | ... O29: =O5 -> 44531 | Q29: =Q5 -> 2021 YTD
D30: =D6 -> Actual | E30: =E6 -> Actual | F30: =F6 -> Actual | G30: =G6 -> Actual | H30: =H6 -> Actual | I30: =I6 -> Actual | J30: =J6 -> Actual | K30: =K6 -> Actual | ... O30: =O6 -> Actual | Q30: =Q6 -> Actual | R30: =$R$6 -> Budget
C31: Cash at Beginning of Period | D31: =BS!N13+BS!N14 -> 0 | E31: =BS!O13+BS!O14 -> 0 | F31: =BS!P13+BS!P14 -> 1663501.8 | G31: =INDEX(CF!$Y$61:$AK$61,MATCH(G$29,CF!$Y$7:$AK$7,0))/$A$1 -> 0 | H31: =INDEX(CF!$Y$61:$AK$61,MATCH(H$29,CF!$Y$7:$AK$7,0))/$A$1 -> 0 | I31: =INDEX(CF!$Y$61:$AK$61,MATCH(I$29,CF!$Y$7:$AK$7,0))/$A$1 -> 1663501.8 | J31: =INDEX(CF!$Y$61:$AK$61,MATCH(J$29,CF!$Y$7:$AK$7,0))/$A$1 -> 0 | K31: =INDEX(CF!$Y$61:$AK$61,MATCH(K$29,CF!$Y$7:$AK$7,0))/$A$1 -> 0 | L31: =INDEX(CF!$Y$61:$AK$61,MATCH(L$29,CF!$Y$7:$AK$7,0))/$A$1 -> 1663501.8 | M31: =INDEX(CF!$Y$61:$AK$61,MATCH(M$29,CF!$Y$7:$AK$7,0))/$A$1 -> 0 | N31: =INDEX(CF!$Y$61:$AK$61,MATCH(N$29,CF!$Y$7:$AK$7,0))/$A$1 -> 0 | O31: =L37 -> 1663501.8 | Q31: =CF!S61/$A$1 -> 1663501.8 | R31: =CF!T61/$A$1 -> 1667734.9
C32: Net Operating Cash Flow | D32: =INDEX(CF!$Y$27:$AK$27,MATCH(D$29,CF!$Y$7:$AK$7,0))/$A$1 -> 0 | E32: =INDEX(CF!$Y$27:$AK$27,MATCH(E$29,CF!$Y$7:$AK$7,0))/$A$1 -> 0 | F32: =INDEX(CF!$Y$27:$AK$27,MATCH(F$29,CF!$Y$7:$AK$7,0))/$A$1 -> 0 | G32: =INDEX(CF!$Y$27:$AK$27,MATCH(G$29,CF!$Y$7:$AK$7,0))/$A$1 -> 0 | H32: =INDEX(CF!$Y$27:$AK$27,MATCH(H$29,CF!$Y$7:$AK$7,0))/$A$1 -> 0 | I32: =CF!AE27 -> 0 | J32: =INDEX(CF!$Y$27:$AK$27,MATCH(J$29,CF!$Y$7:$AK$7,0))/$A$1 -> 0 | K32: =INDEX(CF!$Y$27:$AK$27,MATCH(K$29,CF!$Y$7:$AK$7,0))/$A$1 -> 0 | L32: =CF!AH27 -> 0 | M32: =INDEX(CF!$Y$27:$AK$27,MATCH(M$29,CF!$Y$7:$AK$7,0))/$A$1 -> 0 | N32: =INDEX(CF!$Y$27:$AK$27,MATCH(N$29,CF!$Y$7:$AK$7,0))/$A$1 -> 0 | O32: =CF!AK27 -> -1560685.8 | Q32: =F32+I32+L32+O32 -> -1560685.8 | R32: =CF!T27/$A$1 -> -1896076.1
C33: Total Capital Expenditure | D33: =INDEX(CF!$Y$47:$AK$47,MATCH(D$29,CF!$Y$7:$AK$7,0))/$A$1 -> 0 | E33: =INDEX(CF!$Y$47:$AK$47,MATCH(E$29,CF!$Y$7:$AK$7,0))/$A$1 -> 0 | F33: =INDEX(CF!$Y$47:$AK$47,MATCH(F$29,CF!$Y$7:$AK$7,0))/$A$1 -> 0 | G33: =INDEX(CF!$Y$47:$AK$47,MATCH(G$29,CF!$Y$7:$AK$7,0))/$A$1 -> 0 | H33: =INDEX(CF!$Y$47:$AK$47,MATCH(H$29,CF!$Y$7:$AK$7,0))/$A$1 -> 0 | I33: =INDEX(CF!$Y$47:$AK$47,MATCH(I$29,CF!$Y$7:$AK$7,0))/$A$1 -> 0 | J33: =INDEX(CF!$Y$47:$AK$47,MATCH(J$29,CF!$Y$7:$AK$7,0))/$A$1 -> 0 | K33: =INDEX(CF!$Y$47:$AK$47,MATCH(K$29,CF!$Y$7:$AK$7,0))/$A$1 -> 0 | L33: =CF!AH47 -> 0 | M33: =INDEX(CF!$Y$47:$AK$47,MATCH(M$29,CF!$Y$7:$AK$7,0))/$A$1 -> 0 | N33: =INDEX(CF!$Y$47:$AK$47,MATCH(N$29,CF!$Y$7:$AK$7,0))/$A$1 -> 0 | O33: =CF!AK47 -> -106525.99 | Q33: =F33+I33+L33+O33 -> -106525.99 | R33: =CF!T47/$A$1 -> -74521.519
C34: Total Financing | D34: =INDEX(CF!$Y$57:$AK$57,MATCH(D$29,CF!$Y$7:$AK$7,0))/$A$1 -> 0 | E34: =INDEX(CF!$Y$57:$AK$57,MATCH(E$29,CF!$Y$7:$AK$7,0))/$A$1 -> 0 | F34: =INDEX(CF!$Y$57:$AK$57,MATCH(F$29,CF!$Y$7:$AK$7,0))/$A$1 -> 0 | G34: =INDEX(CF!$Y$57:$AK$57,MATCH(G$29,CF!$Y$7:$AK$7,0))/$A$1 -> 0 | H34: =INDEX(CF!$Y$57:$AK$57,MATCH(H$29,CF!$Y$7:$AK$7,0))/$A$1 -> 0 | I34: =INDEX(CF!$Y$57:$AK$57,MATCH(I$29,CF!$Y$7:$AK$7,0))/$A$1 -> 0 | J34: =INDEX(CF!$Y$57:$AK$57,MATCH(J$29,CF!$Y$7:$AK$7,0))/$A$1 -> 0 | K34: =INDEX(CF!$Y$57:$AK$57,MATCH(K$29,CF!$Y$7:$AK$7,0))/$A$1 -> 0 | L34: =CF!AH57 -> 0 | M34: =INDEX(CF!$Y$47:$AK$47,MATCH(M$29,CF!$Y$7:$AK$7,0))/$A$1 -> 0 | N34: =INDEX(CF!$Y$47:$AK$47,MATCH(N$29,CF!$Y$7:$AK$7,0))/$A$1 -> 0 | O34: =CF!AK57 -> 8627433.5 | Q34: =F34+I34+L34+O34 -> 8627433.5 | R34: =CF!T57/$A$1 -> 3933333.3
C35: Taxation Paid | D35: =INDEX(CF!$Y$49:$AK$49,MATCH(D$29,CF!$Y$7:$AK$7,0))/$A$1 -> 0 | E35: =INDEX(CF!$Y$49:$AK$49,MATCH(E$29,CF!$Y$7:$AK$7,0))/$A$1 -> 0 | F35: =INDEX(CF!$Y$49:$AK$49,MATCH(F$29,CF!$Y$7:$AK$7,0))/$A$1 -> 0 | H35: =INDEX(CF!$Y$49:$AK$49,MATCH(H$29,CF!$Y$7:$AK$7,0))/$A$1 -> 0 | I35: =INDEX(CF!$Y$49:$AK$49,MATCH(I$29,CF!$Y$7:$AK$7,0))/$A$1 -> 0 | J35: =INDEX(CF!$Y$49:$AK$49,MATCH(J$29,CF!$Y$7:$AK$7,0))/$A$1 -> 0 | K35: =INDEX(CF!$Y$49:$AK$49,MATCH(K$29,CF!$Y$7:$AK$7,0))/$A$1 -> 0 | L35: =CF!AH49 -> 0 | M35: =INDEX(CF!$Y$49:$AK$49,MATCH(M$29,CF!$Y$7:$AK$7,0))/$A$1 -> 0 | N35: =INDEX(CF!$Y$49:$AK$49,MATCH(N$29,CF!$Y$7:$AK$7,0))/$A$1 -> 0 | O35: =CF!AK49 -> 0 | Q35: =F35+I35+L35+O35 -> 0 | R35: =CF!T49/$A$1 -> 0
C36: Net Cash Inflow / (Outflow) | D36: =INDEX(CF!$Y$59:$AK$59,MATCH(D$29,CF!$Y$7:$AK$7,0))/$A$1 -> 0 | E36: =INDEX(CF!$Y$59:$AK$59,MATCH(E$29,CF!$Y$7:$AK$7,0))/$A$1 -> 0 | F36: =INDEX(CF!$Y$59:$AK$59,MATCH(F$29,CF!$Y$7:$AK$7,0))/$A$1 -> 0 | H36: =INDEX(CF!$Y$59:$AK$59,MATCH(H$29,CF!$Y$7:$AK$7,0))/$A$1 -> 0 | I36: =SUM(I32:I35) -> 0 | J36: =INDEX(CF!$Y$59:$AK$59,MATCH(J$29,CF!$Y$7:$AK$7,0))/$A$1 -> 0 | K36: =INDEX(CF!$Y$59:$AK$59,MATCH(K$29,CF!$Y$7:$AK$7,0))/$A$1 -> 0 | L36: =SUM(L32:L35) -> 0 | M36: =INDEX(CF!$Y$59:$AK$59,MATCH(M$29,CF!$Y$7:$AK$7,0))/$A$1 -> 0 | N36: =INDEX(CF!$Y$59:$AK$59,MATCH(N$29,CF!$Y$7:$AK$7,0))/$A$1 -> 0 | O36: =SUM(O32:O35) -> 6960221.7 | Q36: =SUM(Q32:Q35) -> 6960221.7 | R36: =CF!T59/$A$1 -> 1962735.8
C37: Cash End Of Period | F37: =INDEX(CF!$Y$63:$AK$63,MATCH(F$29,CF!$Y$7:$AK$7,0))/$A$1 -> 1663501.8 | G37: =INDEX(CF!$Y$63:$AK$63,MATCH(G$29,CF!$Y$7:$AK$7,0))/$A$1 -> 0 | H37: =INDEX(CF!$Y$63:$AK$63,MATCH(H$29,CF!$Y$7:$AK$7,0))/$A$1 -> 0 | I37: =I31+I36 -> 1663501.8 | J37: =INDEX(CF!$Y$63:$AK$63,MATCH(J$29,CF!$Y$7:$AK$7,0))/$A$1 -> 0 | K37: =INDEX(CF!$Y$63:$AK$63,MATCH(K$29,CF!$Y$7:$AK$7,0))/$A$1 -> 0 | L37: =L31+L36 -> 1663501.8 | M37: =INDEX(CF!$Y$63:$AK$63,MATCH(M$29,CF!$Y$7:$AK$7,0))/$A$1 -> 0 | N37: =INDEX(CF!$Y$63:$AK$63,MATCH(N$29,CF!$Y$7:$AK$7,0))/$A$1 -> 0 | O37: =O31+O36 -> 8623723.5 | Q37: =Q31+Q36 -> 8623723.5 | R37: =CF!T63/$A$1 -> 3630470.6
F38: =IF(ABS(ROUND(F37*$A$1,0)=ROUND(INDEX(CF!$Z$63:$AK$63,MATCH(F29,CF!$Z$7:$AK$7,0)),0)),"","Error") | G38: =IF(ABS(ROUND(G37*$A$1,0)=ROUND(INDEX(CF!$Z$63:$AK$63,MATCH(G29,CF!$Z$7:$AK$7,0)),0)),"","Error") | H38: =IF(ABS(ROUND(H37*$A$1,0)=ROUND(INDEX(CF!$Z$63:$AK$63,MATCH(H29,CF!$Z$7:$AK$7,0)),0)),"","Error") | I38: =IF(ABS(ROUND(I37*$A$1,0)=ROUND(INDEX(CF!$Z$63:$AK$63,MATCH(I29,CF!$Z$7:$AK$7,0)),0)),"","Error") | J38: =IF(ABS(ROUND(J37*$A$1,0)=ROUND(INDEX(CF!$Z$63:$AK$63,MATCH(J29,CF!$Z$7:$AK$7,0)),0)),"","Error") | K38: =IF(ABS(ROUND(K37*$A$1,0)=ROUND(INDEX(CF!$Z$63:$AK$63,MATCH(K29,CF!$Z$7:$AK$7,0)),0)),"","Error") | M38: =IF(ABS(ROUND(M37*$A$1,0)=ROUND(INDEX(CF!$Z$63:$AK$63,MATCH(M29,CF!$Z$7:$AK$7,0)),0)),"","Error") | N38: =IF(ABS(ROUND(N37*$A$1,0)=ROUND(INDEX(CF!$Z$63:$AK$63,MATCH(N29,CF!$Z$7:$AK$7,0)),0)),"","Error") | O38: =IF(ABS(ROUND(O37*$A$1,0)=ROUND(INDEX(CF!$Z$63:$AK$63,MATCH(O29,CF!$Z$7:$AK$7,0)),0)),"","Error") | R38: =IF(ROUND(R37*$A$1,0)=ROUND(CF!T63,0),"","Error")
C40: HC summary | D40: =D5 -> 44197 | E40: =E5 -> 44228 | F40: =F5 -> 44256 | G40: =G5 -> 44287 | H40: =H5 -> 44317 | I40: =I5 -> 44348 | J40: =J5 -> 44378 | K40: =K5 -> 44409 | ... O40: =O5 -> 44531 | Q40: =Q29 -> 2021 YTD
D41: =D6 -> Actual | E41: =E6 -> Actual | F41: =F6 -> Actual | G41: =G6 -> Actual | H41: =H6 -> Actual | I41: =I6 -> Actual | J41: =J6 -> Actual | K41: =K6 -> Actual | ... O41: =O6 -> Actual | Q41: =Q6 -> Actual | R41: =$R$6 -> Budget
A42: 22302 | C42: =C14 -> COS | F42: =SUMIFS(INDEX('P&L'!$V$8:$AI$278,,MATCH(F$40,'P&L'!$V$6:$AI$6,0)),'P&L'!$C$8:$C$278,$A42) -> 0 | G42: =SUMIFS(INDEX('P&L'!$V$8:$AI$278,,MATCH(G$40,'P&L'!$V$6:$AI$6,0)),'P&L'!$C$8:$C$278,$A42) -> 0 | H42: =SUMIFS(INDEX('P&L'!$V$8:$AI$278,,MATCH(H$40,'P&L'!$V$6:$AI$6,0)),'P&L'!$C$8:$C$278,$A42) -> 0 | I42: =SUMIFS(INDEX('P&L'!$V$8:$AI$278,,MATCH(I$40,'P&L'!$V$6:$AI$6,0)),'P&L'!$C$8:$C$278,$A42) -> 0 | J42: =SUMIFS(INDEX('P&L'!$V$8:$AI$278,,MATCH(J$40,'P&L'!$V$6:$AI$6,0)),'P&L'!$C$8:$C$278,$A42) -> 0 | K42: =SUMIFS(INDEX('P&L'!$V$8:$AI$278,,MATCH(K$40,'P&L'!$V$6:$AI$6,0)),'P&L'!$C$8:$C$278,$A42) -> 0 | L42: =SUMIFS(INDEX('P&L'!$V$8:$AI$278,,MATCH(L$40,'P&L'!$V$6:$AI$6,0)),'P&L'!$C$8:$C$278,$A42) -> 0 | M42: =SUMIFS(INDEX('P&L'!$V$8:$AI$278,,MATCH(M$40,'P&L'!$V$6:$AI$6,0)),'P&L'!$C$8:$C$278,$A42) -> 0 | ... O42: =SUMIFS(INDEX('P&L'!$V$8:$AI$278,,MATCH(O$40,'P&L'!$V$6:$AI$6,0)),'P&L'!$C$8:$C$278,$A42) -> 0 | Q42: =IFERROR(INDEX('P&L'!$P$8:$P$278,MATCH($A42,'P&L'!$C$8:$C$278,0)),0) -> 0 | R42: =IFERROR(INDEX('P&L'!$Q$8:$Q$278,MATCH($A42,'P&L'!$C$8:$C$278,0)),0) -> 0
A43: 23203 | C43: =C18 -> R&D | F43: =SUMIFS(INDEX('P&L'!$V$8:$AI$278,,MATCH(F$40,'P&L'!$V$6:$AI$6,0)),'P&L'!$C$8:$C$278,$A43) -> 0 | G43: =SUMIFS(INDEX('P&L'!$V$8:$AI$278,,MATCH(G$40,'P&L'!$V$6:$AI$6,0)),'P&L'!$C$8:$C$278,$A43) -> 0 | H43: =SUMIFS(INDEX('P&L'!$V$8:$AI$278,,MATCH(H$40,'P&L'!$V$6:$AI$6,0)),'P&L'!$C$8:$C$278,$A43) -> 0 | I43: =SUMIFS(INDEX('P&L'!$V$8:$AI$278,,MATCH(I$40,'P&L'!$V$6:$AI$6,0)),'P&L'!$C$8:$C$278,$A43) -> 0 | J43: =SUMIFS(INDEX('P&L'!$V$8:$AI$278,,MATCH(J$40,'P&L'!$V$6:$AI$6,0)),'P&L'!$C$8:$C$278,$A43) -> 0 | K43: =SUMIFS(INDEX('P&L'!$V$8:$AI$278,,MATCH(K$40,'P&L'!$V$6:$AI$6,0)),'P&L'!$C$8:$C$278,$A43) -> 0 | L43: =SUMIFS(INDEX('P&L'!$V$8:$AI$278,,MATCH(L$40,'P&L'!$V$6:$AI$6,0)),'P&L'!$C$8:$C$278,$A43) -> 0 | M43: =SUMIFS(INDEX('P&L'!$V$8:$AI$278,,MATCH(M$40,'P&L'!$V$6:$AI$6,0)),'P&L'!$C$8:$C$278,$A43) -> 0 | ... O43: =SUMIFS(INDEX('P&L'!$V$8:$AI$278,,MATCH(O$40,'P&L'!$V$6:$AI$6,0)),'P&L'!$C$8:$C$278,$A43) -> 8 | Q43: =IFERROR(INDEX('P&L'!$P$8:$P$278,MATCH($A43,'P&L'!$C$8:$C$278,0)),0) -> 8 | R43: =IFERROR(INDEX('P&L'!$Q$8:$Q$278,MATCH($A43,'P&L'!$C$8:$C$278,0)),0) -> 9
...

Sheet Charts
B2: KPIs:
B22: 43466 | C22: 43466 | D22: 43497 | E22: 43525 | F22: 43556 | G22: 43586 | H22: 43617 | I22: 43647 | J22: 43678 | K22: 43709 | L22: 43739 | M22: 43770 | N22: 43800
B23: # of customers - Actual | C23: ='Financial highlights'!D8 -> 0 | D23: ='Financial highlights'!E8 -> 0 | E23: ='Financial highlights'!F8 -> 0 | F23: ='Financial highlights'!G8 -> 0 | G23: ='Financial highlights'!H8 -> 0 | H23: ='Financial highlights'!I8 -> 0 | I23: ='Financial highlights'!J8 -> 0 | J23: ='Financial highlights'!K8 -> 0 | ... N23: ='Financial highlights'!O8 -> 0
B24: # of customers - Budget
B26: MRR - Actual | C26: ='Financial highlights'!D9 -> 0
B27: MRR - Budget
B29: ARR - Actual | C29: =C26*12 -> 0
B30: ARR - Budget
B34: Financial Highlights:
B56: 43466 | C56: 43466 | D56: 43497 | E56: 43525 | F56: 43556 | G56: 43586 | H56: 43617 | I56: 43647 | J56: 43678 | K56: 43709 | L56: 43739 | M56: 43770 | N56: 43800
B57: Opex - Actual | C57: ='Financial highlights'!D25 -> 0 | D57: ='Financial highlights'!E25 -> 0 | E57: ='Financial highlights'!F25 -> 0 | F57: ='Financial highlights'!G25 -> 0 | G57: ='Financial highlights'!H25 -> 0 | H57: ='Financial highlights'!I25 -> 0 | I57: ='Financial highlights'!J25 -> 0 | J57: ='Financial highlights'!K25 -> 0 | ... N57: ='Financial highlights'!O25 -> 1932607.5
B58: Opex - Budget
B60: EBITDA - Actual | C60: ='Financial highlights'!D27 -> 0 | D60: ='Financial highlights'!E27 -> 0 | E60: ='Financial highlights'!F27 -> 0 | F60: ='Financial highlights'!G27 -> 0 | G60: ='Financial highlights'!H27 -> 0 | H60: ='Financial highlights'!I27 -> 0 | I60: ='Financial highlights'!J27 -> 0 | J60: ='Financial highlights'!K27 -> 0 | ... N60: ='Financial highlights'!O27 -> -1932607.5
B61: EBITDA - Budget
B63: Cost per emp. - Actual (K$) | C63: =IFERROR(('Financial highlights'!D14+'Financial highlights'!D25)/'Financial highlights'!D50,0)/1000 -> 0 | D63: =IFERROR(('Financial highlights'!E14+'Financial highlights'!E25)/'Financial highlights'!E50,0)/1000 -> 0 | E63: =IFERROR(('Financial highlights'!F14+'Financial highlights'!F25)/'Financial highlights'!F50,0)/1000 -> 0 | F63: =IFERROR(('Financial highlights'!G14+'Financial highlights'!G25)/'Financial highlights'!G50,0)/1000 -> 0 | G63: =IFERROR(('Financial highlights'!H14+'Financial highlights'!H25)/'Financial highlights'!H50,0)/1000 -> 0 | H63: =IFERROR(('Financial highlights'!I14+'Financial highlights'!I25)/'Financial highlights'!I50,0)/1000 -> 0 | I63: =IFERROR(('Financial highlights'!J14+'Financial highlights'!J25)/'Financial highlights'!J50,0)/1000 -> 0 | J63: =IFERROR(('Financial highlights'!K14+'Financial highlights'!K25)/'Financial highlights'!K50,0)/1000 -> 0 | ... N63: =IFERROR(('Financial highlights'!O14+'Financial highlights'!O25)/'Financial highlights'!O50,0)/1000 -> 113.6828
B65: Cash End Of Period - Actual | C65: ='Financial highlights'!D37 -> 0 | D65: ='Financial highlights'!E37 -> 0 | E65: ='Financial highlights'!F37 -> 1663501.8 | F65: ='Financial highlights'!G37 -> 0 | G65: ='Financial highlights'!H37 -> 0 | H65: ='Financial highlights'!I37 -> 1663501.8 | I65: ='Financial highlights'!J37 -> 0 | J65: ='Financial highlights'!K37 -> 0 | ... N65: ='Financial highlights'!O37 -> 8623723.5
B66: Cash End Of Period - Budget
B88: * The Opex by type % is calculated as a percentage of the total Opex amount
B89: HC:

Sheet External Reporting Scheme
B1: ='P&L'!E2 -> Pocket Pie Studios Ltd.
B2: CONSOLIDSTED FINANCIAL STATEMENT
B3: AS OF | C3: =month_of_report -> 44531
B7: CONSOLIDATED STATEMENTS OF OPERATIONS
G8: =C3 -> 44531 | I8: ="Q"&ROUNDUP(MONTH(G8)/3,0)&"-"&RIGHT(YEAR(G8),2) -> Q4-21 | K8: YTD
G9: UNAUDITED | I9: UNAUDITED | K9: UNAUDITED
G10: ACTUAL | I10: ACTUAL | K10: ACTUAL
B11: Gross Revenues | G11: ='P&L'!H13 -> 0 | I11: ='P&L'!L13 -> 0 | K11: ='P&L'!P13 -> 0
B12: Cost of goods | G12: ='P&L'!H26 -> 0 | I12: ='P&L'!L26 -> 0 | K12: ='P&L'!P26 -> 0
B13: Net Revenues | G13: =G11-G12 -> 0 | I13: =I11-I12 -> 0 | K13: =K11-K12 -> 0
B15: Operating expenses:
B16: R&D | G16: ='P&L'!H44 -> 669810.02 | I16: ='P&L'!L44 -> 669810.02 | K16: ='P&L'!P44 -> 669810.02
B17: Product | G17: ='P&L'!H61 -> 326761.88 | I17: ='P&L'!L61 -> 326761.88 | K17: ='P&L'!P61 -> 326761.88
B18: Art | G18: ='P&L'!H81 -> 664947.33 | I18: ='P&L'!L81 -> 664947.33 | K18: ='P&L'!P81 -> 664947.33
B19: Sales | G19: ='P&L'!Z99 -> 0 | I19: ='P&L'!L99 -> 0 | K19: ='P&L'!P99 -> 0
B20: Marketing | G20: ='P&L'!H121 -> 6018.94 | I20: ='P&L'!L121 -> 6018.94 | K20: ='P&L'!P121 -> 6018.94
B21: G&A | G21: ='P&L'!H152 -> 265069.35 | I21: ='P&L'!L152 -> 265069.35 | K21: ='P&L'!P152 -> 265069.35
B22: Total OPEX | G22: =SUM(G16:G21) -> 1932607.5 | I22: ='P&L'!L249 -> 1932607.5 | K22: =SUM(K16:K21) -> 1932607.5
B24: Net Loss before finance and Depreciation | G24: =G13-G22 -> -1932607.5 | I24: ='P&L'!L251 -> -1932607.5 | K24: =K13-K22 -> -1932607.5
B25: Financial expenses, net | G25: =-'P&L'!H266 -> -109458.15 | I25: =-'P&L'!L266 -> -109458.15 | K25: =-'P&L'!P266 -> -109458.15
B26: Taxation provision | G26: =-'P&L'!H268 -> 0 | K26: =-'P&L'!P268 -> 0
B27: Amortization of other intangibles
B28: Depreciation of fixed assets | G28: ='P&L'!H254 -> 0 | I28: ='P&L'!L258 -> 0 | K28: ='P&L'!P258 -> 0
B30: Net loss | G30: =G24-G25-G28-G26-G27 -> -1823149.4 | I30: =I24-I25-I28-I26-I27 -> -1823149.4 | K30: =K24-K25-K28-K26-K27 -> -1823149.4
B34: =B1 -> Pocket Pie Studios Ltd.
B35: CONSOLIDATED BALANCE SHEETS
G38: ="As of"&" "&TEXT(G8,"[$-409]MMMM - YYYY") -> As of December - 2021
G39: UNAUDITED
B40: ASSETS | G40: ACTUAL
B42: CURRENT ASSETS:
C43: Cash and cash equivalents | G43: =SUM(BS!J13:J14) -> 6785753.3
C44: Accounts receivables | G44: =BS!J15 -> 0
C45: Prepaid expenses and other current assets | G45: =SUM(BS!J16:J18) -> 36990.88
C47: Total current assets | G47: =SUM(G43:G46) -> 6822744.2
