Workbook
Name __1: #REF!
Name __2: #REF!
Name _2017_Exp: '[1]Report data 2017'!$AG$18:$AG$635
Name _2B_9: #REF!
Name _ACK1: #REF!
Name _ACK2: #REF!
Name _Grp12: #REF!
Name _Grp13: #REF!
Name _Grp14: #REF!
Name _Grp15: #REF!
Name _Grp2: #REF!
Name _Pg1: #REF!
Name _PG10: #REF!
Name _Sch10: '[2]Schedules PL'!#REF!
Name _Sch11: '[2]Schedules PL'!#REF!
Name _Sch12: '[2]Schedules PL'!#REF!
Name _Sch13: '[2]Schedules PL'!#REF!
Name _Sch14: '[2]Schedules PL'!#REF!
Name _Sch15: '[2]Schedules PL'!#REF!
Name _Sch2: '[2]Schedules PL'!#REF!
Name _Sch4: '[2]Schedules PL'!#REF!
Name _Sch5: '[2]Schedules PL'!#REF!
Name _Sch6: '[2]Schedules PL'!#REF!
Name _Sch7: '[2]Schedules PL'!#REF!
Name _Sch8: '[2]Schedules PL'!#REF!
Name _Sch9: '[2]Schedules BS'!#REF!
Name ADTL: [2]BS!$A$1
Name Annexure: #REF!
Name Annexure1: #REF!
Name area1: #REF!
Name area2: #REF!
Name area3: #REF!
Name BABL: [3]TB!#REF!
Name Banks: #REF!
Name Category_List: #REF!
Name COMP: #REF!
Name compu1: #REF!
Name computation: #REF!
Name Continuation: #REF!
Name da: '[4]FORM-16'!#REF!
Name data: #REF!
Name Date: [2]BS!$C$1
Name days: #REF!
Name days_jj: #REF!
Name db: '[4]FORM-16'!#REF!
Name DEP: #REF!
Name Dep: '[1]Report data 2017'!$A$18:$A$635
Name DRUCKBEREI03: #REF!
Name Elim: #REF!
Name endofdoh: 'מאזן בוחן Australia'!#REF!
Name endofdoh: 'מאזן בוחן EUROPE'!$A$516
Name endofdoh: 'מאזן בוחן הודו'!#REF!
Name endofdoh: 'מאזן בוחן צרפת'!#REF!
Name endofdoh: 'מאזן בוחן'!$A$1018
Name Entity: '[1]Report data 2017'!$B$18:$B$635
Name Excel_BuiltIn_Print_Area_5: #REF!
Name Excel_BuiltIn_Print_Area_6: #REF!
Name far: #REF!
Name ga: '[4]FORM-16'!#REF!
Name gb: '[4]FORM-16'!#REF!

Sheet דוחות
A1: Algosec System Ltd | H1: Algosec System Ltd | N1: Algosec System Ltd
P3: רווח והפסד - חברה
J4: מאזן - חברה - פאסיב
C5: ='נתונים לשינוי'!$C$1 -> 44561 | F5: =L5 -> דצמבר 2007 | G5: =F5 -> דצמבר 2007 | L5: דצמבר 2007 | M5: דצמבר 2007 | T5: מחושב לפי ממוצע חודשי X 12
C6: נומינלי | F6: נומינלי | G6: $ | J6: נומינלי | L6: נומינלי | M6: $ | P6: LTD | Q6: LTD | S6: ממוצע חודשי | T6: דוח שנתי משוער
A7: רכוש שוטף | C7: LTD | D7: LTD | H7: התחייבויות שוטפות | J7: LTD | K7: LTD | P7: ₪ | Q7: $ | S7: $ | T7: $
A8: מזומנים ושווי מזומנים | C8: ₪ | D8: $ | H8: אשראי מתאגידים בנקאיים | J8: ₪ | K8: $ | N8: הכנסות בספרים עד 12/08 | R8: =P8/Q8 -> #DIV/0!
A9: מזומנים בש"ח | B9: =IF(C9=0,"",C9/D9) -> 3.1099992 | C9: =ROUND(('מאזן בוחן'!J10),0) -> 5177110 | D9: =ROUND(('מאזן בוחן'!K10),0) -> 1664666 | H9: משיכות יתר | J9: =-ROUND('מאזן בוחן'!J195,0) -> 0 | L9: 275737.65 | M9: 62440.591 | N9: הכרה בהכנסות שנדחו ש.ק. | R9: =P10/Q9 -> #DIV/0!
A10: מזומנים במט"ח | B10: =IF(C10=0,"",C10/D10) -> 3.11 | C10: =ROUND(('מאזן בוחן'!J22),0) -> 12489113 | D10: =ROUND(('מאזן בוחן'!K22),0) -> 4015792 | H10: הלוואות לז"ק- לא צמודות | J10: =ROUND((0),0) -> 0 | K10: =ROUND((0),0) -> 0 | L10: 0 | M10: 0 | N10: דחיית הכנסות השנה | R10: =#REF!/Q10 -> #REF! | S10: לא נעשה על 2008
A11: פקדונות בש"ח | B11: =IF(C11=0,"",C11/D11) | C11: =ROUND(('מאזן בוחן'!J14),0) -> 0 | D11: =ROUND(('מאזן בוחן'!K14),0) -> 0 | J11: =SUM(J9:J10) -> 0 | K11: =SUM(K9:K10) -> 0 | L11: 275737.65 | M11: 62440.591 | N11: סה"כ הכנסות לדוח כספי | P11: =SUM(P8:P10) -> 0 | Q11: =SUM(Q8:Q10) -> 0
A12: פקדונות במט"ח | B12: =IF(C12=0,"",C12/D12) | C12: 0 | D12: 0 | H12: זכאים ויתרות זכות | N12: הכנסות | O12: =IF(P12=0,"",P12/Q12) -> 3.2708073 | P12: =-'מאזן בוחן'!J564 -> 1.4157395e+08 | Q12: =-'מאזן בוחן'!K564 -> 43284099 | S12: =Q12/12 -> 3607008.3 | T12: =S12*12 -> 43284099
A13: סה"כ קופות קטנות | B13: =IF(C13=0,"",C13/D13) | C13: =ROUND(('מאזן בוחן'!J29),0) -> 0 | D13: =ROUND(('מאזן בוחן'!K29),0) -> 0 | H13: ספקים ונותני שירותים | I13: =IF(J13=0,"",J13/K13) -> 3.1099993 | J13: =ROUND((-SUM('מאזן בוחן'!J199:J447)),0) -> 7089940 | K13: =ROUND((-SUM('מאזן בוחן'!K199:K447)),0) -> 2279724 | O13: =IF(P13=0,"",P13/Q13) | S13: =Q13/10 -> 0
B14: =IF(C14=0,"",C14/D14) -> 3.1099998 | C14: =SUM(C9:C13) -> 17666223 | D14: =SUM(D9:D13) -> 5680458 | H14: מוסדות שכר | I14: =IF(J14=0,"",J14/K14) -> 3.1099997 | J14: =ROUND((-'מאזן בוחן'!J464),0) -> 3564523 | K14: =ROUND((-'מאזן בוחן'!K464),0) -> 1146149 | L14: 444746 | M14: 100712 | N14: הוצאות מו"פ | O14: =IF(P14=0,"",P14/Q14) | S14: =Q14/10 -> 0
B15: =IF(C15=0,"",C15/D15) | H15: הפרשה לחופשה | I15: =IF(J15=0,"",J15/K15) -> 3.1099993 | J15: =ROUND((-'מאזן בוחן'!J468),0) -> 5748162 | K15: =ROUND((-'מאזן בוחן'!K468),0) -> 1848284 | L15: 250806 | M15: 56795 | N15: הוצאות שכר | O15: =IF(P15=0,"",P15/Q15) -> 3.2291752 | P15: =ROUND('מאזן בוחן'!J595,0) -> 65829395 | Q15: =ROUND('מאזן בוחן'!K595,0) -> 20385823 | S15: =Q15/12 -> 1698818.6 | T15: =S15*12 -> 20385823
B16: =IF(C16=0,"",C16/D16) | H16: זכאים אחרים | I16: =IF(J16=0,"",J16/K16) | J16: =ROUND((-'מאזן בוחן'!J492),0)+ROUND((-'מאזן בוחן'!J491),0) -> 0 | K16: =ROUND((-'מאזן בוחן'!K492),0)+ROUND((-'מאזן בוחן'!K491),0) -> 0 | N16: אחרות | O16: =IF(P16=0,"",P16/Q16) -> 3.2331617 | P16: =ROUND('מאזן בוחן'!J618,0) -> 7058380 | Q16: =ROUND('מאזן בוחן'!K618,0) -> 2183120 | S16: =Q16/12 -> 181926.67 | T16: =S16*12 -> 2183120
B17: =IF(C17=0,"",C17/D17) | H17: עובדים | I17: =IF(J17=0,"",J17/K17) -> 3.1099996 | J17: =ROUND((-'מאזן בוחן'!J474),0) -> 8524170 | K17: =ROUND((-'מאזן בוחן'!K474),0) -> 2740891 | L17: 249122.97 | M17: 56413.716 | N17: הוצאות פחת | O17: =IF(P17=0,"",P17/Q17) | P17: =ROUND(('מאזן בוחן'!J623),0) -> 0 | Q17: =ROUND(('מאזן בוחן'!K623),0) -> 0 | S17: =Q17/12 -> 0 | T17: =S17*12 -> 0
A18: חייבים ויתרות חובה | B18: =IF(C18=0,"",C18/D18) | H18: הוצאות לשלם | I18: =IF(J18=0,"",J18/K18) -> 3.1100015 | J18: =ROUND((-SUM('מאזן בוחן'!J449:J456)),0) -> 1371803 | K18: =ROUND((-SUM('מאזן בוחן'!K449:K456)),0) -> 441094 | L18: 0 | M18: 0 | N18: פטנטים | O18: =IF(P18=0,"",P18/Q18) | P18: 0 | Q18: 0 | S18: =Q18/12 -> 0 | T18: =S18*12 -> 0
A19: לקוחות | B19: =IF(C19=0,"",C19/D19) -> 3.11 | C19: ='מאזן בוחן'!J75 -> 13916870 | D19: ='מאזן בוחן'!K75 -> 4474877.7 | H19: חברה אם | I19: =IF(J19=0,"",J19/K19) | L19: =ROUND((-'מאזן בוחן'!L505-'מאזן בוחן'!L456),0) -> 0 | M19: =ROUND((-'מאזן בוחן'!M505-'מאזן בוחן'!M456),0) -> 14641424 | N19: הוצאות מו"פ | O19: =IF(P19=0,"",P19/Q19) | P19: =ROUND(('מאזן בוחן'!J627),0) -> 0 | Q19: =ROUND(('מאזן בוחן'!K627),0) -> 0 | S19: =Q19/12 -> 0 | T19: =S19*12 -> 0
H20: הכנסות מראש חברה בת | J20: =-ROUND(SUM('מאזן בוחן'!J490),0) -> 35665055 | K20: =-ROUND(SUM('מאזן בוחן'!K490),0) -> 11467863
A21: מוסדות | B21: =IF(C21=0,"",C21/D21) -> 3.1235921 | C21: =ROUND(('מאזן בוחן'!J123),0) -> 1970996 | D21: =ROUND((ROUND('מאזן בוחן'!K123,0)),0) -> 631003 | H21: הכנסות מראש | J21: =-ROUND(SUM('מאזן בוחן'!J476:J486),0) -> 14833943 | K21: =-ROUND(SUM('מאזן בוחן'!K476:K486),0) -> 4237920 | L21: 1737092 | M21: 393362.72 | N21: אחזקת רכב | O21: =IF(P21=0,"",P21/Q21) | P21: 0 | Q21: 0 | S21: =Q21/12 -> 0 | T21: =S21*12 -> 0
A22: עובדים | B22: =IF(C22=0,"",C22/D22) | C22: =ROUND(('מאזן בוחן'!J126),0) -> 0 | D22: =ROUND((ROUND('מאזן בוחן'!K126,0)),0) -> 0 | I22: =IF(J22=0,"",J22/K22) -> 3.1784552 | J22: =SUM(J13:J21) -> 76797596 | K22: =SUM(K13:K21) -> 24161925 | N22: העמסת הוצאות | O22: =IF(P22=0,"",P22/Q22) -> 3.313031 | P22: ='מאזן בוחן'!J629 -> 6956062 | Q22: ='מאזן בוחן'!K629 -> 2099606.7 | S22: =Q22/12 -> 174967.22 | T22: =S22*12 -> 2099606.7
A23: הוצאות מראש | B23: =IF(C23=0,"",C23/D23) -> 3.3010847 | C23: =ROUND(('מאזן בוחן'!J141),0) -> 2658720 | D23: =ROUND(('מאזן בוחן'!K141),0) -> 805408 | I23: =IF(J23=0,"",J23/K23) | O23: =IF(P23=0,"",P23/Q23) -> 3.2366652 | P23: =SUM(P15:P22) -> 79843837 | Q23: =SUM(Q15:Q22) -> 24668550 | S23: =SUM(S15:S22) -> 2055712.5 | T23: =SUM(T15:T22) -> 24668550
A24: מסים נדחים זמן קצר | B24: =IF(C24=0,"",C24/D24) | H24: סה"כ התחייבויות שוטפות | I24: =IF(J24=0,"",J24/K24) -> 3.1784552 | J24: =J22+J11 -> 76797596 | K24: =K22+K11 -> 24161925 | L24: 2012829.6 | M24: 455803.31 | N24: עלות מכר | O24: =IF(P24=0,"",P24/Q24) | S24: =Q24/10 -> 0
A25: חברת האם | B25: =IF(C25=0,"",C25/D25) -> 3.11 | C25: =('מאזן בוחן'!J501+'מאזן בוחן'!J503) -> -16043024 | D25: =('מאזן בוחן'!K501+'מאזן בוחן'!K503) -> -5158528.6 | I25: =IF(J25=0,"",J25/K25) | N25: שכר ונלוות | O25: =IF(P31=0,"",P31/Q31) -> 3.2756524 | P25: ='מאזן בוחן'!J659 -> 9664382.5 | Q25: ='מאזן בוחן'!K659 -> 2988267.9 | S25: =Q25/12 -> 249022.32 | T25: =S25*12 -> 2988267.9
A26: חברות בנות | B26: =IF(C26=0,"",C26/D26) -> 3.1100295 | C26: ='מאזן בוחן'!J502+'מאזן בוחן'!J504+'מאזן בוחן'!J498+'מאזן בוחן'!J499+'מאזן בוחן'!J500+'מאזן בוחן'!J496+'מאזן בוחן'!J497 -> 52520370 | D26: ='מאזן בוחן'!K502+'מאזן בוחן'!K504+'מאזן בוחן'!K498+'מאזן בוחן'!K499+'מאזן בוחן'!K500+'מאזן בוחן'!K496+'מאזן בוחן'!K497 -> 16887419 | H26: התחיבויות לזמן ארוך- הכנסות מראש ז.א | I26: =IF(J26=0,"",J26/K26) -> 3.1100004 | J26: =-'מאזן בוחן'!J488 -> 10470146 | K26: =-'מאזן בוחן'!K488 -> 3366606 | N26: תמלוגים ועמלות מכירה | P26: =+SUM('מאזן בוחן'!J710:J710) -> 0 | Q26: =+SUM('מאזן בוחן'!K710:K710) -> 0 | S26: =Q26/12 -> 0 | T26: =S26*12 -> 0
B27: =IF(C27=0,"",C27/D27) -> 3.1192389 | C27: =SUM(C19:C26) -> 55023932 | D27: =SUM(D19:D26) -> 17640179 | H27: התחיבויות לזמן ארוך- הכנסות מראש ז.א TP | I27: =IF(J27=0,"",J27/K27) -> 3.11 | J27: =-'מאזן בוחן'!J494 -> 21497741 | K27: =-'מאזן בוחן'!K494 -> 6912456.9 | L27: 8258008.3 | M27: 1870020 | N27: חשבונית בינחברתית | P27: ='מאזן בוחן'!J706 -> 9389680.8 | Q27: ='מאזן בוחן'!K706 -> 2876821.8 | S27: =Q29/12 -> 186308.53 | T27: =S27*12 -> 2235702.4
H28: התחיבויות לזמן ארוך- מיסים | J28: =-'מאזן בוחן'!J507 -> 245221.47 | K28: =-'מאזן בוחן'!K507 -> 78849.346
B29: =IF(C29=0,"",C29/D29) | H29: עתודה לפיצויים | I29: =IF(J29=0,"",J29/K29) -> 3.1099991 | J29: =ROUND((-'מאזן בוחן'!J508),0) -> 5367790 | K29: =ROUND((-'מאזן בוחן'!K508),0) -> 1725978 | N29: אחרות | P29: ='מאזן בוחן'!J708-P27 -> 7470489.3 | Q29: ='מאזן בוחן'!K708-Q27 -> 2235702.4 | S29: =SUM(S25:S27) -> 435330.85 | T29: =SUM(T25:T27) -> 5223970.3
B30: =IF(C30=0,"",C30/D30) | H30: סה"כ התחייבויות ז.א | I30: =IF(J30=0,"",J30/K30) -> 3.11 | J30: =SUM(J26:J29) -> 37580898 | K30: =SUM(K26:K29) -> 12083890 | L30: =SUM(L26:L29) -> 8258008.3 | M30: =SUM(M26:M29) -> 1870020 | N30: העמסת הוצאות | P30: ='מאזן בוחן'!J711 -> 1101733.7 | Q30: ='מאזן בוחן'!K711 -> 333035.2
A31: סה"כ רכוש שוטף | B31: =IF(C31=0,"",C31/D31) -> 3.1169884 | C31: =C27+C14 -> 72690155 | D31: =D27+D14 -> 23320637 | H31: הון עצמי | I31: =IF(J31=0,"",J31/K31) | P31: =SUM(P25:P30) -> 27626286 | Q31: =SUM(Q25:Q30) -> 8433827.3 | S31: =Q32/10 -> 0
B32: =IF(C32=0,"",C32/D32) | H32: הון מניות | I32: =IF(J32=0,"",J32/K32) | L32: 0 | M32: 0 | S32: =Q33/10 -> 0
A33: פקדון לזמן ארוך | B33: =IF(C33=0,"",C33/D33) -> 3.1129797 | C33: =ROUND(('מאזן בוחן'!J153),0)-C37-C38 -> 543695.08 | D33: =ROUND(('מאזן בוחן'!K153),0)-D37-D38 -> 174654.23 | I33: =IF(J33=0,"",J33/K33) | L33: 0 | M33: 0 | N33: הוצאות הנהלה וכלליות | O33: =IF(P33=0,"",P33/Q33) | S33: =Q34/12 -> 12746.25 | T33: =S33*12 -> 152955
B34: =IF(C34=0,"",C34/D34) | H34: קרן הון | I34: =IF(J34=0,"",J34/K34) | L34: 0 | M34: 0 | N34: שרותים מקצועיים | O34: =IF(P34=0,"",P34/Q34) -> 3.209238 | P34: =ROUND(('מאזן בוחן'!J755),0) -> 490869 | Q34: =ROUND(('מאזן בוחן'!K755),0) -> 152955 | S34: =Q35/12 -> 64103.444 | T34: =S34*12 -> 769241.33
A35: רכוש קבוע | B35: =IF(C35=0,"",C35/D35) -> 3.5267315 | C35: =ROUND(('מאזן בוחן'!J182),0) -> 5696814 | D35: =ROUND(('מאזן בוחן'!K182),0) -> 1615324 | I35: =IF(J35=0,"",J35/K35) | L35: -6541461.3 | M35: -1471612 | N35: שכר דירה ואחזקת משרד | O35: =IF(P35=0,"",P35/Q35) -> 3.2516065 | P35: =SUM('מאזן בוחן'!$J$759:$J$762) -> 2501270.1 | Q35: =SUM('מאזן בוחן'!$K$759:$K$762) -> 769241.33 | S35: =Q36/12 -> 463809.67 | T35: =S35*12 -> 5565716
B36: =IF(C36=0,"",C36/D36) | H36: יתרת רווח לתחילת השנה | I36: =IF(J36=0,"",J36/K36) -> 3.2094039 | J36: =-SUM('מאזן בוחן'!J523) -> -19946063 | K36: =-SUM('מאזן בוחן'!K523) -> -6214880.9 | L36: =E40-L24-L30-L32-L34-L35-L27-L33 -> -11987385 | M36: =F40-M24-M30-M32-M34-M35-M27-M33 -> -2724231.3 | N36: הוצאות שכר | O36: =IF(P36=0,"",P36/Q36) -> 3.2355772 | P36: =ROUND(('מאזן בוחן'!J746),0) -> 18008304 | Q36: =ROUND(('מאזן בוחן'!K746),0) -> 5565716 | S36: =Q37/12 -> 0 | T36: =S36*12 -> 0
A37: יעודה לפיצויים | B37: =IF(C37=0,"",C37/D37) -> 3.11 | C37: ='מאזן בוחן'!J148 -> 786662 | D37: ='מאזן בוחן'!K148 -> 252945.98 | H37: רווח(הפסד) השנה | I37: =IF(J37=0,"",J37/K37) -> 3.1247894 | J37: =P65 -> -13597399 | K37: =Q65 -> -4351460.8 | N37: אחזקת רכב | O37: =IF(P37=0,"",P37/Q37) | P37: =ROUND(('מאזן בוחן'!J859),0) -> 0 | Q37: =ROUND(('מאזן בוחן'!K859),0) -> 0 | S37: =Q38/12 -> 55628.135 | T37: =S37*12 -> 667537.62
A38: הוצ' מראש זמן ארוך | B38: =IF(C38=0,"",C38/D38) -> 3.4963225 | C38: ='מאזן בוחן'!J149 -> 25997.92 | D38: ='מאזן בוחן'!K149 -> 7435.79 | I38: =IF(J38=0,"",J38/K38) -> 3.1745577 | J38: =SUM(J32:J37) -> -33543461 | K38: =SUM(K32:K37) -> -10566342 | N38: ארוח מתנות וכיבודים | O38: =IF(P38=0,"",P38/Q38) -> 3.2195802 | P38: ='מאזן בוחן'!J866-P40 -> 2149190.9 | Q38: ='מאזן בוחן'!K866-Q40 -> 667537.62 | S38: =Q39/12 -> 1367.5867 | T38: =S38*12 -> 16411.04
A39: מסים נדחים זמן ארוך וחייבית אחרים | B39: =IF(C39=0,"",C39/D39) -> 3.5390288 | C39: =ROUND(('מאזן בוחן'!J188),0) -> 1091709 | D39: =ROUND(('מאזן בוחן'!K188),0) -> 308477 | I39: =IF(J39=0,"",J39/K39) | N39: נסיעות לחו"ל | O39: =IF(P39=0,"",P39/Q39) -> 3.1945745 | P39: =SUM('מאזן בוחן'!J817:J836) -> 52426.29 | Q39: =SUM('מאזן בוחן'!K817:K836) -> 16411.04 | S39: =Q40/12 -> 0 | T39: =S39*12 -> 0
A40: סך הכל אקטיב | B40: =IF(C40=0,"",C40/D40) -> 3.1478462 | C40: =C35+C31+C37+C39+C33+C38 -> 80835033 | D40: =D35+D31+D37+D39+D33+D38 -> 25679474 | H40: סך הכל פאסיב | I40: =IF(J40=0,"",J40/K40) -> 3.1478462 | J40: =J24+J30+J38 -> 80835033 | K40: =K24+K30+K38 -> 25679474 | L40: 3743484.7 | M40: 857406.26 | N40: ארוח חו"ל | O40: =IF(P40=0,"",P40/Q40) | P40: =ROUND(('מאזן בוחן'!J865),0) -> 0 | Q40: =ROUND(('מאזן בוחן'!K865),0) -> 0 | S40: =Q41/12 -> 0 | T40: =S40*12 -> 0
B41: =IF(C41=0,"",C41/D41) | J41: =J40-C40 -> -0.29910055 | K41: =K40-D40 -> -0.28108458 | L41: 0 | M41: 0 | O41: =IF(P41=0,"",P41/Q41) | S41: =Q42/12 -> 42947.5 | T41: =S41*12 -> 515370
...

Sheet מאזן בוחן
E1: =E1010 -> 1.3969839e-08 | F1: =F1010/2 -> 0 | G1: =G1010/2 -> 0 | H1: =H1010/2 -> 0 | I1: =I1010/2 -> 0 | J1: =J1010 -> 1.9557774e-08 | K1: =K1010 -> -4.1909516e-09 | M1: =M1010 -> 0
B2: Algosec System Ltd | M2: שע"ח סוף תקופה | N2: ='נתונים לשינוי'!B7 -> 3.11
E3: ='נתונים לשינוי'!C1 -> 44561 | M3: שע"ח ממוצע | N3: ='נתונים לשינוי'!D8 -> 3.2293
E4: NIS | J4: NIS | K4: USD | M4: USD | N4: Rates
E5: יתרה לפי | F5: פקודות | G5: פקודות | H5: פקודות | I5: פקודות | J5: יתרה לאחר | K5: יתרה לאחר | M5: יתרה לפי
D6: סעיף | E6: מאזן | F6: נוספות | G6: נוספות | H6: נוספות | I6: נוספות | J6: נומינלי | K6: דולרי | M6: מאזן
E7: בוחן | F7: ח'(ז') | G7: ח'(ז') | H7: 'ח | I7: ('ז) | J7: ח'(ז') | K7: ח'(ז') | M7: בוחן | AB7: 01/2021 | AC7: 02/2021 | AD7: 03/2021 | AE7: 04/2021 | AF7: 05/2021 | AG7: 06/2021 | AH7: 07/2021 | AI7: 08/2021 | AJ7: 09/2021 | AK7: 10/2021 | AL7: 11/2021 | AM7: 12/2021
D8: Cash & Cash Equivalents
B9: 100.בנקים ומזומנים | C9: 1000020 | D9: בנק לאומי 522600/83 עו"ש שקל | E9: =VLOOKUP(C9,'פקודות נוספות'!$D$274:$F$797,3,0) -> 5177110 | F9: =SUMIF('פקודות נוספות'!C:C,C:C,'פקודות נוספות'!E:E) -> 0 | J9: =SUM(E9:I9) -> 5177110 | K9: =M9+SUMIF('פקודות נוספות'!C:C,'מאזן בוחן'!C9,'פקודות נוספות'!F:F) -> 1664665.6 | M9: =VLOOKUP(C9,'פקודות נוספות'!$D$273:$G$797,4,0) -> 1664665.6 | N9: =IF(K9=0,"-",J9/K9) -> 3.11
D10: סה"כ מזומנים בש"ח | E10: =SUM(E9:E9) -> 5177110 | F10: =SUM(F9:F9) -> 0 | G10: =SUM(G9:G9) -> 0 | H10: =SUM(H9:H9) -> 0 | I10: =SUM(I9:I9) -> 0 | J10: =SUM(J9:J9) -> 5177110 | K10: =SUM(K9:K9) -> 1664665.6 | M10: =SUM(M9:M9) -> 1664665.6 | N10: =IF(K10=0,"-",J10/K10) -> 3.11
D14: סה"כ פקדונות בש"ח | E14: =SUM(E11:E13) -> 0 | F14: =SUM(F11:F13) -> 0 | G14: =SUM(G11:G13) -> 0 | H14: =SUM(H11:H13) -> 0 | I14: =SUM(I11:I13) -> 0 | J14: =SUM(J11:J13) -> 0 | K14: =SUM(K11:K13) -> 0 | M14: =SUM(M11:M13) -> 0
B15: 100.בנקים ומזומנים | C15: 1000021 | D15: בנק לאומי דולר 522600/83 $ | E15: =IFERROR(VLOOKUP(C15,'פקודות נוספות'!$D$274:$F$797,3,0),0) -> 7928899 | F15: =SUMIF('פקודות נוספות'!C:C,C:C,'פקודות נוספות'!E:E) -> 0 | J15: =SUM(E15:I15) -> 7928899 | K15: =M15+SUMIF('פקודות נוספות'!C:C,'מאזן בוחן'!C15,'פקודות נוספות'!F:F) -> 2549485.2 | M15: =IFERROR(VLOOKUP(C15,'פקודות נוספות'!$D$273:$G$797,4,0),0) -> 2549485.2 | N15: =IF(K15=0,"-",J15/K15) -> 3.11
B16: 100.בנקים ומזומנים | C16: 1000024 | D16: בנק לאומי ליש"ט 522600/83 | E16: =IFERROR(VLOOKUP(C16,'פקודות נוספות'!$D$274:$F$797,3,0),0) -> 2942170 | F16: =SUMIF('פקודות נוספות'!C:C,C:C,'פקודות נוספות'!E:E) -> 0 | J16: =SUM(E16:I16) -> 2942170 | K16: =M16+SUMIF('פקודות נוספות'!C:C,'מאזן בוחן'!C16,'פקודות נוספות'!F:F) -> 946035.37 | L16: =J16/'נתונים לשינוי'!$C$20-700000 -> 0 | M16: =IFERROR(VLOOKUP(C16,'פקודות נוספות'!$D$273:$G$797,4,0),0) -> 946035.37 | N16: =IF(K16=0,"-",J16/K16) -> 3.11
B17: 100.בנקים ומזומנים | C17: 1000022 | D17: בנק לאומי ארה"ב חשבון 0768660918 | E17: =IFERROR(VLOOKUP(C17,'פקודות נוספות'!$D$274:$F$797,3,0),0) -> 1092819.3 | F17: =SUMIF('פקודות נוספות'!C:C,C:C,'פקודות נוספות'!E:E) -> 0 | J17: =SUM(E17:I17) -> 1092819.3 | K17: =M17+SUMIF('פקודות נוספות'!C:C,'מאזן בוחן'!C17,'פקודות נוספות'!F:F) -> 351388.83 | M17: =IFERROR(VLOOKUP(C17,'פקודות נוספות'!$D$273:$G$797,4,0),0) -> 351388.83 | N17: =IF(K17=0,"-",J17/K17) -> 3.11
B18: 100.בנקים ומזומנים | C18: 1000023 | D18: בנק לאומי יורו 522600/83 | E18: =IFERROR(VLOOKUP(C18,'פקודות נוספות'!$D$274:$F$797,3,0),0) -> 524796.36 | F18: =SUMIF('פקודות נוספות'!C:C,C:C,'פקודות נוספות'!E:E) -> 0 | J18: =SUM(E18:I18) -> 524796.36 | K18: =M18+SUMIF('פקודות נוספות'!C:C,'מאזן בוחן'!C18,'פקודות נוספות'!F:F) -> 168744.81 | L18: =J18/'נתונים לשינוי'!$C$21-149094 -> 0.11062814 | M18: =IFERROR(VLOOKUP(C18,'פקודות נוספות'!$D$273:$G$797,4,0),0) -> 168744.81 | N18: =IF(K18=0,"-",J18/K18) -> 3.11
B19: 100.בנקים ומזומנים | C19: 10010 | D19: בנק לאומי דולר אוסטרלי | E19: =IFERROR(VLOOKUP(C19,'פקודות נוספות'!$D$274:$F$797,3,0),0) -> 0 | F19: =SUMIF('פקודות נוספות'!C:C,C:C,'פקודות נוספות'!E:E) -> 0 | J19: =SUM(E19:I19) -> 0 | K19: =M19+SUMIF('פקודות נוספות'!C:C,'מאזן בוחן'!C19,'פקודות נוספות'!F:F) -> 0 | L19: =K19/'נתונים לשינוי'!C23*'נתונים לשינוי'!C22-0 -> 0 | M19: =IFERROR(VLOOKUP(C19,'פקודות נוספות'!$D$273:$G$797,4,0),0) -> 0 | N19: =IF(K19=0,"-",J19/K19) -> -
B20: 100.בנקים ומזומנים | C20: 1000030 | D20: קופה קטנה משרד | E20: =IFERROR(VLOOKUP(C20,'פקודות נוספות'!$D$274:$F$797,3,0),0) -> 428.02 | F20: =SUMIF('פקודות נוספות'!C:C,C:C,'פקודות נוספות'!E:E) -> 0 | J20: =SUM(E20:I20) -> 428.02 | K20: =M20+SUMIF('פקודות נוספות'!C:C,'מאזן בוחן'!C20,'פקודות נוספות'!F:F) -> 137.63 | L20: =428-J20 -> -0.02 | M20: =IFERROR(VLOOKUP(C20,'פקודות נוספות'!$D$273:$G$797,4,0),0) -> 137.63 | N20: =IF(K20=0,"-",J20/K20) -> 3.1099324
D22: סה"כ מזומנים במט"ח | E22: =SUM(E15:E21) -> 12489113 | F22: =SUM(F15:F21) -> 0 | G22: =SUM(G15:G21) -> 0 | H22: =SUM(H15:H21) -> 0 | I22: =SUM(I15:I21) -> 0 | J22: =SUM(J15:J21) -> 12489113 | K22: =SUM(K15:K21) -> 4015791.8 | M22: =SUM(M15:M21) -> 4015791.8
D26: סה"כ פקדונות במט"ח | E26: =SUM(E24:E25) -> 0 | F26: =SUM(F24:F25) -> 0 | G26: =SUM(G24:G25) -> 0 | H26: =SUM(H24:H25) -> 0 | I26: =SUM(I24:I25) -> 0 | J26: =SUM(J24:J25) -> 0 | K26: =SUM(K24:K25) -> 0 | M26: =SUM(M24:M25) -> 0
D29: סה"כ קופות קטנות | E29: =SUM(E28:E28) -> 0 | F29: =SUM(F28:F28) -> 0 | G29: =SUM(G28:G28) -> 0 | H29: =SUM(H28:H28) -> 0 | I29: =SUM(I28:I28) -> 0 | J29: =SUM(J28:J28) -> 0 | K29: =SUM(K28:K28) -> 0 | M29: =SUM(M28:M28) -> 0
D31: סה"כ מזומנים וש"מ | E31: =E29+E26+E22+E14+E10 -> 17666223 | F31: =F29+F26+F22+F14+F10 -> 0 | G31: =G29+G26+G22+G14+G10 -> 0 | H31: =H29+H26+H22+H14+H10 -> 0 | I31: =I29+I26+I22+I14+I10 -> 0 | J31: =J29+J26+J22+J14+J10 -> 17666223 | K31: =K29+K26+K22+K14+K10 -> 5680457.4 | M31: =M29+M26+M22+M14+M10 -> 5680457.4
D33: לקוחות
B35: 130.לקוחות ILS | C35: 207978 | D35: Security4IT | E35: =IFERROR(VLOOKUP(C35,'פקודות נוספות'!$D$274:$F$797,3,0),0) -> 0 | F35: =SUMIF('פקודות נוספות'!C:C,C:C,'פקודות נוספות'!E:E) -> 0 | J35: =SUM(E35:I35) -> 0 | K35: =M35+SUMIF('פקודות נוספות'!C:C,'מאזן בוחן'!C35,'פקודות נוספות'!F:F) -> 0 | M35: =IFERROR(VLOOKUP(C35,'פקודות נוספות'!$D$273:$G$797,4,0),0) -> 0 | N35: =IF(K35=0,"-",J35/K35) -> -
B36: 130.לקוחות ILS | C36: 201267 | D36: Bezeq Intl | E36: =IFERROR(VLOOKUP(C36,'פקודות נוספות'!$D$274:$F$797,3,0),0) -> 267932.14 | F36: =SUMIF('פקודות נוספות'!C:C,C:C,'פקודות נוספות'!E:E) -> 0 | J36: =SUM(E36:I36) -> 267932.14 | K36: =M36+SUMIF('פקודות נוספות'!C:C,'מאזן בוחן'!C36,'פקודות נוספות'!F:F) -> 86151.81 | M36: =IFERROR(VLOOKUP(C36,'פקודות נוספות'!$D$273:$G$797,4,0),0) -> 86151.81 | N36: =IF(K36=0,"-",J36/K36) -> 3.1100001
B37: 130.לקוחות ILS | C37: 209280 | D37: TrustNet | E37: =IFERROR(VLOOKUP(C37,'פקודות נוספות'!$D$274:$F$797,3,0),0) -> 82957.7 | F37: =SUMIF('פקודות נוספות'!C:C,C:C,'פקודות נוספות'!E:E) -> 0 | J37: =SUM(E37:I37) -> 82957.7 | K37: =M37+SUMIF('פקודות נוספות'!C:C,'מאזן בוחן'!C37,'פקודות נוספות'!F:F) -> 26674.5 | M37: =IFERROR(VLOOKUP(C37,'פקודות נוספות'!$D$273:$G$797,4,0),0) -> 26674.5 | N37: =IF(K37=0,"-",J37/K37) -> 3.1100002
B38: 130.לקוחות ILS | C38: 226550 | D38: Perion Solution Co., Ltd | E38: =IFERROR(VLOOKUP(C38,'פקודות נוספות'!$D$274:$F$797,3,0),0) -> 99271.2 | F38: =SUMIF('פקודות נוספות'!C:C,C:C,'פקודות נוספות'!E:E) -> 0 | J38: =SUM(E38:I38) -> 99271.2 | K38: =M38+SUMIF('פקודות נוספות'!C:C,'מאזן בוחן'!C38,'פקודות נוספות'!F:F) -> 31920 | M38: =IFERROR(VLOOKUP(C38,'פקודות נוספות'!$D$273:$G$797,4,0),0) -> 31920 | N38: =IF(K38=0,"-",J38/K38) -> 3.11
B39: 131.לקוחות $ | C39: 206364 | D39: ScanSource Brasil Distribuidora de Tecnologias L | E39: =IFERROR(VLOOKUP(C39,'פקודות נוספות'!$D$274:$F$797,3,0),0) -> 30135.9 | F39: =SUMIF('פקודות נוספות'!C:C,C:C,'פקודות נוספות'!E:E) -> 0 | J39: =SUM(E39:I39) -> 30135.9 | K39: =M39+SUMIF('פקודות נוספות'!C:C,'מאזן בוחן'!C39,'פקודות נוספות'!F:F) -> 9690 | M39: =IFERROR(VLOOKUP(C39,'פקודות נוספות'!$D$273:$G$797,4,0),0) -> 9690 | N39: =IF(K39=0,"-",J39/K39) -> 3.11
B40: 131.לקוחות $ | C40: 231045 | D40: Tech Mahindra (Singapore) Pte Ltd | E40: =IFERROR(VLOOKUP(C40,'פקודות נוספות'!$D$274:$F$797,3,0),0) -> 1754002.7 | F40: =SUMIF('פקודות נוספות'!C:C,C:C,'פקודות נוספות'!E:E) -> 0 | J40: =SUM(E40:I40) -> 1754002.7 | K40: =M40+SUMIF('פקודות נוספות'!C:C,'מאזן בוחן'!C40,'פקודות נוספות'!F:F) -> 563988 | M40: =IFERROR(VLOOKUP(C40,'פקודות נוספות'!$D$273:$G$797,4,0),0) -> 563988 | N40: =IF(K40=0,"-",J40/K40) -> 3.11
B41: 130.לקוחות ILS | C41: 201599 | D41: Bynet Data Communications ltd | E41: =IFERROR(VLOOKUP(C41,'פקודות נוספות'!$D$274:$F$797,3,0),0) -> 23153.27 | F41: =SUMIF('פקודות נוספות'!C:C,C:C,'פקודות נוספות'!E:E) -> 0 | J41: =SUM(E41:I41) -> 23153.27 | K41: =M41+SUMIF('פקודות נוספות'!C:C,'מאזן בוחן'!C41,'פקודות נוספות'!F:F) -> 7444.78 | M41: =IFERROR(VLOOKUP(C41,'פקודות נוספות'!$D$273:$G$797,4,0),0) -> 7444.78 | N41: =IF(K41=0,"-",J41/K41) -> 3.1100006
B42: 130.לקוחות ILS | C42: 217664 | D42: 10Secure Infinity Information Security Ltd. | E42: =IFERROR(VLOOKUP(C42,'פקודות נוספות'!$D$274:$F$797,3,0),0) -> 22330.62 | F42: =SUMIF('פקודות נוספות'!C:C,C:C,'פקודות נוספות'!E:E) -> 0 | J42: =SUM(E42:I42) -> 22330.62 | K42: =M42+SUMIF('פקודות נוספות'!C:C,'מאזן בוחן'!C42,'פקודות נוספות'!F:F) -> 7180.26 | M42: =IFERROR(VLOOKUP(C42,'פקודות נוספות'!$D$273:$G$797,4,0),0) -> 7180.26 | N42: =IF(K42=0,"-",J42/K42) -> 3.1100016
B43: 130.לקוחות ILS | C43: 232189 | D43: Exclusive Networks Singapore | E43: =IFERROR(VLOOKUP(C43,'פקודות נוספות'!$D$274:$F$797,3,0),0) -> 429804.55 | F43: =SUMIF('פקודות נוספות'!C:C,C:C,'פקודות נוספות'!E:E) -> 0 | J43: =SUM(E43:I43) -> 429804.55 | K43: =M43+SUMIF('פקודות נוספות'!C:C,'מאזן בוחן'!C43,'פקודות נוספות'!F:F) -> 138200.82 | M43: =IFERROR(VLOOKUP(C43,'פקודות נוספות'!$D$273:$G$797,4,0),0) -> 138200.82 | N43: =IF(K43=0,"-",J43/K43) -> 3.11 | O43: Waiting for payment confirmation
B44: 131.לקוחות $ | C44: 206331 | D44: Netpoleon Solutions Pte Ltd | E44: =IFERROR(VLOOKUP(C44,'פקודות נוספות'!$D$274:$F$797,3,0),0) -> 29382.38 | F44: =SUMIF('פקודות נוספות'!C:C,C:C,'פקודות נוספות'!E:E) -> 0 | J44: =SUM(E44:I44) -> 29382.38 | K44: =M44+SUMIF('פקודות נוספות'!C:C,'מאזן בוחן'!C44,'פקודות נוספות'!F:F) -> 9447.71 | M44: =IFERROR(VLOOKUP(C44,'פקודות נוספות'!$D$273:$G$797,4,0),0) -> 9447.71 | N44: =IF(K44=0,"-",J44/K44) -> 3.1100002
B45: 130.לקוחות ILS | C45: 232025 | D45: iValue InfoSolutions Pvt Ltd. - Singapore Branch | E45: =IFERROR(VLOOKUP(C45,'פקודות נוספות'!$D$274:$F$797,3,0),0) -> 67919.2 | F45: =SUMIF('פקודות נוספות'!C:C,C:C,'פקודות נוספות'!E:E) -> 0 | J45: =SUM(E45:I45) -> 67919.2 | K45: =M45+SUMIF('פקודות נוספות'!C:C,'מאזן בוחן'!C45,'פקודות נוספות'!F:F) -> 21838.97 | M45: =IFERROR(VLOOKUP(C45,'פקודות נוספות'!$D$273:$G$797,4,0),0) -> 21838.97 | N45: =IF(K45=0,"-",J45/K45) -> 3.1100002
B46: 131.לקוחות $ | C46: 202339 | D46: Contacta Seguranca em Conectividade LTDA | E46: =IFERROR(VLOOKUP(C46,'פקודות נוספות'!$D$274:$F$797,3,0),0) -> 35507.8 | F46: =SUMIF('פקודות נוספות'!C:C,C:C,'פקודות נוספות'!E:E) -> 0 | J46: =SUM(E46:I46) -> 35507.8 | K46: =M46+SUMIF('פקודות נוספות'!C:C,'מאזן בוחן'!C46,'פקודות נוספות'!F:F) -> 11417.3 | M46: =IFERROR(VLOOKUP(C46,'פקודות נוספות'!$D$273:$G$797,4,0),0) -> 11417.3 | N46: =IF(K46=0,"-",J46/K46) -> 3.1099997
B47: 131.לקוחות $ | C47: 209952 | D47: Westcon Solutions China | E47: =IFERROR(VLOOKUP(C47,'פקודות נוספות'!$D$274:$F$797,3,0),0) -> 0 | F47: =SUMIF('פקודות נוספות'!C:C,C:C,'פקודות נוספות'!E:E) -> 0 | J47: =SUM(E47:I47) -> 0 | K47: =M47+SUMIF('פקודות נוספות'!C:C,'מאזן בוחן'!C47,'פקודות נוספות'!F:F) -> 0 | M47: =IFERROR(VLOOKUP(C47,'פקודות נוספות'!$D$273:$G$797,4,0),0) -> 0 | N47: =IF(K47=0,"-",J47/K47) -> -
B48: 131.לקוחות $ | C48: 202629 | D48: Datalink Business Solutions Ltd. | E48: =IFERROR(VLOOKUP(C48,'פקודות נוספות'!$D$274:$F$797,3,0),0) -> 0 | F48: =SUMIF('פקודות נוספות'!C:C,C:C,'פקודות נוספות'!E:E) -> 0 | J48: =SUM(E48:I48) -> 0 | K48: =M48+SUMIF('פקודות נוספות'!C:C,'מאזן בוחן'!C48,'פקודות נוספות'!F:F) -> 0 | M48: =IFERROR(VLOOKUP(C48,'פקודות נוספות'!$D$273:$G$797,4,0),0) -> 0 | N48: =IF(K48=0,"-",J48/K48) -> -
B49: 131.לקוחות $ | C49: 209224 | D49: Exclusive Networks Asia Pte Ltd | E49: =IFERROR(VLOOKUP(C49,'פקודות נוספות'!$D$274:$F$797,3,0),0) -> 178617.63 | F49: =SUMIF('פקודות נוספות'!C:C,C:C,'פקודות נוספות'!E:E) -> 0 | J49: =SUM(E49:I49) -> 178617.63 | K49: =M49+SUMIF('פקודות נוספות'!C:C,'מאזן בוחן'!C49,'פקודות נוספות'!F:F) -> 57433.32 | M49: =IFERROR(VLOOKUP(C49,'פקודות נוספות'!$D$273:$G$797,4,0),0) -> 57433.32 | N49: =IF(K49=0,"-",J49/K49) -> 3.1100001
B50: 130.לקוחות ILS | C50: 208844 | D50: Tech Mahindra Ltd. | E50: =IFERROR(VLOOKUP(C50,'פקודות נוספות'!$D$274:$F$797,3,0),0) -> 0 | F50: =SUMIF('פקודות נוספות'!C:C,C:C,'פקודות נוספות'!E:E) -> 0 | J50: =SUM(E50:I50) -> 0 | K50: =M50+SUMIF('פקודות נוספות'!C:C,'מאזן בוחן'!C50,'פקודות נוספות'!F:F) -> 0 | M50: =IFERROR(VLOOKUP(C50,'פקודות נוספות'!$D$273:$G$797,4,0),0) -> 0 | N50: =IF(K50=0,"-",J50/K50) -> -
B51: 131.לקוחות $ | C51: 205457 | D51: Licencias On Line S.A.S | E51: =IFERROR(VLOOKUP(C51,'פקודות נוספות'!$D$274:$F$797,3,0),0) -> 23004.67 | F51: =SUMIF('פקודות נוספות'!C:C,C:C,'פקודות נוספות'!E:E) -> 0 | J51: =SUM(E51:I51) -> 23004.67 | K51: =M51+SUMIF('פקודות נוספות'!C:C,'מאזן בוחן'!C51,'פקודות נוספות'!F:F) -> 7397 | M51: =IFERROR(VLOOKUP(C51,'פקודות נוספות'!$D$273:$G$797,4,0),0) -> 7397 | N51: =IF(K51=0,"-",J51/K51) -> 3.11
B52: 130.לקוחות ILS | C52: 228871 | D52: Software Sources | E52: =IFERROR(VLOOKUP(C52,'פקודות נוספות'!$D$274:$F$797,3,0),0) -> 0 | F52: =SUMIF('פקודות נוספות'!C:C,C:C,'פקודות נוספות'!E:E) -> 0 | J52: =SUM(E52:I52) -> 0 | K52: =M52+SUMIF('פקודות נוספות'!C:C,'מאזן בוחן'!C52,'פקודות נוספות'!F:F) -> 0 | M52: =IFERROR(VLOOKUP(C52,'פקודות נוספות'!$D$273:$G$797,4,0),0) -> 0 | N52: =IF(K52=0,"-",J52/K52) -> -
...

Sheet פקודות נוספות
B1: Algosec System Ltd
B2: ='נתונים לשינוי'!C1 -> 44561
B3: פקודות נוספות לדו"חות הכספיים
B4: מספר | C4: מיון | D4: כרטיס | E4: סכום בש"ח | F4: סכום בדולר
E5: =SUM(E6:E238) -> 0 | F5: =SUM(F6:F238) -> 0
B6: 1 | C6: מיון לקוחות בזכות | E6: ILS | F6: USD | G6: ברבעון - להעביר ולהפוך
C7: 2090001 | D7: =VLOOKUP(C7,'מאזן בוחן'!C:D,2,0) -> הכנסות מראש - מיון לקוחות בזכות
C8: 53602 | D8: =VLOOKUP(C8,'מאזן בוחן'!C:D,2,0) -> הכנסות מראש - מיון לקוחות בזכות | E8: =-E7 -> 0 | F8: =-F7 -> 0
B9: 2 | C9: היפוך הכנסות לקבל בגין תשלום 2 Wipro | E9: ILS | F9: USD | G9: להעביר
C10: 1150001 | D10: =VLOOKUP(C10,'מאזן בוחן'!C:D,2,0) -> הכנסות לקבל | E10: =F10*'מאזן בוחן'!$N$2 -> 0 | F10: =-F12 -> 0
C11: 9010002 | D11: =VLOOKUP(C11,'מאזן בוחן'!C:D,2,0) -> הפרשי שער | E11: =-E12-E10 -> 0 | F11: 0
C12: 53581 | D12: =VLOOKUP(C12,'מאזן בוחן'!C:D,2,0) -> הכנסות מראש מטח Subsription פטורות חדש
B13: =B9+1 -> 3 | C13: היפוך הוצאות לשלם סקירה Q3 + דוח מס 2020 | E13: ILS | F13: USD | G13: להעביר
C14: 2200001 | D14: =VLOOKUP(C14,'מאזן בוחן'!C:D,2,0) -> הוצאות לשלם | F14: =E14/'מאזן בוחן'!$N$2 -> 0
C15: 9010002 | D15: =VLOOKUP(C15,'מאזן בוחן'!C:D,2,0) -> הפרשי שער | E15: 0 | F15: =-F16-F14 -> 0
C16: 8410068 | D16: =VLOOKUP(C16,'מאזן בוחן'!C:D,2,0) -> ביקורת ויעוץ רו"ח | E16: =-E14 -> 0 | F16: =E16/'נתונים לשינוי'!$D$8 -> 0
B17: =B13+1 -> 4 | C17: עמלות On-Hold Q4.2021 | E17: ILS | F17: USD | G17: מרכז רווח:
C18: 7110003 | D18: =VLOOKUP(C18,'מאזן בוחן'!C:D,2,0) -> שכר מכירות- עמלות למאזן בלבד | E18: =F18*'מאזן בוחן'!$N$2 -> 0 | G18: APAC
C19: 2400001 | D19: =VLOOKUP(C19,'מאזן בוחן'!C:D,2,0) -> הוצאות לשלם עובדים | E19: =-E18 -> 0 | F19: =-F18 -> 0 | G19: להעביר
B20: =B17+1 -> 5 | C20: Income receivable due renewals | E20: ILS | F20: USD | G20: להעביר ולהפוך
C21: 1150001 | D21: =VLOOKUP(C21,'מאזן בוחן'!C:D,2,0) -> הכנסות לקבל | E21: =F21*'מאזן בוחן'!N2 -> 0
C22: 80105-2 | D22: =VLOOKUP(C22,'מאזן בוחן'!C:D,2,0) -> הכנסות פטורות תחזוקה לצורך מאזן בלבד | E22: =-E21 -> 0 | F22: =-F21 -> 0
B23: =B20+1 -> 6 | C23: מיון הוצאות מראש לזמן ארוך | E23: ILS | F23: USD | G23: ברבעון - להעביר ולהפוך
C24: 2600003 | D24: =VLOOKUP(C24,'מאזן בוחן'!C:D,2,0) -> הוצ' מראש זמן ארוך
C25: 1100001 | D25: =VLOOKUP(C25,'מאזן בוחן'!C:D,2,0) -> הוצאות מראש
B26: =B23+1 -> 7 | C26: העמסת הוצאות הנה"כ | E26: ILS | F26: USD | G26: ברבעון - להעביר | H26: להעביר להנה"ח בסוף
C27: 6030001 | D27: =VLOOKUP(C27,'מאזן בוחן'!C:D,2,0) -> העמסת הנכ"כ למחלקת מו"פ | E27: ='העמסת הנה"כ'!I5 -> -0.0010582013 | F27: ='העמסת הנה"כ'!J5 -> 0.000178413
C28: 7030001 | D28: =VLOOKUP(C28,'מאזן בוחן'!C:D,2,0) -> העמסת הוצאות הנה"כ על השיווק | E28: ='העמסת הנה"כ'!I6 -> 0.00089947088 | F28: ='העמסת הנה"כ'!J6 -> -0.0010845719
C29: 5120001 | D29: =VLOOKUP(C29,'מאזן בוחן'!C:D,2,0) -> העמסת הנה"כ לעלות המכר | E29: ='העמסת הנה"כ'!I7 -> 0.0038095235 | F29: ='העמסת הנה"כ'!J7 -> 0.00075840688
C30: 93100 | D30: =VLOOKUP(C30,'מאזן בוחן'!C:D,2,0) -> העמסת הוצאות הנה"כ למחלקות אחרות | E30: =-SUM(E27:E29) -> -0.0036507931 | F30: =-SUM(F27:F29) -> 0.00014775206
B31: =B26+1 -> 8 | C31: עמלות Q4.2021 | E31: ILS | F31: USD | G31: מרכז רווח:
C32: 7110003 | D32: =VLOOKUP(C32,'מאזן בוחן'!C:D,2,0) -> שכר מכירות- עמלות למאזן בלבד | E32: =F32*'מאזן בוחן'!$N$2 -> 0 | F32: 0 | G32: EMEA
C33: 7110003 | D33: =VLOOKUP(C33,'מאזן בוחן'!C:D,2,0) -> שכר מכירות- עמלות למאזן בלבד | E33: =F33*'מאזן בוחן'!$N$2 -> 0 | G33: APAC
C34: 7110003 | D34: =VLOOKUP(C34,'מאזן בוחן'!C:D,2,0) -> שכר מכירות- עמלות למאזן בלבד | E34: =F34*'מאזן בוחן'!$N$2 -> 0 | F34: 0 | G34: LATAM
C35: 2400001 | D35: =VLOOKUP(C35,'מאזן בוחן'!C:D,2,0) -> הוצאות לשלם עובדים | E35: =F35*'מאזן בוחן'!$N$2 -> 0 | F35: =-SUM(F32:F34) -> 0 | G35: להעביר ולהפוך
B36: =B31+1 -> 9 | C36: חשבונית בינחברתית - אלגוסק מערכות ישראל-אלגוסק Inc | E36: ILS | F36: USD | G36: ברבעון - להעביר
C37: 1130001 | D37: =VLOOKUP(C37,'מאזן בוחן'!C:D,2,0) -> אלגוסק INC
C38: 80093 | D38: =VLOOKUP(C38,'מאזן בוחן'!C:D,2,0) -> הכנסות בין חברתיות-תיקון/ביטול שנים קודמות
B39: 9A | C39: חשבונית בינחברתית - אלגוסק מערכות ישראל-אלגוסק Inc | E39: ILS | F39: USD | G39: ברבעון - להעביר
C40: 1130001 | D40: =VLOOKUP(C40,'מאזן בוחן'!C:D,2,0) -> אלגוסק INC
...

Sheet מיסים שוטפים 2021
A1: הפרשה למס 2021 | G1: חופשה | H1: NIS | I1: פיצויים | J1: NIS
A2: מחזור הכנסות | D2: =דוחות!$P$12 -> 1.4157395e+08 | G2: הפרשה לחופשה י.פ. | H2: ='[44]מיסים שוטפים 2020'!$H$4 -> 5748419 | I2: פיצויים י.פ. | J2: ='[44]מיסים שוטפים 2020'!$J$4 -> 4572193
A3: רווח(הפסד) לפני מיסים לפי דו"ח | D3: =דוחות!$P$63 -> -11259307 | G3: הוצאות חופשה | H3: =H4-H2 -> -257 | I3: הוצאות חופשה | J3: =J4-J2 -> 8935
A4: הוסף: | G4: הפרשה לחופשה י.ס. | H4: =דוחות!$J$15 -> 5748162 | I4: פיצויים י.ס. | J4: =דוחות!$J$29-דוחות!$C$37 -> 4581128
A5: התחייבות בשל סיום יחסי עובד מעביד, נטו | C5: =J3 -> 8935
A6: הפרשה לחופשה | C6: =H3 -> -257
A7: קנסות | C7: 100532.8
A8: תשלום מבוסס מניות | C8: =+'מאזן בוחן'!$J$916+'מאזן בוחן'!$J$584+'מאזן בוחן'!$J$591+'מאזן בוחן'!$J$657+'מאזן בוחן'!$J$743+'מאזן בוחן'!$J$881 -> 5573718.3
A9: פחת לפי ספרים | C9: =FA!$G$15 -> 2889374
A10: הוצאות מו"פ שלא שולמו במזומן | C10: =-D66 -> 1183657.2
A11: הפקדות לבעש"ט | C11: ='[45]בדיקת הפקדה לבעל שליטה'!$E$47 -> 25223.52
A12: חלק ברווחי שותפות תושבת ההודית - 99% - דוח 31/03/2022 - שע"ח ממוצע לתקופה | C12: =16837084*0.99*'[46]Reference Rates (2)'!$K$15/9*12 -> 1006380.9
A13: הפסד הון ממכירת רכוש קבוע בספרים | C13: ='מאזן בוחן'!$J$1005 -> 20327.74
A14: עמלות 606 (לפני 2019) | C14: ='מאזן בוחן'!$J$912 -> 430510.49
A15: התאמה למחירי העברה [בגין הכנסות נדחות] - 2021 - MKT Prpjection | C15: =SUM('Tax - Inc'!F50)*'מאזן בוחן'!N2 -> 759209.36
A16: הוצאות מו"פ 2/3 שנדחים בגין 2021 | C16: =+D76 -> 5636927.6
A17: הוצאות עודפות | C17: =SUM('[47]חישוב עודפות'!$F$13) -> 149649.82
D18: =SUM(C5:C17) -> 17784190
A19: הורד:
A20: פחת לפי מס הכנסה | B20: לעדכן סוף שנה לפי טופס פחת לצורכי מס | C20: 3544478
A21: הוצאות מו"פ 1/3 מוכר משנת 2019 | C21: =D82 -> 2504275
A22: הוצאות מו"פ 1/3 מוכר משנת 2020 | C22: =D86 -> 2596973.8
A23: הוצאות מו"פ שלא שולמו במזומן ב- 2020, השנה מוכרות | C23: =D65 -> 1183657.2
A24: התאמות בגין ביקורת ניכויים 2016-2019 | C24: =[48]מרכז!$R$31 -> 377286
D26: =SUM(C20:C25) -> 10206670
A28: סה"כ | D28: =D3+D18-D26 -> -3681787.4
A30: הפרש הנובע מאישור המדען | D30: 0
A31: ניכוי בשל פחת | B31: לעדכן סוף שנה לפי טופס פחת לצורכי מס | D31: -72
A33: סה"כ הפסד להעברה
A34: הכנסה חייבת לצורכי מס (הפסד להעברה) | D34: =SUM($D$28:$D$32) -> -3681859.4
A35: הפסדים מועברים משנים קודמות | D35: 0
A36: סה"כ הכנסה חייבת | D36: =SUM(D34:D35) -> -3681859.4
A37: שיעור מס מועדף טכנוולוגי | B37: 0.12 | D37: =D36*B37 -> -441823.13
A38: הכנסה חייבת בשיעור מס חברות | B38: 0.265
A40: מס לתשלום לפני קיזוז בגין זיכויים
A41: זיכוי משנים קודמות | D41: ='[49]מיסים שוטפים 2020'!$D$48 -> 3146824.8
A42: זיכוי בגין תשלום המס בגין תקופה 2021-22 - שע"ח ממוצע לתקופת הדוח בהודו | D42: =(1755380+2105000+1643000+575157)*'[46]Reference Rates (2)'!$K$15 -> 275245.77
A43: זיכוי השנה | D43: =SUM('מאזן בוחן'!$J$118) -> 1708397.1
A44: קיזוז השנה - בגלל מפעל מועדף טכנולוגי אפשר לקזז רק 12% מההכנסה החייבת בחו"ל (הכנ' חייבת בחו"ל זה 98% לפי הטופס 901 השנה) | D44: =-D36*B37*G45 -> 438996.79 | G44: =[50]Main!$F$3 -> 0.006396993
A45: זיכוי מס מועבר לשנים הבאות | D45: =SUM(D41:D44) -> 5569464.4 | G45: =1-G44 -> 0.99360301
...

Sheet העמסת הנה"כ
A2: G&A Loading - Brosh Building
G3: recorded
B4: תמחיר Q4 2021 | E4: פקודה להעמסת הוצאות הנה"כ | G4: ₪ | H4: $ | I4: ₪ | J4: $ | L4: לוודא שמתאפס
A5: Department | B5: # of employees | E5: 6030001 | F5: העמסת הנכ"ל למחלקת מו"פ | G5: =VLOOKUP(E5,'מאזן בוחן'!C:M,3,0) -> 6956062 | H5: =VLOOKUP(E5,'מאזן בוחן'!$C:$N,11,0) -> 2099606.7 | I5: =E15+E16+G15+G16+E66-G5 -> -0.0010582013 | J5: =F15+F16+H15+H16+F66-H5 -> 0.000178413
A6: G&A | B6: =2+12+4+9+3 -> 30 | E6: 7030001 | F6: העמסת הוצאות הנכ"ל על השיווק | G6: =VLOOKUP(E6,'מאזן בוחן'!C:M,3,0) -> 1764557.7 | H6: =VLOOKUP(E6,'מאזן בוחן'!C:N,11,0) -> 536968.96 | I6: =E17+G17+E68-G6 -> 0.00089947088 | J6: =F17+H17+F68-H6 -> -0.0010845719
A7: R&D | B7: =3+106+12 -> 121 | E7: 5120001 | F7: העמסת הנכ"ל ושכר למחלקת עלות המכר | G7: =VLOOKUP(E7,'מאזן בוחן'!C:M,3,0) -> 1101733.7 | H7: =VLOOKUP(E7,'מאזן בוחן'!C:N,11,0) -> 333035.2 | I7: =E13+E14+G13+G14+E70-G7 -> 0.0038095235 | J7: =F13+F14+H13+H14+F70-H7 -> 0.00075840688
A8: S&M | B8: =2/2+2+15+2 -> 20 | E8: 93100 | F8: העמסת הוצאות הנה"כ למחלקות אחרות | G8: =VLOOKUP(E8,'מאזן בוחן'!C:M,3,0) -> -9822353.4 | H8: =VLOOKUP(E8,'מאזן בוחן'!C:N,11,0) -> -2969610.8 | I8: =-SUM(I5:I7) -> -0.0036507931 | J8: =-SUM(J5:J7) -> 0.00014775206
A9: Support | B9: =2/2+5+5+7 -> 18 | G9: =SUM(G5:G8) -> 0 | H9: =SUM(H5:H8) -> 0 | I9: =SUM(E13:E17)+SUM(G13:G17)+SUM(E66:E70)+I8+G8 -> 0 | J9: =SUM(F13:F17)+SUM(H13:H17)+SUM(F59:F70)+J8+H8 -> 0
B10: =SUM(B6:B9) -> 189
E11: Rent | F11: Rent | G11: G&A | H11: G&A
E12: ש"ח | F12: USD | G12: ש"ח | H12: USD
E13: =+$G$27*C17 -> 237589.82 | F13: =+$H$27*C17 -> 73054.372 | G13: =$H$55*C17 -> 612297.88 | H13: =$I$55*C17 -> 182121.11
E14: =+$G$27*C18 -> 0 | F14: =+$H$27*C18 -> 0 | G14: =$H$55*C18 -> 0 | H14: =$I$55*C18 -> 0
E15: =+$G$27*C19 -> 1597131.6 | F15: =+$H$27*C19 -> 491087.73 | G15: =$H$55*C19 -> 4116002.4 | H15: =$I$55*C19 -> 1224258.6
B16: # of employees | C16: Key allocation | E16: =+$G$27*C20 -> 0 | F16: =+$H$27*C20 -> 0 | G16: =$H$55*C20 -> 0 | H16: =$I$55*C20 -> 0
A17: Technical support | B17: =B9 -> 18 | C17: =B17/$B$23 -> 0.095238095 | E17: =+$G$27*C21 -> 263988.69 | F17: =+$H$27*C21 -> 81171.525 | G17: =$H$55*C21 -> 680330.98 | H17: =$I$55*C21 -> 202356.79
A18: Professional services | E18: =+$G$27*C22 -> 395983.03 | F18: =+$H$27*C22 -> 121757.29 | G18: =$H$55*C22 -> 1020496.5 | H18: =$I$55*C22 -> 303535.19
A19: R&D | B19: =B7 -> 121 | C19: =B19/$B$23 -> 0.64021164 | E19: =SUM(E13:E18) -> 2494693.1 | F19: =SUM(F13:F18) -> 767070.91 | G19: =SUM(G13:G18) -> 6429127.8 | H19: =SUM(H13:H18) -> 1912271.7
A20: Product Management | E20: =G27-E19 -> 0 | F20: =H27-F19 -> 0 | G20: =G19-H55 -> 0 | H20: =H19-I55 -> 0
A21: Sales & Marketing | B21: =B8 -> 20 | C21: =B21/$B$23 -> 0.10582011
A22: G&A | B22: =B6 -> 30 | C22: =B22/$B$23 -> 0.15873016
B23: =SUM(B17:B22) -> 189 | C23: =SUM(C17:C22) -> 1 | G23: בש"ח | H23: USD
B24: =+B10-B23 -> 0 | E24: 8030001 | F24: שכר דירה | G24: =VLOOKUP(E24,'מאזן בוחן'!C:K,8,0) -> 1819066.4 | H24: =VLOOKUP(E24,'מאזן בוחן'!C:K,9,0) -> 557731.58 | I24: =G24/H24 -> 3.2615445
E25: 8030002 | F25: חשמל | G25: =VLOOKUP(E25,'מאזן בוחן'!C:K,8,0) -> 332476.92 | H25: =VLOOKUP(E25,'מאזן בוחן'!C:K,9,0) -> 103078.12 | I25: =G25/H25 -> 3.2254849
E26: 8030003 | F26: ארנונה ומים | G26: =VLOOKUP(E26,'מאזן בוחן'!C:K,8,0) -> 343149.8 | H26: =VLOOKUP(E26,'מאזן בוחן'!C:K,9,0) -> 106261.21 | I26: =G26/H26 -> 3.2293045
F27: Rent to allocate | G27: =SUM(G24:G26) -> 2494693.1 | H27: =SUM(H24:H26) -> 767070.91
G28: =SUM('מאזן בוחן'!J759:J761)-G27 -> 0 | H28: =SUM('מאזן בוחן'!K759:K761)-H27 -> 0
G30: G&A to allocate :
H32: בש"ח | I32: USD
F33: 8030020 | G33: פחת | H33: =VLOOKUP(F33,'מאזן בוחן'!C:K,8,0) -> 1890485.7 | I33: =VLOOKUP(F33,'מאזן בוחן'!C:K,9,0) -> 515370.41 | J33: =H33/I33 -> 3.6682076
F34: 8030004 | G34: טלפון, תקשורת ואינטרנט | H34: =VLOOKUP(F34,'מאזן בוחן'!C:K,8,0) -> 189274.77 | I34: =VLOOKUP(F34,'מאזן בוחן'!C:K,9,0) -> 58559.31 | J34: =H34/I34 -> 3.2321892
F35: 8030005 | G35: סלולרי | H35: =VLOOKUP(F35,'מאזן בוחן'!C:K,8,0) -> 4934.87 | I35: =VLOOKUP(F35,'מאזן בוחן'!C:K,9,0) -> 1528.78 | J35: =H35/I35 -> 3.2279792
F36: 8030006 | G36: משרדיות | H36: =VLOOKUP(F36,'מאזן בוחן'!C:K,8,0) -> 43089.95 | I36: =VLOOKUP(F36,'מאזן בוחן'!C:K,9,0) -> 13348.02 | J36: =H36/I36 -> 3.2281904
F37: 8030008 | G37: תחזוקת כללית | H37: =VLOOKUP(F37,'מאזן בוחן'!C:K,8,0) -> 6577 | I37: =VLOOKUP(F37,'מאזן בוחן'!C:K,9,0) -> 2170.42 | J37: =H37/I37 -> 3.0302891
F38: 8030009 | G38: אחזקת משרד | H38: =VLOOKUP(F38,'מאזן בוחן'!C:K,8,0) -> 265441.56 | I38: =VLOOKUP(F38,'מאזן בוחן'!C:K,9,0) -> 81422.72 | J38: =H38/I38 -> 3.2600429
F39: 8030010 | G39: שליחויות | H39: =VLOOKUP(F39,'מאזן בוחן'!C:K,8,0) -> 14714.53 | I39: =VLOOKUP(F39,'מאזן בוחן'!C:K,9,0) -> 4557.28 | J39: =H39/I39 -> 3.2287966
F40: 8030011 | G40: אגרות ודמי חבר | H40: =VLOOKUP(F40,'מאזן בוחן'!C:K,8,0) -> 19860.52 | I40: =VLOOKUP(F40,'מאזן בוחן'!C:K,9,0) -> 6132.12 | J40: =H40/I40 -> 3.238769
F41: 8030012 | G41: מצרכים למשרד ולישיבות | H41: =VLOOKUP(F41,'מאזן בוחן'!C:K,8,0) -> 99742.86 | I41: =VLOOKUP(F41,'מאזן בוחן'!C:K,9,0) -> 31012.99 | J41: =H41/I41 -> 3.2161639
F42: 8030013 | G42: נסיעות כללי, מוניות, (עובדים ללא רכב) וחניה | H42: =VLOOKUP(F42,'מאזן בוחן'!C:K,8,0) -> 3358.69 | I42: =VLOOKUP(F42,'מאזן בוחן'!C:K,9,0) -> 1039.14 | J42: =H42/I42 -> 3.2321824
F43: 8030014 | G43: השתלמויות וספרות מקצועית הנה"כ | H43: =VLOOKUP(F43,'מאזן בוחן'!C:K,8,0) -> 40497.46 | I43: =VLOOKUP(F43,'מאזן בוחן'!C:K,9,0) -> 12597.79 | J43: =H43/I43 -> 3.214648
...

Sheet 606-Prepaid Comm&DR SUB
A9: 606-Prepaid Comm
A11: ='נתונים לשינוי'!C4 -> As at December 31, 2021
I12: ='נתונים לשינוי'!C4 -> As at December 31, 2021
A13: History | B13: Algosec System Ltd | C13: Algosec Inc | D13: Algosec Australia | E13: Algosec Europe | F13: Consolidated | I13: history | J13: Q1 | K13: Q2 | L13: Q3 | M13: Q4 | N13: Q1 2020 | O13: Q2 2020 | P13: Q3 2020 | Q13: Q4 2020 | R13: Q1 2021 | S13: Q2 2021 | T13: Q3 2021 | U13: Q4 2021 | V13: TOTAL
A14: Prepaid Comm 606- Short term | B14: =SUM('[53]Final '!$AU$3:$AX$3) -> 40175.612 | C14: =SUM('[53]Final '!$AU$4:$AX$4) -> 57347.494 | D14: =SUM('[53]Final '!$AU$6:$AX$6) -> 3377.4106 | E14: =SUM('[53]Final '!$AU$5:$AX$5) -> 21011.968 | F14: =SUM(B14:E14) -> 121912.48 | I14: =SUM('[53]Final '!$AU$7:$AX$7) -> 121912.48 | J14: =SUM([54]ALL!$AE$33:$AM$33) -> 40569.147 | K14: =SUM([55]ALL!$AE$33:$AO$33) -> 53574.646 | L14: =SUM([56]ALL!$AE$33:$AR$33) -> 63690.213 | M14: =SUM([57]ALL!$AE$33:$BB$33) -> 243232.28 | N14: =SUM([58]ALL!$AE$33:$AAA$33) -> 99933.598 | O14: =SUM([59]ALL!$AE$33:$BD$33) -> 361759.59 | P14: =SUM([60]ALL!$AE$33:$BE$33) -> 237161.32 | Q14: =SUM([61]ALL!$AE$33:$XFD$33) -> 444351.64 | R14: =SUM([62]ALL!$AE$33:$BC$33) -> 235967.46 | S14: =SUM([63]ALL!$AE$33:$BJ$33) -> 351483.73 | T14: =SUM([64]ALL!$AE$33:$BJ$33) -> 520656.6 | U14: =SUM([65]ALL!$AE$33:$BC$33) -> 869751.94 | V14: =SUM(I14:U14) -> 3644044.6
A15: Prepaid Comm 606- Long term | F15: =SUM(B15:E15) -> 0 | G15: =Consolidation!N19-דוחות!D38-F15-F18-F21-F24-F27-F30-F33-F36-F39-F42-F45-F48-F51 -> -0.25093654 | H15: Check | V15: =V14-F54 -> -0.0062177964
A16: Q1
A17: Prepaid Comm 606- Short term | B17: =SUM([54]ALL!$AE$29:$AH$29) -> 8658.8668 | C17: =SUM([54]ALL!$AE$30:$AH$30) -> 10782.009 | D17: =SUM([54]ALL!$AE$32:$AH$32) -> 8843.5168 | E17: =SUM([54]ALL!$AE$31:$AH$31) -> 5424.5611 | F17: =SUM(B17:E17) -> 33708.954
A18: Prepaid Comm 606- Long term | B18: =SUM([54]ALL!$AL$29:$AM$29) -> 2138.2381 | C18: =SUM([54]ALL!$AL$30:$AO$30) -> 2398.595 | D18: =SUM([54]ALL!$AL$32:$AO$32) -> 1040.5725 | E18: =SUM([54]ALL!$AL$31:$AL$31) -> 1282.7875 | F18: =SUM(B18:E18) -> 6860.1931
A19: Q2
A20: Prepaid Comm 606- Short term | B20: =SUM([55]ALL!$AE$29:$AH$29) -> 4313.8013 | C20: =SUM([55]ALL!$AE$30:$AH$30) -> 22988.81 | D20: =SUM([55]ALL!$AE$32:$AH$32) -> 2081.3175 | E20: =SUM([55]ALL!$AE$31:$AH$31) -> 9260.482 | F20: =SUM(B20:E20) -> 38644.411 | I20: LT TP PREPAID | K20: INC | L20: ='New TB INC'!J270 -> 1152543.5
A21: Prepaid Comm 606- Long term | B21: =SUM([55]ALL!$AL$29:$AO$29) -> 2045.6612 | C21: =SUM([55]ALL!$AL$30:$AO$30) -> 8706.3988 | D21: =SUM([55]ALL!$AL$32:$AO$32) -> 1040.6587 | E21: =SUM([55]ALL!$AL$31:$AO$31) -> 3137.5162 | F21: =SUM(B21:E21) -> 14930.235 | K21: UK | L21: ='FS EU'!C15 -> 377994.78
A22: Q3 | K22: AUD | L22: ='FS AU'!C15 -> 121809.95
A23: Prepaid Comm 606- Short term | B23: =SUM([56]ALL!$AE$29:$AH$29) -> 5399.3376 | C23: =SUM([56]ALL!$AE$30:$AH$30) -> 10725.209 | D23: =SUM([56]ALL!$AE$32:$AH$32) -> 9409.0007 | E23: =SUM([56]ALL!$AE$31:$AH$31) -> 22800.671 | F23: =SUM(B23:E23) -> 48334.218 | K23: LTD | L23: ='מאזן בוחן'!K186 -> 308476.88
A24: Prepaid Comm 606- Long term | B24: =SUM([56]ALL!$AL$29:$AO$29) -> 4003.9219 | C24: =SUM([56]ALL!$AL$30:$AO$30) -> 7098.3337 | D24: =SUM([56]ALL!$AL$32:$AO$32) -> 1081.1325 | E24: =SUM([56]ALL!$AL$31:$AO$31) -> 3172.6069 | F24: =SUM(B24:E24) -> 15355.995 | L24: =SUM(L20:L23) -> 1960825.2
A25: Q4 | L25: =F24+F21+F18+F15+F27+F30+F33+F36-L24+F39+F42+F45+F48+F51 -> 0.37093654
A26: Prepaid Comm 606- Short term | B26: =SUM([57]ALL!$AE$29:$AH$29) -> 25424.768 | C26: =SUM([57]ALL!$AE$30:$AH$30) -> 102986.69 | D26: =SUM([57]ALL!$AE$32:$AH$32) -> 395.9525 | E26: =SUM([57]ALL!$AE$31:$AH$31) -> 48205.005 | F26: =SUM(B26:E26) -> 177012.41
A27: Prepaid Comm 606- Long term | B27: =SUM([57]ALL!$AL$29:$AV$29) -> 11372.778 | C27: =SUM([57]ALL!$AL$30:$AV$30) -> 31262.833 | D27: =SUM([57]ALL!$AL$32:$AV$32) -> 395.9525 | E27: =SUM([57]ALL!$AL$31:$AX$31) -> 23188.305 | F27: =SUM(B27:E27) -> 66219.867
A28: Q1 2020
A29: Prepaid Comm 606- Short term | B29: =SUM([58]ALL!$AE$29:$AH$29) -> 15384.79 | C29: =SUM([58]ALL!$AE$30:$AH$30) -> 30607.92 | D29: =SUM([58]ALL!$AE$32:$AH$32) -> 355.785 | E29: =SUM([58]ALL!$AE$31:$AH$31) -> 6966.5323 | F29: =SUM(B29:E29) -> 53315.027
A30: Prepaid Comm 606- Long term | B30: =SUM([58]ALL!$AL$29:$BC$29) -> 14694.111 | C30: =SUM([58]ALL!$AL$30:$AV$30) -> 23275.078 | D30: =SUM([58]ALL!$AL$32:$AV$32) -> 444.73125 | E30: =SUM([58]ALL!$AL$31:$BC$31) -> 8204.6497 | F30: =SUM(B30:E30) -> 46618.57
A31: Q2 2020
A32: Prepaid Comm 606- Short term | B32: =SUM([59]ALL!$AE$29:$AH$29) -> 10553.229 | C32: =SUM([59]ALL!$AE$30:$AH$30) -> 192165.4 | D32: =SUM([59]ALL!$AE$32:$AH$32) -> 4011.3547 | E32: =SUM([59]ALL!$AE$31:$AH$31) -> 11784.303 | F32: =SUM(B32:E32) -> 218514.29
A33: Prepaid Comm 606- Long term | B33: =SUM([59]ALL!$AL$29:$AU$29) -> 13402.968 | C33: =SUM([59]ALL!$AL$30:$AT$30) -> 114569.92 | D33: =SUM([59]ALL!$AL$32:$AT$32) -> 2814.6024 | E33: =SUM([59]ALL!$AL$31:$AV$31) -> 12457.81 | F33: =SUM(B33:E33) -> 143245.3
A34: Q3 2020
A35: Prepaid Comm 606- Short term | B35: =SUM([60]ALL!$AE$29:$AH$29) -> 17463.033 | C35: =SUM([60]ALL!$AE$30:$AH$30) -> 53001.142 | D35: =SUM([60]ALL!$AE$32:$AH$32) -> 3176.1848 | E35: =SUM([60]ALL!$AE$31:$AH$31) -> 39039.65 | F35: =SUM(B35:E35) -> 112680.01
A36: Prepaid Comm 606- Long term | B36: =SUM([60]ALL!$AL$29:$BE$29) -> 23457.262 | C36: =SUM([60]ALL!$AL$30:$BE$30) -> 60053.506 | D36: =SUM([60]ALL!$AL$32:$BE$32) -> 5026.9005 | E36: =SUM([60]ALL!$AL$31:$BC$31) -> 35943.644 | F36: =SUM(B36:E36) -> 124481.31
A37: Q4 2020
A38: Prepaid Comm 606- Short term | B38: =SUM([66]ALL!$AE$29:$AH$29) -> 25378.056 | C38: =SUM([61]ALL!$AE$30:$AH$30) -> 104530.39 | D38: =SUM([61]ALL!$AE$32:$AH$32) -> 22518.372 | E38: =SUM([61]ALL!$AE$31:$AH$31) -> 17805.689 | F38: =SUM(B38:E38) -> 170232.51
A39: Prepaid Comm 606- Long term | B39: =SUM([66]ALL!$AL$29:$BE$29) -> 43996.643 | C39: =SUM([61]ALL!$AL$30:$BE$30) -> 147086.31 | D39: =SUM([61]ALL!$AL$32:$BE$32) -> 42488.48 | E39: =SUM([61]ALL!$AL$31:$BC$31) -> 40547.697 | F39: =SUM(B39:E39) -> 274119.13
A40: Q1 2021
A41: Prepaid Comm 606- Short term | B41: =SUM([67]ALL!$AE$29:$AH$29) -> 20202.476 | C41: =SUM([62]ALL!$AE$30:$AH$30) -> 50235.018 | D41: =SUM([67]ALL!$AE$32:$AH$32) -> 2522.2239 | E41: =SUM([67]ALL!$AE$31:$AH$31) -> 21046.902 | F41: =SUM(B41:E41) -> 94006.62
A42: Prepaid Comm 606- Long term | B42: =SUM([67]ALL!$AL$29:$BC$29) -> 43015.802 | C42: =SUM([62]ALL!$AL$30:$BF$30) -> 63863.149 | D42: =SUM([67]ALL!$AL$32:$BC$32) -> 5400.9948 | E42: =SUM([67]ALL!$AL$31:$BC$31) -> 29680.897 | F42: =SUM(B42:E42) -> 141960.84
A43: Q2 2021
A44: Prepaid Comm 606- Short term | B44: =SUM([68]ALL!$AE$29:$AH$29) -> 19590.473 | C44: =SUM([63]ALL!$AE$30:$AH$30) -> 79192.503 | D44: =SUM([68]ALL!$AE$32:$AH$32) -> 421.72507 | E44: =SUM([63]ALL!$AE$31:$AH$31) -> 25034.472 | F44: =SUM(B44:E44) -> 124239.17
A45: Prepaid Comm 606- Long term | B45: =SUM([68]ALL!$AL$29:$BJ$29) -> 41279.444 | C45: =SUM([63]ALL!$AL$30:$BJ$30) -> 130926.54 | D45: =SUM([68]ALL!$AL$32:$BJ$32) -> 1021.0562 | E45: =SUM([63]ALL!$AL$31:$BJ$31) -> 54017.52 | F45: =SUM(B45:E45) -> 227244.56
A46: Q3 2021
A47: Prepaid Comm 606- Short term | B47: =SUM([64]ALL!$AE$29:$AH$29) -> 18843.223 | C47: =SUM([64]ALL!$AE$30:$AH$30) -> 129805.67 | D47: =SUM([64]ALL!$AE$32:$AH$32) -> 23710.028 | E47: =SUM([64]ALL!$AE$31:$AH$31) -> 14065.337 | F47: =SUM(B47:E47) -> 186424.25
A48: Prepaid Comm 606- Long term | B48: =SUM([64]ALL!$AL$29:$BJ$29) -> 39400.357 | C48: =SUM([64]ALL!$AL$30:$BJ$30) -> 237263.35 | D48: =SUM([64]ALL!$AL$32:$BJ$32) -> 44506.746 | E48: =SUM([64]ALL!$AL$31:$BJ$31) -> 13061.888 | F48: =SUM(B48:E48) -> 334232.34
A49: Q4 2021
...

Sheet ביאורים לדוחות הכספיים
A2: FAS123 Check
A4: INC | B4: =SUM('New TB INC'!J445) -> -11488368
A5: UK | B5: =SUM('מאזן בוחן EUROPE'!K303,'מאזן בוחן EUROPE'!K305) -> -354154.95
B6: =SUM(B4:B5) -> -11842523
A8: ALTSHULER | B8: =SUM('[90]Expense Amortization'!$X$1190) -> 11837803
A9: NON SIGNIFICANT | B9: =SUM(B6:B8) -> -4720.39
A11: תנועה בקרן הון בארצות הברית
A12: Opening Balance | B12: -9290163.5
A13: Q1 | B13: -619693
A14: Q2 | B14: -511584
A15: Q3 | B15: -533569
A16: Q4 | B16: =-SUM('[91]Department & Entity'!$H$19)+'[91]Department & Entity'!$C$19 -> -533357.86
A17: Closing Balance | B17: =SUM(B12:B16) -> -11488367
B18: =-'New TB INC'!J445+B17 -> 0.59
A19: תנועה בקרן הון באירופה
A20: Opening Balance | B20: -156149
A21: Q1 | B21: -11611.039
A22: Q2 | B22: -11441.95
A23: Q3 | B23: -9406.68
A24: Q4 | B24: =-'[92]99911'!$D$16 -> -12752.05
A25: RECLASS TO A.E. | B25: =-'[92]99911'!$D$17 -> 93551.54
B26: =SUM(B20:B25) -> -107809.18
B27: ='מאזן בוחן EUROPE'!J303-'ביאורים לדוחות הכספיים'!B26 -> 0.56949265
A29: Social security UK | B29: Provision for commissions | C29: UK | D29: Germany | E29: Netherlands | F29: Sweden | G29: Denmark | H29: Switzerland - C. Graf/Payrollplus issues payslip for him | I29: Subcontractor | J29: Total
A30: one time bonus | B30: ='[93]One-Time Bonus '!$C$21*0.73993005162856 -> 12318.126 | C30: ='[93]One-Time Bonus '!$C$46*0.73993005162856 -> 8095.3083 | D30: ='[93]One-Time Bonus '!$C$34*0.73993005162856 -> 4222.8178 | E30: 0 | F30: 0 | G30: 0 | H30: 0 | I30: 0 | J30: =I30+H30+G30+F30+E30+D30+C30-B30 -> 0
C31: =SUM(C30:C30) -> 8095.3083 | D31: =SUM(D30:D30) -> 4222.8178 | E31: =SUM(E30:E30) -> 0 | F31: =SUM(F30:F30) -> 0 | G31: =SUM(G30:G30) -> 0 | I31: =SUM(I30:I30) -> 0
A32: Employer contribution | C32: 0.11 | D32: 0 | E32: 0 | F32: 0.3142 | G32: 0 | H32: 0.2 | I32: 0
A33: Social security | C33: =C31*C32 -> 890.48392 | D33: =D31*D32 -> 0 | E33: =E31*E32 -> 0 | F33: =F31*F32 -> 0 | G33: =G31*G32 -> 0 | I33: =I31*I32 -> 0 | J33: =SUM(C33:I33) -> 890.48392
A35: Social security Ltd | B35: Provision for commissions | C35: Israel | D35: Singapore | E35: Subcontractors | F35: Total
A36: Commisions | B36: =[94]Main!$E$7+[94]Main!$E$16+[94]Main!$E$24 -> 115868.39 | C36: =[94]Main!$E$7 -> 9524.0832 | D36: =[94]Main!$E$16 -> 28945.27 | E36: =[94]Main!$E$24 -> 77399.038 | F36: =SUM($C$36:$E$36)-$B$36 -> 0
A37: Rate | C37: 0.05 | D37: Above SGD 6,000 fixed rate of 1,020 - 3 employees
C38: =$C$36*$C$37 -> 476.20416 | D38: =3*1020 -> 3060 | F38: =SUM(C38:E38) -> 3536.2042
A40: Social security guidance:
D41: לבדוק האם בונוסים לבלרוס, פולין ואוקראינה כוללים בחשבונית העמסה של סוציאליות - במידה ולא אין צורך להוסיף.
A42: Denmark:
A43: Employer contribution based on a fixed amount per year.
A45: USA:
A46: The employee tax rate up to an yearly salary of $142k is 6.2%, each USD above this amount will bear a 1.45% - Most of our employees base salary pass the $142k yearly therefore the emploee tax provision due commissions is immaterial.
K47: גרמניה
K48: מעל שכר של 7,100 יורו לא חלות עלויות מעביד.
...

Sheet יתרות בינחברתיות
A2: Related Parties Reconsilation :
A4: BS | C4: usd | D4: GBP | E4: AUD | F4: EUR | G4: INR
A5: LTD
A6: 1130001 | B6: Algosec Inc | C6: ='מאזן בוחן'!K501 -> -5158528.6
A7: 1130002 | B7: Algosec Europe | C7: ='מאזן בוחן'!K502 -> 5177719.8 | D7: =C7*'נתונים לשינוי'!C22/'נתונים לשינוי'!C20 -> 3831150.5
A8: 1130004 | B8: Algosec INC- CREDIT CARD CHARGES | C8: ='מאזן בוחן'!K503 -> 0
A9: 1130005 | B9: אלגוסק אוסטרליה | C9: ='מאזן בוחן'!K504 -> 6775705.6 | E9: =C9*'מאזן בוחן Australia'!O2 -> 9324915.7
A10: 1130009 | B10: Algosec India | C10: ='מאזן בוחן'!K497 -> 0 | G10: =C10*'מאזן בוחן הודו'!$O$2 -> 0
A12: INC
A13: 1130001 | B13: Intercompany LTD Account | C13: ='New TB INC'!J271 -> 5158528.6
A14: 1130003 | B14: Intercompany Europe | C14: ='New TB INC'!J272 -> 0
A15: 1130004 | B15: Algosec INC- CREDIT CARD CHARGES | C15: ='New TB INC'!J432 -> 0
A16: New4 | B16: Algosec Australia | C16: =+'New TB INC'!J275 -> 14383.75
A17: 1130012 | B17: Algosec India | C17: =+'New TB INC'!J273 -> 40926.91 | G17: =C17*'נתונים לשינוי'!$B$17 -> 3040971.7
A19: EUR
A20: 1130002 | B20: Algosec Israel | C20: ='מאזן בוחן EUROPE'!K171 -> -5177719.8 | D20: ='מאזן בוחן EUROPE'!J171 -> -3831150.5
A21: 1130003 | B21: Algosec INC | C21: ='מאזן בוחן EUROPE'!K172 -> 0
A22: 1130007 | B22: אלגוסק אוסטרליה | C22: ='מאזן בוחן EUROPE'!K177 -> 0 | E22: =C22*'נתונים לשינוי'!C22/'נתונים לשינוי'!C23 -> 0
B23: Algosec France | C23: ='מאזן בוחן צרפת'!K164 -> 0 | F23: =C23*'מאזן בוחן צרפת'!$O$2 -> 0
A25: Australia
A26: 1130007 | B26: אלגוסק אנגליה | C26: 0 | E26: 0
A27: 1130005 | B27: אלגוסק ישראל | C27: ='מאזן בוחן Australia'!K44 -> -6775705.6 | E27: ='מאזן בוחן Australia'!J44 -> -9324921.8
A28: 1130003 | B28: Algosec INC | C28: =+'מאזן בוחן Australia'!K116 -> -14384.38
A30: France
A31: 1130010 | B31: Algosec Europe | C31: ='מאזן בוחן EUROPE'!K173 -> 0 | F31: =C31*'מאזן בוחן צרפת'!$O$2 -> 0
A33: India
B34: Algosec Israel | C34: ='מאזן בוחן הודו'!K47 -> 0 | G34: ='מאזן בוחן הודו'!J47 -> 0
A35: 1130012 | B35: Algosec Inc | C35: ='מאזן בוחן הודו'!K159 -> -40926.87 | G35: ='מאזן בוחן הודו'!J159 -> -3040968.8
D40: usd check | F40: main currency check
D41: =C6+C13 -> 0.05 | F41: =E6+E13 -> 0
D42: =C14+C21 -> 0 | F42: =E14+E21 -> 0
D43: =C15+C8 -> 0 | F43: =E15+E8 -> 0
D44: =C7+C20 -> 0 | F44: =D20+D7 -> 0.0037308177
D45: =C22+C26 -> 0 | F45: =E26+E22 -> 0
D46: =C9+C27 -> 0 | F46: =E9+E27 -> -6.1153801
D47: =C31+C23 -> 0 | F47: =F31+F23 -> 0
D48: =C34+C10+C35+C17 -> 0.04 | F48: =G34+G10+G35+G17 -> 2.9721
D49: =+C28+C16 -> -0.63 | F49: =+E28+E16 -> 0
A50: Income IC | D50: =SUM(D41:D49) -> -0.54 | F50: =SUM(F41:F49) -> -3.1395493
A52: India
...

Sheet Accrued expenses
A13: Algosec Israel
A15: 2200001 | B15: ='מאזן בוחן'!D456 -> הוצאות לשלם
D16: ILS
D17: 44166 | E17: 44197 | F17: 44228 | G17: 44256 | H17: 44287 | I17: 44317 | J17: 44348 | K17: 44378 | L17: 44409 | M17: 44440 | N17: 44470 | O17: 44501 | P17: 44531 | S17: 2021
A18: 8410068 | B18: ביקורת2021 | C18: דוח מס $8k, דוח שנתי $17, שלוש סקירות $18k. | D18: 0 | E18: =(5+18+17)/12*3.291*1000 -> 10970 | F18: =E18+11*1000 -> 21970 | G18: =F18+11*1000-1140 -> 31830 | H18: =G18+10970+3247 -> 46047 | I18: =H18+10970+814 -> 57831 | J18: =I18+10970+814 -> 69615 | K18: =J18+10970+814 -> 81399 | L18: =K18+10970+814 -> 93183 | M18: =L18+10970+814-6000*'מאזן בוחן'!$N$2-180 -> 86127 | N18: =85839+10970+815 -> 97624 | O18: =N18+10970+815 -> 109409 | P18: 77750 | S18: =8000/12*12*3.11 -> 24880 | T18: דוח מס
A19: 8410068 | B19: ביקורת 2020 | C19: דוח מס | D19: 97142 | E19: 97142 | F19: =E19 -> 97142 | G19: =F19-6000*'נתונים לשינוי'!$C$22 -> 78482 | H19: =G19 -> 78482 | I19: =H19 -> 78482 | J19: =I19 -> 78482 | K19: =J19 -> 78482 | L19: =5000*'מאזן בוחן'!$N$2 -> 15550 | M19: =L19 -> 15550 | N19: 15790 | O19: 15790 | P19: 0 | S19: =17000/12*12*3.11 -> 52870 | T19: דוח שנתי
A20: 6020008 | B20: זיו האפט | D20: 31247 | E20: 0 | F20: 0 | G20: =F20 -> 0 | H20: 21950 | I20: 0 | M20: 45690 | N20: 0 | O20: 0 | P20: 0 | R20: שולם | S20: 0 | T20: רבעון 1
A21: 8410068 | B21: EY | C21: דוח מדען | D21: 10931 | E21: 0 | F21: 0 | G21: =F21 -> 0 | I21: =H21 -> 0 | M21: 0 | N21: 0 | O21: 0 | P21: 0 | R21: שולם | S21: 0 | T21: רבעון 2
A22: 8410068 | B22: אלטשולר שחם בנפיטס Q.2020-Q2.2021 | C22: הערכת שווי אופציות | D22: 7957.13 | E22: 7957.13 | F22: =E22 -> 7957.13 | G22: 0 | I22: =H22 -> 0 | M22: 0 | N22: 0 | O22: 0 | P22: 0 | R22: שולם | T22: רבעון 3
B23: הפרשה לכ.אשראי | D23: 35313 | E23: 40289 | F23: 70051 | G23: 84046 | H23: 123886 | I23: 158411 | J23: 117013 | K23: 153350 | L23: 141069 | M23: 136368 | N23: 141146 | O23: 111656 | P23: 180587 | S23: =SUM(S18:S22) -> 77750
A24: 8020013 | B24: mivtah saimon | D24: 8500 | E24: 8500 | F24: =E24 -> 8500 | G24: =F24 -> 8500 | H24: =G24 -> 8500 | I24: =H24 -> 8500 | J24: =I24 -> 8500 | K24: =J24 -> 8500 | L24: =K24 -> 8500 | M24: =L24 -> 8500 | N24: 8500 | O24: 8500 | P24: 8500 | S24: =P18 -> 77750
A25: 6020008 | B25: אולקלאוד | D25: 28000 | E25: =28000+D25 -> 56000 | F25: 0 | G25: =F25 -> 0 | H25: 24578 | M25: 0 | N25: 0 | O25: 0 | P25: 0 | S25: =S23-S24 -> 0
A26: 6010008 | B26: שרותי פיתוח מטריקס | D26: 0 | E26: 148148.49 | F26: 151161.86 | G26: 151355.21 | H26: 181985.61 | I26: 188666.35 | J26: 209436.6 | K26: 140387.58 | L26: 96576.17 | M26: 97724.55 | N26: 29423.23 | O26: 26850.25 | P26: 0
A27: 5420007 | B27: cloudshare | D27: 23668.83 | E27: 0 | F27: 0 | G27: =F27 -> 0 | I27: =H27 -> 0 | M27: 0 | N27: 0 | O27: 0 | P27: 0
A28: 6020014 | B28: אול קלאוד AWS | E28: =85360 -> 85360 | F28: 0 | G28: =F28 -> 0 | H28: 264837 | M28: 0 | N28: 333722 | O28: 359016.64 | P28: 0
A29: 8030020 | B29: Depriciation | D29: 0 | E29: 230000 | F29: =E29+230000 -> 460000 | G29: 0 | H29: 200000 | I29: 400000 | K29: 200000 | L29: =K29+200000 -> 400000 | M29: 200000 | N29: 200000 | O29: 400000 | P29: 0
A30: 8030009 | B30: נקיון | D30: 36594 | E30: 36594 | F30: 0 | G30: =F30 -> 0 | I30: =H30 -> 0 | M30: 0 | N30: 0 | P30: 0
A31: 7120042 | B31: יעוץ APAC | D31: 8287.52 | E31: 0 | F31: 0 | G31: =F31 -> 0 | I31: =H31 -> 0 | M31: 0 | N31: 0 | O31: 0 | P31: 0
A32: 7020026 | B32: Facebook | O32: 51221.24 | P32: 0
A33: 7020026 | B33: קודרס קלאן | D33: 23625 | E33: 0 | F33: 34144.8 | G33: 0 | I33: =H33 -> 0 | M33: 0 | N33: 14211 | P33: =40437+24880 -> 65317
A34: 8410048 | B34: רשיונות תוכנה הנה"כ | C34: בזק בינלאומי | F34: 45260.43 | G34: 0 | I34: =H34 -> 0 | M34: 0 | N34: 0 | O34: 0 | P34: 0
A35: 8220010 | B35: רופטופ פרטנרס | H35: 6125 | M35: 0 | N35: 0 | O35: 0 | P35: 0
A36: 8220010 | B36: אש מהירה | H36: 2200 | M36: 0 | N36: 0 | O36: 0 | P36: 0
A37: 8030012 | B37: אגם שיווק 4/21 | H37: 5000 | M37: 0 | N37: 0 | O37: 0 | P37: 0
A38: 7020038 | B38: הפרשה- איי טי סנטרל | J38: 4970 | K38: =J38+4970 -> 9940 | L38: =K38+4970 -> 14910 | M38: =L38+4970 -> 19880 | N38: =19880+4970 -> 24850 | O38: =4970+24850 -> 29820 | P38: =4970+29820 -> 34790
A39: 6010007 | B39: השמת עובדים -מו"פ | C39: גוטפרנדס | D39: 30392 | E39: 0 | F39: 0 | G39: =F39 -> 0 | I39: =H39 -> 0 | K39: 41500 | L39: =K39 -> 41500 | M39: 28000 | N39: 0 | O39: 0 | P39: 45000
A40: 6010022 | B40: שירותי פיתוח בבלרוס Belisoft International | J40: 712360 | K40: =J40 -> 712360 | L40: =K40 -> 712360 | M40: =L40 -> 712360 | N40: 712360 | O40: 712360 | P40: 712360
A41: 6020014 | B41: אוטומט איט | C41: אוטומט איט | M41: =8595+49111 -> 57706 | N41: =49111+135794 -> 184905 | O41: =15119+184905+12946 -> 212970 | P41: 0
A42: 6020008 | B42: יעוץ ויועצים פיתוח | C42: אברא | M42: 45650 | N42: 0 | O42: 0 | P42: 0
A43: 6020014 | B43: רשיונות ושירותי ענן - פיתוח | C43: שטרן IT | M43: 21000 | P43: 0
A44: 6020014 | B44: ניוווי | O44: 40177 | P44: 0
A45: 6120006 | B45: דובל | K45: 14180 | L45: 0 | M45: 0 | N45: 0 | O45: 29050 | P45: 0
A46: 7020038 | B46: Marketing Demand Generation | M46: 0 | N46: 72634 | O46: 80000 | P46: 0
A47: 5800001 | B47: פדקס | O47: 0 | P47: 0
A48: 5110007 | B48: מתודה | K48: 22227 | L48: =K48 -> 22227 | M48: =L48 -> 22227 | N48: 0 | O48: 0 | P48: 0
A49: 6010007 | B49: השמת עובדים -מו"פ | M49: 9638 | N49: 0 | O49: 26500 | P49: 26500
A50: 6010007 | B50: פעילויות צוות /חברה | C50: ליאור סושארד | M50: 35100 | N50: 0 | O50: 0 | P50: 21000
A51: 8410048 | B51: בזק | L51: 46544.87 | M51: =L51+46544.87 -> 93089.74 | N51: =93089.74+46544.87 -> 139634.61 | O51: =139634.61-46544.87*3 -> 0 | P51: 0
A52: 8030002 | B52: חשמל | D52: 27000 | E52: 27000 | F52: =E52 -> 27000 | G52: =F52 -> 27000 | H52: =G52 -> 27000 | I52: =H52 -> 27000 | J52: =I52 -> 27000 | K52: =J52 -> 27000 | L52: =K52 -> 27000 | M52: =L52 -> 27000 | N52: 27000 | O52: 27000 | P52: 27000
