Workbook
Name \A: '[1]טורים 98'!$HJ$133
Name \A: '[2]טורים 98'!$HJ$133
Name \B: #REF!
Name \B: #REF!
Name \B: #REF!
Name \B: #REF!
Name \C: '[1]טורים 98'!$HJ$154
Name \C: '[2]טורים 98'!$HJ$154
Name \D: '[2]טורים 98'!#REF!
Name \D: '[1]טורים 98'!#REF!
Name \D: '[2]טורים 98'!#REF!
Name \E: '[1]טורים 98'!$HJ$155
Name \E: '[2]טורים 98'!$HJ$155
Name \F: '[1]טורים 98'!$GS$2
Name \F: '[2]טורים 98'!$GS$2
Name \H: '[1]טורים 98'!$B$336
Name \H: '[2]טורים 98'!$B$336
Name \J: '[1]טורים 98'!$HJ$164
Name \J: '[2]טורים 98'!$HJ$164
Name \K: '[1]טורים 98'!$HJ$166
Name \K: '[2]טורים 98'!$HJ$166
Name \L: '[1]טורים 98'!$HJ$124
Name \L: '[2]טורים 98'!$HJ$124
Name \M: '[1]טורים 98'!$HJ$121
Name \M: '[2]טורים 98'!$HJ$121
Name \O: '[1]טורים 98'!$HJ$144
Name \O: '[2]טורים 98'!$HJ$144
Name \P: '[1]טורים 98'!$GT$13
Name \P: '[2]טורים 98'!$GT$13
Name \Q: '[1]טורים 98'!$HJ$127
Name \Q: '[2]טורים 98'!$HJ$127
Name \R: '[1]טורים 98'!$HJ$118
Name \R: '[2]טורים 98'!$HJ$118
Name \S: '[1]טורים 98'!$HJ$151
Name \S: '[2]טורים 98'!$HJ$151
Name \t: #REF!
Name \t: #REF!
Name \t: #REF!
Name \t: #REF!
Name \U: '[1]טורים 98'!$HJ$116
Name \U: '[2]טורים 98'!$HJ$116
Name \W: '[1]טורים 98'!$HJ$113
Name \W: '[2]טורים 98'!$HJ$113
Name \X: '[1]טורים 98'!$HJ$146
Name \X: '[2]טורים 98'!$HJ$146
Name \Y: '[1]טורים 98'!$GT$6
Name \Y: '[2]טורים 98'!$GT$6
Name \Z: '[1]טורים 98'!$HJ$129
Name \Z: '[2]טורים 98'!$HJ$129
Name _____ICP1: #REF!
Name _____ICP1: #REF!
Name _____ICP1: #REF!
Name _____ICP1: #REF!
Name _____ND1: #REF!
Name _____ND1: #REF!
Name _____ND1: #REF!
Name _____ND1: #REF!
Name _____OM9: #REF!
Name _____OM9: #REF!
Name _____OM9: #REF!

Sheet Master Data (do not print)
A13: Company name | B13: Aurora Labs Consolidated
A19: Date | B19: 44926
A20: CompareDate | B20: 44561
A22: exchange rate
A23: USD/NIS | B23: 3.519
A24: Euro NIS | B24: 3.753
A27: Sanity check - בדיקת סך בקרות הסיכום בחוברת | B27: =SUM(BS!C46)+SUM('P&L'!D33:H33)+SUM(NotesBS!C13,NotesBS!C26,NotesBS!C36,NotesBS!C37,NotesBS!C45,NotesBS!C57,NotesBS!C58,NotesBS!C65)+SUM('NotesP&L'!B15,'NotesP&L'!F15,'NotesP&L'!B30,'NotesP&L'!F30,'NotesP&L'!B49,'NotesP&L'!F49,'NotesP&L'!B60,'NotesP&L'!F60) -> 29962875 | C27: חייב להיות אפס

Sheet COVER NEW
A1: =Companyname -> Aurora Labs Consolidated
A13: INTERNAL
A16: FINANCIAL
A18: STATEMENTS
A21: UNAUDITED
A35: =DATE -> 44926

Sheet BS
A1: =Companyname -> Aurora Labs Consolidated | E1: INDEX
A2: BALANCE SHEET
C4: =DATE -> 44926 | D4: 43830
C5: =DATE -> 44926 | D5: =CompareDATE -> 44561
C6: U.S. Dollars | D6: U.S. Dollars
C7: Unaudited | D7: Audited
A8: CURRENT ASSETS | B8: Note
A9: =VLOOKUP(E9,Index!A:B,2,0) -> Cash and cash equivalents | B9: 1 | C9: =-SUMIF(SAP!I:I,E9,SAP!F:F) -> 20779776 | D9: 13400932 | E9: 130
A10: =VLOOKUP(E10,Index!A:B,2,0) -> Short term deposit | C10: =-SUMIF(SAP!I:I,E10,SAP!F:F) -> 40710444 | D10: 0 | E10: 133
A11: =VLOOKUP(E11,Index!A:B,2,0) -> Accounts receivable | C11: =-SUMIF(SAP!I:I,E11,SAP!F:F) -> 1269967 | D11: 220165 | E11: 134
A12: =VLOOKUP(E12,Index!A:B,2,0) -> Other current assets | B12: 2 | C12: =-SUMIF(SAP!I:I,E12,SAP!F:F) -> 208930 | D12: 47343 | E12: 135
C13: =SUM(C9:C12) -> 62969117 | D13: =SUM(D9:D12) -> 13668440
C14: - - - - - - - - - | D14: - - - - - - - - -
A15: NON - CURRENT ASSETS
A16: =VLOOKUP(E16,Index!A:B,2,0) -> Leased property under capital lease | C16: =-SUMIF(SAP!I:I,E16,SAP!F:F) -> 225967 | D16: 0 | E16: 141
A18: FIXED ASSETS
A19: =VLOOKUP(E19,Index!A:B,2,0) -> Fixed assets, gross | B19: 3 | C19: =-SUMIF(SAP!I:I,E19,SAP!F:F) -> 386842 | D19: 286867 | E19: 190
A20: =VLOOKUP(E20,Index!A:B,2,0) -> Accumulated depreciation | C20: =-SUMIF(SAP!I:I,E20,SAP!F:F) -> -211237 | D20: -141400 | E20: 191
C21: =SUM(C19:C20) -> 175605 | D21: =SUM(D19:D20) -> 145467
C22: - - - - - - - | D22: - - - - - - -
C23: =SUM(C21,C16,C13) -> 63370689 | D23: =SUM(D21,,D13) -> 13813907
A25: CURRENT LIABILITIES
A26: =VLOOKUP(E26,Index!A:B,2,0) -> Short Term Loans | C26: =-SUMIF('SAP DRAFT'!K:K,E26,'SAP DRAFT'!H:H) -> 0 | D26: 0 | E26: 261
A27: =VLOOKUP(E27,Index!A:B,2,0) -> Current maturities of obligation under capital lease | C27: =SUMIF(SAP!I:I,E27,SAP!F:F) -> 149136 | D27: 0 | E27: 263
A28: =VLOOKUP(E28,Index!A:B,2,0) -> Accounts payable | B28: 4 | C28: =SUMIF(SAP!I:I,E28,SAP!F:F) -> 150071 | D28: 74466 | E28: 265
A29: =VLOOKUP(E29,Index!A:B,2,0) -> Other liabilities | B29: 5 | C29: =SUMIF(SAP!I:I,E29,SAP!F:F) -> 1319416 | D29: 1190612 | E29: 268
C30: =SUM(C26:C29) -> 1618623 | D30: =SUM(D26:D29) -> 1265078
C32: - - - - - - - - - | D32: - - - - - - - - -
A34: LONG TERM LIABILITIES
A35: =VLOOKUP(E35,Index!A:B,2,0) -> Long Term Lease | C35: =SUMIF(SAP!I:I,E35,SAP!F:F) -> 75354 | D35: 0 | E35: 301
C36: =SUM(C32:C35) -> 75354 | D36: =SUM(D32:D35) -> 0
A38: SHAREHOLDER'S EQUITY
A39: =VLOOKUP(E39,Index!A:B,2,0) -> Share capital | B39: 6 | C39: =SUMIF(SAP!I:I,E39,SAP!F:F) -> 2215 | D39: 1866 | E39: 372 | J39: =טבלה2[[#This Row],[עמודה3]]-טבלה2[[#This Row],[עמודה5]] -> 349 | L39: שינוי בהון
A40: =VLOOKUP(E40,Index!A:B,2,0) -> Additional paid-in capital | C40: =SUMIF(SAP!I:I,E40,SAP!F:F) -> 97198946 | D40: 35489172 | E40: 374 | J40: =טבלה2[[#This Row],[עמודה3]]-טבלה2[[#This Row],[עמודה5]] -> 61709774 | L40: שינוי בפרמיה
A41: =VLOOKUP(E41,Index!A:B,2,0) -> Accumulated Earnings | C41: ='P&L'!H31 -> -35524449 | D41: -22942209 | E41: 378
C42: =SUM(C39:C41) -> 61676712 | D42: =SUM(D39:D41) -> 12548829 | L42: הרכב שינוי בפרמיה:
C43: - - - - - - - | D43: - - - - - - - | J43: 1465364.9 | L43: תשלום במוסס מניות
C44: =SUM(C30,C36,C42) -> 63370689 | D44: =SUM(D30,,D42) -> 13813907 | J44: 63318262 | L44: גיוס 2022
J45: -3073504.9 | L45: הוצאות הנפקה
C46: =ROUND(C44-C23,0) -> 0 | D46: =ROUND(D44-D23,0) -> 0 | J46: -349 | L46: Preferred C Shares
...

Sheet P&L
A1: =Companyname -> Aurora Labs Consolidated | J1: INDEX
A2: STATEMENT OF OPERATIONS
D5: MTD | F5: QTD | H5: YTD | I5: YTD | V5: YTD | X5: MTD | Y5: YTD | AA5: MTD | AB5: YTD | AE5: MTD | AF5: YTD | AH5: YTD | AI5: YTD | AJ5: MTD | AK5: YTD | AM5: MTD | AN5: QTD | AP5: MTD | AQ5: YTD | AT5: MTD | AU5: YTD | AX5: QTD | AY5: MTD | AZ5: YTD | BC5: MTD | BD5: YTD | BF5: MTD | BG5: YTD
D6: =DATE -> 44926 | F6: =DATE -> 44926 | H6: =DATE -> 44926 | I6: 43830 | V6: 44592 | X6: 44620 | Y6: 44620 | AA6: 44651 | AB6: 44742 | AE6: 44681 | AF6: 44681 | AH6: 44712 | AI6: 44742 | AJ6: 44712 | AK6: 44804 | AM6: 44742 | AN6: 44742 | AP6: 44773 | AQ6: 44773 | AT6: 44804 | AU6: 44804 | AX6: 44834 | AY6: 44834 | AZ6: 44834 | BC6: 44865 | BD6: 44865 | BF6: 44895 | BG6: 44895
D7: =DATE -> 44926 | F7: =DATE -> 44926 | H7: =DATE -> 44926 | I7: =CompareDATE -> 44561 | V7: 44592 | X7: 44620 | Y7: 44620 | AA7: 44651 | AB7: 44742 | AE7: 44681 | AF7: 44681 | AH7: 44712 | AI7: 44742 | AJ7: 44712 | AK7: 44804 | AM7: 44742 | AN7: 44742 | AP7: 44773 | AQ7: 44773 | AT7: 44804 | AU7: 44804 | AX7: 44834 | AY7: 44834 | AZ7: 44834 | BC7: 44865 | BD7: 44865 | BF7: 44895 | BG7: 44895
D8: U.S. Dollars | F8: U.S. Dollars | H8: U.S. Dollars | I8: U.S. Dollars | V8: U.S. Dollars | X8: U.S. Dollars | Y8: U.S. Dollars | AA8: U.S. Dollars | AB8: U.S. Dollars | AE8: U.S. Dollars | AF8: U.S. Dollars | AH8: U.S. Dollars | AI8: U.S. Dollars | AJ8: U.S. Dollars | AK8: U.S. Dollars | AM8: U.S. Dollars | AN8: U.S. Dollars | AP8: U.S. Dollars | AQ8: U.S. Dollars | AT8: U.S. Dollars | AU8: U.S. Dollars | AX8: U.S. Dollars | AY8: U.S. Dollars | AZ8: U.S. Dollars | BC8: U.S. Dollars | BD8: U.S. Dollars | BF8: U.S. Dollars | BG8: U.S. Dollars
C9: Note | D9: Unaudited | F9: Unaudited | H9: Unaudited | I9: Audited | V9: Unaudited | X9: Unaudited | Y9: Unaudited | AA9: Unaudited | AB9: Unaudited | AE9: Unaudited | AF9: Unaudited | AH9: Unaudited | AI9: Unaudited | AJ9: Unaudited | AK9: Unaudited | AM9: Unaudited | AN9: Unaudited | AP9: Unaudited | AQ9: Unaudited | AT9: Unaudited | AU9: Unaudited | AX9: Unaudited | AY9: Unaudited | AZ9: Unaudited | BC9: Unaudited | BD9: Unaudited | BF9: Unaudited | BG9: Unaudited
A12: =VLOOKUP(J12,Index!A:B,2,0) -> Revenues | D12: =H12-BG12 -> -37339 | F12: =טבלה3[[#This Row],[עמודה6]]-AZ12 -> 137873 | H12: =SUMIF(SAP!I:I,J12,SAP!F:F) -> 1219917 | I12: 852628 | J12: 420 | L12: =טבלה3[[#This Row],[עמודה6]]/1000 -> 1219.917 | M12: =טבלה3[[#This Row],[עמודה8]]/1000 -> 852.628 | V12: 0 | X12: 0 | Y12: 0 | AA12: 16290 | AB12: 16290 | AE12: 0 | AF12: 16290 | AH12: 16290 | AI12: 16290 | AJ12: 0 | AK12: 267290 | AM12: 0 | AN12: 0 | AP12: 0 | AQ12: 16290 | AT12: 251000 | AU12: 267290 | AX12: 1065754 | AY12: 814754 | AZ12: 1082044 | BC12: 59000 | BD12: 1141044 | BF12: 834261 | BG12: 1257256 | BL12: =טבלה3[[#This Row],[עמודה6]]/1000 -> 1219.917
L13: =טבלה3[[#This Row],[עמודה6]]/1000 -> 0 | M13: =טבלה3[[#This Row],[עמודה8]]/1000 -> 0
A14: =VLOOKUP(J14,Index!A:B,2,0) -> Cost of Goods Sold | D14: =H14-BG14 -> 975934 | F14: =טבלה3[[#This Row],[עמודה6]]-AZ14 -> 975934 | H14: =-SUMIF(SAP!I:I,J14,SAP!F:F) -> 975934 | I14: 681279 | J14: 472 | L14: =טבלה3[[#This Row],[עמודה6]]/1000 -> 975.934 | M14: =טבלה3[[#This Row],[עמודה8]]/1000 -> 681.279 | U14: =טבלה3[[#This Row],[עמודה6]]/H12 -> 0.80000033 | V14: 0 | X14: 0 | Y14: 0 | AA14: 0 | AB14: 0 | AE14: 0 | AF14: 0 | AH14: 0 | AI14: 0 | AJ14: 0 | AK14: 0 | AM14: 0 | AN14: 0 | AP14: 0 | AQ14: 0 | AT14: 0 | AU14: 0 | AX14: 0 | AY14: 0 | AZ14: 0 | BC14: 0 | BD14: 0 | BF14: 0 | BG14: 0
L15: =טבלה3[[#This Row],[עמודה6]]/1000 -> 0 | M15: =טבלה3[[#This Row],[עמודה8]]/1000 -> 0
A16: Gross profit | D16: =D12-D14 -> -1013273 | E16: =E12-E14 -> 0 | F16: =F12-F14 -> -838061 | G16: =G12-G14 -> 0 | H16: =H12-H14 -> 243983 | I16: =I12-I14 -> 171349 | L16: =טבלה3[[#This Row],[עמודה6]]/1000 -> 243.983 | M16: =טבלה3[[#This Row],[עמודה8]]/1000 -> 171.349 | V16: 0 | X16: 0 | Y16: 0 | AA16: 16290 | AB16: 16290 | AE16: 0 | AF16: 16290 | AH16: 16290 | AI16: 16290 | AJ16: 0 | AK16: 267290 | AM16: 0 | AN16: 0 | AP16: 0 | AQ16: 16290 | AT16: 251000 | AU16: 267290 | AX16: 1065754 | AY16: 814754 | AZ16: 1082044 | BC16: 59000 | BD16: 1141044 | BF16: 834261 | BG16: 1257256 | BJ16: =טבלה3[[#This Row],[עמודה6]]/H12 -> 0.19999967
L17: =טבלה3[[#This Row],[עמודה6]]/1000 -> 0 | M17: =טבלה3[[#This Row],[עמודה8]]/1000 -> 0
A18: Operating expenses | L18: =טבלה3[[#This Row],[עמודה6]]/1000 -> 0 | M18: =טבלה3[[#This Row],[עמודה8]]/1000 -> 0
A19: =VLOOKUP(J19,Index!A:B,2,0) -> Research & Development | C19: 7 | D19: =H19-BG19 -> 988994 | F19: =טבלה3[[#This Row],[עמודה6]]-AZ19 -> 2580362 | H19: =-SUMIF(SAP!I:I,J19,SAP!F:F) -> 9603573 | I19: 6319935 | J19: 700 | L19: =טבלה3[[#This Row],[עמודה6]]/1000 -> 9603.573 | M19: =טבלה3[[#This Row],[עמודה8]]/1000 -> 6319.935 | V19: 680328 | X19: 670718 | Y19: 1351046 | AA19: 834423 | AB19: 4474171 | AE19: 693251 | AF19: 2878720 | AH19: 3645784 | AI19: 4474171 | AJ19: 767064 | AK19: 6049875 | AM19: 828387 | AN19: 2288702 | AP19: 738353 | AQ19: 5212524 | AT19: 837351 | AU19: 6049875 | AX19: 2549040 | AY19: 973336 | AZ19: 7023211 | BC19: 698614 | BD19: 7721825 | BF19: 892754 | BG19: 8614579
A20: =VLOOKUP(J20,Index!A:B,2,0) -> Sales & Marketing | C20: 8 | D20: =H20-BG20 -> -21361 | F20: =טבלה3[[#This Row],[עמודה6]]-AZ20 -> 274362 | H20: =-SUMIF(SAP!I:I,J20,SAP!F:F) -> 1406393 | I20: 1322914 | J20: 702 | L20: =טבלה3[[#This Row],[עמודה6]]/1000 -> 1406.393 | M20: =טבלה3[[#This Row],[עמודה8]]/1000 -> 1322.914 | V20: 102942 | X20: 98084 | Y20: 201026 | AA20: 159649 | AB20: 756638 | AE20: 160352 | AF20: 521027 | AH20: 620248 | AI20: 756638 | AJ20: 99221 | AK20: 972585 | AM20: 136390 | AN20: 395963 | AP20: 103390 | AQ20: 860028 | AT20: 112557 | AU20: 972585 | AX20: 375393 | AY20: 159446 | AZ20: 1132031 | BC20: 120805 | BD20: 1252836 | BF20: 174918 | BG20: 1427754
A21: =VLOOKUP(J21,Index!A:B,2,0) -> General & Administrative | C21: 9 | D21: =H21-BG21 -> -80108 | F21: =טבלה3[[#This Row],[עמודה6]]-AZ21 -> 223230 | H21: =-SUMIF(SAP!I:I,J21,SAP!F:F) -> 2185950 | I21: 1859794 | J21: 705 | L21: =טבלה3[[#This Row],[עמודה6]]/1000 -> 2185.95 | M21: =טבלה3[[#This Row],[עמודה8]]/1000 -> 1859.794 | V21: 147583 | X21: 452715 | Y21: 600298 | AA21: 175162 | AB21: 1259969 | AE21: 156108 | AF21: 931568 | AH21: 1089656 | AI21: 1259969 | AJ21: 158088 | AK21: 1699531 | AM21: 170313 | AN21: 484509 | AP21: 262172 | AQ21: 1522141 | AT21: 177390 | AU21: 1699531 | AX21: 702751 | AY21: 263189 | AZ21: 1962720 | BC21: 148573 | BD21: 2111293 | BF21: 154765 | BG21: 2266058
A22: ="Total "&A18 -> Total Operating expenses | D22: =SUM(D19:D21) -> 887525 | F22: =SUM(F19:F21) -> 3077954 | G22: =SUM(G19:G21) -> 0 | H22: =SUM(H19:H21) -> 13195916 | I22: =SUM(I19:I21) -> 9502643 | L22: =טבלה3[[#This Row],[עמודה6]]/1000 -> 13195.916 | M22: =טבלה3[[#This Row],[עמודה8]]/1000 -> 9502.643 | V22: 930853 | X22: 1221517 | Y22: 2152370 | AA22: 1169234 | AB22: 6490778 | AE22: 1009711 | AF22: 4331315 | AH22: 5355688 | AI22: 6490778 | AJ22: 1024373 | AK22: 8721991 | AM22: 1135090 | AN22: 3169174 | AP22: 1103915 | AQ22: 7594693 | AT22: 1127298 | AU22: 8721991 | AX22: 3627184 | AY22: 1395971 | AZ22: 10117962 | BC22: 967992 | BD22: 11085954 | BF22: 1222437 | BG22: 12308391
D23: - - - - - - - - - | F23: - - - - - - - - - | H23: - - - - - - - - - | I23: - - - - - - - - - | V23: - - - - - - - - - | X23: - - - - - - - - - | Y23: - - - - - - - - - | AA23: - - - - - - - - - | AB23: - - - - - - - - - | AE23: - - - - - - - - - | AF23: - - - - - - - - - | AH23: - - - - - - - - - | AI23: - - - - - - - - - | AJ23: - - - - - - - - - | AK23: - - - - - - - - - | AM23: - - - - - - - - - | AN23: - - - - - - - - - | AP23: - - - - - - - - - | AQ23: - - - - - - - - - | AT23: - - - - - - - - - | AU23: - - - - - - - - - | AX23: - - - - - - - - - | AY23: - - - - - - - - - | AZ23: - - - - - - - - - | BC23: - - - - - - - - - | BD23: - - - - - - - - - | BF23: - - - - - - - - - | BG23: - - - - - - - - -
A24: PROFIT (LOSS) FROM OPERATIONS | D24: =D16-D22 -> -1900798 | F24: =F16-F22 -> -3916015 | G24: =G16-G22 -> 0 | H24: =H16-H22 -> -12951933 | I24: =I16-I22 -> -9331294 | L24: =טבלה3[[#This Row],[עמודה6]]/1000 -> -12951.933 | M24: =טבלה3[[#This Row],[עמודה8]]/1000 -> -9331.294 | V24: -930853 | X24: -1221517 | Y24: -2152370 | AA24: -1152944 | AB24: -6474488 | AE24: -1009711 | AF24: -4315025 | AH24: -5339398 | AI24: -6474488 | AJ24: -1024373 | AK24: -8454701 | AM24: -1135090 | AN24: -3169174 | AP24: -1103915 | AQ24: -7578403 | AT24: -876298 | AU24: -8454701 | AX24: -2561430 | AY24: -581217 | AZ24: -9035918 | BC24: -908992 | BD24: -9944910 | BF24: -388176 | BG24: -11051135
A25: =VLOOKUP(J25,Index!A:B,2,0) -> Financial | C25: 10 | D25: =H25-BG25 -> 54384 | F25: =טבלה3[[#This Row],[עמודה6]]-AZ25 -> -810451 | H25: =-SUMIF(SAP!I:I,J25,SAP!F:F) -> -369693 | I25: 18173 | J25: 790 | L25: =טבלה3[[#This Row],[עמודה6]]/1000 -> -369.693 | M25: =טבלה3[[#This Row],[עמודה8]]/1000 -> 18.173 | V25: 9761 | X25: -48730 | Y25: -38969 | AA25: -143247 | AB25: 546178 | AE25: 265543 | AF25: 83327 | AH25: 98028 | AI25: 546178 | AJ25: 14701 | AK25: -56126 | AM25: 448150 | AN25: 728394 | AP25: -364684 | AQ25: 181494 | AT25: -237620 | AU25: -56126 | AX25: -105420 | AY25: 496884 | AZ25: 440758 | BC25: -232699 | BD25: 208059 | BF25: -632136 | BG25: -424077
A26: =VLOOKUP(J26,Index!A:B,2,0) -> Other revenues | D26: =H26-AK26 -> 0 | F26: =טבלה3[[#This Row],[עמודה6]]-AZ26 -> 0 | H26: =-SUMIF(SAP!I:I,J26,SAP!F:F) -> 0 | I26: 0 | J26: 801 | L26: =טבלה3[[#This Row],[עמודה6]]/1000 -> 0 | M26: =טבלה3[[#This Row],[עמודה8]]/1000 -> 0 | V26: 0 | X26: 0 | Y26: 0 | AA26: 0 | AB26: 0 | AE26: 0 | AF26: 0 | AH26: 0 | AI26: 0 | AJ26: 0 | AK26: 0 | AM26: 0 | AN26: 0 | AP26: 0 | AQ26: 0 | AT26: 0 | AU26: 0 | AX26: 0 | AY26: 0 | AZ26: 0 | BC26: 0 | BD26: 0 | BF26: 0 | BG26: 0
A27: =VLOOKUP(J27,Index!A:B,2,0) -> Tax Expenses | D27: =H27-V27 -> 0 | F27: =טבלה3[[#This Row],[עמודה6]]-AA27 -> 0 | H27: =SUMIF(SAP!I:I,J27,SAP!F:F) -> 0 | I27: 0 | J27: 850 | L27: =טבלה3[[#This Row],[עמודה6]]/1000 -> 0 | M27: =טבלה3[[#This Row],[עמודה8]]/1000 -> 0 | V27: 0 | X27: 0 | Y27: 0 | AA27: 0 | AB27: 0 | AE27: 0 | AF27: 0 | AH27: 0 | AI27: 0 | AJ27: 0 | AK27: 0 | AM27: 0 | AN27: 0 | AP27: 0 | AQ27: 0 | AT27: 0 | AU27: 0 | AX27: 0 | AY27: 0 | AZ27: 0 | BC27: 0 | BD27: 0 | BF27: 0 | BG27: 0
A28: NET INCOME (LOSS) | D28: =D24-D25-D27-D26 -> -1955182 | E28: =E24-E25-E27-E26 -> 0 | F28: =F24-F25-F27-F26 -> -3105564 | G28: =G24-G25-G27-G26 -> 0 | H28: =H24-H25-H27-H26 -> -12582240 | I28: =I24-I25-I27-I26 -> -9349467 | L28: =טבלה3[[#This Row],[עמודה6]]/1000 -> -12582.24 | M28: =טבלה3[[#This Row],[עמודה8]]/1000 -> -9349.467 | V28: -940614 | X28: -1172787 | Y28: -2113401 | AA28: -1009697 | AB28: -7020666 | AE28: -1275254 | AF28: -4398352 | AH28: -5437426 | AI28: -7020666 | AJ28: -1039074 | AK28: -8398575 | AM28: -1583240 | AN28: -3897568 | AP28: -739231 | AQ28: -7759897 | AT28: -638678 | AU28: -8398575 | AX28: -2456010 | AY28: -1078101 | AZ28: -9476676 | BC28: -676293 | BD28: -10152969 | BF28: 243960 | BG28: -10627058
L29: =טבלה3[[#This Row],[עמודה6]]/1000 -> 0 | M29: =טבלה3[[#This Row],[עמודה8]]/1000 -> 0
A30: Opening Retained Earnings | D30: =BG31 -> -33569267 | F30: =AX31 -> -2456010 | H30: =SUMIF(SAP!I:I,J30,SAP!F:F) -> -22942209 | I30: -13592742 | J30: 941 | L30: =טבלה3[[#This Row],[עמודה6]]/1000 -> -22942.209 | M30: =טבלה3[[#This Row],[עמודה8]]/1000 -> -13592.742 | V30: -22651833 | X30: -23592447 | Y30: -22651833 | AA30: -24765234 | AB30: -22651833 | AE30: -25774931 | AF30: -22651833 | AH30: -22651833 | AI30: -22651833 | AJ30: -27050185 | AK30: -22651833 | AM30: -28089259 | AN30: -25774931 | AP30: -29672499 | AQ30: -22651833 | AT30: -30411730 | AU30: -22651833 | BH30: =L28+טבלה3[[#This Row],[Column4]] -> -35524.449
A31: ACCUMULATED EARNINGS (LOSS) | D31: =D28+D30 -> -35524449 | F31: =F28+F30 -> -5561574 | G31: =G28+G30 -> 0 | H31: =H28+H30 -> -35524449 | I31: =I28+I30 -> -22942209 | L31: =טבלה3[[#This Row],[עמודה6]]/1000 -> -35524.449 | M31: =טבלה3[[#This Row],[עמודה8]]/1000 -> -22942.209 | V31: -23592447 | X31: -24765234 | Y31: -24765234 | AA31: -25774931 | AB31: -29672499 | AE31: -27050185 | AF31: -27050185 | AH31: -28089259 | AI31: -29672499 | AJ31: -28089259 | AK31: -31050408 | AM31: -29672499 | AN31: -29672499 | AP31: -30411730 | AQ31: -30411730 | AT31: -31050408 | AU31: -31050408 | AX31: =AX28+AX30 -> -2456010 | AY31: =AY28+AY30 -> -1078101 | AZ31: =AZ28+AZ30 -> -9476676 | BC31: -32804802 | BD31: -32804802 | BF31: -33569267 | BG31: -33569267
L32: =טבלה3[[#This Row],[עמודה6]]/1000 -> 0 | M32: =טבלה3[[#This Row],[עמודה8]]/1000 -> 0
D33: =D31-H31 -> 0 | F33: =F31-H31 -> 29962875 | H33: =H30-I31 -> 0 | L33: =טבלה3[[#This Row],[עמודה6]]/1000 -> 0 | M33: =טבלה3[[#This Row],[עמודה8]]/1000 -> 0 | AB33: 0 | AE33: 0 | AF33: 0 | AH33: 0 | AI33: 0 | AJ33: 0 | AK33: 0 | AM33: 0 | AN33: 0 | AP33: 0 | AQ33: 0 | AT33: 0 | AU33: 0 | AX33: 0 | AY33: 0 | AZ33: 0 | BC33: 0 | BD33: 0 | BF33: 0 | BG33: 0
L34: =טבלה3[[#This Row],[עמודה6]]/1000 -> 0 | M34: =טבלה3[[#This Row],[עמודה8]]/1000 -> 0 | BD34: 290376
BD35: -33095178
A40: =Companyname &" Confidential" -> Aurora Labs Consolidated Confidential

Sheet CF
A1: =Companyname -> Aurora Labs Consolidated
A2: STATEMENT OF CASH FLOW
D4: QTD | E4: YTD | F4: YTD | H4: YTD | I4: YTD | J4: YTD | K4: YTD | L4: YTD
D5: =DATE -> 44926 | E5: =DATE -> 44926 | F5: 41639 | H5: 40908 | I5: 41364 | J5: 41455 | K5: 41547 | L5: 41639
D6: =DATE -> 44926 | E6: =DATE -> 44926 | F6: 41639 | H6: 41274 | I6: 41364 | J6: 41455 | K6: 41547 | L6: 41639
D7: U.S. Dollars | E7: U.S. Dollars | F7: U.S. Dollars | H7: NIS | I7: U.S. Dollars | J7: U.S. Dollars | K7: U.S. Dollars | L7: U.S. Dollars
A8: Cash flows from operating activities
A9: Net profit (Loss) | D9: =E9-O9 -> -12582240 | E9: ='P&L'!H28 -> -12582240 | F9: -1593533 | H9: -3883878 | I9: -382921 | J9: -826690 | K9: -990570 | L9: -1367620 | N9: =E9/1000 -> -12582.24
N10: =E10/1000 -> 0
A11: Expenses not involving cash flows: | N11: =E11/1000 -> 0
A12: Depreciation | D12: =E12-O12 -> 69837 | E12: =-(BS!C20-BS!D20) -> 69837 | F12: 14414 | H12: 24802 | I12: 3254 | J12: 6753 | K12: 10525 | L12: 14414 | N12: =E12/1000 -> 69.837
A13: Compensation charged in respect of options | N13: =E13/1000 -> 0
A14: granted to employee | D14: =E14-O14 -> 1465365 | E14: ='SAP DRAFT'!D166-1625923 -> 1465365 | F14: 128525.11 | H14: 67688.211 | I14: 0 | J14: 0 | K14: 0 | L14: 0 | N14: =E14/1000 -> 1465.365
N15: =E15/1000 -> 0
A16: Changes in operating asset and liability items: | N16: =E16/1000 -> 0
A17: (Increase) Decrease in Short term deposit | E17: =-(BS!C10-BS!D10) -> -40710444
A18: (Increase) Decrease in accounts receivable | D18: =E18-O18 -> -1049802 | E18: =-(BS!C11-BS!D11) -> -1049802 | F18: 0 | H18: 0 | I18: -33597 | J18: 0 | K18: -24921 | L18: 0 | N18: =E18/1000 -> -1049.802
A19: (Increase) Decrease in other current assets | D19: =E19-O19 -> -161587 | E19: =-(BS!C12-BS!D12) -> -161587 | F19: -91109 | H19: -139291 | I19: 7263 | J19: -10095 | K19: -21052 | L19: -52665 | N19: =E19/1000 -> -161.587
A20: (Increase) Decrease in Leased property under capital lease | D20: =E20-O20 -> -225967 | E20: =-(BS!C16-BS!D16) -> -225967 | F20: 13596 | H20: -50752 | I20: -363 | J20: -522 | K20: 13596 | L20: 13596 | N20: =E20/1000 -> -225.967
A21: Increase (Decrease) in accounts payable and accruals | D21: =E21-O21 -> 75605 | E21: =BS!C28-BS!D28 -> 75605 | F21: 21250 | H21: 72729 | I21: -14603 | J21: 4632 | K21: 23063 | L21: 21250 | N21: =E21/1000 -> 75.605
A22: Increase (Decrease) in obligation under capital lease | E22: =(BS!C27-BS!D27)+(BS!C35-BS!D35) -> 224490
A23: Increase (Decrease) in other liabilities | D23: =E23-O23 -> 128804 | E23: =(BS!C29-BS!D29) -> 128804 | F23: 36658 | H23: 515653 | I23: 8584 | J23: 25970 | K23: 15427 | L23: 36658 | N23: =E23/1000 -> 128.804
D24: =SUM(D9:D23) -> -12279985 | E24: =SUM(E9:E23) -> -52765939 | F24: -1470198.9 | H24: -3393048.8 | I24: -411781 | J24: -799952 | K24: -973932 | L24: -1334367 | N24: =E24/1000 -> -52765.939
D25: - - - - - - - - | E25: - - - - - - - - | F25: - - - - - - - - | H25: - - - - - - - - | I25: - - - - - - - - | J25: - - - - - - - - | K25: - - - - - - - - | L25: - - - - - - - -
A26: Cash flows from investing activities | N26: =E26/1000 -> 0
A27: Purchase of fixed assets | D27: =E27-O27 -> -99975 | E27: =-(BS!C19-BS!D19) -> -99975 | F27: -9766 | H27: -188915 | I27: 0 | J27: -6975 | K27: -9104 | L27: -9766 | N27: =E27/1000 -> -99.975
A28: (Increase)Decrease in Share capital | E28: =BS!C39-BS!D39 -> 349 | N28: =E28/1000 -> 0.349
D29: =SUM(D27:D27) -> -99975 | E29: =SUM(E27:E28) -> -99626 | F29: -9766 | H29: -188915 | I29: 0 | J29: -6975 | K29: -9104 | L29: -9766 | N29: =E29/1000 -> -99.626
D30: - - - - - - - - | E30: - - - - - - - - | F30: - - - - - - - - | H30: - - - - - - - - | I30: - - - - - - - - | J30: - - - - - - - - | K30: - - - - - - - - | L30: - - - - - - - -
A31: Total Cash Outflow before financing | D31: =D24-D29 -> -12180010 | E31: =E24-E29 -> -52666313 | F31: -1460432.9 | H31: -3204133.8 | I31: -411781 | J31: -792977 | K31: -964828 | L31: -1324601 | N31: =E31/1000 -> -52666.313
A33: Cash flows from financing activities | N33: =E33/1000 -> 0
A34: Proceeds from Additional paid-in capital | D34: =E34-O34 -> 60244409 | E34: =BS!C40-BS!D40-E14 -> 60244409 | F34: 2085661.9 | H34: 7539834.8 | I34: =1266776+602 -> 1267378 | J34: 1949830 | K34: 1949830 | L34: 1949830 | N34: =E34/1000 -> 60244.409
D35: =SUM(D34:D34) -> 60244409 | E35: =SUM(E34:E34) -> 60244409 | F35: 2085661.9 | H35: 7319834.8 | I35: 1266776 | J35: 1949830 | K35: 1949830 | L35: 1949830 | N35: =E35/1000 -> 60244.409
D36: - - - - - - - - | E36: - - - - - - - - | F36: - - - - - - - - | H36: - - - - - - - - | I36: - - - - - - - - | J36: - - - - - - - - | K36: - - - - - - - - | L36: - - - - - - - -
A37: Increase(decrease) in cash and cash equivalents | D37: =SUM(D35,D29,D24) -> 47864449 | E37: =SUM(E35,E29,E24) -> 7378844 | F37: 605697 | H37: 3737871 | I37: 854995 | J37: 1142903 | K37: 966794 | L37: 605697 | N37: =E37/1000 -> 7378.844
A38: Cash and cash equivalents at beginning of period | D38: =O39 -> 0 | E38: =BS!D9 -> 13400932 | F38: 1003375 | H38: 7725 | I38: 1003375 | J38: 1003375 | K38: 1003375 | L38: 1003375 | N38: =E38/1000 -> 13400.932
A39: Cash and cash equivalents at end of period | D39: =SUM(D37:D38) -> 47864449 | E39: =SUM(E37:E38) -> 20779776 | F39: 1609072 | H39: 3745596 | I39: 1858370 | J39: 2146278 | K39: 1970169 | L39: 1609072 | N39: =E39/1000 -> 20779.776
D40: =ROUND(D39-BS!$C$9,0) -> 27084673 | E40: =ROUND(E39-BS!$C$9,0) -> 0 | F40: =ROUND(F39-BS!#REF!,0) -> #REF! | N40: =E40/1000 -> 0
N41: =E41/1000 -> 0
N42: =E42/1000 -> 0
...

Sheet NotesBS
A1: =Companyname -> Aurora Labs Consolidated | E1: INDEX
A2: NOTES TO FINANCIAL STATEMENTS
A4: Note 1 - Cash and Cash Equivalents
C5: =DATE -> 44926 | D5: 43830 | G5: 44592 | I5: 44620 | K5: 44651 | M5: 44681 | Q5: 44712 | T5: 44742 | V5: 44773 | X5: 44804 | Z5: 44834 | AC5: 44865 | AF5: 44895
C6: =DATE -> 44926 | D6: =CompareDATE -> 44561 | G6: 44592 | I6: 44620 | K6: 44651 | M6: 44681 | Q6: 44712 | T6: 44742 | V6: 44773 | X6: 44804 | Z6: 44834 | AC6: 44865 | AF6: 44895
C7: U.S. Dollars | D7: U.S. Dollars | G7: U.S. Dollars | I7: U.S. Dollars | K7: U.S. Dollars | M7: U.S. Dollars | Q7: U.S. Dollars | T7: U.S. Dollars | V7: U.S. Dollars | X7: U.S. Dollars | Z7: U.S. Dollars | AC7: U.S. Dollars | AF7: U.S. Dollars
A9: =VLOOKUP(E9,Index!A:B,2,0) -> Israeli currency | C9: =-SUMIF(SAP!A:A,E9,SAP!F:F) -> 12486866 | D9: 71138 | E9: 1302 | G9: 1289860 | I9: 5084457 | K9: 6532473 | M9: 6433363 | Q9: 8394078 | T9: 12995838 | V9: 12635288 | X9: 11911901 | Z9: 13916155 | AC9: 14186857 | AF9: 13684763 | AI9: =C9/1000 -> 12486.866 | AJ9: =D9/1000 -> 71.138
A10: =VLOOKUP(E10,Index!A:B,2,0) -> USD currency | C10: =-SUMIF(SAP!A:A,E10,SAP!F:F) -> 8290712 | D10: 13327078 | E10: 1304 | G10: 11220739 | I10: 6553208 | K10: 4009069 | M10: 2717223 | Q10: 29571 | T10: 54347641 | V10: 56879436 | X10: 53932390 | Z10: 50288980 | AC10: 49245779 | AF10: 49106881 | AI10: =C10/1000 -> 8290.712 | AJ10: =D10/1000 -> 13327.078
A11: =VLOOKUP(E11,Index!A:B,2,0) -> EURO currency | C11: =-SUMIF(SAP!A:A,E11,SAP!F:F) -> 2198 | D11: 2716 | E11: 1307 | G11: 2677 | I11: 2688 | K11: 2662 | M11: 2541 | Q11: 2570 | T11: 2527 | V11: 2489 | X11: 6798 | Z11: 2133 | AC11: 2148 | AF11: 2245 | AI11: =C11/1000 -> 2.198 | AJ11: =D11/1000 -> 2.716
C12: =SUM(C9:C11) -> 20779776 | D12: =SUM(D9:D11) -> 13400932 | G12: 12513276 | I12: 11640353 | K12: 10544204 | M12: 9153127 | Q12: 8426219 | T12: 67346006 | V12: 69517213 | X12: 65851089 | Z12: 64207268 | AC12: 63434784 | AF12: 62793889 | AI12: =C12/1000 -> 20779.776 | AJ12: =D12/1000 -> 13400.932
C13: =C12-BS!C9 -> 0 | D13: =D12-BS!D9 -> 0 | I13: 0 | K13: 0 | M13: 0 | Q13: 0 | T13: 0 | V13: 0 | X13: 0 | Z13: 0 | AC13: 0 | AF13: 0 | AI13: =C13/1000 -> 0 | AJ13: =D13/1000 -> 0
AI14: =C14/1000 -> 0 | AJ14: =D14/1000 -> 0
A15: Note 2 - Other current assets | AI15: =C15/1000 -> 0 | AJ15: =D15/1000 -> 0
C16: =DATE -> 44926 | D16: 43830 | G16: 44592 | I16: 44620 | K16: 44651 | M16: 44681 | Q16: 44712 | T16: 44742 | V16: 44773 | X16: 44804 | Z16: 44834 | AC16: 44865 | AF16: 44895 | AI16: =C16/1000 -> 44.926 | AJ16: =D16/1000 -> 43.83
C17: =DATE -> 44926 | D17: =CompareDATE -> 44561 | G17: 44592 | I17: 44620 | K17: 44651 | M17: 44681 | Q17: 44712 | T17: 44742 | V17: 44773 | X17: 44804 | Z17: 44834 | AC17: 44865 | AF17: 44895 | AI17: =C17/1000 -> 44.926 | AJ17: =D17/1000 -> 44.561
C18: U.S. Dollars | D18: U.S. Dollars | G18: U.S. Dollars | I18: U.S. Dollars | K18: U.S. Dollars | M18: U.S. Dollars | Q18: U.S. Dollars | T18: U.S. Dollars | V18: U.S. Dollars | X18: U.S. Dollars | Z18: U.S. Dollars | AC18: U.S. Dollars | AF18: U.S. Dollars | AI18: =C18/1000 -> #VALUE! | AJ18: =D18/1000 -> #VALUE!
A19: =VLOOKUP(E19,Index!A:B,2,0) -> Related company | C19: =-SUMIF(SAP!A:A,E19,SAP!F:F) -> 0 | D19: 0 | E19: 1351 | G19: 0 | I19: 0 | K19: 0 | M19: 0 | Q19: 0 | T19: 0 | V19: 0 | X19: 0 | Z19: 0 | AC19: 0 | AF19: 0 | AI19: =C19/1000 -> 0 | AJ19: =D19/1000 -> 0
A20: =VLOOKUP(E20,Index!A:B,2,0) -> Prepaid expenses | C20: =-SUMIF(SAP!A:A,E20,SAP!F:F) -> 127522 | D20: 2991 | E20: 1354 | G20: 2243 | I20: 47900 | K20: 99389 | M20: 129793 | Q20: 118889 | T20: 104362 | V20: 176260 | X20: 162798 | Z20: 89627 | AC20: 121449 | AF20: 114876 | AI20: =C20/1000 -> 127.522 | AJ20: =D20/1000 -> 2.991
A21: =VLOOKUP(E21,Index!A:B,2,0) -> Guaranty deposits | C21: =-SUMIF(SAP!A:A,E21,SAP!F:F) -> 22131 | D21: 23879 | E21: 1355 | G21: 23244 | I21: 22935 | K21: 23383 | M21: 22389 | Q21: 22248 | T21: 21218 | V21: 22966 | X21: 23310 | Z21: 21981 | AC21: 22062 | AF21: 22633 | AI21: =C21/1000 -> 22.131 | AJ21: =D21/1000 -> 23.879
A22: =VLOOKUP(E22,Index!A:B,2,0) -> Income tax | C22: =-SUMIF(SAP!A:A,E22,SAP!F:F) -> 0 | D22: 660 | E22: 1356 | G22: 19430 | I22: 18893 | K22: 22401 | M22: 22954 | Q22: 22817 | T22: 24354 | V22: 26607 | X22: 28499 | Z22: 26877 | AC22: 26977 | AF22: 11625 | AI22: =C22/1000 -> 0 | AJ22: =D22/1000 -> 0.66
A23: =VLOOKUP(E23,Index!A:B,2,0) -> VAT | C23: =-SUMIF(SAP!A:A,E23,SAP!F:F) -> 55725 | D23: 19813 | E23: 1357 | G23: 32131 | I23: 40232 | K23: 31855 | M23: 45790 | Q23: 13889 | T23: 16151 | V23: 40821 | X23: 66206 | Z23: 62024 | AC23: 52789 | AF23: 42811 | AI23: =C23/1000 -> 55.725 | AJ23: =D23/1000 -> 19.813
A24: =VLOOKUP(E24,Index!A:B,2,0) -> Other | C24: =-SUMIF(SAP!A:A,E24,SAP!F:F) -> 3552 | D24: 0 | E24: 1358 | G24: 0 | I24: 13897 | K24: 11020 | M24: 10552 | Q24: 8987 | T24: 7143 | V24: 13270 | X24: 11223 | Z24: 351205 | AC24: 349112 | AF24: 4359 | AI24: =C24/1000 -> 3.552 | AJ24: =D24/1000 -> 0
C25: =SUM(C19:C24) -> 208930 | D25: =SUM(D20:D24) -> 47343 | G25: 77048 | I25: 143857 | K25: 188048 | M25: 231478 | Q25: 186830 | T25: 173228 | V25: 279924 | X25: 292036 | Z25: 551714 | AC25: 572389 | AF25: 196304 | AI25: =C25/1000 -> 208.93 | AJ25: =D25/1000 -> 47.343
C26: =C25-BS!C12 -> 0 | D26: =D25-BS!D12 -> 0 | M26: 0 | Q26: 0 | T26: 0 | V26: 0 | X26: 0 | Z26: 0 | AC26: 0 | AF26: 0 | AI26: =C26/1000 -> 0 | AJ26: =D26/1000 -> 0
AI27: =C27/1000 -> 0 | AJ27: =D27/1000 -> 0
A28: Note 3 - Fixed assets, gross | AI28: =C28/1000 -> 0 | AJ28: =D28/1000 -> 0
C29: =DATE -> 44926 | D29: 43830 | G29: 44592 | I29: 44620 | K29: 44651 | M29: 44681 | Q29: 44712 | T29: 44742 | V29: 44773 | X29: 44804 | Z29: 44834 | AC29: 44865 | AF29: 44895 | AI29: =C29/1000 -> 44.926 | AJ29: =D29/1000 -> 43.83
C30: =DATE -> 44926 | D30: =CompareDATE -> 44561 | G30: 44592 | I30: 44620 | K30: 44651 | M30: 44681 | Q30: 44712 | T30: 44742 | V30: 44773 | X30: 44804 | Z30: 44834 | AC30: 44865 | AF30: 44895 | AI30: =C30/1000 -> 44.926 | AJ30: =D30/1000 -> 44.561
C31: U.S. Dollars | D31: U.S. Dollars | G31: U.S. Dollars | I31: U.S. Dollars | K31: U.S. Dollars | M31: U.S. Dollars | Q31: U.S. Dollars | T31: U.S. Dollars | V31: U.S. Dollars | X31: U.S. Dollars | Z31: U.S. Dollars | AC31: U.S. Dollars | AF31: U.S. Dollars | AI31: =C31/1000 -> #VALUE! | AJ31: =D31/1000 -> #VALUE!
A32: =VLOOKUP(E32,Index!A:B,2,0) -> Furniture & Fixtures General | C32: =-SUMIF(SAP!A:A,E32,SAP!F:F) -> 17471 | D32: 14486 | E32: 1903 | G32: 15050 | I32: 15541 | K32: 15541 | M32: 15541 | Q32: 15541 | T32: 15541 | V32: 15555 | X32: 17471 | Z32: 17471 | AC32: 17471 | AF32: 17471 | AI32: =C32/1000 -> 17.471 | AJ32: =D32/1000 -> 14.486
A33: =VLOOKUP(E33,Index!A:B,2,0) -> Computers & Software | C33: =-SUMIF(SAP!A:A,E33,SAP!F:F) -> 344827 | D33: 253167 | E33: 1901 | G33: 265468 | I33: 269340 | K33: 286745 | M33: 286745 | Q33: 286745 | T33: 295539 | V33: 297342 | X33: 316555 | Z33: 318058 | AC33: 327092 | AF33: 327092 | AI33: =C33/1000 -> 344.827 | AJ33: =D33/1000 -> 253.167
A34: =VLOOKUP(E34,Index!A:B,2,0) -> Electronic equipment | C34: =-SUMIF(SAP!A:A,E34,SAP!F:F) -> 24544 | D34: 19214 | E34: 1904 | G34: 19214 | I34: 19216 | K34: 19216 | M34: 19216 | Q34: 19216 | T34: 19216 | V34: 20213 | X34: 23516 | Z34: 23516 | AC34: 23516 | AF34: 23516 | AI34: =C34/1000 -> 24.544 | AJ34: =D34/1000 -> 19.214
C35: =SUM(C31:C34) -> 386842 | D35: =SUM(D32:D34) -> 286867 | G35: 299732 | I35: 304097 | K35: 321502 | M35: 321502 | Q35: 321502 | T35: 330296 | V35: 333110 | X35: 357542 | Z35: 359045 | AC35: 368079 | AF35: 368079 | AI35: =C35/1000 -> 386.842 | AJ35: =D35/1000 -> 286.867
C36: =C35-BS!C19 -> 0 | D36: =D35-BS!D19 -> 0 | M36: 0 | Q36: 0 | T36: 0 | V36: 0 | X36: 0 | Z36: 0 | AC36: 0 | AF36: 0 | AI36: =C36/1000 -> 0 | AJ36: =D36/1000 -> 0
AI37: =C37/1000 -> 0 | AJ37: =D37/1000 -> 0
A38: Note 4 - Accounts payable | AI38: =C38/1000 -> 0 | AJ38: =D38/1000 -> 0
C39: =DATE -> 44926 | D39: 43830 | G39: 44592 | I39: 44620 | K39: 44651 | M39: 44681 | Q39: 44712 | T39: 44742 | V39: 44773 | X39: 44804 | Z39: 44834 | AC39: 44865 | AF39: 44895
C40: =DATE -> 44926 | D40: =CompareDATE -> 44561 | G40: 44592 | I40: 44620 | K40: 44651 | M40: 44681 | Q40: 44712 | T40: 44742 | V40: 44773 | X40: 44804 | Z40: 44834 | AC40: 44865 | AF40: 44895
C41: U.S. Dollars | D41: U.S. Dollars | G41: U.S. Dollars | I41: U.S. Dollars | K41: U.S. Dollars | M41: U.S. Dollars | Q41: U.S. Dollars | T41: U.S. Dollars | V41: U.S. Dollars | X41: U.S. Dollars | Z41: U.S. Dollars | AC41: U.S. Dollars | AF41: U.S. Dollars
A42: =VLOOKUP(E42,Index!A:B,2,0) -> Accounts payable | C42: =SUMIF(SAP!A:A,E42,SAP!F:F) -> 129249 | D42: 60901 | E42: 2652 | G42: 91049 | I42: 432673 | K42: 140429 | M42: 117470 | Q42: 56416 | T42: 61330 | V42: 2805995 | X42: 154647 | Z42: 166345 | AC42: 143862 | AF42: 88743 | AI42: =C42/1000 -> 129.249 | AJ42: =D42/1000 -> 60.901
...

Sheet NotesP&L
A1: =Companyname -> Aurora Labs Consolidated | H1: INDEX
A2: NOTES TO FINANCIAL STATEMENTS
A4: Note 7 - Research & Development
B5: MTD | D5: QTD | F5: YTD | G5: YTD | J5: YTD | L5: MTD | M5: YTD | O5: MTD | P5: YTD | R5: MTD | S5: YTD | U5: YTD | V5: YTD | W5: MTD | X5: YTD | Y5: MTD | Z5: QTD | AC5: MTD | AD5: YTD | AF5: MTD | AG5: YTD | AH5: MTD | AI5: QTD | AJ5: YTD | AL5: MTD | AM5: YTD | AQ5: MTD | AR5: YTD
B6: =DATE -> 44926 | D6: =DATE -> 44926 | F6: =DATE -> 44926 | G6: 43830 | J6: 44592 | L6: 44620 | M6: 44620 | O6: 44651 | P6: 44742 | R6: 44681 | S6: 44681 | U6: 44712 | V6: 44742 | W6: 44712 | X6: 44804 | Y6: 44742 | Z6: 44742 | AC6: 44773 | AD6: 44773 | AF6: 44804 | AG6: 44804 | AH6: 44834 | AI6: 44834 | AJ6: 44834 | AL6: 44865 | AM6: 44865 | AQ6: 44895 | AR6: 44895
B7: =DATE -> 44926 | D7: =DATE -> 44926 | F7: =DATE -> 44926 | G7: =CompareDATE -> 44561 | J7: 44592 | L7: 44620 | M7: 44620 | O7: 44651 | P7: 44742 | R7: 44681 | S7: 44681 | U7: 44712 | V7: 44742 | W7: 44712 | X7: 44804 | Y7: 44742 | Z7: 44742 | AC7: 44773 | AD7: 44773 | AF7: 44804 | AG7: 44804 | AH7: 44834 | AI7: 44834 | AJ7: 44834 | AL7: 44865 | AM7: 44865 | AQ7: 44895 | AR7: 44895
B8: U.S. Dollars | D8: U.S. Dollars | F8: U.S. Dollars | G8: U.S. Dollars | J8: U.S. Dollars | L8: U.S. Dollars | M8: U.S. Dollars | O8: U.S. Dollars | P8: U.S. Dollars | R8: U.S. Dollars | S8: U.S. Dollars | U8: U.S. Dollars | V8: U.S. Dollars | W8: U.S. Dollars | X8: U.S. Dollars | Y8: U.S. Dollars | Z8: U.S. Dollars | AC8: U.S. Dollars | AD8: U.S. Dollars | AF8: U.S. Dollars | AG8: U.S. Dollars | AH8: U.S. Dollars | AI8: U.S. Dollars | AJ8: U.S. Dollars | AL8: U.S. Dollars | AM8: U.S. Dollars | AQ8: U.S. Dollars | AR8: U.S. Dollars
A10: =VLOOKUP(H10,Index!A:B,2,0) -> Salaries and social benefits | B10: =טבלה5[[#This Row],[עמודה4]]-AR10 -> 845679 | D10: =טבלה5[[#This Row],[עמודה4]]-AJ10 -> 2107456 | F10: =-SUMIF(SAP!A:A,H10,SAP!F:F) -> 7823748 | G10: 4719388 | H10: 7000 | J10: 556984 | L10: 555255 | M10: 1112239 | O10: 716439 | P10: 3683897 | R10: 547781 | S10: 2376459 | U10: 2999454 | V10: 3683897 | W10: 622995 | X10: 4959416 | Y10: 684443 | Z10: 1855219 | AC10: 617593 | AD10: 4301490 | AF10: 657926 | AG10: 4959416 | AH10: 756876 | AI10: 2032395 | AJ10: 5716292 | AL10: 588857 | AM10: 6305149 | AQ10: 672920 | AR10: 6978069 | AX10: =טבלה5[[#This Row],[עמודה4]]/1000 -> 7823.748 | AY10: =טבלה5[[#This Row],[עמודה4]]/1000 -> 7823.748
A11: =VLOOKUP(H11,Index!A:B,2,0) -> Outsourcing & Consultation | B11: =טבלה5[[#This Row],[עמודה4]]-AR11 -> 113996 | D11: =טבלה5[[#This Row],[עמודה4]]-AJ11 -> 351588 | F11: =-SUMIF(SAP!A:A,H11,SAP!F:F) -> 1267597 | G11: 1174376 | H11: 7001 | J11: 99768 | L11: 98284 | M11: 198052 | O11: 97146 | P11: 623169 | R11: 115746 | S11: 410944 | U11: 513602 | V11: 623169 | W11: 102658 | X11: 805805 | Y11: 109567 | Z11: 327971 | AC11: 80334 | AD11: 703503 | AF11: 102302 | AG11: 805805 | AH11: 110204 | AI11: 292840 | AJ11: 916009 | AL11: 88950 | AM11: 1004959 | AQ11: 148642 | AR11: 1153601 | AX11: =טבלה5[[#This Row],[עמודה4]]/1000 -> 1267.597 | AY11: =טבלה5[[#This Row],[עמודה4]]/1000 -> 1267.597
A12: =VLOOKUP(H12,Index!A:B,2,0) -> Communication & Computer Maintenance | B12: =טבלה5[[#This Row],[עמודה4]]-AR12 -> 29319 | D12: =טבלה5[[#This Row],[עמודה4]]-AJ12 -> 121318 | F12: =-SUMIF(SAP!A:A,H12,SAP!F:F) -> 512228 | G12: 426171 | H12: 7002 | J12: 23576 | L12: 17179 | M12: 40755 | O12: 20838 | P12: 167105 | R12: 29724 | S12: 91317 | U12: 132728 | V12: 167105 | W12: 41411 | X12: 284654 | Y12: 34377 | Z12: 105512 | AC12: 40426 | AD12: 207531 | AF12: 77123 | AG12: 284654 | AH12: 106256 | AI12: 223805 | AJ12: 390910 | AL12: 20807 | AM12: 411717 | AQ12: 71192 | AR12: 482909 | AX12: =טבלה5[[#This Row],[עמודה4]]/1000 -> 512.228 | AY12: =טבלה5[[#This Row],[עמודה4]]/1000 -> 512.228
A13: =VLOOKUP(H13,Index!A:B,2,0) -> Travel Abroad | B13: =F13-J13 -> 0 | F13: =-SUMIF(SAP!A:A,H13,SAP!F:F) -> 0 | H13: 7007 | J13: 0 | L13: 0 | M13: 0 | O13: 0 | P13: 0 | R13: 0 | S13: 0 | U13: 0 | V13: 0 | W13: 0 | X13: 0 | Y13: 0 | AC13: 0 | AD13: 0 | AF13: 0 | AG13: 0 | AH13: 0 | AJ13: 0 | AL13: 0 | AM13: 0 | AQ13: 0 | AR13: 0 | AX13: =טבלה5[[#This Row],[עמודה4]]/1000 -> 0 | AY13: =טבלה5[[#This Row],[עמודה4]]/1000 -> 0
B14: =SUM(B10:B13) -> 988994 | C14: =SUM(C10:C13) -> 0 | D14: =SUM(D10:D13) -> 2580362 | F14: =SUM(F10:F13) -> 9603573 | G14: =SUM(G10:G13) -> 6319935 | J14: 680328 | L14: 670718 | M14: 1351046 | O14: 834423 | P14: 4474171 | R14: 693251 | S14: 2878720 | U14: 3645784 | V14: 4474171 | W14: 767064 | X14: 6049875 | Y14: 828387 | Z14: 2288702 | AC14: 738353 | AD14: 5212524 | AF14: 837351 | AG14: 6049875 | AH14: 973336 | AI14: 2549040 | AJ14: 7023211 | AL14: 698614 | AM14: 7721825 | AQ14: 892754 | AR14: 8614579 | AX14: =טבלה5[[#This Row],[עמודה4]]/1000 -> 9603.573 | AY14: =טבלה5[[#This Row],[עמודה4]]/1000 -> 9603.573
B15: =B14-'P&L'!D19 -> 0 | D15: =D14-'P&L'!F19 -> 0 | F15: =F14-'P&L'!H19 -> 0 | G15: =G14-'P&L'!I19 -> 0 | P15: 0 | S15: 0 | U15: 0 | V15: 0 | W15: 0 | X15: 0 | Y15: 0 | Z15: 0 | AC15: 0 | AD15: 0 | AF15: 0 | AG15: 0 | AH15: 0 | AI15: 0 | AJ15: 0 | AL15: 0 | AM15: 0 | AQ15: 0 | AR15: 0 | AX15: =טבלה5[[#This Row],[עמודה4]]/1000 -> 0 | AY15: =טבלה5[[#This Row],[עמודה4]]/1000 -> 0
AX16: =טבלה5[[#This Row],[עמודה4]]/1000 -> 0 | AY16: =טבלה5[[#This Row],[עמודה4]]/1000 -> 0
A17: Note 8 - Sales & Marketing | AX17: =טבלה5[[#This Row],[עמודה4]]/1000 -> 0 | AY17: =טבלה5[[#This Row],[עמודה4]]/1000 -> 0
B18: =B5 -> MTD | D18: QTD | F18: YTD | G18: YTD | J18: YTD | L18: MTD | M18: YTD | O18: MTD | P18: YTD | R18: MTD | S18: YTD | U18: YTD | V18: YTD | W18: MTD | X18: YTD | Y18: MTD | Z18: QTD | AC18: MTD | AD18: YTD | AF18: MTD | AG18: YTD | AH18: MTD | AI18: QTD | AJ18: YTD | AL18: MTD | AM18: YTD | AQ18: MTD | AR18: YTD
B19: =DATE -> 44926 | D19: =DATE -> 44926 | F19: =DATE -> 44926 | G19: 43830 | J19: 44592 | L19: 44620 | M19: 44620 | O19: 44651 | P19: 44742 | R19: 44681 | S19: 44681 | U19: 44712 | V19: 44742 | W19: 44712 | X19: 44804 | Y19: 44742 | Z19: 44742 | AC19: 44773 | AD19: 44773 | AF19: 44804 | AG19: 44804 | AH19: 44834 | AI19: 44834 | AJ19: 44834 | AL19: 44865 | AM19: 44865 | AQ19: 44895 | AR19: 44895
B20: =DATE -> 44926 | D20: =DATE -> 44926 | F20: =DATE -> 44926 | G20: =CompareDATE -> 44561 | J20: 44592 | L20: 44620 | M20: 44620 | O20: 44651 | P20: 44742 | R20: 44681 | S20: 44681 | U20: 44712 | V20: 44742 | W20: 44712 | X20: 44804 | Y20: 44742 | Z20: 44742 | AC20: 44773 | AD20: 44773 | AF20: 44804 | AG20: 44804 | AH20: 44834 | AI20: 44834 | AJ20: 44834 | AL20: 44865 | AM20: 44865 | AQ20: 44895 | AR20: 44895
B21: U.S. Dollars | D21: U.S. Dollars | F21: U.S. Dollars | G21: U.S. Dollars | J21: U.S. Dollars | L21: U.S. Dollars | M21: U.S. Dollars | O21: U.S. Dollars | P21: U.S. Dollars | R21: U.S. Dollars | S21: U.S. Dollars | U21: U.S. Dollars | V21: U.S. Dollars | W21: U.S. Dollars | X21: U.S. Dollars | Y21: U.S. Dollars | Z21: U.S. Dollars | AC21: U.S. Dollars | AD21: U.S. Dollars | AF21: U.S. Dollars | AG21: U.S. Dollars | AH21: U.S. Dollars | AI21: U.S. Dollars | AJ21: U.S. Dollars | AL21: U.S. Dollars | AM21: U.S. Dollars | AQ21: U.S. Dollars | AR21: U.S. Dollars
A22: =VLOOKUP(H22,Index!A:B,2,0) -> Salaries and social benefits | B22: =טבלה5[[#This Row],[עמודה4]]-AR22 -> -136286 | D22: =טבלה5[[#This Row],[עמודה4]]-AJ22 -> 4244 | F22: =-SUMIF(SAP!A:A,H22,SAP!F:F) -> 639847 | G22: 873229 | H22: 7020 | J22: 57074 | L22: 57576 | M22: 114650 | O22: 104488 | P22: 423716 | R22: 52542 | S22: 271680 | U22: 321569 | V22: 423716 | W22: 49889 | X22: 522265 | Y22: 102147 | Z22: 204578 | AC22: 53348 | AD22: 477064 | AF22: 45201 | AG22: 522265 | AH22: 113338 | AI22: 211887 | AJ22: 635603 | AL22: 59805 | AM22: 695408 | AQ22: 80725 | AR22: 776133 | AX22: =טבלה5[[#This Row],[עמודה4]]/1000 -> 639.847 | AY22: =טבלה5[[#This Row],[עמודה4]]/1000 -> 639.847
A23: =VLOOKUP(H23,Index!A:B,2,0) -> Marketing exepences | B23: =טבלה5[[#This Row],[עמודה4]]-AR23 -> 48402 | D23: =טבלה5[[#This Row],[עמודה4]]-AJ23 -> 142440 | F23: =-SUMIF(SAP!A:A,H23,SAP!F:F) -> 471153 | G23: 327480 | H23: 7021 | J23: 34927 | L23: 31174 | M23: 66101 | O23: 46352 | P23: 196784 | R23: 33730 | S23: 146183 | U23: 181038 | V23: 196784 | W23: 34855 | X23: 295018 | Y23: 15746 | Z23: 84331 | AC23: 46614 | AD23: 243398 | AF23: 51620 | AG23: 295018 | AH23: 33695 | AI23: 131929 | AJ23: 328713 | AL23: 38444 | AM23: 367157 | AQ23: 55594 | AR23: 422751 | AX23: =טבלה5[[#This Row],[עמודה4]]/1000 -> 471.153 | AY23: =טבלה5[[#This Row],[עמודה4]]/1000 -> 471.153
A24: =VLOOKUP(H24,Index!A:B,2,0) -> Conference and shows | B24: =טבלה5[[#This Row],[עמודה4]]-AR24 -> 27054 | D24: =טבלה5[[#This Row],[עמודה4]]-AJ24 -> 49686 | F24: =-SUMIF(SAP!A:A,H24,SAP!F:F) -> 75712 | G24: 16541 | H24: 7022 | J24: =-SUMIF(SAP!E:E,L24,SAP!J:J) -> 0 | L24: 0 | M24: 0 | O24: 0 | P24: 24411 | R24: 16699 | S24: 16699 | U24: 17844 | V24: 24411 | W24: 1145 | X24: 25332 | Y24: 6567 | Z24: 24411 | AC24: -3838 | AD24: 20573 | AF24: 4759 | AG24: 25332 | AH24: 694 | AI24: 1615 | AJ24: 26026 | AL24: 9219 | AM24: 35245 | AQ24: 13413 | AR24: 48658 | AX24: =טבלה5[[#This Row],[עמודה4]]/1000 -> 75.712 | AY24: =טבלה5[[#This Row],[עמודה4]]/1000 -> 75.712
A25: =VLOOKUP(H25,Index!A:B,2,0) -> Subcontructors GMBH | B25: =טבלה5[[#This Row],[עמודה4]]-AR25 -> 0 | D25: =טבלה5[[#This Row],[עמודה4]]-AJ25 -> 0 | F25: =-SUMIF(SAP!A:A,H25,SAP!F:F) -> 0 | G25: 0 | H25: 7023 | J25: =-SUMIF(SAP!E:E,L25,SAP!J:J) -> 0 | L25: 0 | M25: 0 | O25: 0 | P25: 0 | R25: 0 | S25: 0 | U25: 0 | V25: 0 | W25: 0 | X25: 0 | Y25: 0 | Z25: 0 | AC25: 0 | AD25: 0 | AF25: 0 | AG25: 0 | AH25: 0 | AI25: 0 | AJ25: 0 | AL25: 0 | AM25: 0 | AQ25: 0 | AR25: 0 | AX25: =טבלה5[[#This Row],[עמודה4]]/1000 -> 0 | AY25: =טבלה5[[#This Row],[עמודה4]]/1000 -> 0
A26: =VLOOKUP(H26,Index!A:B,2,0) -> Other expenses | B26: =טבלה5[[#This Row],[עמודה4]]-AR26 -> 8635 | D26: =טבלה5[[#This Row],[עמודה4]]-AJ26 -> 8777 | F26: =-SUMIF(SAP!A:A,H26,SAP!F:F) -> 10194 | G26: 2566 | H26: 7028 | J26: =-SUMIF(SAP!E:E,L26,SAP!J:J) -> 0 | L26: 290 | M26: 290 | O26: 338 | P26: 4342 | R26: -29 | S26: 599 | U26: 971 | V26: 4342 | W26: 372 | X26: 1131 | Y26: 3371 | Z26: 3714 | AC26: 9973 | AD26: 14315 | AF26: -13184 | AG26: 1131 | AH26: 286 | AI26: -2925 | AJ26: 1417 | AL26: 10 | AM26: 1427 | AQ26: 132 | AR26: 1559 | AX26: =טבלה5[[#This Row],[עמודה4]]/1000 -> 10.194 | AY26: =טבלה5[[#This Row],[עמודה4]]/1000 -> 10.194
A27: =VLOOKUP(H27,Index!A:B,2,0) -> Travel Abroad | B27: =טבלה5[[#This Row],[עמודה4]]-AR27 -> 793 | D27: =טבלה5[[#This Row],[עמודה4]]-AJ27 -> 1088 | F27: =-SUMIF(SAP!A:A,H27,SAP!F:F) -> 6688 | G27: 2452 | H27: 7025 | J27: 0 | L27: 0 | M27: 0 | O27: 0 | P27: 0 | R27: 0 | S27: 0 | U27: 0 | V27: 0 | W27: 0 | X27: 5826 | Y27: 0 | Z27: 0 | AC27: 5826 | AD27: 5826 | AF27: 0 | AG27: 5826 | AH27: -226 | AI27: 5600 | AJ27: 5600 | AL27: 40 | AM27: 5640 | AQ27: 255 | AR27: 5895 | AX27: =טבלה5[[#This Row],[עמודה4]]/1000 -> 6.688 | AY27: =טבלה5[[#This Row],[עמודה4]]/1000 -> 6.688
A28: =VLOOKUP(H28,Index!A:B,2,0) -> Creative & branding | B28: =טבלה5[[#This Row],[עמודה4]]-AR28 -> 30041 | D28: =טבלה5[[#This Row],[עמודה4]]-AJ28 -> 68127 | F28: =-SUMIF(SAP!A:A,H28,SAP!F:F) -> 202799 | G28: 100646 | H28: 7026 | J28: 10941 | L28: 9044 | M28: 19985 | O28: 8471 | P28: 107385 | R28: 57410 | S28: 85866 | U28: 98826 | V28: 107385 | W28: 12960 | X28: 123013 | Y28: 8559 | Z28: 78929 | AC28: -8533 | AD28: 98852 | AF28: 24161 | AG28: 123013 | AH28: 11659 | AI28: 27287 | AJ28: 134672 | AL28: 13287 | AM28: 147959 | AQ28: 24799 | AR28: 172758 | AX28: =טבלה5[[#This Row],[עמודה4]]/1000 -> 202.799 | AY28: =טבלה5[[#This Row],[עמודה4]]/1000 -> 202.799
B29: =SUM(B22:B28) -> -21361 | C29: =SUM(C22:C28) -> 0 | D29: =SUM(D22:D28) -> 274362 | E29: =SUM(E22:E28) -> 0 | F29: =SUM(F22:F28) -> 1406393 | G29: =SUM(G22:G28) -> 1322914 | J29: 102942 | L29: 98084 | M29: 201026 | O29: 159649 | P29: 756638 | R29: 160352 | S29: 521027 | U29: 620248 | V29: 756638 | W29: 99221 | X29: 972585 | Y29: 136390 | Z29: 395963 | AC29: 103390 | AD29: 860028 | AF29: 112557 | AG29: 972585 | AH29: 159446 | AI29: 375393 | AJ29: 1132031 | AL29: 120805 | AM29: 1252836 | AQ29: 174918 | AR29: 1427754 | AX29: =טבלה5[[#This Row],[עמודה4]]/1000 -> 1406.393 | AY29: =טבלה5[[#This Row],[עמודה4]]/1000 -> 1406.393
B30: =B29-'P&L'!D20 -> 0 | D30: =D29-'P&L'!F20 -> 0 | F30: =F29-'P&L'!H20 -> 0 | G30: =G29-'P&L'!I20 -> 0 | P30: 0 | S30: 0 | U30: 0 | V30: 0 | W30: 0 | X30: 0 | Y30: 0 | Z30: 0 | AC30: 0 | AD30: 0 | AF30: 0 | AG30: 0 | AH30: 0 | AI30: 0 | AJ30: 0 | AL30: 0 | AM30: 0 | AQ30: 0 | AR30: 0 | AX30: =טבלה5[[#This Row],[עמודה4]]/1000 -> 0 | AY30: =טבלה5[[#This Row],[עמודה4]]/1000 -> 0
AX31: =טבלה5[[#This Row],[עמודה4]]/1000 -> 0 | AY31: =טבלה5[[#This Row],[עמודה4]]/1000 -> 0
AX32: =טבלה5[[#This Row],[עמודה4]]/1000 -> 0 | AY32: =טבלה5[[#This Row],[עמודה4]]/1000 -> 0
AX33: =טבלה5[[#This Row],[עמודה4]]/1000 -> 0 | AY33: =טבלה5[[#This Row],[עמודה4]]/1000 -> 0
A34: Note 9 - General & Administrative | AX34: =טבלה5[[#This Row],[עמודה4]]/1000 -> 0 | AY34: =טבלה5[[#This Row],[עמודה4]]/1000 -> 0
B35: =B18 -> MTD | D35: QTD | F35: YTD | G35: YTD | J35: YTD | L35: MTD | M35: YTD | O35: MTD | P35: YTD | R35: MTD | S35: YTD | U35: YTD | V35: YTD | W35: MTD | X35: YTD | Y35: MTD | Z35: QTD | AC35: MTD | AD35: YTD | AF35: MTD | AG35: YTD | AH35: MTD | AI35: QTD | AJ35: YTD | AL35: MTD | AM35: YTD | AQ35: MTD | AR35: YTD | AX35: =טבלה5[[#This Row],[עמודה4]]/1000 -> #VALUE! | AY35: =טבלה5[[#This Row],[עמודה4]]/1000 -> #VALUE!
B36: =DATE -> 44926 | D36: =DATE -> 44926 | F36: =DATE -> 44926 | G36: 43830 | J36: 44592 | L36: 44620 | M36: 44620 | O36: 44651 | P36: 44742 | R36: 44681 | S36: 44681 | U36: 44712 | V36: 44742 | W36: 44712 | X36: 44804 | Y36: 44742 | Z36: 44742 | AC36: 44773 | AD36: 44773 | AF36: 44804 | AG36: 44804 | AH36: 44834 | AI36: 44834 | AJ36: 44834 | AL36: 44865 | AM36: 44865 | AQ36: 44895 | AR36: 44895 | AX36: =טבלה5[[#This Row],[עמודה4]]/1000 -> 44.926 | AY36: =טבלה5[[#This Row],[עמודה4]]/1000 -> 44.926
B37: =DATE -> 44926 | D37: =DATE -> 44926 | F37: =DATE -> 44926 | G37: =CompareDATE -> 44561 | J37: 44592 | L37: 44620 | M37: 44620 | O37: 44651 | P37: 44742 | R37: 44681 | S37: 44681 | U37: 44712 | V37: 44742 | W37: 44712 | X37: 44804 | Y37: 44742 | Z37: 44742 | AC37: 44773 | AD37: 44773 | AF37: 44804 | AG37: 44804 | AH37: 44834 | AI37: 44834 | AJ37: 44834 | AL37: 44865 | AM37: 44865 | AQ37: 44895 | AR37: 44895 | AX37: =טבלה5[[#This Row],[עמודה4]]/1000 -> 44.926 | AY37: =טבלה5[[#This Row],[עמודה4]]/1000 -> 44.926
B38: U.S. Dollars | D38: U.S. Dollars | F38: U.S. Dollars | G38: U.S. Dollars | J38: U.S. Dollars | L38: U.S. Dollars | M38: U.S. Dollars | O38: U.S. Dollars | P38: U.S. Dollars | R38: U.S. Dollars | S38: U.S. Dollars | U38: U.S. Dollars | V38: U.S. Dollars | W38: U.S. Dollars | X38: U.S. Dollars | Y38: U.S. Dollars | Z38: U.S. Dollars | AC38: U.S. Dollars | AD38: U.S. Dollars | AF38: U.S. Dollars | AG38: U.S. Dollars | AH38: U.S. Dollars | AI38: U.S. Dollars | AJ38: U.S. Dollars | AL38: U.S. Dollars | AM38: U.S. Dollars | AQ38: U.S. Dollars | AR38: U.S. Dollars | AX38: =טבלה5[[#This Row],[עמודה4]]/1000 -> #VALUE! | AY38: =טבלה5[[#This Row],[עמודה4]]/1000 -> #VALUE!
A39: =VLOOKUP(H39,Index!A:B,2,0) -> Salaries and social benefits | B39: =טבלה5[[#This Row],[עמודה4]]-AR39 -> 62436 | D39: =טבלה5[[#This Row],[עמודה4]]-AJ39 -> 209618 | F39: =-SUMIF(SAP!A:A,H39,SAP!F:F) -> 933435 | G39: 820270 | H39: 7050 | J39: 73400 | L39: 77980 | M39: 151380 | O39: 92151 | P39: 485780 | R39: 76377 | S39: 319908 | U39: 398777 | V39: 485780 | W39: 78869 | X39: 640821 | Y39: 87003 | Z39: 242249 | AC39: 75887 | AD39: 561667 | AF39: 79154 | AG39: 640821 | AH39: 82996 | AI39: 238037 | AJ39: 723817 | AL39: 70714 | AM39: 794531 | AQ39: 76468 | AR39: 870999 | AX39: =טבלה5[[#This Row],[עמודה4]]/1000 -> 933.435 | AY39: =טבלה5[[#This Row],[עמודה4]]/1000 -> 933.435
A40: =VLOOKUP(H40,Index!A:B,2,0) -> Professional services | B40: =טבלה5[[#This Row],[עמודה4]]-AR40 -> 19171 | D40: =טבלה5[[#This Row],[עמודה4]]-AJ40 -> 40173 | F40: =-SUMIF(SAP!A:A,H40,SAP!F:F) -> 181013 | G40: 335179 | H40: 7051 | J40: 23816 | L40: 13870 | M40: 37686 | O40: 13841 | P40: 101072 | R40: 18263 | S40: 69790 | U40: 94169 | V40: 101072 | W40: 24379 | X40: 128359 | Y40: 6903 | Z40: 49545 | AC40: 8603 | AD40: 109675 | AF40: 18684 | AG40: 128359 | AH40: 12481 | AI40: 39768 | AJ40: 140840 | AL40: 9929 | AM40: 150769 | AQ40: 11073 | AR40: 161842 | AX40: =טבלה5[[#This Row],[עמודה4]]/1000 -> 181.013 | AY40: =טבלה5[[#This Row],[עמודה4]]/1000 -> 181.013
A41: =VLOOKUP(H41,Index!A:B,2,0) -> Depreciation | B41: =טבלה5[[#This Row],[עמודה4]]-AR41 -> 6997 | D41: =טבלה5[[#This Row],[עמודה4]]-AJ41 -> 20488 | F41: =-SUMIF(SAP!A:A,H41,SAP!F:F) -> 73303 | G41: 46356 | H41: 7052 | J41: 5276 | L41: 5371 | M41: 10647 | O41: 5463 | P41: 33657 | R41: 5807 | S41: 21917 | U41: 27671 | V41: 33657 | W41: 5754 | X41: 46243 | Y41: 5986 | Z41: 17547 | AC41: 6059 | AD41: 39716 | AF41: 6527 | AG41: 46243 | AH41: 6572 | AI41: 19158 | AJ41: 52815 | AL41: 6573 | AM41: 59388 | AQ41: 6918 | AR41: 66306 | AX41: =טבלה5[[#This Row],[עמודה4]]/1000 -> 73.303 | AY41: =טבלה5[[#This Row],[עמודה4]]/1000 -> 73.303
A42: =VLOOKUP(H42,Index!A:B,2,0) -> Insurance | B42: =טבלה5[[#This Row],[עמודה4]]-AR42 -> 3359 | D42: =טבלה5[[#This Row],[עמודה4]]-AJ42 -> 10060 | F42: =-SUMIF(SAP!A:A,H42,SAP!F:F) -> 124846 | G42: 12350 | H42: 7054 | J42: 2006 | L42: 1316 | M42: 3322 | O42: 1347 | P42: 7080 | R42: 1261 | S42: 5930 | U42: 6240 | V42: 7080 | W42: 310 | X42: 43402 | Y42: 840 | Z42: 2411 | AC42: 32811 | AD42: 39891 | AF42: 3511 | AG42: 43402 | AH42: 71384 | AI42: 107706 | AJ42: 114786 | AL42: 779 | AM42: 115565 | AQ42: 5922 | AR42: 121487 | AX42: =טבלה5[[#This Row],[עמודה4]]/1000 -> 124.846 | AY42: =טבלה5[[#This Row],[עמודה4]]/1000 -> 124.846
...

Sheet Equity
I4: Evigilo
D6: Retained Earning
K8: LTD
K9: December 31, 2015
K10: $
D11: Stockholders' Equity | E11: Number of ordinary shares | F11: Number of series A-1 preferred shares | G11: Number of series A-2 preferred shares | H11: Number of series A-3 preferred shares | I11: Number of series B preferred shares | J11: Number of series C preferred shares | K11: Share capital | L11: Receivables on account of shares | M11: Additional paid in capital | N11: Accumulated deficit | O11: Total
D12: Opening balance | E12: 1000000 | F12: 6621798 | G12: 6709427 | H12: 155848 | I12: 5437857 | J12: 82347724 | K12: 255005.08 | L12: -26 | M12: 6579304.9 | N12: -6878314.8 | O12: -44030.808
D13: Conversion of convertible loan
D14: Investment
D15: Issuance of anti-dilution shares | F15: =6621798-F12 -> 0
D16: Share based payment
D17: profit for the year
D19: Total Stockholders' Equity | E19: =SUM(E12:E18) -> 1000000 | F19: =SUM(F12:F18) -> 6621798 | G19: =SUM(G12:G18) -> 6709427 | H19: =SUM(H12:H18) -> 155848 | I19: =SUM(I12:I18) -> 5437857 | J19: =SUM(J12:J18) -> 82347724 | K19: =SUM(K12:K18) -> 255005.08 | L19: =SUM(L12:L18) -> -26 | ... O19: =SUM(O12:O18) -> -44030.808
O21: =O19-[83]CONSBS!G44 -> -3.45
K23: ₪
D24: Stockholders' Equity | E24: Number of ordinary shares | F24: Number of series A-1 preferred shares | G24: Number of series A-2 preferred shares | H24: Number of series A-3 preferred shares | I24: Number of series B preferred shares | J24: Number of series C preferred shares | K24: Share capital | L24: Receivables on account of shares | M24: Additional paid in capital | N24: Accumulated deficit | O24: Total
D25: Opening balance | E25: 1000000 | F25: 6621798 | G25: 6709427 | H25: 155848 | I25: 5437857 | J25: 82347724 | K25: 990813 | L25: -100 | M25: 24181105 | N25: -25194620 | O25: -22802
D26: Conversion of convertible loan
D27: Investment
D28: Issuance of anti-dilution shares | F28: =6621798-F25 -> 0
D29: Share based payment | M29: 9751 | O29: =SUM(K29:N29) -> 9751
D30: profit for the year | N30: ='P&L'!#REF! -> #REF! | O30: =SUM(K30:N30) -> #REF!
O31: =SUM(K31:N31) -> 0
D32: Total Stockholders' Equity | E32: =SUM(E25:E31) -> 1000000 | F32: =SUM(F25:F31) -> 6621798 | G32: =SUM(G25:G31) -> 6709427 | H32: =SUM(H25:H31) -> 155848 | I32: =SUM(I25:I31) -> 5437857 | J32: =SUM(J25:J31) -> 82347724 | K32: =SUM(K25:K31) -> 990813 | L32: =SUM(L25:L31) -> -100 | ... O32: =SUM(O25:O31) -> #REF!
K34: =K32-BS!#REF! -> #REF! | M34: =Equity!M32+Equity!L32-BS!#REF! -> #REF! | O34: =O32-BS!#REF! -> #REF!

Sheet SAP
A1: קוד 4 ספרות | C1: LTD $ | D1: GMBH $ | E1: פקודות נוספות $ (-) חובה | F1: יתרה $ | G1: פקודות נוספות ש"ח (-) חובה | H1: יתרה ישראל - ₪ | I1: קוד 3 ספרות | J1: קוד 2 ספרות | K1: שער | L1: שער | M1: Details
A2: 1302 | B2: =VLOOKUP(A2,Index!A:B,2,0) -> Israeli currency | C2: =SUMIF('SAP DRAFT'!B:B,A2,'SAP DRAFT'!D:D) -> -12486866 | D2: =SUMIF('SAP DRAFT'!B:B,A2,'SAP DRAFT'!F:F) -> 0 | E2: =SUMIF(AE!$B$1:$B$1009,A2,AE!$E$1:$E$1009)-SUMIF(AE!$B$1:$B$1009,A2,AE!$D$1:$D$1009) -> 0 | F2: =ROUND(E2+C2+D2,0) -> -12486866 | G2: =SUMIF(AE!$B$1:$B$1009,#REF!,AE!$G$1:$G$1009)-SUMIF(AE!$B$1:$B$1009,#REF!,AE!$F$1:$F$1009) -> 0 | H2: =ROUND(G2+#REF!,0) -> #REF! | I2: =LEFT(A2,3) -> 130 | J2: =LEFT(A2,2) -> 13 | K2: =+#REF!/C2 -> #REF! | L2: =+H2/F2 -> #REF! | M2: תואם לריכוז יתרות 30.06.19 | N2: =VLOOKUP(A2,'SAP DRAFT'!A:B,1,0) -> #N/A
A3: 1304 | B3: =VLOOKUP(A3,Index!A:B,2,0) -> USD currency | C3: =SUMIF('SAP DRAFT'!B:B,A3,'SAP DRAFT'!D:D) -> -8290712 | D3: =SUMIF('SAP DRAFT'!B:B,A3,'SAP DRAFT'!F:F) -> 0 | E3: =SUMIF(AE!$B$1:$B$1009,A3,AE!$E$1:$E$1009)-SUMIF(AE!$B$1:$B$1009,A3,AE!$D$1:$D$1009) -> 0 | F3: =ROUND(E3+C3+D3,0) -> -8290712 | G3: =SUMIF(AE!$B$1:$B$1009,#REF!,AE!$G$1:$G$1009)-SUMIF(AE!$B$1:$B$1009,#REF!,AE!$F$1:$F$1009) -> 0 | H3: =ROUND(G3+#REF!,0) -> #REF! | I3: =LEFT(A3,3) -> 130 | J3: =LEFT(A3,2) -> 13 | K3: =+#REF!/C3 -> #REF! | L3: =+H3/F3 -> #REF! | M3: תואם לריכוז יתרות 30.06.19 | N3: =VLOOKUP(A3,'SAP DRAFT'!A:B,1,0) -> #N/A
A4: 1307 | B4: =VLOOKUP(A4,Index!A:B,2,0) -> EURO currency | C4: =SUMIF('SAP DRAFT'!B:B,A4,'SAP DRAFT'!D:D) -> 0 | D4: =SUMIF('SAP DRAFT'!B:B,A4,'SAP DRAFT'!F:F) -> -2198.2832 | E4: =SUMIF(AE!$B$1:$B$1009,A4,AE!$E$1:$E$1009)-SUMIF(AE!$B$1:$B$1009,A4,AE!$D$1:$D$1009) -> 0 | F4: =ROUND(E4+C4+D4,0) -> -2198 | G4: =SUMIF(AE!$B$1:$B$1009,#REF!,AE!$G$1:$G$1009)-SUMIF(AE!$B$1:$B$1009,#REF!,AE!$F$1:$F$1009) -> 0 | H4: =ROUND(G4+#REF!,0) -> #REF! | I4: =LEFT(A4,3) -> 130 | J4: =LEFT(A4,2) -> 13 | N4: =VLOOKUP(A4,'SAP DRAFT'!A:B,1,0) -> #N/A
A5: 1330 | B5: =VLOOKUP(A5,Index!A:B,2,0) -> Short term deposit | C5: =SUMIF('SAP DRAFT'!B:B,A5,'SAP DRAFT'!D:D) -> -40710444 | D5: =SUMIF('SAP DRAFT'!B:B,A5,'SAP DRAFT'!F:F) -> 0 | E5: =SUMIF(AE!$B$1:$B$1009,A5,AE!$E$1:$E$1009)-SUMIF(AE!$B$1:$B$1009,A5,AE!$D$1:$D$1009) -> 0 | F5: =ROUND(E5+C5+D5,0) -> -40710444 | I5: =LEFT(A5,3) -> 133 | J5: =LEFT(A5,2) -> 13
A6: 1351 | B6: =VLOOKUP(A6,Index!A:B,2,0) -> Related company | C6: =SUMIF('SAP DRAFT'!B:B,A6,'SAP DRAFT'!D:D) -> 0 | D6: =SUMIF('SAP DRAFT'!B:B,A6,'SAP DRAFT'!F:F) -> -238143.08 | E6: =SUMIF(AE!$B$1:$B$1009,A6,AE!$E$1:$E$1009)-SUMIF(AE!$B$1:$B$1009,A6,AE!$D$1:$D$1009) -> 238143.08 | F6: =ROUND(E6+C6+D6,0) -> 0 | G6: =SUMIF(AE!$B$1:$B$1009,#REF!,AE!$G$1:$G$1009)-SUMIF(AE!$B$1:$B$1009,#REF!,AE!$F$1:$F$1009) -> 0 | H6: =ROUND(G6+#REF!,0) -> #REF! | I6: =LEFT(A6,3) -> 135 | J6: =LEFT(A6,2) -> 13 | N6: =VLOOKUP(A6,'SAP DRAFT'!A:B,1,0) -> #N/A
A7: 1354 | B7: =VLOOKUP(A7,Index!A:B,2,0) -> Prepaid expenses | C7: =SUMIF('SAP DRAFT'!B:B,A7,'SAP DRAFT'!D:D) -> -128703 | D7: =SUMIF('SAP DRAFT'!B:B,A7,'SAP DRAFT'!F:F) -> 0 | E7: =SUMIF(AE!$B$1:$B$1009,A7,AE!$E$1:$E$1009)-SUMIF(AE!$B$1:$B$1009,A7,AE!$D$1:$D$1009) -> 1180.7232 | F7: =ROUND(E7+C7+D7,0) -> -127522 | G7: =SUMIF(AE!$B$1:$B$1009,#REF!,AE!$G$1:$G$1009)-SUMIF(AE!$B$1:$B$1009,#REF!,AE!$F$1:$F$1009) -> 0 | H7: =ROUND(G7+#REF!,0) -> #REF! | I7: =LEFT(A7,3) -> 135 | J7: =LEFT(A7,2) -> 13 | K7: =+#REF!/C7 -> #REF! | L7: =+H7/F7 -> #REF! | M7: תואם לנייר עבודה Q2 2019 | N7: =VLOOKUP(A7,'SAP DRAFT'!A:B,1,0) -> #N/A
A8: 1355 | B8: =VLOOKUP(A8,Index!A:B,2,0) -> Guaranty deposits | C8: =SUMIF('SAP DRAFT'!B:B,A8,'SAP DRAFT'!D:D) -> -22131 | D8: =SUMIF('SAP DRAFT'!B:B,A8,'SAP DRAFT'!F:F) -> 0 | E8: =SUMIF(AE!$B$1:$B$1009,A8,AE!$E$1:$E$1009)-SUMIF(AE!$B$1:$B$1009,A8,AE!$D$1:$D$1009) -> 0 | F8: =ROUND(E8+C8+D8,0) -> -22131 | G8: =SUMIF(AE!$B$1:$B$1009,#REF!,AE!$G$1:$G$1009)-SUMIF(AE!$B$1:$B$1009,#REF!,AE!$F$1:$F$1009) -> 0 | H8: =ROUND(G8+#REF!,0) -> #REF! | I8: =LEFT(A8,3) -> 135 | J8: =LEFT(A8,2) -> 13 | K8: =+#REF!/C8 -> #REF! | L8: =+H8/F8 -> #REF! | M8: ללא שינוי משנה קודמת. לקבל בסוף שנה אישור מהספק | N8: =VLOOKUP(A8,'SAP DRAFT'!A:B,1,0) -> #N/A
A9: 1356 | B9: =VLOOKUP(A9,Index!A:B,2,0) -> Income tax | C9: =SUMIF('SAP DRAFT'!B:B,A9,'SAP DRAFT'!D:D) -> 0 | D9: =SUMIF('SAP DRAFT'!B:B,A9,'SAP DRAFT'!F:F) -> 0 | E9: =SUMIF(AE!$B$1:$B$1009,A9,AE!$E$1:$E$1009)-SUMIF(AE!$B$1:$B$1009,A9,AE!$D$1:$D$1009) -> 0 | F9: =ROUND(E9+C9+D9,0) -> 0 | G9: =SUMIF(AE!$B$1:$B$1009,#REF!,AE!$G$1:$G$1009)-SUMIF(AE!$B$1:$B$1009,#REF!,AE!$F$1:$F$1009) -> 0 | H9: =ROUND(G9+#REF!,0) -> #REF! | I9: =LEFT(A9,3) -> 135 | J9: =LEFT(A9,2) -> 13 | K9: =+#REF!/C9 -> #REF! | L9: =+H9/F9 -> #REF! | M9: מקדמות בגין עודפות 2017. לסגור מול הפרשה בסוף שנה | N9: =VLOOKUP(A9,'SAP DRAFT'!A:B,1,0) -> #N/A
A10: 1357 | B10: =VLOOKUP(A10,Index!A:B,2,0) -> VAT | C10: =SUMIF('SAP DRAFT'!B:B,A10,'SAP DRAFT'!D:D) -> -50267 | D10: =SUMIF('SAP DRAFT'!B:B,A10,'SAP DRAFT'!F:F) -> -5458.0524 | E10: =SUMIF(AE!$B$1:$B$1009,A10,AE!$E$1:$E$1009)-SUMIF(AE!$B$1:$B$1009,A10,AE!$D$1:$D$1009) -> 0 | F10: =ROUND(E10+C10+D10,0) -> -55725 | G10: =SUMIF(AE!$B$1:$B$1009,#REF!,AE!$G$1:$G$1009)-SUMIF(AE!$B$1:$B$1009,#REF!,AE!$F$1:$F$1009) -> 0 | H10: =ROUND(G10+#REF!,0) -> #REF! | I10: =LEFT(A10,3) -> 135 | J10: =LEFT(A10,2) -> 13 | K10: =+#REF!/C10 -> #REF! | L10: =+H10/F10 -> #REF! | M10: תשומות בגין 5-6.2019. טרם הועברה פקודת מע"מ | N10: =VLOOKUP(A10,'SAP DRAFT'!A:B,1,0) -> #N/A
A11: 1358 | B11: =VLOOKUP(A11,Index!A:B,2,0) -> Other | C11: =SUMIF('SAP DRAFT'!B:B,A11,'SAP DRAFT'!D:D) -> -3552 | D11: =SUMIF('SAP DRAFT'!B:B,A11,'SAP DRAFT'!F:F) -> 0 | E11: =SUMIF(AE!$B$1:$B$1009,A11,AE!$E$1:$E$1009)-SUMIF(AE!$B$1:$B$1009,A11,AE!$D$1:$D$1009) -> 0 | F11: =ROUND(E11+C11+D11,0) -> -3552 | G11: =SUMIF(AE!$B$1:$B$1009,#REF!,AE!$G$1:$G$1009)-SUMIF(AE!$B$1:$B$1009,#REF!,AE!$F$1:$F$1009) -> 0 | H11: =ROUND(G11+#REF!,0) -> #REF! | I11: =LEFT(A11,3) -> 135 | J11: =LEFT(A11,2) -> 13 | N11: =VLOOKUP(A11,'SAP DRAFT'!A:B,1,0) -> #N/A
