Workbook

Sheet דוח התאמה למס
B2: Papaya Gaming LTD | C2: דוח התאמה 2021
B6: רווח לפני מס 2021 | E6: ='P&L LTD USD'!J122-'P&L LTD USD'!J120 -> -95997189
B8: תיאום הוצאות עודפות:
B9: מחקר ופיתוח - דחיית הוצאות | E9: ='R&D 20A'!G8+'R&D 20A'!G9+'R&D 20A'!H9 -> #N/A | F9: פריסה על פני 3 שנים
B10: מחקר ופיתוח - הכרה בהוצאות ש"ק | E10: ='R&D 20A'!F7+'R&D 20A'!F8 -> 2898754.6 | F10: בגין הוצאות שמקורן ב 2018-2019
A11: 23031 | B11: הוצאות בגין תשלום מבוסס מניות | E11: =VLOOKUP(A12,'TB LTD 12.22'!D:F,3,0) -> #N/A
A12: 20060 | B12: הוצאות בגין תשלום מבוסס מניות | E12: =VLOOKUP(A13,'TB LTD 12.22'!D:F,3,0) -> #N/A
A13: 20048 | B13: הוצאות בגין תשלום מבוסס מניות | E13: =VLOOKUP(A14,'TB LTD 12.22'!D:F,3,0) -> #N/A
A14: 90017 | B14: גידול בהפרשה לחופשה | E14: =VLOOKUP(A15,'TB LTD 12.22'!D:F,3,0) -> #N/A
A15: 90018 | B15: גידול בהפרשה להבראה | E15: =VLOOKUP(A16,'TB LTD 12.22'!D:F,3,0) -> #N/A
A16: 20024 | B16: ארוחות | E16: =VLOOKUP(A17,'TB LTD 12.22'!D:F,3,0) -> #N/A | F16: 100% מתואם
A17: ='[1]TB 12.2018'!C7 -> 20001 | B17: כיבודים
B18: עודפות
B19: רווחי אקוויטי | E19: =-'[2]FS ILS 12.20'!E72 -> #REF!
A20: 20039 | B20: תרומות | E20: =VLOOKUP(A20,'[2]TB LTD 12.20'!$D:$F,3,FALSE)-17586.4 -> #N/A
A21: 20035 | B21: קנסות | E21: =+VLOOKUP(A21,'[2]TB LTD 12.20'!$D:$F,3,FALSE) -> #N/A | F21: קנסות תנועה + מוסדות
E23: =SUM(E9:E21) -> #N/A
N24: כרטיס | O24: תאור | Q24: סה"כ הוצאה | R24: שויים | S24: הוצאה עודפת
B25: הפסד מועבר משנת 2019 | E25: -4245210 | N25: 20014 | O25: מצרכים וכיבודים | Q25: #REF! | S25: =+Q25*0.2 -> #VALUE!
N26: 20021 | O26: מתנות | P26: 90015 | Q26: #REF! | R26: #REF! | S26: =+Q26-R26 -> #VALUE!
B27: הפסד לצרכי מס - מועבר לשנת 2021 | E27: =E6+E23+E25 -> #N/A | F27: =-E27+E25 -> #N/A | N27: 20024 | O27: ארוחות | P27: 90012 | Q27: #REF! | R27: #REF! | S27: =+Q27-R27 -> #VALUE!
N28: 20036 | O28: אירוע חברה | Q28: #REF! | S28: =+Q28 -> #REF!
B29: תרומה להעברה לשנים הבאות לשם קבלת הזיכוי | E29: =+E20 -> #N/A | F29: =+E27-E29 -> #N/A | N29: 20041 | O29: מתנות לעובדים חד פעמי | Q29: #REF! | S29: =+Q29 -> #REF!
S30: =0.45*SUM(S25:S29) -> #VALUE!
C32: USD | D32: NIS | E32: שיעור המס לפי מפעל טכנולוגי מועדף (גישה שמרנית)
B33: נכס מס נדחה בגין הפסד להעברה | C33: =+D33/'[2]FS USD 12.20'!$I$1 -> #N/A | D33: =-E27*E33 -> #N/A | E33: 0.12
A34: 90017 | B34: נכס מס נדחה בגין הפרשה לחופשה | C34: #REF! | D34: =-VLOOKUP(A34,'[2]TB LTD 12.20'!$D:$F,3,FALSE)*$E$34 -> #N/A | E34: 0.12 | O34: התאמת מו"פ
A35: 90018 | B35: נכס מס נדחה בגין הפרשה להבראה | C35: #REF! | D35: =-VLOOKUP(A35,'[2]TB LTD 12.20'!$D:$F,3,FALSE)*$E$35 -> #N/A | E35: 0.12
B36: הוצאות מו״פ שנדחו | C36: =+D36/'[2]FS USD 12.20'!$I$1 -> #REF! | D36: =+SUM(M9:N10)*E36 -> 0 | E36: 0.12 | N36: הוצאות מו"פ | O36: =-'[2]FS ILS 12.20'!E60 -> #REF!
M38: 23012 | N38: הוצאות הפרשה להבראה מופ | O38: #REF!
M39: 23011 | N39: הוצאות חופשה מופ | O39: #REF!
M40: SBC Expenses R&D | N40: הוצאות בגין תשלום מבוסס מניות | O40: =-E11 -> #N/A
O41: =SUM(O36:O40) -> #REF!

Sheet Income WP
C1: January | D1: februay | E1: march | F1: April | G1: May | H1: June | I1: July | J1: August | K1: September | L1: October | M1: November | N1: December
B4: Net revenue | C4: Books
B6: Revenue -Revenue Worldpay | C6: -8464.236 | D6: -8214.9616 | E6: -7864.6015 | F6: -6635.6998 | G6: -6367.1782 | H6: -5679.5026 | I6: -6074.0722 | J6: -6044.8198 | K6: -5718.7637 | L6: -5812.9114 | M6: -5945.4744 | N6: -7092.0165 | O6: =SUM(C6:N6) -> -79914.238
B7: Revenue -Revenue Paypal IL | C7: -7708.4674 | D7: -8023.2407 | E7: -8567.4289 | F7: -2482.4601 | G7: -549.67162 | H7: -588.54806 | I7: -772.40202 | J7: -698.99656 | K7: -569.86207 | L7: -633.74312 | M7: -651.10238 | N7: -795.55018 | O7: =SUM(C7:N7) -> -32041.473
B8: Revenue -Revenue Paypal US | C8: -11.161 | D8: -15.068 | E8: -913.23003 | F8: -6763.3307 | G8: -8302.2735 | H8: -7566.9065 | I8: -8300.8356 | J8: -8661.674 | K8: -8403.418 | L8: -9039.249 | M8: -9231.405 | N8: -11230.575 | O8: =SUM(C8:N8) -> -78439.126
B9: Revenue -Revenue Cyber Source | C9: -10287.134 | D9: -9723.4638 | E9: -11979.491 | F9: -10840.921 | G9: -11149.886 | H9: -10416.312 | I9: -11524.237 | J9: -11540.062 | K9: -11056.225 | L9: -11555.783 | M9: -11900.453 | N9: -14063.502 | O9: =SUM(C9:N9) -> -136037.47
B10: Revenue - Braintree | C10: 0 | D10: -0.009 | E10: -668.6464 | F10: -1421.1699 | G10: -1898.0734 | H10: -2037.7415 | I10: -2256.9943 | J10: -2872.641 | K10: -2934.0622 | L10: -3108.4732 | M10: -3325.7385 | N10: -3863.4214 | O10: =SUM(C10:N10) -> -24386.971
B11: direct Sales tax | M11: 366 | N11: 1038.077 | O11: =SUM(C11:N11) -> 1404.077
B12: FX paypal | C12: -2.4 | D12: -18.6 | E12: -24.3 | F12: -23.6 | G12: -23.199 | H12: -23.6 | I12: -27.4 | J12: -24.9 | K12: -20.8 | L12: -23.1 | M12: -16.9 | N12: -20.6 | O12: =SUM(C12:N12) -> -249.399
B13: Revenue Sales Tax | C13: 997.217 | D13: 952.537 | E13: 1069.429 | F13: 940.664 | G13: 926.095 | H13: 878.436 | I13: 946.384 | J13: 929.883 | K13: 770.866 | L13: 855.649 | M13: 531 | N13: =30+181 -> 211 | O13: =SUM(C13:N13) -> 10009.16
B15: ='P&L LTD USD'!C8 -> withdrawals | C15: 316.551 | D15: 223.42657 | E15: 267.68417 | F15: 167.10198 | G15: 153.64264 | H15: 233.62136 | I15: 200.58034 | J15: 199.29227 | K15: 186.66177 | L15: 264.48114 | M15: 299.47245 | N15: 554.15426 | O15: ='P&L LTD USD'!F8/1000 -> 3066.6699
B16: ='P&L LTD USD'!C7 -> Net Cash | C16: 418.747 | D16: 411.425 | E16: 463.667 | F16: 414.138 | G16: 244.824 | H16: 421.944 | I16: 538.704 | J16: 431.387 | K16: 394.87727 | L16: 287.31728 | M16: 511.67244 | N16: 392.65548 | O16: ='P&L LTD USD'!F7/1000 -> 4931.3585
B17: ='P&L LTD USD'!C6 -> ads revenue | C17: -207.63259 | D17: -197.12699 | E17: -212.44853 | F17: -208.6662 | G17: -219.74986 | H17: -214.47608 | I17: -256.15022 | J17: -217.27895 | K17: -225.66554 | L17: -220.16938 | M17: -206.10497 | N17: -215.09991 | O17: ='P&L LTD USD'!F6/1000 -> -2600.5692
B19: Total income | O19: =SUM(O5:O17) -> -334257.98
O63: =-334239531.33/1000 -> -334239.53
N64: i/m | O64: =O19-O63 -> -18.44882
E129: ;

Sheet Exp By type
B4: Total revenue
C5: India | D5: INC | E5: LTD | F5: Total
B6: Ua | C6: =+SUMIFS('P&L India'!F:F,'P&L India'!A:A,'Exp By type'!B6) -> 0 | D6: =+SUMIFS('P&L INC'!F:F,'P&L INC'!A:A,'Exp By type'!B6) -> 24308066 | E6: =SUMIFS('P&L LTD USD'!F:F,'P&L LTD USD'!A:A,'Exp By type'!B6) -> 2.2524941e+08 | F6: =SUM(C6:E6) -> 2.4955748e+08
B7: Fee | C7: =+SUMIFS('P&L India'!F:F,'P&L India'!A:A,'Exp By type'!B7) -> 0 | D7: =+SUMIFS('P&L INC'!F:F,'P&L INC'!A:A,'Exp By type'!B7) -> 19761872 | E7: =SUMIFS('P&L LTD USD'!F:F,'P&L LTD USD'!A:A,'Exp By type'!B7) -> 0 | F7: =SUM(C7:E7) -> 19761872
B8: Payroll | C8: =+SUMIFS('P&L India'!F:F,'P&L India'!A:A,'Exp By type'!B8) -> 0 | D8: =+SUMIFS('P&L INC'!F:F,'P&L INC'!A:A,'Exp By type'!B8) -> 0 | E8: =SUMIFS('P&L LTD USD'!F:F,'P&L LTD USD'!A:A,'Exp By type'!B8) -> 19481623 | F8: =SUM(C8:E8) -> 19481623
B9: Options | C9: =+SUMIFS('P&L India'!F:F,'P&L India'!A:A,'Exp By type'!B9) -> 0 | D9: =+SUMIFS('P&L INC'!F:F,'P&L INC'!A:A,'Exp By type'!B9) -> 0 | E9: =SUMIFS('P&L LTD USD'!F:F,'P&L LTD USD'!A:A,'Exp By type'!B9) -> 185110.54 | F9: =SUM(C9:E9) -> 185110.54
B10: Overheads | C10: =+SUMIFS('P&L India'!F:F,'P&L India'!A:A,'Exp By type'!B10) -> 51073.93 | D10: =+SUMIFS('P&L INC'!F:F,'P&L INC'!A:A,'Exp By type'!B10) -> 244662.34 | E10: =SUMIFS('P&L LTD USD'!F:F,'P&L LTD USD'!A:A,'Exp By type'!B10) -> 15118489 | F10: =SUM(C10:E10) -> 15414226
B11: Financial expenses | C11: =+SUMIFS('P&L India'!F:F,'P&L India'!A:A,'Exp By type'!B11) -> 262.11 | D11: =+SUMIFS('P&L INC'!F:F,'P&L INC'!A:A,'Exp By type'!B11) -> 179789.7 | E11: =SUMIFS('P&L LTD USD'!F:F,'P&L LTD USD'!A:A,'Exp By type'!B11) -> 242412.35 | F11: =SUM(C11:E11) -> 422464.16
B12: Taxes | C12: =+SUMIFS('P&L India'!F:F,'P&L India'!A:A,'Exp By type'!B12) -> 0 | D12: =+SUMIFS('P&L INC'!F:F,'P&L INC'!A:A,'Exp By type'!B12) -> 89337.55 | E12: =SUMIFS('P&L LTD USD'!F:F,'P&L LTD USD'!A:A,'Exp By type'!B12) -> 3503498.7 | F12: =SUM(C12:E12) -> 3592836.3
B13: Ua Indirect | C13: =+SUMIFS('P&L India'!F:F,'P&L India'!A:A,'Exp By type'!B13) -> 0 | D13: =+SUMIFS('P&L INC'!F:F,'P&L INC'!A:A,'Exp By type'!B13) -> 587361.08 | E13: =SUMIFS('P&L LTD USD'!F:F,'P&L LTD USD'!A:A,'Exp By type'!B13) -> 2935151.9 | F13: =SUM(C13:E13) -> 3522513
B14: Depreciation | C14: =+SUMIFS('P&L India'!F:F,'P&L India'!A:A,'Exp By type'!B14) -> 0 | D14: =+SUMIFS('P&L INC'!F:F,'P&L INC'!A:A,'Exp By type'!B14) -> 0 | E14: =SUMIFS('P&L LTD USD'!F:F,'P&L LTD USD'!A:A,'Exp By type'!B14) -> 216788.83 | F14: =SUM(C14:E14) -> 216788.83
C15: =SUM(C6:C14) -> 51336.04 | D15: =SUM(D6:D14) -> 45171089 | E15: =SUM(E6:E14) -> 2.6693249e+08 | F15: =SUM(F6:F14) -> 3.1215491e+08
C16: ='P&L India'!F28 -> 51336.04 | D16: ='P&L INC'!F79 -> 0 | E16: ='P&L LTD USD'!F129 -> 2.6693249e+08
C17: =C15-C16 -> 0 | D17: =D15-D16 -> 45171089 | E17: =E15-E16 -> 0

Sheet Summary 
B4: Revenues | C4: 2022
B5: Revenues from commissions | C5: ='Income WP'!#REF! -> #REF!
B6: ADJ | C6: ='Income WP'!#REF!+'Income WP'!#REF! -> #REF!
B7: Total revenues | C7: =SUM(C5:C6) -> #REF!
B9: UA- Direct | C9: ='Exp By type'!F6/1000 -> 249557.48
B10: UA -Indirect | C10: ='Exp By type'!F13/1000 -> 3522.513
B11: Total Marketing | C11: =SUM(C9:C10) -> 253079.99
B13: GP | C13: =C7+C11 -> #REF!
B14: % | C14: =C13/C7 -> #REF!
B16: Clearing fees | C16: ='Exp By type'!F7/1000 -> 19761.872
B17: Payroll | C17: ='Exp By type'!F8/1000 -> 19481.623
B18: OverHeads | C18: ='Exp By type'!F10/1000 -> 15414.226
B20: EBITDA (Loss) | C20: =C13+C16+C17+C18 -> #REF!

Sheet FS
A1: 44926
A2: FS
A3: Papaya Gaming Ltd
A4: USD
A7: BS | F7: PL
C10: 44926 | H10: 44926 | I10: 44926
C11: Consolidated | H11: Consolidated | I11: Consolidated - K$
B14: CURRENT ASSETS | G14: Total Revenues | H14: ='P&L USD CONS'!L7 -> -3.3423953e+08 | I14: =H14/1000 -> -334239.53
A16: Short term deposit | B16: Cash | C16: =SUMIF('BS USD CONS '!B:B,FS!A16,'BS USD CONS '!M:M)+SUMIF('BS USD CONS '!B:B,FS!B16,'BS USD CONS '!M:M) -> 78468.185 | G16: Cost of revenues | H16: ='P&L USD CONS'!L9 -> 23057127 | I16: =H16/1000 -> 23057.127
A17: Related Party India | B17: Related Party | C17: =SUMIF('BS USD CONS '!B:B,FS!A17,'BS USD CONS '!M:M)+SUMIF('BS USD CONS '!B:B,FS!B17,'BS USD CONS '!M:M) -> -0.00025 | G17: Gross loss (profit) | H17: ='P&L USD CONS'!L11 -> -3.111824e+08 | I17: =H17/1000 -> -311182.4
B18: Account receivable | C18: =SUMIF('BS USD CONS '!B:B,FS!A18,'BS USD CONS '!M:M)+SUMIF('BS USD CONS '!B:B,FS!B18,'BS USD CONS '!M:M) -> 2668.2386
B19: Shareholders' loan | C19: =SUMIF('BS USD CONS '!B:B,FS!A19,'BS USD CONS '!M:M)+SUMIF('BS USD CONS '!B:B,FS!B19,'BS USD CONS '!M:M) -> 0
A20: Other accounts receivable | B20: Prepaid exepnses and other current assets | C20: =SUMIF('BS USD CONS '!B:B,FS!A20,'BS USD CONS '!M:M)+SUMIF('BS USD CONS '!B:B,FS!A21,'BS USD CONS '!M:M) -> 4289.8373 | G20: Research and development expenses, net | H20: ='P&L USD CONS'!L13 -> 20781725 | I20: =H20/1000 -> 20781.725
A21: Prepaid Expenses | C21: =SUM(C16:C20) -> 85426.261
B23: NON-CURRENT ASSETS | G23: Marketing expenses | H23: ='P&L USD CONS'!L15 -> 2.5604807e+08 | I23: =H23/1000 -> 256048.07
A25: Fixed assets, net | B25: Property and equipment, net | C25: =SUMIF('BS USD CONS '!B:B,FS!A25,'BS USD CONS '!M:M)+SUMIF('BS USD CONS '!B:B,FS!B25,'BS USD CONS '!M:M) -> 1659.0749
B26: ROA Assets | C26: =SUMIF('BS USD CONS '!B:B,FS!A26,'BS USD CONS '!M:M)+SUMIF('BS USD CONS '!B:B,FS!B26,'BS USD CONS '!M:M) -> 20186.267 | G26: General and administrative expenses | H26: ='P&L USD CONS'!L17 -> 8252686.3 | I26: =H26/1000 -> 8252.6863
A27: Reserve - Wordpay | B27: Restricted LT deposit | C27: =SUMIF('BS USD CONS '!B:B,FS!A27,'BS USD CONS '!M:M)+SUMIF('BS USD CONS '!B:B,FS!B27,'BS USD CONS '!M:M) -> 3667.2055
B28: Deferred tax assets | C28: =SUMIF('BS USD CONS '!B:B,FS!A28,'BS USD CONS '!M:M)+SUMIF('BS USD CONS '!B:B,FS!B28,'BS USD CONS '!M:M) -> 2030.2293
C29: =SUM(C25:C28) -> 27542.777
G30: Operating expenses | H30: ='P&L USD CONS'!L19 -> 2.8508248e+08 | I30: =H30/1000 -> 285082.48
B31: Total Assets | C31: =C29+C21 -> 112969.04
G32: Operating loss (profit) | H32: ='P&L USD CONS'!L21 -> -26099922 | I32: =H32/1000 -> -26099.922
B34: CURRENT LIABILITIES | G34: Financial expenses, net | H34: ='P&L USD CONS'!L23 -> 242674.46 | I34: =H34/1000 -> 242.67446
A36: Trade payables | B36: Account payables | C36: =SUMIF('BS USD CONS '!B:B,FS!A36,'BS USD CONS '!M:M)+SUMIF('BS USD CONS '!B:B,FS!B36,'BS USD CONS '!M:M) -> -8752.1494 | G36: TP Expenses | H36: ='P&L USD CONS'!L25 -> 0 | I36: =H36/1000 -> 0
A37: Loan-Short Term | B37: Current maurities of short term loan | C37: =SUMIF('BS USD CONS '!B:B,FS!A37,'BS USD CONS '!M:M)+SUMIF('BS USD CONS '!B:B,FS!B37,'BS USD CONS '!M:M) -> 0
B38: Contract liability | C38: =SUMIF('BS USD CONS '!B:B,FS!A38,'BS USD CONS '!M:M)+SUMIF('BS USD CONS '!B:B,FS!B38,'BS USD CONS '!M:M) -> -8960.3131 | G38: Equity | H38: ='P&L USD CONS'!L27 -> -12793.34 | I38: =H38/1000 -> -12.79334
B39: Related Party-AP | C39: =SUMIF('BS USD CONS '!B:B,FS!A39,'BS USD CONS '!M:M)+SUMIF('BS USD CONS '!B:B,FS!B39,'BS USD CONS '!M:M) -> 0
A40: Tax provision | B40: Warrant liability | C40: =SUMIF('BS USD CONS '!B:B,FS!B40,'BS USD CONS '!M:M) -> -1411.3574 | G40: loss before taxes | H40: ='P&L USD CONS'!L29 -> -25870040 | I40: =H40/1000 -> -25870.04
A41: Other accounts payable | B41: Other accounts payable and accrued expenses | C41: =SUMIF('BS USD CONS '!B:B,FS!A41,'BS USD CONS '!M:M)+SUMIF('BS USD CONS '!B:B,FS!A43,'BS USD CONS '!M:M)+SUMIF('BS USD CONS '!B:B,FS!A40,'BS USD CONS '!M:M)+SUMIF('BS USD CONS '!B:B,FS!A44,'BS USD CONS '!M:M)+SUMIF('BS USD CONS '!B:B,FS!A42,'BS USD CONS '!M:M) -> -35559.508
A42: Accrued expenses | C42: =SUM(C36:C41) -> -54683.328 | G42: Tax expenses | H42: ='P&L USD CONS'!L31 -> 3503498.7 | I42: =H42/1000 -> 3503.4987
A43: Sales Tax Provision
B44: ROA Liability | C44: =SUMIF('BS USD CONS '!B:B,FS!B44,'BS USD CONS '!M:M) -> 0 | G44: Net loss ( profit ) | H44: ='P&L USD CONS'!L33 -> -22366542 | I44: =H44/1000 -> -22366.542
B45: Shareholders | C45: =SUMIF('BS USD CONS '!B:B,FS!A45,'BS USD CONS '!M:M)+SUMIF('BS USD CONS '!B:B,FS!B45,'BS USD CONS '!M:M) -> 0
B46: Convertible Loan | C46: =SUMIF('BS USD CONS '!B:B,FS!A46,'BS USD CONS '!M:M)+SUMIF('BS USD CONS '!B:B,FS!B46,'BS USD CONS '!M:M) -> 0
C47: =SUM(C44:C46) -> 0
B49: Total liabilities | C49: =C47+C42 -> -54683.328
B51: SHAREHOLDERS' EQUITY
B53: Share capital - Ordinary Shares | C53: =SUMIF('BS USD CONS '!B:B,FS!A53,'BS USD CONS '!M:M)+SUMIF('BS USD CONS '!B:B,FS!B53,'BS USD CONS '!M:M) -> -0.69022
B54: Share capital - Preferred Seed-1 | C54: =SUMIF('BS USD CONS '!B:B,FS!A54,'BS USD CONS '!M:M)+SUMIF('BS USD CONS '!B:B,FS!B54,'BS USD CONS '!M:M) -> -0.191
...

Sheet FS Notes
A1: 44926
A2: FS Notes
A3: Papaya Gaming Ltd
A4: USD
B7: Note 3 - Property and Equipment, Net
F8: Signed FS
B9: Group | D9: 44926 | F9: 44561
B10: Computers and electronic equipment | D10: ='TB LTD 12.22'!G33/1000 -> -2.38178 | F10: 96
B11: Vehicles | D11: ='TB LTD 12.22'!G31/1000 -> 743.03846 | F11: 3
B12: Office furniture and equipment | D12: =('TB LTD 12.22'!G35+'TB LTD 12.22'!G40)/1000 -> -53.74139 | F12: 10
B13: Leasehold improvements | D13: ='TB LTD 12.22'!G36/1000 -> -10.63371 | F13: 3
D14: =SUM(D10:D13) -> 676.28158 | F14: =SUM(F10:F13) -> 112
B15: Less – accumulated depreciation | D15: =SUM('TB LTD 12.22'!G32,'TB LTD 12.22'!G34,'TB LTD 12.22'!G37,'TB LTD 12.22'!G38,'TB LTD 12.22'!G39)/1000-'AJE 2022'!H70/1000 -> 13533.105 | F15: -31
B16: Total property and equipment, net | D16: =SUM(D14:D15) -> 14209.386 | F16: =SUM(F14:F15) -> 81
B20: Note 5 - Other current Liabilities
F21: Signed FS
B22: Group | D22: 44926 | F22: 44561 | I22: Other current liabilities INC
B23: Accrued expenses | D23: =-'TB LTD 12.22'!G105/1000-(O25+O24+O26)/1000 -> 74800.143 | F23: 622 | I23: Entity | K23: Account | M23: 44561 | O23: 44926
B24: Payroll and related expenses | D24: =-SUM('TB LTD 12.22'!G19:G28)/1000 -> 18836.575 | F24: 372 | I24: INC | K24: SVB Commission | M24: -125276.67 | O24: -518442.74
B25: WHT | D25: =-'TB LTD 12.22'!G9/1000 -> -1056.9565 | F25: 0 | I25: INC | K25: WorldPay Commission | M25: 0 | O25: -35916.02
B26: Income tax payable | D26: =-O27/1000 -> 101.4614 | F26: 0 | I26: INC | K26: James Kong | M26: 0 | O26: -8333.33
B27: Sales Tax | D27: ='AJE 2022'!#REF!/1000 -> #REF! | F27: 0 | I27: INC | K27: Income tax payable | M27: 714 | O27: -101461.4
D28: =SUM(D23:D27) -> #REF! | F28: =SUM(F23:F27) -> 994
B31: Note 11 - Supplementary statements of operation information
F32: Signed FS
B33: a. Research and development expenses: | D33: 44926 | F33: 44561
B34: Payroll and related expenses | D34: =SUM('TB LTD 12.22'!G173,'TB LTD 12.22'!G187:G232,'TB LTD 12.22'!G249,'TB LTD 12.22'!G251,'TB LTD 12.22'!G253)/1000 -> 24333.964 | F34: 1089
B35: Computer Maintenance | D35: =('TB LTD 12.22'!G350)/1000 -> 52.92387 | F35: 159
B36: Software subscription | D36: =SUM('TB LTD 12.22'!G238,'TB LTD 12.22'!G241,'TB LTD 12.22'!G243:G244,'TB LTD 12.22'!G247,'TB LTD 12.22'!G250)/1000 -> 182.33229 | F36: 0
B37: Professional consulting | D37: =SUM('TB LTD 12.22'!G239+'TB LTD 12.22'!G240+'TB LTD 12.22'!G254+'TB LTD 12.22'!G236)/1000 -> 181.41188 | F37: 535
B38: Share-based compensation | D38: ='TB LTD 12.22'!G245/1000+'P&L LTD USD'!E49/1000 -> -57.85857 | F38: 370
B39: Hosting and Servers | D39: ='TB LTD 12.22'!G252/1000 -> 82.4095 | F39: 0
B40: Other | D40: =SUM('TB LTD 12.22'!G233,'TB LTD 12.22'!G234,'TB LTD 12.22'!G237,'TB LTD 12.22'!G242,'TB LTD 12.22'!G246,'TB LTD 12.22'!G248)/1000 -> 1734.4082 | F40: 144
D41: =SUM(D34:D40) -> 26509.591 | F41: =SUM(F34:F40) -> 2297
F43: Signed FS
B44: b. Marketing expenses: | D44: 44926 | F44: 44561
B45: Payroll and related expenses | D45: =SUM('TB LTD 12.22'!G255:G260,'TB LTD 12.22'!G262:G269,'TB LTD 12.22'!G279)/1000 -> 1780.7246 | F45: 314
B46: Marketing and Advertising | D46: =SUM('TB LTD 12.22'!G270,'TB LTD 12.22'!G273,'TB LTD 12.22'!G275:G277,'TB LTD 12.22'!G329)/1000 -> 162.14992 | F46: 12695
B47: Software subscription | D47: =SUM('TB LTD 12.22'!G271:G272,'TB LTD 12.22'!G280)/1000 -> 173.66855 | F47: 0
B48: Share-based compensation | D48: ='TB LTD 12.22'!G281/1000+'P&L LTD USD'!E74/1000 -> -31.70624 | F48: 0
...

Sheet BS USD CONS 
C3: 2022 | E3: 2022 | G3: 2022 | I3: Cons Company | K3: 2022 | M3: 2022
C4: LTD | E4: INC | G4: India | K4: Cons | M4: Cons
C5: USD | E5: USD | G5: USD | K5: USD | M5: $ In thousands
B6: CURRENT ASSETS
B8: Cash | C8: =SUMIF('BS LTD USD '!B:B,'BS USD CONS '!$B8,'BS LTD USD '!E:E) -> 23504184 | E8: =SUMIF('BS INC'!B:B,'BS USD CONS '!$B8,'BS INC'!E:E) -> 24693919 | G8: =SUMIF('BS India'!B:B,'BS USD CONS '!$B8,'BS India'!E:E) -> 0 | K8: =+E8+C8+I8+G8 -> 48198103 | M8: =K8/1000 -> 48198.103 | N8: =K8/1000 -> 48198.103
B9: Account receivable | C9: =SUMIF('BS LTD USD '!B:B,'BS USD CONS '!$B9,'BS LTD USD '!E:E) -> 2668238.6 | E9: =SUMIF('BS INC'!B:B,'BS USD CONS '!$B9,'BS INC'!E:E) -> 0 | G9: =SUMIF('BS India'!B:B,'BS USD CONS '!$B9,'BS India'!E:E) -> 0 | K9: =+E9+C9+I9+G9 -> 2668238.6 | M9: =K9/1000 -> 2668.2386 | N9: =K9/1000 -> 2668.2386
B10: Related Party | C10: =SUMIF('BS LTD USD '!B:B,'BS USD CONS '!$B10,'BS LTD USD '!E:E) -> 24505604 | E10: =SUMIF('BS INC'!B:B,'BS USD CONS '!$B10,'BS INC'!E:E) -> -24505604 | G10: =SUMIF('BS India'!B:B,'BS USD CONS '!$B10,'BS India'!E:E) -> 0 | K10: =+E10+C10+I10+G10 -> -0.25 | M10: =K10/1000 -> -0.00025
B11: Related Party India | C11: =SUMIF('BS LTD USD '!B:B,'BS USD CONS '!$B11,'BS LTD USD '!E:E) -> 29383.12 | E11: =SUMIF('BS INC'!B:B,'BS USD CONS '!$B11,'BS INC'!E:E) -> 0 | G11: =SUMIF('BS India'!B:B,'BS USD CONS '!$B11,'BS India'!E:E) -> -29383.12 | K11: =+E11+C11+I11+G11 -> 0 | M11: =K11/1000 -> 0
B12: Short term deposit | C12: =SUMIF('BS LTD USD '!B:B,'BS USD CONS '!$B12,'BS LTD USD '!E:E) -> 30270082 | E12: =SUMIF('BS INC'!B:B,'BS USD CONS '!$B12,'BS INC'!E:E) -> 0 | G12: =SUMIF('BS India'!B:B,'BS USD CONS '!$B12,'BS India'!E:E) -> 0 | K12: =+E12+C12+I12+G12 -> 30270082 | M12: =K12/1000 -> 30270.082 | N12: =K12/1000 -> 30270.082
B13: Shareholders' loan | C13: =SUMIF('BS LTD USD '!B:B,'BS USD CONS '!$B13,'BS LTD USD '!E:E) -> 0 | E13: =SUMIF('BS INC'!B:B,'BS USD CONS '!$B13,'BS INC'!E:E) -> 0 | G13: =SUMIF('BS India'!B:B,'BS USD CONS '!$B13,'BS India'!E:E) -> 0 | K13: =+E13+C13+I13+G13 -> 0 | M13: =K13/1000 -> 0
B14: Prepaid Expenses | C14: =SUMIF('BS LTD USD '!B:B,'BS USD CONS '!$B14,'BS LTD USD '!E:E) -> 611164.27 | E14: =SUMIF('BS INC'!B:B,'BS USD CONS '!$B14,'BS INC'!E:E) -> 0 | G14: =SUMIF('BS India'!B:B,'BS USD CONS '!$B14,'BS India'!E:E) -> 0 | K14: =+E14+C14+I14+G14 -> 611164.27 | M14: =K14/1000 -> 611.16427 | N14: =K14/1000 -> 611.16427
B15: Other accounts receivable | C15: =SUMIF('BS LTD USD '!B:B,'BS USD CONS '!$B15,'BS LTD USD '!E:E) -> 2592878.1 | E15: =SUMIF('BS INC'!B:B,'BS USD CONS '!$B15,'BS INC'!E:E) -> 1085652.4 | G15: =SUMIF('BS India'!B:B,'BS USD CONS '!$B15,'BS India'!E:E) -> 142.43 | K15: =+E15+C15+I15+G15 -> 3678673 | M15: =K15/1000 -> 3678.673 | N15: =K15/1000 -> 3678.673
C16: =SUM(C8:C15) -> 84181534 | E16: =SUM(E8:E15) -> 1273967.5 | G16: =SUM(G8:G15) -> -29240.69 | K16: =+E16+C16+G16 -> 85426261 | M16: =K16/1000 -> 85426.261 | N16: =K16/1000 -> 85426.261
B18: NON-CURRENT ASSETS
B20: Investment | C20: =SUMIF('BS LTD USD '!B:B,'BS USD CONS '!$B20,'BS LTD USD '!E:E) -> 310312.38 | E20: =SUMIF('BS INC'!B:B,'BS USD CONS '!$B20,'BS INC'!E:E) -> 0 | G20: =SUMIF('BS India'!B:B,'BS USD CONS '!$B20,'BS India'!E:E) -> 0 | I20: =-C20 -> -310312.38 | K20: =+E20+C20+I20+G20 -> 0 | M20: =K20/1000 -> 0
B21: ROA Assets | C21: =SUMIF('BS LTD USD '!B:B,'BS USD CONS '!$B21,'BS LTD USD '!E:E) -> 20186267 | E21: =SUMIF('BS INC'!B:B,'BS USD CONS '!$B21,'BS INC'!E:E) -> 0 | G21: =SUMIF('BS India'!B:B,'BS USD CONS '!$B21,'BS India'!E:E) -> 0 | K21: =+E21+C21+I21+G21 -> 20186267 | M21: =K21/1000 -> 20186.267 | N21: =K21/1000 -> 20186.267
B22: Restricted LT deposit | C22: =SUMIF('BS LTD USD '!B:B,'BS USD CONS '!$B22,'BS LTD USD '!E:E) -> 2467206.5 | E22: =SUMIF('BS INC'!B:B,'BS USD CONS '!$B22,'BS INC'!E:E) -> 1199999 | G22: =SUMIF('BS India'!B:B,'BS USD CONS '!$B22,'BS India'!E:E) -> 0 | K22: =+E22+C22+I22+G22 -> 3667205.5 | M22: =K22/1000 -> 3667.2055 | N22: =K22/1000 -> 3667.2055
B23: Deferred tax assets | C23: =SUMIF('BS LTD USD '!B:B,'BS USD CONS '!$B23,'BS LTD USD '!E:E) -> 2030229.3 | E23: =SUMIF('BS INC'!B:B,'BS USD CONS '!$B23,'BS INC'!E:E) -> 0 | G23: =SUMIF('BS India'!B:B,'BS USD CONS '!$B23,'BS India'!E:E) -> 0 | K23: =+E23+C23+I23+G23 -> 2030229.3 | M23: =K23/1000 -> 2030.2293 | N23: =K23/1000 -> 2030.2293
B24: Reserve - Wordpay | C24: =SUMIF('BS LTD USD '!B:B,'BS USD CONS '!$B24,'BS LTD USD '!E:E) -> 0 | E24: =SUMIF('BS INC'!B:B,'BS USD CONS '!$B24,'BS INC'!E:E) -> 0 | G24: =SUMIF('BS India'!B:B,'BS USD CONS '!$B24,'BS India'!E:E) -> 0 | K24: =+E24+C24+I24+G24 -> 0 | M24: =K24/1000 -> 0
B25: Fixed assets, net | C25: =SUMIF('BS LTD USD '!B:B,'BS USD CONS '!$B25,'BS LTD USD '!E:E) -> 1659074.9 | E25: =SUMIF('BS INC'!B:B,'BS USD CONS '!$B25,'BS INC'!E:E) -> 0 | G25: =SUMIF('BS India'!B:B,'BS USD CONS '!$B25,'BS India'!C:C) -> 0 | K25: =+E25+C25+I25+G25 -> 1659074.9 | M25: =K25/1000 -> 1659.0749 | N25: =K25/1000 -> 1659.0749
C26: =SUM(C20:C25) -> 26653090 | E26: =SUM(E20:E25) -> 1199999 | G26: =SUM(G20:G25) -> 0 | I26: =SUM(I20:I25) -> -310312.38 | K26: =SUM(K20:K25) -> 27542777 | M26: =K26/1000 -> 27542.777 | N26: =K26/1000 -> 27542.777
N27: =K27/1000 -> 0
B28: Total Assets | C28: =+C26+C16 -> 1.1083462e+08 | E28: =+E26+E16 -> 2473966.5 | G28: =+G26+G16 -> -29240.69 | I28: =+I26+I16 -> -310312.38 | K28: =K16+K26 -> 1.1296904e+08 | M28: =K28/1000 -> 112969.04 | N28: =K28/1000 -> 112969.04
B31: CURRENT LIABILITIES
B33: Trade payables | C33: =SUMIF('BS LTD USD '!B:B,'BS USD CONS '!$B33,'BS LTD USD '!E:E) -> -7799848.3 | E33: =SUMIF('BS INC'!B:B,'BS USD CONS '!$B33,'BS INC'!E:E) -> -952301.09 | G33: =SUMIF('BS India'!B:B,'BS USD CONS '!$B33,'BS India'!C:C) -> 0 | K33: =+E33+C33+I33+G33 -> -8752149.4 | M33: =K33/1000 -> -8752.1494 | N33: =K33/1000 -> -8752.1494
B34: Accrued Expenses | C34: =SUMIF('BS LTD USD '!B:B,'BS USD CONS '!$B34,'BS LTD USD '!E:E) -> -14333945 | E34: =SUMIF('BS INC'!B:B,'BS USD CONS '!$B34,'BS INC'!E:E) -> 0 | G34: =SUMIF('BS India'!B:B,'BS USD CONS '!$B34,'BS India'!C:C) -> 0 | K34: =+E34+C34+I34+G34 -> -14333945 | M34: =K34/1000 -> -14333.945 | N34: =K34/1000 -> -14333.945
B35: Loan-Short Term | C35: =SUMIF('BS LTD USD '!B:B,'BS USD CONS '!$B35,'BS LTD USD '!E:E) -> 0 | E35: =SUMIF('BS INC'!B:B,'BS USD CONS '!$B35,'BS INC'!E:E) -> 0 | G35: =SUMIF('BS India'!B:B,'BS USD CONS '!$B35,'BS India'!C:C) -> 0 | K35: =+E35+C35+I35+G35 -> 0 | M35: =K35/1000 -> 0 | N35: =K35/1000 -> 0
B36: Contract liability | C36: =SUMIF('BS LTD USD '!B:B,'BS USD CONS '!$B36,'BS LTD USD '!E:E) -> -8960313.1 | E36: =SUMIF('BS INC'!B:B,'BS USD CONS '!$B36,'BS INC'!E:E) -> 0 | G36: =SUMIF('BS India'!B:B,'BS USD CONS '!$B36,'BS India'!C:C) -> 0 | K36: =+E36+C36+I36+G36 -> -8960313.1 | M36: =K36/1000 -> -8960.3131 | N36: =K36/1000 -> -8960.3131
B37: Tax provision | C37: =SUMIF('BS LTD USD '!B:B,'BS USD CONS '!$B37,'BS LTD USD '!E:E) -> -4156792.7 | E37: =SUMIF('BS INC'!B:B,'BS USD CONS '!$B37,'BS INC'!E:E) -> 0 | G37: =SUMIF('BS India'!B:B,'BS USD CONS '!$B37,'BS India'!C:C) -> 0 | K37: =+E37+C37+I37+G37 -> -4156792.7 | M37: =K37/1000 -> -4156.7927 | N37: =K37/1000 -> -4156.7927
B38: Warrant liability | C38: =SUMIF('BS LTD USD '!B:B,'BS USD CONS '!$B38,'BS LTD USD '!E:E) -> -1411357.4 | E38: =SUMIF('BS INC'!B:B,'BS USD CONS '!$B38,'BS INC'!E:E) -> 0 | G38: =SUMIF('BS India'!B:B,'BS USD CONS '!$B38,'BS India'!C:C) -> 0 | K38: =+E38+C38+I38+G38 -> -1411357.4 | M38: =K38/1000 -> -1411.3574 | N38: =K38/1000 -> -1411.3574
B39: ROA Liability ST | C39: =SUMIF('BS LTD USD '!B:B,'BS USD CONS '!$B39,'BS LTD USD '!E:E) -> -958916.79 | E39: =SUMIF('BS INC'!B:B,'BS USD CONS '!$B39,'BS INC'!E:E) -> 0 | G39: =SUMIF('BS India'!B:B,'BS USD CONS '!$B39,'BS India'!C:C) -> 0 | K39: =+E39+C39+I39+G39 -> -958916.79 | M39: =K39/1000 -> -958.91679 | N39: =K39/1000 -> -958.91679
B40: ROA Liability LT | C40: =SUMIF('BS LTD USD '!B:B,'BS USD CONS '!$B40,'BS LTD USD '!E:E) -> -17832251 | K40: =+E40+C40+I40+G40 -> -17832251 | M40: =K40/1000 -> -17832.251 | N40: =K40/1000 -> -17832.251
B41: Sales Tax Provision | C41: =SUMIF('BS LTD USD '!B:B,'BS USD CONS '!$B41,'BS LTD USD '!E:E) -> -15835320 | E41: =SUMIF('BS INC'!B:B,'BS USD CONS '!$B41,'BS INC'!E:E) -> 0 | G41: =SUMIF('BS India'!B:B,'BS USD CONS '!$B41,'BS India'!C:C) -> 0 | K41: =+E41+C41+I41+G41 -> -15835320 | M41: =K41/1000 -> -15835.32 | N41: =K41/1000 -> -15835.32
B42: Employees payables | C42: =SUMIF('BS LTD USD '!B:B,'BS USD CONS '!$B42,'BS LTD USD '!E:E) -> -4238437.8 | E42: =SUMIF('BS INC'!B:B,'BS USD CONS '!$B42,'BS INC'!E:E) -> 0 | G42: =SUMIF('BS India'!B:B,'BS USD CONS '!$B42,'BS India'!C:C) -> 0 | K42: =+E42+C42+I42+G42 -> -4238437.8 | M42: =K42/1000 -> -4238.4378 | N42: =K42/1000 -> -4238.4378
B43: Deferred tax liability | C43: =SUMIF('BS LTD USD '!B:B,'BS USD CONS '!$B43,'BS LTD USD '!E:E) -> 0 | E43: =SUMIF('BS INC'!B:B,'BS USD CONS '!$B43,'BS INC'!E:E) -> 0 | G43: =SUMIF('BS India'!B:B,'BS USD CONS '!$B43,'BS India'!C:C) -> 0 | K43: =+E43+C43+I43+G43 -> 0 | M43: =K43/1000 -> 0 | N43: =K43/1000 -> 0
B44: Other accounts payable | C44: =SUMIF('BS LTD USD '!B:B,'BS USD CONS '!$B44,'BS LTD USD '!E:E) -> 0 | E44: =SUMIF('BS INC'!B:B,'BS USD CONS '!$B44,'BS INC'!E:E) -> -1211355.4 | G44: =SUMIF('BS India'!B:B,'BS USD CONS '!$B44,'BS India'!C:C) -> -22095.35 | K44: =+E44+C44+I44+G44 -> -1233450.8 | M44: =K44/1000 -> -1233.4507 | N44: =K44/1000 -> -1233.4507
C45: =SUM(C33:C44) -> -75527182 | E45: =SUM(E31:E44) -> -2163656.5 | G45: =SUM(G31:G44) -> -22095.35 | K45: =+E45+C45+G45 -> -77712934 | M45: =K45/1000 -> -77712.934 | N45: =K45/1000 -> -77712.934
N46: =K46/1000 -> 0
N47: =K47/1000 -> 0
B48: Total liabilities | C48: =+C45 -> -75527182 | E48: =+E45 -> -2163656.5 | G48: =+G45 -> -22095.35 | I48: =+I45 -> 0 | K48: =+E48+C48+G48 -> -77712934 | M48: =K48/1000 -> -77712.934 | N48: =K48/1000 -> -77712.934
...

Sheet P&L USD CONS
D3: 2022 | F3: 2022 | H3: 2022 | J3: 2022 | L3: 2022 | N3: 2022
D4: LTD | F4: INC | H4: India | J4: Cons | L4: Cons | N4: Cons
D5: USD | F5: USD | H5: USD | J5: USD | L5: USD | N5: $ In thousands
B7: Total Revenues | D7: =SUMIF('P&L LTD USD'!C:C,B:B,'P&L LTD USD'!F:F) -> -3.3423953e+08 | F7: =SUMIF('P&L INC'!B:B,'P&L USD CONS'!$B:$B,'P&L INC'!F:F) -> -3.8458971e+08 | H7: =SUMIF('P&L India'!B:B,'P&L USD CONS'!$B:$B,'P&L India'!D:D) -> 0 | J7: =-F7 -> 3.8458971e+08 | L7: =(+F7+D7+H7+J7) -> -3.3423953e+08 | N7: =L7/1000 -> -334239.53
B9: Operations | D9: =SUMIF('P&L LTD USD'!C:C,B:B,'P&L LTD USD'!F:F) -> 23057127 | F9: =SUMIF('P&L INC'!B:B,'P&L USD CONS'!$B:$B,'P&L INC'!F:F) -> 19761872 | H9: =SUMIF('P&L India'!B:B,'P&L USD CONS'!$B:$B,'P&L India'!D:D) -> 0 | J9: =-F9 -> -19761872 | L9: =(+F9+D9+H9+J9) -> 23057127 | N9: =L9/1000 -> 23057.127
B11: Gross loss (profit) | D11: =D9+D7 -> -3.111824e+08 | F11: =F9+F7 -> -3.6482784e+08 | H11: =H9+H7 -> 0 | J11: =J9+J7 -> 3.6482784e+08 | L11: =L9+L7 -> -3.111824e+08 | N11: =N9+N7 -> -311182.4
B13: Research and development expenses, net | D13: =SUMIF('P&L LTD USD'!C:C,B:B,'P&L LTD USD'!F:F) -> 20781725 | F13: =SUMIF('P&L INC'!B:B,'P&L USD CONS'!$B:$B,'P&L INC'!F:F) -> 0 | H13: =-SUMIF('P&L India'!B:B,'P&L USD CONS'!$B:$B,'P&L India'!D:D) -> 0 | L13: =(+F13+D13+H13+J13) -> 20781725 | N13: =L13/1000 -> 20781.725
B15: Marketing expenses | D15: =SUMIF('P&L LTD USD'!C:C,B:B,'P&L LTD USD'!F:F) -> 2.5601775e+08 | F15: =SUMIF('P&L INC'!B:B,'P&L USD CONS'!$B:$B,'P&L INC'!F:F) -> 24957328 | H15: =SUMIF('P&L India'!B:B,'P&L USD CONS'!$B:$B,'P&L India'!D:D) -> 30322.73 | J15: =-F15 -> -24957328 | L15: =(+F15+D15+H15+J15) -> 2.5604807e+08 | N15: =L15/1000 -> 256048.07
B17: General and administrative expenses | D17: =SUMIF('P&L LTD USD'!C:C,B:B,'P&L LTD USD'!F:F) -> 8244728.4 | F17: =SUMIF('P&L INC'!B:B,'P&L USD CONS'!$B:$B,'P&L INC'!F:F) -> 182761.95 | H17: =SUMIF('P&L India'!B:B,'P&L USD CONS'!$B:$B,'P&L India'!D:D) -> 20751.2 | J17: =-F17*1.07 -> -195555.29 | L17: =(+F17+D17+H17+J17) -> 8252686.3 | N17: =L17/1000 -> 8252.6863 | O17: =J17+F17 -> -12793.337
B19: Operating expenses | D19: =+D17+D15+D13 -> 2.850442e+08 | F19: =+F17+F15+F13 -> 25140090 | H19: =+H17+H15+H13 -> 51073.93 | J19: =+J17+J15+J13 -> -25152883 | L19: =+L17+L15+L13 -> 2.8508248e+08 | N19: =+N17+N15+N13 -> 285082.48
B21: Operating loss (pprofit) | D21: =SUMIF('P&L LTD USD'!C:C,B:B,'P&L LTD USD'!F:F) -> -26138202 | F21: =F11+F19 -> -3.3968775e+08 | H21: =H11+H19 -> 51073.93 | J21: =J11+J19 -> 3.3967496e+08 | L21: =L11+L19 -> -26099922 | N21: =N19+N11 -> -26099.922
B23: Financial expenses, net | D23: =SUMIF('P&L LTD USD'!C:C,B:B,'P&L LTD USD'!F:F) -> 242412.35 | F23: =SUMIF('P&L INC'!B:B,'P&L USD CONS'!$B:$B,'P&L INC'!F:F) -> 179789.7 | H23: =SUMIF('P&L India'!B:B,'P&L USD CONS'!$B:$B,'P&L India'!D:D) -> 262.11 | J23: =-F23 -> -179789.7 | L23: =(+F23+D23+H23+J23) -> 242674.46 | N23: =L23/1000 -> 242.67446
B25: TP Expenses | D25: =SUMIF('P&L LTD USD'!C:C,B:B,'P&L LTD USD'!F:F) -> 0 | F25: =SUMIF('P&L INC'!B:B,'P&L USD CONS'!$B:$B,'P&L INC'!F:F) -> 3.3940583e+08 | H25: =SUMIF('P&L India'!B:B,'P&L USD CONS'!$B:$B,'P&L India'!D:D) -> 0 | J25: =-F25 -> -3.3940583e+08 | L25: =(+F25+D25+H25+J25) -> 0 | N25: =L25/1000 -> 0
B27: Equity | D27: =SUMIF('P&L LTD USD'!C:C,B:B,'P&L LTD USD'!F:F) -> -12793.34 | F27: =SUMIF('P&L INC'!B:B,'P&L USD CONS'!$B:$B,'P&L INC'!D:D) -> 0 | H27: =SUMIF('P&L India'!B:B,'P&L USD CONS'!$B:$B,'P&L India'!D:D) -> 0 | L27: =(+F27+D27+H27) -> -12793.34 | N27: =L27/1000 -> -12.79334
B29: loss before taxes | D29: =SUM(D21:D27) -> -25908583 | F29: =SUM(F21:F27) -> -102130.89 | H29: =SUM(H21:H27) -> 51336.04 | J29: =SUM(J21:J27) -> 89337.553 | L29: =SUM(L21:L27) -> -25870040 | N29: =SUM(N21:N27) -> -25870.04
B31: Tax expenses | D31: =SUMIF('P&L LTD USD'!C:C,B:B,'P&L LTD USD'!F:F) -> 3503498.7 | F31: =SUMIF('P&L INC'!B:B,'P&L USD CONS'!$B:$B,'P&L INC'!F:F) -> 89337.55 | H31: =SUMIF('P&L India'!B:B,'P&L USD CONS'!$B:$B,'P&L India'!D:D) -> 0 | J31: =-F31 -> -89337.55 | L31: =(+F31+D31+H31+J31) -> 3503498.7 | N31: =L31/1000 -> 3503.4987
B33: Net loss ( profit ) | D33: =+D29+D31 -> -22405084 | F33: =+F31+F29 -> -12793.34 | H33: =+H31+H29 -> 51336.04 | J33: =+J31+J29 -> 0.0034999967 | L33: =+L29+L31 -> -22366542 | N33: =+N29+N31 -> -22366.542
D34: =D33-'P&L LTD USD'!F122 -> 0 | F34: =F33-'P&L INC'!F51 -> -1.1990778e-08 | H34: ='P&L India'!D28-H33 -> 0
D35: =D9+D13+D15+D17+D23+D31 -> 3.1184724e+08 | F35: =F9+F13+F15+F17+F23+F31 -> 45171089 | H35: =H9+H13+H15+H17+H23+H31 -> 51336.04 | L35: =L9+L13+L15+L17+L23+L31 -> 3.1188578e+08 | N35: -21787.447
N36: =N35-N33 -> 579.09429

Sheet COA LTD
A1: חשבון | B1: תאור חשבון
A2: 10000 | B2: Leumi IL 568400 | C2: BS | D2: cash
A3: 10001 | B3: Leumi $ 568400 | C3: BS | D3: cash
A4: 10002 | B4: Leumi GBP 568400 | C4: BS | D4: cash
A5: 10003 | B5: Leumi EURO 568400 | C5: BS | D5: cash
A6: 10004 | B6: SVB LTD | C6: BS | D6: cash
A7: 10200 | B7: Bank Paypal LTD-USD | C7: BS | D7: cash
A8: 11004 | B8: Applovin | C8: BS | D8: Account receivable
A9: 11100 | B9: Account receivable | C9: BS | D9: Account receivable
A10: 12000 | B10: Papaya Gaming INC | C10: BS | D10: Related Party
A11: 13000 | B11: Vat D/C | C11: BS | D11: Other accounts receivable
A12: 13002 | B12: VAT input | C12: BS | D12: Other accounts receivable
A13: 13003 | B13: VAT Input FA | C13: BS | D13: Other accounts receivable
... A136: 51200 | B136: Premium | C136: BS | D136: Share premium
A137: 53000 | B137: Capital reserve for share-based Payment | C137: BS | D137: Other accounts receivable | E137: 0
A138: 54000 | B138: Accumulated deficit | C138: BS | D138: Accumulated deficit | E138: 0
A139: 60202000 | B139: Revenue - Revenue Worldpay IC | C139: PL | D139: Revenues | E139: Revenues
A140: 60202007 | B140: Revenue - Revenue Paypal IL IC | C140: PL | D140: Revenues | E140: Revenues
A141: 60202009 | B141: Revenue - Revenue Paypal US IC | C141: PL | D141: Revenues | E141: Revenues
A142: 60202016 | B142: Revenue - Revenue Cyber Source IC | C142: PL | D142: Revenues | E142: Revenues
A143: 60202023 | B143: Revenue - Revenue Braintree IC | C143: PL | D143: Revenues | E143: Revenues
A144: 60202101 | B144: Revenue - Israeli Customer | C144: PL | D144: Revenues | E144: Revenues
A145: 60202094 | B145: Revenue - Advertising income | C145: PL | D145: Revenues | E145: ads revenue
A146: 60202095 | B146: Revenue - Advertising income- VAT | C146: PL | D146: Revenues | E146: ads revenue
A147: 60202097 | B147: Revenue - Net cash Balance | C147: PL | D147: Revenues | E147: Net cash
A148: 60202098 | B148: Revenue - Self invoice Debit | C148: PL | D148: Revenues | E148: Revenues
A149: 60202099 | B149: Revenue - Self invoice Credit | C149: PL | D149: Revenues | E149: Revenues
A150: 60202100 | B150: Revenue - Withdrawals | C150: PL | D150: Revenues | E150: Withdrawals
... A154: 60203016 | B154: Revenue - Revenue Paypal Cyber Source Receiveab | C154: PL | D154: Revenues | E154: Revenues
A155: 60203094 | B155: Revenue - Revenue Advertising Receiveable | C155: PL | D155: Revenues | E155: ads revenue | F155: ;
A156: 70201200 | B156: Tax - Tax expenses current period | C156: PL | D156: Tax expenses | E156: Tax expenses
A157: 80010100 | B157: Operations Support- Base salary | C157: PL | D157: Operations | E157: Salary
A158: 80010101 | B158: Operations Support- Contractors as employees Sup | C158: PL | D158: Operations | E158: Salary
A159: 80010102 | B159: Operations Support- Options | C159: PL | D159: Operations | E159: option expenses
A160: 80010104 | B160: Operations Support- Bonus provision | C160: PL | D160: Operations | E160: Salary
A161: 80010105 | B161: Operations Support- Bonus-subcontractors | C161: PL | D161: Operations | E161: Salary
A162: 80010107 | B162: Operations Support- vacation provision | C162: PL | D162: Operations | E162: Salary
A163: 80010108 | B163: Operations Support- Social security | C163: PL | D163: Operations | E163: Salary
A164: 80010109 | B164: Operations Support- Pension | C164: PL | D164: Operations | E164: Salary
A165: 80010110 | B165: Operations Support- Education fund | C165: PL | D165: Operations | E165: Salary
...

Sheet FS Notes ILS
B3: Note 3 - חייבים ויתרות חובה
F4: Signed FS
B5: Group | D5: 44926 | F5: 44561
B6: מוסדות ממשלתיים | D6: =SUM('TB LTD 12.22'!F14:F16)/1000 -> 4373.887 | F6: 4413
B7: הוצאות מראש | D7: ='BS LTD USD '!K14/1000 -> 2150.687 | F7: 3162
B8: חייבים על חשבון מניות | D8: ='TB LTD 12.22'!F157/1000 -> 68.76185 | F8: 171
B9: חייבים בגין הקצב | D9: =SUM('TB LTD 12.22'!F17)/1000 -> 4679.8518 | F9: 0
B11: סה״כ | D11: =SUM(D6:D9) -> 11273.188 | F11: =SUM(F6:F9) -> 7746
D12: =D11-'BS LTD USD '!N14 -> 0
B14: Note 4 - רכוש קבוע נטו
F15: Signed FS
B16: Group | D16: 44926 | F16: 44561
B17: מחשבים וציוד אלקטרוני | D17: =SUM('TB LTD 12.22'!F30,'TB LTD 12.22'!F31)/1000 -> 3093.2701 | F17: 1308
B18: ריהוט וציוד משרדי | D18: =('TB LTD 12.22'!F27+'TB LTD 12.22'!F28)/1000 -> 2817.3151 | F18: 574
B19: שיפורים במושכר | D19: ='TB LTD 12.22'!F29/1000 -> 758.76923 | F19: 118
D20: =SUM(D17:D19) -> 6669.3544 | F20: =SUM(F17:F19) -> 2000
B22: בניכוי פחת שנצבר | D22: =SUM('TB LTD 12.22'!F33:F37)/1000 -> -1072.9372 | F22: -369
B24: סה״כ | D24: =SUM(D20:D22) -> 5596.4173 | F24: =SUM(F20:F22) -> 1631
D25: =D24-'BS LTD USD '!M23 -> 0
B26: הוצאות פחת | D26: 704 | F26: 268
B29: Note 4 - זכאים ויתרות זכות
F30: Signed FS
B31: Group | D31: 44926 | F31: 44561
B32: הוצאות לשלם | D32: =-'BS LTD USD '!M33 -> 50441.183 | F32: 33054
B33: מיסים לשלם | D33: =-'BS LTD USD '!M37-'BS LTD USD '!M36-SUM('TB LTD 12.22'!F36,'TB LTD 12.22'!F111,'TB LTD 12.22'!F38)/1000 -> 76401.737 | F33: 21536
B34: שכר | D34: =-SUM('TB LTD 12.22'!F19,'TB LTD 12.22'!F112,'TB LTD 12.22'!F116:F124)/1000 -> 53451.326 | F34: 2449
B36: סה״כ | D36: =SUM(D32:D34) -> 180294.25 | F36: =SUM(F32:F34) -> 57039
D37: =D36+'BS LTD USD '!N33 -> 44585.757

Sheet BS LTD USD 
B1: -17832251 | C1: USD -LTD | I1: ILS -LTD
C3: 44926 | E3: 44926 | I3: 44926 | K3: 44926
A4: Restricted | D4: JE | E4: AJE | J4: JE | K4: AJE
B6: CURRENT ASSETS
B8: Cash | C8: =SUMIF('TB LTD 12.22'!I:I,B8,'TB LTD 12.22'!G:G) -> 23504184 | E8: =C8+D8 -> 23504184 | I8: =SUMIF('TB LTD 12.22'!I:I,B8,'TB LTD 12.22'!F:F) -> 82711224 | K8: =I8+J8 -> 82711224 | L8: =K8/E8 -> 3.519 | M8: =K8/1000 -> 82711.224
B9: Account receivable | C9: =SUMIF('TB LTD 12.22'!I:I,B9,'TB LTD 12.22'!G:G) -> 2668238.6 | D9: ='AJE 2022'!G49 -> 0 | E9: =C9+D9 -> 2668238.6 | I9: =SUMIF('TB LTD 12.22'!I:I,B9,'TB LTD 12.22'!F:F) -> 9389531.7 | J9: ='AJE 2022'!J49 -> 0 | K9: =I9+J9 -> 9389531.7 | L9: =K9/E9 -> 3.519 | M9: =K9/1000 -> 9389.5317
B10: Related Party | C10: =SUMIF('TB LTD 12.22'!I:I,B10,'TB LTD 12.22'!G:G) -> 24505604 | D10: =-'AJE 2022'!H13-'AJE 2022'!H23-'AJE 2022'!H28-'AJE 2022'!H33+'AJE 2022'!G43-'AJE 2022'!H50 -> 0 | E10: =C10+D10 -> 24505604 | I10: =SUMIF('TB LTD 12.22'!I:I,B10,'TB LTD 12.22'!F:F) -> 86235220 | J10: =-'AJE 2022'!K13-'AJE 2022'!K23-'AJE 2022'!K28-'AJE 2022'!K33+'AJE 2022'!J43-'AJE 2022'!J49 -> 0 | K10: =I10+J10 -> 86235220 | L10: =K10/E10 -> 3.519 | M10: =K10/1000 -> 86235.22 | N10: =M10+M11 -> 86338.619 | O10: =E10*3.519 -> 86235220 | P10: =O10-K10 -> -0.003370136
B11: Related Party India | C11: =SUMIF('TB LTD 12.22'!I:I,B11,'TB LTD 12.22'!G:G) -> 29383.12 | E11: =C11+D11 -> 29383.12 | I11: =SUMIF('TB LTD 12.22'!I:I,B11,'TB LTD 12.22'!F:F) -> 103399.2 | K11: =I11+J11 -> 103399.2 | L11: =K11/E11 -> 3.519 | M11: =K11/1000 -> 103.3992
B12: Short term deposit | C12: =SUMIF('TB LTD 12.22'!I:I,B12,'TB LTD 12.22'!G:G) -> 30270082 | D12: ='AJE 2022'!H93 -> 0 | E12: =C12+D12 -> 30270082 | I12: =SUMIF('TB LTD 12.22'!I:I,B12,'TB LTD 12.22'!F:F) -> 106520419 | J12: ='AJE 2022'!K93 -> 0 | K12: =I12+J12 -> 106520419 | L12: =K12/E12 -> 3.519 | M12: =K12/1000 -> 106520.42
B13: Shareholders' loan | C13: =SUMIF('TB LTD 12.22'!I:I,B13,'TB LTD 12.22'!G:G) -> 0 | E13: =C13+D13 -> 0 | I13: =SUMIF('TB LTD 12.22'!I:I,B13,'TB LTD 12.22'!F:F) -> 0 | K13: =I13+J13 -> 0 | L13: =K13/E13 -> #DIV/0! | M13: =K13/1000 -> 0
B14: Prepaid Expenses | C14: =SUMIF('TB LTD 12.22'!I:I,B14,'TB LTD 12.22'!G:G) -> 611164.27 | D14: =-'AJE 2022'!H81 -> 0 | E14: =C14+D14 -> 611164.27 | I14: =SUMIF('TB LTD 12.22'!I:I,B14,'TB LTD 12.22'!F:F) -> 2150687 | J14: =-'AJE 2022'!K81 -> 0 | K14: =I14+J14 -> 2150687 | L14: =K14/E14 -> 3.519 | M14: =K14/1000 -> 2150.687 | N14: =M14+M15 -> 11273.188
B15: Other accounts receivable | C15: =SUMIF('TB LTD 12.22'!I:I,B15,'TB LTD 12.22'!G:G) -> 2592878.1 | E15: =C15+D15 -> 2592878.1 | I15: =SUMIF('TB LTD 12.22'!I:I,B15,'TB LTD 12.22'!F:F) -> 9122500.7 | K15: =I15+J15 -> 9122500.7 | L15: =K15/E15 -> 3.5182913 | M15: =K15/1000 -> 9122.5006
C16: =SUM(C8:C15) -> 84181534 | D16: =SUM(D8:D15) -> 0 | E16: =SUM(E8:E15) -> 84181534 | I16: =SUM(I8:I15) -> 2.9623298e+08 | J16: =SUM(J8:J15) -> 0 | K16: =SUM(K8:K15) -> 2.9623298e+08 | L16: =K16/E16 -> 3.5189782 | M16: =K16/1000 -> 296232.98 | O16: 297457
L17: =K17/E17 -> #DIV/0! | M17: =K17/1000 -> 0 | O17: 89523
B18: NON-CURRENT ASSETS | L18: =K18/E18 -> #DIV/0! | M18: =K18/1000 -> 0
L19: =K19/E19 -> #DIV/0! | M19: =K19/1000 -> 0
B20: Investment | C20: =SUMIF('TB LTD 12.22'!I:I,B20,'TB LTD 12.22'!G:G) -> 297519.04 | D20: =-'P&L INC'!F51 -> 12793.34 | E20: =C20+D20 -> 310312.38 | I20: =SUMIF('TB LTD 12.22'!I:I,B20,'TB LTD 12.22'!F:F) -> 970500.41 | J20: =-'P&L LTD USD'!K121 -> 42857.689 | K20: =I20+J20 -> 1013358.1 | L20: =K20/E20 -> 3.2656064 | M20: =K20/1000 -> 1013.3581
B21: Restricted LT deposit | C21: =SUMIF('TB LTD 12.22'!I:I,B21,'TB LTD 12.22'!G:G) -> 2467206.5 | E21: =C21+D21 -> 2467206.5 | I21: =SUMIF('TB LTD 12.22'!I:I,B21,'TB LTD 12.22'!F:F) -> 8682099.8 | K21: =I21+J21 -> 8682099.8 | L21: =K21/E21 -> 3.519 | M21: =K21/1000 -> 8682.0997
B22: ROA Assets | C22: =SUMIF('TB LTD 12.22'!I:I,B22,'TB LTD 12.22'!G:G) -> 20186267 | D22: ='AJE 2022'!G78 -> 0 | E22: =C22+D22 -> 20186267 | I22: =SUMIF('TB LTD 12.22'!I:I,B22,'TB LTD 12.22'!F:F) -> 71364452 | J22: ='AJE 2022'!J78 -> 0 | K22: =I22+J22 -> 71364452 | L22: =K22/E22 -> 3.5352971 | M22: =K22/1000 -> 71364.452
B23: Fixed assets, net | C23: =SUMIF('TB LTD 12.22'!I:I,B23,'TB LTD 12.22'!G:G) -> 1659074.9 | E23: =C23+D23 -> 1659074.9 | I23: =SUMIF('TB LTD 12.22'!I:I,B23,'TB LTD 12.22'!F:F) -> 5596417.2 | K23: =I23+J23 -> 5596417.2 | L23: =K23/E23 -> 3.3732155 | M23: =K23/1000 -> 5596.4173
B24: Deferred tax assets | C24: =SUMIF('TB LTD 12.22'!I:I,B24,'TB LTD 12.22'!G:G) -> 2030229.3 | D24: ='AJE 2022'!G56 -> 0 | E24: =C24+D24 -> 2030229.3 | I24: =SUMIF('TB LTD 12.22'!I:I,B24,'TB LTD 12.22'!F:F) -> 7144377 | J24: ='AJE 2022'!J56 -> 0 | K24: =I24+J24 -> 7144377 | L24: =K24/E24 -> 3.519 | M24: =K24/1000 -> 7144.377 | N24: =K24/3.519 -> 2030229.3 | O24: =N24-E24 -> -0.0048536519
C25: =SUM(C18:C24) -> 26640297 | D25: =SUM(D18:D24) -> 12793.34 | E25: =SUM(E18:E24) -> 26653090 | I25: =SUM(I18:I24) -> 93757846 | J25: =SUM(J18:J24) -> 42857.689 | K25: =SUM(K18:K24) -> 93800704 | L25: =K25/E25 -> 3.5193182 | M25: =K25/1000 -> 93800.704
L26: =K26/E26 -> #DIV/0! | M26: =K26/1000 -> 0
B27: Total Assets | C27: =+C25+C16 -> 1.1082183e+08 | D27: =+D25+D16 -> 12793.34 | E27: =+E25+E16 -> 1.1083462e+08 | I27: =+I25+I16 -> 3.8999083e+08 | J27: =+J25+J16 -> 42857.689 | K27: =+K25+K16 -> 3.9003369e+08 | L27: =K27/E27 -> 3.5190599 | M27: =K27/1000 -> 390033.69
L28: =K28/E28 -> #DIV/0! | M28: =K28/1000 -> 0
L29: =K29/E29 -> #DIV/0! | M29: =K29/1000 -> 0
B30: CURRENT LIABILITIES | L30: =K30/E30 -> #DIV/0! | M30: =K30/1000 -> 0
L31: =K31/E31 -> #DIV/0! | M31: =K31/1000 -> 0
B32: Trade payables | C32: =SUMIF('TB LTD 12.22'!I:I,B32,'TB LTD 12.22'!G:G) -> -7799848.3 | E32: =C32+D32 -> -7799848.3 | I32: =SUMIF('TB LTD 12.22'!I:I,B32,'TB LTD 12.22'!F:F) -> -27447666 | J32: =-'AJE 2022'!K36 -> 0 | K32: =I32+J32 -> -27447666 | L32: =K32/E32 -> 3.519 | M32: =K32/1000 -> -27447.666
B33: Accrued Expenses | C33: =SUMIF('TB LTD 12.22'!I:I,B33,'TB LTD 12.22'!G:G) -> -14333945 | D33: =-'AJE 2022'!H89 -> 0 | E33: =C33+D33 -> -14333945 | I33: =SUMIF('TB LTD 12.22'!I:I,B33,'TB LTD 12.22'!F:F) -> -50441183 | J33: =-'AJE 2022'!K89 -> 0 | K33: =I33+J33 -> -50441183 | L33: =K33/E33 -> 3.5190021 | M33: =K33/1000 -> -50441.183 | N33: =M33+M36+M37+M40+M38 -> -135708.49
B34: Loan-Short Term | C34: =SUMIF('TB LTD 12.22'!I:I,B34,'TB LTD 12.22'!G:G) -> 0 | E34: =C34+D34 -> 0 | I34: =SUMIF('TB LTD 12.22'!I:I,B34,'TB LTD 12.22'!F:F) -> 0 | K34: =I34+J34 -> 0 | L34: =K34/E34 -> #DIV/0! | M34: =K34/1000 -> 0
B35: Contract liability | C35: =SUMIF('TB LTD 12.22'!I:I,B35,'TB LTD 12.22'!G:G) -> -8960313.1 | E35: =C35+D35 -> -8960313.1 | I35: =SUMIF('TB LTD 12.22'!I:I,B35,'TB LTD 12.22'!F:F) -> -31531317 | J35: =-'AJE 2022'!K42 -> 0 | K35: =I35+J35 -> -31531317 | L35: =K35/E35 -> 3.5189973 | M35: =K35/1000 -> -31531.317
B36: Tax provision | C36: =SUMIF('TB LTD 12.22'!I:I,B36,'TB LTD 12.22'!G:G) -> -4203504.2 | D36: =-('AJE 2022'!G109-'AJE 2022'!H105) -> 46711.547 | E36: =C36+D36 -> -4156792.7 | I36: =SUMIF('TB LTD 12.22'!I:I,B36,'TB LTD 12.22'!F:F) -> -14792131 | J36: =-('AJE 2022'!J109-'AJE 2022'!K105) -> 164377.93 | K36: =I36+J36 -> -14627753 | L36: =K36/E36 -> 3.519 | M36: =K36/1000 -> -14627.753 | N36: =K36/3.519 -> -4156792.7 | O36: =N36-E36 -> -0.002790567
B37: Sales tax Provision | C37: =SUMIF('TB LTD 12.22'!I:I,B37,'TB LTD 12.22'!G:G) -> -15835320 | D37: =-'AJE 2022'!G43 -> 0 | E37: =C37+D37 -> -15835320 | I37: =SUMIF('TB LTD 12.22'!I:I,B37,'TB LTD 12.22'!F:F) -> -55724490 | J37: =-'AJE 2022'!K44 -> 0 | K37: =I37+J37 -> -55724490 | L37: =K37/E37 -> 3.519 | M37: =K37/1000 -> -55724.49 | N37: =E37*3.519 -> -55724490 | O37: =N37-K37 -> -0.4662
B38: Employees payables | C38: =SUMIF('TB LTD 12.22'!I:I,B38,'TB LTD 12.22'!G:G) -> -4238437.8 | E38: =C38+D38 -> -4238437.8 | I38: =SUMIF('TB LTD 12.22'!I:I,B38,'TB LTD 12.22'!F:F) -> -14915063 | K38: =I38+J38 -> -14915063 | L38: =K38/E38 -> 3.519 | M38: =K38/1000 -> -14915.063
B39: ROA Liability ST | C39: =SUMIF('TB LTD 12.22'!I:I,B39,'TB LTD 12.22'!G:G) -> -18791168 | D39: =--17832251.4423087 -> 17832251 | E39: =C39+D39 -> -958916.79 | I39: =SUMIF('TB LTD 12.22'!I:I,B39,'TB LTD 12.22'!F:F) -> -66126121 | J39: =62751693 -> 62751693 | K39: =I39+J39 -> -3374428 | L39: =K39/E39 -> 3.5189998 | M39: =K39/1000 -> -3374.428
B40: Other accounts payable | C40: =SUMIF('TB LTD 12.22'!I:I,B40,'TB LTD 12.22'!G:G) -> 0 | E40: =C40+D40 -> 0 | I40: =SUMIF('TB LTD 12.22'!I:I,B40,'TB LTD 12.22'!F:F) -> 0 | K40: =I40+J40 -> 0 | L40: =K40/E40 -> #DIV/0! | M40: =K40/1000 -> 0
B41: Warrant liability | C41: =SUMIF('TB LTD 12.22'!I:I,B41,'TB LTD 12.22'!G:G) -> -1411357.4 | E41: =C41+D41 -> -1411357.4 | I41: =SUMIF('TB LTD 12.22'!I:I,B41,'TB LTD 12.22'!F:F) -> -4966566.8 | K41: =I41+J41 -> -4966566.8 | L41: =K41/E41 -> 3.519 | M41: =K41/1000 -> -4966.5668
C42: =SUM(C32:C41) -> -75573894 | D42: =SUM(D32:D41) -> 17878963 | E42: =SUM(E32:E41) -> -57694931 | I42: =SUM(I32:I41) -> -265944538 | J42: =SUM(J32:J41) -> 62916071 | K42: =SUM(K32:K41) -> -2.0302847e+08 | L42: =K42/E42 -> 3.5190001 | M42: =K42/1000 -> -203028.47
L43: =K43/E43 -> #DIV/0!
...

Sheet P&L LTD  USD
D1: USD -LTD | J1: ILS -LTD
D3: 2022 | F3: 2022 | J3: 2022 | L3: 2022
E4: JE | F4: AJE | J4: LTD | K4: JE | L4: AJE
B5: Revenues | C5: Revenues | D5: =SUMIFS('TB LTD 12.22'!G:G,'TB LTD 12.22'!I:I,$B5,'TB LTD 12.22'!J:J,$C5) -> -3.3963699e+08 | E5: ='AJE 2022'!G12+'AJE 2022'!G27 -> 0 | F5: =D5+E5 -> -3.3963699e+08 | G5: =SUM('P&L INC'!F12:F17) -> -3.3940583e+08 | J5: =SUMIFS('TB LTD 12.22'!F:F,'TB LTD 12.22'!I:I,$B5,'TB LTD 12.22'!J:J,$C5) -> -1.1480931e+09 | K5: ='AJE 2022'!J12+'AJE 2022'!J27 -> 0 | L5: =J5+K5 -> -1.1480931e+09
B6: Revenues | C6: ads revenue | D6: =SUMIFS('TB LTD 12.22'!G:G,'TB LTD 12.22'!I:I,$B6,'TB LTD 12.22'!J:J,$C6) -> -2600569.2 | F6: =D6+E6 -> -2600569.2 | G6: =F5-G5 -> -231159.39 | J6: =SUMIFS('TB LTD 12.22'!F:F,'TB LTD 12.22'!I:I,$B6,'TB LTD 12.22'!J:J,$C6) -> -8791096.3 | L6: =J6+K6 -> -8791096.3
B7: Revenues | C7: Net Cash | D7: =SUMIFS('TB LTD 12.22'!G:G,'TB LTD 12.22'!I:I,$B7,'TB LTD 12.22'!J:J,$C7) -> 4931358.5 | F7: =D7+E7 -> 4931358.5 | G7: 249578 | J7: =SUMIFS('TB LTD 12.22'!F:F,'TB LTD 12.22'!I:I,$B7,'TB LTD 12.22'!J:J,$C7) -> 16699482 | L7: =J7+K7 -> 16699482
B8: Revenues | C8: withdrawals | D8: =SUMIFS('TB LTD 12.22'!G:G,'TB LTD 12.22'!I:I,$B8,'TB LTD 12.22'!J:J,$C8) -> 3066670 | F8: =D8+E8 -> 3066670 | J8: =SUMIFS('TB LTD 12.22'!F:F,'TB LTD 12.22'!I:I,$B8,'TB LTD 12.22'!J:J,$C8) -> 10391330 | L8: =J8+K8 -> 10391330
B9: Revenues | C9: Hekzev | D9: =SUMIFS('TB LTD 12.22'!G:G,'TB LTD 12.22'!I:I,$B9,'TB LTD 12.22'!J:J,$C9) -> 0.0099999999 | F9: =D9+E9 -> 0.0099999999 | J9: =SUMIFS('TB LTD 12.22'!F:F,'TB LTD 12.22'!I:I,$B9,'TB LTD 12.22'!J:J,$C9) -> 0 | L9: =J9+K9 -> 0
B10: Revenues | C10: Total Revenues | D10: =SUM(D5:D8) -> -3.3423953e+08 | E10: =SUM(E5:E8) -> 0 | F10: =SUM(F5:F8) -> -3.3423953e+08 | J10: =SUM(J5:J8) -> -1.1297934e+09 | K10: =SUM(K5:K8) -> 0 | L10: =SUM(L5:L8) -> -1.1297934e+09 | N10: =L10/1000 -> -1129793.4
C12: Operations | D12: =SUM(D13:D31) -> 23057127 | E12: =SUM(E13:E31) -> 0 | F12: =SUM(F13:F31) -> 23057127 | J12: =SUM(J13:J31) -> 77948520 | K12: =SUM(K13:K31) -> 0 | L12: =SUM(L13:L31) -> 77948520 | N12: =L12/1000 -> 77948.52
A13: Payroll | B13: Operations | C13: Salary | D13: =SUMIFS('TB LTD 12.22'!G:G,'TB LTD 12.22'!I:I,$B13,'TB LTD 12.22'!J:J,$C13) -> 844546.94 | F13: =D13+E13 -> 844546.94 | J13: =SUMIFS('TB LTD 12.22'!F:F,'TB LTD 12.22'!I:I,$B13,'TB LTD 12.22'!J:J,$C13) -> 2852594.4 | L13: =J13+K13 -> 2852594.4
A14: Overheads | B14: Operations | C14: Professional Services | D14: =SUMIFS('TB LTD 12.22'!G:G,'TB LTD 12.22'!I:I,$B14,'TB LTD 12.22'!J:J,$C14) -> 321517.7 | F14: =D14+E14 -> 321517.7 | J14: =SUMIFS('TB LTD 12.22'!F:F,'TB LTD 12.22'!I:I,$B14,'TB LTD 12.22'!J:J,$C14) -> 1079539.9 | L14: =J14+K14 -> 1079539.9
A15: Overheads | B15: Operations | C15: Softwere subscription | D15: =SUMIFS('TB LTD 12.22'!G:G,'TB LTD 12.22'!I:I,$B15,'TB LTD 12.22'!J:J,$C15) -> 70434.95 | F15: =D15+E15 -> 70434.95 | J15: =SUMIFS('TB LTD 12.22'!F:F,'TB LTD 12.22'!I:I,$B15,'TB LTD 12.22'!J:J,$C15) -> 238667.82 | L15: =J15+K15 -> 238667.82
A16: Options | B16: Operations | C16: option expenses | D16: =SUMIFS('TB LTD 12.22'!G:G,'TB LTD 12.22'!I:I,$B16,'TB LTD 12.22'!J:J,$C16) -> 21106.66 | E16: ='AJE 2022'!G38 -> 0 | F16: =D16+E16 -> 21106.66 | J16: =SUMIFS('TB LTD 12.22'!F:F,'TB LTD 12.22'!I:I,$B16,'TB LTD 12.22'!J:J,$C16) -> 70070.51 | K16: ='AJE 2022'!J38 -> 0 | L16: =J16+K16 -> 70070.51
A17: Overheads | B17: Operations | C17: Rent and related | D17: =SUMIFS('TB LTD 12.22'!G:G,'TB LTD 12.22'!I:I,$B17,'TB LTD 12.22'!J:J,$C17) -> 114342.52 | F17: =D17+E17 -> 114342.52 | J17: =SUMIFS('TB LTD 12.22'!F:F,'TB LTD 12.22'!I:I,$B17,'TB LTD 12.22'!J:J,$C17) -> 392459.69 | L17: =J17+K17 -> 392459.69
A18: Depreciation | B18: Operations | C18: Depreciation | D18: =SUMIFS('TB LTD 12.22'!G:G,'TB LTD 12.22'!I:I,$B18,'TB LTD 12.22'!J:J,$C18) -> 16803.74 | F18: =D18+E18 -> 16803.74 | J18: =SUMIFS('TB LTD 12.22'!F:F,'TB LTD 12.22'!I:I,$B18,'TB LTD 12.22'!J:J,$C18) -> 54762.66 | L18: =J18+K18 -> 54762.66
A19: Overheads | B19: Operations | C19: Welfare | D19: =SUMIFS('TB LTD 12.22'!G:G,'TB LTD 12.22'!I:I,$B19,'TB LTD 12.22'!J:J,$C19) -> 1757.32 | F19: =D19+E19 -> 1757.32 | J19: =SUMIFS('TB LTD 12.22'!F:F,'TB LTD 12.22'!I:I,$B19,'TB LTD 12.22'!J:J,$C19) -> 6136 | L19: =J19+K19 -> 6136
A20: Overheads | B20: Operations | C20: Refreshments & Meals | D20: =SUMIFS('TB LTD 12.22'!G:G,'TB LTD 12.22'!I:I,$B20,'TB LTD 12.22'!J:J,$C20) -> 48346.67 | F20: =D20+E20 -> 48346.67 | J20: =SUMIFS('TB LTD 12.22'!F:F,'TB LTD 12.22'!I:I,$B20,'TB LTD 12.22'!J:J,$C20) -> 162032.54 | L20: =J20+K20 -> 162032.54
A21: Overheads | B21: Operations | C21: Benefits | D21: =SUMIFS('TB LTD 12.22'!G:G,'TB LTD 12.22'!I:I,$B21,'TB LTD 12.22'!J:J,$C21) -> 9171.54 | F21: =D21+E21 -> 9171.54 | J21: =SUMIFS('TB LTD 12.22'!F:F,'TB LTD 12.22'!I:I,$B21,'TB LTD 12.22'!J:J,$C21) -> 30310.62 | L21: =J21+K21 -> 30310.62
A22: Overheads | B22: Operations | C22: Company events | D22: =SUMIFS('TB LTD 12.22'!G:G,'TB LTD 12.22'!I:I,$B22,'TB LTD 12.22'!J:J,$C22) -> 52156.54 | F22: =D22+E22 -> 52156.54 | J22: =SUMIFS('TB LTD 12.22'!F:F,'TB LTD 12.22'!I:I,$B22,'TB LTD 12.22'!J:J,$C22) -> 174725.83 | L22: =J22+K22 -> 174725.83
A23: Overheads | B23: Operations | C23: Conferences and seminars | D23: =SUMIFS('TB LTD 12.22'!G:G,'TB LTD 12.22'!I:I,$B23,'TB LTD 12.22'!J:J,$C23) -> 1872.76 | F23: =D23+E23 -> 1872.76 | J23: =SUMIFS('TB LTD 12.22'!F:F,'TB LTD 12.22'!I:I,$B23,'TB LTD 12.22'!J:J,$C23) -> 6808.42 | L23: =J23+K23 -> 6808.42
A24: Overheads | B24: Operations | C24: Office exp | D24: =SUMIFS('TB LTD 12.22'!G:G,'TB LTD 12.22'!I:I,$B24,'TB LTD 12.22'!J:J,$C24) -> 0 | F24: =D24+E24 -> 0 | J24: =SUMIFS('TB LTD 12.22'!F:F,'TB LTD 12.22'!I:I,$B24,'TB LTD 12.22'!J:J,$C24) -> 0 | L24: =J24+K24 -> 0
A25: Overheads | B25: Operations | C25: Design | D25: =SUMIFS('TB LTD 12.22'!G:G,'TB LTD 12.22'!I:I,$B25,'TB LTD 12.22'!J:J,$C25) -> 2471.58 | F25: =D25+E25 -> 2471.58 | J25: =SUMIFS('TB LTD 12.22'!F:F,'TB LTD 12.22'!I:I,$B25,'TB LTD 12.22'!J:J,$C25) -> 8556.43 | L25: =J25+K25 -> 8556.43
A26: Overheads | B26: Operations | C26: Donation | D26: =SUMIFS('TB LTD 12.22'!G:G,'TB LTD 12.22'!I:I,$B26,'TB LTD 12.22'!J:J,$C26) -> 0 | F26: =D26+E26 -> 0 | J26: =SUMIFS('TB LTD 12.22'!F:F,'TB LTD 12.22'!I:I,$B26,'TB LTD 12.22'!J:J,$C26) -> 0 | L26: =J26+K26 -> 0
A27: Overheads | B27: Operations | C27: hosting | D27: =SUMIFS('TB LTD 12.22'!G:G,'TB LTD 12.22'!I:I,$B27,'TB LTD 12.22'!J:J,$C27) -> 1787545.2 | E27: =-'AJE 2022'!H67 -> 0 | F27: =D27+E27 -> 1787545.2 | J27: =SUMIFS('TB LTD 12.22'!F:F,'TB LTD 12.22'!I:I,$B27,'TB LTD 12.22'!J:J,$C27) -> 6216999.6 | K27: =-'AJE 2022'!J66 -> 0 | L27: =J27+K27 -> 6216999.6
A28: Overheads | B28: Operations | C28: insurance | D28: =SUMIFS('TB LTD 12.22'!G:G,'TB LTD 12.22'!I:I,$B28,'TB LTD 12.22'!J:J,$C28) -> 3082.15 | F28: =D28+E28 -> 3082.15 | J28: =SUMIFS('TB LTD 12.22'!F:F,'TB LTD 12.22'!I:I,$B28,'TB LTD 12.22'!J:J,$C28) -> 9998.95 | L28: =J28+K28 -> 9998.95
A29: Overheads | B29: Operations | C29: Fees and fines | D29: =SUMIFS('TB LTD 12.22'!G:G,'TB LTD 12.22'!I:I,$B29,'TB LTD 12.22'!J:J,$C29) -> 99.05 | F29: =D29+E29 -> 99.05 | J29: =SUMIFS('TB LTD 12.22'!F:F,'TB LTD 12.22'!I:I,$B29,'TB LTD 12.22'!J:J,$C29) -> 338.71 | L29: =J29+K29 -> 338.71
A30: Overheads | B30: Operations | C30: recruitment | D30: =SUMIFS('TB LTD 12.22'!G:G,'TB LTD 12.22'!I:I,$B30,'TB LTD 12.22'!J:J,$C30) -> 0 | F30: =D30+E30 -> 0 | J30: =SUMIFS('TB LTD 12.22'!F:F,'TB LTD 12.22'!I:I,$B30,'TB LTD 12.22'!J:J,$C30) -> 0 | L30: =J30+K30 -> 0
B31: Operations | C31: IC expenses | D31: =SUMIFS('TB LTD 12.22'!G:G,'TB LTD 12.22'!I:I,$B31,'TB LTD 12.22'!J:J,$C31) -> 19761872 | E31: ='AJE 2022'!G17 -> 0 | F31: =D31+E31 -> 19761872 | J31: =SUMIFS('TB LTD 12.22'!F:F,'TB LTD 12.22'!I:I,$B31,'TB LTD 12.22'!J:J,$C31) -> 66644518 | K31: ='AJE 2022'!J17 -> 0 | L31: =J31+K31 -> 66644518
C32: Gross loss (profit) | D32: =D10+D12 -> -3.111824e+08 | E32: =E10+E12 -> 0 | F32: =F10+F12 -> -3.111824e+08 | J32: =J10+J12 -> -1.0518449e+09 | K32: =K10+K12 -> 0 | L32: =L10+L12 -> -1.0518449e+09 | N32: =L32/1000 -> -1051844.9
C35: Research and development expenses, net | D35: =SUM(D36:D54) -> 20781725 | E35: =SUM(E36:E54) -> 0 | F35: =SUM(F36:F54) -> 20781725 | J35: =SUM(J36:J54) -> 70597716 | K35: =SUM(K36:K54) -> 0 | L35: =SUM(L36:L54) -> 70597716 | N35: =L35/1000 -> 70597.716
A36: Payroll | B36: Research and development expenses, net | C36: Salary | D36: =SUMIFS('TB LTD 12.22'!G:G,'TB LTD 12.22'!I:I,$B36,'TB LTD 12.22'!J:J,$C36) -> 13350033 | E36: ='AJE 2022'!G97-'AJE 2022'!G101 -> 0 | F36: =D36+E36 -> 13350033 | J36: =SUMIFS('TB LTD 12.22'!F:F,'TB LTD 12.22'!I:I,$B36,'TB LTD 12.22'!J:J,$C36) -> 45424826 | K36: ='AJE 2022'!K98-'AJE 2022'!J101 -> 0 | L36: =J36+K36 -> 45424826
A37: Overheads | B37: Research and development expenses, net | C37: Professional Services | D37: =SUMIFS('TB LTD 12.22'!G:G,'TB LTD 12.22'!I:I,$B37,'TB LTD 12.22'!J:J,$C37) -> 1119298.7 | F37: =D37+E37 -> 1119298.7 | J37: =SUMIFS('TB LTD 12.22'!F:F,'TB LTD 12.22'!I:I,$B37,'TB LTD 12.22'!J:J,$C37) -> 3777596 | L37: =J37+K37 -> 3777596
A38: Overheads | B38: Research and development expenses, net | C38: Softwere subscription | D38: =SUMIFS('TB LTD 12.22'!G:G,'TB LTD 12.22'!I:I,$B38,'TB LTD 12.22'!J:J,$C38) -> 1670933.7 | F38: =D38+E38 -> 1670933.7 | J38: =SUMIFS('TB LTD 12.22'!F:F,'TB LTD 12.22'!I:I,$B38,'TB LTD 12.22'!J:J,$C38) -> 5623468.9 | L38: =J38+K38 -> 5623468.9
A39: Options | B39: Research and development expenses, net | C39: option expenses | D39: =SUMIFS('TB LTD 12.22'!G:G,'TB LTD 12.22'!I:I,$B39,'TB LTD 12.22'!J:J,$C39) -> -39848.17 | E39: =-'AJE 2022'!H37 -> 0 | F39: =D39+E39 -> -39848.17 | J39: =SUMIFS('TB LTD 12.22'!F:F,'TB LTD 12.22'!I:I,$B39,'TB LTD 12.22'!J:J,$C39) -> -161997.48 | K39: =-'AJE 2022'!K37 -> 0 | L39: =J39+K39 -> -161997.48
A40: Overheads | B40: Research and development expenses, net | C40: Rent and related | D40: =SUMIFS('TB LTD 12.22'!G:G,'TB LTD 12.22'!I:I,$B40,'TB LTD 12.22'!J:J,$C40) -> 989386.59 | F40: =D40+E40 -> 989386.59 | J40: =SUMIFS('TB LTD 12.22'!F:F,'TB LTD 12.22'!I:I,$B40,'TB LTD 12.22'!J:J,$C40) -> 3423464.7 | L40: =J40+K40 -> 3423464.7
A41: Depreciation | B41: Research and development expenses, net | C41: Depreciation | D41: =SUMIFS('TB LTD 12.22'!G:G,'TB LTD 12.22'!I:I,$B41,'TB LTD 12.22'!J:J,$C41) -> 136688.74 | F41: =D41+E41 -> 136688.74 | J41: =SUMIFS('TB LTD 12.22'!F:F,'TB LTD 12.22'!I:I,$B41,'TB LTD 12.22'!J:J,$C41) -> 445711.95 | L41: =J41+K41 -> 445711.95
A42: Overheads | B42: Research and development expenses, net | C42: Welfare | D42: =SUMIFS('TB LTD 12.22'!G:G,'TB LTD 12.22'!I:I,$B42,'TB LTD 12.22'!J:J,$C42) -> 18024.67 | F42: =D42+E42 -> 18024.67 | J42: =SUMIFS('TB LTD 12.22'!F:F,'TB LTD 12.22'!I:I,$B42,'TB LTD 12.22'!J:J,$C42) -> 61677.9 | L42: =J42+K42 -> 61677.9
A43: Overheads | B43: Research and development expenses, net | C43: Refreshments & Meals | D43: =SUMIFS('TB LTD 12.22'!G:G,'TB LTD 12.22'!I:I,$B43,'TB LTD 12.22'!J:J,$C43) -> 392581.94 | F43: =D43+E43 -> 392581.94 | J43: =SUMIFS('TB LTD 12.22'!F:F,'TB LTD 12.22'!I:I,$B43,'TB LTD 12.22'!J:J,$C43) -> 1326297 | L43: =J43+K43 -> 1326297
A44: Overheads | B44: Research and development expenses, net | C44: Benefits | D44: =SUMIFS('TB LTD 12.22'!G:G,'TB LTD 12.22'!I:I,$B44,'TB LTD 12.22'!J:J,$C44) -> 76196.55 | F44: =D44+E44 -> 76196.55 | J44: =SUMIFS('TB LTD 12.22'!F:F,'TB LTD 12.22'!I:I,$B44,'TB LTD 12.22'!J:J,$C44) -> 255373.49 | L44: =J44+K44 -> 255373.49
...

Sheet TB LTD 12.22
A1: כותרת ראשית; | B1: כותרת משנה; | C1: סעיף; | D1: חשבון | E1: תאור החשבון | F1: יתרה בשקלים | G1: יתרה בדולרים | H1: סוג דוח | I1: מחלקה | J1: תת מחלקה
A2: Assets.1** | B2: Cash and Cash equivalent.10* | C2: Banks.100 | D2: 10000 | E2: Bank Leumi IL 568400 | F2: 4069321.5 | G2: 1156385.8 | H2: =VLOOKUP(D2,'COA LTD'!A:F,3,0) -> BS | I2: =VLOOKUP(D2,'COA LTD'!A:F,4,0) -> cash | J2: =VLOOKUP(D2,'COA LTD'!A:F,5,0) -> 0 | K2: =F2/G2 -> 3.519 | M2: 1
A3: Assets.1** | B3: Cash and Cash equivalent.10* | C3: Banks.100 | D3: 10001 | E3: Bank Leumi $ 568400 | F3: 5712873.2 | G3: 1623436.6 | H3: =VLOOKUP(D3,'COA LTD'!A:F,3,0) -> BS | I3: =VLOOKUP(D3,'COA LTD'!A:F,4,0) -> cash | J3: =VLOOKUP(D3,'COA LTD'!A:F,5,0) -> 0 | K3: =F3/G3 -> 3.519
A4: Assets.1** | B4: Cash and Cash equivalent.10* | C4: Banks.100 | D4: 10002 | E4: Bank Leumi GBP 568400 | F4: 3949.53 | G4: 1122.34 | H4: =VLOOKUP(D4,'COA LTD'!A:F,3,0) -> BS | I4: =VLOOKUP(D4,'COA LTD'!A:F,4,0) -> cash | J4: =VLOOKUP(D4,'COA LTD'!A:F,5,0) -> 0 | K4: =F4/G4 -> 3.5190138
A5: Assets.1** | B5: Cash and Cash equivalent.10* | C5: Banks.100 | D5: 10004 | E5: Bank SVB LTD **3838 | F5: 2900219.3 | G5: 824160.08 | H5: =VLOOKUP(D5,'COA LTD'!A:F,3,0) -> BS | I5: =VLOOKUP(D5,'COA LTD'!A:F,4,0) -> cash | J5: =VLOOKUP(D5,'COA LTD'!A:F,5,0) -> 0 | K5: =F5/G5 -> 3.519
