Workbook

Sheet Summary
B6: GetCtrl LTD
B7: Unaudited Managerial Financial Report for the Month ended - | J7: 45291
B8: Profit & Loss Summary
G11: YTD
G12: 45291 | H12: =G12 -> 45291
G13: NIS | H13: USD
B15: Revenues | G15: ='P&L'!E15 -> 0 | H15: ='P&L'!F15 -> 0
B16: Cost of revenues | G16: ='P&L'!E21 -> 0 | H16: ='P&L'!F21 -> 0
B17: Gross profit | G17: =G15-G16 -> 0 | H17: =H15-H16 -> 0
B19: Operating expenses
C20: R&D expenses | G20: ='P&L'!E35 -> 4940779.5 | H20: ='P&L'!F35 -> 1343306.1 | J20: =H20/$H$23 -> 0.53528066
C21: S&M expenses | G21: ='P&L'!E46 -> 2228851.2 | H21: ='P&L'!F46 -> 612473.45 | J21: =H21/$H$23 -> 0.24405845
C22: G&A expenses | G22: ='P&L'!E63 -> 2012572.7 | H22: ='P&L'!F63 -> 553756.44 | J22: =H22/$H$23 -> 0.22066089
B23: Total Operating Expenses | G23: =SUM(G20:G22) -> 9182203.4 | H23: =SUM(H20:H22) -> 2509536
B25: (*) EBITDA | G25: ='P&L'!E76 -> -9100727.4 | H25: ='P&L'!F76 -> -2484756
B27: (*) Earnings Before Interest, Tax, Depreciation and Amortization
B30: Cash Status as of | E30: =J7 -> 45291 | G30: =BS!E16 -> 2798941.6 | H30: =BS!G16 -> 771696.05
B33: Monthly average Burn Rate(K$)
G36: YTD
G37: =G12 -> 45291 | H37: =H12 -> 45291
G38: NIS | H38: USD
C39: EBITDA | G39: =G25/9 -> -1011191.9 | H39: =H25/9 -> -276084
C40: CAPEX | G40: 0 | H40: 0
C42: Burn rate for period | G42: =G39+G40 -> -1011191.9 | H42: =H39+H40 -> -276084
B46: Head Count
H49: Month ended
G50: 43190 | H50: 43465
C51: Cogs | G51: 0.05 | H51: 0.4
C52: R&D | G52: 8.3 | H52: 5.6
C53: M&S | G53: 1.05 | H53: 0.7
C54: G&A | G54: 1.6 | H54: 1.3
C55: Total head count | G55: =SUM(G52:G54) -> 10.95 | H55: =SUM(H52:H54) -> 7.6

Sheet BS
B6: =Summary!B6 -> GetCtrl LTD
B7: Unaudited Managerial Financial Report as of - | I7: =Summary!J7 -> 45291
B8: Profit & Loss Summary
E11: =I7 -> 45291 | G11: =I7 -> 45291 | K11: 45199 | M11: 45199 | O11: 45107 | Q11: 45107 | S11: 45016 | U11: 45016 | W11: 44926 | Y11: 44926 | AA11: 44561 | AC11: 44561
E12: NIS | G12: USD | K12: NIS | M12: USD | O12: NIS | Q12: USD | S12: NIS | U12: USD | W12: NIS | Y12: USD | AA12: NIS | AC12: USD
B13: ASSETS
C15: Current Assets
D16: Cash and cash equivalents | E16: =SUMIF(TB!$J$2:$J$121,D16,TB!$F$2:$F$121) -> 2798941.6 | G16: =SUMIF(TB!$J$2:$J$121,D16,TB!$I$2:$I121) -> 771696.05 | K16: 4215848.2 | M16: 1101246.7 | O16: 5701783.6 | Q16: 1541050 | S16: 10315135 | U16: 2852307.3 | W16: 7141709.9 | Y16: 2029479.2 | AA16: 3333096.3 | AC16: 1071735.1
D17: Accounts receivable | E17: =SUMIF(TB!$J$2:$J$121,D17,TB!$F$2:$F$121) -> 0 | G17: =SUMIF(TB!$J$2:$J$121,D17,TB!$I$2:$I122) -> 0 | K17: 0 | M17: 0 | O17: 0 | Q17: 0 | S17: 0 | U17: 0 | W17: 0 | Y17: 0 | AA17: 0 | AC17: 0
D18: Prepaid expenses | E18: =SUMIF(TB!$J$2:$J$121,D18,TB!$F$2:$F$121) -> 0 | G18: =SUMIF(TB!$J$2:$J$121,D18,TB!$I$2:$I123) -> 0 | K18: 0 | M18: 0 | O18: 0 | Q18: 0 | S18: 0 | U18: 0 | W18: 0 | Y18: 0 | AA18: 0 | AC18: 0
D19: Account Receivable-VAT+TAX | E19: =SUMIF(TB!$J$2:$J$121,D19,TB!$F$2:$F$121) -> 111434.76 | G19: =SUMIF(TB!$J$2:$J$121,D19,TB!$I$2:$I124) -> 30723.68 | K19: 113888.95 | M19: 29782.67 | O19: 104315.43 | Q19: 28193.35 | S19: 87603.37 | U19: 24233.31 | W19: 104029.47 | Y19: 29562.23 | AA19: 53258.19 | AC19: 17124.82
D20: Deposit | E20: =SUMIF(TB!$J$2:$J$121,D20,TB!$F$2:$F$121) -> 0 | G20: =SUMIF(TB!$J$2:$J$121,D20,TB!$I$2:$I125) -> 0
D21: Related party Debit | E21: =SUMIF(TB!$J$2:$J$121,D21,TB!$F$2:$F$121) -> 0 | G21: =SUMIF(TB!$J$2:$J$121,D21,TB!$I$2:$I125) -> 0 | K21: 0 | M21: 0 | O21: 0 | Q21: 0 | S21: 0 | U21: 0 | W21: 0 | Y21: 0 | AA21: 445173.54 | AC21: 143142.62
D22: Other current assets | E22: =SUMIF(TB!$J$2:$J$121,D22,TB!$F$2:$F$121) -> 100360.02 | G22: =SUMIF(TB!$J$2:$J$121,D22,TB!$I$2:$I125) -> 27670.25 | K22: 30673.79 | M22: 8021.39 | O22: 38921.41 | Q22: 10519.3 | S22: 27957.46 | U22: 7733.74 | W22: 27957.46 | Y22: 7944.72 | AA22: 1240.75 | AC22: 398.95
C23: Total current assets | E23: =SUM(E16:E22) -> 3010736.4 | G23: =SUM(G16:G22) -> 830089.98 | K23: 4360410.9 | M23: 1139050.8 | O23: 5845020.4 | Q23: 1579762.7 | S23: 10430696 | U23: 2884274.3 | W23: 7273696.9 | Y23: 2066986.2 | AA23: 3832768.7 | AC23: 1232401.5
C25: Non current assets
D26: Restricted cash | E26: =SUMIF(TB!$J$2:$J$121,D26,TB!$F$2:$F$121) -> 145977.02 | G26: =SUMIF(TB!$J$2:$J$121,D26,TB!$I$2:$I129) -> 40247.32 | K26: 144210 | M26: 38975.676 | O26: 144210 | Q26: 38975.676 | S26: 144210 | U26: 40980.392 | W26: 144210 | Y26: 40980.392 | AA26: 144216.47 | AC26: 46371.85
D27: Property and Equipment, Net | E27: =SUMIF(TB!$J$2:$J$121,D27,TB!$F$2:$F$121) -> 288898.85 | G27: =SUMIF(TB!$J$2:$J$121,D27,TB!$I$2:$I130) -> 87591.02 | K27: 363026.13 | M27: 110528.31 | O27: 336124.8 | Q27: 103326.65 | S27: 336124.8 | U27: 103326.65 | W27: 336124.8 | Y27: 103326.65 | AA27: 357746.04 | AC27: 110861.09
D28: Other Long term Assets | E28: =SUMIF(TB!$J$2:$J$121,D28,TB!$F$2:$F$121) -> 563565 | G28: =SUMIF(TB!$J$2:$J$121,D28,TB!$I$2:$I131) -> 160149.19 | K28: 563565 | M28: 160149.19 | O28: 563565 | Q28: 160149.19 | W28: 563565 | Y28: 160149.19
C29: Total Non current assets | E29: =SUM(E26:E28) -> 998440.87 | G29: =SUM(G26:G28) -> 287987.53 | K29: 1070801.1 | M29: 309653.18 | O29: 1043899.8 | Q29: 302451.52 | S29: 480334.8 | U29: 144307.04 | W29: 1043899.8 | Y29: 304456.23 | AA29: 501962.51 | AC29: 157232.94
B32: TOTAL ASSETS | E32: =E23+E29 -> 4009177.2 | G32: =G23+G29 -> 1118077.5 | K32: 5431212 | M32: 1448704 | O32: 6888920.2 | Q32: 1882214.2 | S32: 10911031 | U32: 3028581.4 | W32: 8317596.7 | Y32: 2371442.4 | AA32: 4334731.2 | AC32: 1389634.5
B34: LIABILITIES AND SHAREHOLDERS' EQUITY
C36: Current Liabilities
D37: Short term loans | E37: =-SUMIF(TB!$J$2:$J$121,D37,TB!$F$2:$F$121) -> 0 | G37: =-SUMIF(TB!$J$2:$J$121,D37,TB!$I$2:$I135) -> 0 | K37: 0 | M37: 0 | O37: 0 | Q37: 0 | S37: 0 | U37: 0 | W37: 0 | Y37: 0 | AA37: 0 | AC37: 0
D38: Accounts payable | E38: =-SUMIF(TB!$J$2:$J$121,D38,TB!$F$2:$F$121) -> 267533.76 | G38: =-SUMIF(TB!$J$2:$J$121,D38,TB!$I$2:$I135) -> 73761.726 | K38: 128163.42 | M38: 33515.522 | O38: 119881.81 | Q38: 33696.817 | S38: 179452.29 | U38: 49641.002 | W38: 220909.19 | Y38: 62776.033 | AA38: 47369.14 | AC38: 15231.23
D39: Accrued expenses | E39: =-SUMIF(TB!$J$2:$J$121,D39,TB!$F$2:$F$121) -> 32627.41 | G39: =-SUMIF(TB!$J$2:$J$121,D39,TB!$I$2:$I135) -> 8995.7018 | K39: 32000 | M39: 8648.6486 | O39: 40800 | Q39: 11027.027 | S39: 75555 | U39: 20610.909 | W39: 75555 | Y39: 20610.909 | AA39: 66937.5 | AC39: 21523.31
D40: Employee payables & institutions | E40: =-SUMIF(TB!$J$2:$J$121,D40,TB!$F$2:$F$121) -> 320113.73 | G40: =-SUMIF(TB!$J$2:$J$121,D40,TB!$I$2:$I135) -> 93603.46 | K40: 460536.81 | M40: 128578.28 | O40: 342373.27 | Q40: 98950.6 | S40: 441473.87 | U40: 127287.27 | W40: 478198.82 | Y40: 139567.34 | AA40: 516508.38 | AC40: 166079.88
D41: Related party | E41: =-SUMIF(TB!$J$2:$J$121,D41,TB!$F$2:$F$121) -> 5507655.5 | G41: =-SUMIF(TB!$J$2:$J$121,D41,TB!$I$2:$I135) -> 1534943.1 | K41: 2767370.9 | M41: 810205.3 | O41: 47328011 | Q41: 13988401 | S41: 28930967 | U41: 8188365.7 | W41: 814859.54 | Y41: 253055.79 | AA41: 7884283.4 | AC41: 2535139.3
D42: Other short term liabilities | E42: =-SUMIF(TB!$J$2:$J$121,D42,TB!$F$2:$F$121) -> 0 | G42: =-SUMIF(TB!$J$2:$J$121,D42,TB!$I$2:$I135) -> 0 | K42: 0 | M42: 0 | O42: 0 | Q42: 0 | S42: 0 | U42: 0 | W42: 369893 | Y42: 105113.1 | AA42: 0 | AC42: 0
C43: Total Current Liabilities | E43: =SUM(E37:E42) -> 6127930.4 | G43: =SUM(G37:G42) -> 1711304 | K43: 3388071.1 | M43: 980947.75 | O43: 47831066 | Q43: 14132076 | S43: 29627448 | U43: 8385904.9 | W43: 1959415.6 | Y43: 581123.17 | AA43: 8515098.4 | AC43: 2737973.8
C45: Long Term Liabilities
D46: Severance, Net | E46: =-SUMIF(TB!$J$2:$J$121,D46,TB!$F$2:$F$121) -> 0 | G46: =-SUMIF(TB!$J$2:$J$121,D46,TB!$I$2:$I135) -> 0 | K46: 0 | M46: 0 | O46: 0 | Q46: 0 | S46: 0 | U46: 0 | W46: 0 | Y46: 0 | AA46: 0 | AC46: 0
D47: Other Long term liabilities | E47: =-SUMIF(TB!$J$2:$J$121,D47,TB!$F$2:$F$121) -> 569697 | G47: =-SUMIF(TB!$J$2:$J$121,D47,TB!$I$2:$I136) -> 161891.73 | K47: 569697 | M47: 161891.73 | O47: 569697 | Q47: 161891.73 | S47: 0 | U47: 0 | W47: 199804 | Y47: 56778.63 | AA47: 0 | AC47: 0
C48: Total Long Term Liabilities | E48: =SUM(E46:E47) -> 569697 | G48: =SUM(G46:G47) -> 161891.73 | K48: 569697 | M48: 161891.73 | O48: 569697 | Q48: 161891.73 | S48: 0 | U48: 0 | W48: 199804 | Y48: 56778.63 | AA48: 0 | AC48: 0
C50: Shareholders' Equity
D51: Share capital | E51: =-SUMIF(TB!$J$2:$J$121,D51,TB!$F$2:$F$121) -> 0 | G51: =-SUMIF(TB!$J$2:$J$121,D51,TB!$I$2:$I140) -> 0 | K51: 0 | M51: 0 | O51: 0 | Q51: 0 | S51: 0 | U51: 0 | W51: 0 | Y51: 0 | AA51: 0 | AC51: 0
D52: Additional paid-in capital | E52: =-SUMIF(TB!$J$2:$J$121,D52,TB!$F$2:$F$121) -> 0 | G52: =-SUMIF(TB!$J$2:$J$121,D52,TB!$I$2:$I141) -> 0 | K52: 0 | M52: 0 | O52: 0 | Q52: 0 | S52: 0 | U52: 0 | W52: 0 | Y52: 0 | AA52: 0 | AC52: 0
D53: Capital note | E53: =-SUMIF(TB!$J$2:$J$121,D53,TB!$F$2:$F$121) -> 22281920 | G53: =-SUMIF(TB!$J$2:$J$121,D53,TB!$I$2:$I142) -> 6600000 | K53: 22281920 | M53: 6600000 | O53: -22281920 | Q53: -6600000 | S53: 0 | U53: 0 | W53: 22281920 | Y53: 6600000
D54: Equity expenses | E54: =-SUMIF(TB!$J$2:$J$121,D54,TB!$F$2:$F$121) -> 0 | G54: =-SUMIF(TB!$J$2:$J$121,D54,TB!$I$2:$I142) -> 0 | K54: 0 | M54: 0 | O54: 0 | Q54: 0 | S54: 0 | U54: 0 | W54: 0 | Y54: 0 | AA54: 0 | AC54: 0
D55: Capital reserve | E55: =-SUMIF(TB!$J$2:$J$121,D55,TB!$F$2:$F$121) -> 0 | G55: =-SUMIF(TB!$J$2:$J$121,D55,TB!$I$2:$I143) -> 0 | K55: 0 | M55: 0 | O55: 0 | Q55: 0 | W55: 0 | Y55: 0 | AA55: 0 | AC55: 0
...

Sheet CF
B6: =Summary!B6 -> GetCtrl LTD
B7: Unaudited Consilidated Managerial Financial Report for the Month ended - | K7: =Summary!J7 -> 45291
B8: Cash Flow (K$)
E11: =K7 -> 45291 | G11: YTD
C14: Cash Flows from Operating Activities
D15: Net Income (Loss)
C16: Adjustments to reconcile loss to net cash flow-
D17: Expenses not involving cash flow:
D18: Decrease (Increase) in Receivables
D19: Increase (Decrease) in Liabilities
D20: Increase (Decrease) in deferred revenue
D21: Depreciation
C22: Total Adjustments | E22: =SUM(E18:E21) -> 0
C23: Net cash used in operating activities | E23: =E15+E22 -> 0 | G23: =G15+G22 -> 0
D25: Purchase of fixed assets
D26: Increase in restricted cash
C27: Net cash used in investment activities | E27: =E25 -> 0 | G27: =SUM(G25:G26) -> 0
C29: Cash Flows from Financing Activities
D30: Receipt of loans
D31: Issuance of share capital
C32: Net cash provided by financing activities | E32: =SUM(E30:E31) -> 0 | G32: =SUM(G30:G31) -> 0
C34: Increase (decrease) in cash | E34: =E23+E27+E32 -> 0 | G34: =G23+G27+G32 -> 0
C36: Cash at beginning of period
C38: Cash at end of the period | G38: =G34+G36 -> 0
C42: Notes
C44: (1) | D44: The above mentioned cash flow is based on unaudited ledger
C46: (2)
C48: (3)

Sheet P&L
B6: =Summary!B6 -> GetCtrl LTD
B7: Unaudited Managerial Financial Report for the Month ended - | H7: =Summary!J7 -> 45291
B8: Profit & Loss Summary
E11: YTD | N11: YTD | Q11: YTD | T11: YTD | W11: YTD | Z11: YTD
E12: =H7 -> 45291 | F12: =E12 -> 45291 | G12: Note | N12: 45199 | O12: 45199 | Q12: 45107 | R12: 45107 | T12: 45016 | U12: 45016 | W12: 44926 | X12: 44926 | Z12: 44561 | AA12: 44561
E13: NIS | F13: USD | N13: NIS | O13: USD | Q13: NIS | R13: USD | T13: NIS | U13: USD | W13: NIS | X13: USD | Z13: NIS | AA13: USD
B15: Revenues | E15: =-SUMIF(TB!$J$2:$J$121,B15,TB!$F$2:$F$121) -> 0 | F15: =-SUMIF(TB!$J$2:$J$121,B15,TB!$I$2:$I$121) -> 0 | N15: 0 | O15: 0 | Q15: 0 | R15: 0 | T15: 0 | U15: 0 | W15: 0 | X15: 0 | Z15: 0 | AA15: 0
B17: Cost of revenues
B18: Cost of sales | E18: =SUMIF(TB!$J$2:$J$121,B18,TB!$F$2:$F$121) -> 0 | F18: =SUMIF(TB!$J$2:$J$121,B18,TB!$I$2:$I$121) -> 0 | N18: 0 | O18: 0 | Q18: 0 | R18: 0 | T18: 0 | U18: 0 | W18: 0 | X18: 0 | Z18: 0 | AA18: 0
B19: Cogs Payroll and social benefits | E19: =SUMIF(TB!$J$2:$J$121,B19,TB!$F$2:$F$121) -> 0 | F19: =SUMIF(TB!$J$2:$J$121,B19,TB!$I$2:$I$121) -> 0 | N19: 0 | O19: 0 | Q19: 0 | R19: 0 | T19: 0 | U19: 0 | W19: 0 | X19: 0 | Z19: 0 | AA19: 0
B20: Allocation cogs | E20: =SUMIF(TB!$J$2:$J$121,B20,TB!$F$2:$F$121) -> 0 | F20: =SUMIF(TB!$J$2:$J$121,B20,TB!$I$2:$I$121) -> 0 | N20: 0 | O20: 0 | Q20: 0 | R20: 0 | T20: 0 | U20: 0 | W20: 0 | X20: 0 | Z20: 0 | AA20: 0
B21: Total Cost of revenues | E21: =SUM(E18:E20) -> 0 | F21: =SUM(F18:F20) -> 0 | N21: 0 | O21: 0 | Q21: 0 | R21: 0 | T21: 0 | U21: 0 | W21: 0 | X21: 0 | Z21: 0 | AA21: 0
B23: Gross profit | E23: =E15-E21 -> 0 | F23: =F15-F21 -> 0 | N23: 0 | O23: 0 | Q23: 0 | R23: 0 | T23: 0 | U23: 0 | W23: 0 | X23: 0 | Z23: 0 | AA23: 0
B25: Operating expenses
B27: Research and development-
C28: Salaries and social benefits - R&D | E28: =SUMIF(TB!$J$2:$J$121,C28,TB!$F$2:$F$121) -> 3412007.6 | F28: =SUMIF(TB!$J$2:$J$121,C28,TB!$I$2:$I$121) -> 926825.31 | G28: (1) | I28: =E28-N28 -> 391919.24 | J28: =N28-Q28 -> 827827.16 | K28: =Q28-T28 -> 901590.74 | L28: =T28 -> 1290670.5 | N28: 3020088.4 | O28: 826546.87 | Q28: 2192261.2 | R28: 607213 | T28: 1290670.5 | U28: 359538.79 | W28: 4223891.8 | X28: 1248097.7 | Z28: 1852803.5 | AA28: 582341.96
C29: Subcontractors | E29: =SUMIF(TB!$J$2:$J$121,C29,TB!$F$2:$F$121) -> -35550 | F29: =SUMIF(TB!$J$2:$J$121,C29,TB!$I$2:$I$121) -> -10104.27 | I29: =E29-N29 -> 0 | J29: =N29-Q29 -> 0 | K29: =Q29-T29 -> -38000 | L29: =T29 -> 2450 | N29: -35550 | O29: -10104.27 | Q29: -35550 | R29: -10104.27 | T29: 2450 | U29: 694.25 | W29: 152000 | X29: 44337.642 | Z29: 121000 | AA29: 37501.49
C30: IIA Expenses | E30: =SUMIF(TB!$J$2:$J$121,C30,TB!$F$2:$F$121) -> 0 | F30: =SUMIF(TB!$J$2:$J$121,C30,TB!$I$2:$I$121) -> 0 | I30: =E30-N30 -> 0 | J30: =N30-Q30 -> 0 | K30: =Q30-T30 -> 0 | L30: =T30 -> 0 | N30: 0 | O30: 0 | Q30: 0 | R30: 0 | T30: 0 | U30: 0 | W30: 0 | X30: 0 | Z30: 0 | AA30: 0
C31: Recrutment | E31: =SUMIF(TB!$J$2:$J$121,C31,TB!$F$2:$F$121) -> 0 | F31: =SUMIF(TB!$J$2:$J$121,C31,TB!$I$2:$I$121) -> 0 | I31: =E31-N31 -> 0 | J31: =N31-Q31 -> 0 | K31: =Q31-T31 -> 0 | L31: =T31 -> 0 | N31: 0 | O31: 0 | Q31: 0 | R31: 0 | T31: 0 | U31: 0 | W31: 67097.05 | X31: 20502.54 | Z31: 32000 | AA31: 9959.54
C32: Travel R&D | E32: =SUMIF(TB!$J$2:$J$121,C32,TB!$F$2:$F$121) -> 0 | F32: =SUMIF(TB!$J$2:$J$121,C32,TB!$I$2:$I$121) -> 0 | I32: =E32-N32 -> 0 | J32: =N32-Q32 -> 0 | K32: =Q32-T32 -> 0 | L32: =T32 -> 0 | N32: 0 | O32: 0 | Q32: 0 | R32: 0 | T32: 0 | U32: 0 | W32: 0 | X32: 0 | Z32: 0 | AA32: 0
C33: G&A overhead | E33: =SUMIF(TB!$J$2:$J$121,C33,TB!$F$2:$F$121) -> 640307.23 | F33: =SUMIF(TB!$J$2:$J$121,C33,TB!$I$2:$I$121) -> 176539.08 | I33: =E33-N33 -> 172514.14 | J33: =N33-Q33 -> 155085.98 | K33: =Q33-T33 -> 154689.05 | L33: =T33 -> 158018.06 | N33: 467793.09 | O33: 126430.56 | Q33: 312707.1 | R33: 84515.434 | T33: 158018.06 | U33: 44904.25 | W33: 743604.89 | X33: 211311.42
C34: R&D expenses | E34: =SUMIF(TB!$J$2:$J$121,C34,TB!$F$2:$F$121) -> 924014.67 | F34: =SUMIF(TB!$J$2:$J$121,C34,TB!$I$2:$I$121) -> 250045.97 | I34: =E34-N34 -> 149498.25 | J34: =N34-Q34 -> 395690.46 | K34: =Q34-T34 -> 190928.5 | L34: =T34 -> 187897.46 | N34: 774516.42 | O34: 209029.29 | Q34: 378825.96 | R34: 104747.08 | T34: 187897.46 | U34: 52530.292 | W34: 1557440.5 | X34: 473461.24 | Z34: 488245.56 | AA34: 153274.96
B35: Total R&D | E35: =SUM(E28:E34) -> 4940779.5 | F35: =SUM(F28:F34) -> 1343306.1 | I35: =E35-N35 -> 713931.63 | J35: =N35-Q35 -> 1378603.6 | K35: =Q35-T35 -> 1209208.3 | L35: =T35 -> 1639036 | N35: 4226847.9 | O35: 1151902.5 | Q35: 2848244.3 | R35: 786371.24 | T35: 1639036 | U35: 457667.59 | W35: 6744034.2 | X35: 1997710.6 | Z35: 2494049 | AA35: 783077.95
I36: =E36-N36 -> 0 | J36: =N36-Q36 -> 0 | K36: =Q36-T36 -> 0 | L36: =T36 -> 0
B37: Sales and marketing- | I37: =E37-N37 -> 0 | J37: =N37-Q37 -> 0 | K37: =Q37-T37 -> 0 | L37: =T37 -> 0
C38: Salaries and social benefits - S&M | E38: =SUMIF(TB!$J$2:$J$121,C38,TB!$F$2:$F$121) -> 0 | F38: =SUMIF(TB!$J$2:$J$121,C38,TB!$I$2:$I$121) -> 0 | I38: =E38-N38 -> 0 | J38: =N38-Q38 -> 0 | K38: =Q38-T38 -> 0 | L38: =T38 -> 0 | N38: 0 | O38: 0 | Q38: 0 | R38: 0 | T38: 0 | U38: 0 | W38: 0 | X38: 0 | Z38: 0 | AA38: 0
C39: Travel | E39: =SUMIF(TB!$J$2:$J$121,C39,TB!$F$2:$F$121) -> 52909.86 | F39: =SUMIF(TB!$J$2:$J$121,C39,TB!$I$2:$I$121) -> 14359.73 | G39: (2) | I39: =E39-N39 -> 3147.04 | J39: =N39-Q39 -> 40036.86 | K39: =Q39-T39 -> 1704.61 | L39: =T39 -> 8021.35 | N39: 49762.82 | O39: 13367.507 | Q39: 9725.96 | R39: 2747.1174 | T39: 8021.35 | U39: 2275.6199 | W39: 132562.63 | X39: 39325.25 | Z39: 55859.74 | AA39: 17708.34
C40: PR | E40: =SUMIF(TB!$J$2:$J$121,C40,TB!$F$2:$F$121) -> 10000 | F40: =SUMIF(TB!$J$2:$J$121,C40,TB!$I$2:$I$121) -> 2721.08 | I40: =E40-N40 -> 0 | J40: =N40-Q40 -> 0 | K40: =Q40-T40 -> 10000 | L40: =T40 -> 0 | N40: 10000 | O40: 2721.08 | Q40: 10000 | R40: 2721.08 | T40: 0 | U40: 0 | W40: 0 | X40: 0 | Z40: 0 | AA40: 0
C41: Other S&M | E41: =SUMIF(TB!$J$2:$J$121,C41,TB!$F$2:$F$121) -> 455176.75 | F41: =SUMIF(TB!$J$2:$J$121,C41,TB!$I$2:$I$121) -> 123717.83 | I41: =E41-N41 -> 231053.62 | J41: =N41-Q41 -> 66739.55 | K41: =Q41-T41 -> 93045.63 | L41: =T41 -> 64337.95 | N41: 224123.13 | O41: 58746.774 | Q41: 157383.58 | R41: 43563.375 | T41: 64337.95 | U41: 17837.889 | W41: 67732.15 | X41: 19971.69 | Z41: 3031.68 | AA41: 950.68981
C42: Marketing | E42: =SUMIF(TB!$J$2:$J$121,C42,TB!$F$2:$F$121) -> 0 | F42: =SUMIF(TB!$J$2:$J$121,C42,TB!$I$2:$I$121) -> 0 | I42: =E42-N42 -> 0 | J42: =N42-Q42 -> 0 | K42: =Q42-T42 -> 0 | L42: =T42 -> 0 | N42: 0 | O42: 0 | Q42: 0 | R42: 0 | T42: 0 | U42: 0 | W42: 0 | X42: 0 | Z42: 0 | AA42: 0
C43: Recrutment S&M | E43: =SUMIF(TB!$J$2:$J$121,C43,TB!$F$2:$F$121) -> 0 | F43: =SUMIF(TB!$J$2:$J$121,C43,TB!$I$2:$I$121) -> 0 | I43: =E43-N43 -> 0 | J43: =N43-Q43 -> 0 | K43: =Q43-T43 -> 0 | L43: =T43 -> 0 | N43: 0 | O43: 0 | Q43: 0 | R43: 0 | T43: 0 | U43: 0 | W43: 0 | X43: 0 | Z43: 0 | AA43: 0
C44: Consultants S&M | E44: =SUMIF(TB!$J$2:$J$121,C44,TB!$F$2:$F$121) -> 0 | F44: =SUMIF(TB!$J$2:$J$121,C44,TB!$I$2:$I$121) -> 0 | I44: =E44-N44 -> 0 | J44: =N44-Q44 -> 0 | K44: =Q44-T44 -> 0 | L44: =T44 -> 0 | N44: 0 | O44: 0 | Q44: 0 | R44: 0 | T44: 0 | U44: 0 | W44: 0 | X44: 0 | Z44: 0 | AA44: 0
C45: COST + UK S&M | E45: =SUMIF(TB!$J$2:$J$121,C45,TB!$F$2:$F$121) -> 1710764.6 | F45: =SUMIF(TB!$J$2:$J$121,C45,TB!$I$2:$I$121) -> 471674.81 | I45: =E45-N45 -> 1710764.6 | J45: =N45-Q45 -> 0 | K45: =Q45-T45 -> 0 | L45: =T45 -> 0 | N45: 0 | O45: 0 | Q45: 0 | R45: 0 | T45: 0 | U45: 0 | W45: 1810051.1 | X45: 510162.46 | Z45: 0 | AA45: 0
B46: Total S&M | E46: =SUM(E38:E45) -> 2228851.2 | F46: =SUM(F38:F45) -> 612473.45 | I46: =E46-N46 -> 1944965.2 | J46: =N46-Q46 -> 106776.41 | K46: =Q46-T46 -> 104750.24 | L46: =T46 -> 72359.3 | N46: 283885.95 | O46: 74835.361 | Q46: 177109.54 | R46: 49031.572 | T46: 72359.3 | U46: 20113.509 | W46: 2010345.9 | X46: 569459.4 | Z46: 58891.42 | AA46: 18659.03
I47: =E47-N47 -> 0 | J47: =N47-Q47 -> 0 | K47: =Q47-T47 -> 0 | L47: =T47 -> 0
B48: General and administrative- | I48: =E48-N48 -> 0 | J48: =N48-Q48 -> 0 | K48: =Q48-T48 -> 0 | L48: =T48 -> 0
C49: Salaries and social benefits - G&A | E49: =SUMIF(TB!$J$2:$J$121,C49,TB!$F$2:$F$121) -> 564006 | F49: =SUMIF(TB!$J$2:$J$121,C49,TB!$I$2:$I$121) -> 153711.53 | I49: =E49-N49 -> 87564.77 | J49: =N49-Q49 -> 142413.17 | K49: =Q49-T49 -> 167013.31 | L49: =T49 -> 167014.75 | N49: 476441.23 | O49: 128767.9 | Q49: 334028.06 | R49: 90277.854 | T49: 167014.75 | U49: 47460.855 | W49: 1448994.8 | X49: 411763.22 | Z49: 84405.93 | AA49: 27148.9
C50: Accounting & Financial Services | E50: =SUMIF(TB!$J$2:$J$121,C50,TB!$F$2:$F$121) -> 147200 | F50: =SUMIF(TB!$J$2:$J$121,C50,TB!$I$2:$I$121) -> 40385.611 | I50: =E50-N50 -> 28800 | J50: =N50-Q50 -> 19700 | K50: =Q50-T50 -> 54200 | L50: =T50 -> 44500 | N50: 118400 | O50: 33157.109 | Q50: 98700 | R50: 27901.327 | T50: 44500 | U50: 12513.12 | W50: 120800 | X50: 34546.75 | Z50: 46461.18 | AA50: 14665.111
C51: Legal & Professional Services | E51: =SUMIF(TB!$J$2:$J$121,C51,TB!$F$2:$F$121) -> 101137.93 | F51: =SUMIF(TB!$J$2:$J$121,C51,TB!$I$2:$I$121) -> 27086.2 | I51: =E51-N51 -> 19315.14 | J51: =N51-Q51 -> 27567.84 | K51: =Q51-T51 -> 38699.33 | L51: =T51 -> 15555.62 | N51: 81822.79 | O51: 22134.87 | Q51: 54254.95 | R51: 14896.11 | T51: 15555.62 | U51: 4561.77 | W51: 367189.51 | X51: 107912.78 | Z51: 49337.62 | AA51: 15337.12
C52: Insurance | E52: =SUMIF(TB!$J$2:$J$121,C52,TB!$F$2:$F$121) -> 5349.75 | F52: =SUMIF(TB!$J$2:$J$121,C52,TB!$I$2:$I$121) -> 1474.03 | I52: =E52-N52 -> 5349.75 | J52: =N52-Q52 -> 0 | K52: =Q52-T52 -> 0 | L52: =T52 -> 0 | N52: 0 | O52: 0 | Q52: 0 | R52: 0 | T52: 0 | U52: 0 | W52: 0 | X52: 0 | Z52: 1754.25 | AA52: 540
...

Sheet TB
A1: סעיף; | B1: חשבון | C1: תאור החשבון | D1: יתרה בשקלים | E1: AJE | F1: Total NIS | G1: יתרה בדולרים | H1: AJE | I1: Total USD
A2: ="100.מזומנים ושווי מזומנים" -> 100.מזומנים ושווי מזומנים | B2: 1000 | C2: ="בנק לאומי שח 864/01880046" -> בנק לאומי שח 864/01880046 | D2: =VLOOKUP(B2,[1]DataSheet!$E$2:$H$112,3,0) -> 130855.81 | E2: =SUMIF(AJE!$B$8:$B$36,B2,AJE!$D$8:$D$36)-SUMIF(AJE!$G$8:$G$36,B2,AJE!$I$8:$I$36) -> 0 | F2: =D2+E2 -> 130855.81 | G2: =VLOOKUP(B2,[1]DataSheet!$E$2:$H$112,4,0) -> 36078.25 | H2: =SUMIF(AJE!$B$8:$B$36,B2,AJE!$E$8:$E$36)-SUMIF(AJE!$G$8:$G$36,B2,AJE!$J$8:$J$36) -> 0 | I2: =G2+H2 -> 36078.25 | J2: Cash and cash equivalents | K2: =D2/G2 -> 3.6269999 | L2: מתאים לבנק
A3: ="100.מזומנים ושווי מזומנים" -> 100.מזומנים ושווי מזומנים | B3: 1001 | C3: ="בנק לאומי 864/01880046 $$" -> בנק לאומי 864/01880046 $$ | D3: =VLOOKUP(B3,[1]DataSheet!$E$2:$H$112,3,0) -> 1019378.2 | E3: =SUMIF(AJE!$B$8:$B$36,B3,AJE!$D$8:$D$36)-SUMIF(AJE!$G$8:$G$36,B3,AJE!$I$8:$I$36) -> 0 | F3: =D3+E3 -> 1019378.2 | G3: =VLOOKUP(B3,[1]DataSheet!$E$2:$H$112,4,0) -> 281052.72 | H3: =SUMIF(AJE!$B$8:$B$36,B3,AJE!$E$8:$E$36)-SUMIF(AJE!$G$8:$G$36,B3,AJE!$J$8:$J$36) -> 0 | I3: =G3+H3 -> 281052.72 | J3: Cash and cash equivalents | K3: =F3/I3 -> 3.627 | L3: מתאים לבנק
A4: ="100.מזומנים ושווי מזומנים" -> 100.מזומנים ושווי מזומנים | B4: 1003 | C4: ="כ""א ויזה 9519 ש""ח" -> כ"א ויזה 9519 ש"ח | D4: =VLOOKUP(B4,[1]DataSheet!$E$2:$H$112,3,0) -> -15738.04 | E4: =SUMIF(AJE!$B$8:$B$36,B4,AJE!$D$8:$D$36)-SUMIF(AJE!$G$8:$G$36,B4,AJE!$I$8:$I$36) -> 0 | F4: =D4+E4 -> -15738.04 | G4: =VLOOKUP(B4,[1]DataSheet!$E$2:$H$112,4,0) -> -4339.13 | H4: =SUMIF(AJE!$B$8:$B$36,B4,AJE!$E$8:$E$36)-SUMIF(AJE!$G$8:$G$36,B4,AJE!$J$8:$J$36) -> 0 | I4: =G4+H4 -> -4339.13 | J4: Accounts payable | K4: =D4/G4 -> 3.6270036
A5: ="100.מזומנים ושווי מזומנים" -> 100.מזומנים ושווי מזומנים | B5: 1004 | C5: ="כ""א ויזה 9311 ש""ח" -> כ"א ויזה 9311 ש"ח | D5: =VLOOKUP(B5,[1]DataSheet!$E$2:$H$112,3,0) -> -2121.21 | E5: =SUMIF(AJE!$B$8:$B$36,B5,AJE!$D$8:$D$36)-SUMIF(AJE!$G$8:$G$36,B5,AJE!$I$8:$I$36) -> 0 | F5: =D5+E5 -> -2121.21 | G5: =VLOOKUP(B5,[1]DataSheet!$E$2:$H$112,4,0) -> -584.84 | H5: =SUMIF(AJE!$B$8:$B$36,B5,AJE!$E$8:$E$36)-SUMIF(AJE!$G$8:$G$36,B5,AJE!$J$8:$J$36) -> 0 | I5: =G5+H5 -> -584.84 | J5: Accounts payable | K5: =D5/G5 -> 3.626992
A6: ="100.מזומנים ושווי מזומנים" -> 100.מזומנים ושווי מזומנים | B6: 1005 | C6: ="כ""א ויזה 7413 ש""ח" -> כ"א ויזה 7413 ש"ח | D6: =VLOOKUP(B6,[1]DataSheet!$E$2:$H$112,3,0) -> -664.38 | E6: =SUMIF(AJE!$B$8:$B$36,B6,AJE!$D$8:$D$36)-SUMIF(AJE!$G$8:$G$36,B6,AJE!$I$8:$I$36) -> 0 | F6: =D6+E6 -> -664.38 | G6: =VLOOKUP(B6,[1]DataSheet!$E$2:$H$112,4,0) -> -183.18 | H6: =SUMIF(AJE!$B$8:$B$36,B6,AJE!$E$8:$E$36)-SUMIF(AJE!$G$8:$G$36,B6,AJE!$J$8:$J$36) -> 0 | I6: =G6+H6 -> -183.18 | J6: Accounts payable | K6: =D6/G6 -> 3.6269243
A7: ="100.מזומנים ושווי מזומנים" -> 100.מזומנים ושווי מזומנים | B7: 1006 | C7: ="בנק לאומי GBP 864/01880046" -> בנק לאומי GBP 864/01880046 | D7: =VLOOKUP(B7,[1]DataSheet!$E$2:$H$112,3,0) -> 0.42 | E7: =SUMIF(AJE!$B$8:$B$36,B7,AJE!$D$8:$D$36)-SUMIF(AJE!$G$8:$G$36,B7,AJE!$I$8:$I$36) -> 0 | F7: =D7+E7 -> 0.42 | G7: =VLOOKUP(B7,[1]DataSheet!$E$2:$H$112,4,0) -> 0.11 | H7: =SUMIF(AJE!$B$8:$B$36,B7,AJE!$E$8:$E$36)-SUMIF(AJE!$G$8:$G$36,B7,AJE!$J$8:$J$36) -> 0 | I7: =G7+H7 -> 0.11 | J7: Cash and cash equivalents | K7: =D7/G7 -> 3.8181818 | L7: מתאים לבנק
A8: ="100.מזומנים ושווי מזומנים" -> 100.מזומנים ושווי מזומנים | B8: 1007 | C8: ="כ""א ויזה 7413 $" -> כ"א ויזה 7413 $ | D8: =VLOOKUP(B8,[1]DataSheet!$E$2:$H$112,3,0) -> -15236.05 | E8: =SUMIF(AJE!$B$8:$B$36,B8,AJE!$D$8:$D$36)-SUMIF(AJE!$G$8:$G$36,B8,AJE!$I$8:$I$36) -> 0 | F8: =D8+E8 -> -15236.05 | G8: =VLOOKUP(B8,[1]DataSheet!$E$2:$H$112,4,0) -> -4200.73 | H8: =SUMIF(AJE!$B$8:$B$36,B8,AJE!$E$8:$E$36)-SUMIF(AJE!$G$8:$G$36,B8,AJE!$J$8:$J$36) -> 0 | I8: =G8+H8 -> -4200.73 | J8: Accounts payable | K8: =D8/G8 -> 3.6270005
B9: 1008 | C9: כ"א ויזה 9519 $ | D9: =VLOOKUP(B9,[1]DataSheet!$E$2:$H$112,3,0) -> -18669.98 | E9: =SUMIF(AJE!$B$8:$B$36,B9,AJE!$D$8:$D$36)-SUMIF(AJE!$G$8:$G$36,B9,AJE!$I$8:$I$36) -> 0 | F9: =D9+E9 -> -18669.98 | G9: =VLOOKUP(B9,[1]DataSheet!$E$2:$H$112,4,0) -> -5147.5 | H9: =SUMIF(AJE!$B$8:$B$36,B9,AJE!$E$8:$E$36)-SUMIF(AJE!$G$8:$G$36,B9,AJE!$J$8:$J$36) -> 0 | I9: =G9+H9 -> -5147.5 | J9: Accounts payable | K9: =D9/G9 -> 3.6269995
A10: ="100.מזומנים ושווי מזומנים" -> 100.מזומנים ושווי מזומנים | B10: 1011 | C10: ="פקדון בנק לאומי פק""מ" -> פקדון בנק לאומי פק"מ | D10: =VLOOKUP(B10,[1]DataSheet!$E$2:$H$112,3,0) -> 145977.02 | E10: =SUMIF(AJE!$B$8:$B$36,B10,AJE!$D$8:$D$36)-SUMIF(AJE!$G$8:$G$36,B10,AJE!$I$8:$I$36) -> 0 | F10: =D10+E10 -> 145977.02 | G10: =VLOOKUP(B10,[1]DataSheet!$E$2:$H$112,4,0) -> 40247.32 | H10: =SUMIF(AJE!$B$8:$B$36,B10,AJE!$E$8:$E$36)-SUMIF(AJE!$G$8:$G$36,B10,AJE!$J$8:$J$36) -> 0 | I10: =G10+H10 -> 40247.32 | J10: Restricted cash | K10: =D10/G10 -> 3.6269998 | L10: מתאים לבנק
B11: 1012 | C11: פקדון בנק לאומי $$ | D11: =VLOOKUP(B11,[1]DataSheet!$E$2:$H$112,3,0) -> 1648707.1 | E11: =SUMIF(AJE!$B$8:$B$36,B11,AJE!$D$8:$D$36)-SUMIF(AJE!$G$8:$G$36,B11,AJE!$I$8:$I$36) -> 0 | F11: =D11+E11 -> 1648707.1 | G11: =VLOOKUP(B11,[1]DataSheet!$E$2:$H$112,4,0) -> 454564.97 | H11: =SUMIF(AJE!$B$8:$B$36,B11,AJE!$E$8:$E$36)-SUMIF(AJE!$G$8:$G$36,B11,AJE!$J$8:$J$36) -> 0 | I11: =G11+H11 -> 454564.97 | J11: Cash and cash equivalents | K11: =D11/G11 -> 3.627 | L11: הוכנס ב 31/10 נפרע ב 31/1/24
B12: 1701 | C12: מראש | D12: =VLOOKUP(B12,[1]DataSheet!$E$2:$H$112,3,0) -> 100360.02 | E12: =SUMIF(AJE!$B$8:$B$36,B12,AJE!$D$8:$D$36)-SUMIF(AJE!$G$8:$G$36,B12,AJE!$I$8:$I$36) -> 0 | F12: =D12+E12 -> 100360.02 | G12: =VLOOKUP(B12,[1]DataSheet!$E$2:$H$112,4,0) -> 27670.25 | H12: =SUMIF(AJE!$B$8:$B$36,B12,AJE!$E$8:$E$36)-SUMIF(AJE!$G$8:$G$36,B12,AJE!$J$8:$J$36) -> 0 | I12: =G12+H12 -> 27670.25 | J12: Other current assets | L12: נייר פרוט
A13: ="150.עלות" -> 150.עלות | B13: 1500 | C13: ="מחשבים ותוכנות" -> מחשבים ותוכנות | D13: =VLOOKUP(B13,[1]DataSheet!$E$2:$H$112,3,0) -> 200238.09 | E13: =SUMIF(AJE!$B$8:$B$36,B13,AJE!$D$8:$D$36)-SUMIF(AJE!$G$8:$G$36,B13,AJE!$I$8:$I$36) -> 0 | F13: =D13+E13 -> 200238.09 | G13: =VLOOKUP(B13,[1]DataSheet!$E$2:$H$112,4,0) -> 60215.91 | H13: =SUMIF(AJE!$B$8:$B$36,B13,AJE!$E$8:$E$36)-SUMIF(AJE!$G$8:$G$36,B13,AJE!$J$8:$J$36) -> 0 | I13: =G13+H13 -> 60215.91 | J13: Property and Equipment, Net | K13: =D13/G13 -> 3.3253353 | L13: טופס פחת
A14: ="150.עלות" -> 150.עלות | B14: 1501 | C14: ="ריהוט וציוד" -> ריהוט וציוד | D14: =VLOOKUP(B14,[1]DataSheet!$E$2:$H$112,3,0) -> 152525.54 | E14: =SUMIF(AJE!$B$8:$B$36,B14,AJE!$D$8:$D$36)-SUMIF(AJE!$G$8:$G$36,B14,AJE!$I$8:$I$36) -> 0 | F14: =D14+E14 -> 152525.54 | G14: =VLOOKUP(B14,[1]DataSheet!$E$2:$H$112,4,0) -> 46915.77 | H14: =SUMIF(AJE!$B$8:$B$36,B14,AJE!$E$8:$E$36)-SUMIF(AJE!$G$8:$G$36,B14,AJE!$J$8:$J$36) -> 0 | I14: =G14+H14 -> 46915.77 | J14: Property and Equipment, Net | K14: =D14/G14 -> 3.2510506 | L14: טופס פחת
A15: ="150.עלות" -> 150.עלות | B15: 1502 | C15: ="שיפורים במושכר" -> שיפורים במושכר | D15: =VLOOKUP(B15,[1]DataSheet!$E$2:$H$112,3,0) -> 113554.22 | E15: =SUMIF(AJE!$B$8:$B$36,B15,AJE!$D$8:$D$36)-SUMIF(AJE!$G$8:$G$36,B15,AJE!$I$8:$I$36) -> 0 | F15: =D15+E15 -> 113554.22 | G15: =VLOOKUP(B15,[1]DataSheet!$E$2:$H$112,4,0) -> 35016.34 | H15: =SUMIF(AJE!$B$8:$B$36,B15,AJE!$E$8:$E$36)-SUMIF(AJE!$G$8:$G$36,B15,AJE!$J$8:$J$36) -> 0 | I15: =G15+H15 -> 35016.34 | J15: Property and Equipment, Net | K15: =D15/G15 -> 3.2428923 | L15: טופס פחת
B16: 1550 | C16: פחת נצבר | D16: =VLOOKUP(B16,[1]DataSheet!$E$2:$H$112,3,0) -> -177419 | E16: =SUMIF(AJE!$B$8:$B$36,B16,AJE!$D$8:$D$36)-SUMIF(AJE!$G$8:$G$36,B16,AJE!$I$8:$I$36) -> 0 | F16: =D16+E16 -> -177419 | G16: =VLOOKUP(B16,[1]DataSheet!$E$2:$H$112,4,0) -> -54557 | H16: =SUMIF(AJE!$B$8:$B$36,B16,AJE!$E$8:$E$36)-SUMIF(AJE!$G$8:$G$36,B16,AJE!$J$8:$J$36) -> 0 | I16: =G16+H16 -> -54557 | J16: Property and Equipment, Net | K16: =D16/G16 -> 3.2519933 | L16: טופס פחת
A17: ="250.מע'מ חו'ז" -> 250.מע'מ חו'ז | B17: 2500 | C17: ="מע'מ חו'ז" -> מע'מ חו'ז | D17: =VLOOKUP(B17,[1]DataSheet!$E$2:$H$112,3,0) -> 61128.31 | E17: =SUMIF(AJE!$B$8:$B$36,B17,AJE!$D$8:$D$36)-SUMIF(AJE!$G$8:$G$36,B17,AJE!$I$8:$I$36) -> 0 | F17: =D17+E17 -> 61128.31 | G17: =VLOOKUP(B17,[1]DataSheet!$E$2:$H$112,4,0) -> 16853.68 | H17: =SUMIF(AJE!$B$8:$B$36,B17,AJE!$E$8:$E$36)-SUMIF(AJE!$G$8:$G$36,B17,AJE!$J$8:$J$36) -> 0 | I17: =G17+H17 -> 16853.68 | J17: Account Receivable-VAT+TAX | K17: =D17/G17 -> 3.6270007
A18: ="250.מע'מ חו'ז" -> 250.מע'מ חו'ז | B18: 2502 | C18: ="מע'מ תשומות" -> מע'מ תשומות | D18: =VLOOKUP(B18,[1]DataSheet!$E$2:$H$112,3,0) -> 2237.45 | E18: =SUMIF(AJE!$B$8:$B$36,B18,AJE!$D$8:$D$36)-SUMIF(AJE!$G$8:$G$36,B18,AJE!$I$8:$I$36) -> 0 | F18: =D18+E18 -> 2237.45 | G18: =VLOOKUP(B18,[1]DataSheet!$E$2:$H$112,4,0) -> 616.89 | H18: =SUMIF(AJE!$B$8:$B$36,B18,AJE!$E$8:$E$36)-SUMIF(AJE!$G$8:$G$36,B18,AJE!$J$8:$J$36) -> 0 | I18: =G18+H18 -> 616.89 | J18: Account Receivable-VAT+TAX | K18: =D18/G18 -> 3.6269837
A19: ="250.מע'מ חו'ז" -> 250.מע'מ חו'ז | B19: 2503 | C19: ="מע'מ תשומות לנכסים" -> מע'מ תשומות לנכסים | E19: =SUMIF(AJE!$B$8:$B$36,B19,AJE!$D$8:$D$36)-SUMIF(AJE!$G$8:$G$36,B19,AJE!$I$8:$I$36) -> 0 | F19: =D19+E19 -> 0 | H19: =SUMIF(AJE!$B$8:$B$36,B19,AJE!$E$8:$E$36)-SUMIF(AJE!$G$8:$G$36,B19,AJE!$J$8:$J$36) -> 0 | I19: =G19+H19 -> 0 | J19: Account Receivable-VAT+TAX | K19: =D19/G19 -> #DIV/0!
B20: 2610 | C20: עודפות 2021 | D20: =VLOOKUP(B20,[1]DataSheet!$E$2:$H$112,3,0) -> 7038 | E20: =SUMIF(AJE!$B$8:$B$36,B20,AJE!$D$8:$D$36)-SUMIF(AJE!$G$8:$G$36,B20,AJE!$I$8:$I$36) -> 0 | F20: =D20+E20 -> 7038 | G20: =VLOOKUP(B20,[1]DataSheet!$E$2:$H$112,4,0) -> 1940.45 | H20: =SUMIF(AJE!$B$8:$B$36,B20,AJE!$E$8:$E$36)-SUMIF(AJE!$G$8:$G$36,B20,AJE!$J$8:$J$36) -> 0 | I20: =G20+H20 -> 1940.45 | J20: Account Receivable-VAT+TAX | K20: =D20/G20 -> 3.6269937
B21: 2611 | C21: עודפות 2022 | D21: =VLOOKUP(B21,[1]DataSheet!$E$2:$H$112,3,0) -> 41031 | E21: =SUMIF(AJE!$B$8:$B$36,B21,AJE!$D$8:$D$36)-SUMIF(AJE!$G$8:$G$36,B21,AJE!$I$8:$I$36) -> 0 | F21: =D21+E21 -> 41031 | G21: =VLOOKUP(B21,[1]DataSheet!$E$2:$H$112,4,0) -> 11312.66 | H21: =SUMIF(AJE!$B$8:$B$36,B21,AJE!$E$8:$E$36)-SUMIF(AJE!$G$8:$G$36,B21,AJE!$J$8:$J$36) -> 0 | I21: =G21+H21 -> 11312.66 | J21: Account Receivable-VAT+TAX
B22: 2701 | C22: לשלם | E22: =SUMIF(AJE!$B$8:$B$36,B22,AJE!$D$8:$D$36)-SUMIF(AJE!$G$8:$G$36,B22,AJE!$I$8:$I$36) -> -32627.41 | F22: =D22+E22 -> -32627.41 | H22: =SUMIF(AJE!$B$8:$B$36,B22,AJE!$E$8:$E$36)-SUMIF(AJE!$G$8:$G$36,B22,AJE!$J$8:$J$36) -> -8995.7018 | I22: =G22+H22 -> -8995.7018 | J22: Accrued expenses | L22: פרוט בפקודת יומן גיליון AJE , חסר לי הפרשה ל EY
A23: ="280.צדדים קשורים" -> 280.צדדים קשורים | B23: 2801 | C23: ="GETCTRL INC חו""ז" -> GETCTRL INC חו"ז | D23: =VLOOKUP(B23,[1]DataSheet!$E$2:$H$112,3,0) -> -5156583.3 | E23: =SUMIF(AJE!$B$8:$B$36,B23,AJE!$D$8:$D$36)-SUMIF(AJE!$G$8:$G$36,B23,AJE!$I$8:$I$36) -> 0 | F23: =D23+E23 -> -5156583.3 | G23: =VLOOKUP(B23,[1]DataSheet!$E$2:$H$112,4,0) -> -1434999.3 | H23: =SUMIF(AJE!$B$8:$B$36,B23,AJE!$E$8:$E$36)-SUMIF(AJE!$G$8:$G$36,B23,AJE!$J$8:$J$36) -> 0 | I23: =G23+H23 -> -1434999.3 | J23: Related party | K23: =D23/G23 -> 3.5934395
B24: 2803 | C24: UK Getctrl LTD | D24: =VLOOKUP(B24,[1]DataSheet!$E$2:$H$112,3,0) -> 2360100 | E24: =SUMIF(AJE!$B$8:$B$36,B24,AJE!$D$8:$D$36)-SUMIF(AJE!$G$8:$G$36,B24,AJE!$I$8:$I$36) -> -2711172.1 | F24: =D24+E24 -> -351072.18 | G24: =VLOOKUP(B24,[1]DataSheet!$E$2:$H$112,4,0) -> 650703.05 | H24: =SUMIF(AJE!$B$8:$B$36,B24,AJE!$E$8:$E$36)-SUMIF(AJE!$G$8:$G$36,B24,AJE!$J$8:$J$36) -> -750646.81 | I24: =G24+H24 -> -99943.758 | J24: Related party | K24: =D24/G24 -> 3.627 | L24: היתרה בלישט | M24: -164258 | N24: מתאים לספרי אנגליה
B25: 2804 | C25: שטר הון USA GETCTRL | D25: =VLOOKUP(B25,[1]DataSheet!$E$2:$H$112,3,0) -> -22281920 | E25: =SUMIF(AJE!$B$8:$B$36,B25,AJE!$D$8:$D$36)-SUMIF(AJE!$G$8:$G$36,B25,AJE!$I$8:$I$36) -> 0 | F25: =D25+E25 -> -22281920 | G25: =VLOOKUP(B25,[1]DataSheet!$E$2:$H$112,4,0) -> -6600000 | H25: =SUMIF(AJE!$B$8:$B$36,B25,AJE!$E$8:$E$36)-SUMIF(AJE!$G$8:$G$36,B25,AJE!$J$8:$J$36) -> 0 | I25: =G25+H25 -> -6600000 | J25: Capital note | L25: ללא תזוזה משנה שעברה
B26: 1704 | C26: נכס בגין תקן שכירות | D26: =VLOOKUP(B26,[1]DataSheet!$E$2:$H$112,3,0) -> 563565 | E26: =SUMIF(AJE!$B$8:$B$36,B26,AJE!$D$8:$D$36)-SUMIF(AJE!$G$8:$G$36,B26,AJE!$I$8:$I$36) -> 0 | F26: =D26+E26 -> 563565 | G26: =VLOOKUP(B26,[1]DataSheet!$E$2:$H$112,4,0) -> 160149.19 | H26: =SUMIF(AJE!$B$8:$B$36,B26,AJE!$E$8:$E$36)-SUMIF(AJE!$G$8:$G$36,B26,AJE!$J$8:$J$36) -> 0 | I26: =G26+H26 -> 160149.19 | J26: Other Long term Assets
B27: 2704 | C27: התחייבות בגין שכירות | D27: =VLOOKUP(B27,[1]DataSheet!$E$2:$H$112,3,0) -> -569697 | E27: =SUMIF(AJE!$B$8:$B$36,B27,AJE!$D$8:$D$36)-SUMIF(AJE!$G$8:$G$36,B27,AJE!$I$8:$I$36) -> 0 | F27: =D27+E27 -> -569697 | G27: =VLOOKUP(B27,[1]DataSheet!$E$2:$H$112,4,0) -> -161891.73 | H27: =SUMIF(AJE!$B$8:$B$36,B27,AJE!$E$8:$E$36)-SUMIF(AJE!$G$8:$G$36,B27,AJE!$J$8:$J$36) -> 0 | I27: =G27+H27 -> -161891.73 | J27: Other Long term liabilities
A28: ="300.ספקים" -> 300.ספקים | B28: 3003 | C28: ="סודקסו פאס ישראל בע""מ CIBUS" -> סודקסו פאס ישראל בע"מ CIBUS | D28: =VLOOKUP(B28,[1]DataSheet!$E$2:$H$112,3,0) -> -6571 | E28: =SUMIF(AJE!$B$8:$B$36,B28,AJE!$D$8:$D$36)-SUMIF(AJE!$G$8:$G$36,B28,AJE!$I$8:$I$36) -> 0 | F28: =D28+E28 -> -6571 | G28: =VLOOKUP(B28,[1]DataSheet!$E$2:$H$112,4,0) -> -1811.69 | H28: =SUMIF(AJE!$B$8:$B$36,B28,AJE!$E$8:$E$36)-SUMIF(AJE!$G$8:$G$36,B28,AJE!$J$8:$J$36) -> 0 | I28: =G28+H28 -> -1811.69 | J28: Accounts payable | K28: =D28/G28 -> 3.6270002
A29: ="300.ספקים" -> 300.ספקים | B29: 3017 | C29: ="תכן חברה כלכלית של הקיבוץ הארצי בע""מ" -> תכן חברה כלכלית של הקיבוץ הארצי בע"מ | D29: =VLOOKUP(B29,[1]DataSheet!$E$2:$H$112,3,0) -> -5868 | E29: =SUMIF(AJE!$B$8:$B$36,B29,AJE!$D$8:$D$36)-SUMIF(AJE!$G$8:$G$36,B29,AJE!$I$8:$I$36) -> 0 | F29: =D29+E29 -> -5868 | G29: =VLOOKUP(B29,[1]DataSheet!$E$2:$H$112,4,0) -> -1617.87 | H29: =SUMIF(AJE!$B$8:$B$36,B29,AJE!$E$8:$E$36)-SUMIF(AJE!$G$8:$G$36,B29,AJE!$J$8:$J$36) -> 0 | I29: =G29+H29 -> -1617.87 | J29: Accounts payable | K29: =D29/G29 -> 3.626991
A30: ="300.ספקים" -> 300.ספקים | B30: 3026 | C30: ="נ.פ.א סוכנות לביטוח (2001) בע""מ" -> נ.פ.א סוכנות לביטוח (2001) בע"מ | D30: =VLOOKUP(B30,[1]DataSheet!$E$2:$H$112,3,0) -> -350 | E30: =SUMIF(AJE!$B$8:$B$36,B30,AJE!$D$8:$D$36)-SUMIF(AJE!$G$8:$G$36,B30,AJE!$I$8:$I$36) -> 0 | F30: =D30+E30 -> -350 | G30: =VLOOKUP(B30,[1]DataSheet!$E$2:$H$112,4,0) -> -96.5 | H30: =SUMIF(AJE!$B$8:$B$36,B30,AJE!$E$8:$E$36)-SUMIF(AJE!$G$8:$G$36,B30,AJE!$J$8:$J$36) -> 0 | I30: =G30+H30 -> -96.5 | J30: Accounts payable | K30: =D30/G30 -> 3.626943
A31: ="305.ספקים חו""ל" -> 305.ספקים חו"ל | B31: 3120 | C31: ="GOOGLE" -> GOOGLE | D31: =VLOOKUP(B31,[1]DataSheet!$E$2:$H$112,3,0) -> -25.82 | E31: =SUMIF(AJE!$B$8:$B$36,B31,AJE!$D$8:$D$36)-SUMIF(AJE!$G$8:$G$36,B31,AJE!$I$8:$I$36) -> 0 | F31: =D31+E31 -> -25.82 | G31: =VLOOKUP(B31,[1]DataSheet!$E$2:$H$112,4,0) -> -7.12 | H31: =SUMIF(AJE!$B$8:$B$36,B31,AJE!$E$8:$E$36)-SUMIF(AJE!$G$8:$G$36,B31,AJE!$J$8:$J$36) -> 0 | I31: =G31+H31 -> -7.12 | J31: Accounts payable | K31: =D31/G31 -> 3.6264045
B32: 3099 | C32: אוטומט איט מלם תים בע"מ | D32: =VLOOKUP(B32,[1]DataSheet!$E$2:$H$112,3,0) -> 15461.12 | E32: =SUMIF(AJE!$B$8:$B$36,B32,AJE!$D$8:$D$36)-SUMIF(AJE!$G$8:$G$36,B32,AJE!$I$8:$I$36) -> -15461.12 | F32: =D32+E32 -> 0 | G32: =VLOOKUP(B32,[1]DataSheet!$E$2:$H$112,4,0) -> 4262.78 | H32: =SUMIF(AJE!$B$8:$B$36,B32,AJE!$E$8:$E$36)-SUMIF(AJE!$G$8:$G$36,B32,AJE!$J$8:$J$36) -> -4262.7847 | I32: =G32+H32 -> -0.0046705266 | J32: Accounts payable | K32: =D32/G32 -> 3.627004
B33: 3180 | C33: FullStory,Inc. | D33: =VLOOKUP(B33,[1]DataSheet!$E$2:$H$112,3,0) -> -27933.99 | E33: =SUMIF(AJE!$B$8:$B$36,B33,AJE!$D$8:$D$36)-SUMIF(AJE!$G$8:$G$36,B33,AJE!$I$8:$I$36) -> 0 | F33: =D33+E33 -> -27933.99 | G33: =VLOOKUP(B33,[1]DataSheet!$E$2:$H$112,4,0) -> -7701.68 | H33: =SUMIF(AJE!$B$8:$B$36,B33,AJE!$E$8:$E$36)-SUMIF(AJE!$G$8:$G$36,B33,AJE!$J$8:$J$36) -> 0 | I33: =G33+H33 -> -7701.68 | J33: Accounts payable | K33: =D33/G33 -> 3.6269996
B34: 3245 | C34: LinkedIN -ש"ח | D34: =VLOOKUP(B34,[1]DataSheet!$E$2:$H$112,3,0) -> 7273.84 | E34: =SUMIF(AJE!$B$8:$B$36,B34,AJE!$D$8:$D$36)-SUMIF(AJE!$G$8:$G$36,B34,AJE!$I$8:$I$36) -> -7273.84 | F34: =D34+E34 -> 0 | G34: =VLOOKUP(B34,[1]DataSheet!$E$2:$H$112,4,0) -> 2005.47 | H34: =SUMIF(AJE!$B$8:$B$36,B34,AJE!$E$8:$E$36)-SUMIF(AJE!$G$8:$G$36,B34,AJE!$J$8:$J$36) -> -2005.4701 | I34: =G34+H34 -> -8.5470086e-05 | J34: Accounts payable | K34: =D34/G34 -> 3.6270002
B35: 3016 | C35: GETT ג'יטי גטאקסי | D35: =VLOOKUP(B35,[1]DataSheet!$E$2:$H$112,3,0) -> -125 | E35: =SUMIF(AJE!$B$8:$B$36,B35,AJE!$D$8:$D$36)-SUMIF(AJE!$G$8:$G$36,B35,AJE!$I$8:$I$36) -> 0 | F35: =D35+E35 -> -125 | G35: =VLOOKUP(B35,[1]DataSheet!$E$2:$H$112,4,0) -> -34.46 | H35: =SUMIF(AJE!$B$8:$B$36,B35,AJE!$E$8:$E$36)-SUMIF(AJE!$G$8:$G$36,B35,AJE!$J$8:$J$36) -> 0 | I35: =G35+H35 -> -34.46 | J35: Accounts payable | K35: =D35/G35 -> 3.6273941
B36: 3139 | C36: Amazon.co.UK | D36: =VLOOKUP(B36,[1]DataSheet!$E$2:$H$112,3,0) -> 1669.21 | E36: =SUMIF(AJE!$B$8:$B$36,B36,AJE!$D$8:$D$36)-SUMIF(AJE!$G$8:$G$36,B36,AJE!$I$8:$I$36) -> -1669.21 | F36: =D36+E36 -> 0 | G36: =VLOOKUP(B36,[1]DataSheet!$E$2:$H$112,4,0) -> 460.22 | H36: =SUMIF(AJE!$B$8:$B$36,B36,AJE!$E$8:$E$36)-SUMIF(AJE!$G$8:$G$36,B36,AJE!$J$8:$J$36) -> -460.21781 | I36: =G36+H36 -> 0.002189137 | J36: Accounts payable | K36: =D36/G36 -> 3.6269827
B37: 3191 | C37: GBP-SKYPE.COM/GO/BILL Luxembourg | D37: =VLOOKUP(B37,[1]DataSheet!$E$2:$H$112,3,0) -> -10.63 | E37: =SUMIF(AJE!$B$8:$B$36,B37,AJE!$D$8:$D$36)-SUMIF(AJE!$G$8:$G$36,B37,AJE!$I$8:$I$36) -> 0 | F37: =D37+E37 -> -10.63 | G37: =VLOOKUP(B37,[1]DataSheet!$E$2:$H$112,4,0) -> -2.93 | H37: =SUMIF(AJE!$B$8:$B$36,B37,AJE!$E$8:$E$36)-SUMIF(AJE!$G$8:$G$36,B37,AJE!$J$8:$J$36) -> 0 | I37: =G37+H37 -> -2.93 | J37: Accounts payable | K37: =D37/G37 -> 3.6279863
B38: 3277 | C38: HubSpot Ireland Ltd | D38: =VLOOKUP(B38,[1]DataSheet!$E$2:$H$112,3,0) -> 1813.5 | E38: =SUMIF(AJE!$B$8:$B$36,B38,AJE!$D$8:$D$36)-SUMIF(AJE!$G$8:$G$36,B38,AJE!$I$8:$I$36) -> -1813.5 | F38: =D38+E38 -> 0 | G38: =VLOOKUP(B38,[1]DataSheet!$E$2:$H$112,4,0) -> 500 | H38: =SUMIF(AJE!$B$8:$B$36,B38,AJE!$E$8:$E$36)-SUMIF(AJE!$G$8:$G$36,B38,AJE!$J$8:$J$36) -> -500 | I38: =G38+H38 -> 0 | J38: Accounts payable | K38: =D38/G38 -> 3.627
B39: 3302 | C39: Nickolay Ribal | D39: =VLOOKUP(B39,[1]DataSheet!$E$2:$H$112,3,0) -> -37478.08 | E39: =SUMIF(AJE!$B$8:$B$36,B39,AJE!$D$8:$D$36)-SUMIF(AJE!$G$8:$G$36,B39,AJE!$I$8:$I$36) -> 0 | F39: =D39+E39 -> -37478.08 | G39: =VLOOKUP(B39,[1]DataSheet!$E$2:$H$112,4,0) -> -10333.08 | H39: =SUMIF(AJE!$B$8:$B$36,B39,AJE!$E$8:$E$36)-SUMIF(AJE!$G$8:$G$36,B39,AJE!$J$8:$J$36) -> 0 | I39: =G39+H39 -> -10333.08 | J39: Accounts payable | K39: =D39/G39 -> 3.6269999
B40: 3303 | C40: Tricentis | D40: =VLOOKUP(B40,[1]DataSheet!$E$2:$H$112,3,0) -> -25362.16 | E40: =SUMIF(AJE!$B$8:$B$36,B40,AJE!$D$8:$D$36)-SUMIF(AJE!$G$8:$G$36,B40,AJE!$I$8:$I$36) -> 0 | F40: =D40+E40 -> -25362.16 | G40: =VLOOKUP(B40,[1]DataSheet!$E$2:$H$112,4,0) -> -6992.6 | H40: =SUMIF(AJE!$B$8:$B$36,B40,AJE!$E$8:$E$36)-SUMIF(AJE!$G$8:$G$36,B40,AJE!$J$8:$J$36) -> 0 | I40: =G40+H40 -> -6992.6 | J40: Accounts payable | K40: =D40/G40 -> 3.627
...

Sheet AJE
G2: 45291 | H2: 3.627
B3: Additional Entries | G3: Averge | H3: 3.6
E4: 929080.21
B6: Debit | G6: Credit | L6: Description
B7: Account # | C7: Account name | D7: ₪ | E7: $ | G7: Account # | H7: Account name | I7: ₪ | J7: $
L10: לשלם
B11: 7810 | D11: =8100*2 -> 16200 | E11: =D11/$H$2 -> 4466.5012 | G11: 2701 | H11: =VLOOKUP(G11,TB!$B$2:$C$121,2,0) -> לשלם | I11: =D11 -> 16200 | J11: =E11 -> 4466.5012 | L11: הוצ לשלם שינדלר 11+12
B12: 7805 | D12: 4671 | E12: =D12/$H$2 -> 1287.8412 | G12: 2701 | H12: =VLOOKUP(G12,TB!$B$2:$C$121,2,0) -> לשלם | I12: =D12 -> 4671 | J12: =E12 -> 1287.8412 | L12: ארנונה 11+12
B13: 7450 | D13: =13755/1.17 -> 11756.41 | E13: =D13/$H$2 -> 3241.3593 | G13: 2701 | H13: =VLOOKUP(G13,TB!$B$2:$C$121,2,0) -> לשלם | I13: =D13 -> 11756.41 | J13: =E13 -> 3241.3593 | L13: רוני מסיאנו 12-23
L18: הפרשה לספקים בחובה
B19: 7450 | D19: 147034.74 | E19: =D19/$H$2 -> 40538.941 | G19: 3110 | H19: LINKEDIN | I19: =D19 -> 147034.74 | J19: =E19 -> 40538.941
B20: 7450 | D20: 7273.84 | E20: =D20/$H$2 -> 2005.4701 | G20: 3245 | H20: LinkedIN -ש"ח | I20: =D20 -> 7273.84 | J20: =E20 -> 2005.4701
B21: 7450 | D21: 1813.5 | E21: =D21/$H$2 -> 500 | G21: 3277 | H21: HubSpot Ireland Ltd | I21: =D21 -> 1813.5 | J21: =E21 -> 500
B22: 7301 | D22: 15461.12 | E22: =D22/$H$2 -> 4262.7847 | G22: 3099 | H22: אוטומט איט מלם תים בע"מ | I22: =D22 -> 15461.12 | J22: =E22 -> 4262.7847
B23: 7301 | D23: 5461 | E23: =D23/$H$2 -> 1505.6521 | G23: 3314 | H23: דורקם סהר | I23: =D23 -> 5461 | J23: =E23 -> 1505.6521
B24: 7305 | D24: 5787.57 | E24: =D24/$H$2 -> 1595.6907 | G24: 3119 | H24: NOTION LABS INC | I24: =D24 -> 5787.57 | J24: =E24 -> 1595.6907
B25: 7305 | D25: 1094.85 | E25: =D25/$H$2 -> 301.86104 | G25: 3123 | H25: GITHUB | I25: =D25 -> 1094.85 | J25: =E25 -> 301.86104
B26: 7301 | D26: 1669.21 | E26: =D26/$H$2 -> 460.21781 | G26: 3139 | H26: Amazon.co.UK | I26: =D26 -> 1669.21 | J26: =E26 -> 460.21781
B27: 7450 | D27: 3506.76 | E27: =D27/$H$2 -> 966.84864 | G27: 3338 | H27: מיסאנו רוני | I27: =D27 -> 3506.76 | J27: =E27 -> 966.84864
N29: סכומים בלישט
B30: 7560 | C30: COST+אנגליה שיווק | D30: =E30*H2 -> 1710764.6 | E30: ='TB UK'!E74 -> 471674.81 | G30: 2803 | I30: =D30 -> 1710764.6 | J30: =E30 -> 471674.81 | L30: COST + סכום בלישט 370484 | N30: 370487.32
B31: 7861 | C31: COST+אנגליה | D31: =E31*H3 -> 1000407.6 | E31: ='TB UK'!E75 -> 277890.99 | G31: 2803 | I31: =D31 -> 1000407.6 | J31: =E31 -> 277890.99 | L31: COST +סכום בלישט 218276 | N31: 218275.57
B32: 9002 | E32: 1081 | G32: 2803 | J32: =E32 -> 1081 | L32: הפרשי שער רק בדולרים
B35: 4 | C35: =VLOOKUP(B35,TB!$B$2:$C$121,2,0) -> אלוקציות RD | D35: ='אלוקציה הוצ'!C13 -> 640307.23 | E35: =D35/$H$2 -> 176539.08 | G35: 3 | H35: =VLOOKUP(G35,TB!$B$2:$C$121,2,0) -> אלוקציות הנהלה | I35: =D35 -> 640307.23 | J35: =E35 -> 176539.08 | L35: אלוקציות הוצאות RD

Sheet TB UK
A1: Currency | D1: GBP | E1: AJE | F1: Total GPB | G1: USD | H1: AJE | I1: Total USD
A2: Account Code | B2: Account | C2: Account Type | D2: 45291 | E2: 45291 | F2: 45291 | G2: 45291 | H2: 45291 | I2: 45291 | Q2: Currency | T2: GBP | U2: USD
A3: 200 | B3: S&M Cost plus revenue | C3: Revenue | D3: =VLOOKUP(A3,$Q$4:$U$67,4,0) -> -370487 | F3: =D3+E3 -> -370487 | G3: =VLOOKUP(A3,$Q$4:$U$67,5,0) -> -471674.41 | I3: =G3+H3 -> -471674.41 | J3: COST + UK S&M | Q3: Account Code | R3: Account | S3: Account Type | T3: 45291 | U3: 45291
A4: 200a | B4: G&A Cost plus revenue | C4: Revenue | D4: =VLOOKUP(A4,$Q$4:$U$67,4,0) -> -218276 | F4: =D4+E4 -> -218276 | G4: =VLOOKUP(A4,$Q$4:$U$67,5,0) -> -277891.54 | I4: =G4+H4 -> -277891.54 | J4: COST + UK G&A | Q4: 200 | R4: S&M Cost plus revenue | S4: Revenue | T4: -370487 | U4: -471674.41 | V4: =VLOOKUP(Q4,$A$3:$A$63,1,0) -> 200
A5: 270 | B5: Interest Income | C5: Overhead | D5: =VLOOKUP(A5,$Q$4:$U$67,4,0) -> -556.5 | F5: =D5+E5 -> -556.5 | G5: =VLOOKUP(A5,$Q$4:$U$67,5,0) -> -708.49128 | I5: =G5+H5 -> -708.49128 | J5: Financial expenses (income) | Q5: 200a | R5: G&A Cost plus revenue | S5: Revenue | T5: -218276 | U5: -277891.54 | V5: =VLOOKUP(Q5,$A$3:$A$63,1,0) -> 200a
A6: 310 | B6: Cost of Goods Sold | C6: Overhead | D6: =VLOOKUP(A6,$Q$4:$U$67,4,0) -> 103.2 | F6: =D6+E6 -> 103.2 | G6: =VLOOKUP(A6,$Q$4:$U$67,5,0) -> 131.38598 | I6: =G6+H6 -> 131.38598 | J6: Other - G&A | Q6: 270 | R6: Interest Income | S6: Revenue | T6: -556.5 | U6: -708.49128 | V6: =VLOOKUP(Q6,$A$3:$A$63,1,0) -> 270
A7: 400 | B7: G&A - Marketing | C7: Overhead | D7: =VLOOKUP(A7,$Q$4:$U$67,4,0) -> 8690 | F7: =D7+E7 -> 8690 | G7: =VLOOKUP(A7,$Q$4:$U$67,5,0) -> 11063.413 | I7: =G7+H7 -> 11063.413 | J7: Marketing | Q7: 310 | R7: Cost of Goods Sold | S7: Direct Costs | T7: 103.2 | U7: 131.38598 | V7: =VLOOKUP(Q7,$A$3:$A$63,1,0) -> 310
A8: 401 | B8: G&A - Audit and Accounting | C8: Overhead | D8: =VLOOKUP(A8,$Q$4:$U$67,4,0) -> 38064.35 | F8: =D8+E8 -> 38064.35 | G8: =VLOOKUP(A8,$Q$4:$U$67,5,0) -> 48460.485 | I8: =G8+H8 -> 48460.485 | J8: Accounting & Financial Services | Q8: 400 | R8: G&A - Marketing | S8: Overhead | T8: 8690 | U8: 11063.413 | V8: =VLOOKUP(Q8,$A$3:$A$63,1,0) -> 400
A9: 404 | B9: Finance - Bank Charges And Fees | C9: Overhead | D9: =VLOOKUP(A9,$Q$4:$U$67,4,0) -> 82.62 | F9: =D9+E9 -> 82.62 | G9: =VLOOKUP(A9,$Q$4:$U$67,5,0) -> 105.18517 | I9: =G9+H9 -> 105.18517 | J9: Financial expenses (income) | Q9: 401 | R9: G&A - Audit and Accounting | S9: Overhead | T9: 38064.35 | U9: 48460.485 | V9: =VLOOKUP(Q9,$A$3:$A$63,1,0) -> 401
A10: 412 | B10: Consulting | C10: Overhead | D10: =VLOOKUP(A10,$Q$4:$U$67,4,0) -> 0 | F10: =D10+E10 -> 0 | G10: =VLOOKUP(A10,$Q$4:$U$67,5,0) -> 0 | I10: =G10+H10 -> 0 | J10: Legal & Professional Services | Q10: 404 | R10: Finance - Bank Charges And Fees | S10: Overhead | T10: 82.62 | U10: 105.18517 | V10: =VLOOKUP(Q10,$A$3:$A$63,1,0) -> 404
A11: 416 | B11: G&A - Depreciation Expenses | C11: Overhead | D11: =VLOOKUP(A11,$Q$4:$U$67,4,0) -> 330 | F11: =D11+E11 -> 330 | G11: =VLOOKUP(A11,$Q$4:$U$67,5,0) -> 420.1296 | I11: =G11+H11 -> 420.1296 | J11: Depreciation | Q11: 412 | R11: Consulting | S11: Overhead | T11: 0 | U11: 0 | V11: =VLOOKUP(Q11,$A$3:$A$63,1,0) -> 412
A12: 418 | B12: Charitable and Political Donations | C12: Overhead | D12: =VLOOKUP(A12,$Q$4:$U$67,4,0) -> 1315 | F12: =D12+E12 -> 1315 | G12: =VLOOKUP(A12,$Q$4:$U$67,5,0) -> 1674.1528 | I12: =G12+H12 -> 1674.1528 | J12: Other - G&A | Q12: 416 | R12: G&A - Depreciation Expenses | S12: Overhead | T12: 330 | U12: 420.1296 | V12: =VLOOKUP(Q12,$A$3:$A$63,1,0) -> 416
A13: 420 | B13: Entertainment-100% business | C13: Overhead | D13: =VLOOKUP(A13,$Q$4:$U$67,4,0) -> 3066.62 | F13: =D13+E13 -> 3066.62 | G13: =VLOOKUP(A13,$Q$4:$U$67,5,0) -> 3904.1753 | I13: =G13+H13 -> 3904.1753 | J13: Welfare | Q13: 418 | R13: Charitable and Political Donations | S13: Overhead | T13: 1315 | U13: 1674.1528 | V13: =VLOOKUP(Q13,$A$3:$A$63,1,0) -> 418
A14: 426 | B14: G&A - Fines and penalties | C14: Overhead | D14: =VLOOKUP(A14,$Q$4:$U$67,4,0) -> 701.07 | F14: =D14+E14 -> 701.07 | G14: =VLOOKUP(A14,$Q$4:$U$67,5,0) -> 892.54624 | I14: =G14+H14 -> 892.54624 | J14: Financial expenses (income) | Q14: 420 | R14: Entertainment-100% business | S14: Overhead | T14: 3066.62 | U14: 3904.1753 | V14: =VLOOKUP(Q14,$A$3:$A$63,1,0) -> 420
A15: 429 | B15: G&A - Office Equipment And Miscellaneous | C15: Overhead | D15: =VLOOKUP(A15,$Q$4:$U$67,4,0) -> 542.71 | F15: =D15+E15 -> 542.71 | G15: =VLOOKUP(A15,$Q$4:$U$67,5,0) -> 690.93496 | I15: =G15+H15 -> 690.93496 | J15: Maintenance | Q15: 426 | R15: G&A - Fines and penalties | S15: Overhead | T15: 701.07 | U15: 892.54624 | V15: =VLOOKUP(Q15,$A$3:$A$63,1,0) -> 426
A16: 433 | B16: G&A - Insurance | C16: Overhead | D16: =VLOOKUP(A16,$Q$4:$U$67,4,0) -> 1545 | F16: =D16+E16 -> 1545 | G16: =VLOOKUP(A16,$Q$4:$U$67,5,0) -> 1966.9704 | I16: =G16+H16 -> 1966.9704 | J16: Insurance | Q16: 429 | R16: G&A - Office Equipment And Miscellaneous | S16: Overhead | T16: 542.71 | U16: 690.93496 | V16: =VLOOKUP(Q16,$A$3:$A$63,1,0) -> 429
A17: 437 | B17: Finance - Interest | C17: Overhead | D17: =VLOOKUP(A17,$Q$4:$U$67,4,0) -> -173.43 | F17: =D17+E17 -> -173.43 | G17: =VLOOKUP(A17,$Q$4:$U$67,5,0) -> -220.7972 | I17: =G17+H17 -> -220.7972 | J17: Financial expenses (income) | Q17: 433 | R17: G&A - Insurance | S17: Overhead | T17: 1545 | U17: 1966.9704 | V17: =VLOOKUP(Q17,$A$3:$A$63,1,0) -> 433
... A21: 477 | B21: S&M - Base Salary | C21: Overhead | D21: =VLOOKUP(A21,$Q$4:$U$67,4,0) -> 299089.7 | F21: =D21+E21 -> 299089.7 | G21: =VLOOKUP(A21,$Q$4:$U$67,5,0) -> 380777.08 | I21: =G21+H21 -> 380777.08 | J21: Salaries and social benefits - R&D | Q21: 469 | R21: G&A - Rent Expenses | S21: Overhead | T21: 13371.92 | U21: 17024.059 | V21: =VLOOKUP(Q21,$A$3:$A$63,1,0) -> 469
A22: 477a | B22: G&A - Base Salary | C22: Overhead | D22: =VLOOKUP(A22,$Q$4:$U$67,4,0) -> 105000 | F22: =D22+E22 -> 105000 | G22: =VLOOKUP(A22,$Q$4:$U$67,5,0) -> 133677.6 | I22: =G22+H22 -> 133677.6 | J22: Salaries and social benefits - G&A | Q22: 477 | R22: S&M - Base Salary | S22: Overhead | T22: 299089.7 | U22: 380777.08 | V22: =VLOOKUP(Q22,$A$3:$A$63,1,0) -> 477
A23: 477b | B23: S&M - Vacation Expenses | C23: Overhead | D23: =VLOOKUP(A23,$Q$4:$U$67,4,0) -> 509.28 | F23: =D23+E23 -> 509.28 | G23: =VLOOKUP(A23,$Q$4:$U$67,5,0) -> 648.37455 | I23: =G23+H23 -> 648.37455 | J23: Salaries and social benefits - R&D | Q23: 477a | R23: G&A - Base Salary | S23: Overhead | T23: 105000 | U23: 133677.6 | V23: =VLOOKUP(Q23,$A$3:$A$63,1,0) -> 477a
A24: 479 | B24: S&M - Employer Taxes | C24: Overhead | D24: =VLOOKUP(A24,$Q$4:$U$67,4,0) -> 37717.97 | F24: =D24+E24 -> 37717.97 | G24: =VLOOKUP(A24,$Q$4:$U$67,5,0) -> 48019.502 | I24: =G24+H24 -> 48019.502 | J24: Salaries and social benefits - R&D | Q24: 477b | R24: S&M - Vacation Expenses | S24: Overhead | T24: 509.28 | U24: 648.37455 | V24: =VLOOKUP(Q24,$A$3:$A$63,1,0) -> 477b
A25: 479a | B25: G&A - National Insurance | C25: Overhead | D25: =VLOOKUP(A25,$Q$4:$U$67,4,0) -> 13287.02 | F25: =D25+E25 -> 13287.02 | G25: =VLOOKUP(A25,$Q$4:$U$67,5,0) -> 16915.971 | I25: =G25+H25 -> 16915.971 | J25: Salaries and social benefits - G&A | Q25: 479 | R25: S&M - Employer Taxes | S25: Overhead | T25: 37717.97 | U25: 48019.502 | V25: =VLOOKUP(Q25,$A$3:$A$63,1,0) -> 479
A26: 481 | B26: Recruitment | C26: Overhead | D26: =VLOOKUP(A26,$Q$4:$U$67,4,0) -> 0 | F26: =D26+E26 -> 0 | G26: =VLOOKUP(A26,$Q$4:$U$67,5,0) -> 0 | I26: =G26+H26 -> 0 | Q26: 479a | R26: G&A - National Insurance | S26: Overhead | T26: 13287.02 | U26: 16915.971 | V26: =VLOOKUP(Q26,$A$3:$A$63,1,0) -> 479a
A27: 482 | B27: S&M - Pension | C27: Overhead | D27: =VLOOKUP(A27,$Q$4:$U$67,4,0) -> 8932.88 | F27: =D27+E27 -> 8932.88 | G27: =VLOOKUP(A27,$Q$4:$U$67,5,0) -> 11372.628 | I27: =G27+H27 -> 11372.628 | J27: Salaries and social benefits - R&D | Q27: 481 | R27: Recruitment | S27: Overhead | T27: 0 | U27: 0 | V27: =VLOOKUP(Q27,$A$3:$A$63,1,0) -> 481
A28: 482a | B28: G&A - Pension | C28: Overhead | D28: =VLOOKUP(A28,$Q$4:$U$67,4,0) -> 3113.65 | F28: =D28+E28 -> 3113.65 | G28: =VLOOKUP(A28,$Q$4:$U$67,5,0) -> 3964.0501 | I28: =G28+H28 -> 3964.0501 | J28: Salaries and social benefits - G&A | Q28: 482 | R28: S&M - Pension | S28: Overhead | T28: 8932.88 | U28: 11372.628 | V28: =VLOOKUP(Q28,$A$3:$A$63,1,0) -> 482
A29: 483 | B29: Medical Insurance | C29: Overhead | D29: =VLOOKUP(A29,$Q$4:$U$67,4,0) -> 3766.14 | F29: =D29+E29 -> 3766.14 | G29: =VLOOKUP(A29,$Q$4:$U$67,5,0) -> 4794.7482 | I29: =G29+H29 -> 4794.7482 | J29: Salaries and social benefits - G&A | M29: זה בטעות לא נכנס לחישוב של COST + לא מהותי | Q29: 482a | R29: G&A - Pension | S29: Overhead | T29: 3113.65 | U29: 3964.0501 | V29: =VLOOKUP(Q29,$A$3:$A$63,1,0) -> 482a
A30: 485 | B30: Subscriptions | C30: Overhead | D30: =VLOOKUP(A30,$Q$4:$U$67,4,0) -> 3429.08 | F30: =D30+E30 -> 3429.08 | G30: =VLOOKUP(A30,$Q$4:$U$67,5,0) -> 4365.6303 | I30: =G30+H30 -> 4365.6303 | J30: Maintenance | Q30: 483 | R30: Medical Insurance | S30: Overhead | T30: 3766.14 | U30: 4794.7482 | V30: =VLOOKUP(Q30,$A$3:$A$63,1,0) -> 483
A31: 486 | B31: G&A - Refreshments | C31: Overhead | D31: =VLOOKUP(A31,$Q$4:$U$67,4,0) -> 470.4 | F31: =D31+E31 -> 470.4 | G31: =VLOOKUP(A31,$Q$4:$U$67,5,0) -> 598.87565 | I31: =G31+H31 -> 598.87565 | J31: Welfare | Q31: 485 | R31: Subscriptions | S31: Overhead | T31: 3429.08 | U31: 4365.6303 | V31: =VLOOKUP(Q31,$A$3:$A$63,1,0) -> 485
A32: 493 | B32: G&A - Travel | C32: Overhead | D32: =VLOOKUP(A32,$Q$4:$U$67,4,0) -> 2727.52 | F32: =D32+E32 -> 2727.52 | G32: =VLOOKUP(A32,$Q$4:$U$67,5,0) -> 3472.4603 | I32: =G32+H32 -> 3472.4603 | J32: Other - G&A | Q32: 486 | R32: G&A - Refreshments | S32: Overhead | T32: 470.4 | U32: 598.87565 | V32: =VLOOKUP(Q32,$A$3:$A$63,1,0) -> 486
A33: 494 | B33: S&M - Travel Abroad | C33: Overhead | D33: =VLOOKUP(A33,$Q$4:$U$67,4,0) -> 1952.52 | F33: =D33+E33 -> 1952.52 | G33: =VLOOKUP(A33,$Q$4:$U$67,5,0) -> 2485.7923 | I33: =G33+H33 -> 2485.7923 | J33: Travel | Q33: 493 | R33: G&A - Travel | S33: Overhead | T33: 2727.52 | U33: 3472.4603 | V33: =VLOOKUP(Q33,$A$3:$A$63,1,0) -> 493
A34: 494a | B34: G&A - Travel Abroad | C34: Overhead | D34: =VLOOKUP(A34,$Q$4:$U$67,4,0) -> 3678.11 | F34: =D34+E34 -> 3678.11 | G34: =VLOOKUP(A34,$Q$4:$U$67,5,0) -> 4682.6754 | I34: =G34+H34 -> 4682.6754 | J34: Travel G&A | Q34: 494 | R34: S&M - Travel Abroad | S34: Overhead | T34: 1952.52 | U34: 2485.7923 | V34: =VLOOKUP(Q34,$A$3:$A$63,1,0) -> 494
A35: 497 | B35: Bank Revaluations | C35: Expense | D35: =VLOOKUP(A35,$Q$4:$U$67,4,0) -> -2944.96 | F35: =D35+E35 -> -2944.96 | G35: =VLOOKUP(A35,$Q$4:$U$67,5,0) -> -3749.2875 | I35: =G35+H35 -> -3749.2875 | J35: Other - G&A | Q35: 494a | R35: G&A - Travel Abroad | S35: Overhead | T35: 3678.11 | U35: 4682.6754 | V35: =VLOOKUP(Q35,$A$3:$A$63,1,0) -> 494a
A36: 498 | B36: Unrealised Currency Gains | C36: Expense | D36: =VLOOKUP(A36,$Q$4:$U$67,4,0) -> 17.1 | F36: =D36+E36 -> 17.1 | G36: =VLOOKUP(A36,$Q$4:$U$67,5,0) -> 29376.728 | I36: =G36+H36 -> 29376.728 | J36: Financial expenses (income) | Q36: 497 | R36: Bank Revaluations | S36: Expense | T36: -2944.96 | U36: -3749.2875 | V36: =VLOOKUP(Q36,$A$3:$A$63,1,0) -> 497
A37: 499 | B37: Finance - Exchange Rate Differences | C37: Expense | D37: =VLOOKUP(A37,$Q$4:$U$67,4,0) -> -6068.91 | F37: =D37+E37 -> -6068.91 | G37: =VLOOKUP(A37,$Q$4:$U$67,5,0) -> -7726.4507 | I37: =G37+H37 -> -7726.4507 | J37: Financial expenses (income) | Q37: 498 | R37: Unrealised Currency Gains | S37: Expense | T37: 17.1 | U37: 29376.728 | V37: =VLOOKUP(Q37,$A$3:$A$63,1,0) -> 498
A38: Deposit account- 0401 | B38: Deposit Account | C38: Bank | D38: =VLOOKUP(A38,$Q$4:$U$67,4,0) -> 241139.88 | F38: =D38+E38 -> 241139.88 | G38: =VLOOKUP(A38,$Q$4:$U$67,5,0) -> 307000 | I38: =G38+H38 -> 307000 | J38: Cash and cash equivalents | Q38: 499 | R38: Finance - Exchange Rate Differences | S38: Expense | T38: -6068.91 | U38: -7726.4507 | V38: =VLOOKUP(Q38,$A$3:$A$63,1,0) -> 499
A39: Cash Bank Deposits | B39: Cash Bank Deposits | C39: Bank | D39: =VLOOKUP(A39,$Q$4:$U$67,4,0) -> 0 | F39: =D39+E39 -> 0 | G39: =VLOOKUP(A39,$Q$4:$U$67,5,0) -> 0 | I39: =G39+H39 -> 0 | J39: Cash and cash equivalents | K39: Name of the bank | L39: In TB | M39: In the bank | N39: Diffrences | Q39: 500 | R39: Corporation Tax | S39: Overhead | T39: 0 | U39: 0 | V39: =VLOOKUP(Q39,$A$3:$A$63,1,0) -> #N/A
A40: GetCtrl UK Ltd | B40: GetCtrl UK Ltd | C40: Bank | D40: =VLOOKUP(A40,$Q$4:$U$67,4,0) -> 78089.08 | F40: =D40+E40 -> 78089.08 | G40: =VLOOKUP(A40,$Q$4:$U$67,5,0) -> 99416.77 | I40: =G40+H40 -> 99416.77 | J40: Cash and cash equivalents | K40: GetCtrl UK Ltd HSBC GPB | L40: =D40 -> 78089.08 | M40: 78089.08 | N40: =L40-M40 -> 0 | Q40: Deposit Account | R40: Deposit Account | S40: Bank | T40: 0 | U40: 0 | V40: =VLOOKUP(Q40,$A$3:$A$63,1,0) -> #N/A
A41: Wise Bank USD | B41: Wise Bank USD | C41: Bank | D41: =VLOOKUP(A41,$Q$4:$U$67,4,0) -> 21.17 | F41: =D41+E41 -> 21.17 | G41: =VLOOKUP(A41,$Q$4:$U$67,5,0) -> 26.95195 | I41: =G41+H41 -> 26.95195 | J41: Cash and cash equivalents | K41: Wise Bank USD | L41: =G41 -> 26.95195 | M41: 26.95 | N41: =L41-M41 -> 0.0019504 | Q41: Intercompany USA. | R41: Intercompany USA. | S41: Bank | T41: -286260.37 | U41: -364443.8 | V41: =VLOOKUP(Q41,$A$3:$A$63,1,0) -> Intercompany USA.
A42: Wise Bank GBP | B42: Wise Bank GBP | C42: Bank | D42: =VLOOKUP(A42,$Q$4:$U$67,4,0) -> 4496.56 | F42: =D42+E42 -> 4496.56 | G42: =VLOOKUP(A42,$Q$4:$U$67,5,0) -> 5724.6605 | I42: =G42+H42 -> 5724.6605 | J42: Cash and cash equivalents | K42: Wise Bank GBP | L42: =D42 -> 4496.56 | M42: 4496.56 | N42: =L42-M42 -> 0 | Q42: Cash Bank Deposits | R42: Cash Bank Deposits | S42: Bank | T42: 0 | U42: 0 | V42: =VLOOKUP(Q42,$A$3:$A$63,1,0) -> Cash Bank Deposits
A43: SVB GBP 20251475 | B43: SVB GBP 20251475 | C43: Bank | D43: =VLOOKUP(A43,$Q$4:$U$67,4,0) -> 0 | F43: =D43+E43 -> 0 | G43: =VLOOKUP(A43,$Q$4:$U$67,5,0) -> 0 | I43: =G43+H43 -> 0 | J43: Cash and cash equivalents | K43: SVB GBP 20251475 | N43: =L43-M43 -> 0 | Q43: GetCtrl UK Ltd | R43: GetCtrl UK Ltd | S43: Bank | T43: 78089.08 | U43: 99416.77 | V43: =VLOOKUP(Q43,$A$3:$A$63,1,0) -> GetCtrl UK Ltd
...

Sheet TB US
B1: TB us 31.12.23
B3: 102 · Cash-Operating | C3: =1420500.3-1400000+C36-75021-8797.5-46442.34 -> 0 | D3: Cash and cash equivalents
B4: 125 · Due from Getctrl Ltd Israel Sub | C4: =6635139.34+1400000 -> 8035139.3 | D4: Related party
B5: 126 · Due from Getctrl UK Ltd | C5: =232986.58+75021+46442.34+10000 -> 364449.92 | D5: Related party
B6: 400 · Capital Stock | C6: =-8345043.34-C36-10000 -> -8464803.9 | D6: Additional paid-in capital | M6: סכום של 10 אלף השקעה התקבל ב 31/5/23 בח WISE וUSD חשבון ששייך לחברה באנגליה
B7: 410 · Equity Expenses | C7: =55000 -> 55000 | D7: Equity expenses
B8: Accumulated deficit | C8: 1417.12 | D8: Accumulated deficit | H8: מתאים לדוח שנה קודמת
B9: 849 · Legal and Accounting | C9: =-L25 -> 5862.5 | D9: Legal & Professional Services
B10: 863 · Outside Service | C10: =-L15 -> 1900 | D10: Legal & Professional Services
B11: 882 · State Franchise Tax | C11: =-L23 -> 1045 | D11: Other - G&A | G11: 8797.5
B12: 809 · Bank Charges | C12: =-L19 -> -10 | D12: Other - G&A
C13: =SUM(C3:C12) -> 8.1854523e-10 | L13: תנועות בבנק
L14: 1420500.3
L15: -1900
L16: 17501.09
L17: -75021
F18: השקעות שבוצעו השנה בבנק | L18: 14970
L19: 10
L20: 19999.06
C21: 490000 | D21: INVEST | L21: 24990.1
C22: 147977 | D22: INVEST | L22: 12301.23
C23: 409463.33 | D23: INVEST | L23: -1045
C24: 3800000.1 | D24: INVEST | L24: 19999.06
C25: 10002.03 | D25: INVEST | L25: -5862.5
L26: -1400000
L27: -46442.34
L28: =SUM(L14:L27) -> 3.2014214e-10
F29: השקעות ב 2023
C30: 17501.09
C31: 14970
C32: 19999.06
C33: 24990.1
C34: 12301.23
C35: 19999.06
C36: =SUM(C30:C35) -> 109760.54
C38: 10000 | F38: סכום של 10 אלף השקעה התקבל ב 31/5/23 בח WISE וUSD חשבון ששייך לחברה באנגליה
C40: =C36+C38 -> 119760.54

Sheet BS (consolidate)
B6: =Summary!B6 -> GetCtrl LTD
B7: Unaudited Consolidated Managerial Financial Report as of - | J7: =Summary!J7 -> 45291
B8: Balance Sheet (K$)
E11: =$J$7 -> 45291 | F11: =$J$7 -> 45291 | G11: =$J$7 -> 45291 | H11: AJE | I11: =$J$7 -> 45291 | N11: 45199 | O11: 45107 | P11: 45016 | Q11: 44926
E12: Israel | F12: UK | G12: US | I12: Consolidated | N12: Consolidated | O12: Consolidated | P12: Consolidated | Q12: Consolidated
E13: USD | F13: USD | G13: USD | I13: USD | N13: USD | O13: USD | P13: USD | Q13: USD
B14: ASSETS
C16: Current Assets
D17: Cash and cash equivalents | E17: =SUMIF(TB!$J$2:$J$121,D17,TB!$I$2:$I121) -> 771696.05 | F17: =SUMIF('TB UK'!$J$2:$J$63,D17,'TB UK'!$I$2:$I$64) -> 413195.17 | G17: ='TB US'!C3 -> 0 | I17: =SUM(E17:G17) -> 1184891.2 | N17: 1661133.9 | O17: 2268299.2 | P17: 2947698.8 | Q17: 3536756.1
D18: Accounts receivable | E18: =SUMIF(TB!$J$2:$J$121,D18,TB!$I$2:$I122) -> 0 | F18: =SUMIF('TB UK'!$J$2:$J$63,D18,'TB UK'!$I$2:$I$64) -> 0 | I18: =SUM(E18:G18) -> 0 | N18: 0 | O18: 0 | P18: 0 | Q18: 0
D19: Prepaid expenses | E19: =SUMIF(TB!$J$2:$J$121,D19,TB!$I$2:$I123) -> 0 | F19: =SUMIF('TB UK'!$J$2:$J$63,D19,'TB UK'!$I$2:$I$64) -> 8819.246 | I19: =SUM(E19:G19) -> 8819.246 | N19: 8450.8538 | O19: 0 | P19: 0 | Q19: 0
