Workbook

Sheet BS USD
C1: Wematch.live
C2: USD
E5: EQD | F5: WUS- LLC | G5: WIR | H5: WSF- LTD [IL] | I5: WSF (UK) | J5: WUS- INC | K5: R&D | L5: WTSE | M5: Elimination | N5: Elimination US | P5: JE'S | Q5: Total
E6: =+'BS ILS'!$E$6 -> 31.12.2023 | F6: =+'BS ILS'!$E$6 -> 31.12.2023 | G6: =+'BS ILS'!$E$6 -> 31.12.2023 | H6: =+'BS ILS'!$E$6 -> 31.12.2023 | I6: =+'BS ILS'!$E$6 -> 31.12.2023 | J6: =+'BS ILS'!$E$6 -> 31.12.2023 | K6: =+'BS ILS'!$E$6 -> 31.12.2023 | L6: =+'BS ILS'!$E$6 -> 31.12.2023 | Q6: =+'BS ILS'!$E$6 -> 31.12.2023 | S6: in 000' | U6: NOTE
B7: INDEX
C8: Assets | S8: =+Q8/1000 -> 0
C10: Current Assets: | S10: =+Q10/1000 -> 0
B11: 10 | C11: Cash and cash equivalent | E11: =+SUMIF('Full BS-USD'!$M:$M,B11,'Full BS-USD'!$D:$D) -> 20694.27 | F11: =+SUMIF('Full BS-USD'!$M:$M,B11,'Full BS-USD'!$G:$G) -> 1183093.2 | G11: =+SUMIF('Full BS-USD'!$M:$M,B11,'Full BS-USD'!$E:$E) -> 21.14 | H11: =+SUMIF('Full BS-USD'!$M:$M,B11,'Full BS-USD'!$F:$F) -> 299.37 | I11: =+SUMIF('Full BS-USD'!$M:$M,B11,'Full BS-USD'!$H:$H) -> 195757.56 | J11: =+SUMIF('Full BS-USD'!$M:$M,B11,'Full BS-USD'!$I:$I) -> 490094.22 | K11: =+SUMIF('Full BS-USD'!$M:$M,B11,'Full BS-USD'!$J:$J) -> 3193193.2 | L11: =+SUMIF('Full BS-USD'!$M:$M,B11,'Full BS-USD'!$K:$K) -> 208398.82 | M11: =+SUMIF('Full BS-USD'!$M:$M,B11,'Full BS-USD'!$B:$B) -> 0 | N11: =+SUMIF('Full BS-USD'!$M:$M,B11,'Full BS-USD'!$C:$C) -> 0 | Q11: =+SUMIF('Full BS-USD'!$M:$M,B11,'Full BS-USD'!$L:$L) -> 5291551.8 | R11: =+Q11-SUM(E11:N11) -> 0 | S11: =+ROUND((Q11/1000),0) -> 5292
B12: 11 | C12: Short term restricted deposits | E12: =+SUMIF('Full BS-USD'!$M:$M,B12,'Full BS-USD'!$D:$D) -> 0 | F12: =+SUMIF('Full BS-USD'!$M:$M,B12,'Full BS-USD'!$G:$G) -> 0 | G12: =+SUMIF('Full BS-USD'!$M:$M,B12,'Full BS-USD'!$E:$E) -> 0 | H12: =+SUMIF('Full BS-USD'!$M:$M,B12,'Full BS-USD'!$F:$F) -> 0 | I12: =+SUMIF('Full BS-USD'!$M:$M,B12,'Full BS-USD'!$H:$H) -> 0 | J12: =+SUMIF('Full BS-USD'!$M:$M,B12,'Full BS-USD'!$I:$I) -> 0 | K12: =+SUMIF('Full BS-USD'!$M:$M,B12,'Full BS-USD'!$J:$J) -> 7718871.7 | L12: =+SUMIF('Full BS-USD'!$M:$M,B12,'Full BS-USD'!$K:$K) -> 607156 | M12: =+SUMIF('Full BS-USD'!$M:$M,B12,'Full BS-USD'!$B:$B) -> 0 | N12: =+SUMIF('Full BS-USD'!$M:$M,B12,'Full BS-USD'!$C:$C) -> 0 | Q12: =+SUMIF('Full BS-USD'!$M:$M,B12,'Full BS-USD'!$L:$L) -> 8326027.7 | R12: =+Q12-SUM(E12:N12) -> 0 | S12: =+ROUND((Q12/1000),0) -> 8326
B13: 12 | C13: Trade recievables | E13: =+SUMIF('Full BS-USD'!$M:$M,B13,'Full BS-USD'!$D:$D) -> 0 | F13: =+SUMIF('Full BS-USD'!$M:$M,B13,'Full BS-USD'!$G:$G) -> 0 | G13: =+SUMIF('Full BS-USD'!$M:$M,B13,'Full BS-USD'!$E:$E) -> 0 | H13: =+SUMIF('Full BS-USD'!$M:$M,B13,'Full BS-USD'!$F:$F) -> 0 | I13: =+SUMIF('Full BS-USD'!$M:$M,B13,'Full BS-USD'!$H:$H) -> 0 | J13: =+SUMIF('Full BS-USD'!$M:$M,B13,'Full BS-USD'!$I:$I) -> 0 | K13: =+SUMIF('Full BS-USD'!$M:$M,B13,'Full BS-USD'!$J:$J) -> 658882.12 | L13: =+SUMIF('Full BS-USD'!$M:$M,B13,'Full BS-USD'!$K:$K) -> 0 | M13: =+SUMIF('Full BS-USD'!$M:$M,B13,'Full BS-USD'!$B:$B) -> 0 | N13: =+SUMIF('Full BS-USD'!$M:$M,B13,'Full BS-USD'!$C:$C) -> 0 | Q13: =+SUMIF('Full BS-USD'!$M:$M,B13,'Full BS-USD'!$L:$L) -> 658882.12 | R13: =+Q13-SUM(E13:N13) -> 0 | S13: =+ROUND((Q13/1000),0) -> 659 | U13: =+'NOTES-Conso'!B5 -> 3
B14: 13 | C14: other recievables and prepaid expenses | E14: =+SUMIF('Full BS-USD'!$M:$M,B14,'Full BS-USD'!$D:$D) -> 4101.54 | F14: =+SUMIF('Full BS-USD'!$M:$M,B14,'Full BS-USD'!$G:$G) -> 1359.83 | G14: =+SUMIF('Full BS-USD'!$M:$M,B14,'Full BS-USD'!$E:$E) -> 491.94 | H14: =+SUMIF('Full BS-USD'!$M:$M,B14,'Full BS-USD'!$F:$F) -> 48261.82 | I14: =+SUMIF('Full BS-USD'!$M:$M,B14,'Full BS-USD'!$H:$H) -> 2433115 | J14: =+SUMIF('Full BS-USD'!$M:$M,B14,'Full BS-USD'!$I:$I) -> 546686.67 | K14: =+SUMIF('Full BS-USD'!$M:$M,B14,'Full BS-USD'!$J:$J) -> 5432383.5 | L14: =+SUMIF('Full BS-USD'!$M:$M,B14,'Full BS-USD'!$K:$K) -> 975458.86 | M14: =+SUMIF('Full BS-USD'!$M:$M,B14,'Full BS-USD'!$B:$B) -> -8791437.7 | N14: =+SUMIF('Full BS-USD'!$M:$M,B14,'Full BS-USD'!$C:$C) -> 8338.78 | Q14: =+SUMIF('Full BS-USD'!$M:$M,B14,'Full BS-USD'!$L:$L) -> 658760.23 | R14: =+Q14-SUM(E14:N14) -> -1.3969839e-09 | S14: =+ROUND((Q14/1000),0) -> 659 | U14: =+'NOTES-Conso'!B10 -> 4
R15: =+Q15-SUM(E15:N15) -> 0 | S15: =+Q15/1000 -> 0
C16: Total cerrent assets | E16: =+SUM(E11:E14) -> 24795.81 | F16: =+SUM(F11:F14) -> 1184453 | G16: =+SUM(G11:G14) -> 513.08 | H16: =+SUM(H11:H14) -> 48561.19 | I16: =+SUM(I11:I14) -> 2628872.6 | J16: =+SUM(J11:J14) -> 1036780.9 | K16: =+SUM(K11:K14) -> 17003331 | L16: =+SUM(L11:L14) -> 1791013.7 | ... N16: =+SUM(N11:N14) -> 8338.78 | Q16: =+SUM(Q11:Q14) -> 14935222 | R16: =+Q16-SUM(E16:N16) -> 0 | S16: =+SUM(S11:S14) -> 14936
R17: =+Q17-SUM(E17:N17) -> 0 | S17: =+Q17/1000 -> 0
R18: =+Q18-SUM(E18:N18) -> 0
C19: Long-Term assets: | R19: =+Q19-SUM(E19:N19) -> 0
B20: 14 | C20: loans to employees | E20: =+SUMIF('Full BS-USD'!$M:$M,B20,'Full BS-USD'!$D:$D) -> 38487.03 | F20: =+SUMIF('Full BS-USD'!$M:$M,B20,'Full BS-USD'!$G:$G) -> 0 | G20: =+SUMIF('Full BS-USD'!$M:$M,B20,'Full BS-USD'!$E:$E) -> 0 | H20: =+SUMIF('Full BS-USD'!$M:$M,B20,'Full BS-USD'!$F:$F) -> 0 | I20: =+SUMIF('Full BS-USD'!$M:$M,B20,'Full BS-USD'!$H:$H) -> 0 | J20: =+SUMIF('Full BS-USD'!$M:$M,B20,'Full BS-USD'!$I:$I) -> 0 | K20: =+SUMIF('Full BS-USD'!$M:$M,B20,'Full BS-USD'!$J:$J) -> 261263.83 | L20: =+SUMIF('Full BS-USD'!$M:$M,B20,'Full BS-USD'!$K:$K) -> 0 | M20: =+SUMIF('Full BS-USD'!$M:$M,B20,'Full BS-USD'!$B:$B) -> -261263.83 | N20: =+SUMIF('Full BS-USD'!$M:$M,B20,'Full BS-USD'!$C:$C) -> 0 | Q20: =+SUMIF('Full BS-USD'!$M:$M,B20,'Full BS-USD'!$L:$L) -> 38487.03 | R20: =+Q20-SUM(E20:N20) -> 0 | S20: =+ROUND((Q20/1000),0) -> 38
B21: 15 | C21: property and equipment | E21: =+SUMIF('Full BS-USD'!$M:$M,B21,'Full BS-USD'!$D:$D) -> 0 | F21: =+SUMIF('Full BS-USD'!$M:$M,B21,'Full BS-USD'!$G:$G) -> 279.12 | G21: =+SUMIF('Full BS-USD'!$M:$M,B21,'Full BS-USD'!$E:$E) -> 0 | H21: =+SUMIF('Full BS-USD'!$M:$M,B21,'Full BS-USD'!$F:$F) -> 0 | I21: =+SUMIF('Full BS-USD'!$M:$M,B21,'Full BS-USD'!$H:$H) -> 46935.5 | J21: =+SUMIF('Full BS-USD'!$M:$M,B21,'Full BS-USD'!$I:$I) -> 4503.67 | K21: =+SUMIF('Full BS-USD'!$M:$M,B21,'Full BS-USD'!$J:$J) -> 53053.19 | L21: =+SUMIF('Full BS-USD'!$M:$M,B21,'Full BS-USD'!$K:$K) -> 16549.81 | M21: =+SUMIF('Full BS-USD'!$M:$M,B21,'Full BS-USD'!$B:$B) -> 0 | N21: =+SUMIF('Full BS-USD'!$M:$M,B21,'Full BS-USD'!$C:$C) -> 0 | Q21: =+SUMIF('Full BS-USD'!$M:$M,B21,'Full BS-USD'!$L:$L) -> 121321.29 | R21: =+Q21-SUM(E21:N21) -> 0 | S21: =+ROUND((Q21/1000),0) -> 121 | U21: 5
R22: =+Q22-SUM(E22:N22) -> 0
R23: =+Q23-SUM(E23:N23) -> 0
C24: Total Long-term assets | E24: =+E20+E21 -> 38487.03 | F24: =+F20+F21 -> 279.12 | G24: =+G20+G21 -> 0 | H24: =+H20+H21 -> 0 | I24: =+I20+I21 -> 46935.5 | J24: =+J20+J21 -> 4503.67 | K24: =+K20+K21 -> 314317.02 | L24: =+L20+L21 -> 16549.81 | ... N24: =+N20+N21 -> 0 | Q24: =+Q20+Q21 -> 159808.32 | R24: =+Q24-SUM(E24:N24) -> 0 | S24: =+ROUND(Q24/1000,0) -> 160
R25: =+Q25-SUM(E25:N25) -> 0
R26: =+Q26-SUM(E26:N26) -> 0
C27: Total assets | E27: =+E24+E16 -> 63282.84 | F27: =+F24+F16 -> 1184732.1 | G27: =+G24+G16 -> 513.08 | H27: =+H24+H16 -> 48561.19 | I27: =+I24+I16 -> 2675808.1 | J27: =+J24+J16 -> 1041284.6 | K27: =+K24+K16 -> 17317648 | L27: =+L24+L16 -> 1807563.5 | ... N27: =+N24+N16 -> 8338.78 | Q27: =+Q24+Q16 -> 15095030 | R27: =+Q27-SUM(E27:N27) -> 0 | S27: =+S24+S16 -> 15096
R28: =+Q28-SUM(E28:N28) -> 0
R29: =+Q29-SUM(E29:N29) -> 0 | S29: =+Q29/1000 -> 0
C30: Liabilities and shareholders' equity | R30: =+Q30-SUM(E30:N30) -> 0
R31: =+Q31-SUM(E31:N31) -> 0
C32: Current Liabilities: | R32: =+Q32-SUM(E32:N32) -> 0
R33: =+Q33-SUM(E33:N33) -> 0
B34: 16 | C34: Trade payables | E34: =+SUMIF('Full BS-USD'!$M:$M,B34,'Full BS-USD'!$D:$D) -> 0 | F34: =+SUMIF('Full BS-USD'!$M:$M,B34,'Full BS-USD'!$G:$G)+'Full BS-USD'!G157 -> 8115.99 | G34: =+SUMIF('Full BS-USD'!$M:$M,B34,'Full BS-USD'!$E:$E)+'Full BS-USD'!E157 -> 0 | H34: =+SUMIF('Full BS-USD'!$M:$M,B34,'Full BS-USD'!$F:$F)+'Full BS-USD'!F157 -> 0 | I34: =+SUMIF('Full BS-USD'!$M:$M,B34,'Full BS-USD'!$H:$H)+'Full BS-USD'!H157 -> 30952.4 | J34: =+SUMIF('Full BS-USD'!$M:$M,B34,'Full BS-USD'!$I:$I)+'Full BS-USD'!I157 -> 5746.28 | K34: =+SUMIF('Full BS-USD'!$M:$M,B34,'Full BS-USD'!$J:$J)+'Full BS-USD'!J157 -> 93784.12 | L34: =+SUMIF('Full BS-USD'!$M:$M,B34,'Full BS-USD'!$K:$K)+'Full BS-USD'!K157 -> 28738.66 | M34: =+SUMIF('Full BS-USD'!$M:$M,B34,'Full BS-USD'!$B:$B)+'Full BS-USD'!B157 -> 0.01 | N34: =+SUMIF('Full BS-USD'!$M:$M,B34,'Full BS-USD'!$C:$C) -> 0 | Q34: =+SUMIF('Full BS-USD'!$M:$M,B34,'Full BS-USD'!$L:$L)+'Full BS-USD'!L157 -> 167337.46 | R34: =+Q34-SUM(E34:N34) -> 0 | S34: =+ROUND((Q34/1000),0) -> 167
B35: 17 | C35: Accrued expenses and other liabilities | E35: =+SUMIF('Full BS-USD'!$M:$M,B35,'Full BS-USD'!$D:$D) -> 320.38 | F35: =+SUMIF('Full BS-USD'!$M:$M,B35,'Full BS-USD'!$G:$G) -> 21787.94 | G35: =+SUMIF('Full BS-USD'!$M:$M,B35,'Full BS-USD'!$E:$E) -> 320.38 | H35: =+SUMIF('Full BS-USD'!$M:$M,B35,'Full BS-USD'!$F:$F) -> 8858.12 | I35: =+SUMIF('Full BS-USD'!$M:$M,B35,'Full BS-USD'!$H:$H) -> 2128996.9 | J35: =+SUMIF('Full BS-USD'!$M:$M,B35,'Full BS-USD'!$I:$I) -> 346957.74 | K35: =+SUMIF('Full BS-USD'!$M:$M,B35,'Full BS-USD'!$J:$J) -> 4359939.4 | L35: =+SUMIF('Full BS-USD'!$M:$M,B35,'Full BS-USD'!$K:$K) -> 1432154.3 | M35: =+SUMIF('Full BS-USD'!$M:$M,B35,'Full BS-USD'!$B:$B) -> -8789619.4 | N35: =+SUMIF('Full BS-USD'!$M:$M,B35,'Full BS-USD'!$C:$C) -> 1608338.8 | Q35: =+SUMIF('Full BS-USD'!$M:$M,B35,'Full BS-USD'!$L:$L) -> 1118054.6 | R35: =+Q35-SUM(E35:N35) -> 0 | S35: =+ROUND((Q35/1000),0) -> 1118 | U35: =+'NOTES-Conso'!B27 -> 6
R36: =+Q36-SUM(E36:N36) -> 0
C37: Total current liabilities | E37: =+E35+E34 -> 320.38 | F37: =+F35+F34 -> 29903.93 | G37: =+G35+G34 -> 320.38 | H37: =+H35+H34 -> 8858.12 | I37: =+I35+I34 -> 2159949.3 | J37: =+J35+J34 -> 352704.02 | K37: =+K35+K34 -> 4453723.5 | L37: =+L35+L34 -> 1460893 | ... N37: =+N35+N34 -> 1608338.8 | Q37: =+Q35+Q34 -> 1285392 | R37: =+Q37-SUM(E37:N37) -> 0 | S37: =+S35+S34 -> 1285
R38: =+Q38-SUM(E38:N38) -> 0
R39: =+Q39-SUM(E39:N39) -> 0
C40: Non current Liabilities: | R40: =+Q40-SUM(E40:N40) -> 0
R41: =+Q41-SUM(E41:N41) -> 0
B42: 18 | C42: Long-Term liabilities: | E42: =+SUMIF('Full BS-USD'!$M:$M,B42,'Full BS-USD'!$D:$D) -> 0 | F42: =+SUMIF('Full BS-USD'!$M:$M,B42,'Full BS-USD'!$G:$G) -> 0 | G42: =+SUMIF('Full BS-USD'!$M:$M,B42,'Full BS-USD'!$E:$E) -> 261263.83 | H42: =+SUMIF('Full BS-USD'!$M:$M,B42,'Full BS-USD'!$F:$F) -> 0 | I42: =+SUMIF('Full BS-USD'!$M:$M,B42,'Full BS-USD'!$H:$H) -> 0 | J42: =+SUMIF('Full BS-USD'!$M:$M,B42,'Full BS-USD'!$I:$I) -> 0 | K42: =+SUMIF('Full BS-USD'!$M:$M,B42,'Full BS-USD'!$J:$J) -> 44955.43 | L42: =+SUMIF('Full BS-USD'!$M:$M,B42,'Full BS-USD'!$K:$K) -> 50.78 | M42: =+SUMIF('Full BS-USD'!$M:$M,B42,'Full BS-USD'!$B:$B) -> -261263.83 | N42: =+SUMIF('Full BS-USD'!$M:$M,B42,'Full BS-USD'!$C:$C) -> 0 | Q42: =+SUMIF('Full BS-USD'!$M:$M,B42,'Full BS-USD'!$L:$L) -> 45006.21 | R42: =+Q42-SUM(E42:N42) -> 0 | S42: =+ROUND(Q42/1000,0)-1 -> 44
R43: =+Q43-SUM(E43:N43) -> 0
...

Sheet P&L
C1: Wematch.live
C2: USD
B5: INDEX | E5: EQD | F5: WIR | G5: WSF- LTD [IL] | H5: WUS LLC | I5: WSF LTD | J5: WUS INC | K5: R&D | L5: WTSE | N5: Total
E6: =+'P&L ILS'!$E$6 -> 2023 | F6: =+'P&L ILS'!$E$6 -> 2023 | G6: =+'P&L ILS'!$E$6 -> 2023 | H6: =+'P&L ILS'!$E$6 -> 2023 | I6: =+'P&L ILS'!$E$6 -> 2023 | J6: =+'P&L ILS'!$E$6 -> 2023 | K6: =+'P&L ILS'!$E$6 -> 2023 | L6: =+'P&L ILS'!$E$6 -> 2023 | N6: =+'P&L ILS'!$E$6 -> 2023 | P6: in 000' | R6: NOTE
B8: 1 | C8: Revenues | E8: =+SUMIF('Full P&L-USD'!$K:$K,B8,'Full P&L-USD'!$B:$B) -> 0 | F8: =+SUMIF('Full P&L-USD'!$K:$K,B8,'Full P&L-USD'!$C:$C) -> 0 | G8: =+SUMIF('Full P&L-USD'!$K:$K,B8,'Full P&L-USD'!$D:$D) -> 0 | H8: =+SUMIF('Full P&L-USD'!$K:$K,B8,'Full P&L-USD'!$E:$E) -> 0 | I8: =+SUMIF('Full P&L-USD'!$K:$K,B8,'Full P&L-USD'!$F:$F) -> 0 | J8: =+SUMIF('Full P&L-USD'!$K:$K,B8,'Full P&L-USD'!$G:$G) -> 0 | K8: =+SUMIF('Full P&L-USD'!$K:$K,B8,'Full P&L-USD'!$H:$H) -> 9466029.3 | L8: =+SUMIF('Full P&L-USD'!$K:$K,B8,'Full P&L-USD'!$I:$I) -> 0 | N8: =+SUMIF('Full P&L-USD'!$K:$K,B8,'Full P&L-USD'!$J:$J) -> 9466029.3 | O8: =+N8-SUM(E8:L8) -> 0 | P8: =+ROUND(N8/1000,0) -> 9466 | R8: =+'NOTES-Conso'!B50 -> 9
O9: =+N9-SUM(E9:L9) -> 0
B10: 2 | C10: Cost of Revenues | E10: =+SUMIF('Full P&L-USD'!$K:$K,B10,'Full P&L-USD'!$B:$B) -> 0 | F10: =+SUMIF('Full P&L-USD'!$K:$K,B10,'Full P&L-USD'!$C:$C) -> 0 | G10: =+SUMIF('Full P&L-USD'!$K:$K,B10,'Full P&L-USD'!$D:$D) -> 0 | H10: =+SUMIF('Full P&L-USD'!$K:$K,B10,'Full P&L-USD'!$E:$E) -> -71276.44 | I10: =+SUMIF('Full P&L-USD'!$K:$K,B10,'Full P&L-USD'!$F:$F) -> -20466.03 | J10: =+SUMIF('Full P&L-USD'!$K:$K,B10,'Full P&L-USD'!$G:$G) -> -27322.1 | K10: =+SUMIF('Full P&L-USD'!$K:$K,B10,'Full P&L-USD'!$H:$H) -> -2824601.4 | L10: =+SUMIF('Full P&L-USD'!$K:$K,B10,'Full P&L-USD'!$I:$I) -> -133042.18 | N10: =+SUMIF('Full P&L-USD'!$K:$K,B10,'Full P&L-USD'!$J:$J) -> -3076708.1 | O10: =+N10-SUM(E10:L10) -> 0 | P10: =+ROUND(N10/1000,0) -> -3077 | R10: =+'NOTES-Conso'!B59 -> 10
O11: =+N11-SUM(E11:L11) -> 0
B12: 3 | C12: Gross profit | E12: =+E8+E10 -> 0 | F12: =+F8+F10 -> 0 | G12: =+G8+G10 -> 0 | H12: =+H8+H10 -> -71276.44 | I12: =+I8+I10 -> -20466.03 | J12: =+J8+J10 -> -27322.1 | K12: =+K8+K10 -> 6641427.9 | L12: =+L8+L10 -> -133042.18 | N12: =+N8+N10 -> 6389321.2 | O12: =+N12-SUM(E12:L12) -> 0 | P12: =+P8+P10 -> 6389
O13: =+N13-SUM(E13:L13) -> 0
C14: Operating expenses: | O14: =+N14-SUM(E14:L14) -> 0
A15: Total - R&D | B15: 4.1 | C15: R&D | E15: =+SUMIF('Full P&L-USD'!$K:$K,B15,'Full P&L-USD'!$B:$B) -> 0 | F15: =+SUMIF('Full P&L-USD'!$K:$K,B15,'Full P&L-USD'!$C:$C) -> 0 | G15: =+SUMIF('Full P&L-USD'!$K:$K,B15,'Full P&L-USD'!$D:$D) -> 0 | H15: =+SUMIF('Full P&L-USD'!$K:$K,B15,'Full P&L-USD'!$E:$E)+'Full P&L-USD'!E222 -> 8957.16 | I15: =+SUMIF('Full P&L-USD'!$K:$K,B15,'Full P&L-USD'!$F:$F)+'Full P&L-USD'!F222 -> 1513589.8 | J15: =+SUMIF('Full P&L-USD'!$K:$K,B15,'Full P&L-USD'!$G:$G)+'Full P&L-USD'!G222 -> 528752.56 | K15: =+SUMIF('Full P&L-USD'!$K:$K,B15,'Full P&L-USD'!$H:$H)+'Full P&L-USD'!H222 -> 2699383.3 | L15: =+SUMIF('Full P&L-USD'!$K:$K,B15,'Full P&L-USD'!$I:$I)+'Full P&L-USD'!I222 -> 789404.87 | N15: =+'Full P&L-USD'!J405+'Full P&L-USD'!J222 -> 5540087.6 | O15: =+N15-SUM(E15:L15) -> 0 | P15: =+ROUND(N15/1000,0) -> 5540
A16: Total - S&M | B16: 4.2 | C16: S&M | E16: =+SUMIF('Full P&L-USD'!$K:$K,B16,'Full P&L-USD'!$B:$B) -> 0 | F16: =+SUMIF('Full P&L-USD'!$K:$K,B16,'Full P&L-USD'!$C:$C) -> 0 | G16: =+SUMIF('Full P&L-USD'!$K:$K,B16,'Full P&L-USD'!$D:$D) -> 0 | H16: =+SUMIF('Full P&L-USD'!$K:$K,B16,'Full P&L-USD'!$E:$E) -> 281115.73 | I16: =+SUMIF('Full P&L-USD'!$K:$K,B16,'Full P&L-USD'!$F:$F) -> 1391589.7 | J16: =+SUMIF('Full P&L-USD'!$K:$K,B16,'Full P&L-USD'!$G:$G) -> 825110.41 | K16: =+SUMIF('Full P&L-USD'!$K:$K,B16,'Full P&L-USD'!$H:$H) -> 1892920.5 | L16: =+SUMIF('Full P&L-USD'!$K:$K,B16,'Full P&L-USD'!$I:$I) -> 365308.16 | N16: =+'Full P&L-USD'!J581 -> 4756044.5 | O16: =+N16-SUM(E16:L16) -> 0 | P16: =+ROUND(N16/1000,0) -> 4756
A17: Total - G&A | B17: 4.3 | C17: G&A | E17: =+SUMIF('Full P&L-USD'!$K:$K,B17,'Full P&L-USD'!$B:$B) -> 0 | F17: =+SUMIF('Full P&L-USD'!$K:$K,B17,'Full P&L-USD'!$C:$C) -> 0 | G17: =+SUMIF('Full P&L-USD'!$K:$K,B17,'Full P&L-USD'!$D:$D) -> 0 | H17: =+SUMIF('Full P&L-USD'!$K:$K,B17,'Full P&L-USD'!$E:$E) -> 128130.87 | I17: =+SUMIF('Full P&L-USD'!$K:$K,B17,'Full P&L-USD'!$F:$F) -> 1113905.1 | J17: =+SUMIF('Full P&L-USD'!$K:$K,B17,'Full P&L-USD'!$G:$G) -> 741036.55 | K17: =+SUMIF('Full P&L-USD'!$K:$K,B17,'Full P&L-USD'!$H:$H) -> 1411783.6 | L17: =+SUMIF('Full P&L-USD'!$K:$K,B17,'Full P&L-USD'!$I:$I) -> 129771.13 | N17: =+'Full P&L-USD'!J942 -> 3524627.3 | O17: =+N17-SUM(E17:L17)+'Full P&L-USD'!J798 -> 4.6566129e-10 | P17: =+ROUND(N17/1000,0) -> 3525
O18: =+N18-SUM(E18:L18) -> 0
A19: Total Operation Expense | B19: 4 | C19: Total Operatiing Expense | E19: =+SUM(E15:E17) -> 0 | F19: =+SUM(F15:F17) -> 0 | G19: =+SUM(G15:G17) -> 0 | H19: =+SUM(H15:H17) -> 418203.76 | I19: =+SUM(I15:I17) -> 4019084.6 | J19: =+SUM(J15:J17) -> 2094899.5 | K19: =+SUM(K15:K17) -> 6004087.4 | L19: =+SUM(L15:L17) -> 1284484.2 | N19: =+SUM(N15:N17) -> 13820759 | O19: =+N19-SUM(E19:L19) -> 0 | P19: =+SUM(P15:P17) -> 13821
O20: =+N20-SUM(E20:L20) -> 0
C21: Operating Loss | E21: =+E12-E19 -> 0 | F21: =+F12-F19 -> 0 | G21: =+G12-G19 -> 0 | H21: =+H12-H19 -> -489480.2 | I21: =+I12-I19 -> -4039550.6 | J21: =+J12-J19 -> -2122221.6 | K21: =+K12-K19 -> 637340.5 | L21: =+L12-L19 -> -1417526.3 | N21: =+N12-N19 -> -7431438.3 | P21: =+P12-P19 -> -7432
B23: 5 | C23: Earning/(Loss) Before Interest & Tax | E23: =+E12-E19 -> 0 | F23: =+F12-F19 -> 0 | G23: =+G12-G19 -> 0 | H23: =+H12-H19 -> -489480.2 | I23: =+I12-I19 -> -4039550.6 | J23: =+J12-J19 -> -2122221.6 | K23: =+K12-K19 -> 637340.5 | L23: =+L12-L19 -> -1417526.3 | N23: =+N12-N19 -> -7431438.3 | O23: =+N23-SUM(E23:L23) -> 0 | P23: =+P12-P19 -> -7432
O24: =+N24-SUM(E24:L24) -> 0
B25: 6 | C25: Financial expenses, net | E25: =+SUMIF('Full P&L-USD'!$K:$K,B25,'Full P&L-USD'!$B:$B) -> 5.15 | F25: =+SUMIF('Full P&L-USD'!$K:$K,B25,'Full P&L-USD'!$C:$C) -> 9.56 | G25: =+SUMIF('Full P&L-USD'!$K:$K,B25,'Full P&L-USD'!$D:$D) -> -429.43 | H25: =+SUMIF('Full P&L-USD'!$K:$K,B25,'Full P&L-USD'!$E:$E) -> 44408.39 | I25: =+SUMIF('Full P&L-USD'!$K:$K,B25,'Full P&L-USD'!$F:$F) -> 12561.62 | J25: =+SUMIF('Full P&L-USD'!$K:$K,B25,'Full P&L-USD'!$G:$G) -> -625.11 | K25: =+SUMIF('Full P&L-USD'!$K:$K,B25,'Full P&L-USD'!$H:$H) -> 509470.73 | L25: =+SUMIF('Full P&L-USD'!$K:$K,B25,'Full P&L-USD'!$I:$I) -> 13097.9 | N25: =+SUMIF('Full P&L-USD'!$K:$K,B25,'Full P&L-USD'!$J:$J) -> 578498.81 | O25: =+N25-SUM(E25:L25) -> 0 | P25: =+ROUND(N25/1000,0) -> 578 | R25: =+'NOTES-Conso'!B67 -> 11
O26: =+N26-SUM(E26:L26) -> 0
B27: 7 | C27: Loss Before Taxes On Income | E27: =+E25+E23 -> 5.15 | F27: =+F25+F23 -> 9.56 | G27: =+G25+G23 -> -429.43 | H27: =+H25+H23 -> -445071.81 | I27: =+I25+I23 -> -4026989 | J27: =+J25+J23 -> -2122846.7 | K27: =+K25+K23 -> 1146811.2 | L27: =+L25+L23 -> -1404428.4 | N27: =+N25+N23 -> -6852939.5 | O27: =+N27-SUM(E27:L27) -> 0 | P27: =+P25+P23 -> -6854
O28: =+N28-SUM(E28:L28) -> 0
B29: 8 | C29: Tax on Income | E29: =+SUMIF('Full P&L-USD'!$K:$K,B29,'Full P&L-USD'!$B:$B) -> 0 | F29: =+SUMIF('Full P&L-USD'!$K:$K,B29,'Full P&L-USD'!$C:$C) -> 0 | G29: =+SUMIF('Full P&L-USD'!$K:$K,B29,'Full P&L-USD'!$D:$D) -> 0 | H29: =+SUMIF('Full P&L-USD'!$K:$K,B29,'Full P&L-USD'!$E:$E) -> -100 | I29: =+SUMIF('Full P&L-USD'!$K:$K,B29,'Full P&L-USD'!$F:$F) -> -72806.3 | J29: =+SUMIF('Full P&L-USD'!$K:$K,B29,'Full P&L-USD'!$G:$G) -> -47086.07 | K29: =+SUMIF('Full P&L-USD'!$K:$K,B29,'Full P&L-USD'!$H:$H) -> 200 | L29: =+SUMIF('Full P&L-USD'!$K:$K,B29,'Full P&L-USD'!$I:$I) -> 59189.74 | N29: =+SUMIF('Full P&L-USD'!$K:$K,B29,'Full P&L-USD'!$J:$J) -> -60602.63 | O29: =+N29-SUM(E29:L29) -> 0 | P29: =+ROUND(N29/1000,0) -> -61
O30: =+N30-SUM(E30:L30) -> 0
C31: Net Loss | E31: =+E27+E29 -> 5.15 | F31: =+F27+F29 -> 9.56 | G31: =+G27+G29 -> -429.43 | H31: =+H27+H29 -> -445171.81 | I31: =+I27+I29 -> -4099795.3 | J31: =+J27+J29 -> -2169932.8 | K31: =+K27+K29 -> 1147011.2 | L31: =+L27+L29 -> -1345238.7 | N31: =+N27+N29 -> -6913542.1 | O31: =+N31-SUM(E31:L31) -> 0 | P31: =+P27+P29 -> -6915

Sheet CF
A4: Cash flows from operating activities:
C5: As of December 31, 2023
C7: US thousand
A9: Net loss | C9: =-E96 -> -6915
A11: Adjustments to reconcile net loss to net cash provided by operating activities:
A14: Depreciation and amortization and impermanent | C14: =-E83 -> 43.221
A15: Share-based compensation expense | C15: =-E93 -> 292.364
A16: Change in employee long term loans | C16: =-E82 -> -4
A17: Change in long time employee benefit | C17: =-E89 -> -370
A19: Change in SAFE fair value | C19: =-E88 -> 0
A21: Changes in operating assets and liabilities:
A22: Accounts receivable | C22: =-E80 -> 1378
A23: Prepaid expenses and other assets | C23: =-E81 -> 117
A24: Accounts payable | C24: =-E84 -> -35
A25: Accrued expenses and other liabilities | C25: =-E85 -> 326
A26: Change in Deferred revenue | C26: =-E86 -> 0
A28: Net cash provided by operating activities | C28: =SUM(C9:C27) -> -5167.415
A30: Cash flows from investing activities:
A32: Change in short term restricted deposit | C32: =-F79-284 -> 2553
A33: Purchases of property and equipment | C33: =-F83 -> -41.221
A35: Net cash used in investing activities | C35: =-F97 -> 2795.779
A37: Cash flows from financing activities:
A39: Proceeds from issuance of Sample agreement for future equity ("SAFE") | C39: 0
A40: Proceeds from opsions excersize | C40: =-G91 -> 4
A41: Issuance of Preferred B shares, net of issuance cost
A42: Proceeds from issuance of convertible preferred shares, net of issuance costs
A44: Net cash provided by financing activities | C44: =+C42+C41+C39+C40 -> 4
A46: Net increase (decrease) in cash, cash equivalents, and restricted cash | C46: =+C44+C28+C35 -> -2367.636
A47: Cash, cash equivalents, and restricted cash—beginning of period | C47: =+D78 -> 7660
A49: Cash, cash equivalents, and restricted cash—end of period | C49: =+C46+C47 -> 5292.364 | D49: =+J78 -> 5292 | E49: =+C49-D49 -> 0.364
E55: אם הפקדונות משמשים לפעילות השוטפת או נזילים תוך פחות מ-3 חודשים הם מסווגים כמזומן ושווי מזומן
E56: .
F71: Working peper for cash flow
D75: Closing balance as | E75: Cash flow from | F75: Cash flow from | G75: Cash flow from | J75: Closing balance as
D76: 44926 | E76: Opeartion | F76: Investing | G76: Financing | H76: Non-cash activites | I76: Change in cash | J76: 45291 | L76: Check
B78: 10 | C78: Cash and cash equivalents | D78: 7660 | I78: =J78-D78-E78 -> -2368 | J78: =+'BS USD'!S11 -> 5292 | K78: =+J78-'BS USD'!$S11 -> 0 | L78: =SUM(D78:I78)-J78 -> 0
B79: 11 | C79: Restricted Bank Deposit | D79: 11163 | F79: =J79-D79 -> -2837 | J79: =+'BS USD'!S12 -> 8326 | K79: =+J79-'BS USD'!$S12 -> 0 | L79: =SUM(D79:I79)-J79 -> 0
B80: 12 | C80: Account Receivable | D80: 2037 | E80: =J80-D80 -> -1378 | J80: =+'BS USD'!S13 -> 659 | K80: =+J80-'BS USD'!$S13 -> 0 | L80: =SUM(D80:I80)-J80 -> 0
B81: 13 | C81: Prepaid expenses and other current assets | D81: 776 | E81: =J81-D81 -> -117 | J81: =+'BS USD'!S14 -> 659 | K81: =+J81-'BS USD'!$S14 -> 0 | L81: =SUM(D81:I81)-J81 -> 0
B82: 14 | C82: Other long term accounts receivables | D82: 34 | E82: =J82-D82 -> 4 | J82: =+'BS USD'!S20 -> 38 | K82: =+J82-'BS USD'!$S20 -> 0 | L82: =SUM(D82:I82)-J82 -> 0
...

Sheet Change in Equity
D3: Ordinary shares | H3: Preferred Shares | L3: Additional | N3: Receivable on | P3: Accumulated | R3: Total shareholders' equity
L4: paid-in
D5: Number | F5: Amount | H5: Number | J5: Amount | L5: capital | N5: Shares account | P5: deficit | R5: (deficit)
B7: Balance as of January 1, 2021 | D7: 1401739 | F7: 4 | H7: 1481702 | J7: 5 | L7: 41580 | N7: 0 | P7: -14078 | R7: 27511
B9: Net loss and other comprehensive loss | D9: 0 | F9: 0 | H9: 0 | J9: 0 | L9: 0 | N9: 0 | P9: -7391 | R9: =+P9+F9+L9+J9 -> -7391
B10: Option exercise | D10: 2600 | L10: 8 | R10: =+P10+F10+L10+J10+N10 -> 8
B11: Share based compensation | D11: 0 | F11: 0 | H11: 0 | J11: 0 | L11: 257 | N11: 0 | P11: 0 | R11: =+P11+F11+L11+J11 -> 257
B12: Warrant exercise | H12: 127247 | J12: (*)
B13: SAFE exercise | D13: 0 | F13: 0 | N13: - | P13: 0 | R13: =+P13+F13+L13+J13 -> 0
B14: Issuance of preferred B Shares, net of issuance cost | D14: 0 | F14: 0 | P14: 0 | R14: =+P14+J14+L14+N14 -> 0 | S14: =+H14+'NOTES-Conso'!H41 -> 0
B16: Balance as of December 31, 2021 | D16: =SUM(D7:D15) -> 1404339 | F16: =SUM(F7:F15) -> 4 | H16: =SUM(H7:H15) -> 1608949 | J16: =SUM(J7:J15) -> 5 | L16: =SUM(L7:L15) -> 41845 | N16: =SUM(N7:N15) -> 0 | P16: =SUM(P7:P15) -> -21469 | R16: =+P16+F16+L16+N16+J16 -> 20385
B18: Net loss and other comprehensive loss | D18: 0 | F18: 0 | H18: 0 | J18: 0 | L18: 0 | N18: 0 | P18: =+'P&L'!P31 -> -6915 | R18: =SUM(J18:P18,F18) -> -6915
B19: Option exercise | R19: =SUM(J19:P19,F19) -> 0
B20: Share based compensation | L20: =-CF!E93+4 -> 296.364 | R20: =SUM(J20:P20,F20) -> 296.364
B21: SAFE exercise | R21: =SUM(J21:P21,F21) -> 0
B22: Warrant exercise | J22: (*) | R22: =SUM(J22:P22,F22) -> 0
B23: Issuance of preferred A Shares, net of issuance cost
B24: Issuance of ordinary stocks, net of issuance cost | F24: 0 | P24: 0 | R24: =SUM(J24:P24,F24) -> 0
B26: Balance as of December 31, 2022 | D26: =SUM(D16:D24) -> 1404339 | F26: =SUM(F16:F24) -> 4 | H26: =SUM(H16:H24) -> 1608949 | J26: =SUM(J16:J24) -> 5 | L26: =SUM(L16:L24) -> 42141.364 | N26: =SUM(N16:N24) -> 0 | P26: =SUM(P16:P24) -> -28384 | R26: =+R16+R18+R20 -> 13766.364
D28: =+D16+D19+D20-D26 -> 0 | H28: =+H16+H22-H26 -> 0 | L28: =+L16+L20-L26 -> 0 | P28: =+P16+P18-P26 -> 0 | Q28: =+Q16+Q18-Q26 -> 0
R29: =+'BS USD'!S51-R26 -> 0.636
L30: =+L26-'BS USD'!S46 -> 0

Sheet JE'S
B5: 1 | D5: AR-DR Offset | G5: JEIL-01719
C9: D | D9: 12002 AR OFFSET | E9: 47763.9
C10: C | D10: 26002 DR OFFSET | E10: 47763.9
B14: 2
B35: 3 | D35: Rent paid upfront- wework | G35: JEIL-03339
G36: ILS
C37: D | D37: 67101 Rent | G37: 53520
C38: C | D38: 20001 AP | G38: =+G37 -> 53520

Sheet NOTES-Conso
D3: Balance Sheet Notes
B5: 3 | D5: Trade recievables | E5: =+SUMIF('Full BS-USD'!$M$9:$M$226,F5,'Full BS-USD'!$L$9:$L$226)/1000 -> 424.62305 | F5: 12.1 | I5: See WP AR Breakdown
D6: Unbilled revenue | E6: =SUMIF('Full BS-USD'!$M$9:$M$226,F6,'Full BS-USD'!$L$9:$L$226)/1000-E5-1 -> 233.25907 | F6: 12
E7: =SUM(E5:E6) -> 657.88212
E8: =+E7-'BS USD'!S13 -> -1.11788
B10: 4 | D10: Prepaid expenses | E10: =+SUMIF('Full BS-USD'!$M$9:$M$226,F10,'Full BS-USD'!$L$9:$L$226)/1000 -> 273.23526 | F10: 13.1 | I10: See WP Prepaid expenses
D11: Government institutions | E11: =+SUMIF('Full BS-USD'!$M$9:$M$226,F11,'Full BS-USD'!$L$9:$L$226)/1000 -> 162.24782 | F11: 13.2
D12: Other current assts | E12: =SUMIF('Full BS-USD'!$M$9:$M$226,F12,'Full BS-USD'!$L$9:$L$226)/1000-E11-E10 -> 223.27715 | F12: 13
E13: =SUM(E10:E12) -> 658.76023
E14: =+E13-'BS USD'!S14 -> -0.23977
B15: 5 | D15: Cost:
D16: Computers & Software | E16: =+SUMIF('Full BS-USD'!$M$9:$M$226,F16,'Full BS-USD'!$L$9:$L$226)/1000 -> 233.65423 | F16: 15.1
D17: Office furniture | E17: =+SUMIF('Full BS-USD'!$M$9:$M$226,F17,'Full BS-USD'!$L$9:$L$226)/1000 -> 28.00532 | F17: 15.2
D18: Leasehold improvements | E18: =SUMIF('Full BS-USD'!$M$9:$M$226,F18,'Full BS-USD'!$L$9:$L$226)/1000 -> 2.65233 | F18: 15.3
E19: =SUM(E16:E18) -> 264.31188
D21: Accumulated depritiation | E21: =SUMIF('Full BS-USD'!$M$9:$M$226,F21,'Full BS-USD'!$L$9:$L$226)/1000 -> -142.99059 | F21: 15.4
D23: Preperty and equipment, net | E23: =+E19+E21 -> 121.32129
E24: =+E23-'BS USD'!S21 -> 0.32129
I26: See WP : Accruals Breakdown
B27: 6 | D27: Accrued employee compensation and benefits | E27: =+SUMIF('Full BS-USD'!$M$9:$M$226,F27,'Full BS-USD'!$L$9:$L$226)/1000 -> 592.20807 | F27: 17.1
D28: Accrued expenses | E28: =+SUMIF('Full BS-USD'!$M$9:$M$226,F28,'Full BS-USD'!$L$9:$L$226)/1000 -> 211.29614 | F28: 17.2
D29: Income and indirect tax payable | E29: =+SUMIF('Full BS-USD'!$M$9:$M$226,F29,'Full BS-USD'!$L$9:$L$226)/1000-E28-E27 -> 314.55034 | F29: 17 | G29: includes DR
E30: =SUM(E27:E29) -> 1118.0546
E31: =+E30-'BS USD'!S35 -> 0.05455
B33: 8 | D33: Share capital: | O33: Shareholders' equity
O35: 2022
E36: Authorized | F36: issued and outstanding | J36: Authorized | K36: issued and outstanding | O36: number of options | P36: weightes average excersise price
E37: December 31,2023 | J37: December 31,2022 | N37: Balance as of December 31,2021
D38: ordinary shares | E38: 3074000 | F38: 1223458 | J38: 3074000 | K38: 1223458 | N38: Granted
D39: ordinary A Shares | E39: 205000 | F39: 180881 | J39: 205000 | K39: 180881 | N39: Balance as of December 31,2022
D40: Preferred A shares (*) | E40: 651000 | F40: 641271 | J40: 651000 | K40: 641271 | N40: Excercisable as of December 31,2021
D41: preferred B shares (*) | E41: 1070000 | F41: 967678 | J41: 1070000 | K41: 967678
E42: =SUM(E38:E41) -> 5000000 | F42: =SUM(F38:F41) -> 3013288 | J42: =SUM(J38:J41) -> 5000000 | K42: =SUM(K38:K41) -> 3013288
K45: The information is taken from Carta- "Summery Cap Table" report
D48: P&L Notes
B50: 9
D51: Subscription fees | F51: From rev File | I51: See WP: Revenue File
D52: Variable Fees | F52: From rev File
E53: =SUM(E51:E52) -> 0
E54: =+'P&L'!P8 -> 9466 | F54: NS
...

Sheet Options -Outstanding Awards
B5: Number of Awards | C5: Weighted Average Exercise Price | D5: Weighted Average Share Price on Date of Exercise | E5: Weighted Average Remaining Contractual Life | F5: Aggregate Intrinsic Value
A6: Outstanding, beginning of period | B6: 146702 | C6: 8.431322 | F6: 3604274.2
A7: Granted | B7: 23750 | C7: 21.18
A8: Exercised/Released | B8: -2600 | C8: 4.3474829 | D8: 4.3474829
A9: Cancelled/Forfeited | B9: -5752 | C9: 13.90386
A10: Expired | B10: -765 | C10: 12.5
A11: Outstanding, End of period | B11: 161335 | C11: 10.159456 | E11: 7.7855858 | F11: 3684979.2
A12: Exercisable, End of period | B12: 89352 | C12: 4.9935285 | E12: 6.9678835 | F12: 2502434.2
B18: 2022
B19: Number of options | C19: Weightes average exercise price | E19: *
A20: Balance as of December 31,2021 | B20: 105702 | C20: 5.47 | E20: =+B20/B22 -> 0.81653431 | F20: =+C20*E20 -> 4.4664427 | L20: From Carta
A21: Granted | B21: =+B7 -> 23750 | C21: =+C7 -> 21.18 | E21: =+B21/B22 -> 0.18346569 | F21: =+E21*C21 -> 3.8858032 | L21: Wematch.live R&D LTD Options Exercised & RSUs Settled
A22: Balance as of December 31,2022 | B22: =+B21+B20 -> 129452 | C22: 8.35 | D22: * | F22: =+F21+F20 -> 8.3522459 | L22: As of 12/31/2022 • Generated by Hila Eliasi (hila.eliasi@wematch.live) at 08/10/2023 06:10:37
A23: Excercisable as of December 31,2022 | B23: =+B12 -> 89352 | C23: =+C12 -> 4.9935285
L24: ID | M24: Optionholder | N24: Employee ID | O24: Shares Exercised | P24: Grant Date | Q24: Exercise Request Date | R24: Off System Transaction | S24: Exercise Price | T24: Total Exercise Price
L25: ES-1008 | M25: Rudy Perez | O25: 1216 | P25: 43586 | Q25: 44650 | S25: 0.002783 | T25: =O25*S25 -> 3.384128
L26: ES-1019 | M26: Eitan Katz | O26: 800 | P26: 43952 | Q26: 44921 | S26: 5 | T26: =O26*S26 -> 4000
L27: ES-1054 | M27: Rudy Perez | O27: 584 | P27: 44317 | Q27: 44650 | S27: 12.5 | T27: =O27*S27 -> 7300
A28: Grant date | B28: number of options granted during 2023 | C28: number of options excercised during 2023 | D28: Options outstanding as of December 31, 2023 | E28: Exercise price | F28: Options excercisable as of December 31,2023 | G28: Excercisable through
A29: 43647 | B29: 14900 | C29: =+O25 -> 1216 | D29: =+C29+B29 -> 16116 | E29: 0.001 | F29: 7450 | G29: =+A29+365*10+3 -> 47300
A30: 43952 | B30: 9500 | C30: =+O26 -> 800 | E30: 5 | G30: =+A30+365*10+2 -> 47604
A31: 44317 | B31: 300 | C31: =+O27 -> 584 | D31: =+C31+B31 -> 884 | E31: 12.5 | F31: 100 | G31: =+A31+365*10+2 -> 47969
A32: 01/05/2022 | B32: 11800 | C32: - | E32: =+C7 -> 21.18 | F32: =+F33 -> 89352 | G32: =+A32+365*10+3 -> 48335
A33: 22/09/2022 | B33: 11950 | C33: - | D33: =+B11 -> 161335 | E33: =+E32 -> 21.18 | F33: =+B12 -> 89352 | G33: =+A33+365*10+3 -> 48479
E39: December 31,
E40: 2023 | F40: 2022
D41: CogS | E41: 2 | F41: 2 | J41: CogS | L41: 1607
D42: R&D | E42: 80 | F42: 80 | J42: R&D | K42: Product | L42: 60098
D43: S&M | E43: 44 | F43: 44 | K43: Technology | L43: 19839
D44: G&A | E44: 131 | F44: 131 | J44: S&M | K44: Sales | L44: 57149
E45: =SUM(E41:E44) -> 257 | F45: 257 | K45: Marketing | L45: -13087
J46: G&A | L46: =97986+19940+1135+12277 -> 131338
E47: 257 | L47: =SUM(L41:L46) -> 256944
B53: 01/08/2023 from Carta | C53: 66288
B54: Niv Sabag | C54: -800
B55: Shane Martin | C55: -2000
B56: Christine Lowe | C56: -1000
B57: Jason Hunter | C57: -750
B58: Jason Hunter | C58: -1500
B59: Shane Martin | C59: -2000
...

Sheet Full BS-USD
A1: Wematch.live R&D LTD
A2: Wematch.live R&D LTD (Consolidated)
A3: Balance Sheet
A4: End of Dec 2023
A7: Financial Row | B7: Elimination | C7: Elimination US | D7: Wematch EQD LTD | E7: Wematch Interest rate LTD | F7: Wematch Securities. Financing LTD [IL] | G7: Wematch.Live LLC | H7: Wematch.SecuritiesFinancing LTD | I7: Wematch.Support US INC. | J7: Wematch.live R&D LTD | K7: Wematch.live Tech Support Europe | L7: Total | M7: INDEX
B8: Amount | C8: Amount | D8: Amount | E8: Amount | F8: Amount | G8: Amount | H8: Amount | I8: Amount | J8: Amount | K8: Amount | L8: Amount
A9: Current Assets
A10: Bank
A11: 100 - DUMMY USD | B11: 0 | C11: 0 | D11: 0 | E11: 0 | F11: 0 | G11: 0 | H11: 0 | I11: 0 | J11: -2039.05 | K11: 0 | L11: =SUM(B11:K11) -> -2039.05 | M11: 10
A12: 10000 - Cash and Cash Equivalent (WRD-IL)
A13: 10001 - Bank Fibi 327492 NIS | B13: 0 | C13: 0 | D13: 0 | E13: 0 | F13: 0 | G13: 0 | H13: 0 | I13: 0 | J13: 95130.17 | K13: 0 | L13: =SUM(B13:K13) -> 95130.17
A14: 10002 - Bank Hapoalim 120737 NIS | B14: 0 | C14: 0 | D14: 0 | E14: 0 | F14: 0 | G14: 0 | H14: 0 | I14: 0 | J14: 281335.24 | K14: 0 | L14: =SUM(B14:K14) -> 281335.24
A15: 10003 - Bank Hapoalim 120737 USD | B15: 0 | C15: 0 | D15: 0 | E15: 0 | F15: 0 | G15: 0 | H15: 0 | I15: 0 | J15: 2680320.9 | K15: 0 | L15: =SUM(B15:K15) -> 2680320.9
A16: 10004 - Bank Hapoalim 120737 GBP | B16: 0 | C16: 0 | D16: 0 | E16: 0 | F16: 0 | G16: 0 | H16: 0 | I16: 0 | J16: 3012.11 | K16: 0 | L16: =SUM(B16:K16) -> 3012.11
A17: 10005 - Bank Hapoalim 120737 EUR | B17: 0 | C17: 0 | D17: 0 | E17: 0 | F17: 0 | G17: 0 | H17: 0 | I17: 0 | J17: 125756.42 | K17: 0 | L17: =SUM(B17:K17) -> 125756.42
A18: 10006 - Bank Hapoalim 120737 CAD | B18: 0 | C18: 0 | D18: 0 | E18: 0 | F18: 0 | G18: 0 | H18: 0 | I18: 0 | J18: 9468.65 | K18: 0 | L18: =SUM(B18:K18) -> 9468.65
A19: 10007 - Bank Hapoalim 120737 SGD | B19: 0 | C19: 0 | D19: 0 | E19: 0 | F19: 0 | G19: 0 | H19: 0 | I19: 0 | J19: 208.81 | K19: 0 | L19: =SUM(B19:K19) -> 208.81
A20: Total - 10000 - Cash and Cash Equivalent (WRD-IL) | B20: =SUM(B13:B19) -> 0 | C20: =SUM(C13:C19) -> 0 | D20: =SUM(D13:D19) -> 0 | E20: =SUM(E13:E19) -> 0 | F20: =SUM(F13:F19) -> 0 | G20: =SUM(G13:G19) -> 0 | H20: =SUM(H13:H19) -> 0 | I20: =SUM(I13:I19) -> 0 | ... L20: =SUM(L13:L19) -> 3195232.3 | M20: 10
A21: 10100 - Cash and Cash Equivalent (WIR-IL)
A22: 10101 - Bank Hapoalim 120720 NIS | B22: 0 | C22: 0 | D22: 0 | E22: 21.14 | F22: 0 | G22: 0 | H22: 0 | I22: 0 | J22: 0 | K22: 0 | L22: =SUM(B22:K22) -> 21.14
A23: Total - 10100 - Cash and Cash Equivalent (WIR-IL) | B23: =SUM(B22) -> 0 | C23: =SUM(C22) -> 0 | D23: =SUM(D22) -> 0 | E23: =SUM(E22) -> 21.14 | F23: =SUM(F22) -> 0 | G23: =SUM(G22) -> 0 | H23: =SUM(H22) -> 0 | I23: =SUM(I22) -> 0 | ... L23: =SUM(L22) -> 21.14 | M23: 10
A24: 102 - DUMMY - FR | B24: 0 | C24: 0 | D24: 0 | E24: 0 | F24: 0 | G24: 0 | H24: 0 | I24: 0 | J24: 0 | K24: 18.74 | L24: =SUM(B24:K24) -> 18.74 | M24: 10
A25: 10200 - Cash and Cash Equivalent (WSF-IL)
A26: 10201 - Bank Hapoalim 120729 NIS | B26: 0 | C26: 0 | D26: 0 | E26: 0 | F26: 45.87 | G26: 0 | H26: 0 | I26: 0 | J26: 0 | K26: 0 | L26: =SUM(B26:K26) -> 45.87
A27: 10202 - Bank Hapoalim 120729 USD | B27: 0 | C27: 0 | D27: 0 | E27: 0 | F27: 24.67 | G27: 0 | H27: 0 | I27: 0 | J27: 0 | K27: 0 | L27: =SUM(B27:K27) -> 24.67
A28: 10203 - Bank Hapoalim 120729 EUR | B28: 0 | C28: 0 | D28: 0 | E28: 0 | F28: 228.83 | G28: 0 | H28: 0 | I28: 0 | J28: 0 | K28: 0 | L28: =SUM(B28:K28) -> 228.83
A29: Total - 10200 - Cash and Cash Equivalent (WSF-IL) | B29: =SUM(B26:B28) -> 0 | C29: =SUM(C26:C28) -> 0 | D29: =SUM(D26:D28) -> 0 | E29: =SUM(E26:E28) -> 0 | F29: =SUM(F26:F28) -> 299.37 | G29: =SUM(G26:G28) -> 0 | H29: =SUM(H26:H28) -> 0 | I29: =SUM(I26:I28) -> 0 | ... L29: =SUM(L26:L28) -> 299.37 | M29: 10
A30: 10300 - Cash and Cash Equivalent (WEQD-IL)
A31: 10301 - Bank Hapoalim 120702 NIS | B31: 0 | C31: 0 | D31: 19 | E31: 0 | F31: 0 | G31: 0 | H31: 0 | I31: 0 | J31: 0 | K31: 0 | L31: =SUM(B31:K31) -> 19
A32: 10302 - Bank Hapoalim 120702 USD | B32: 0 | C32: 0 | D32: 6438.02 | E32: 0 | F32: 0 | G32: 0 | H32: 0 | I32: 0 | J32: 0 | K32: 0 | L32: =SUM(B32:K32) -> 6438.02
A33: 10303 - Bank BIA | B33: 0 | C33: 0 | D33: 14237.25 | E33: 0 | F33: 0 | G33: 0 | H33: 0 | I33: 0 | J33: 0 | K33: 0 | L33: =SUM(B33:K33) -> 14237.25
A34: Total - 10300 - Cash and Cash Equivalent (WEQD-IL) | B34: =SUM(B31:B33) -> 0 | C34: =SUM(C31:C33) -> 0 | D34: =SUM(D31:D33) -> 20694.27 | E34: =SUM(E31:E33) -> 0 | F34: =SUM(F31:F33) -> 0 | G34: =SUM(G31:G33) -> 0 | H34: =SUM(H31:H33) -> 0 | I34: =SUM(I31:I33) -> 0 | ... L34: =SUM(L31:L33) -> 20694.27 | M34: 10
A35: 10400 - Cash and Cash Equivalent (WSF-UK)
A36: 10401 - Bank Netwest 27557405 £ | B36: 0 | C36: 0 | D36: 0 | E36: 0 | F36: 0 | G36: 0 | H36: 166161.23 | I36: 0 | J36: 0 | K36: 0 | L36: =SUM(B36:K36) -> 166161.23
A37: 70942471 - Soldo UK Wallet | B37: 0 | C37: 0 | D37: 0 | E37: 0 | F37: 0 | G37: 0 | H37: 29596.33 | I37: 0 | J37: 0 | K37: 0 | L37: =SUM(B37:K37) -> 29596.33
A38: Total - 10400 - Cash and Cash Equivalent (WSF-UK) | B38: =SUM(B36:B37) -> 0 | C38: =SUM(C36:C37) -> 0 | D38: =SUM(D36:D37) -> 0 | E38: =SUM(E36:E37) -> 0 | F38: =SUM(F36:F37) -> 0 | G38: =SUM(G36:G37) -> 0 | H38: =SUM(H36:H37) -> 195757.56 | I38: =SUM(I36:I37) -> 0 | ... L38: =SUM(L36:L37) -> 195757.56 | M38: 10
A39: 10500 - Cash and Cash Equivalent (WTSE-FR)
A40: 10501 - Bank SG 20020671 EUR | B40: 0 | C40: 0 | D40: 0 | E40: 0 | F40: 0 | G40: 0 | H40: 0 | I40: 0 | J40: 0 | K40: 198122.7 | L40: =SUM(B40:K40) -> 198122.7
A41: 70424674 - Soldo FR Wallet € | B41: 0 | C41: 0 | D41: 0 | E41: 0 | F41: 0 | G41: 0 | H41: 0 | I41: 0 | J41: 0 | K41: 10257.38 | L41: =SUM(B41:K41) -> 10257.38
A42: Total - 10500 - Cash and Cash Equivalent (WTSE-FR) | B42: =SUM(B40:B41) -> 0 | C42: =SUM(C40:C41) -> 0 | D42: =SUM(D40:D41) -> 0 | E42: =SUM(E40:E41) -> 0 | F42: =SUM(F40:F41) -> 0 | G42: =SUM(G40:G41) -> 0 | H42: =SUM(H40:H41) -> 0 | I42: =SUM(I40:I41) -> 0 | ... L42: =SUM(L40:L41) -> 208380.08 | M42: 10
...

Sheet Full P&L-USD
A1: Wematch.live R&D LTD
A2: Wematch.live R&D LTD (Consolidated)
A3: WM INCOME STATEMENT for budget -Oren
A4: From Jan 2023 to Dec 2023
A7: Financial Row | B7: Wematch EQD LTD | C7: Wematch Interest rate LTD | D7: Wematch Securities. Financing LTD [IL] | E7: Wematch.Live LLC | F7: Wematch.SecuritiesFinancing LTD | G7: Wematch.Support US INC. | H7: Wematch.live R&D LTD | I7: Wematch.live Tech Support Europe | J7: Total | K7: INDEX | L7: note
B8: Amount | C8: Amount | D8: Amount | E8: Amount | F8: Amount | G8: Amount | H8: Amount | I8: Amount | J8: Amount
A9: Gross Revenue
A10: Securities Financing
A11: TRS | B11: 0 | C11: 0 | D11: 0 | E11: 0 | F11: 0 | G11: 0 | H11: 8244447.1 | I11: 0 | J11: =SUM(B11:I11) -> 8244447.1
A12: SBL | B12: 0 | C12: 0 | D12: 0 | E12: 0 | F12: 0 | G12: 0 | H12: 528827.37 | I12: 0 | J12: =SUM(B12:I12) -> 528827.37
A13: Total - Securities Financing | B13: =SUM(B11:B12) -> 0 | C13: =SUM(C11:C12) -> 0 | D13: =SUM(D11:D12) -> 0 | E13: =SUM(E11:E12) -> 0 | F13: =SUM(F11:F12) -> 0 | G13: =SUM(G11:G12) -> 0 | H13: =SUM(H11:H12) -> 8773274.4 | I13: =SUM(I11:I12) -> 0 | J13: =SUM(J11:J12) -> 8773274.4
A14: Equity Derivative | B14: 0 | C14: 0 | D14: 0 | E14: 0 | F14: 0 | G14: 0 | H14: 272800.02 | I14: 0 | J14: =SUM(B14:I14) -> 272800.02
A15: Interest rate | B15: 0 | C15: 0 | D15: 0 | E15: 0 | F15: 0 | G15: 0 | H15: 419954.86 | I15: 0 | J15: =SUM(B15:I15) -> 419954.86
A16: Total Gross Revenue | B16: =SUM(B13:B15) -> 0 | C16: =SUM(C13:C15) -> 0 | D16: =SUM(D13:D15) -> 0 | E16: =SUM(E13:E15) -> 0 | F16: =SUM(F13:F15) -> 0 | G16: =SUM(G13:G15) -> 0 | H16: =SUM(H13:H15) -> 9466029.3 | I16: =SUM(I13:I15) -> 0 | J16: =SUM(J13:J15) -> 9466029.3 | K16: 1 | L16: 9
A17: Revenue Shared With Regulated Broker Dealer
A18: 45000 - Revenues shared to third parties
A19: 45002 - Commission Shared with third party | B19: 0 | C19: 0 | D19: 0 | E19: 0 | F19: 0 | G19: 0 | H19: -1311204.7 | I19: 0 | J19: =SUM(B19:I19) -> -1311204.7 | K19: 2.1
A20: 45001 - ISIN | B20: 0 | C20: 0 | D20: 0 | E20: 0 | F20: 0 | G20: 0 | H20: -36045.01 | I20: 0 | J20: =SUM(B20:I20) -> -36045.01 | K20: 2.1
A21: 45003 - Non Reclaimable VAT | B21: 0 | C21: 0 | D21: 0 | E21: 0 | F21: 0 | G21: 0 | H21: -405247.27 | I21: 0 | J21: =SUM(B21:I21) -> -405247.27 | K21: 2.1
A22: Total - 45000 - Revenues shared to third parties | B22: =SUM(B19:B21) -> 0 | C22: =SUM(C19:C21) -> 0 | D22: =SUM(D19:D21) -> 0 | E22: =SUM(E19:E21) -> 0 | F22: =SUM(F19:F21) -> 0 | G22: =SUM(G19:G21) -> 0 | H22: =SUM(H19:H21) -> -1752497 | I22: =SUM(I19:I21) -> 0 | J22: =SUM(J19:J21) -> -1752497 | K22: 2
A23: Total Revenue Shared With Regulated Broker Dealer | B23: =SUM(B22) -> 0 | C23: =SUM(C22) -> 0 | D23: =SUM(D22) -> 0 | E23: =SUM(E22) -> 0 | F23: =SUM(F22) -> 0 | G23: =SUM(G22) -> 0 | H23: =SUM(H22) -> -1752497 | I23: =SUM(I22) -> 0 | J23: =SUM(J22) -> -1752497
A24: Net Revenue | B24: =+B16+B23 -> 0 | C24: =+C16+C23 -> 0 | D24: =+D16+D23 -> 0 | E24: =+E16+E23 -> 0 | F24: =+F16+F23 -> 0 | G24: =+G16+G23 -> 0 | H24: =+H16+H23 -> 7713532.3 | I24: =+I16+I23 -> 0 | J24: =+J16+J23 -> 7713532.3
A25: Cost Of Sales
A26: CoS
A27: Platform Operation
A28: 50000 - COGS expenses
A29: 50100 - Payroll and Related expenses [COGS]
A30: 50101 - COGS Gross Salaries | B30: 0 | C30: 0 | D30: 0 | E30: -57460.16 | F30: -10363.15 | G30: -18764.36 | H30: -512355.68 | I30: 0 | J30: =SUM(B30:I30) -> -598943.35
A31: 50106 - COGS Workers Compensation | B31: 0 | C31: 0 | D31: 0 | E31: -273.16 | F31: 0 | G31: 0 | H31: 0 | I31: 0 | J31: =SUM(B31:I31) -> -273.16
A32: 50107 - COGS Benefits | B32: 0 | C32: 0 | D32: 0 | E32: 0 | F32: 47.61 | G32: 0 | H32: 0 | I32: 0 | J32: =SUM(B32:I32) -> 47.61
A33: 50108 - COGS Employee stock-based compensation | B33: 0 | C33: 0 | D33: 0 | E33: -288 | F33: -3697.56 | G33: -459 | H33: 0 | I33: -811 | J33: =SUM(B33:I33) -> -5255.56
A34: 50109 - COGS Payroll processing fees | B34: 0 | C34: 0 | D34: 0 | E34: 0 | F34: 0 | G34: 0 | H34: -2073.97 | I34: 0 | J34: =SUM(B34:I34) -> -2073.97
A35: 50112 - COGS Employee Life Insurance | B35: 0 | C35: 0 | D35: 0 | E35: 0 | F35: -41.94 | G35: 0 | H35: 0 | I35: 0 | J35: =SUM(B35:I35) -> -41.94
A36: 50114 - COGS Gym membership | B36: 0 | C36: 0 | D36: 0 | E36: 0 | F36: -828.44 | G36: 0 | H36: 0 | I36: 0 | J36: =SUM(B36:I36) -> -828.44
A37: 51003 - COGS Medical Insurance | B37: 0 | C37: 0 | D37: 0 | E37: -646.9 | F37: -1379.36 | G37: 577.49 | H37: -693.86 | I37: 0 | J37: =SUM(B37:I37) -> -2142.63
A38: Total - 50100 - Payroll and Related expenses [COGS] | B38: =SUM(B30:B37) -> 0 | C38: =SUM(C30:C37) -> 0 | D38: =SUM(D30:D37) -> 0 | E38: =SUM(E30:E37) -> -58668.22 | F38: =SUM(F30:F37) -> -16262.84 | G38: =SUM(G30:G37) -> -18645.87 | H38: =SUM(H30:H37) -> -515123.51 | I38: =SUM(I30:I37) -> -811 | J38: =SUM(J30:J37) -> -609511.44
A39: 50200 - COGS Travel and Entertainment
A40: 50201 - COGS Airfare | B40: 0 | C40: 0 | D40: 0 | E40: 0 | F40: 0 | G40: 0 | H40: -992.96 | I40: 0 | J40: =SUM(B40:I40) -> -992.96
A41: 50202 - COGS Lodging | B41: 0 | C41: 0 | D41: 0 | E41: 0 | F41: 0 | G41: 0 | H41: -992.96 | I41: 0 | J41: =SUM(B41:I41) -> -992.96
A42: Total - 50200 - COGS Travel and Entertainment | B42: =SUM(B40:B41) -> 0 | C42: =SUM(C40:C41) -> 0 | D42: =SUM(D40:D41) -> 0 | E42: =SUM(E40:E41) -> 0 | F42: =SUM(F40:F41) -> 0 | G42: =SUM(G40:G41) -> 0 | H42: =SUM(H40:H41) -> -1985.92 | I42: =SUM(I40:I41) -> 0 | J42: =SUM(J40:J41) -> -1985.92
...

Sheet Solo--->

Sheet Change in Equity ILS
D3: הון | F3: חייבים על חשבון מניות | H3: פרמיה | J3: עודפים | L3: סה"כ
D4: המניות
D5: אלפי ש"ח
B7: יתרה ליום 1 בינואר, 2021 | D7: 16 | F7: -163 | H7: 38957 | J7: -31471 | L7: 7339
B9: הנפקת מניות | D9: 12 | F9: 163 | H9: 89852 | L9: =SUM(D9:K9) -> 90027
B10: קרן הון בגין אופציות | D10: - | H10: 1757 | L10: =SUM(D10:K10) -> 1757
B11: הפסד נקי | D11: - | F11: - | H11: - | J11: -13588 | L11: =SUM(D11:K11) -> -13588
B13: יתרה ליום 31 בדצמבר, 2021 | D13: =SUM(D7:D12) -> 28 | F13: - | H13: =SUM(H7:H12) -> 130566 | J13: =SUM(J7:J12) -> -45059 | L13: =SUM(L7:L12) -> 85535
L14: =SUM(D14:K14) -> 0
B15: מימוש אופציות | F15: =+'WRD Solo BS'!B146/1000-1 -> 22.17112 | L15: =SUM(D15:K15) -> 22.17112
B16: קרן הון בגין אופציות | H16: =+'WRD Solo BS'!E147/1000-1 -> 823.74508 | L16: =SUM(D16:K16) -> 823.74508
B17: הפסד נקי | D17: - | F17: - | H17: - | J17: =+'P&L ILS'!G31 -> -17338 | L17: =+J17 -> -17338
B19: יתרה ליום 31 בדצמבר, 2022 | D19: =SUM(D13:D17) -> 28 | F19: =SUM(F13:F17) -> 22.17112 | H19: =SUM(H13:H17) -> 131389.75 | J19: =SUM(J13:J18) -> -62397 | L19: =SUM(L13:L18) -> 69042.916
L21: =+'BS ILS'!E51/1000-L19 -> 0.27307

Sheet P&L ILS
C1: Wematch.live
C2: USD
B5: INDEX | E5: R&D
E6: 2023 | G6: in 000' | I6: NOTE
B8: 1 | C8: Revenues | E8: =+SUMIF('WRD Solo P&L'!$C$7:$C$674,B8,'WRD Solo P&L'!$B$7:$B$674) -> 22654854 | G8: =+ROUND(E8/1000,0) -> 22655 | I8: =+'NOTES-Conso'!B50 -> 9
B10: 2 | C10: Cost of Revenues | E10: =+SUMIF('WRD Solo P&L'!$C$7:$C$674,B10,'WRD Solo P&L'!$B$7:$B$674) -> -5998216.2 | G10: =+ROUND(E10/1000,0) -> -5998 | I10: =+'NOTES-Conso'!B59 -> 10
B12: 3 | C12: Gross profit | E12: =+E8+E10 -> 16656638 | G12: =+G8+G10 -> 16657
C14: Operating expenses:
A15: Total - R&D | B15: 4.1 | C15: R&D | E15: =+SUMIF('WRD Solo P&L'!$C$7:$C$674,B15,'WRD Solo P&L'!$B$7:$B$674)+'WRD Solo P&L'!E680 -> 19092521 | G15: =+ROUND(E15/1000,0) -> 19093
A16: Total - S&M | B16: 4.2 | C16: S&M | E16: =+SUMIF('WRD Solo P&L'!$C$7:$C$674,B16,'WRD Solo P&L'!$B$7:$B$674)+'WRD Solo P&L'!E681 -> 13490588 | G16: =+ROUND(E16/1000,0) -> 13491
A17: Total - G&A | B17: 4.3 | C17: G&A | E17: =+SUMIF('WRD Solo P&L'!$C$7:$C$674,B17,'WRD Solo P&L'!$B$7:$B$674)+'WRD Solo P&L'!E682 -> 12234312 | G17: =+ROUND(E17/1000,0) -> 12234
A19: Total Operation Expense | B19: 4 | C19: Total Operatiing Expense | E19: =+SUMIF('WRD Solo P&L'!$C$7:$C$674,B19,'WRD Solo P&L'!$B$7:$B$674)+'WRD Solo P&L'!B676 -> 44817421 | G19: =+SUM(G15:G17) -> 44818 | H19: =+E19-E17-E16-E15 -> 0
C21: Operating Loss | E21: =+E12-E19 -> -28160782 | G21: =+G12-G19 -> -28161
B23: 5 | C23: Earning/(Loss) Before Interest & Tax | E23: =+E12-E19 -> -28160782 | G23: =+G12-G19 -> -28161
B25: 6 | C25: Financial expenses, net | E25: =+SUMIF('WRD Solo P&L'!$C$7:$C$674,B25,'WRD Solo P&L'!$B$7:$B$674) -> 10822974 | G25: =+ROUND(E25/1000,0) -> 10823 | I25: =+'NOTES-Conso'!B67 -> 11
B27: 7 | C27: Loss Before Taxes On Income | E27: =+E25+E23 -> -17337808 | G27: =+G25+G23 -> -17338
B29: 8 | C29: Tax on Income | E29: =+SUMIF('WRD Solo P&L'!$C$7:$C$674,B29,'WRD Solo P&L'!$B$7:$B$674) -> 0 | G29: =+ROUND(E29/1000,0) -> 0
C31: Net Loss | E31: =+E27+E29 -> -17337808 | G31: =+G27+G29 -> -17338

Sheet BS ILS
C1: Wematch.live
C2: USD
E5: R&D
E6: 31.12.2023 | G6: in 000' | I6: NOTE
B7: INDEX
C8: Assets | G8: =+E8/1000 -> 0
C10: Current Assets: | G10: =+E10/1000 -> 0
B11: 10 | C11: Cash and cash equivalent | E11: =+SUMIF('WRD Solo BS'!$C$7:$C$154,B11,'WRD Solo BS'!$B$7:$B$154) -> 22763397 | G11: =+ROUND((E11/1000),0)+1 -> 22764
B12: 11 | C12: Short term restricted deposits | E12: =+SUMIF('WRD Solo BS'!$C$7:$C$154,B12,'WRD Solo BS'!$B$7:$B$154) -> 39137419 | G12: =+ROUND((E12/1000),0)+1 -> 39138
B13: 12 | C13: Trade recievables | E13: =+SUMIF('WRD Solo BS'!$C$7:$C$154,B13,'WRD Solo BS'!$B$7:$B$154) -> 6718863.5 | G13: =+ROUND((E13/1000),0)-1 -> 6718 | I13: =+'NOTES-Conso'!B5 -> 3
B14: 13 | C14: other recievables and prepaid expenses | E14: =+SUMIF('WRD Solo BS'!$C$7:$C$154,B14,'WRD Solo BS'!$B$7:$B$154) -> 1047905.9 | G14: =+ROUND((E14/1000),0)-1 -> 1047
B15: 13.5 | C15: intercompany | E15: =+SUMIF('WRD Solo BS'!$C$7:$C$154,B15,'WRD Solo BS'!$B$7:$B$154) -> 16483008 | G15: =+'NOTES-Solo'!E69 -> 3620 | I15: =+'NOTES-Conso'!B10 -> 4
G16: =+E16/1000 -> 0
C17: Total cerrent assets | E17: =+SUM(E11:E15) -> 86150593 | G17: =+SUM(G11:G15) -> 73287
G18: =+E18/1000 -> 0
C20: Long-Term assets:
B21: 14 | C21: loans to employees | E21: =+SUMIF('WRD Solo BS'!$C$7:$C$154,B21,'WRD Solo BS'!$B$7:$B$154) -> 0 | G21: =+ROUND((E21/1000),0) -> 0
B22: 15 | C22: property and equipment | E22: =+SUMIF('WRD Solo BS'!$C$7:$C$154,B22,'WRD Solo BS'!$B$7:$B$154) -> 183362.48 | G22: =+ROUND((E22/1000),0) -> 183 | I22: =+'NOTES-Solo'!B15 -> 5
C25: Total Long-term assets | E25: =+E21+E22 -> 183362.48 | G25: =+ROUND(E25/1000,0) -> 183
C28: Total assets | E28: =+E25+E17 -> 86333955 | G28: =+G25+G17 -> 73470
G30: =+E30/1000 -> 0
C31: Liabilities and shareholders' equity
C33: Current Liabilities:
B35: 16 | C35: Trade payables | E35: =+SUMIF('WRD Solo BS'!$C$7:$C$154,B35,'WRD Solo BS'!$B$7:$B$154) -> 510409.23 | G35: =+ROUND((E35/1000),0) -> 510
B36: 16.1 | C36: Intercompany | E36: =+SUMIF('WRD Solo BS'!$C$7:$C$154,B36,'WRD Solo BS'!$B$7:$B$154)/1000 -> 13044.607 | G36: =-'NOTES-Solo'!E76 -> 181.51692 | I36: =+'NOTES-Conso'!B27 -> 6
B37: 17 | C37: Accrued expenses and other liabilities | E37: =+SUMIF('WRD Solo BS'!$C$7:$C$154,B37,'WRD Solo BS'!$B$7:$B$154) -> 2278915.2 | G37: =+ROUND((E37/1000),0) -> 2279
C39: Total current liabilities | E39: =+E37+E35+E36 -> 2802369.1 | G39: =+G37+G35+G36 -> 2970.5169
C41: Non current Liabilities:
B43: 18 | C43: Long-Term liabilities: | E43: =+SUMIF('WRD Solo BS'!$C$7:$C$154,B43,'WRD Solo BS'!$B$7:$B$154) -> 1456834.9 | G43: =+SUMIF('WRD Solo BS'!$C$7:$C$154,B43,'WRD Solo BS'!$B$7:$B$154)/1000 -> 1456.8349
C45: Shareholders equity
B47: 19 | C47: additrional paid in capital | E47: =+SUMIF('WRD Solo BS'!$C$7:$C$154,B47,'WRD Solo BS'!$B$7:$B$154) -> 1.3144118e+08 | G47: =+ROUND((E47/1000),0) -> 131441 | H47: =+G47-'Change in Equity ILS'!H19 -> 51.25492
B48: 20 | C48: Recievable on share account | E48: =+SUMIF('WRD Solo BS'!$C$7:$C$154,B48,'WRD Solo BS'!$B$7:$B$154) -> 0 | G48: =+ROUND((E48/1000),0) -> 0
B49: 21 | C49: Accumulated deficit | E49: =+SUMIF('WRD Solo BS'!$C$7:$C$154,B49,'WRD Solo BS'!$B$7:$B$154) -> -62397988 | G49: =+ROUND((E49/1000),0)+ROUND(E47/1000,0)-G47 -> -62398
C51: Total shareholders equity | E51: =+SUM(E47:E49) -> 69043189 | G51: =+SUM(G47:G49) -> 69043
C53: Total liabilities and shareholders' equity | E53: =+E51+E43+E39 -> 73302393 | G53: =+G51+G43+G39 -> 73470.352
C55: check | E55: =+E53-E28 -> -13031562 | G55: =+G53-G28 -> 0.35185

Sheet WRD Solo P&L
A1: Wematch.live R&D LTD
A2: Wematch.live R&D LTD
A3: WM INCOME STATEMENT | H3: This report doesn't include intercompany transactions
A4: From Jan 2022 to Dec 2022 | H4: download them from report: Income statement-->Account 60002
A7: Financial Row | B7: Amount
A8: Gross Income
A9: - No Class - | B9: -291319.42
A10: TRS | B10: 19366160
A11: SBL | B11: 1316300.2
A12: Securities Financing | B12: -289116.71
A13: Interest rate | B13: 1566131
A14: Equity Derivative | B14: 986699.3
A15: Total Gross Income | B15: =SUM(B9:B14) -> 22654854 | C15: 1
A16: Revenue Shared With Regulated Broker Dealer
A17: 45000 - Revenues shared to third parties
A18: 45002 - Commission Shared with third party | B18: -2291594.3 | C18: 2.1
A19: 45001 - IS IN | B19: -217430.61 | C19: 2.1
A20: 45003 - Non Reclaimable VAT | B20: -566840.57 | C20: 2.1
A21: Total - 45000 - Revenues shared to third parties | B21: =SUM(B18:B20) -> -3075865.5 | C21: 2
A22: Total Revenue Shared With Regulated Broker Dealer | B22: =SUM(B21) -> -3075865.5
A23: Net Income | B23: =+B15+B22 -> 19578989
A24: Cost Of Sales
A25: 50000 - COGS expenses
A26: 50100 - Payroll and Related expenses [COGS]
A27: 50101 - COGS Gross Salaries | B27: -1418426.1
A28: 50108 - COGS Employee stock-based compensation | B28: -5096.32
A29: Total - 50100 - Payroll and Related expenses [COGS] | B29: =SUM(B27:B28) -> -1423522.4 | C29: 2.2
A30: 50400 - COGS Hosting
A31: 50402 - AWS | B31: -732235.83
A32: 50401 - COGS Hosting exp. | B32: -207326.05
A33: Total - 50400 - COGS Hosting | B33: =SUM(B31:B32) -> -939561.88 | C33: 2.2
A34: 50300 - COGS Tools/ Systems
A35: 50301 - COGS Tools | B35: -547331.41
A36: Total - 50300 - COGS Tools/ Systems | B36: =SUM(B35) -> -547331.41 | C36: 2.2
A37: 51110 - Recruiting Fees
A38: 51110 - Recruiting Fees | B38: -11935.02
A39: Total - 51110 - Recruiting Fees | B39: =SUM(B38) -> -11935.02 | C39: 2.2
A40: Total - 50000 - COGS expenses | B40: =SUM(B29,B33,B36,B39) -> -2922350.7
A41: Total - Cost Of Sales | B41: =SUM(B40) -> -2922350.7 | C41: 2
A42: Gross Profit | B42: =B23+B41 -> 16656638
...

Sheet WRD Solo BS
A1: Wematch.live R&D LTD
A2: Wematch.live R&D LTD
A3: Balance Sheet
A4: End of Dec 2022
A7: Financial Row | B7: Amount
A8: Current Assets
A9: Bank
A10: 10000 - Cash and Cash Equivalent (WRD-IL)
A11: 10001 - Bank Fibi 327492 NIS | B11: 347754.07
A12: 10002 - Bank Hapoalim 120737 NIS | B12: 648131.34
A13: 10003 - Bank Hapoalim 120737 USD | B13: 21568727
A14: 10004 - Bank Hapoalim 120737 GBP | B14: 41070.08
A15: 10005 - Bank Hapoalim 120737 EUR | B15: 59093.11
A16: Total - 10000 - Cash and Cash Equivalent (WRD-IL) | B16: =SUM(B11:B15) -> 22664776 | C16: 10
A17: 11000 - Short-term Restricted cash
A18: 11001 - Bank Hapoalim Deposit NIS | B18: 60130.82
A19: 11002 - Bank FIBI Deposit NIS | B19: 10054.45
A20: 11003 - Bank FIBI Deposit EUR | B20: 28435.63
A21: Total - 11000 - Short-term Restricted cash | B21: =SUM(B18:B20) -> 98620.9 | C21: 10
A22: 11100 - Short term Bank Deposit
A23: 11101 - Short term Bank Deposit [BANK HAPOALIM] | B23: 39137419 | C23: 11
A24: Total - 11100 - Short term Bank Deposit | B24: =SUM(B23) -> 39137419
A25: Total Bank | B25: =SUM(B16,B21,B24) -> 61900816
A26: Accounts Receivable
A27: 12000 - Accounts Receivable
A28: 12001 - Accounts Receivable | B28: 5733182.8
A29: 12002 - Accounts Receivable - Customers offset | B29: -166571.4
A30: Total - 12000 - Accounts Receivable | B30: =SUM(B28:B29) -> 5566611.4 | C30: 12
A31: Total Accounts Receivable | B31: =SUM(B30) -> 5566611.4
A32: Other Current Asset
A33: 12004 - Unbilled Revenue | B33: 1152252.1 | C33: 12
A34: 12600 - Intercompany (O.C Assets)
A35: 12601 - WeMatch.Securitiesfinancing Ltd. [P] | B35: 9554851.5 | C35: 13.5.1
A36: 12602 - WeMatch.Live Tech Support Europe [P] | B36: 3041990.8 | C36: 13.5.2
A37: 12603 - WeMatch Securities Financing Ltd. [P] | B37: 3486 | C37: 13.5.3
A38: 12606 - Wematch.Support US INC [P] | B38: 2964415.6 | C38: 13.5.4
A39: Total - 12600 - Intercompany (O.C Assets) | B39: =SUM(B35:B38) -> 15564744 | C39: 13.5
A40: 13000 - Prepaid Exp.
A41: 13001 - Prepaid Expenses | B41: 454510.24
A42: 13003 - Deferred Customer acquisition cost | B42: 329537.48
...

Sheet NOTES-Solo
D3: Balance Sheet Notes
B5: 3 | D5: Trade recievables | E5: =+SUMIF('Full BS-USD'!$M$9:$M$226,F5,'Full BS-USD'!$L$9:$L$226)/1000 -> 424.62305 | F5: 12.1
D6: Unbilled revenue | E6: =SUMIF('Full BS-USD'!$M$9:$M$226,F6,'Full BS-USD'!$L$9:$L$226)/1000-E5-1 -> 233.25907 | F6: 12
E7: =SUM(E5:E6) -> 657.88212
E8: =+E7-'BS USD'!S13 -> -1.11788
B10: 4 | D10: Prepaid expenses | E10: =+SUMIF('Full BS-USD'!$M$9:$M$226,F10,'Full BS-USD'!$L$9:$L$226)/1000 -> 273.23526 | F10: 13.1
D11: Government institutions | E11: =+SUMIF('Full BS-USD'!$M$9:$M$226,F11,'Full BS-USD'!$L$9:$L$226)/1000 -> 162.24782 | F11: 13.2
D12: Other current assts | E12: =SUMIF('Full BS-USD'!$M$9:$M$226,F12,'Full BS-USD'!$L$9:$L$226)/1000-E11-E10-'Full BS-USD'!L157/1000 -> 201.69305 | F12: 13
E13: =SUM(E10:E12) -> 637.17613
E14: =+E13-'BS USD'!S14 -> -21.82387
B15: 5 | D15: Cost:
D16: Computers & Software | E16: =+SUMIF('WRD Solo BS'!C7:C154,F16,'WRD Solo BS'!B7:B154)/1000 -> 397.05579 | F16: 15.1
D17: Office furniture | E17: =+SUMIF('WRD Solo BS'!C8:C155,F17,'WRD Solo BS'!B8:B155)/1000 -> 6.807 | F17: 15.2
D18: Leasehold improvements | E18: =+SUMIF('WRD Solo BS'!C9:C156,F18,'WRD Solo BS'!B9:B156)/1000 -> 9.2 | F18: 15.3
E19: =SUM(E16:E18) -> 413.06279
D21: Accumulated depritiation | E21: =+SUMIF('WRD Solo BS'!C12:C159,F21,'WRD Solo BS'!B12:B159)/1000 -> -229.70031 | F21: 15.4
D23: Preperty and equipment, net | E23: =+E19+E21 -> 183.36248
E24: =+E23-'BS ILS'!G22 -> 0.36248
B27: 6 | D27: Accrued employee compensation and benefits | E27: =+SUMIF('WRD Solo BS'!C18:C165,F27,'WRD Solo BS'!B18:B165)/1000 -> 1656.894 | F27: 17.1
C28: 23501 - Other Current Liability | D28: Accrued expenses | E28: =+SUMIF('WRD Solo BS'!C19:C166,F28,'WRD Solo BS'!B19:B166)/1000+VLOOKUP(C28,'WRD Solo BS'!$A$73:$B$136,2,0)/1000 -> 227.3206 | F28: 17.2
D29: Income and indirect tax payable | E29: =+SUMIF('WRD Solo BS'!C20:C167,F29,'WRD Solo BS'!B20:B167)/1000 -> 394.70063 | F29: 17.4
E30: =SUM(E27:E29) -> 2278.9152
E31: =+E30-'BS ILS'!G37 -> -0.08478
B33: 8 | D33: Share capital: | O33: Shareholders' equity
O35: 2022
E36: Authorized | F36: issued and outstanding | J36: Authorized | K36: issued and outstanding | O36: number of options | P36: weightes average excersise price
E37: December 31,2022 | J37: December 31,2021 | N37: Balance as of December 31,2021
D38: ordinary shares | E38: 3074000 | F38: 1223458 | J38: 3074000 | K38: 1220858 | N38: Granted
D39: ordinary A Shares | E39: 205000 | F39: 180881 | J39: 205000 | K39: 180881 | N39: Balance as of December 31,2022
D40: Preferred A shares (*) | E40: 651000 | F40: 641271 | J40: 651000 | K40: 514024 | N40: Excercisable as of December 31,2021
D41: preferred B shares (*) | E41: 1070000 | F41: 967678 | G41: =+K41 -> 967678 | H41: =+F41-G41 -> 0 | J41: 1070000 | K41: 967678 | L41: different from 2021 signed report
E42: =SUM(E38:E41) -> 5000000 | F42: =SUM(F38:F41) -> 3013288 | J42: =SUM(J38:J41) -> 5000000 | K42: =SUM(K38:K41) -> 2883441
K45: The information is taken from Carta- "Summery Cap Table" report
B47: 9 | D47: 12600 - Intercompany (O.C Assets)
D48: 12601 - WeMatch.Securitiesfinancing Ltd. [P] | E48: =+SUMIF('WRD Solo BS'!C7:C153,F48,'WRD Solo BS'!B7:B153)/1000 -> 9554.8515 | F48: 13.5.1
D49: 12602 - WeMatch.Live Tech Support Europe [P] | E49: =+SUMIF('WRD Solo BS'!C8:C154,F49,'WRD Solo BS'!B8:B154)/1000 -> 3041.9908 | F49: 13.5.2
D50: 12603 - WeMatch Securities Financing Ltd. [P] | E50: =+SUMIF('WRD Solo BS'!C9:C155,F50,'WRD Solo BS'!B9:B155)/1000 -> 3.486 | F50: 13.5.3
D51: 12606 - Wematch.Support US INC [P] | E51: =+SUMIF('WRD Solo BS'!C10:C156,F51,'WRD Solo BS'!B10:B156)/1000 -> 2964.4156 | F51: 13.5.4
C52: WIR | D52: 17001 - Interco Loans | E52: =918263.98/1000 -> 918.26398
E53: =SUM(E47:E52) -> 16483.008 | I53: =+E53-E61 -> 3438.4013
...

Sheet Full BS-USD (2)
A1: Wematch.live R&D LTD
A2: Wematch.live R&D LTD (Consolidated)
A3: Balance Sheet
A4: End of FY 2022
A7: Financial Row | B7: Elimination | C7: WEMATCH.SUPPORT US INC. | D7: Wematch EQD LTD | E7: Wematch Interest rate LTD | F7: Wematch Securities. Financing LTD [IL] | G7: Wematch.Securities Financing LTD | H7: Wematch.live R&D LTD | I7: Wematch.live Tech Support Europe | J7: Total | K7: INDEX
B8: Amount | C8: Amount | D8: Amount | E8: Amount | F8: Amount | G8: Amount | H8: Amount | I8: Amount | J8: Amount
A9: Current Assets
A10: Bank
A11: 10000 - Cash and Cash Equivalent (WRD-IL)
A12: 10001 - Bank Fibi 327492 NIS | B12: 0 | C12: 0 | D12: 0 | E12: 0 | F12: 0 | G12: 0 | H12: 98925.39 | I12: 0 | J12: =+IFERROR(VLOOKUP(A12,[1]BalanceSheet!A$8:B$154,2,0),0) -> 26151.22
A13: 10002 - Bank Hapoalim 120737 NIS | B13: 0 | C13: 0 | D13: 0 | E13: 0 | F13: 0 | G13: 0 | H13: 184319.33 | I13: 0 | J13: =+IFERROR(VLOOKUP(A13,[1]BalanceSheet!A$8:B$154,2,0),0) -> 344.4
A14: 10003 - Bank Hapoalim 120737 USD | B14: 0 | C14: 0 | D14: 0 | E14: 0 | F14: 0 | G14: 0 | H14: 6136719.3 | I14: 0 | J14: =+IFERROR(VLOOKUP(A14,[1]BalanceSheet!A$8:B$154,2,0),0) -> 26906064
A15: 10004 - Bank Hapoalim 120737 GBP | B15: 0 | C15: 0 | D15: 0 | E15: 0 | F15: 0 | G15: 0 | H15: 11685.56 | I15: 0 | J15: =+IFERROR(VLOOKUP(A15,[1]BalanceSheet!A$8:B$154,2,0),0) -> 5309.75
A16: 10005 - Bank Hapoalim 120737 EUR | B16: 0 | C16: 0 | D16: 0 | E16: 0 | F16: 0 | G16: 0 | H16: 16813.13 | I16: 0 | J16: =+IFERROR(VLOOKUP(A16,[1]BalanceSheet!A$8:B$154,2,0),0) -> 367423.66
A17: Total - 10000 - Cash and Cash Equivalent (WRD-IL) | B17: =SUM(B12:B16) -> 0 | C17: =SUM(C12:C16) -> 0 | D17: =SUM(D12:D16) -> 0 | E17: =SUM(E12:E16) -> 0 | F17: =SUM(F12:F16) -> 0 | G17: =SUM(G12:G16) -> 0 | H17: =SUM(H12:H16) -> 6448462.7 | I17: =SUM(I12:I16) -> 0 | J17: =+IFERROR(VLOOKUP(A17,[1]BalanceSheet!A$8:B$154,2,0),0) -> 27305293 | K17: 10
A18: 101 - Dummy USD [UK] | B18: 0 | C18: 0 | D18: 0 | E18: 0 | F18: 0 | G18: -0.01 | H18: 0 | I18: 0 | J18: =+IFERROR(VLOOKUP(A18,[1]BalanceSheet!A$8:B$154,2,0),0) -> 0
