Workbook
Name ___thinkcellH0YAAAAAAAAAAAAAAbeHRFzlWE2uPyH9A6Q3vA: '[1]Master List technology spli EPC'!$A$94:$H$100
Name ___thinkcellH0YAAAAAAAAAAAAAs6d8nGaIbUK8FJH9dh7DkA: '[1]Master List technology spli EPC'!$A$118:$H$124
Name ___thinkcellhkMAAAAAAAAAAAAA57beSTVytE2I7JqSMJDRqw: '[2]Evaluations master list (order)'!$B$18:$J$29
Name ___thinkcellhkMAAAAAAAAAAAAA7gglqEXtAUuFGRX83IhJHg: '[2]Evaluations master list (order)'!$B$49:$J$60
Name ___thinkcellhkMAAAAAAAAAAAAAA1OlPiG7vUyRVcey.zE4.A: '[2]Order year by technology'!$A$53:$G$60
Name ___thinkcellhkMAAAAAAAAAAAAAE9cDjjT78EGiGoFzh4BoJQ: '[2]Evaluation installation p. year'!$B$18:$J$29
Name ___thinkcellhkMAAAAAAAAAAAAAEmg5knyxEkumYODT3xUZvQ: '[2]Order year by technology'!$A$92:$G$99
Name ___thinkcellhkMAAAAAAAAAAAAAOVPfM9XMWkyNTmxP7c1ogQ: '[2]arab countries market'!$A$19:$H$30
Name ___thinkcellhkMAAAAAAAAAAAAAr5FRo9lrKESOsRa6pwZ6Bg: '[2]arab countries market'!$A$38:$H$49
Name ___thinkcellhkMAAAAAAAAAAAAAzvzDuBaOvUalz8oQYLRn9w: '[2]Order year by technology'!$A$82:$G$89
Name ___thinkcellJ0YAAAAAAAAAAAAAxxe2w0vIYkSwqa8CViiJMQ: '[3]Alignment with E O'!$C$120:$L$123
Name ___thinkcellM0YAAAAAAAAAAAAAGuVyKWbgm0ejNwDEIyQmkA: [4]Mix!#REF!
Name ___thinkcellM0YAAAAAAAAAAAAAYIORGssyX0y.C0TzDAVkSg: '[5]MW CSP market old-new'!$X$28:$AE$39
Name ___thinkcellM0YAAAAAAAABAAAAtU6bd5Iu8kaYiGYthvGSMA: [4]Mix!#REF!
Name ___thinkcellM0YAAAAAAAADAAAATfJU.3Wkd0uyHxwS.whxcg: '[4]Grafics Base'!#REF!
Name ___thinkcellM0YAAAAAAAAEAAAACkePQ7R9WEyWVDXXuP7rxQ: [4]Mix!#REF!
Name ___thinkcellNUMAAAAAAAAAAAAAHgEoWX6oDE6.igFHPsGu1w: '[6]High Growth'!$C$79:$F$85
Name ___thinkcellNUMAAAAAAAAAAAAAIHAYpfVrAUez_kl9E5ssXw: '[6]High Growth'!$C$68:$I$75
Name ___thinkcellNUMAAAAAAAAAAAAAPY1DxDuJ5k.TTl.AC9jLcw: '[6]High Growth'!$I$79:$L$85
Name ___thinkcellNUMAAAAAAAAAAAAAqat2s5B2Vk.JDGESv5MRgg: '[6]High Growth'!$C$78:$L$85
Name ___thinkcellNUMAAAAAAAABAAAAuS77Vn0yBEGHmXJ23nirYg: '[6]High Growth'!$C$68:$I$75
Name ___thinkcellNUMAAAEAAAAGAAAAbzZc6A_Px0ee7cWD5d.4cg: '[7]Overview incentive schemes'!$AD$147:$AG$170
Name ___thinkcellNUMAAAEAAAAGAAAAODW1t7nePUuNNcMPfPA2PA: '[7] TWh targets'!$N$3:$Q$39
Name ___thinkcellNUMAAAEAAAAGAAAAX6Cf49KrXUi..OiyrcHesQ: '[7] TWh targets'!$N$3:$Q$37
Name ___thinkcellNUYAAAAAAAAAAAAA4yIzjySHZkKlh2BSSzfi7g: [8]ER_EVA_ROCE!#REF!
Name ___thinkcellPkYAAAAAAAABAAAACfCgeAUy_0SCaTmpBKZuCA: '[9]Technology Split'!#REF!
Name ___thinkcellw0UAAAAAAAAAAAAA3kbAzw87l0uvbu92dkE79A: '[2]Order year by technology'!$A$92:$E$99
Name ___thinkcellw0UAAAAAAAAAAAAAc8D3Alwu2k2l_67NaHwtMg: '[2]Order year by techn. EPC update'!$A$82:$E$89
Name ___thinkcellykUAAAAAAAABAAAA9r94OUzIGk6hKuNZuf3xQA: [10]Bilder!$B$169:$C$175
Name ___thinkcellykUAAAAAAAABAAAAlK5PatKEZUGah_xHFk7jrQ: [10]Bilder!$D$169:$E$175
Name ___thinkcellykUAAAAAAAABAAAAsYrXHDHqaUqmY0d3tALWZg: [10]Bilder!$F$169:$G$175
Name __DCF1: {"Back Page",#N/A,FALSE,"Front and Back"}
Name __FDS_HYPERLINK_TOGGLE_STATE__: "ON"
Name __q2: {"Total1",#N/A,FALSE,"Total Summary";"Risk1",#N/A,FALSE,"Risks"}
Name _1_???: 0.17
Name _1__xlfn.COUNTIFS: #NAME?
Name _BvA: [11]pswzParams!$J$1
Name _DAT3: '[12]Anl 0.5'!#REF!
Name _DCF1: {"Back Page",#N/A,FALSE,"Front and Back"}
Name _GSRATES_1: "CT300001Latest "
Name _GSRATES_2: "H20070129Latest USDEUR1000001"
Name _GSRATES_3: "H20060711Latest EURUSD1000001"
Name _GSRATES_4: "H20051206Latest USDEUR1000001"
Name _GSRATES_5: "H20060307Latest GBPEUR1000001"
Name _GSRATES_6: "H20060714Latest GBPUSD1000001"
Name _GSRATES_7: "CT30000119980930 "
Name _GSRATES_8: "CT30000119980630 "
Name _GSRATES_9: "CT30000119980331 "
Name _GSRATES_COUNT: 1
Name _newDAT3: '[12]Anl 0.5'!#REF!
Name _Order1: 255
Name _Order2: 255
Name _q2: {"Total1",#N/A,FALSE,"Total Summary";"Risk1",#N/A,FALSE,"Risks"}
Name _Regression_Int: 1
Name a: {#N/A,#N/A,FALSE,"מאזן בוחן";"כל_מאזן_בוחן",#N/A,FALSE,"מאזן בוחן"}
Name a: {#N/A,#N/A,FALSE,"מאזן בוחן";"כל_מאזן_בוחן",#N/A,FALSE,"מאזן בוחן"}
Name a: {#N/A,#N/A,FALSE,"מאזן בוחן";"כל_מאזן_בוחן",#N/A,FALSE,"מאזן בוחן"}
Name a: {#N/A,#N/A,FALSE,"מאזן בוחן";"כל_מאזן_בוחן",#N/A,FALSE,"מאזן בוחן"}
Name a: {#N/A,#N/A,FALSE,"מאזן בוחן";"כל_מאזן_בוחן",#N/A,FALSE,"מאזן בוחן"}
Name aa: {#N/A,#N/A,FALSE,"מאזן";#N/A,#N/A,FALSE,"רווהפ";#N/A,#N/A,FALSE,"שינויים בהון";#N/A,#N/A,FALSE,"תזרים";#N/A,#N/A,FALSE,"נספח - התאמות";#N/A,#N/A,FALSE,"ני""ע לתזרים";#N/A,#N/A,FALSE,"פירוטים לדוחות"}

Sheet BOD Slides
B2: 45047
B4: P&L Summary | D4: Q1 2023 | E4: Q2 2023 | F4: Q3 2023 | G4: Q4 2023 | I4: Q2 2022 | M4: 2023 YTD
B5: US K$ | D5: Actual | E5: Actual | F5: Actual | G5: Actual | I5: Actual | J5: Budget | K5: Variance | M5: Actual | N5: Budget | O5: Variance
B6: Revenues | D6: -37 | E6: =FS!M79/1000-D6 -> -1450.1293 | F6: 0 | G6: 0 | I6: ='Actual vs Budget'!I14/1000 -> #ERROR! | J6: 0 | K6: =J6-I6 -> #ERROR! | M6: =('Actual vs Budget'!N14)*0 -> #ERROR! | N6: ='Actual vs Budget'!O14/1000 -> 0 | O6: =(N6-M6)/1000 -> #ERROR!
B7: COS | D7: 45 | E7: =FS!M87/1000-D7 -> 36.17857 | F7: 0 | G7: 0 | I7: =A7 | J7: 0 | K7: =J7-I7 -> 0 | M7: =('Actual vs Budget'!N15)*0 -> #ERROR! | N7: ='Actual vs Budget'!J15/1000 -> 0 | O7: =(N7-M7)/1000 -> #ERROR! | Q7: 0
B8: Gross loss | D8: 8 | E8: =E6+E7 -> -1413.9507 | F8: 0 | G8: 0 | I8: =I6 -> #ERROR! | J8: 0 | K8: =J8-I8 -> #ERROR! | M8: =(M6-M7)/1000 -> #ERROR! | N8: =N6-N7 -> 0 | O8: =O6-O7 -> #ERROR!
B9: Gross Margin (%) | D9: -0.2 | E9: =E8/E6 -> 0.97505149 | F9: 0 | I9: 1 | J9: 0 | K9: =K8/K6 -> #ERROR! | M9: =M8/M6*1000 -> #ERROR! | N9: =N8/N6 -> #DIV/0! | O9: =O8/O6 -> #ERROR!
B11: R&D | D11: 793 | E11: =FS!M110/1000-D11 -> 2661.69 | F11: 0 | G11: 0 | I11: ='Actual vs Budget'!I19/1000 -> #ERROR! | J11: ='Actual vs Budget'!J19/1000 -> 0 | K11: =J11-I11 -> #ERROR! | M11: =('Actual vs Budget'!N19/1000)*0 -> #ERROR! | N11: ='Actual vs Budget'!O19/1000 -> 0 | O11: =N11-M11 -> #ERROR!
B12: Sales / Customer Success | D12: 297 | E12: =FS!M129/1000-D12 -> 529.39082 | F12: 0 | G12: 0 | I12: ='Actual vs Budget'!I20/1000 -> #ERROR! | J12: ='Actual vs Budget'!J20/1000 -> 0 | K12: =J12-I12 -> #ERROR! | M12: =('Actual vs Budget'!N20/1000)*0 -> #ERROR! | N12: ='Actual vs Budget'!O20/1000 -> 0 | O12: =N12-M12 -> #ERROR!
B13: Marketing | D13: 135 | E13: =FS!M146/1000-D13 -> 2086.9726 | F13: 0 | G13: 0 | I13: ='Actual vs Budget'!I21/1000 -> #ERROR! | J13: ='Actual vs Budget'!J21/1000 -> 0 | K13: =J13-I13 -> #ERROR! | M13: =('Actual vs Budget'!N21/1000)*0 -> #ERROR! | N13: ='Actual vs Budget'!O21/1000 -> 0 | O13: =N13-M13 -> #ERROR!
B14: G&A | D14: 245 | E14: =FS!M187/1000-D14 -> 699.52116 | F14: 0 | G14: 0 | I14: ='Actual vs Budget'!I22/1000 -> #ERROR! | J14: ='Actual vs Budget'!J22/1000 -> 0 | K14: =J14-I14 -> #ERROR! | M14: =('Actual vs Budget'!N22/1000)*0 -> #ERROR! | N14: ='Actual vs Budget'!O22/1000 -> 0 | O14: =N14-M14 -> #ERROR!
B15: Developer Experiance | D15: 250 | E15: =FS!M164/1000-D15 -> 445.27785 | F15: 0 | G15: 0 | I15: ='Actual vs Budget'!I23/1000 -> #ERROR! | J15: ='Actual vs Budget'!J23/1000 -> 0 | K15: =J15-I15 -> #ERROR! | M15: =('Actual vs Budget'!N23/1000)*0 -> #ERROR! | N15: ='Actual vs Budget'!O23/1000 -> 0 | O15: =N15-M15 -> #ERROR!
B16: OPEX | D16: 1719 | E16: =SUM(E11:E15) -> 6422.8525 | F16: =(SUM(F11:F15))*0 -> 0 | G16: 0 | I16: =SUM(I11:I15) -> #ERROR! | J16: =SUM(J11:J15) -> 0 | K16: =SUM(K11:K15) -> #ERROR! | M16: =SUM(M11:M15) -> #ERROR! | N16: =SUM(N11:N15) -> 0 | O16: =SUM(O11:O15) -> #ERROR!
B17: EBITDA | D17: 1727 | E17: =E8+E16 -> 5008.9017 | F17: =F8-F16 -> 0 | I17: =I8-I16 -> #ERROR! | J17: =J8-J16 -> 0 | K17: =K8-K16 -> #ERROR! | M17: =M8-M16 -> #ERROR! | N17: =N8-N16 -> 0 | O17: =O8-O16 -> #ERROR!
B20: HC Summary | D20: =D4 -> Q1 2023 | E20: =E4 -> Q2 2023 | F20: =F4 -> Q3 2023 | G20: =G4 -> Q4 2023 | I20: =I4 -> Q2 2022 | M20: =M4 -> 2023 YTD
D21: Actual | E21: Actual | F21: Actual | G21: Actual | I21: Actual | J21: Budget | K21: Variance | M21: Actual | N21: Budget | O21: Variance
B23: R&D | D23: 16 | E23: ='Actual vs Budget'!D39 -> 16 | F23: 0 | G23: 0 | I23: =E23 -> 16 | J23: ='Actual vs Budget'!J39 -> 0 | K23: =I23-J23 -> 16 | M23: ='Actual vs Budget'!N39 -> 0 | N23: ='Actual vs Budget'!O39 -> 0 | O23: =M23-N23 -> 0
B24: Sales / Customer Success | D24: 2 | E24: ='Actual vs Budget'!D40 -> 2 | F24: 0 | G24: 0 | I24: =E24 -> 2 | J24: ='Actual vs Budget'!J40 -> 0 | K24: =I24-J24 -> 2 | M24: ='Actual vs Budget'!N40 -> 0 | N24: ='Actual vs Budget'!O40 -> 0 | O24: =M24-N24 -> 0
B25: Marketing | D25: 2 | E25: ='Actual vs Budget'!D41 -> 2 | F25: 0 | G25: 0 | I25: =E25 -> 2 | J25: ='Actual vs Budget'!J41 -> 0 | K25: =I25-J25 -> 2 | M25: ='Actual vs Budget'!N41 -> 0 | N25: ='Actual vs Budget'!O41 -> 0 | O25: =M25-N25 -> 0
B26: G&A | D26: 3 | E26: ='Actual vs Budget'!D42 -> 3 | F26: 0 | G26: 0 | I26: =E26 -> 3 | J26: ='Actual vs Budget'!J42 -> 0 | K26: =I26-J26 -> 3 | M26: ='Actual vs Budget'!N42 -> 0 | N26: ='Actual vs Budget'!O42 -> 0 | O26: =M26-N26 -> 0
B27: Developer Experiance | D27: 4 | E27: ='Actual vs Budget'!D43 -> 1 | F27: 0 | G27: 0 | I27: =E27 -> 1 | J27: ='Actual vs Budget'!J43 -> 0 | K27: =I27-J27 -> 1 | M27: ='Actual vs Budget'!N43 -> 0 | N27: ='Actual vs Budget'!O43 -> 0 | O27: =M27-N27 -> 0
B28: Total HC | D28: 27 | E28: =SUM(E23:E27) -> 24 | F28: =SUM(F23:F27) -> 0 | G28: 0 | I28: =SUM(I23:I27) -> 24 | J28: =SUM(J23:J27) -> 0 | K28: =SUM(K23:K27) -> 24 | M28: =SUM(M23:M27) -> 0 | N28: =SUM(N23:N27) -> 0 | O28: =SUM(O23:O27) -> 0
B30: Cash Flow Summary - K USD | D30: =D20 -> Q1 2023 | E30: =E20 -> Q2 2023 | F30: =F20 -> Q3 2023 | G30: =G20 -> Q4 2023 | I30: =I4 -> Q2 2022 | M30: =M20 -> 2023 YTD
D31: Actual | E31: Actual | F31: Actual | G31: Actual | I31: Actual | J31: Budget | K31: Variance | M31: Actual | N31: Budget | O31: Variance
B33: Cash at Beginning of Period | D33: 12394000 | E33: =D38 -> 10584334 | F33: 0 | G33: 0 | I33: ='Actual vs Budget'!I28 -> #REF! | J33: ='Actual vs Budget'!J28 -> #REF! | K33: =J33-I33 -> #REF! | M33: 0 | N33: 0 | O33: 0
B34: Net Operating Cash Flow | D34: -1854276.9 | E34: -1060663 | F34: 0 | G34: 0 | I34: ='Actual vs Budget'!I29 -> #REF! | J34: ='Actual vs Budget'!J29 -> #REF! | K34: =J34-I34 -> #REF! | M34: 0 | N34: 0 | O34: 0
B35: Total Capital Expenditure | D35: -8308.4582 | E35: -2517.2308 | F35: 0 | G35: 0 | I35: ='Actual vs Budget'!I30 -> #REF! | J35: ='Actual vs Budget'!J30 -> #REF! | K35: =J35-I35 -> #REF! | M35: 0 | N35: 0 | O35: 0
B36: Equity financing | D36: 52919.46 | E36: -5794 | F36: 0 | G36: 0 | I36: ='Actual vs Budget'!I31 -> #REF! | J36: ='Actual vs Budget'!J31 -> #REF! | K36: =J36-I36 -> #REF! | M36: 0 | N36: 0 | O36: 0
B37: Net Cash Inflow / (Outflow) | D37: =SUM(D34:D36) -> -1809665.9 | E37: =SUM(E34:E36) -> -1068974.2 | F37: 0 | G37: 0 | I37: =SUM(I34:I36) -> #REF! | J37: =SUM(J34:J36) -> #REF! | K37: =J37-I37 -> #REF! | M37: 0 | N37: 0 | O37: 0
B38: Cash End Of Period | D38: =D33+D37 -> 10584334 | E38: =E33+E37 -> 9515359.8 | F38: 0 | G38: 0 | I38: =I37+I33 -> #REF! | J38: =J33+J37 -> #REF! | K38: =K33+K37 -> #REF! | M38: =M33+M37 -> 0 | N38: =N33+N37 -> 0 | O38: =O33+O37 -> 0
B41: Opex Breakdown by Type - K USD | D41: =D30 -> Q1 2023 | E41: =E30 -> Q2 2023 | F41: =F30 -> Q3 2023 | G41: =G30 -> Q4 2023 | I41: =I30 -> Q2 2022 | M41: =M30 -> 2023 YTD
D42: Actual | E42: Actual | F42: Actual | G42: Actual | I42: Actual | J42: Budget | K42: Variance | M42: Actual | N42: Budget | O42: Variance
B44: Payroll | D44: 1250 | E44: =(FS!M94+FS!M113+FS!M132+FS!M151+FS!M167)/1000-D44 -> 2932.1099 | F44: 0 | G44: 0 | I44: ='Actual vs Budget'!I48 -> #ERROR! | J44: ='Actual vs Budget'!J48 | K44: =J44-I44 -> #ERROR! | M44: 0 | N44: 0 | O44: 0
B45: Recruiting | D45: 1 | E45: =(FS!M182)/1000-D45 -> 53.89842 | F45: 0 | G45: 0 | I45: ='Actual vs Budget'!I49 -> #ERROR! | J45: ='Actual vs Budget'!J49 | K45: =J45-I45 -> #ERROR! | M45: 0 | N45: 0 | O45: 0
B46: Bonus | D46: 132 | E46: =(FS!M114+FS!M152)/1000-D46 -> 22.48174 | F46: 0 | G46: 0 | I46: ='Actual vs Budget'!I50 -> #ERROR! | J46: ='Actual vs Budget'!J50 | K46: =J46-I46 -> #ERROR! | M46: 0 | N46: 0 | O46: 0
B47: Tools | D47: 54 | E47: =(FS!M100+FS!M116+FS!M134+FS!M153+FS!M169)/1000-E49-D47 -> 194.21811 | F47: 0 | G47: 0 | I47: ='Actual vs Budget'!I51 -> #ERROR! | J47: ='Actual vs Budget'!J51 | K47: =J47-I47 -> #ERROR! | M47: 0 | N47: 0 | O47: 0
B48: Hosting | D48: 103 | E48: =(FS!M82+FS!M108)/1000-D48 -> 278.70183 | F48: 0 | G48: 0 | I48: ='Actual vs Budget'!I52 -> #ERROR! | J48: ='Actual vs Budget'!J52 | K48: =J48-I48 -> #ERROR! | M48: 0 | N48: 0 | O48: 0
B49: HUBSPOT + site ground | D49: 4 | E49: =1.6+1.4+1.4-D49 -> 0.4 | F49: 0 | G49: 0 | I49: ='Actual vs Budget'!I54 -> #ERROR! | J49: ='Actual vs Budget'!J54 | K49: =J49-I49 -> #ERROR! | M49: 0 | N49: 0 | O49: 0
B50: Consultant | D50: 40 | E50: =(FS!M98+FS!M135+FS!M154+FS!M168)/1000-D50 -> 637.54752 | F50: 0 | G50: 0 | I50: ='Actual vs Budget'!I55 -> #ERROR! | J50: ='Actual vs Budget'!J55 | K50: =J50-I50 -> #ERROR! | M50: 0 | N50: 0 | O50: 0
B51: Travel | D51: 29 | E51: =(FS!M97+FS!M118+FS!M137+FS!M155+FS!M172)/1000-D51 -> 106.51198 | F51: 0 | G51: 0 | I51: ='Actual vs Budget'!I56 -> #ERROR! | J51: ='Actual vs Budget'!J56 | K51: =J51-I51 -> #ERROR! | M51: 0 | N51: 0 | O51: 0
...

Sheet Actual vs Budget
A2: Errors in this sheet: | H2: =#REF! -> #REF!
A3: =COUNTIF(D26:O26,"error")+COUNTIF(D35:O35,"error")+COUNTIF(D45:O45,"error")+COUNTIF(D73:O73,"error") -> 0 | C3: Actual vs Budget | H3: Actual vs Budget
A4: General errors in file:
A5: =A3+#REF!+#REF!+#REF!+#REF!+#REF!+#REF!+#REF!+#REF!+#REF! -> #REF!
A6: Scale | C6: Month $ | D6: 45047 | H6: ="Quarter "&$A$7 -> #REF! | I6: Q1-23 | M6: =$A$7&" YTD "&YEAR(month_of_report) -> #REF! | N6: 2023
A7: =#REF! -> #REF! | D7: Actual | E7: Budget | F7: Variance | I7: Actual | J7: Budget | K7: Variance | N7: Actual | O7: Budget | P7: Variance
A8: =IF(A7="$",1,IF(A7="$k",1000,1000000)) -> #REF! | C8: KPI | H8: =C8 -> KPI | M8: =H8 -> KPI
C9: KPI | H9: =C9 -> KPI | M9: =H9 -> KPI
C10: MRR | H10: =C10 -> MRR | M10: =H10 -> MRR
C11: ARR | H11: =C11 -> ARR | M11: =H11 -> ARR
C13: P&L Summary $ | H13: =C13 -> P&L Summary $ | M13: =H13 -> P&L Summary $
A14: 1 | C14: Revenues | D14: =-FS!#REF! -> #ERROR! | E14: 14792 | F14: =D14-E14 -> #ERROR! | H14: =C14 -> Revenues | I14: =D14 -> #ERROR! | K14: =IFERROR(INDEX(#REF!,MATCH($A14,#REF!,0),),0)/$A$8 -> #REF! | M14: =H14 -> Revenues | N14: =I14 -> #ERROR! | P14: =IFERROR(INDEX(#REF!,MATCH($A14,#REF!,0),),0)/$A$8 -> #REF!
A15: 2 | C15: Cost of Sales | D15: =FS!#REF! -> #ERROR! | E15: 8400 | F15: =D15-E15 -> #ERROR! | H15: =C15 -> Cost of Sales | I15: =D15 -> #ERROR! | K15: =IFERROR(INDEX(#REF!,MATCH($A15,#REF!,0),),0)/$A$8 -> #REF! | M15: =H15 -> Cost of Sales | N15: =I15 -> #ERROR! | P15: =IFERROR(INDEX(#REF!,MATCH($A15,#REF!,0),),0)/$A$8 -> #REF!
C16: Gross profit | D16: =D14-D15 -> #ERROR! | E16: 6392 | F16: =D16-E16 -> #ERROR! | H16: =C16 -> Gross profit | I16: =I14-I15 -> #ERROR! | J16: =J14-J15 -> 0 | K16: =K14+K15 -> #REF! | M16: =H16 -> Gross profit | N16: =N14-N15 -> #ERROR! | O16: =O14-O15 -> 0 | P16: =P14+P15 -> #REF!
C17: Gross margin | D17: =IFERROR(+D16/D14,0) -> 0 | E17: 0.43212547 | F17: =IFERROR(+F16/F14,0) -> 0 | H17: =C17 -> Gross margin | I17: =IFERROR(+I16/I14,0) -> 0 | J17: =IFERROR(+J16/J14,0) -> 0 | K17: =IFERROR(+K16/K14,0) -> 0 | M17: =H17 -> Gross margin | N17: =IFERROR(+N16/N14,0) -> 0 | O17: =IFERROR(+O16/O14,0) -> 0 | P17: =IFERROR(+P16/P14,0) -> 0
C18: Opex: | H18: =C18 -> Opex: | M18: =H18 -> Opex:
A19: =#REF! -> #REF! | C19: R&D | D19: =FS!#REF! -> #ERROR! | E19: 253251 | F19: =D19-E19 -> #ERROR! | H19: =C19 -> R&D | I19: =D19 -> #ERROR! | K19: =IFERROR(INDEX(#REF!,MATCH($A19,#REF!,0),),0)/$A$8 -> #REF! | M19: =H19 -> R&D | N19: =I19 -> #ERROR! | P19: =IFERROR(INDEX(#REF!,MATCH($A19,#REF!,0),),0)/$A$8 -> #REF!
A20: =#REF! -> #REF! | C20: Sales / Customer Success | D20: =FS!#REF! -> #ERROR! | E20: 67047 | F20: =D20-E20 -> #ERROR! | H20: =C20 -> Sales / Customer Success | I20: =D20 -> #ERROR! | K20: =IFERROR(INDEX(#REF!,MATCH($A20,#REF!,0),),0)/$A$8 -> #REF! | M20: =H20 -> Sales / Customer Success | N20: =I20 -> #ERROR! | P20: =IFERROR(INDEX(#REF!,MATCH($A20,#REF!,0),),0)/$A$8 -> #REF!
A21: =#REF! -> #REF! | C21: Marketing | D21: =FS!#REF! -> #ERROR! | E21: 40926.286 | F21: =D21-E21 -> #ERROR! | H21: =C21 -> Marketing | I21: =D21 -> #ERROR! | K21: =IFERROR(INDEX(#REF!,MATCH($A21,#REF!,0),),0)/$A$8 -> #REF! | M21: =H21 -> Marketing | N21: =I21 -> #ERROR! | P21: =IFERROR(INDEX(#REF!,MATCH($A21,#REF!,0),),0)/$A$8 -> #REF!
A22: =#REF! -> #REF! | C22: G&A | D22: =FS!#REF! -> #ERROR! | E22: 117416.08 | F22: =D22-E22 -> #ERROR! | H22: =C22 -> G&A | I22: =D22 -> #ERROR! | K22: =IFERROR(INDEX(#REF!,MATCH($A22,#REF!,0),),0)/$A$8 -> #REF! | M22: =H22 -> G&A | N22: =I22 -> #ERROR! | P22: =IFERROR(INDEX(#REF!,MATCH($A22,#REF!,0),),0)/$A$8 -> #REF!
A23: =#REF! -> #REF! | C23: Developer Experiance | D23: =FS!#REF! -> #ERROR! | E23: 62624.833 | F23: =D23-E23 -> #ERROR! | H23: =C23 -> Developer Experiance | I23: =D23 -> #ERROR! | K23: =IFERROR(INDEX(#REF!,MATCH($A23,#REF!,0),),0)/$A$8 -> #REF! | M23: =H23 -> Developer Experiance | N23: =I23 -> #ERROR! | P23: =IFERROR(INDEX(#REF!,MATCH($A23,#REF!,0),),0)/$A$8 -> #REF!
C24: Total OPEX | D24: =SUM(D19:D23) -> #ERROR! | E24: 585054.65 | F24: =D24-E24 -> #ERROR! | H24: =C24 -> Total OPEX | I24: =SUM(I19:I23) -> #ERROR! | J24: =SUM(J19:J23) -> 0 | K24: =SUM(K19:K23) -> #REF! | M24: =H24 -> Total OPEX | N24: =SUM(N19:N23) -> #ERROR! | O24: =SUM(O19:O23) -> 0 | P24: =SUM(P19:P23) -> #REF!
C25: EBITDA | D25: =D16-D24 -> #ERROR! | E25: -578662.65 | F25: =D25-E25 -> #ERROR! | H25: =C25 -> EBITDA | I25: =I16-I24 -> #ERROR! | J25: =J16-J24 -> 0 | K25: =K16+K24 -> #REF! | M25: =H25 -> EBITDA | N25: =N16-N24 -> #ERROR! | O25: =O16-O24 -> 0 | P25: =P16+P24 -> #REF!
I26: =IF(ROUND(I24*$A$8,0)=ROUND(#REF!,0),"","Error") -> #ERROR! | J26: =IF(ROUND(J24*$A$8,0)=ROUND(#REF!,0),"","Error") -> #REF! | N26: =IF(ROUND(N24*$A$8,0)=ROUND(#REF!,0),"","Error") -> #ERROR! | O26: =IF(ROUND(O24*$A$8,0)=ROUND(#REF!,0),"","Error") -> #REF!
C27: Cash flow $ | D27: =D7 -> Actual | E27: =E7 -> Budget | F27: =F7 -> Variance | H27: =C27 -> Cash flow $ | I27: =I7 -> Actual | J27: =J7 -> Budget | K27: =K7 -> Variance | M27: =H27 -> Cash flow $ | N27: =N7 -> Actual | O27: =O7 -> Budget | P27: =P7 -> Variance
C28: Cash at Beginning of Period | D28: 10006986 | E28: 9890000 | F28: =D28-E28 -> 116985.9 | H28: =C28 -> Cash at Beginning of Period | I28: =INDEX(#REF!,MATCH($C28,#REF!,0))/$A$8 -> #REF! | J28: =INDEX(#REF!,MATCH($C28,#REF!,0))/$A$8 -> #REF! | K28: =INDEX(#REF!,MATCH($C28,#REF!,0))/$A$8 -> #REF! | M28: =H28 -> Cash at Beginning of Period | N28: =INDEX(#REF!,MATCH($C28,#REF!,0))/$A$8 -> #REF! | O28: =INDEX(#REF!,MATCH($C28,#REF!,0))/$A$8 -> #REF! | P28: =INDEX(#REF!,MATCH($C28,#REF!,0))/$A$8 -> #REF!
C29: Net Operating Cash Flow | D29: -488560 | E29: -590921.32 | F29: =D29-E29 -> 102361.32 | H29: =C29 -> Net Operating Cash Flow | I29: =INDEX(#REF!,MATCH($C29,#REF!,0))/$A$8 -> #REF! | J29: =INDEX(#REF!,MATCH($C29,#REF!,0))/$A$8 -> #REF! | K29: =INDEX(#REF!,MATCH($C29,#REF!,0))/$A$8 -> #REF! | M29: =H29 -> Net Operating Cash Flow | N29: =INDEX(#REF!,MATCH($C29,#REF!,0))/$A$8 -> #REF! | O29: =INDEX(#REF!,MATCH($C29,#REF!,0))/$A$8 -> #REF! | P29: =INDEX(#REF!,MATCH($C29,#REF!,0))/$A$8 -> #REF! | R29: על פי תקציב חדש 6.23
C30: Total Capital Expenditure | D30: 0 | E30: 0 | F30: =D30-E30 -> 0 | H30: =C30 -> Total Capital Expenditure | I30: =INDEX(#REF!,MATCH($C30,#REF!,0))/$A$8 -> #REF! | J30: =INDEX(#REF!,MATCH($C30,#REF!,0))/$A$8 -> #REF! | K30: =INDEX(#REF!,MATCH($C30,#REF!,0))/$A$8 -> #REF! | M30: =H30 -> Total Capital Expenditure | N30: =INDEX(#REF!,MATCH($C30,#REF!,0))/$A$8 -> #REF! | O30: =INDEX(#REF!,MATCH($C30,#REF!,0))/$A$8 -> #REF! | P30: =INDEX(#REF!,MATCH($C30,#REF!,0))/$A$8 -> #REF!
C31: Total Financing | D31: -2979 | E31: 0 | F31: =D31-E31 -> -2979 | H31: =C31 -> Total Financing | I31: =INDEX(#REF!,MATCH($C31,#REF!,0))/$A$8 -> #REF! | J31: =INDEX(#REF!,MATCH($C31,#REF!,0))/$A$8 -> #REF! | K31: =INDEX(#REF!,MATCH($C31,#REF!,0))/$A$8 -> #REF! | M31: =H31 -> Total Financing | N31: =INDEX(#REF!,MATCH($C31,#REF!,0))/$A$8 -> #REF! | O31: =INDEX(#REF!,MATCH($C31,#REF!,0))/$A$8 -> #REF! | P31: =INDEX(#REF!,MATCH($C31,#REF!,0))/$A$8 -> #REF!
C32: Taxation Paid | D32: 0 | E32: 0 | F32: =D32-E32 -> 0 | H32: =C32 -> Taxation Paid | I32: =INDEX(#REF!,MATCH($C32,#REF!,0))/$A$8 -> #REF! | J32: =INDEX(#REF!,MATCH($C32,#REF!,0))/$A$8 -> #REF! | K32: =INDEX(#REF!,MATCH($C32,#REF!,0))/$A$8 -> #REF! | M32: =H32 -> Taxation Paid | N32: =INDEX(#REF!,MATCH($C32,#REF!,0))/$A$8 -> #REF! | O32: =INDEX(#REF!,MATCH($C32,#REF!,0))/$A$8 -> #REF! | P32: =INDEX(#REF!,MATCH($C32,#REF!,0))/$A$8 -> #REF!
C33: Net Cash Inflow / (Outflow) | D33: =SUM(D29:D32) -> -491539 | E33: =SUM(E29:E32) -> -590921.32 | F33: =D33-E33 -> 99382.316 | H33: =C33 -> Net Cash Inflow / (Outflow) | I33: =INDEX(#REF!,MATCH($C33,#REF!,0))/$A$8 -> #REF! | J33: =INDEX(#REF!,MATCH($C33,#REF!,0))/$A$8 -> #REF! | K33: =INDEX(#REF!,MATCH($C33,#REF!,0))/$A$8 -> #REF! | M33: =H33 -> Net Cash Inflow / (Outflow) | N33: =INDEX(#REF!,MATCH($C33,#REF!,0))/$A$8 -> #REF! | O33: =INDEX(#REF!,MATCH($C33,#REF!,0))/$A$8 -> #REF! | P33: =INDEX(#REF!,MATCH($C33,#REF!,0))/$A$8 -> #REF!
C34: Cash End Of Period | D34: =D28+D33 -> 9515446.9 | E34: =E28+E33 -> 9299078.7 | F34: =F28+F33 -> 216368.21 | H34: =C34 -> Cash End Of Period | I34: =INDEX(#REF!,MATCH($C34,#REF!,0))/$A$8 -> #REF! | J34: =INDEX(#REF!,MATCH($C34,#REF!,0))/$A$8 -> #REF! | K34: =INDEX(#REF!,MATCH($C34,#REF!,0))/$A$8 -> #REF! | M34: =H34 -> Cash End Of Period | N34: =INDEX(#REF!,MATCH($C34,#REF!,0))/$A$8 -> #REF! | O34: =INDEX(#REF!,MATCH($C34,#REF!,0))/$A$8 -> #REF! | P34: =INDEX(#REF!,MATCH($C34,#REF!,0))/$A$8 -> #REF!
I35: =IF(ROUND(I34*$A$8,0)=ROUND(#REF!,0),"","Error") -> #REF! | J35: =IF(ROUND(J34*$A$8,0)=ROUND(#REF!,0),"","Error") -> #REF! | N35: =IF(ROUND(N34*$A$8,0)=ROUND(#REF!,0),"","Error") -> #REF! | O35: =IF(ROUND(O34*$A$8,0)=ROUND(#REF!,0),"","Error") -> #REF!
C37: HC | D37: =D6 -> 45047 | H37: =C37 -> HC | I37: =I6 -> Q1-23 | M37: =H37 -> HC | N37: =N6 -> 2023
D38: =D7 -> Actual | E38: =E7 -> Budget | F38: =F7 -> Variance | I38: =I7 -> Actual | J38: =J7 -> Budget | K38: =K7 -> Variance | N38: =N7 -> Actual | O38: =O7 -> Budget | P38: =P7 -> Variance
A39: =#REF! -> #REF! | C39: =C19 -> R&D | D39: 16 | E39: 16 | F39: =D39-E39 -> 0 | H39: R&D | I39: =IFERROR(INDEX(#REF!,MATCH($A39,#REF!,0),),0) -> 0 | J39: =IFERROR(INDEX(#REF!,MATCH($A39,#REF!,0),),0) -> 0 | K39: =IFERROR(INDEX(#REF!,MATCH($A39,#REF!,0),),0) -> 0 | M39: =H39 -> R&D | N39: =IFERROR(INDEX(#REF!,MATCH($A39,#REF!,0),),0) -> 0 | O39: =IFERROR(INDEX(#REF!,MATCH($A39,#REF!,0),),0) -> 0 | P39: =IFERROR(INDEX(#REF!,MATCH($A39,#REF!,0),),0) -> 0
A40: =#REF! -> #REF! | C40: =C20 -> Sales / Customer Success | D40: 2 | E40: 2 | F40: =D40-E40 -> 0 | H40: Sales / Customer Success | I40: =IFERROR(INDEX(#REF!,MATCH($A40,#REF!,0),),0) -> 0 | J40: =IFERROR(INDEX(#REF!,MATCH($A40,#REF!,0),),0) -> 0 | K40: =IFERROR(INDEX(#REF!,MATCH($A40,#REF!,0),),0) -> 0 | M40: =H40 -> Sales / Customer Success | N40: =IFERROR(INDEX(#REF!,MATCH($A40,#REF!,0),),0) -> 0 | O40: =IFERROR(INDEX(#REF!,MATCH($A40,#REF!,0),),0) -> 0 | P40: =IFERROR(INDEX(#REF!,MATCH($A40,#REF!,0),),0) -> 0
A41: =#REF! -> #REF! | C41: =C21 -> Marketing | D41: 2 | E41: 2 | F41: =D41-E41 -> 0 | H41: Marketing | I41: =IFERROR(INDEX(#REF!,MATCH($A41,#REF!,0),),0) -> 0 | J41: =IFERROR(INDEX(#REF!,MATCH($A41,#REF!,0),),0) -> 0 | K41: =IFERROR(INDEX(#REF!,MATCH($A41,#REF!,0),),0) -> 0 | M41: =H41 -> Marketing | N41: =IFERROR(INDEX(#REF!,MATCH($A41,#REF!,0),),0) -> 0 | O41: =IFERROR(INDEX(#REF!,MATCH($A41,#REF!,0),),0) -> 0 | P41: =IFERROR(INDEX(#REF!,MATCH($A41,#REF!,0),),0) -> 0
A42: =#REF! -> #REF! | C42: =C22 -> G&A | D42: 3 | E42: 3 | F42: =D42-E42 -> 0 | H42: G&A | I42: =IFERROR(INDEX(#REF!,MATCH($A42,#REF!,0),),0) -> 0 | J42: =IFERROR(INDEX(#REF!,MATCH($A42,#REF!,0),),0) -> 0 | K42: =IFERROR(INDEX(#REF!,MATCH($A42,#REF!,0),),0) -> 0 | M42: =H42 -> G&A | N42: =IFERROR(INDEX(#REF!,MATCH($A42,#REF!,0),),0) -> 0 | O42: =IFERROR(INDEX(#REF!,MATCH($A42,#REF!,0),),0) -> 0 | P42: =IFERROR(INDEX(#REF!,MATCH($A42,#REF!,0),),0) -> 0
A43: =#REF! -> #REF! | C43: =C23 -> Developer Experiance | D43: 1 | E43: 1 | F43: =D43-E43 -> 0 | H43: Developer Experiance | I43: =IFERROR(INDEX(#REF!,MATCH($A43,#REF!,0),),0) -> 0 | J43: =IFERROR(INDEX(#REF!,MATCH($A43,#REF!,0),),0) -> 0 | K43: =IFERROR(INDEX(#REF!,MATCH($A43,#REF!,0),),0) -> 0 | M43: =H43 -> Developer Experiance | N43: =IFERROR(INDEX(#REF!,MATCH($A43,#REF!,0),),0) -> 0 | O43: =IFERROR(INDEX(#REF!,MATCH($A43,#REF!,0),),0) -> 0 | P43: =IFERROR(INDEX(#REF!,MATCH($A43,#REF!,0),),0) -> 0
...

Sheet Reports
K1: =A10 | P1: =K1 | U1: =P1
G2: Balance Sheets | L2: =G2 -> Balance Sheets | Q2: Statements of operations
G3: USD in thousands | L3: =G3 -> USD in thousands | Q3: =L3 -> USD in thousands
T4: DRAFT
J5: DRAFT | O5: DRAFT | T5: For the period ended
J6: =WP_LTD!C9 -> 44926 | O6: =J6 -> 44926 | T6: =O6 -> 44926
J7: UNAUDITED | O7: =J7 -> UNAUDITED | T7: =O7 -> UNAUDITED
G9: CURRENT ASSETS | L9: CURRENT LIABILITIES | Q9: Revenues | T9: =-ROUND(FS!M79/1000,0) -> 1487
A10: =+WP_LTD!B3 | G10: Cash and short term deposit | J10: =ROUND(FS!M11/1000,0) -> 1795 | L10: Trade payables | O10: =-ROUND(FS!M37/1000,0)+1 -> 117 | Q10: Cost of revenues | T10: =ROUND(FS!M87/1000,0) -> 81 | X10: =T10/T9 -> 0.054472091
G11: Short-term Deposits | J11: =ROUND(FS!M13/1000,0) -> 7600 | L11: Employees and related | O11: =-ROUND(FS!M38/1000,0) -> 312 | Q11: Gross Profit/(Loss) | T11: =T9-T10 -> 1406 | X11: =T11/T9 -> 0.94552791
G12: Other account receivable & prepaid expenses | J12: =ROUND((FS!M14+FS!M17)/1000,0) -> 129 | L12: Other current liabilities | O12: =-ROUND((FS!M39)/1000,0) -> 11
G13: Total current assets | J13: =SUM(J10:J12) -> 9524 | L13: Total current liabilities | O13: =SUM(O10:O12) -> 440 | Q13: Operation Expenses:
Q14: Research and Development | T14: =ROUND(FS!M110/1000,0) -> 3455 | X14: =T14/$T$17 -> 0.66111749
A15: Unaudited financial statements | G15: NON-CURRENT ASSETS | L15: NON-CURRENT LIABILITIES | Q15: Sales and Marketing | T15: =ROUND(FS!M129/1000,0) -> 826 | X15: =T15/$T$17 -> 0.15805587
G16: Long-term Deposits | J16: =ROUND(FS!M21/1000,0) -> 34 | L16: Convertible Loan | O16: =-ROUND(FS!M41/1000,0) -> 0 | Q16: General and Administrative | T16: =ROUND(FS!M187/1000,0) -> 945 | X16: =T16/$T$17 -> 0.18082664
A17: =WP_LTD!B4 -> As of Dec 31, 2022 | G17: Property and equipment, NET | J17: =ROUND(FS!M28/1000,0) -> 295 | L17: Total Non-current liabilities | O17: =O16 -> 0 | Q17: Total Operating expenses | T17: =SUM(T14:T16) -> 5226
G18: Total Non-current assets | J18: =SUM(J16:J17) -> 329
D19: DRAFT
L20: SHAREHOLDERS EQUITY/(DEFICIENCY) | Q20: Loss From Operations | T20: =T17-T11 -> 3820
L22: Share capital & Additional paid-in capital | O22: =-ROUND((FS!M56+FS!M61+FS!M62+FS!M64)/1000,0) -> 22801 | Q22: Financial Expenses/(income) | T22: =ROUND(FS!M193/1000,0)-1 -> -11
L23: Accumulated profit/(loss) | O23: =-ROUND((FS!M65+FS!M66)/1000,0) -> -10728 | Q23: Other Expenses / (Income) | T23: =ROUND(FS!M194/1000,0) -> 0
L24: Total Shareholder's Equity/(deficiency) | O24: =SUM(O22:O23) -> 12073 | Q24: Tax Expenses | T24: =ROUND(FS!M194/1000,0) -> 0
G27: Total Assets | J27: =J13+J18 -> 9853 | L27: Total Liability and shareholders equity | O27: =O13+O24+O17 -> 12513 | Q27: Net Loss | T27: =T20+T22+T24 -> 3809
M29: =J27-O27 -> -2660
G35: Page 1 | L35: Page 2 | Q35: Page 3
A37: Financial Solutions | Q37: Page 3

Sheet FS
B3: Financial Statements
B4: =WP_LTD!B4 -> As of Dec 31, 2022
B5: In NIS
C6: LTD | I6: INC | K6: AJE | M6: Consolidated | O6: 44926 | P6: Budget | Q6: ישראל | R6: אינק | S6: הערות
C7: IL | E7: $ | I7: $ | M7: $
B8: ASSETS
B10: Current assets
A11: 1 | B11: Cash and cash equivalents LTD | C11: =SUMIF(GL_LTD!$J:$J,A11,GL_LTD!$I:$I) -> 6315593.8 | E11: =SUMIF(GL_LTD!$J:$J,A11,GL_LTD!$G:$G) -> 1794712.6 | G11: =IFERROR(C11/E11,0) -> 3.519 | I11: =SUMIF(GL_INC!G:G,A11,GL_INC!F:F) -> 0 | M11: =SUM(E11+I11) -> 1794712.6 | O11: 9428530.8 | Q11: תקין
A12: 1.5 | B12: Cash and cash equivalents US | C12: =SUMIF(GL_LTD!$J:$J,A12,GL_LTD!$I:$I) -> 0 | E12: =SUMIF(GL_LTD!$J:$J,A12,GL_LTD!$G:$G) -> 0 | G12: =IFERROR(C12/E12,0) -> 0 | I12: =SUMIF(GL_INC!G:G,A12,GL_INC!F:F) -> 2966550.7 | M12: =SUM(E12+I12) -> 2966550.7 | O12: 2965550.7 | R12: תקין
A13: 2 | B13: Short-term Deposits | C13: =SUMIF(GL_LTD!$J:$J,A13,GL_LTD!$I:$I) -> 26744400 | E13: =SUMIF(GL_LTD!$J:$J,A13,GL_LTD!$G:$G) -> 7600000 | G13: =IFERROR(C13/E13,0) -> 3.519 | I13: =SUMIF(GL_INC!G:G,A13,GL_INC!F:F) -> 0 | M13: =SUM(E13+I13) -> 7600000 | Q13: תקין - ראה בדיקת מזומנים
A14: 5 | B14: Accounts Receivables | C14: =SUMIF(GL_LTD!$J:$J,A14,GL_LTD!$I:$I) -> 11691.9 | E14: =SUMIF(GL_LTD!$J:$J,A14,GL_LTD!$G:$G) -> 3300 | G14: =IFERROR(C14/E14,0) -> 3.543 | I14: =SUMIF(GL_INC!G:G,A14,GL_INC!F:F) -> 0 | M14: =SUM(E14+I14) -> 3300 | O14: 0 | Q14: תקין
A15: 6 | B15: Intercompany | C15: =SUMIF(GL_LTD!$J:$J,A15,GL_LTD!$I:$I) -> -6512491.1 | E15: =SUMIF(GL_LTD!$J:$J,A15,GL_LTD!$G:$G) -> -1850665.3 | G15: =IFERROR(C15/E15,0) -> 3.519 | I15: =SUMIF(GL_INC!G:G,A15,GL_INC!F:F) -> 19978310 | M15: =SUM(E15+I15) -> 18127645 | O15: 0
A16: 7.1 | B16: Prepaid expenses | C16: =SUMIF(GL_LTD!$J:$J,A16,GL_LTD!$I:$I) -> 199115.83 | E16: =SUMIF(GL_LTD!$J:$J,A16,GL_LTD!$G:$G) -> 58556.86 | G16: =IFERROR(C16/E16,0) -> 3.4003843 | I16: =SUMIF(GL_INC!G:G,A16,GL_INC!F:F) -> 19852.35 | M16: =SUM(E16+I16) -> 78409.21 | O16: 76421.53 | Q16: טיסות קינג 35 אלפד MARCH 2023 -CloserStill - 18K | R16: Gong - $9.3K
A17: 7 | B17: Other receivables | C17: =C222 -> 173018.36 | E17: =E222 -> 49176.387 | G17: =IFERROR(C17/E17,0) -> 3.518322 | I17: =I222 -> 76966.74 | M17: =SUM(E17+I17) -> 126143.13 | O17: 106017.44 | Q17: תקין | R17: Deposit Papaya - $56K | S17: לבדוק מיליון מניות של עינת ושל עוז כל אחד - מול מה נרשם?
G18: =IFERROR(C18/E18,0) -> 0 | I18: =SUMIF(GL_INC!G:G,A18,GL_INC!F:F) -> 0 | M18: =SUM(E18+I18) -> 0
B19: Total Current assets | C19: =SUM(C11:C18) -> 26931329 | E19: =SUM(E11:E18) -> 7655080.6 | G19: =IFERROR(C19/E19,0) -> 3.5180987 | I19: =SUM(I11:I18) -> 23041680 | M19: =SUM(M11:M18) -> 30696761 | O19: =SUM(O11:O17) -> 12576520
G20: =IFERROR(C20/E20,0) -> 0 | M20: =SUM(E20+I20) -> 0
A21: 20.1 | B21: Restricted deposit | C21: =SUMIF(GL_LTD!$J:$J,A21,GL_LTD!$I:$I) -> 120409.93 | E21: =SUMIF(GL_LTD!$J:$J,A21,GL_LTD!$G:$G) -> 34217.09 | G21: =IFERROR(C21/E21,0) -> 3.5189997 | I21: =SUMIF(GL_INC!G:G,A21,GL_INC!F:F) -> 0 | M21: =SUM(E21+I21) -> 34217.09 | Q21: תקין - ראה בדיקת מזומנים
A22: 20 | B22: Long term Assets | C22: =C21 -> 120409.93 | E22: =E21 -> 34217.09 | G22: =IFERROR(C22/E22,0) -> 3.5189997 | I22: =I21 -> 0 | M22: =M21 -> 34217.09
G23: =IFERROR(C23/E23,0) -> 0 | M23: =SUM(E23+I23) -> 0
G24: =IFERROR(C24/E24,0) -> 0 | M24: =SUM(E24+I24) -> 0
B25: Fixed assets | G25: =IFERROR(C25/E25,0) -> 0 | M25: =SUM(E25+I25) -> 0
A26: 21 | B26: Fixed assets | C26: =SUMIF(GL_LTD!$J:$J,A26,GL_LTD!$I:$I) -> 1160559.5 | E26: =SUMIF(GL_LTD!$J:$J,A26,GL_LTD!$G:$G) -> 359332.47 | G26: =IFERROR(C26/E26,0) -> 3.2297652 | I26: =SUMIF(GL_INC!G:G,A26,GL_INC!F:F) -> 12994.45 | M26: =SUM(E26+I26) -> 372326.92 | O26: 372326.89
A27: 22 | B27: Accumulated depreciation | C27: =SUMIF(GL_LTD!$J:$J,A27,GL_LTD!$I:$I) -> -249045.12 | E27: =SUMIF(GL_LTD!$J:$J,A27,GL_LTD!$G:$G) -> -75295.25 | G27: =IFERROR(C27/E27,0) -> 3.3075808 | I27: =SUMIF(GL_INC!G:G,A27,GL_INC!F:F) -> -2382.7 | M27: =SUM(E27+I27) -> -77677.95 | O27: -77677.95
B28: Total Fixed assets | C28: =SUM(C26:C27) -> 911514.4 | E28: =SUM(E26:E27) -> 284037.22 | G28: =IFERROR(C28/E28,0) -> 3.2091372 | I28: =SUM(I26:I27) -> 10611.75 | M28: =SUM(E28+I28) -> 294648.97 | O28: =SUM(O26:O27) -> 294648.94 | Q28: לבקש טופס פחת
G29: =IFERROR(C29/E29,0) -> 0 | M29: =SUM(E29+I29) -> 0
A30: 25 | B30: Other Assets | C30: =SUMIF(GL_LTD!$J:$J,A30,GL_LTD!$I:$I) -> 0 | E30: =SUMIF(GL_LTD!$J:$J,A30,GL_LTD!$G:$G) -> 0 | G30: =IFERROR(C30/E30,0) -> 0 | I30: =SUMIF(GL_INC!G:G,A30,GL_INC!F:F) -> 0 | M30: =SUM(E30+I30) -> 0
G31: =IFERROR(C31/E31,0) -> 0 | M31: =SUM(E31+I31) -> 0
B32: Total Assets | C32: =C28+C19+C30+C22 -> 27963253 | E32: =E28+E19+E30+E22 -> 7973334.9 | G32: =IFERROR(C32/E32,0) -> 3.5070963 | I32: =I28+I19+I30+I22 -> 23052292 | M32: =M28+M19+M30+M22 -> 31025627 | O32: =O28+O19+O30+O22 -> 12871169
G33: =IFERROR(C33/E33,0) -> 0 | M33: =SUM(E33+I33) -> 0
B34: LIABILITIES | G34: =IFERROR(C34/E34,0) -> 0 | M34: =SUM(E34+I34) -> 0
G35: =IFERROR(C35/E35,0) -> 0 | M35: =SUM(E35+I35) -> 0
B36: Current liabilities | G36: =IFERROR(C36/E36,0) -> 0 | M36: =SUM(E36+I36) -> 0
A37: 31 | B37: Accounts payables | C37: =C236 -> -337109.07 | E37: =E236 -> -95796.83 | G37: =IFERROR(C37/E37,0) -> 3.5190003 | I37: =I236 -> -20271.55 | M37: =SUM(E37+I37) -> -116068.38 | O37: -82839.51 | Q37: תקין
A38: 33 | B38: Employees and related | C38: =C229 -> -1100045.1 | E38: =E229 -> -312370.54 | G38: =IFERROR(C38/E38,0) -> 3.5216031 | I38: =I229 -> 0 | M38: =SUM(E38+I38) -> -312370.54 | O38: -310976.71 | Q38: תקין
A39: 34 | B39: Other current liabilities | C39: =SUMIF(GL_LTD!$J:$J,A39,GL_LTD!$I:$I) -> -30000 | E39: =SUMIF(GL_LTD!$J:$J,A39,GL_LTD!$G:$G) -> -8525.15 | G39: =IFERROR(C39/E39,0) -> 3.5189997 | I39: =SUMIF(GL_INC!G:G,A39,GL_INC!F:F) -> -2662.5 | M39: =SUM(E39+I39) -> -11187.65 | O39: -11187.65 | Q39: פקדון שכירות מהשוכר בייס לאבס
A40: 38 | B40: Accrued Expenses | C40: =SUMIF(GL_LTD!$J:$J,A40,GL_LTD!$I:$I) -> -464040.8 | E40: =SUMIF(GL_LTD!$J:$J,A40,GL_LTD!$G:$G) -> -131867.24 | G40: =IFERROR(C40/E40,0) -> 3.5189999 | I40: =SUMIF(GL_INC!G:G,A40,GL_INC!F:F) -> -142024 | M40: =SUM(E40+I40) -> -273891.24 | O40: -126218.42 | Q40: תקין
A41: 35 | B41: Shareholders liability | C41: =SUMIF(GL_LTD!$J:$J,A41,GL_LTD!$I:$I) -> 0 | E41: =SUMIF(GL_LTD!$J:$J,A41,GL_LTD!$G:$G) -> 0 | G41: =IFERROR(C41/E41,0) -> 0 | I41: =SUMIF(GL_INC!G:G,A41,GL_INC!F:F) -> 0 | M41: =SUM(E41+I41) -> 0 | O41: 0
A42: 37 | B42: Deferred revenues | C42: =SUMIF(GL_LTD!$J:$J,A42,GL_LTD!$I:$I) -> -2748.83 | E42: =SUMIF(GL_LTD!$J:$J,A42,GL_LTD!$G:$G) -> -1249.65 | G42: =IFERROR(C42/E42,0) -> 2.1996799 | I42: =SUMIF(GL_INC!G:G,A42,GL_INC!F:F) -> -77620.96 | M42: =SUM(E42+I42) -> -78870.61 | O42: -78870.61 | Q42: תקין | R42: תקין
A43: 36 | B43: Intercompany | C43: =SUMIF(GL_LTD!$J:$J,A43,GL_LTD!$I:$I) -> 0 | E43: =SUMIF(GL_LTD!$J:$J,A43,GL_LTD!$G:$G) -> 0 | G43: =IFERROR(C43/E43,0) -> 0 | I43: =SUMIF(GL_INC!G:G,A43,GL_INC!F:F) -> 0 | M43: =SUM(E43+I43) -> 0
...

Sheet GL_LTD
C3: General Ledger | G3: =D85/E85 -> 3.519
C4: =WP_LTD!B4 -> As of Dec 31, 2022
B6: Account | C6: שם | D6: יתרה | E6: יתרה | F6: AJE | G6: Final Balance USD | H6: AJE | I6: Final Balance NIS | J6: FS Code | K6: FS Name | L6: BVA Code | M6: Check | P6: Exchange rate
F7: =SUMIF(AJE_LTD!$B:$B,B7,AJE_LTD!$D:$D) -> 0 | G7: =IF(E3="__________________"," ",IF(ISERROR(F7+E7),"",(F7+E7))) -> 0 | H7: =SUMIF(AJE_LTD!$B:$B,B7,AJE_LTD!$F:$F) -> 0 | I7: =IF(D3="__________________"," ",IF(ISERROR(H7+D7),"",(H7+D7))) -> 0 | J7: =IF(ISERROR(VLOOKUP(B7,Accounts_LTD!$B:$E,3,FALSE)),"",VLOOKUP(B7,Accounts_LTD!$B:$E,3,FALSE)) | K7: =IFERROR(IF(J7="","",VLOOKUP(J7,FS!$A$11:$B$241,2,FALSE)),"") | L7: =IFERROR(VLOOKUP(B7,Accounts_LTD!B:G,6,FALSE),"") | P7: =IF(G7=0," ",IF(G7="__________________"," ",ROUND(I7/G7,3)))
B8: PL0001 | C8: =VLOOKUP(B8,Accounts_LTD!B:C,2,0) -> קיזוז הכנסות שכירות | F8: =SUMIF(AJE_LTD!$B:$B,B8,AJE_LTD!$D:$D) -> 0 | G8: =IF(E4="__________________"," ",IF(ISERROR(F8+E8),"",(F8+E8))) -> 0 | H8: =SUMIF(AJE_LTD!$B:$B,B8,AJE_LTD!$F:$F) -> 0 | I8: =IF(D4="__________________"," ",IF(ISERROR(H8+D8),"",(H8+D8))) -> 0 | J8: =IF(ISERROR(VLOOKUP(B8,Accounts_LTD!$B:$E,3,FALSE)),"",VLOOKUP(B8,Accounts_LTD!$B:$E,3,FALSE)) -> 504 | K8: =IFERROR(IF(J8="","",VLOOKUP(J8,FS!$A$11:$B$241,2,FALSE)),"") -> Rent & Related expenses | L8: =IFERROR(VLOOKUP(B8,Accounts_LTD!B:G,6,FALSE),"") | P8: =IF(G8=0," ",IF(G8="__________________"," ",ROUND(I8/G8,3)))
B9: PL0002 | C9: מייד פיננסים | F9: =SUMIF(AJE_LTD!$B:$B,B9,AJE_LTD!$D:$D) -> 0 | G9: =IF(E5="__________________"," ",IF(ISERROR(F9+E9),"",(F9+E9))) -> 0 | H9: =SUMIF(AJE_LTD!$B:$B,B9,AJE_LTD!$F:$F) -> 0 | I9: =IF(D5="__________________"," ",IF(ISERROR(H9+D9),"",(H9+D9))) -> 0 | J9: =IF(ISERROR(VLOOKUP(B9,Accounts_LTD!$B:$E,3,FALSE)),"",VLOOKUP(B9,Accounts_LTD!$B:$E,3,FALSE)) -> 501 | K9: =IFERROR(IF(J9="","",VLOOKUP(J9,FS!$A$11:$B$241,2,FALSE)),"") -> Professional services LTD | L9: =IFERROR(VLOOKUP(B9,Accounts_LTD!B:G,6,FALSE),"") | P9: =IF(G9=0," ",IF(G9="__________________"," ",ROUND(I9/G9,3)))
B10: BS001 | C10: הכנסות לקבל | F10: =SUMIF(AJE_LTD!$B:$B,B10,AJE_LTD!$D:$D) -> 0 | G10: =IF(E6="__________________"," ",IF(ISERROR(F10+E10),"",(F10+E10))) -> 0 | H10: =SUMIF(AJE_LTD!$B:$B,B10,AJE_LTD!$F:$F) -> 0 | I10: =IF(D6="__________________"," ",IF(ISERROR(H10+D10),"",(H10+D10))) -> 0 | J10: =IF(ISERROR(VLOOKUP(B10,Accounts_LTD!$B:$E,3,FALSE)),"",VLOOKUP(B10,Accounts_LTD!$B:$E,3,FALSE)) -> 5 | K10: =IFERROR(IF(J10="","",VLOOKUP(J10,FS!$A$11:$B$241,2,FALSE)),"") -> Accounts Receivables | L10: =IFERROR(VLOOKUP(B10,Accounts_LTD!B:G,6,FALSE),"") | P10: =IF(G10=0," ",IF(G10="__________________"," ",ROUND(I10/G10,3))) | S10: BL00072
B11: PL0003 | C11: Azure (microsoft) | F11: =SUMIF(AJE_LTD!$B:$B,B11,AJE_LTD!$D:$D) -> 0 | G11: =IF(E7="__________________"," ",IF(ISERROR(F11+E11),"",(F11+E11))) -> 0 | H11: =SUMIF(AJE_LTD!$B:$B,B11,AJE_LTD!$F:$F) -> 0 | I11: =IF(D7="__________________"," ",IF(ISERROR(H11+D11),"",(H11+D11))) -> 0 | J11: =IF(ISERROR(VLOOKUP(B11,Accounts_LTD!$B:$E,3,FALSE)),"",VLOOKUP(B11,Accounts_LTD!$B:$E,3,FALSE)) -> 305 | K11: =IFERROR(IF(J11="","",VLOOKUP(J11,FS!$A$11:$B$241,2,FALSE)),"") -> Other R&D expenses | L11: =IFERROR(VLOOKUP(B11,Accounts_LTD!B:G,6,FALSE),"") | P11: =IF(G11=0," ",IF(G11="__________________"," ",ROUND(I11/G11,3)))
B12: BS0017 | C12: נסיעה עוז כץ 02-04/02/23 בריסל | F12: =SUMIF(AJE_LTD!$B:$B,B12,AJE_LTD!$D:$D) -> 0 | G12: =IF(E8="__________________"," ",IF(ISERROR(F12+E12),"",(F12+E12))) -> 0 | H12: =SUMIF(AJE_LTD!$B:$B,B12,AJE_LTD!$F:$F) -> 0 | I12: =IF(D8="__________________"," ",IF(ISERROR(H12+D12),"",(H12+D12))) -> 0 | J12: =IF(ISERROR(VLOOKUP(B12,Accounts_LTD!$B:$E,3,FALSE)),"",VLOOKUP(B12,Accounts_LTD!$B:$E,3,FALSE)) | K12: =IFERROR(IF(J12="","",VLOOKUP(J12,FS!$A$11:$B$241,2,FALSE)),"") | L12: =IFERROR(VLOOKUP(B12,Accounts_LTD!B:G,6,FALSE),"") | P12: =IF(G12=0," ",IF(G12="__________________"," ",ROUND(I12/G12,3)))
B13: PL0004 | C13: נקסטייג | F13: =SUMIF(AJE_LTD!$B:$B,B13,AJE_LTD!$D:$D) -> 0 | G13: =IF(E9="__________________"," ",IF(ISERROR(F13+E13),"",(F13+E13))) -> 0 | H13: =SUMIF(AJE_LTD!$B:$B,B13,AJE_LTD!$F:$F) -> 0 | I13: =IF(D9="__________________"," ",IF(ISERROR(H13+D13),"",(H13+D13))) -> 0 | J13: =IF(ISERROR(VLOOKUP(B13,Accounts_LTD!$B:$E,3,FALSE)),"",VLOOKUP(B13,Accounts_LTD!$B:$E,3,FALSE)) -> 501 | K13: =IFERROR(IF(J13="","",VLOOKUP(J13,FS!$A$11:$B$241,2,FALSE)),"") -> Professional services LTD | L13: =IFERROR(VLOOKUP(B13,Accounts_LTD!B:G,6,FALSE),"") | P13: =IF(G13=0," ",IF(G13="__________________"," ",ROUND(I13/G13,3)))
B14: PL0099 | F14: =SUMIF(AJE_LTD!$B:$B,B14,AJE_LTD!$D:$D) -> 0 | G14: =IF(E11="__________________"," ",IF(ISERROR(F14+E14),"",(F14+E14))) -> 0 | H14: =SUMIF(AJE_LTD!$B:$B,B14,AJE_LTD!$F:$F) -> 0 | I14: =IF(D11="__________________"," ",IF(ISERROR(H14+D14),"",(H14+D14))) -> 0 | J14: =IF(ISERROR(VLOOKUP(B14,Accounts_LTD!$B:$E,3,FALSE)),"",VLOOKUP(B14,Accounts_LTD!$B:$E,3,FALSE)) | K14: =IFERROR(IF(J14="","",VLOOKUP(J14,FS!$A$11:$B$241,2,FALSE)),"") | P14: =IF(G14=0," ",IF(G14="__________________"," ",ROUND(I14/G14,3)))
B15: PL113 | C15: אלוקציה למופ | F15: =SUMIF(AJE_LTD!$B:$B,B15,AJE_LTD!$D:$D) -> 159905.79 | G15: =IF(E12="__________________"," ",IF(ISERROR(F15+E15),"",(F15+E15))) -> 159905.79 | H15: =SUMIF(AJE_LTD!$B:$B,B15,AJE_LTD!$F:$F) -> 533869.57 | I15: =IF(D12="__________________"," ",IF(ISERROR(H15+D15),"",(H15+D15))) -> 533869.57 | J15: =IF(ISERROR(VLOOKUP(B15,Accounts_LTD!$B:$E,3,FALSE)),"",VLOOKUP(B15,Accounts_LTD!$B:$E,3,FALSE)) -> 323 | K15: =IFERROR(IF(J15="","",VLOOKUP(J15,FS!$A$11:$B$241,2,FALSE)),"") -> Allocation to other departments | P15: =IF(G15=0," ",IF(G15="__________________"," ",ROUND(I15/G15,3))) -> 3.339
B16: PL114 | C16: אלוקציה למרקטינג | F16: =SUMIF(AJE_LTD!$B:$B,B16,AJE_LTD!$D:$D) -> 10660.386 | G16: =IF(E13="__________________"," ",IF(ISERROR(F16+E16),"",(F16+E16))) -> 10660.386 | H16: =SUMIF(AJE_LTD!$B:$B,B16,AJE_LTD!$F:$F) -> 35591.305 | I16: =IF(D13="__________________"," ",IF(ISERROR(H16+D16),"",(H16+D16))) -> 35591.305 | J16: =IF(ISERROR(VLOOKUP(B16,Accounts_LTD!$B:$E,3,FALSE)),"",VLOOKUP(B16,Accounts_LTD!$B:$E,3,FALSE)) -> 812 | K16: =IFERROR(IF(J16="","",VLOOKUP(J16,FS!$A$11:$B$241,2,FALSE)),"") -> Allocation to other departments | L16: =IFERROR(VLOOKUP(B16,Accounts_LTD!B:G,6,FALSE),"") | P16: =IF(G16=0," ",IF(G16="__________________"," ",ROUND(I16/G16,3))) -> 3.339
B17: PL115 | C17: אלוקציה ל DEVEX | F17: =SUMIF(AJE_LTD!$B:$B,B17,AJE_LTD!$D:$D) -> 10660.386 | G17: =IF(E14="__________________"," ",IF(ISERROR(F17+E17),"",(F17+E17))) -> 10660.386 | H17: =SUMIF(AJE_LTD!$B:$B,B17,AJE_LTD!$F:$F) -> 35591.305 | I17: =IF(D14="__________________"," ",IF(ISERROR(H17+D17),"",(H17+D17))) -> 35591.305 | J17: =IF(ISERROR(VLOOKUP(B17,Accounts_LTD!$B:$E,3,FALSE)),"",VLOOKUP(B17,Accounts_LTD!$B:$E,3,FALSE)) -> 611 | K17: =IFERROR(IF(J17="","",VLOOKUP(J17,FS!$A$11:$B$241,2,FALSE)),"") -> Allocation to other departments | P17: =IF(G17=0," ",IF(G17="__________________"," ",ROUND(I17/G17,3))) -> 3.339
B18: PL116 | C18: אלוקציה מהנהכ | F18: =SUMIF(AJE_LTD!$B:$B,B18,AJE_LTD!$D:$D) -> -181226.57 | G18: =IF(E14="__________________"," ",IF(ISERROR(F18+E18),"",(F18+E18))) -> -181226.57 | H18: =SUMIF(AJE_LTD!$B:$B,B18,AJE_LTD!$F:$F) -> -605052.18 | I18: =IF(D14="__________________"," ",IF(ISERROR(H18+D18),"",(H18+D18))) -> -605052.18 | J18: =IF(ISERROR(VLOOKUP(B18,Accounts_LTD!$B:$E,3,FALSE)),"",VLOOKUP(B18,Accounts_LTD!$B:$E,3,FALSE)) -> 510 | K18: =IFERROR(IF(J18="","",VLOOKUP(J18,FS!$A$11:$B$241,2,FALSE)),"") -> Allocation to other departments | P18: =IF(G18=0," ",IF(G18="__________________"," ",ROUND(I18/G18,3))) -> 3.339
B19: PL0011 | C19: הוצ נסיעות DEVEX ל WELFARE | F19: =SUMIF(AJE_LTD!$B:$B,B19,AJE_LTD!$D:$D) -> 0 | G19: =IF(E15="__________________"," ",IF(ISERROR(F19+E19),"",(F19+E19))) -> 0 | H19: =SUMIF(AJE_LTD!$B:$B,B19,AJE_LTD!$F:$F) -> 0 | I19: =IF(D15="__________________"," ",IF(ISERROR(H19+D19),"",(H19+D19))) -> 0 | J19: =IF(ISERROR(VLOOKUP(B19,Accounts_LTD!$B:$E,3,FALSE)),"",VLOOKUP(B19,Accounts_LTD!$B:$E,3,FALSE)) -> 600 | K19: =IFERROR(IF(J19="","",VLOOKUP(J19,FS!$A$11:$B$241,2,FALSE)),"") -> Payroll and related (DevEx) | P19: =IF(G19=0," ",IF(G19="__________________"," ",ROUND(I19/G19,3)))
B20: PL0012 | C20: הוצ ארוחות G&A ל WELFARE | F20: =SUMIF(AJE_LTD!$B:$B,B20,AJE_LTD!$D:$D) -> 0 | G20: =IF(E16="__________________"," ",IF(ISERROR(F20+E20),"",(F20+E20))) -> 0 | H20: =SUMIF(AJE_LTD!$B:$B,B20,AJE_LTD!$F:$F) -> 0 | I20: =IF(D16="__________________"," ",IF(ISERROR(H20+D20),"",(H20+D20))) -> 0 | J20: =IF(ISERROR(VLOOKUP(B20,Accounts_LTD!$B:$E,3,FALSE)),"",VLOOKUP(B20,Accounts_LTD!$B:$E,3,FALSE)) -> 500 | K20: =IFERROR(IF(J20="","",VLOOKUP(J20,FS!$A$11:$B$241,2,FALSE)),"") -> Payroll and related (G&A) | P20: =IF(G20=0," ",IF(G20="__________________"," ",ROUND(I20/G20,3)))
B21: PL0013 | C21: הוצ נסיעות G&A ל WELFARE | F21: =SUMIF(AJE_LTD!$B:$B,B21,AJE_LTD!$D:$D) -> 0 | G21: =IF(E17="__________________"," ",IF(ISERROR(F21+E21),"",(F21+E21))) -> 0 | H21: =SUMIF(AJE_LTD!$B:$B,B21,AJE_LTD!$F:$F) -> 0 | I21: =IF(D17="__________________"," ",IF(ISERROR(H21+D21),"",(H21+D21))) -> 0 | J21: =IF(ISERROR(VLOOKUP(B21,Accounts_LTD!$B:$E,3,FALSE)),"",VLOOKUP(B21,Accounts_LTD!$B:$E,3,FALSE)) -> 500 | K21: =IFERROR(IF(J21="","",VLOOKUP(J21,FS!$A$11:$B$241,2,FALSE)),"") -> Payroll and related (G&A) | P21: =IF(G21=0," ",IF(G21="__________________"," ",ROUND(I21/G21,3)))
B22: PL0014 | C22: ארוחות WELFARE | F22: =SUMIF(AJE_LTD!$B:$B,B22,AJE_LTD!$D:$D) -> 0 | G22: =IF(E18="__________________"," ",IF(ISERROR(F22+E22),"",(F22+E22))) -> 0 | H22: =SUMIF(AJE_LTD!$B:$B,B22,AJE_LTD!$F:$F) -> 0 | I22: =IF(D18="__________________"," ",IF(ISERROR(H22+D22),"",(H22+D22))) -> 0 | J22: =IF(ISERROR(VLOOKUP(B22,Accounts_LTD!$B:$E,3,FALSE)),"",VLOOKUP(B22,Accounts_LTD!$B:$E,3,FALSE)) -> 508 | K22: =IFERROR(IF(J22="","",VLOOKUP(J22,FS!$A$11:$B$241,2,FALSE)),"") -> Welfare (Meals + transportation) | P22: =IF(G22=0," ",IF(G22="__________________"," ",ROUND(I22/G22,3)))
B23: PL0015 | C23: נסיעות WELFARE | F23: =SUMIF(AJE_LTD!$B:$B,B23,AJE_LTD!$D:$D) -> 0 | G23: =IF(E19="__________________"," ",IF(ISERROR(F23+E23),"",(F23+E23))) -> 0 | H23: =SUMIF(AJE_LTD!$B:$B,B23,AJE_LTD!$F:$F) -> 0 | I23: =IF(D19="__________________"," ",IF(ISERROR(H23+D23),"",(H23+D23))) -> 0 | J23: =IF(ISERROR(VLOOKUP(B23,Accounts_LTD!$B:$E,3,FALSE)),"",VLOOKUP(B23,Accounts_LTD!$B:$E,3,FALSE)) -> 508 | K23: =IFERROR(IF(J23="","",VLOOKUP(J23,FS!$A$11:$B$241,2,FALSE)),"") -> Welfare (Meals + transportation) | P23: =IF(G23=0," ",IF(G23="__________________"," ",ROUND(I23/G23,3)))
B24: 50500 | C24: נסיעה לארה"ב עוז כץ 11.10.21-15.10.21 | F24: =SUMIF(AJE_LTD!$B:$B,B24,AJE_LTD!$D:$D) -> 12386.42 | G24: =IF(E20="__________________"," ",IF(ISERROR(F24+E24),"",(F24+E24))) -> 12386.42 | H24: =SUMIF(AJE_LTD!$B:$B,B24,AJE_LTD!$F:$F) -> 43587.81 | I24: =IF(D20="__________________"," ",IF(ISERROR(H24+D24),"",(H24+D24))) -> 43587.81 | J24: =IF(ISERROR(VLOOKUP(B24,Accounts_LTD!$B:$E,3,FALSE)),"",VLOOKUP(B24,Accounts_LTD!$B:$E,3,FALSE)) -> 303 | K24: =IFERROR(IF(J24="","",VLOOKUP(J24,FS!$A$11:$B$241,2,FALSE)),"") -> Travel abroad | P24: =IF(G24=0," ",IF(G24="__________________"," ",ROUND(I24/G24,3))) -> 3.519
B25: PL51000 | C25: =VLOOKUP(B25,Accounts_LTD!B:C,2,0) -> #N/A | F25: =SUMIF(AJE_LTD!$B:$B,B25,AJE_LTD!$D:$D) -> 0 | G25: =IF(E21="__________________"," ",IF(ISERROR(F25+E25),"",(F25+E25))) -> 0 | H25: =SUMIF(AJE_LTD!$B:$B,B25,AJE_LTD!$F:$F) -> 0 | I25: =IF(D21="__________________"," ",IF(ISERROR(H25+D25),"",(H25+D25))) -> 0 | J25: =IF(ISERROR(VLOOKUP(B25,Accounts_LTD!$B:$E,3,FALSE)),"",VLOOKUP(B25,Accounts_LTD!$B:$E,3,FALSE)) | K25: =IFERROR(IF(J25="","",VLOOKUP(J25,FS!$A$11:$B$241,2,FALSE)),"") | P25: =IF(G25=0," ",IF(G25="__________________"," ",ROUND(I25/G25,3)))
B26: PL32300 | C26: =VLOOKUP(B26,Accounts_LTD!B:C,2,0) -> #N/A | F26: =SUMIF(AJE_LTD!$B:$B,B26,AJE_LTD!$D:$D) -> 0 | G26: =IF(E22="__________________"," ",IF(ISERROR(F26+E26),"",(F26+E26))) -> 0 | H26: =SUMIF(AJE_LTD!$B:$B,B26,AJE_LTD!$F:$F) -> 0 | I26: =IF(D22="__________________"," ",IF(ISERROR(H26+D26),"",(H26+D26))) -> 0 | J26: =IF(ISERROR(VLOOKUP(B26,Accounts_LTD!$B:$E,3,FALSE)),"",VLOOKUP(B26,Accounts_LTD!$B:$E,3,FALSE)) | K26: =IFERROR(IF(J26="","",VLOOKUP(J26,FS!$A$11:$B$241,2,FALSE)),"") | P26: =IF(G26=0," ",IF(G26="__________________"," ",ROUND(I26/G26,3)))
B27: BS002 | C27: מעמ ספקים | F27: =SUMIF(AJE_LTD!$B:$B,B27,AJE_LTD!$D:$D) -> 1897.1666 | G27: =IF(E23="__________________"," ",IF(ISERROR(F27+E27),"",(F27+E27))) -> 1897.1666 | H27: =SUMIF(AJE_LTD!$B:$B,B27,AJE_LTD!$F:$F) -> 6676.1238 | I27: =IF(D23="__________________"," ",IF(ISERROR(H27+D27),"",(H27+D27))) -> 6676.1238 | J27: =IF(ISERROR(VLOOKUP(B27,Accounts_LTD!$B:$E,3,FALSE)),"",VLOOKUP(B27,Accounts_LTD!$B:$E,3,FALSE)) -> 7.3 | K27: =IFERROR(IF(J27="","",VLOOKUP(J27,FS!$A$11:$B$241,2,FALSE)),"") -> Government Institutions | P27: =IF(G27=0," ",IF(G27="__________________"," ",ROUND(I27/G27,3))) -> 3.519
B28: 70039 | C28: הוצאות VANTA INC | F28: =SUMIF(AJE_LTD!$B:$B,B28,AJE_LTD!$D:$D) -> 0 | G28: =IF(E24="__________________"," ",IF(ISERROR(F28+E28),"",(F28+E28))) -> 0 | H28: =SUMIF(AJE_LTD!$B:$B,B28,AJE_LTD!$F:$F) -> 0 | I28: =IF(D24="__________________"," ",IF(ISERROR(H28+D28),"",(H28+D28))) -> 0 | J28: =IF(ISERROR(VLOOKUP(B28,Accounts_LTD!$B:$E,3,FALSE)),"",VLOOKUP(B28,Accounts_LTD!$B:$E,3,FALSE)) -> 511 | K28: =IFERROR(IF(J28="","",VLOOKUP(J28,FS!$A$11:$B$241,2,FALSE)),"") -> G&A Software | P28: =IF(G28=0," ",IF(G28="__________________"," ",ROUND(I28/G28,3)))
B29: BS510 | C29: Additional Paid-In Capital | F29: =SUMIF(AJE_LTD!$B:$B,B29,AJE_LTD!$D:$D) -> #ERROR! | G29: =IF(E25="__________________"," ",IF(ISERROR(F29+E29),"",(F29+E29))) | H29: =SUMIF(AJE_LTD!$B:$B,B29,AJE_LTD!$F:$F) -> #ERROR! | I29: =IF(D25="__________________"," ",IF(ISERROR(H29+D29),"",(H29+D29))) | J29: =IF(ISERROR(VLOOKUP(B29,Accounts_LTD!$B:$E,3,FALSE)),"",VLOOKUP(B29,Accounts_LTD!$B:$E,3,FALSE)) -> 51 | K29: =IFERROR(IF(J29="","",VLOOKUP(J29,FS!$A$11:$B$241,2,FALSE)),"") -> Additional paid-in capital | P29: =IF(G29=0," ",IF(G29="__________________"," ",ROUND(I29/G29,3))) -> #DIV/0!
C30: תוכנה וכילים TOOLS הנה"כ | F30: =SUMIF(AJE_LTD!$B:$B,B30,AJE_LTD!$D:$D) -> 0 | G30: =IF(E25="__________________"," ",IF(ISERROR(F30+E30),"",(F30+E30))) -> 0 | H30: =SUMIF(AJE_LTD!$B:$B,B30,AJE_LTD!$F:$F) -> 0 | I30: =IF(D25="__________________"," ",IF(ISERROR(H30+D30),"",(H30+D30))) -> 0 | J30: =IF(ISERROR(VLOOKUP(B30,Accounts_LTD!$B:$E,3,FALSE)),"",VLOOKUP(B30,Accounts_LTD!$B:$E,3,FALSE)) | K30: =IFERROR(IF(J30="","",VLOOKUP(J30,FS!$A$11:$B$241,2,FALSE)),"") | P30: =IF(G30=0," ",IF(G30="__________________"," ",ROUND(I30/G30,3)))
B31: PL112 | C31: Bonus DevEx | F31: =SUMIF(AJE_LTD!$B:$B,B31,AJE_LTD!$D:$D) -> 10116.51 | G31: =IF(E26="__________________"," ",IF(ISERROR(F31+E31),"",(F31+E31))) -> 10116.51 | H31: =SUMIF(AJE_LTD!$B:$B,B31,AJE_LTD!$F:$F) -> 35600 | I31: =IF(D26="__________________"," ",IF(ISERROR(H31+D31),"",(H31+D31))) -> 35600 | J31: =IF(ISERROR(VLOOKUP(B31,Accounts_LTD!$B:$E,3,FALSE)),"",VLOOKUP(B31,Accounts_LTD!$B:$E,3,FALSE)) -> 601 | K31: =IFERROR(IF(J31="","",VLOOKUP(J31,FS!$A$11:$B$241,2,FALSE)),"") -> Bonus DevEx | P31: =IF(G31=0," ",IF(G31="__________________"," ",ROUND(I31/G31,3))) -> 3.519
B32: PL117 | C32: אופציות- מו"פ | F32: =SUMIF(AJE_LTD!$B:$B,B32,AJE_LTD!$D:$D) -> #REF! | G32: =IF(E27="__________________"," ",IF(ISERROR(F32+E32),"",(F32+E32))) | H32: =SUMIF(AJE_LTD!$B:$B,B32,AJE_LTD!$F:$F) -> #REF! | I32: =IF(D27="__________________"," ",IF(ISERROR(H32+D32),"",(H32+D32))) | J32: =IF(ISERROR(VLOOKUP(B32,Accounts_LTD!$B:$E,3,FALSE)),"",VLOOKUP(B32,Accounts_LTD!$B:$E,3,FALSE)) -> 314 | K32: =IFERROR(IF(J32="","",VLOOKUP(J32,FS!$A$11:$B$241,2,FALSE)),"") -> Stock compensation exp - R&D | P32: =IF(G32=0," ",IF(G32="__________________"," ",ROUND(I32/G32,3))) -> #DIV/0!
B33: PL118 | C33: אופציות-הנה"כ | F33: =SUMIF(AJE_LTD!$B:$B,B33,AJE_LTD!$D:$D) -> #REF! | G33: =IF(E28="__________________"," ",IF(ISERROR(F33+E33),"",(F33+E33))) | H33: =SUMIF(AJE_LTD!$B:$B,B33,AJE_LTD!$F:$F) -> #REF! | I33: =IF(D28="__________________"," ",IF(ISERROR(H33+D33),"",(H33+D33))) | J33: =IF(ISERROR(VLOOKUP(B33,Accounts_LTD!$B:$E,3,FALSE)),"",VLOOKUP(B33,Accounts_LTD!$B:$E,3,FALSE)) -> 512 | K33: =IFERROR(IF(J33="","",VLOOKUP(J33,FS!$A$11:$B$241,2,FALSE)),"") -> Stock compensation exp - G&A | P33: =IF(G33=0," ",IF(G33="__________________"," ",ROUND(I33/G33,3))) -> #DIV/0!
B34: PL119 | C34: אופציות- מכירה ושיווק | F34: =SUMIF(AJE_LTD!$B:$B,B34,AJE_LTD!$D:$D) -> #REF! | G34: =IF(E30="__________________"," ",IF(ISERROR(F34+E34),"",(F34+E34))) | H34: =SUMIF(AJE_LTD!$B:$B,B34,AJE_LTD!$F:$F) -> #REF! | I34: =IF(D30="__________________"," ",IF(ISERROR(H34+D34),"",(H34+D34))) | J34: =IF(ISERROR(VLOOKUP(B34,Accounts_LTD!$B:$E,3,FALSE)),"",VLOOKUP(B34,Accounts_LTD!$B:$E,3,FALSE)) -> 813 | K34: =IFERROR(IF(J34="","",VLOOKUP(J34,FS!$A$11:$B$241,2,FALSE)),"") -> Stock compensation exp - marketing | P34: =IF(G34=0," ",IF(G34="__________________"," ",ROUND(I34/G34,3))) -> #DIV/0!
B35: BS200 | C35: קרן הון- אופציות | F35: =SUMIF(AJE_LTD!$B:$B,B35,AJE_LTD!$D:$D) -> #REF! | G35: =IF(E31="__________________"," ",IF(ISERROR(F35+E35),"",(F35+E35))) | H35: =SUMIF(AJE_LTD!$B:$B,B35,AJE_LTD!$F:$F) -> #REF! | I35: =IF(D31="__________________"," ",IF(ISERROR(H35+D35),"",(H35+D35))) | J35: =IF(ISERROR(VLOOKUP(B35,Accounts_LTD!$B:$E,3,FALSE)),"",VLOOKUP(B35,Accounts_LTD!$B:$E,3,FALSE)) -> 54 | K35: =IFERROR(IF(J35="","",VLOOKUP(J35,FS!$A$11:$B$241,2,FALSE)),"") -> Stock compensation | P35: =IF(G35=0," ",IF(G35="__________________"," ",ROUND(I35/G35,3))) -> #DIV/0!
B36: PL0019 | C36: =VLOOKUP(B36,Accounts_LTD!B:C,2,0) -> Michal Wosk Big Data & AI World UK 2023 07-10/03/23 | F36: =SUMIF(AJE_LTD!$B:$B,B36,AJE_LTD!$D:$D) -> 0 | G36: =IF(E27="__________________"," ",IF(ISERROR(F36+E36),"",(F36+E36))) -> 0 | H36: =SUMIF(AJE_LTD!$B:$B,B36,AJE_LTD!$F:$F) -> 0 | I36: =IF(D27="__________________"," ",IF(ISERROR(H36+D36),"",(H36+D36))) -> 0 | J36: =IF(ISERROR(VLOOKUP(B36,Accounts_LTD!$B:$E,3,FALSE)),"",VLOOKUP(B36,Accounts_LTD!$B:$E,3,FALSE)) -> 811 | K36: =IFERROR(IF(J36="","",VLOOKUP(J36,FS!$A$11:$B$241,2,FALSE)),"") -> Conference Expenses marketing | P36: =IF(G36=0," ",IF(G36="__________________"," ",ROUND(I36/G36,3)))
B37: 460001 | C37: =VLOOKUP(B37,Accounts_LTD!B:C,2,0) -> #N/A | F37: =SUMIF(AJE_LTD!$B:$B,B37,AJE_LTD!$D:$D) -> 0 | G37: =IF(E28="__________________"," ",IF(ISERROR(F37+E37),"",(F37+E37))) -> 0 | H37: =SUMIF(AJE_LTD!$B:$B,B37,AJE_LTD!$F:$F) -> 0 | I37: =IF(D28="__________________"," ",IF(ISERROR(H37+D37),"",(H37+D37))) -> 0 | J37: =IF(ISERROR(VLOOKUP(B37,Accounts_LTD!$B:$E,3,FALSE)),"",VLOOKUP(B37,Accounts_LTD!$B:$E,3,FALSE)) | K37: =IFERROR(IF(J37="","",VLOOKUP(J37,FS!$A$11:$B$241,2,FALSE)),"") | P37: =IF(G37=0," ",IF(G37="__________________"," ",ROUND(I37/G37,3)))
B38: PL0016 | C38: =VLOOKUP(B38,Accounts_LTD!B:C,2,0) -> יעוץ | F38: =SUMIF(AJE_LTD!$B:$B,B38,AJE_LTD!$D:$D) -> 0 | G38: =IF(E30="__________________"," ",IF(ISERROR(F38+E38),"",(F38+E38))) -> 0 | H38: =SUMIF(AJE_LTD!$B:$B,B38,AJE_LTD!$F:$F) -> 0 | I38: =IF(D30="__________________"," ",IF(ISERROR(H38+D38),"",(H38+D38))) -> 0 | J38: =IF(ISERROR(VLOOKUP(B38,Accounts_LTD!$B:$E,3,FALSE)),"",VLOOKUP(B38,Accounts_LTD!$B:$E,3,FALSE)) -> 501 | K38: =IFERROR(IF(J38="","",VLOOKUP(J38,FS!$A$11:$B$241,2,FALSE)),"") -> Professional services LTD
B39: =IF(IF(ISERROR(LEFT(C39,5)*1),"",(LEFT(C39,5)*1))<10000,"",IF(ISERROR(LEFT(C39,5)*1),"",(LEFT(C39,5)*1))) | F39: =SUMIF(AJE_LTD!$B:$B,B39,AJE_LTD!$D:$D) -> 0 | G39: =IF(E22="__________________"," ",IF(ISERROR(F39+E39),"",(F39+E39))) -> 0 | H39: =SUMIF(AJE_LTD!$B:$B,B39,AJE_LTD!$F:$F) -> 0 | I39: =IF(D22="__________________"," ",IF(ISERROR(H39+D39),"",(H39+D39))) -> 0 | J39: =IF(ISERROR(VLOOKUP(B39,Accounts_LTD!$B:$E,3,FALSE)),"",VLOOKUP(B39,Accounts_LTD!$B:$E,3,FALSE)) | K39: =IFERROR(IF(J39="","",VLOOKUP(J39,FS!$A$11:$B$241,2,FALSE)),"") | L39: =IFERROR(VLOOKUP(B39,Accounts_LTD!B:G,6,FALSE),"") | M39: =IF(and(B39<>"",J39=""),"Error","")
B40: חשבון | C40: תאור החשבון | D40: יתרה בשקלים | E40: יתרה בדולרים | F40: =SUMIF(AJE_LTD!$B:$B,B40,AJE_LTD!$D:$D) -> 0 | G40: =IF(E23="__________________"," ",IF(ISERROR(F40+E40),"",(F40+E40))) | H40: =SUMIF(AJE_LTD!$B:$B,B40,AJE_LTD!$F:$F) -> 0 | I40: =IF(D23="__________________"," ",IF(ISERROR(H40+D40),"",(H40+D40))) | J40: =IF(ISERROR(VLOOKUP(B40,Accounts_LTD!$B:$E,3,FALSE)),"",VLOOKUP(B40,Accounts_LTD!$B:$E,3,FALSE)) | K40: =IFERROR(IF(J40="","",VLOOKUP(J40,FS!$A$11:$B$241,2,FALSE)),"") | L40: =IFERROR(VLOOKUP(#REF!,Accounts_LTD!B:G,6,FALSE),"")
B41: 10000 | C41: בנק לאומי ש"ח | D41: 5716204.6 | E41: 1624383.2 | F41: =SUMIF(AJE_LTD!$B:$B,B41,AJE_LTD!$D:$D) -> 0 | G41: =IF(E24="__________________"," ",IF(ISERROR(F41+E41),"",(F41+E41))) -> 1624383.2 | H41: =SUMIF(AJE_LTD!$B:$B,B41,AJE_LTD!$F:$F) -> 0 | I41: =IF(D24="__________________"," ",IF(ISERROR(H41+D41),"",(H41+D41))) -> 5716204.6 | J41: =IF(ISERROR(VLOOKUP(B41,Accounts_LTD!$B:$E,3,FALSE)),"",VLOOKUP(B41,Accounts_LTD!$B:$E,3,FALSE)) -> 1 | K41: =IFERROR(IF(J41="","",VLOOKUP(J41,FS!$A$11:$B$241,2,FALSE)),"") -> Cash and cash equivalents LTD | L41: =IFERROR(VLOOKUP(B42,Accounts_LTD!B:G,6,FALSE),"") | P41: =IF(G41=0," ",IF(G41="__________________"," ",ROUND(I41/G41,3))) -> 3.519 | R41: =IF(E44>G42,0,1) -> 1 | S41: =E41-G41 -> 0 | U41: =D41-I41 -> 0
B42: 10001 | C42: בנק לאומי $ | D42: 586873.73 | E42: 166772.87 | F42: =SUMIF(AJE_LTD!$B:$B,B42,AJE_LTD!$D:$D) -> 0 | G42: =IF(E25="__________________"," ",IF(ISERROR(F42+E42),"",(F42+E42))) -> 166772.87 | H42: =SUMIF(AJE_LTD!$B:$B,B42,AJE_LTD!$F:$F) -> 0 | I42: =IF(D25="__________________"," ",IF(ISERROR(H42+D42),"",(H42+D42))) -> 586873.73 | J42: =IF(ISERROR(VLOOKUP(B42,Accounts_LTD!$B:$E,3,FALSE)),"",VLOOKUP(B42,Accounts_LTD!$B:$E,3,FALSE)) -> 1 | K42: =IFERROR(IF(J42="","",VLOOKUP(J42,FS!$A$11:$B$241,2,FALSE)),"") -> Cash and cash equivalents LTD | L42: =IFERROR(VLOOKUP(B43,Accounts_LTD!B:G,6,FALSE),"") | P42: =IF(G42=0," ",IF(G42="__________________"," ",ROUND(I42/G42,3))) -> 3.519 | R42: =IF(E45>G43,0,1) -> 1 | S42: =E42-G42 -> 0 | U42: =D42-I42 -> 0
B43: 10002 | C43: בנק לאומי דולר קנדי | D43: 11130.46 | E43: 3162.96 | F43: =SUMIF(AJE_LTD!$B:$B,B43,AJE_LTD!$D:$D) -> 0 | G43: =IF(E39="__________________"," ",IF(ISERROR(F43+E43),"",(F43+E43))) -> 3162.96 | H43: =SUMIF(AJE_LTD!$B:$B,B43,AJE_LTD!$F:$F) -> 0 | I43: =IF(D39="__________________"," ",IF(ISERROR(H43+D43),"",(H43+D43))) -> 11130.46 | J43: =IF(ISERROR(VLOOKUP(B43,Accounts_LTD!$B:$E,3,FALSE)),"",VLOOKUP(B43,Accounts_LTD!$B:$E,3,FALSE)) -> 1 | K43: =IFERROR(IF(J43="","",VLOOKUP(J43,FS!$A$11:$B$241,2,FALSE)),"") -> Cash and cash equivalents LTD | L43: =IFERROR(VLOOKUP(#REF!,Accounts_LTD!B:G,6,FALSE),"") | P43: =IF(G43=0," ",IF(G43="__________________"," ",ROUND(I43/G43,3))) -> 3.519 | R43: =IF(E46>G44,0,1) -> 1 | S43: =E43-G43 -> 0 | U43: =D43-I43 -> 0
...

Sheet GL_INC
C3: General Ledger
C4: =WP_LTD!B4 -> As of Dec 31, 2022
A6: Account | B6: Account | C6: שם | D6: יתרה | E6: AJE | F6: Final Balance USD | G6: FS Code | H6: FS Name | I6: BVA Code | J6: Check
E7: =SUMIF(AJE_INC!B:B,B7,AJE_INC!D:D) -> 0 | F7: =IF(D3="__________________"," ",IF(ISERROR(E7+D7),"",(E7+D7))) -> 0 | G7: =IF(ISERROR(VLOOKUP(B7,Accounts_INC!$B:$E,3,FALSE)),"",VLOOKUP(B7,Accounts_INC!$B:$E,3,FALSE)) | H7: =IFERROR(IF(G7="","",VLOOKUP(G7,FS!$A$11:$B$241,2,FALSE)),"")
A8: PL001 | B8: PL001 | C8: =VLOOKUP(B8,Accounts_INC!B:C,2,0) -> #N/A | E8: =SUMIF(AJE_INC!B:B,B8,AJE_INC!D:D) -> 0 | F8: =IF(D4="__________________"," ",IF(ISERROR(E8+D8),"",(E8+D8))) -> 0 | G8: =IF(ISERROR(VLOOKUP(B8,Accounts_INC!$B:$E,3,FALSE)),"",VLOOKUP(B8,Accounts_INC!$B:$E,3,FALSE)) | H8: =IFERROR(IF(G8="","",VLOOKUP(G8,FS!$A$11:$B$241,2,FALSE)),"") | I8: =IFERROR(VLOOKUP(B8,Accounts_LTD!B:G,6,FALSE),"")
A9: BS11000 | B9: BS11000 | C9: =VLOOKUP(B9,Accounts_INC!B:C,2,0) -> #N/A | E9: =SUMIF(AJE_INC!B:B,B9,AJE_INC!D:D) -> 0 | F9: =IF(D5="__________________"," ",IF(ISERROR(E9+D9),"",(E9+D9))) -> 0 | G9: =IF(ISERROR(VLOOKUP(B9,Accounts_INC!$B:$E,3,FALSE)),"",VLOOKUP(B9,Accounts_INC!$B:$E,3,FALSE)) | H9: =IFERROR(IF(G9="","",VLOOKUP(G9,FS!$A$11:$B$241,2,FALSE)),"") | I9: =IFERROR(VLOOKUP(B9,Accounts_LTD!B:G,6,FALSE),"")
A10: 90003 | B10: 90003 | C10: =VLOOKUP(B10,Accounts_INC!B:C,2,0) -> #N/A | E10: =SUMIF(AJE_INC!B:B,B10,AJE_INC!D:D) -> 0 | F10: =IF(D6="__________________"," ",IF(ISERROR(E10+D10),"",(E10+D10))) -> 0 | G10: =IF(ISERROR(VLOOKUP(B10,Accounts_INC!$B:$E,3,FALSE)),"",VLOOKUP(B10,Accounts_INC!$B:$E,3,FALSE)) | H10: =IFERROR(IF(G10="","",VLOOKUP(G10,FS!$A$11:$B$241,2,FALSE)),"") | I10: =IFERROR(VLOOKUP(B10,Accounts_LTD!B:G,6,FALSE),"")
A11: BS99001 | B11: BS99001 | C11: =VLOOKUP(B11,Accounts_INC!B:C,2,0) -> #N/A | E11: =SUMIF(AJE_INC!B:B,B11,AJE_INC!D:D) -> 0 | F11: =IF(D7="__________________"," ",IF(ISERROR(E11+D11),"",(E11+D11))) -> 0 | G11: =IF(ISERROR(VLOOKUP(B11,Accounts_INC!$B:$E,3,FALSE)),"",VLOOKUP(B11,Accounts_INC!$B:$E,3,FALSE)) | H11: =IFERROR(IF(G11="","",VLOOKUP(G11,FS!$A$11:$B$241,2,FALSE)),"") | I11: =IFERROR(VLOOKUP(B11,Accounts_LTD!B:G,6,FALSE),"")
