Workbook

Sheet BS USD
C1: Wematch.live
C2: USD
E5: WUS- INC | F5: EQD | G5: WIR | H5: WSF- LTD [IL] | I5: WSF LTD | J5: R&D | K5: WTSE | L5: Elimination | N5: JE'S | O5: Total
E6: 31.12.2022 | F6: 31.12.2022 | G6: 31.12.2022 | H6: 31.12.2022 | I6: 31.12.2022 | J6: 31.12.2022 | K6: 31.12.2022 | O6: 31.12.2022 | Q6: in 000' | S6: NOTE
B7: INDEX
C8: Assets | Q8: =+O8/1000 -> 0
C10: Current Assets: | Q10: =+O10/1000 -> 0
B11: 10 | C11: Cash and cash equivalent | E11: =+SUMIF('Full BS-USD'!$K:$K,B11,'Full BS-USD'!$C:$C) -> 222640.47 | F11: =+SUMIF('Full BS-USD'!$K:$K,B11,'Full BS-USD'!$D:$D) -> 20671.85 | G11: =+SUMIF('Full BS-USD'!$K:$K,B11,'Full BS-USD'!$E:$E) -> 21.81 | H11: =+SUMIF('Full BS-USD'!$K:$K,B11,'Full BS-USD'!$F:$F) -> 476.55 | I11: =+SUMIF('Full BS-USD'!$K:$K,B11,'Full BS-USD'!$G:$G) -> 671296.2 | J11: =+SUMIF('Full BS-USD'!$K:$K,B11,'Full BS-USD'!$H:$H) -> 6448566.6 | K11: =+SUMIF('Full BS-USD'!$K:$K,B11,'Full BS-USD'!$I:$I) -> 294848.47 | L11: =+SUMIF('Full BS-USD'!$K:$K,B11,'Full BS-USD'!$B:$B) -> 0 | O11: =+SUMIF('Full BS-USD'!$K:$K,B11,'Full BS-USD'!$J:$J) -> 7658522 | P11: =+O11-SUM(E11:L11) -> 0 | Q11: =+ROUND((O11/1000),0)+1 -> 7660
B12: 11 | C12: Short term restricted deposits | E12: =+SUMIF('Full BS-USD'!$K:$K,B12,'Full BS-USD'!$C:$C) -> 0 | F12: =+SUMIF('Full BS-USD'!$K:$K,B12,'Full BS-USD'!$D:$D) -> 0 | G12: =+SUMIF('Full BS-USD'!$K:$K,B12,'Full BS-USD'!$E:$E) -> 0 | H12: =+SUMIF('Full BS-USD'!$K:$K,B12,'Full BS-USD'!$F:$F) -> 0 | I12: =+SUMIF('Full BS-USD'!$K:$K,B12,'Full BS-USD'!$G:$G) -> 0 | J12: =+SUMIF('Full BS-USD'!$K:$K,B12,'Full BS-USD'!$H:$H) -> 11163411 | K12: =+SUMIF('Full BS-USD'!$K:$K,B12,'Full BS-USD'!$I:$I) -> 0 | L12: =+SUMIF('Full BS-USD'!$K:$K,B12,'Full BS-USD'!$B:$B) -> 0 | O12: =+SUMIF('Full BS-USD'!$K:$K,B12,'Full BS-USD'!$J:$J) -> 11163411 | P12: =+O12-SUM(E12:L12) -> 0 | Q12: =+ROUND((O12/1000),0) -> 11163
B13: 12 | C13: Trade recievables | E13: =+SUMIF('Full BS-USD'!$K:$K,B13,'Full BS-USD'!$C:$C) -> 0 | F13: =+SUMIF('Full BS-USD'!$K:$K,B13,'Full BS-USD'!$D:$D) -> 0 | G13: =+SUMIF('Full BS-USD'!$K:$K,B13,'Full BS-USD'!$E:$E) -> 0 | H13: =+SUMIF('Full BS-USD'!$K:$K,B13,'Full BS-USD'!$F:$F) -> 0 | I13: =+SUMIF('Full BS-USD'!$K:$K,B13,'Full BS-USD'!$G:$G) -> 0 | J13: =+SUMIF('Full BS-USD'!$K:$K,B13,'Full BS-USD'!$H:$H) -> 2037911.9 | K13: =+SUMIF('Full BS-USD'!$K:$K,B13,'Full BS-USD'!$I:$I) -> 28375.56 | L13: =+SUMIF('Full BS-USD'!$K:$K,B13,'Full BS-USD'!$B:$B) -> -28375.56 | O13: =+SUMIF('Full BS-USD'!$K:$K,B13,'Full BS-USD'!$J:$J) -> 2037911.9 | P13: =+O13-SUM(E13:L13) -> 0 | Q13: =+ROUND((O13/1000),0)-1 -> 2037 | S13: =+NOTES!B5 -> 3
B14: 13 | C14: other recievables and prepaid expenses | E14: =+SUMIF('Full BS-USD'!$K:$K,B14,'Full BS-USD'!$C:$C) -> 754723.55 | F14: =+SUMIF('Full BS-USD'!$K:$K,B14,'Full BS-USD'!$D:$D) -> 4129.04 | G14: =+SUMIF('Full BS-USD'!$K:$K,B14,'Full BS-USD'!$E:$E) -> 491.94 | H14: =+SUMIF('Full BS-USD'!$K:$K,B14,'Full BS-USD'!$F:$F) -> 48261.82 | I14: =+SUMIF('Full BS-USD'!$K:$K,B14,'Full BS-USD'!$G:$G)+1012 -> 2440457 | J14: =+SUMIF('Full BS-USD'!$K:$K,B14,'Full BS-USD'!$H:$H)+1644 -> 4744524.1 | K14: =+SUMIF('Full BS-USD'!$K:$K,B14,'Full BS-USD'!$I:$I) -> 939180.31 | L14: =+SUMIF('Full BS-USD'!$K:$K,B14,'Full BS-USD'!$B:$B) -> -8155804.9 | O14: =+SUMIF('Full BS-USD'!$K:$K,B14,'Full BS-USD'!$J:$J)+2656 -> 775962.88 | P14: =+O14-SUM(E14:L14) -> 0 | Q14: =+ROUND((O14/1000),0) -> 776 | S14: =+NOTES!B10 -> 4
P15: =+O15-SUM(E15:L15) -> 0 | Q15: =+O15/1000 -> 0
C16: Total cerrent assets | E16: =+SUM(E11:E14) -> 977364.02 | F16: =+SUM(F11:F14) -> 24800.89 | G16: =+SUM(G11:G14) -> 513.75 | H16: =+SUM(H11:H14) -> 48738.37 | I16: =+SUM(I11:I14) -> 3111753.2 | J16: =+SUM(J11:J14) -> 24394413 | K16: =+SUM(K11:K14) -> 1262404.3 | L16: =+SUM(L11:L14) -> -8184180.5 | O16: =+SUM(O11:O14) -> 21635807 | P16: =+O16-SUM(E16:L16) -> 0 | Q16: =+SUM(Q11:Q14) -> 21636
P17: =+O17-SUM(E17:L17) -> 0 | Q17: =+O17/1000 -> 0
P18: =+O18-SUM(E18:L18) -> 0
C19: Long-Term assets: | P19: =+O19-SUM(E19:L19) -> 0
B20: 14 | C20: loans to employees | E20: =+SUMIF('Full BS-USD'!$K:$K,B20,'Full BS-USD'!$C:$C) -> -2371.05 | F20: =+SUMIF('Full BS-USD'!$K:$K,B20,'Full BS-USD'!$D:$D) -> 37427.66 | G20: =+SUMIF('Full BS-USD'!$K:$K,B20,'Full BS-USD'!$E:$E) -> 0 | H20: =+SUMIF('Full BS-USD'!$K:$K,B20,'Full BS-USD'!$F:$F) -> 0 | I20: =+SUMIF('Full BS-USD'!$K:$K,B20,'Full BS-USD'!$G:$G) -> -3045.65 | J20: =+SUMIF('Full BS-USD'!$K:$K,B20,'Full BS-USD'!$H:$H) -> 262306.48 | K20: =+SUMIF('Full BS-USD'!$K:$K,B20,'Full BS-USD'!$I:$I) -> -32.19 | L20: =+SUMIF('Full BS-USD'!$K:$K,B20,'Full BS-USD'!$B:$B) -> -261263.83 | O20: =+SUMIF('Full BS-USD'!$K:$K,B20,'Full BS-USD'!$J:$J) -> 33021.42 | P20: =+O20-SUM(E20:L20) -> 0 | Q20: =+ROUND((O20/1000),0) -> 33
B21: 15 | C21: property and equipment | E21: =+SUMIF('Full BS-USD'!$K:$K,B21,'Full BS-USD'!$C:$C) -> 1036.51 | F21: =+SUMIF('Full BS-USD'!$K:$K,B21,'Full BS-USD'!$D:$D) -> 0 | G21: =+SUMIF('Full BS-USD'!$K:$K,B21,'Full BS-USD'!$E:$E) -> 0 | H21: =+SUMIF('Full BS-USD'!$K:$K,B21,'Full BS-USD'!$F:$F) -> 0 | I21: =+SUMIF('Full BS-USD'!$K:$K,B21,'Full BS-USD'!$G:$G) -> 57330.94 | J21: =+SUMIF('Full BS-USD'!$K:$K,B21,'Full BS-USD'!$H:$H) -> 56102.66 | K21: =+SUMIF('Full BS-USD'!$K:$K,B21,'Full BS-USD'!$I:$I) -> 8608.31 | L21: =+SUMIF('Full BS-USD'!$K:$K,B21,'Full BS-USD'!$B:$B) -> 0 | O21: =+SUMIF('Full BS-USD'!$K:$K,B21,'Full BS-USD'!$J:$J) -> 123078.42 | P21: =+O21-SUM(E21:L21) -> 0 | Q21: =+ROUND((O21/1000),0) -> 123 | S21: 5
P22: =+O22-SUM(E22:L22) -> 0
P23: =+O23-SUM(E23:L23) -> 0
C24: Total Long-term assets | E24: =+E20+E21 -> -1334.54 | F24: =+F20+F21 -> 37427.66 | G24: =+G20+G21 -> 0 | H24: =+H20+H21 -> 0 | I24: =+I20+I21 -> 54285.29 | J24: =+J20+J21 -> 318409.14 | K24: =+K20+K21 -> 8576.12 | L24: =+L20+L21 -> -261263.83 | O24: =+O20+O21 -> 156099.84 | P24: =+O24-SUM(E24:L24) -> 0 | Q24: =+ROUND(O24/1000,0) -> 156
P25: =+O25-SUM(E25:L25) -> 0
P26: =+O26-SUM(E26:L26) -> 0
C27: Total assets | E27: =+E24+E16 -> 976029.48 | F27: =+F24+F16 -> 62228.55 | G27: =+G24+G16 -> 513.75 | H27: =+H24+H16 -> 48738.37 | I27: =+I24+I16 -> 3166038.5 | J27: =+J24+J16 -> 24712823 | K27: =+K24+K16 -> 1270980.5 | L27: =+L24+L16 -> -8445444.3 | O27: =+O24+O16 -> 21791907 | P27: =+O27-SUM(E27:L27) -> 0 | Q27: =+Q24+Q16 -> 21792
Q29: =+O29/1000 -> 0
C30: Liabilities and shareholders' equity
C32: Current Liabilities:
B34: 16 | C34: Trade payables | E34: =+SUMIF('Full BS-USD'!$K:$K,B34,'Full BS-USD'!$C:$C) -> 37909.68 | F34: =+SUMIF('Full BS-USD'!$K:$K,B34,'Full BS-USD'!$D:$D) -> 0 | G34: =+SUMIF('Full BS-USD'!$K:$K,B34,'Full BS-USD'!$E:$E) -> 0 | H34: =+SUMIF('Full BS-USD'!$K:$K,B34,'Full BS-USD'!$F:$F) -> 0 | I34: =+SUMIF('Full BS-USD'!$K:$K,B34,'Full BS-USD'!$G:$G) -> 34022.45 | J34: =+SUMIF('Full BS-USD'!$K:$K,B34,'Full BS-USD'!$H:$H) -> 146906.29 | K34: =+SUMIF('Full BS-USD'!$K:$K,B34,'Full BS-USD'!$I:$I) -> 11256.91 | L34: =+SUMIF('Full BS-USD'!$K:$K,B34,'Full BS-USD'!$B:$B) -> -28375.56 | O34: =+SUMIF('Full BS-USD'!$K:$K,B34,'Full BS-USD'!$J:$J) -> 201719.77 | P34: =+O34-SUM(E34:L34) -> 0 | Q34: =+ROUND((O34/1000),0) -> 202
B35: 17 | C35: Accrued expenses and other liabilities | E35: =+SUMIF('Full BS-USD'!$K:$K,B35,'Full BS-USD'!$C:$C) -> 878638.47 | F35: =+SUMIF('Full BS-USD'!$K:$K,B35,'Full BS-USD'!$D:$D) -> 330.61 | G35: =+SUMIF('Full BS-USD'!$K:$K,B35,'Full BS-USD'!$E:$E) -> 330.61 | H35: =+SUMIF('Full BS-USD'!$K:$K,B35,'Full BS-USD'!$F:$F) -> 8607.33 | I35: =+SUMIF('Full BS-USD'!$K:$K,B35,'Full BS-USD'!$G:$G) -> 2789090.5 | J35: =+SUMIF('Full BS-USD'!$K:$K,B35,'Full BS-USD'!$H:$H) -> 4277167 | K35: =+SUMIF('Full BS-USD'!$K:$K,B35,'Full BS-USD'!$I:$I) -> 993737.4 | L35: =+SUMIF('Full BS-USD'!$K:$K,B35,'Full BS-USD'!$B:$B) -> -8155804.9 | O35: =+SUMIF('Full BS-USD'!$K:$K,B35,'Full BS-USD'!$J:$J) -> 792096.95 | P35: =+O35-SUM(E35:L35) -> 1.0477379e-09 | Q35: =+ROUND((O35/1000),0) -> 792 | S35: =+NOTES!B27 -> 6
C37: Total current liabilities | E37: =+E35+E34 -> 916548.15 | F37: =+F35+F34 -> 330.61 | G37: =+G35+G34 -> 330.61 | H37: =+H35+H34 -> 8607.33 | I37: =+I35+I34 -> 2823112.9 | J37: =+J35+J34 -> 4424073.2 | K37: =+K35+K34 -> 1004994.3 | L37: =+L35+L34 -> -8184180.5 | O37: =+O35+O34 -> 993816.72 | P37: =+O37-SUM(E37:L37) -> 0 | Q37: =+Q35+Q34 -> 994
C40: Non current Liabilities:
B42: 18 | C42: Long-Term liabilities: | E42: =+SUMIF('Full BS-USD'!$K:$K,B42,'Full BS-USD'!$C:$C) -> 0 | F42: =+SUMIF('Full BS-USD'!$K:$K,B42,'Full BS-USD'!$D:$D) -> 0 | G42: =+SUMIF('Full BS-USD'!$K:$K,B42,'Full BS-USD'!$E:$E) -> 261263.83 | H42: =+SUMIF('Full BS-USD'!$K:$K,B42,'Full BS-USD'!$F:$F) -> 0 | I42: =+SUMIF('Full BS-USD'!$K:$K,B42,'Full BS-USD'!$G:$G) -> 0 | J42: =+SUMIF('Full BS-USD'!$K:$K,B42,'Full BS-USD'!$H:$H) -> 414497.66 | K42: =+SUMIF('Full BS-USD'!$K:$K,B42,'Full BS-USD'!$I:$I) -> 49.23 | L42: =+SUMIF('Full BS-USD'!$K:$K,B42,'Full BS-USD'!$B:$B) -> -261263.83 | O42: =+SUMIF('Full BS-USD'!$K:$K,B42,'Full BS-USD'!$J:$J) -> 414546.89 | P42: =+O42-SUM(E42:L42) -> 0 | Q42: =+ROUND(O42/1000,0)-1 -> 414
C44: Shareholders equity
B46: 19 | C46: additrional paid in capital | E46: =+SUMIF('Full BS-USD'!$K:$K,B46,'Full BS-USD'!$C:$C) -> 0 | F46: =+SUMIF('Full BS-USD'!$K:$K,B46,'Full BS-USD'!$D:$D) -> 600244.31 | G46: =+SUMIF('Full BS-USD'!$K:$K,B46,'Full BS-USD'!$E:$E) -> 27.32 | H46: =+SUMIF('Full BS-USD'!$K:$K,B46,'Full BS-USD'!$F:$F) -> 1000280.6 | I46: =+SUMIF('Full BS-USD'!$K:$K,B46,'Full BS-USD'!$G:$G) -> 0 | J46: =+SUMIF('Full BS-USD'!$K:$K,B46,'Full BS-USD'!$H:$H) -> 40523528 | K46: =+SUMIF('Full BS-USD'!$K:$K,B46,'Full BS-USD'!$I:$I) -> 1227 | L46: =+SUMIF('Full BS-USD'!$K:$K,B46,'Full BS-USD'!$B:$B) -> 0 | O46: =+SUMIF('Full BS-USD'!$K:$K,B46,'Full BS-USD'!$J:$J) -> 42125308 | P46: =+O46-SUM(E46:L46) -> 0 | Q46: =+ROUND((O46/1000),0)+1 -> 42126
B47: 20 | C47: Recievable on share account | E47: =+SUMIF('Full BS-USD'!$K:$K,B47,'Full BS-USD'!$C:$C) -> 0 | F47: =+SUMIF('Full BS-USD'!$K:$K,B47,'Full BS-USD'!$D:$D) -> 0 | G47: =+SUMIF('Full BS-USD'!$K:$K,B47,'Full BS-USD'!$E:$E) -> 0 | H47: =+SUMIF('Full BS-USD'!$K:$K,B47,'Full BS-USD'!$F:$F) -> 0 | I47: =+SUMIF('Full BS-USD'!$K:$K,B47,'Full BS-USD'!$G:$G) -> 0 | J47: =+SUMIF('Full BS-USD'!$K:$K,B47,'Full BS-USD'!$H:$H) -> 0 | K47: =+SUMIF('Full BS-USD'!$K:$K,B47,'Full BS-USD'!$I:$I) -> 0 | L47: =+SUMIF('Full BS-USD'!$K:$K,B47,'Full BS-USD'!$B:$B) -> 0 | O47: =+SUMIF('Full BS-USD'!$K:$K,B47,'Full BS-USD'!$J:$J) -> 0 | P47: =+O47-SUM(E47:L47) -> 0 | Q47: =+ROUND((O47/1000),0) -> 0
B48: 21 | C48: Accumulated deficit | E48: =+SUMIF('Full BS-USD'!$K:$K,B48,'Full BS-USD'!$C:$C) -> 59481.33 | F48: =+SUMIF('Full BS-USD'!$K:$K,B48,'Full BS-USD'!$D:$D) -> -538346.37 | G48: =+SUMIF('Full BS-USD'!$K:$K,B48,'Full BS-USD'!$E:$E) -> -261108.01 | H48: =+SUMIF('Full BS-USD'!$K:$K,B48,'Full BS-USD'!$F:$F) -> -960149.58 | I48: =+SUMIF('Full BS-USD'!$K:$K,B48,'Full BS-USD'!$G:$G) -> 342925.47 | J48: =+SUMIF('Full BS-USD'!$K:$K,B48,'Full BS-USD'!$H:$H) -> -20649266 | K48: =+SUMIF('Full BS-USD'!$K:$K,B48,'Full BS-USD'!$I:$I) -> 264709.92 | L48: =+SUMIF('Full BS-USD'!$K:$K,B48,'Full BS-USD'!$B:$B) -> 0 | O48: =+SUMIF('Full BS-USD'!$K:$K,B48,'Full BS-USD'!$J:$J) -> -21741753 | P48: =+O48-SUM(E48:L48) -> 0 | Q48: =+ROUND((O48/1000),0) -> -21742
C50: Total shareholders equity | E50: =+SUM(E46:E48) -> 59481.33 | F50: =+SUM(F46:F48) -> 61897.94 | G50: =+SUM(G46:G48) -> -261080.69 | H50: =+SUM(H46:H48) -> 40131.04 | I50: =+SUM(I46:I48) -> 342925.47 | J50: =+SUM(J46:J48) -> 19874263 | K50: =+SUM(K46:K48) -> 265936.92 | L50: =+SUM(L46:L48) -> 0 | O50: =+SUM(O46:O48) -> 20383555 | Q50: =+SUM(Q46:Q48) -> 20384
C52: Total liabilities and shareholders' equity | E52: =+E50+E42+E37 -> 976029.48 | F52: =+F50+F42+F37 -> 62228.55 | G52: =+G50+G42+G37 -> 513.75 | H52: =+H50+H42+H37 -> 48738.37 | I52: =+I50+I42+I37 -> 3166038.4 | J52: =+J50+J42+J37 -> 24712834 | K52: =+K50+K42+K37 -> 1270980.5 | L52: =+L50+L42+L37 -> -8445444.3 | O52: =+O50+O42+O37 -> 21791918 | Q52: =+Q50+Q42+Q37 -> 21792
C54: check | E54: =+E52-E27 -> 0 | F54: =+F52-F27 -> 5.8207661e-11 | G54: =+G52-G27 -> -4.422418e-11 | H54: =+H52-H27 -> -8.0035534e-11 | I54: =+I52-I27 -> -0.079999999 | J54: =+J52-J27 -> 11.16 | K54: =+K52-K27 -> 0 | L54: =+L52-L27 -> 0 | O54: =+O52-O27 -> 11.08 | Q54: =+Q52-Q27 -> 0

Sheet P&L
C1: Wematch.live
C2: USD
B5: INDEX | E5: WUS- INC | F5: EQD | G5: WIR | H5: WSF- LTD [IL] | I5: WSF LTD | J5: R&D | K5: WTSE | M5: Total
E6: 2022 | F6: 2022 | G6: 2022 | H6: 2022 | I6: 2022 | J6: 2022 | K6: 2022 | M6: 2022 | O6: in 000' | Q6: NOTE
B8: 1 | C8: Revenues | E8: =+SUMIF('Full P&L-USD'!$J:$J,B8,'Full P&L-USD'!$B:$B) -> 0 | F8: =+SUMIF('Full P&L-USD'!$J:$J,B8,'Full P&L-USD'!$C:$C) -> 0 | G8: =+SUMIF('Full P&L-USD'!$J:$J,B8,'Full P&L-USD'!$D:$D) -> 0 | H8: =+SUMIF('Full P&L-USD'!$J:$J,B8,'Full P&L-USD'!$E:$E) -> 0 | I8: =+SUMIF('Full P&L-USD'!$J:$J,B8,'Full P&L-USD'!$F:$F) -> 0 | J8: =+SUMIF('Full P&L-USD'!$J:$J,B8,'Full P&L-USD'!$G:$G) -> 6849954.6 | K8: =+SUMIF('Full P&L-USD'!$J:$J,B8,'Full P&L-USD'!$H:$H) -> 0 | M8: =+SUMIF('Full P&L-USD'!$J:$J,B8,'Full P&L-USD'!$I:$I) -> 6849954.6 | N8: =+M8-SUM(E8:K8) -> 0 | O8: =+ROUND(M8/1000,0) -> 6850 | Q8: =+NOTES!B50 -> 9
N9: =+M9-SUM(E9:K9) -> 0
B10: 2 | C10: Cost of Revenues | E10: =+SUMIF('Full P&L-USD'!$J:$J,B10,'Full P&L-USD'!$B:$B) -> 0 | F10: =+SUMIF('Full P&L-USD'!$J:$J,B10,'Full P&L-USD'!$C:$C) -> 0 | G10: =+SUMIF('Full P&L-USD'!$J:$J,B10,'Full P&L-USD'!$D:$D) -> 0 | H10: =+SUMIF('Full P&L-USD'!$J:$J,B10,'Full P&L-USD'!$E:$E) -> 0 | I10: =+SUMIF('Full P&L-USD'!$J:$J,B10,'Full P&L-USD'!$F:$F) -> -69088.03 | J10: =+SUMIF('Full P&L-USD'!$J:$J,B10,'Full P&L-USD'!$G:$G) -> -1758857 | K10: =+SUMIF('Full P&L-USD'!$J:$J,B10,'Full P&L-USD'!$H:$H) -> -313932.24 | M10: =+SUMIF('Full P&L-USD'!$J:$J,B10,'Full P&L-USD'!$I:$I) -> -2141877.3 | N10: =+M10-SUM(E10:K10) -> 0 | O10: =+ROUND(M10/1000,0) -> -2142 | Q10: =+NOTES!B59 -> 10
N11: =+M11-SUM(E11:K11) -> 0
B12: 3 | C12: Gross profit | E12: =+E8+E10 -> 0 | F12: =+F8+F10 -> 0 | G12: =+G8+G10 -> 0 | H12: =+H8+H10 -> 0 | I12: =+I8+I10 -> -69088.03 | J12: =+J8+J10 -> 5091097.6 | K12: =+K8+K10 -> -313932.24 | M12: =+M8+M10 -> 4708077.3 | N12: =+M12-SUM(E12:K12) -> 0 | O12: =+O8+O10 -> 4708
N13: =+M13-SUM(E13:K13) -> 0
C14: Operating expenses: | N14: =+M14-SUM(E14:K14) -> 0
A15: Total - R&D | B15: 4.1 | C15: R&D | E15: =+SUMIF('Full P&L-USD'!$J:$J,B15,'Full P&L-USD'!$B:$B) -> 96722.92 | F15: =+SUMIF('Full P&L-USD'!$J:$J,B15,'Full P&L-USD'!$C:$C) -> 0 | G15: =+SUMIF('Full P&L-USD'!$J:$J,B15,'Full P&L-USD'!$D:$D) -> 0 | H15: =+SUMIF('Full P&L-USD'!$J:$J,B15,'Full P&L-USD'!$E:$E) -> 0 | I15: =+SUMIF('Full P&L-USD'!$J:$J,B15,'Full P&L-USD'!$F:$F) -> 915306.08 | J15: =+SUMIF('Full P&L-USD'!$J:$J,B15,'Full P&L-USD'!$G:$G) -> 2942658.1 | K15: =+SUMIF('Full P&L-USD'!$J:$J,B15,'Full P&L-USD'!$H:$H) -> 482346.81 | M15: =+VLOOKUP(A15,'Full P&L-USD'!$A:$I,9,0)+'Full P&L-USD'!I126 -> 4437033.9 | N15: =+M15-SUM(E15:K15) -> 0 | O15: =+ROUND(M15/1000,0) -> 4437
A16: Total - S&M | B16: 4.2 | C16: S&M | E16: =+SUMIF('Full P&L-USD'!$J:$J,B16,'Full P&L-USD'!$B:$B) -> 424507.61 | F16: =+SUMIF('Full P&L-USD'!$J:$J,B16,'Full P&L-USD'!$C:$C) -> 0 | G16: =+SUMIF('Full P&L-USD'!$J:$J,B16,'Full P&L-USD'!$D:$D) -> 0 | H16: =+SUMIF('Full P&L-USD'!$J:$J,B16,'Full P&L-USD'!$E:$E) -> 0 | I16: =+SUMIF('Full P&L-USD'!$J:$J,B16,'Full P&L-USD'!$F:$F) -> 2211092 | J16: =+SUMIF('Full P&L-USD'!$J:$J,B16,'Full P&L-USD'!$G:$G) -> 2086267.7 | K16: =+SUMIF('Full P&L-USD'!$J:$J,B16,'Full P&L-USD'!$H:$H) -> 113052.5 | M16: =+VLOOKUP(A16,'Full P&L-USD'!$A:$I,9,0) -> 4834919.8 | N16: =+M16-SUM(E16:K16) -> 0 | O16: =+ROUND(M16/1000,0) -> 4835
A17: Total - G&A | B17: 4.3 | C17: G&A | E17: =+SUMIF('Full P&L-USD'!$J:$J,B17,'Full P&L-USD'!$B:$B) -> 334345.02 | F17: =+SUMIF('Full P&L-USD'!$J:$J,B17,'Full P&L-USD'!$C:$C) -> 353.51 | G17: =+SUMIF('Full P&L-USD'!$J:$J,B17,'Full P&L-USD'!$D:$D) -> 353.51 | H17: =+SUMIF('Full P&L-USD'!$J:$J,B17,'Full P&L-USD'!$E:$E) -> 353.51 | I17: =+SUMIF('Full P&L-USD'!$J:$J,B17,'Full P&L-USD'!$F:$F) -> 722121.38 | J17: =+SUMIF('Full P&L-USD'!$J:$J,B17,'Full P&L-USD'!$G:$G) -> 1893021.2 | K17: =+SUMIF('Full P&L-USD'!$J:$J,B17,'Full P&L-USD'!$H:$H) -> 67638.42 | M17: =+VLOOKUP(A17,'Full P&L-USD'!$A:$I,9,0) -> 3018181.2 | N17: =+M17-SUM(E17:K17)+'Full P&L-USD'!I798 -> -5.587939e-10 | O17: =+ROUND(M17/1000,0) -> 3018
N18: =+M18-SUM(E18:K18) -> 0
A19: Total Operation Expense | B19: 4 | C19: Total Operatiing Expense | E19: =+SUM(E15:E17) -> 855575.55 | F19: =+SUM(F15:F17) -> 353.51 | G19: =+SUM(G15:G17) -> 353.51 | H19: =+SUM(H15:H17) -> 353.51 | I19: =+SUM(I15:I17) -> 3848519.5 | J19: =+SUM(J15:J17) -> 6921947 | K19: =+SUM(K15:K17) -> 663037.73 | M19: =+VLOOKUP(A19,'Full P&L-USD'!$A:$I,9,0) -> 12290140 | N19: =+M19-SUM(E19:K19) -> 0 | O19: =+SUM(O15:O17) -> 12290
N20: =+M20-SUM(E20:K20) -> 0
C21: Operating Loss | E21: =+E12-E19 -> -855575.55 | F21: =+F12-F19 -> -353.51 | G21: =+G12-G19 -> -353.51 | H21: =+H12-H19 -> -353.51 | I21: =+I12-I19 -> -3917607.5 | J21: =+J12-J19 -> -1830849.4 | K21: =+K12-K19 -> -976969.97 | M21: =+M12-M19 -> -7582063 | O21: =+O12-O19 -> -7582
B23: 5 | C23: Earning/(Loss) Before Interest & Tax | E23: =+E12-E19 -> -855575.55 | F23: =+F12-F19 -> -353.51 | G23: =+G12-G19 -> -353.51 | H23: =+H12-H19 -> -353.51 | I23: =+I12-I19 -> -3917607.5 | J23: =+J12-J19 -> -1830849.4 | K23: =+K12-K19 -> -976969.97 | M23: =+M12-M19 -> -7582063 | N23: =+M23-SUM(E23:K23) -> 0 | O23: =+O12-O19 -> -7582
N24: =+M24-SUM(E24:K24) -> 0
B25: 6 | C25: Financial expenses, net | E25: =+SUMIF('Full P&L-USD'!$J:$J,B25,'Full P&L-USD'!$B:$B) -> 186.03 | F25: =+SUMIF('Full P&L-USD'!$J:$J,B25,'Full P&L-USD'!$C:$C) -> -51.51 | G25: =+SUMIF('Full P&L-USD'!$J:$J,B25,'Full P&L-USD'!$D:$D) -> -111.66 | H25: =+SUMIF('Full P&L-USD'!$J:$J,B25,'Full P&L-USD'!$E:$E) -> 221.48 | I25: =+SUMIF('Full P&L-USD'!$J:$J,B25,'Full P&L-USD'!$F:$F) -> -99081.95 | J25: =+SUMIF('Full P&L-USD'!$J:$J,B25,'Full P&L-USD'!$G:$G) -> 323867.05 | K25: =+SUMIF('Full P&L-USD'!$J:$J,B25,'Full P&L-USD'!$H:$H) -> -21418.02 | M25: =+SUMIF('Full P&L-USD'!$J:$J,B25,'Full P&L-USD'!$I:$I) -> 203611.42 | N25: =+M25-SUM(E25:K25) -> 0 | O25: =+ROUND(M25/1000,0) -> 204 | Q25: =+NOTES!B67 -> 11
N26: =+M26-SUM(E26:K26) -> 0
B27: 7 | C27: Loss Before Taxes On Income | E27: =+E25+E23 -> -855389.52 | F27: =+F25+F23 -> -405.02 | G27: =+G25+G23 -> -465.17 | H27: =+H25+H23 -> -132.03 | I27: =+I25+I23 -> -4016689.4 | J27: =+J25+J23 -> -1506982.4 | K27: =+K25+K23 -> -998387.99 | M27: =+M25+M23 -> -7378451.5 | N27: =+M27-SUM(E27:K27) -> 0 | O27: =+O25+O23 -> -7378
N28: =+M28-SUM(E28:K28) -> 0
B29: 8 | C29: Tax on Income | E29: =+SUMIF('Full P&L-USD'!$J:$J,B29,'Full P&L-USD'!$B:$B) -> -15762.04 | F29: =+SUMIF('Full P&L-USD'!$J:$J,B29,'Full P&L-USD'!$C:$C) -> 0 | G29: =+SUMIF('Full P&L-USD'!$J:$J,B29,'Full P&L-USD'!$D:$D) -> 0 | H29: =+SUMIF('Full P&L-USD'!$J:$J,B29,'Full P&L-USD'!$E:$E) -> 0 | I29: =+SUMIF('Full P&L-USD'!$J:$J,B29,'Full P&L-USD'!$F:$F) -> -63044.47 | J29: =+SUMIF('Full P&L-USD'!$J:$J,B29,'Full P&L-USD'!$G:$G) -> 0 | K29: =+SUMIF('Full P&L-USD'!$J:$J,B29,'Full P&L-USD'!$H:$H) -> 65201.39 | M29: =+SUMIF('Full P&L-USD'!$J:$J,B29,'Full P&L-USD'!$I:$I) -> -13605.12 | N29: =+M29-SUM(E29:K29) -> 0 | O29: =+ROUND(M29/1000,0) -> -14
N30: =+M30-SUM(E30:K30) -> 0
C31: Net Loss | E31: =+E27+E29 -> -871151.56 | F31: =+F27+F29 -> -405.02 | G31: =+G27+G29 -> -465.17 | H31: =+H27+H29 -> -132.03 | I31: =+I27+I29 -> -4079733.9 | J31: =+J27+J29 -> -1506982.4 | K31: =+K27+K29 -> -933186.6 | M31: =+M27+M29 -> -7392056.7 | N31: =+M31-SUM(E31:K31) -> 0 | O31: =+O27+O29 -> -7392

Sheet CF
A4: Cash flows from operating activities:
C5: As of December 31, 2022
C7: US thousand
A9: Net loss | C9: =-E96 -> -7392
A11: Adjustments to reconcile net loss to net cash provided by operating activities:
A14: Depreciation and amortization and impermanent | C14: =-E83 -> 29.55433
A15: Share-based compensation expense | C15: =-E93 -> 258.137
A16: Change in employee long term loans | C16: =-E82 -> 4.428
A17: Change in long time employee benefit | C17: =-E89 -> 20.77
A19: Change in SAFE fair value | C19: =-E88 -> 0
A21: Changes in operating assets and liabilities:
A22: Accounts receivable | C22: =-E80 -> -1020.612
A23: Prepaid expenses and other assets | C23: =-E81 -> -523.098
A24: Accounts payable | C24: =-E84 -> 70
A25: Accrued expenses and other liabilities | C25: =-E85 -> 27.617
A26: Change in Deferred revenue | C26: =-E86 -> 0.001
A28: Net cash provided by operating activities | C28: =SUM(C9:C27) -> -8525.2027
A30: Cash flows from investing activities:
A32: Change in short term restricted deposit | C32: =-F79-284 -> -11415.935
A33: Purchases of property and equipment | C33: =-F83 -> -92.416
A35: Net cash used in investing activities | C35: =-F97 -> -11224.351
A37: Cash flows from financing activities:
A39: Proceeds from issuance of Sample agreement for future equity ("SAFE") | C39: 0
A40: Proceeds from opsions excersize | C40: =-G91 -> 7
A41: Issuance of Preferred B shares, net of issuance cost
A42: Proceeds from issuance of convertible preferred shares, net of issuance costs
A44: Net cash provided by financing activities | C44: =+C42+C41+C39+C40 -> 7
A46: Net increase (decrease) in cash, cash equivalents, and restricted cash | C46: =+C44+C28+C35 -> -19742.554
A47: Cash, cash equivalents, and restricted cash—beginning of period | C47: =+D78 -> 27403
A49: Cash, cash equivalents, and restricted cash—end of period | C49: =+C46+C47 -> 7660.4463 | D49: =+J78 -> 7660 | E49: =+C49-D49 -> 0.44633
E55: אם הפקדונות משמשים לפעילות השוטפת או נזילים תוך פחות מ-3 חודשים הם מסווגים כמזומן ושווי מזומן
E56: .
F71: Working peper for cash flow
D75: Closing balance as | E75: Cash flow from | F75: Cash flow from | G75: Cash flow from | J75: Closing balance as
D76: 44561 | E76: Opeartion | F76: Investing | G76: Financing | H76: Non-cash activites | I76: Change in cash | J76: 44926 | L76: Check
B78: 10 | C78: Cash and cash equivalents | D78: =27403 -> 27403 | I78: =J78-D78-E78 -> -19743 | J78: =+'BS USD'!Q11 -> 7660 | K78: =+J78-'BS USD'!$Q11 -> 0 | L78: =SUM(D78:I78)-J78 -> 0
B79: 11 | C79: Restricted Bank Deposit | D79: 31.065 | F79: =J79-D79 -> 11131.935 | J79: =+'BS USD'!Q12 -> 11163 | K79: =+J79-'BS USD'!$Q12 -> 0 | L79: =SUM(D79:I79)-J79 -> 0
B80: 12 | C80: Account Receivable | D80: 1016.388 | E80: =J80-D80 -> 1020.612 | J80: =+'BS USD'!Q13 -> 2037 | K80: =+J80-'BS USD'!$Q13 -> 0 | L80: =SUM(D80:I80)-J80 -> 0
B81: 13 | C81: Prepaid expenses and other current assets | D81: 252.902 | E81: =J81-D81 -> 523.098 | J81: =+'BS USD'!Q14 -> 776 | K81: =+J81-'BS USD'!$Q14 -> 0 | L81: =SUM(D81:I81)-J81 -> 0
B82: 14 | C82: Other long term accounts receivables | D82: 37.428 | E82: =J82-D82 -> -4.428 | J82: =+'BS USD'!Q20 -> 33 | K82: =+J82-'BS USD'!$Q20 -> 0 | L82: =SUM(D82:I82)-J82 -> 0
...

Sheet Change in Equity
D3: Ordinary shares | H3: Preferred Shares | L3: Additional | N3: Receivable on | P3: Accumulated | R3: Total shareholders' equity
L4: paid-in
D5: Number | F5: Amount | H5: Number | J5: Amount | L5: capital | N5: Shares account | P5: deficit | R5: (deficit)
B7: Balance as of January 1, 2021 | D7: 1401739 | F7: 4 | H7: 198028 | J7: (*) | L7: 12952 | N7: -50 | P7: -10806 | R7: =+P7+F7+L7+N7 -> 2100
B9: Net loss and other comprehensive loss | D9: 0 | F9: 0 | H9: 0 | J9: 0 | L9: 0 | N9: 0 | P9: -3272 | R9: =+P9+F9+L9+J9 -> -3272
B10: Receivable of shares | N10: 50 | R10: =+P10+F10+L10+J10+N10 -> 50
B11: Share based compensation | D11: 0 | F11: 0 | H11: 0 | J11: 0 | L11: 565 | N11: 0 | P11: 0 | R11: =+P11+F11+L11+J11 -> 565
B12: Warrant exercise | H12: 315996 | J12: 1 | L12: 3124 | R12: =+P12+F12+L12+J12 -> 3125
B13: SAFE exercise | D13: 0 | F13: 0 | H13: 105500 | J13: 1 | L13: =[1]CF!D35+[1]CF!D15-1 -> -1 | N13: - | P13: 0 | R13: =+P13+F13+L13+J13 -> 0
B14: Issuance of preferred B Shares, net of issuance cost | D14: 0 | F14: 0 | H14: =570204+293045 -> 863249 | J14: 3 | L14: 24940 | P14: 0 | R14: =+P14+J14+L14+N14 -> 24943
B16: Balance as of December 31, 2021 | D16: =SUM(D7:D15) -> 1401739 | F16: =SUM(F7:F15) -> 4 | H16: =SUM(H7:H15) -> 1482773 | J16: =SUM(J7:J15) -> 5 | L16: =SUM(L7:L15) -> 41580 | N16: =SUM(N7:N15) -> 0 | P16: =SUM(P7:P15) -> -14078 | R16: =+P16+F16+L16+N16+J16 -> 27511
B18: Net loss and other comprehensive loss | D18: 0 | F18: 0 | H18: 0 | J18: 0 | L18: 0 | N18: 0 | P18: =+'P&L'!O31 -> -7392 | R18: =SUM(J18:P18,F18) -> -7392
B19: recievable on account of shares | D19: 800 | R19: =SUM(J19:P19,F19) -> 0
B20: Share based compensation | D20: =584+1216 -> 1800 | L20: =-CF!E93+7 -> 265.137 | R20: =SUM(J20:P20,F20) -> 265.137
B21: SAFE exercise | R21: =SUM(J21:P21,F21) -> 0
B22: Warrant exercise | H22: 127247 | J22: (*) | R22: =SUM(J22:P22,F22) -> 0
B23: Issuance of preferred A Shares, net of issuance cost
B24: Issuance of ordinary stocks, net of issuance cost | F24: 0 | P24: 0 | R24: =SUM(J24:P24,F24) -> 0
B26: Balance as of December 31, 2022 | D26: =SUM(D16:D24) -> 1404339 | F26: =SUM(F16:F24) -> 4 | H26: =SUM(H16:H24) -> 1610020 | J26: =SUM(J16:J24) -> 5 | L26: =SUM(L16:L24) -> 41845.137 | N26: =SUM(N16:N24) -> 0 | P26: =SUM(P16:P24) -> -21470 | R26: =+R16+R18+R20 -> 20384.137
D28: =+D16+D19+D20-D26 -> 0 | H28: =+H16+H22-H26 -> 0 | L28: =+L16+L20-L26 -> 0 | P28: =+P16+P18-P26 -> 0 | Q28: =+Q16+Q18-Q26 -> 0
R29: =+'BS USD'!Q50-R26 -> -0.137

Sheet JE'S
B5: 1 | D5: AR-DR Offset | G5: JEIL-01719
C9: D | D9: 12002 AR OFFSET | E9: 47763.9
C10: C | D10: 26002 DR OFFSET | E10: 47763.9
B14: 2 | D14: NS Open balance correction | G14: JE10500 | H14: =+'AP correction OB'!H2 -> A
F16: USD | G16: ILS
C17: D | D17: WEQD - 10010 Bank BIA | F17: 14237.25 | G17: =+F17/0.32154341 -> 44277.847 | I17: Max corrected the open balance
C18: C | D18: Retained Earnings | F18: =+F17 -> 14237.25 | G18: =+F18/0.32154341 -> 44277.847
D21: JE10500 | E21: reversal--> | G21: JEIL-03302
F22: USD | G22: ILS
C23: D | D23: Retained Earnings | F23: =+F24+F25 -> 2750.4 | G23: =+F23/0.32154341 -> 8553.744
C24: C | D24: AP Z Hotel | F24: 652.27 | G24: =+F24/0.32154341 -> 2028.5597
C25: C | D25: AP Vissensa Ltd | F25: 2098.13 | G25: =+F25/0.32154341 -> 6525.1843
F28: USD | G28: ILS | H28: JEIL-03349
C29: D | D29: I digital | G29: 2855 | I29: Open balance correction | L29: FX rate | M29: 0.26342132
C30: C | D30: 67301 | G30: =+G29 -> 2855
B35: 3 | D35: Rent pad upfront- wework | G35: JEIL-03339
G36: ILS
C37: D | D37: 67101 Rent | G37: 53520
C38: C | D38: 20001 AP | G38: =+G37 -> 53520

Sheet NOTES
D3: Balance Sheet Notes
B5: 3 | D5: Trade recievables | E5: =+SUMIF('Full BS-USD'!$K$9:$K$201,F5,'Full BS-USD'!$J$9:$J$201)/1000-1 -> 1582.7382 | F5: 12.1
D6: Unbilled revenue | E6: =SUMIF('Full BS-USD'!$K$9:$K$201,F6,'Full BS-USD'!$J$9:$J$201)/1000-E5-2 -> 453.17373 | F6: 12
E7: =SUM(E5:E6) -> 2035.9119
E8: =+E7-'BS USD'!Q13 -> -1.08809
B10: 4 | D10: Prepaid expenses | E10: =+SUMIF('Full BS-USD'!$K$9:$K$201,F10,'Full BS-USD'!$J$9:$J$201)/1000 -> 404.47206 | F10: 13.1
D11: Government institutions | E11: =+SUMIF('Full BS-USD'!$K$9:$K$201,F11,'Full BS-USD'!$J$9:$J$201)/1000 -> 197.99699 | F11: 13.2
D12: Other current assts | E12: =SUMIF('Full BS-USD'!$K$9:$K$201,F12,'Full BS-USD'!$J$9:$J$201)/1000-E11-E10-'Full BS-USD'!J143/1000 -> 173.50492 | F12: 13
E13: =SUM(E10:E12) -> 775.97397
E14: =+E13-'BS USD'!Q14 -> -0.02603
B15: 5 | D15: Cost:
D16: Computers & Software | E16: =+SUMIF('Full BS-USD'!$K$9:$K$201,F16,'Full BS-USD'!$J$9:$J$201)/1000 -> 197.37263 | F16: 15.1
D17: Office furniture | E17: =+SUMIF('Full BS-USD'!$K$9:$K$201,F17,'Full BS-USD'!$J$9:$J$201)/1000 -> 18.92198 | F17: 15.2
D18: Leasehold improvements | E18: =SUMIF('Full BS-USD'!$K$9:$K$201,F18,'Full BS-USD'!$J$9:$J$201)/1000 -> 2.65233 | F18: 15.3
E19: =SUM(E16:E18) -> 218.94694
D21: Accumulated depritiation | E21: =SUMIF('Full BS-USD'!$K$9:$K$201,F21,'Full BS-USD'!$J$9:$J$201)/1000 -> -95.86852 | F21: 15.4
D23: Preperty and equipment, net | E23: =+E19+E21 -> 123.07842
E24: =+E23-'BS USD'!Q21 -> 0.07842
B27: 6 | D27: Accrued employee compensation and benefits | E27: =+SUMIF('Full BS-USD'!$K$9:$K$201,F27,'Full BS-USD'!$J$9:$J$201)/1000 -> 542.77519 | F27: 17.1
D28: Accrued expenses | E28: =+SUMIF('Full BS-USD'!$K$9:$K$201,F28,'Full BS-USD'!$J$9:$J$201)/1000 -> 136.42016 | F28: 17.2
D29: Income and indirect tax payable | E29: =+SUMIF('Full BS-USD'!$K$9:$K$201,F29,'Full BS-USD'!$J$9:$J$201)/1000-E28-E27 -> 112.9016 | F29: 17 | G29: includes DR
E30: =SUM(E27:E29) -> 792.09695
E31: =+E30-'BS USD'!Q35 -> 0.09695
B33: 8 | D33: Share capital: | O33: Shareholders' equity
O35: 2022
E36: Authorized | F36: issued and outstanding | J36: Authorized | K36: issued and outstanding | O36: number of options | P36: weightes average excersise price
E37: December 31,2022 | J37: December 31,2021 | N37: Balance as of December 31,2021
D38: ordinary shares | E38: 3074000 | F38: 1223458 | J38: 3074000 | K38: 1220858 | N38: Granted
D39: ordinary A Shares | E39: 205000 | F39: 180881 | J39: 205000 | K39: 180881 | N39: Balance as of December 31,2022
D40: Preferred A shares (*) | E40: 651000 | F40: 641271 | J40: 651000 | K40: 514024 | N40: Excercisable as of December 31,2021
D41: preferred B shares (*) | E41: 1070000 | F41: 967678 | G41: =+K41 -> 968749 | H41: =+F41-G41 -> -1071 | J41: 1070000 | K41: 968749
E42: =SUM(E38:E41) -> 5000000 | F42: =SUM(F38:F41) -> 3013288 | J42: =SUM(J38:J41) -> 5000000 | K42: =SUM(K38:K41) -> 2884512
K45: The information is taken from Carta- "Summery Cap Table" report
D48: P&L Notes
B50: 9
D51: Subscription fees | E51: 5884 | F51: From rev File
D52: Variable Fees | E52: =965+97 -> 1062 | F52: From rev File
E53: =SUM(E51:E52) -> 6946
E54: =+'P&L'!O8 -> 6850 | F54: NS
E55: =+E53-E54 -> 96 | F55: DIFF
...

Sheet Options -Outstanding Awards
B5: Number of Awards | C5: Weighted Average Exercise Price | D5: Weighted Average Share Price on Date of Exercise | E5: Weighted Average Remaining Contractual Life | F5: Aggregate Intrinsic Value
A6: Outstanding, beginning of period | B6: 146702 | C6: 8.431322 | F6: 3604274.2
A7: Granted | B7: 23750 | C7: 21.18
A8: Exercised/Released | B8: -2600 | C8: 4.3474829 | D8: 4.3474829
A9: Cancelled/Forfeited | B9: -5752 | C9: 13.90386
A10: Expired | B10: -765 | C10: 12.5
A11: Outstanding, End of period | B11: 161335 | C11: 10.159456 | E11: 7.7855858 | F11: 3684979.2
A12: Exercisable, End of period | B12: 89352 | C12: 4.9935285 | E12: 6.9678835 | F12: 2502434.2
B18: 2022
B19: Number of options | C19: Weightes average exercise price | E19: *
A20: Balance as of December 31,2021 | B20: 105702 | C20: 5.47 | E20: =+B20/B22 -> 0.81653431 | F20: =+C20*E20 -> 4.4664427 | L20: From Carta
A21: Granted | B21: =+B7 -> 23750 | C21: =+C7 -> 21.18 | E21: =+B21/B22 -> 0.18346569 | F21: =+E21*C21 -> 3.8858032 | L21: Wematch.live R&D LTD Options Exercised & RSUs Settled
A22: Balance as of December 31,2022 | B22: =+B21+B20 -> 129452 | C22: 8.35 | D22: * | F22: =+F21+F20 -> 8.3522459 | L22: As of 12/31/2022 • Generated by Hila Eliasi (hila.eliasi@wematch.live) at 08/10/2023 06:10:37
A23: Excercisable as of December 31,2022 | B23: =+B12 -> 89352 | C23: =+C12 -> 4.9935285
L24: ID | M24: Optionholder | N24: Employee ID | O24: Shares Exercised | P24: Grant Date | Q24: Exercise Request Date | R24: Off System Transaction | S24: Exercise Price | T24: Total Exercise Price
L25: ES-1008 | M25: Rudy Perez | O25: 1216 | P25: 43586 | Q25: 44650 | S25: 0.002783 | T25: =O25*S25 -> 3.384128
L26: ES-1019 | M26: Eitan Katz | O26: 800 | P26: 43952 | Q26: 44921 | S26: 5 | T26: =O26*S26 -> 4000
L27: ES-1054 | M27: Rudy Perez | O27: 584 | P27: 44317 | Q27: 44650 | S27: 12.5 | T27: =O27*S27 -> 7300
A28: Grant date | B28: number of options granted during 2022 | C28: number of options excercised during 2022 | D28: Options outstanding as of December 31, 2022 | E28: Exercise price | F28: Options excercisable as of December 31,2022 | G28: Excercisable through
A29: 43647 | B29: 14900 | C29: =+O25 -> 1216 | D29: =+C29+B29 -> 16116 | E29: 0.001 | F29: 7450 | G29: =+A29+365*10+3 -> 47300
A30: 43952 | B30: 9500 | C30: =+O26 -> 800 | E30: 5 | G30: =+A30+365*10+2 -> 47604
A31: 44317 | B31: 300 | C31: =+O27 -> 584 | D31: =+C31+B31 -> 884 | E31: 12.5 | F31: 100 | G31: =+A31+365*10+2 -> 47969
A32: 01/05/2022 | B32: 11800 | C32: - | E32: =+C7 -> 21.18 | F32: =+F33 -> 89352 | G32: =+A32+365*10+3 -> 48335
A33: 22/09/2022 | B33: 11950 | C33: - | D33: =+B11 -> 161335 | E33: =+E32 -> 21.18 | F33: =+B12 -> 89352 | G33: =+A33+365*10+3 -> 48479
E39: December 31,
E40: 2022 | F40: 2021
D41: CogS | E41: 0 | F41: 5 | J41: CogS | L41: -1450
D42: R&D | E42: 80 | F42: 134 | J42: R&D | K42: Product | L42: 60098
D43: S&M | E43: 51 | F43: 125 | K43: Technology | L43: 19839
D44: G&A | E44: 131 | F44: 301 | J44: S&M | K44: Sales | L44: 63820
E45: =SUM(E41:E44) -> 262 | F45: =SUM(F41:F44) -> 565 | K45: Marketing | L45: -13087
J46: G&A | L46: =97986+19940+1135+12277 -> 131338
L47: =SUM(L41:L46) -> 260558
B53: 01/08/2023 from Carta | C53: 66288
B54: Niv Sabag | C54: -800
B55: Shane Martin | C55: -2000
B56: Christine Lowe | C56: -1000
B57: Jason Hunter | C57: -750
B58: Jason Hunter | C58: -1500
B59: Shane Martin | C59: -2000
...

Sheet Options JE's
A5: Expense to Amortize for the Period | B5: Debit | C5: Credit
A6: Compensation Expense | B6: 440195.56
A7: Additional Paid-in-Capital | C7: 440195.56
A8: Expense (Fair Value) of Awards Exercised / Released in Period | B8: Debit | C8: Credit
A9: Additional Paid-in-Capital | B9: 40288.686
A10: Cash | B10: 11312.16
A11: Common Stock | C11: 51600.846
A12: Expiration | B12: Debit | C12: Credit
A13: Additional Paid-in-Capital | B13: 4466.7839
A14: Premium | C14: 4466.7839

Sheet Full BS-USD
A1: Wematch.live R&D LTD
A2: Wematch.live R&D LTD (Consolidated)
A3: Balance Sheet
A4: End of FY 2022
A7: Financial Row | B7: Elimination | C7: WEMATCH.SUPPORT US INC. | D7: Wematch EQD LTD | E7: Wematch Interest rate LTD | F7: Wematch Securities. Financing LTD [IL] | G7: Wematch.SecuritiesFinancing LTD | H7: Wematch.live R&D LTD | I7: Wematch.live Tech Support Europe | J7: Total | K7: INDEX
B8: Amount | C8: Amount | D8: Amount | E8: Amount | F8: Amount | G8: Amount | H8: Amount | I8: Amount | J8: Amount
A9: Current Assets
A10: Bank
A11: 10000 - Cash and Cash Equivalent (WRD-IL)
A12: 10001 - Bank Fibi 327492 NIS | B12: 0 | C12: 0 | D12: 0 | E12: 0 | F12: 0 | G12: 0 | H12: 98942.75 | I12: 0 | J12: =SUM(B12:I12) -> 98942.75
A13: 10002 - Bank Hapoalim 120737 NIS | B13: 0 | C13: 0 | D13: 0 | E13: 0 | F13: 0 | G13: 0 | H13: 184405.88 | I13: 0 | J13: =SUM(B13:I13) -> 184405.88
A14: 10003 - Bank Hapoalim 120737 USD | B14: 0 | C14: 0 | D14: 0 | E14: 0 | F14: 0 | G14: 0 | H14: 6136719.3 | I14: 0 | J14: =SUM(B14:I14) -> 6136719.3
A15: 10004 - Bank Hapoalim 120737 GBP | B15: 0 | C15: 0 | D15: 0 | E15: 0 | F15: 0 | G15: 0 | H15: 11685.56 | I15: 0 | J15: =SUM(B15:I15) -> 11685.56
A16: 10005 - Bank Hapoalim 120737 EUR | B16: 0 | C16: 0 | D16: 0 | E16: 0 | F16: 0 | G16: 0 | H16: 16813.13 | I16: 0 | J16: =SUM(B16:I16) -> 16813.13
A17: Total - 10000 - Cash and Cash Equivalent (WRD-IL) | B17: =SUM(B12:B16) -> 0 | C17: =SUM(C12:C16) -> 0 | D17: =SUM(D12:D16) -> 0 | E17: =SUM(E12:E16) -> 0 | F17: =SUM(F12:F16) -> 0 | G17: =SUM(G12:G16) -> 0 | H17: =SUM(H12:H16) -> 6448566.6 | I17: =SUM(I12:I16) -> 0 | J17: =SUM(J12:J16) -> 6448566.6 | K17: 10
A18: 101 - Dummy USD [UK] | B18: 0 | C18: 0 | D18: 0 | E18: 0 | F18: 0 | G18: -0.01 | H18: 0 | I18: 0 | J18: =SUM(B18:I18) -> -0.01
A19: 10100 - Cash and Cash Equivalent (WIR-IL)
A20: 10101 - Bank Hapoalim 120720 NIS | B20: 0 | C20: 0 | D20: 0 | E20: 21.81 | F20: 0 | G20: 0 | H20: 0 | I20: 0 | J20: =SUM(B20:I20) -> 21.81
A21: Total - 10100 - Cash and Cash Equivalent (WIR-IL) | B21: =SUM(B20) -> 0 | C21: =SUM(C20) -> 0 | D21: =SUM(D20) -> 0 | E21: =SUM(E20) -> 21.81 | F21: =SUM(F20) -> 0 | G21: =SUM(G20) -> 0 | H21: =SUM(H20) -> 0 | I21: =SUM(I20) -> 0 | J21: =SUM(J20) -> 21.81 | K21: 10
A22: 10200 - Cash and Cash Equivalent (WSF-IL)
A23: 10201 - Bank Hapoalim 120729 NIS | B23: 0 | C23: 0 | D23: 0 | E23: 0 | F23: 124.45 | G23: 0 | H23: 0 | I23: 0 | J23: =SUM(B23:I23) -> 124.45
A24: 10202 - Bank Hapoalim 120729 USD | B24: 0 | C24: 0 | D24: 0 | E24: 0 | F24: 24.67 | G24: 0 | H24: 0 | I24: 0 | J24: =SUM(B24:I24) -> 24.67
A25: 10203 - Bank Hapoalim 120729 EUR | B25: 0 | C25: 0 | D25: 0 | E25: 0 | F25: 327.43 | G25: 0 | H25: 0 | I25: 0 | J25: =SUM(B25:I25) -> 327.43
A26: Total - 10200 - Cash and Cash Equivalent (WSF-IL) | B26: =SUM(B23:B25) -> 0 | C26: =SUM(C23:C25) -> 0 | D26: =SUM(D23:D25) -> 0 | E26: =SUM(E23:E25) -> 0 | F26: =SUM(F23:F25) -> 476.55 | G26: =SUM(G23:G25) -> 0 | H26: =SUM(H23:H25) -> 0 | I26: =SUM(I23:I25) -> 0 | J26: =SUM(J23:J25) -> 476.55 | K26: 10
A27: 10300 - Cash and Cash Equivalent (WEQD-IL)
A28: 10301 - Bank Hapoalim 120702 NIS | B28: 0 | C28: 0 | D28: -3.42 | E28: 0 | F28: 0 | G28: 0 | H28: 0 | I28: 0 | J28: =SUM(B28:I28) -> -3.42
A29: 10302 - Bank Hapoalim 120702 USD | B29: 0 | C29: 0 | D29: 6438.02 | E29: 0 | F29: 0 | G29: 0 | H29: 0 | I29: 0 | J29: =SUM(B29:I29) -> 6438.02
A30: 10303 - Bank BIA | B30: 0 | C30: 0 | D30: 14237.25 | E30: 0 | F30: 0 | G30: 0 | H30: 0 | I30: 0 | J30: =SUM(B30:I30) -> 14237.25
A31: Total - 10300 - Cash and Cash Equivalent (WEQD-IL) | B31: =SUM(B28:B30) -> 0 | C31: =SUM(C28:C30) -> 0 | D31: =SUM(D28:D30) -> 20671.85 | E31: =SUM(E28:E30) -> 0 | F31: =SUM(F28:F30) -> 0 | G31: =SUM(G28:G30) -> 0 | H31: =SUM(H28:H30) -> 0 | I31: =SUM(I28:I30) -> 0 | J31: =SUM(J28:J30) -> 20671.85 | K31: 10
A32: 10400 - Cash and Cash Equivalent (WSF-UK)
A33: 10401 - Bank Netwest 27557405 GBP | B33: 0 | C33: 0 | D33: 0 | E33: 0 | F33: 0 | G33: 671296.2 | H33: 0 | I33: 0 | J33: =SUM(B33:I33) -> 671296.2
A34: Total - 10400 - Cash and Cash Equivalent (WSF-UK) | B34: =SUM(B33) -> 0 | C34: =SUM(C33) -> 0 | D34: =SUM(D33) -> 0 | E34: =SUM(E33) -> 0 | F34: =SUM(F33) -> 0 | G34: =SUM(G33) -> 671296.2 | H34: =SUM(H33) -> 0 | I34: =SUM(I33) -> 0 | J34: =SUM(J33) -> 671296.2 | K34: 10
A35: 10500 - Cash and Cash Equivalent (WTSE-FR)
A36: 10501 - Bank SG 20020671 EUR | B36: 0 | C36: 0 | D36: 0 | E36: 0 | F36: 0 | G36: 0 | H36: 0 | I36: 294848.47 | J36: =SUM(B36:I36) -> 294848.47
A37: Total - 10500 - Cash and Cash Equivalent (WTSE-FR) | B37: =SUM(B36) -> 0 | C37: =SUM(C36) -> 0 | D37: =SUM(D36) -> 0 | E37: =SUM(E36) -> 0 | F37: =SUM(F36) -> 0 | G37: =SUM(G36) -> 0 | H37: =SUM(H36) -> 0 | I37: =SUM(I36) -> 294848.47 | J37: =SUM(J36) -> 294848.47 | K37: 10
A38: 10600 - Cash and Cash Equivalent (WUS-US)
A39: 10601 - Bank Hapoalim 542 Saving USD | B39: 0 | C39: 180344.74 | D39: 0 | E39: 0 | F39: 0 | G39: 0 | H39: 0 | I39: 0 | J39: =SUM(B39:I39) -> 180344.74
A40: 10602 - Bank Hapoalim 0700 Checking USD | B40: 0 | C40: 42295.73 | D40: 0 | E40: 0 | F40: 0 | G40: 0 | H40: 0 | I40: 0 | J40: =SUM(B40:I40) -> 42295.73
A41: Total - 10600 - Cash and Cash Equivalent (WUS-US) | B41: =SUM(B39:B40) -> 0 | C41: =SUM(C39:C40) -> 222640.47 | D41: =SUM(D39:D40) -> 0 | E41: =SUM(E39:E40) -> 0 | F41: =SUM(F39:F40) -> 0 | G41: =SUM(G39:G40) -> 0 | H41: =SUM(H39:H40) -> 0 | I41: =SUM(I39:I40) -> 0 | J41: =SUM(J39:J40) -> 222640.47 | K41: 10
A42: 11000 - Short-term Restricted cash
...

Sheet Full P&L-USD
A1: Wematch.live R&D LTD
A2: Wematch.live R&D LTD (Consolidated)
A3: WM INCOME STATEMENT
A4: From Jan 2022 to Dec 2022
A7: Financial Row | B7: WEMATCH.SUPPORT US INC. | C7: Wematch EQD LTD | D7: Wematch Interest rate LTD | E7: Wematch Securities. Financing LTD [IL] | F7: Wematch.SecuritiesFinancing LTD | G7: Wematch.live R&D LTD | H7: Wematch.live Tech Support Europe | I7: Total | J7: INDEX | L7: note
B8: Amount | C8: Amount | D8: Amount | E8: Amount | F8: Amount | G8: Amount | H8: Amount | I8: Amount
A9: Gross Income
A10: TRS | B10: 0 | C10: 0 | D10: 0 | E10: 0 | F10: 0 | G10: 5714412.2 | H10: 0 | I10: =SUM(B10:H10) -> 5714412.2
A11: SBL | B11: 0 | C11: 0 | D11: 0 | E11: 0 | F11: 0 | G11: 381782.67 | H11: 0 | I11: =SUM(B11:H11) -> 381782.67
A12: Interest rate | B12: 0 | C12: 0 | D12: 0 | E12: 0 | F12: 0 | G12: 464323.65 | H12: 0 | I12: =SUM(B12:H12) -> 464323.65
A13: Equity Derivative | B13: 0 | C13: 0 | D13: 0 | E13: 0 | F13: 0 | G13: 289436.07 | H13: 0 | I13: =SUM(B13:H13) -> 289436.07
A14: Total Gross Income | B14: =SUM(B10:B13) -> 0 | C14: =SUM(C10:C13) -> 0 | D14: =SUM(D10:D13) -> 0 | E14: =SUM(E10:E13) -> 0 | F14: =SUM(F10:F13) -> 0 | G14: =SUM(G10:G13) -> 6849954.6 | H14: =SUM(H10:H13) -> 0 | I14: =SUM(I10:I13) -> 6849954.6 | J14: 1 | L14: 9
A15: Revenue Shared With Regulated Broker Dealer
A16: 45000 - Revenues shared to third parties
A17: 45002 - Commission Shared with third party | B17: 0 | C17: 0 | D17: 0 | E17: 0 | F17: 0 | G17: -672410.8 | H17: 0 | I17: =SUM(B17:H17) -> -672410.8 | J17: 2.1
A18: 45001 - IS IN | B18: 0 | C18: 0 | D18: 0 | E18: 0 | F18: 0 | G18: -64227.52 | H18: 0 | I18: =SUM(B18:H18) -> -64227.52 | J18: 2.1
A19: 45003 - Non Reclaimable VAT | B19: 0 | C19: 0 | D19: 0 | E19: 0 | F19: 0 | G19: -165975.65 | H19: 0 | I19: =SUM(B19:H19) -> -165975.65 | J19: 2.1
A20: Total - 45000 - Revenues shared to third parties | B20: =SUM(B17:B19) -> 0 | C20: =SUM(C17:C19) -> 0 | D20: =SUM(D17:D19) -> 0 | E20: =SUM(E17:E19) -> 0 | F20: =SUM(F17:F19) -> 0 | G20: =SUM(G17:G19) -> -902613.97 | H20: =SUM(H17:H19) -> 0 | I20: =SUM(I17:I19) -> -902613.97 | J20: 2
A21: Total Revenue Shared With Regulated Broker Dealer | B21: =SUM(B20) -> 0 | C21: =SUM(C20) -> 0 | D21: =SUM(D20) -> 0 | E21: =SUM(E20) -> 0 | F21: =SUM(F20) -> 0 | G21: =SUM(G20) -> -902613.97 | H21: =SUM(H20) -> 0 | I21: =SUM(I20) -> -902613.97
A22: Net Income | B22: =+B14+B21 -> 0 | C22: =+C14+C21 -> 0 | D22: =+D14+D21 -> 0 | E22: =+E14+E21 -> 0 | F22: =+F14+F21 -> 0 | G22: =+G14+G21 -> 5947340.6 | H22: =+H14+H21 -> 0 | I22: =+I14+I21 -> 5947340.6
A23: Cost Of Sales
A24: 50000 - COGS expenses
A25: 50100 - Payroll and Related expenses [COGS]
A26: 50101 - COGS Gross Salaries | B26: 0 | C26: 0 | D26: 0 | E26: 0 | F26: 0 | G26: -416682.64 | H26: -188919.56 | I26: =SUM(B26:H26) -> -605602.2
A27: 50105 - COGS Employer taxes | B27: 0 | C27: 0 | D27: 0 | E27: 0 | F27: 0 | G27: 0 | H27: -2565.5 | I27: =SUM(B27:H27) -> -2565.5
A28: 50107 - COGS Benefits | B28: 0 | C28: 0 | D28: 0 | E28: 0 | F28: 0 | G28: 0 | H28: -1971.42 | I28: =SUM(B28:H28) -> -1971.42
A29: 50108 - COGS Employee stock-based compensation | B29: 0 | C29: 0 | D29: 0 | E29: 0 | F29: 6549.24 | G29: 0 | H29: -36.17 | I29: =SUM(B29:H29) -> 6513.07
A30: Total - 50100 - Payroll and Related expenses [COGS] | B30: =SUM(B26:B29) -> 0 | C30: =SUM(C26:C29) -> 0 | D30: =SUM(D26:D29) -> 0 | E30: =SUM(E26:E29) -> 0 | F30: =SUM(F26:F29) -> 6549.24 | G30: =SUM(G26:G29) -> -416682.64 | H30: =SUM(H26:H29) -> -193492.65 | I30: =SUM(I26:I29) -> -603626.05
A31: 51000 - Pyroll Taxes [COGS]
A32: 51001 - Social Security | B32: 0 | C32: 0 | D32: 0 | E32: 0 | F32: 0 | G32: 0 | H32: -50011.9 | I32: =SUM(B32:H32) -> -50011.9
A33: 51002 - Participation in vocational training | B33: 0 | C33: 0 | D33: 0 | E33: 0 | F33: 0 | G33: 0 | H33: -2302.4 | I33: =SUM(B33:H33) -> -2302.4
A34: 51003 - Medical Insurance | B34: 0 | C34: 0 | D34: 0 | E34: 0 | F34: 0 | G34: 0 | H34: -1264.1 | I34: =SUM(B34:H34) -> -1264.1
A35: Total - 51000 - Pyroll Taxes [COGS] | B35: =SUM(B32:B34) -> 0 | C35: =SUM(C32:C34) -> 0 | D35: =SUM(D32:D34) -> 0 | E35: =SUM(E32:E34) -> 0 | F35: =SUM(F32:F34) -> 0 | G35: =SUM(G32:G34) -> 0 | H35: =SUM(H32:H34) -> -53578.4 | I35: =SUM(I32:I34) -> -53578.4
A36: 51100 - Other Payroll related cost [COGS]
A37: 51101 - Pension Contribution [COGS] | B37: 0 | C37: 0 | D37: 0 | E37: 0 | F37: 0 | G37: 0 | H37: -20104.84 | I37: =SUM(B37:H37) -> -20104.84
A38: Total - 51100 - Other Payroll related cost [COGS] | B38: =SUM(B37) -> 0 | C38: =SUM(C37) -> 0 | D38: =SUM(D37) -> 0 | E38: =SUM(E37) -> 0 | F38: =SUM(F37) -> 0 | G38: =SUM(G37) -> 0 | H38: =SUM(H37) -> -20104.84 | I38: =SUM(I37) -> -20104.84
A39: 50400 - COGS Hosting
A40: 50402 - AWS | B40: 0 | C40: 0 | D40: 0 | E40: 0 | F40: 0 | G40: -214611.22 | H40: 0 | I40: =SUM(B40:H40) -> -214611.22
A41: 50401 - COGS Hosting exp. | B41: 0 | C41: 0 | D41: 0 | E41: 0 | F41: 0 | G41: -61140.65 | H41: 0 | I41: =SUM(B41:H41) -> -61140.65
A42: Total - 50400 - COGS Hosting | B42: =SUM(B40:B41) -> 0 | C42: =SUM(C40:C41) -> 0 | D42: =SUM(D40:D41) -> 0 | E42: =SUM(E40:E41) -> 0 | F42: =SUM(F40:F41) -> 0 | G42: =SUM(G40:G41) -> -275751.87 | H42: =SUM(H40:H41) -> 0 | I42: =SUM(I40:I41) -> -275751.87
...

Sheet AP correction OB
A1: Wematch.live R&D LTD
A2: Wematch.live R&D LTD | H2: A
A3: Balance Sheet Detail
A4: From Jan 2021 to Dec 2021
A7: Financial Row | B7: Type | C7: Date | D7: Document Number | E7: Name | F7: Amount
A8: Current Liabilities | F8: 0 | J8: תפעול פנסיוני | K8: 425.37
A9: Accounts Payable | F9: 0 | J9: איי דיגיטל סטור בע"מ | K9: -225.34
A10: 20000 - AP | F10: 0 | J10: אל על | K10: 2889.67
A11: 20001 - Accounts Payable | F11: 0 | J11: NOBU HOTEL | K11: 550.75
B12: Bill | C12: 44389 | D12: 467 | E12: Vissensa Ltd | F12: 1068.79 | G12: =-K12 -> 3295.07 | H12: =+F12-G12 -> -2226.28 | J12: VISSENSA | K12: -3295.07
B13: Bill | C13: 44486 | D13: 87KL2Y | E13: Z Hotel | F13: 652.27 | G13: =-K13 -> 997.27 | H13: =+F13-G13 -> -345 | J13: GLOUCESTER PLACE HOTEL | K13: -997.27
B14: Bill | C14: 44515 | D14: 1429268 | E14: Intralinks, Inc. | F14: 929.99 | G14: =-K14 -> 1871.48 | H14: =+F14-G14 -> -941.49 | J14: INTRALINKS | K14: -1871.48
B15: Bill | C15: 44530 | D15: IN214008196 | E15: DoiT International LTD | F15: 11709.22 | G15: =-K20-F26 -> 11708.29 | H15: =+F15-G15 -> 0.93 | J15: ENGAGE - ADRIAN | K15: -716.95
B16: Bill | C16: 44531 | D16: 1912 | E16: OpenFin Inc | F16: 5000 | G16: =-K19 -> 5000 | H16: =+F16-G16 -> 0 | J16: תן ביס | K16: -4411.58
B17: Bill | C17: 44545 | D17: 1456847 | E17: Intralinks, Inc. | F17: 931.26 | H17: =+F17-G17 -> 931.26 | J17: MONGODBCLOUD | K17: -4467.73
B18: Bill | C18: 44551 | D18: 21-124 | E18: Engage-Adrian S.L. | F18: 724.71 | G18: =-K15 -> 716.95 | H18: =+F18-G18 -> 7.76 | J18: BLOOMBERG | K18: -17115.93
B19: Bill | C19: 44551 | D19: IN21010009624 | E19: monday.com Ltd | F19: 982 | G19: =-K24 -> 977.43 | H19: =+F19-G19 -> 4.57 | J19: OPENFIN INC | K19: -5000
B20: Bill | C20: 44552 | D20: BD0002081 | E20: eFinancialCareers Limited | F20: 4058.7 | G20: =-K27 -> 4039.87 | H20: =+F20-G20 -> 18.83 | J20: DOIT INTERNATIONAL LTD | K20: -18923.35
B21: Bill | C21: 44557 | D21: 5606566270 | E21: BLOOMBERG FINANCE L.P | F21: 140 | H21: =+F21-G21 -> 140 | J21: JAMES BOYCE | K21: -25220.29
B22: Bill | C22: 44557 | D22: 5606566274 | E22: BLOOMBERG FINANCE L.P | F22: 17070 | G22: =-K18 -> 17115.93 | H22: =+F22-G22 -> -45.93 | J22: הפרשה לספקים בחובה(אל על) | K22: -3605.76
B23: Bill | C23: 44559 | D23: IIR025280 | E23: MongoDB Limited | F23: 3200 | G23: =-K17-F25 -> 3175.44 | H23: =+F23-G23 -> 24.56 | J23: דאטהצ'ק בע"מ | K23: 112.22
B24: Bill | C24: 44561 | D24: UNK 1 | E24: iDigital Store LTD | F24: 72.35 | G24: =-K9 -> 225.34 | H24: =+F24-G24 -> -152.99 | J24: MONDAY | K24: -977.43
B25: Bill | C25: 44561 | D25: IIR025446 | E25: MongoDB Limited | F25: 1292.29 | H25: =+F25-G25 -> 1292.29 | J25: מוזגו מנשה | K25: -26898.71
B26: Bill | C26: 44561 | D26: IN214008800 | E26: DoiT International LTD | F26: 7215.06 | J26: EXPENSIFY | K26: -20
B27: Bill | C27: 44561 | D27: 1 | E27: Menashe Mozago | F27: 26898.72 | G27: =-K25 -> 26898.71 | H27: =+F27-G27 -> 0.01 | J27: EFINANCIAL CAREERS | K27: -4039.87
B28: Bill | C28: 44561 | D28: 3 | E28: James Boyce | F28: 25220.29 | G28: =-K21 -> 25220.29 | H28: =+F28-G28 -> 0
B29: Bill | C29: 44561 | D29: 86344375 | E29: Expensify, Inc. | F29: 20 | G29: =-K26 -> 20 | H29: =+F29-G29 -> 0
B30: Bill | C30: 44561 | D30: 202146051 | E30: 10Bis LTD | F30: 4411.58 | G30: =-K16 -> 4411.58 | H30: =+F30-G30 -> 0
A31: Total - 20001 - Accounts Payable | F31: =SUM(F11:F30) -> 111597.23
A32: Total - 20000 - AP | F32: =SUM(F10,F31) -> 111597.23
A33: Total Accounts Payable | F33: =SUM(F9,F32) -> 111597.23
A34: Total Liabilities | F34: =F33+0+0 -> 111597.23
A35: Current Assets Less Current Liabilities | F35: =0-F34 -> -111597.23
A36: Total Assets Less Current Liabilities | F36: =F35+0+0 -> -111597.23
A37: Total Assets Less Total Liabilities | F37: =F36-0 -> -111597.23
A46: Wematch.live R&D LTD
A47: Wematch.live R&D LTD
A48: Israeli A/P Register
A49: 31 December 2021 - 31 August 2023
A52: Vendor Name | B52: Type | C52: Date | D52: No. | E52: Memo | F52: Date Due | G52: Billed | H52: Paid | I52: Balance | J52: Amount (Foreign Currency) | K52: Currency: Currency Symbol | L52: Exchange Rate
...

Sheet OLD--->

Sheet CF.
A4: Cash flows from operating activities:
C5: As of December 31, 2022
C7: US thousand
A9: Net loss | C9: =-E95 -> -7371
A11: Adjustments to reconcile net loss to net cash provided by operating activities:
A14: Depreciation and amortization and impermanent | C14: =-E82 -> 28.55433
A15: Share-based compensation expense | C15: =-E92 -> 257.137
A16: Change in employee long term loans | C16: =-E81 -> 4
A17: Change in long time employee benefit | C17: =-E88 -> -2
A19: Change in SAFE fair value | C19: =-E87 -> 0
A21: Changes in operating assets and liabilities:
A22: Accounts receivable | C22: =-E79 -> -1020
A23: Prepaid expenses and other assets | C23: =-E80 -> -517
A24: Accounts payable | C24: =-E83 -> 69
A25: Accrued expenses and other liabilities | C25: =-E84 -> 47
A26: Change in Deferred revenue | C26: =-E85 -> 0
A28: Net cash provided by operating activities | C28: =SUM(C9:C27) -> -8504.3087
A30: Cash flows from investing activities:
A32: Change in short term restricted deposit | C32: =-F78-284 -> -11416
A33: Purchases of property and equipment | C33: =-F82 -> -92.63258
A35: Net cash used in investing activities | C35: =-F96 -> -11508.633
A37: Cash flows from financing activities:
A39: Proceeds from issuance of Sample agreement for future equity ("SAFE")
A40: Issuance of Preferred B shares, net of issuance cost | C40: =-G91-G89 -> 3185.706
A41: Proceeds from issuance of convertible preferred shares, net of issuance costs
A43: Net cash provided by financing activities | C43: =+C41+C40+C39 -> 3185.706
A45: Net increase (decrease) in cash, cash equivalents, and restricted cash | C45: =+C43+C28+C35 -> -16827.235
A46: Cash, cash equivalents, and restricted cash—beginning of period | C46: =+D77+E77 -> 27388
A48: Cash, cash equivalents, and restricted cash—end of period | C48: =+C45+C46 -> 10560.765 | D48: =+J77 -> 7660 | E48: =+C48-D48 -> 2900.7647
D53: לבדוק האם לשים יתרה עם פקדונות או בלי? | E53: EY
F70: Working peper for cash flow
D74: Closing balance as | E74: Cash flow from | F74: Cash flow from | G74: Cash flow from | J74: Closing balance as
D75: 44561 | E75: Opeartion | F75: Investing | G75: Financing | H75: Non-cash activites | I75: Change in cash | J75: 44926 | L75: Check
B77: 10 | C77: Cash and cash equivalents | D77: 27403 | E77: =-27403+27388 -> -15 | I77: =J77-D77-E77 -> -19728 | J77: =+ROUND(SUMIF('BS USD'!$B$7:$B$54,B77,'BS USD'!$Q$7:$Q$54),0) -> 7660 | L77: =SUM(D77:I77)-J77 -> 0
B78: 11 | C78: Restricted Bank Deposit | D78: 31 | F78: =J78-D78 -> 11132 | J78: =+ROUND(SUMIF('BS USD'!$B$7:$B$54,B78,'BS USD'!$Q$7:$Q$54),0) -> 11163 | L78: =SUM(D78:I78)-J78 -> 0
B79: 12 | C79: Account Receivable | D79: 1017 | E79: =J79-D79 -> 1020 | J79: =+ROUND(SUMIF('BS USD'!$B$7:$B$54,B79,'BS USD'!$Q$7:$Q$54),0) -> 2037 | L79: =SUM(D79:I79)-J79 -> 0
B80: 13 | C80: Prepaid expenses and other current assets | D80: 259 | E80: =J80-D80 -> 517 | J80: =+ROUND(SUMIF('BS USD'!$B$7:$B$54,B80,'BS USD'!$Q$7:$Q$54),0) -> 776 | L80: =SUM(D80:I80)-J80 -> 0
B81: 14 | C81: Other long term accounts receivables | D81: 37 | E81: =J81-D81 -> -4 | J81: =+ROUND(SUMIF('BS USD'!$B$7:$B$54,B81,'BS USD'!$Q$7:$Q$54),0) -> 33 | L81: =SUM(D81:I81)-J81 -> 0
B82: 15 | C82: Property & Equipment, Net | D82: 58 | E82: =-(26238+1110.97+2205.36)/1000+1 -> -28.55433 | F82: =+(67350.26+17015.98+7266.34)/1000+1 -> 92.63258 | J82: =+ROUND(SUMIF('BS USD'!$B$7:$B$54,B82,'BS USD'!$Q$7:$Q$54),0) -> 123 | L82: =SUM(D82:I82)-J82 -> -0.92175
B83: 16 | C83: Account Payable | D83: -133 | E83: =J83-D83 -> -69 | J83: =-ROUND(SUMIF('BS USD'!$B$7:$B$54,B83,'BS USD'!$Q$7:$Q$54),0) -> -202 | L83: =SUM(D83:I83)-J83 -> 0
...

Sheet CF NS
A1: Wematch.live R&D LTD
A2: Wematch.live R&D LTD (Consolidated)
A3: Cash Flow Statement
A4: From Jan 2022 to Dec 2022
A7: Financial Row | B7: Amount
A8: Operating Activities
A9: Net Income | B9: -7370915.9
A10: Adjustments to Profit/(Loss)
A11: Accounts Receivable | B11: -786713.56
A12: Unbilled Receivable | B12: -126335.77
A13: Other Current Asset | B13: -660237.04
A14: Accounts Payable | B14: 72052.69
A15: Sales Tax Payable | B15: 10196.89
A16: Other Current Liabilities | B16: 47875.8
A17: Total Adjustments to Profit/(Loss) | B17: -1443161
A18: Total Operating Activities | B18: -8814076.9
A19: Investing Activities
A20: Fixed Asset | B20: -62078.09
A21: Total Investing Activities | B21: -62078.09
A22: Financing Activities
A23: Other Equity | B23: 264248.86
A24: Total Financing Activities | B24: 264248.86
A25: Net Change in Cash for Period | B25: -8611906.1
A26: Cash at Beginning of Period | B26: 27419436
A27: Cash at End of Period | B27: 18807530

Sheet Change in Equity (2)
D3: Ordinary shares | H3: Preferred Shares | L3: Additional | N3: Receivable on | P3: Accumulated | R3: Total shareholders' equity
L4: paid-in
D5: Number | F5: Amount | H5: Number | J5: Amount | L5: capital | N5: Shares account | P5: deficit | R5: (deficit)
B7: Balance as of January 1, 2021 | D7: 1401739 | F7: 4 | H7: 198028 | J7: (*) | L7: 12952 | N7: -50 | P7: -10806 | R7: =+P7+F7+L7+N7 -> 2100
B9: Net loss and other comprehensive loss | D9: 0 | F9: 0 | H9: 0 | J9: 0 | L9: 0 | N9: 0 | P9: -3272 | R9: =+P9+F9+L9+J9 -> -3272
B10: Receivable of shares | N10: 50 | R10: =+P10+F10+L10+J10+N10 -> 50
B11: Share based compensation | D11: 0 | F11: 0 | H11: 0 | J11: 0 | L11: 565 | N11: 0 | P11: 0 | R11: =+P11+F11+L11+J11 -> 565 | T11: =+SUM('[2]Summary Cap Table'!$C$12:$C$22)-H16 -> -1071
B12: Warrant exercise | H12: 315996 | J12: 1 | L12: 3124 | R12: =+P12+F12+L12+J12 -> 3125
B13: SAFE exercise | D13: 0 | F13: 0 | H13: 105500 | J13: 1 | L13: =[1]CF!D35+[1]CF!D15-1 -> -1 | N13: - | P13: 0 | R13: =+P13+F13+L13+J13 -> 0
B14: Issuance of preferred B Shares, net of issuance cost | D14: 0 | F14: 0 | H14: =570204+293045 -> 863249 | J14: 3 | L14: 24940 | P14: 0 | R14: =+P14+J14+L14+N14 -> 24943
B16: Balance as of December 31, 2021 | D16: =SUM(D7:D15) -> 1401739 | F16: =SUM(F7:F15) -> 4 | H16: =SUM(H7:H15) -> 1482773 | J16: =SUM(J7:J15) -> 5 | L16: =SUM(L7:L15) -> 41580 | N16: =SUM(N7:N15) -> 0 | P16: =SUM(P7:P15) -> -14078 | R16: =+P16+F16+L16+N16+J16 -> 27511
B18: Net loss and other comprehensive loss | D18: 0 | F18: 0 | H18: 0 | J18: 0 | L18: 0 | N18: 0 | P18: =+'P&L'!O31 -> -7392 | R18: =SUM(J18:P18,F18) -> -7392
B19: recievable on account of shares | D19: 800 | R19: =SUM(J19:P19,F19) -> 0
B20: Share based compensation | D20: =584+1216 -> 1800 | L20: =-CF!E93+7 -> 265.137 | R20: =SUM(J20:P20,F20) -> 265.137
B21: SAFE exercise | R21: =SUM(J21:P21,F21) -> 0
B22: Warrant exercise | H22: 127247 | J22: (*) | R22: =SUM(J22:P22,F22) -> 0
B23: Issuance of preferred A Shares, net of issuance cost
B24: Issuance of ordinary stocks, net of issuance cost | F24: 0 | P24: 0 | R24: =SUM(J24:P24,F24) -> 0
B26: Balance as of December 31, 2022 | D26: =SUM(D16:D24) -> 1404339 | F26: =SUM(F16:F24) -> 4 | H26: =SUM(H16:H24) -> 1610020 | J26: =SUM(J16:J24) -> 5 | L26: =SUM(L16:L24) -> 41845.137 | N26: =SUM(N16:N24) -> 0 | P26: =SUM(P16:P24) -> -21470 | R26: =SUM(R16:R24) -> 20384.137
J27: =F26+J26-[1]BS!O134 -> 0
D28: =+D16+D19+D20-D26 -> 0 | H28: =+H16+H22-H26 -> 0 | L28: =+L16+L20-L26 -> 0 | P28: =+P16+P18-P26 -> 0 | Q28: =+Q16+Q18-Q26 -> 0
L32: 42125 | P32: 21732
L33: =+L26-L32 -> -279.863 | P33: =+P26+P32 -> 262

Sheet Full BS-USD (2)
A1: Wematch.live R&D LTD
A2: Wematch.live R&D LTD (Consolidated)
A3: Balance Sheet
A4: End of FY 2022
A7: Financial Row | B7: Elimination | C7: WEMATCH.SUPPORT US INC. | D7: Wematch EQD LTD | E7: Wematch Interest rate LTD | F7: Wematch Securities. Financing LTD [IL] | G7: Wematch.Securities Financing LTD | H7: Wematch.live R&D LTD | I7: Wematch.live Tech Support Europe | J7: Total | K7: INDEX
B8: Amount | C8: Amount | D8: Amount | E8: Amount | F8: Amount | G8: Amount | H8: Amount | I8: Amount | J8: Amount
A9: Current Assets
A10: Bank
A11: 10000 - Cash and Cash Equivalent (WRD-IL)
A12: 10001 - Bank Fibi 327492 NIS | B12: 0 | C12: 0 | D12: 0 | E12: 0 | F12: 0 | G12: 0 | H12: 98925.39 | I12: 0 | J12: =+IFERROR(VLOOKUP(A12,[3]BalanceSheet!A$8:B$154,2,0),0) -> 26151.22
A13: 10002 - Bank Hapoalim 120737 NIS | B13: 0 | C13: 0 | D13: 0 | E13: 0 | F13: 0 | G13: 0 | H13: 184319.33 | I13: 0 | J13: =+IFERROR(VLOOKUP(A13,[3]BalanceSheet!A$8:B$154,2,0),0) -> 344.4
A14: 10003 - Bank Hapoalim 120737 USD | B14: 0 | C14: 0 | D14: 0 | E14: 0 | F14: 0 | G14: 0 | H14: 6136719.3 | I14: 0 | J14: =+IFERROR(VLOOKUP(A14,[3]BalanceSheet!A$8:B$154,2,0),0) -> 26906064
A15: 10004 - Bank Hapoalim 120737 GBP | B15: 0 | C15: 0 | D15: 0 | E15: 0 | F15: 0 | G15: 0 | H15: 11685.56 | I15: 0 | J15: =+IFERROR(VLOOKUP(A15,[3]BalanceSheet!A$8:B$154,2,0),0) -> 5309.75
A16: 10005 - Bank Hapoalim 120737 EUR | B16: 0 | C16: 0 | D16: 0 | E16: 0 | F16: 0 | G16: 0 | H16: 16813.13 | I16: 0 | J16: =+IFERROR(VLOOKUP(A16,[3]BalanceSheet!A$8:B$154,2,0),0) -> 367423.66
A17: Total - 10000 - Cash and Cash Equivalent (WRD-IL) | B17: =SUM(B12:B16) -> 0 | C17: =SUM(C12:C16) -> 0 | D17: =SUM(D12:D16) -> 0 | E17: =SUM(E12:E16) -> 0 | F17: =SUM(F12:F16) -> 0 | G17: =SUM(G12:G16) -> 0 | H17: =SUM(H12:H16) -> 6448462.7 | I17: =SUM(I12:I16) -> 0 | J17: =+IFERROR(VLOOKUP(A17,[3]BalanceSheet!A$8:B$154,2,0),0) -> 27305293 | K17: 10
A18: 101 - Dummy USD [UK] | B18: 0 | C18: 0 | D18: 0 | E18: 0 | F18: 0 | G18: -0.01 | H18: 0 | I18: 0 | J18: =+IFERROR(VLOOKUP(A18,[3]BalanceSheet!A$8:B$154,2,0),0) -> 0
A19: 10100 - Cash and Cash Equivalent (WIR-IL) | J19: =+IFERROR(VLOOKUP(A19,[3]BalanceSheet!A$8:B$154,2,0),0) -> 0
A20: 10101 - Bank Hapoalim 120720 NIS | B20: 0 | C20: 0 | D20: 0 | E20: 21.81 | F20: 0 | G20: 0 | H20: 0 | I20: 0 | J20: =+IFERROR(VLOOKUP(A20,[3]BalanceSheet!A$8:B$154,2,0),0) -> 156.37
A21: Total - 10100 - Cash and Cash Equivalent (WIR-IL) | B21: =SUM(B20) -> 0 | C21: =SUM(C20) -> 0 | D21: =SUM(D20) -> 0 | E21: =SUM(E20) -> 21.81 | F21: =SUM(F20) -> 0 | G21: =SUM(G20) -> 0 | H21: =SUM(H20) -> 0 | I21: =SUM(I20) -> 0 | J21: =+IFERROR(VLOOKUP(A21,[3]BalanceSheet!A$8:B$154,2,0),0) -> 156.37 | K21: 10
A22: 10200 - Cash and Cash Equivalent (WSF-IL) | J22: =+IFERROR(VLOOKUP(A22,[3]BalanceSheet!A$8:B$154,2,0),0) -> 0
A23: 10201 - Bank Hapoalim 120729 NIS | B23: 0 | C23: 0 | D23: 0 | E23: 0 | F23: 124.45 | G23: 0 | H23: 0 | I23: 0 | J23: =+IFERROR(VLOOKUP(A23,[3]BalanceSheet!A$8:B$154,2,0),0) -> 422.32
A24: 10202 - Bank Hapoalim 120729 USD | B24: 0 | C24: 0 | D24: 0 | E24: 0 | F24: 24.67 | G24: 0 | H24: 0 | I24: 0 | J24: =+IFERROR(VLOOKUP(A24,[3]BalanceSheet!A$8:B$154,2,0),0) -> 24.67
A25: 10203 - Bank Hapoalim 120729 EUR | B25: 0 | C25: 0 | D25: 0 | E25: 0 | F25: 327.43 | G25: 0 | H25: 0 | I25: 0 | J25: =+IFERROR(VLOOKUP(A25,[3]BalanceSheet!A$8:B$154,2,0),0) -> 346.29
A26: Total - 10200 - Cash and Cash Equivalent (WSF-IL) | B26: =SUM(B23:B25) -> 0 | C26: =SUM(C23:C25) -> 0 | D26: =SUM(D23:D25) -> 0 | E26: =SUM(E23:E25) -> 0 | F26: =SUM(F23:F25) -> 476.55 | G26: =SUM(G23:G25) -> 0 | H26: =SUM(H23:H25) -> 0 | I26: =SUM(I23:I25) -> 0 | J26: =+IFERROR(VLOOKUP(A26,[3]BalanceSheet!A$8:B$154,2,0),0) -> 793.28 | K26: 10
A27: 10300 - Cash and Cash Equivalent (WEQD-IL) | J27: =+IFERROR(VLOOKUP(A27,[3]BalanceSheet!A$8:B$154,2,0),0) -> 0
A28: 10301 - Bank Hapoalim 120702 NIS | B28: 0 | C28: 0 | D28: -3.42 | E28: 0 | F28: 0 | G28: 0 | H28: 0 | I28: 0 | J28: =+IFERROR(VLOOKUP(A28,[3]BalanceSheet!A$8:B$154,2,0),0) -> 3.88
A29: 10302 - Bank Hapoalim 120702 USD | B29: 0 | C29: 0 | D29: 6438.02 | E29: 0 | F29: 0 | G29: 0 | H29: 0 | I29: 0 | J29: =+IFERROR(VLOOKUP(A29,[3]BalanceSheet!A$8:B$154,2,0),0) -> 6563.41
