Workbook
Name Actuals: #REF!
Name Actuals: #REF!
Name Actuals: #REF!
Name Capital_Gains_Taxes: #REF!
Name Capital_Gains_Taxes: #REF!
Name Capital_Gains_Taxes: #REF!
Name codes: [1]קליטה!#REF!
Name Company_Scenarios: #REF!
Name Company_Scenarios: #REF!
Name Company_Scenarios: #REF!
Name Currency: #REF!
Name Currency: #REF!
Name Currency: #REF!
Name Days_per_Year: 365
Name Deployment_Scenarios: #REF!
Name Deployment_Scenarios: #REF!
Name Deployment_Scenarios: #REF!
Name Dividend_Tax: #REF!
Name Dividend_Tax: #REF!
Name Dividend_Tax: #REF!
Name Exchange_Rate_to_USD: #REF!
Name Exchange_Rate_to_USD: #REF!
Name Exchange_Rate_to_USD: #REF!
Name Fiscal_Year_Ending: #REF!
Name Fiscal_Year_Ending: #REF!
Name Fiscal_Year_Ending: #REF!
Name h: #REF!
Name Helpline: '[2]Debt Capex'!$AF$71:$AM$71
Name mbm: [1]קליטה!#REF!
Name mbmtuam: [1]קליטה!#REF!
Name mbnom: [1]קליטה!#REF!
Name Name: #REF!
Name Name: #REF!
Name Name: #REF!
Name NPV_Correction: #REF!
Name NPV_Correction: #REF!
Name NPV_Correction: #REF!
Name Operating_Deployment_Scenario: #REF!
Name Operating_Deployment_Scenario: #REF!
Name Operating_Deployment_Scenario: #REF!
Name Operating_Scenario: #REF!
Name Operating_Scenario: #REF!
Name Operating_Scenario: #REF!
Name pncodes: '[1]פקודות נוספות'!#REF!
Name pnmtuam: '[1]פקודות נוספות'!#REF!
Name pnnom: '[1]פקודות נוספות'!#REF!
Name Projection_Period: #REF!
Name Projection_Period: #REF!
Name Projection_Period: #REF!
Name Selected_Scenario: #REF!
Name Selected_Scenario: #REF!
Name Selected_Scenario: #REF!
Name Selected_ScenarioDV: #REF!
Name Selected_ScenarioDV: #REF!
Name Selected_ScenarioDV: #REF!
Name STV_Investment_Date: #REF!
Name STV_Investment_Date: #REF!
Name STV_Investment_Date: #REF!
Name Units: #REF!
Name Units: #REF!

Sheet HARKAVA 
C1: =+C59+C28 -> 0 | D1: =D28+D59 -> 7789953.4 | E1: =E28+E59 -> 7789953.4 | F1: =F28+F59 -> 0 | H1: =H28+H59 -> 0 | I1: =I28+I59 -> 61840 | J1: =J28+J59 -> 61840 | K1: =K28+K59 -> 0 | M1: =+M59+M28 -> 0 | N1: =+N59+N28 -> 1443366.2 | O1: =+O59+O28 -> 1443366.2 | P1: =+P59+P28 -> 0 | R1: =+R59+R28 -> 0 | S1: =+S59+S28 -> 2697288.7 | T1: =+T59+T28 -> 2697288.7 | U1: =+U59+U28 -> 0 | V1: =+V59+V28 -> 0 | X1: =+X59+X28 -> 43788.72 | Y1: =+Y59+Y28 -> 43788.72 | AD1: 0 | AF1: 0 | AG1: 61840 | AH1: 61840 | AI1: 0 | AK1: 0 | AL1: 1332358 | AM1: 1332358 | AN1: 0 | AP1: -0.0099999979 | AQ1: 2744953.8 | AR1: 2744953.8 | AS1: -0.0099999979 | AT1: -0.0099999942 | AV1: 0.72 | AW1: 0.71
F2: =B5 -> 44561 | AD2: 44561
C3: Mitiga Ltd. | H3: Mitiga USA Inc. | M3: Mitiga UK | R3: Mitiga Security Inc. | AF3: Mitiga USA Inc. | AK3: Mitiga UK | AP3: Mitiga Security Inc.
A4: code | B4: Mitiga Security Inc. | C4: Presented | D4: Addi ente. In $ | F4: Closing Balance | H4: Presented | I4: Addi ente. In $ | K4: Closing Balance | M4: Presented | N4: Addi ente. In $ | P4: Closing Balance | R4: Presented | S4: Addi ente. In $ | U4: Closing Balance | V4: Combined | X4: Consolidation entries | Y4: Consolidated | AD4: Closing Balance | AF4: Presented | AG4: Addi ente. In $ | AI4: Closing Balance | AK4: Presented | AL4: Addi ente. In $ | AN4: Closing Balance | AP4: Presented | AQ4: Addi ente. In $ | AS4: Closing Balance | AT4: Combined | AV4: Consolidation entries | AW4: Consolidated | AY4: LTD | AZ4: UK | BA4: SEC | BB4: Consolidation entries | BC4: Notes
B5: 44561 | C5: $ | D5: D | E5: C | F5: $ | P5: $ | U5: $ | V5: $ | X5: $ | Y5: $ | AD5: $ | AN5: $ | AS5: $ | AT5: $ | AV5: $ | AW5: $
A6: 1100 | B6: Cash and cash equivalents- in $ | C6: =SUMIF('TB Mitiga LTD'!A:A,'HARKAVA '!A6,'TB Mitiga LTD'!D:D) -> 919260.82 | D6: =SUMIF('Adj Entries Ltd'!$B$4:$B$954,A6,'Adj Entries Ltd'!$D$4:$D$954) -> 3000000 | E6: =SUMIF('Adj Entries Ltd'!$B$4:$B$954,A6,'Adj Entries Ltd'!$E$4:$E$954) -> 0 | F6: =(+C6+D6-E6) -> 3919260.8 | H6: =SUMIF('TB US'!A:A,'HARKAVA '!A6,'TB US'!D:D) -> 0 | I6: =SUMIF('Adj. entries US'!B:B,'HARKAVA '!A6,'Adj. entries US'!D:D) -> 0 | J6: =SUMIF('Adj. entries US'!B:B,'HARKAVA '!A6,'Adj. entries US'!E:E) -> 0 | K6: =H6+I6-J6 -> 0 | M6: =SUMIF('TB UK'!A:A,'HARKAVA '!A6,'TB UK'!E:E) -> 0 | N6: =SUMIF('Adj. Entries UK'!B:B,'HARKAVA '!A6,'Adj. Entries UK'!D:D) -> 0 | O6: =SUMIF('Adj. Entries UK'!B:B,'HARKAVA '!A6,'Adj. Entries UK'!E:E) -> 0 | P6: =M6+N6-O6 -> 0 | R6: =SUMIF('TB security'!A:A,'HARKAVA '!A6,'TB security'!D:D) -> 14375507 | S6: =SUMIF('Adj. Entries security'!B:B,'HARKAVA '!A6,'Adj. Entries security'!D:D) -> 0 | T6: =SUMIF('Adj. Entries security'!B:B,'HARKAVA '!A6,'Adj. Entries security'!E:E) -> 0 | U6: =R6+S6-T6 -> 14375507 | V6: =P6+F6+U6+K6 -> 18294768 | Y6: =V6+X6 -> 18294768 | Z6: =LEFT(A6,2) -> 11 | AD6: 3919260.8 | AF6: 0 | AG6: 0 | AH6: 0 | AI6: 0 | AK6: 0 | AL6: 0 | AM6: 0 | AN6: 0 | AP6: 14375507 | AQ6: 0 | AR6: 0 | AS6: 14375507 | AT6: 18294768 | AW6: 18294768 | AY6: =F6-AD6 -> 0 | AZ6: =P6-AN6 -> 0 | BA6: =U6-AS6 -> 0 | BB6: =X6-AV6 -> 0
A7: 1110 | B7: Cash and cash equivalents- in other currency | C7: =SUMIF('TB Mitiga LTD'!A:A,'HARKAVA '!A7,'TB Mitiga LTD'!D:D) -> 84442.69 | D7: =SUMIF('Adj Entries Ltd'!$B$4:$B$954,A7,'Adj Entries Ltd'!$D$4:$D$954) -> 0 | E7: =SUMIF('Adj Entries Ltd'!$B$4:$B$954,A7,'Adj Entries Ltd'!$E$4:$E$954) -> 0 | F7: =(+C7+D7-E7) -> 84442.69 | H7: =SUMIF('TB US'!A:A,'HARKAVA '!A7,'TB US'!D:D) -> 0 | I7: =SUMIF('Adj. entries US'!B:B,'HARKAVA '!A7,'Adj. entries US'!D:D) -> 0 | J7: =SUMIF('Adj. entries US'!B:B,'HARKAVA '!A7,'Adj. entries US'!E:E) -> 0 | K7: =H7+I7-J7 -> 0 | M7: =SUMIF('TB UK'!A:A,'HARKAVA '!A7,'TB UK'!E:E) -> 514660.89 | N7: =SUMIF('Adj. Entries UK'!B:B,'HARKAVA '!A7,'Adj. Entries UK'!D:D) -> 0 | O7: =SUMIF('Adj. Entries UK'!B:B,'HARKAVA '!A7,'Adj. Entries UK'!E:E) -> 0 | P7: =M7+N7-O7 -> 514660.89 | R7: =SUMIF('TB security'!A:A,'HARKAVA '!A7,'TB security'!D:D) -> 0 | S7: =SUMIF('Adj. Entries security'!B:B,'HARKAVA '!A7,'Adj. Entries security'!D:D) -> 0 | T7: =SUMIF('Adj. Entries security'!B:B,'HARKAVA '!A7,'Adj. Entries security'!E:E) -> 0 | U7: =R7+S7-T7 -> 0 | V7: =P7+F7+U7+K7 -> 599103.58 | Y7: =V7+X7 -> 599103.58 | Z7: =LEFT(A7,2) -> 11 | AD7: 84442.69 | AF7: 0 | AG7: 0 | AH7: 0 | AI7: 0 | AK7: 514660.89 | AL7: 0 | AM7: 0 | AN7: 514660.89 | AP7: 0 | AQ7: 0 | AR7: 0 | AS7: 0 | AT7: 599103.58 | AW7: 599103.58 | AY7: =F7-AD7 -> 0 | AZ7: =P7-AN7 -> 0 | BA7: =U7-AS7 -> 0 | BB7: =X7-AV7 -> 0
A8: 1300 | B8: Deposits | C8: =SUMIF('TB Mitiga LTD'!A:A,'HARKAVA '!A8,'TB Mitiga LTD'!D:D) -> 347835.82 | D8: =SUMIF('Adj Entries Ltd'!$B$4:$B$954,A8,'Adj Entries Ltd'!$D$4:$D$954) -> 0 | E8: =SUMIF('Adj Entries Ltd'!$B$4:$B$954,A8,'Adj Entries Ltd'!$E$4:$E$954) -> 0 | F8: =(+C8+D8-E8) -> 347835.82 | H8: =SUMIF('TB US'!A:A,'HARKAVA '!A8,'TB US'!D:D) -> 0 | I8: =SUMIF('Adj. entries US'!B:B,'HARKAVA '!A8,'Adj. entries US'!D:D) -> 0 | J8: =SUMIF('Adj. entries US'!B:B,'HARKAVA '!A8,'Adj. entries US'!E:E) -> 0 | K8: =H8+I8-J8 -> 0 | M8: =SUMIF('TB UK'!A:A,'HARKAVA '!A8,'TB UK'!E:E) -> 20272.19 | N8: =SUMIF('Adj. Entries UK'!B:B,'HARKAVA '!A8,'Adj. Entries UK'!D:D) -> 0 | O8: =SUMIF('Adj. Entries UK'!B:B,'HARKAVA '!A8,'Adj. Entries UK'!E:E) -> 0 | P8: =M8+N8-O8 -> 20272.19 | R8: =SUMIF('TB security'!A:A,'HARKAVA '!A8,'TB security'!D:D) -> 40000 | S8: =SUMIF('Adj. Entries security'!B:B,'HARKAVA '!A8,'Adj. Entries security'!D:D) -> 0 | T8: =SUMIF('Adj. Entries security'!B:B,'HARKAVA '!A8,'Adj. Entries security'!E:E) -> 0 | U8: =R8+S8-T8 -> 40000 | V8: =P8+F8+U8+K8 -> 408108.01 | Y8: =V8+X8 -> 408108.01 | Z8: =LEFT(A8,2) -> 13 | AD8: 347835.82 | AF8: 0 | AG8: 0 | AH8: 0 | AI8: 0 | AK8: 20272.19 | AL8: 0 | AM8: 0 | AN8: 20272.19 | AP8: 40000 | AQ8: 0 | AR8: 0 | AS8: 40000 | AT8: 408108.01 | AW8: 408108.01 | AY8: =F8-AD8 -> 0 | AZ8: =P8-AN8 -> 0 | BA8: =U8-AS8 -> 0 | BB8: =X8-AV8 -> 0
A9: 1400 | B9: Trade receivable, net | C9: =SUMIF('TB Mitiga LTD'!A:A,'HARKAVA '!A9,'TB Mitiga LTD'!D:D) -> 197867.53 | D9: =SUMIF('Adj Entries Ltd'!$B$4:$B$954,A9,'Adj Entries Ltd'!$D$4:$D$954) -> 0 | E9: =SUMIF('Adj Entries Ltd'!$B$4:$B$954,A9,'Adj Entries Ltd'!$E$4:$E$954) -> 0 | F9: =(+C9+D9-E9) -> 197867.53 | H9: =SUMIF('TB US'!A:A,'HARKAVA '!A9,'TB US'!D:D) -> 0 | I9: =SUMIF('Adj. entries US'!B:B,'HARKAVA '!A9,'Adj. entries US'!D:D) -> 0 | J9: =SUMIF('Adj. entries US'!B:B,'HARKAVA '!A9,'Adj. entries US'!E:E) -> 0 | K9: =H9+I9-J9 -> 0 | M9: =SUMIF('TB UK'!A:A,'HARKAVA '!A9,'TB UK'!E:E) -> 119038.28 | N9: =SUMIF('Adj. Entries UK'!B:B,'HARKAVA '!A9,'Adj. Entries UK'!D:D) -> 0 | O9: =SUMIF('Adj. Entries UK'!B:B,'HARKAVA '!A9,'Adj. Entries UK'!E:E) -> 0 | P9: =M9+N9-O9 -> 119038.28 | R9: =SUMIF('TB security'!A:A,'HARKAVA '!A9,'TB security'!D:D) -> 270540 | S9: =SUMIF('Adj. Entries security'!B:B,'HARKAVA '!A9,'Adj. Entries security'!D:D) -> 0 | T9: =SUMIF('Adj. Entries security'!B:B,'HARKAVA '!A9,'Adj. Entries security'!E:E) -> 0 | U9: =R9+S9-T9 -> 270540 | V9: =P9+F9+U9+K9 -> 587445.81 | Y9: =V9+X9 -> 587445.81 | Z9: =LEFT(A9,2) -> 14 | AD9: 197867.53 | AF9: 0 | AG9: 0 | AH9: 0 | AI9: 0 | AK9: 119038.28 | AL9: 0 | AM9: 0 | AN9: 119038.28 | AP9: 270540 | AQ9: 0 | AR9: 0 | AS9: 270540 | AT9: 587445.81 | AV9: 372917 | AW9: 960362.81 | AY9: =F9-AD9 -> 0 | AZ9: =P9-AN9 -> 0 | BA9: =U9-AS9 -> 0 | BB9: =X9-AV9 -> -372917
A10: 1450 | B10: Income receivable | C10: =SUMIF('TB Mitiga LTD'!A:A,'HARKAVA '!A10,'TB Mitiga LTD'!D:D) -> 39750 | D10: =SUMIF('Adj Entries Ltd'!$B$4:$B$954,A10,'Adj Entries Ltd'!$D$4:$D$954) -> 0 | E10: =SUMIF('Adj Entries Ltd'!$B$4:$B$954,A10,'Adj Entries Ltd'!$E$4:$E$954) -> 0 | F10: =(+C10+D10-E10) -> 39750 | H10: =SUMIF('TB US'!A:A,'HARKAVA '!A10,'TB US'!D:D) -> 0 | I10: =SUMIF('Adj. entries US'!B:B,'HARKAVA '!A10,'Adj. entries US'!D:D) -> 0 | J10: =SUMIF('Adj. entries US'!B:B,'HARKAVA '!A10,'Adj. entries US'!E:E) -> 0 | K10: =H10+I10-J10 -> 0 | M10: =SUMIF('TB UK'!A:A,'HARKAVA '!A10,'TB UK'!E:E) -> 0 | N10: =SUMIF('Adj. Entries UK'!B:B,'HARKAVA '!A10,'Adj. Entries UK'!D:D) -> 0 | O10: =SUMIF('Adj. Entries UK'!B:B,'HARKAVA '!A10,'Adj. Entries UK'!E:E) -> 0 | P10: =M10+N10-O10 -> 0 | R10: =SUMIF('TB security'!A:A,'HARKAVA '!A10,'TB security'!D:D) -> 117959 | S10: =SUMIF('Adj. Entries security'!B:B,'HARKAVA '!A10,'Adj. Entries security'!D:D) -> 0 | T10: =SUMIF('Adj. Entries security'!B:B,'HARKAVA '!A10,'Adj. Entries security'!E:E) -> 0 | U10: =R10+S10-T10 -> 117959 | V10: =P10+F10+U10+K10 -> 157709 | Y10: =V10+X10 -> 157709 | Z10: =LEFT(A10,2) -> 14 | AD10: 110000 | AF10: 0 | AG10: 0 | AH10: 0 | AI10: 0 | AK10: 0 | AL10: 0 | AM10: 0 | AN10: 0 | AP10: 47709 | AQ10: 0 | AR10: 0 | AS10: 47709 | AT10: 157709 | AW10: 157709 | AY10: =F10-AD10 -> -70250 | AZ10: =P10-AN10 -> 0 | BA10: =U10-AS10 -> 70250 | BB10: =X10-AV10 -> 0 | BC10: Moved Income receivable that was initially recorded in IL to Security (Safebreach). This is a was through I/C, so no impact.
A11: 1500 | B11: Related parties | C11: =SUMIF('TB Mitiga LTD'!A:A,'HARKAVA '!A11,'TB Mitiga LTD'!D:D) -> 958184.27 | D11: =SUMIF('Adj Entries Ltd'!$B$4:$B$954,A11,'Adj Entries Ltd'!$D$4:$D$954) -> 0 | E11: =SUMIF('Adj Entries Ltd'!$B$4:$B$954,A11,'Adj Entries Ltd'!$E$4:$E$954) -> 0 | F11: =(+C11+D11-E11) -> 958184.27 | H11: =SUMIF('TB US'!A:A,'HARKAVA '!A11,'TB US'!D:D) -> 67042.28 | I11: =SUMIF('Adj. entries US'!B:B,'HARKAVA '!A11,'Adj. entries US'!D:D) -> 0 | J11: =SUMIF('Adj. entries US'!B:B,'HARKAVA '!A11,'Adj. entries US'!E:E) -> 0 | K11: =H11+I11-J11 -> 67042.28 | M11: =SUMIF('TB UK'!A:A,'HARKAVA '!A11,'TB UK'!E:E) -> 0 | N11: =SUMIF('Adj. Entries UK'!B:B,'HARKAVA '!A11,'Adj. Entries UK'!D:D) -> 0 | O11: =SUMIF('Adj. Entries UK'!B:B,'HARKAVA '!A11,'Adj. Entries UK'!E:E) -> 0 | P11: =M11+N11-O11 -> 0 | R11: =SUMIF('TB security'!A:A,'HARKAVA '!A11,'TB security'!D:D) -> 16350 | S11: =SUMIF('Adj. Entries security'!B:B,'HARKAVA '!A11,'Adj. Entries security'!D:D) -> 0 | T11: =SUMIF('Adj. Entries security'!B:B,'HARKAVA '!A11,'Adj. Entries security'!E:E) -> 0 | U11: =R11+S11-T11 -> 16350 | V11: =P11+F11+U11+K11 -> 1041576.5 | X11: =-V11+16350+4721 -> -1020505.5 | Y11: =V11+X11 -> 21071 | Z11: 16 | AD11: 958184.27 | AF11: 67042.28 | AG11: 0 | AH11: 0 | AI11: 67042.28 | AK11: 0 | AL11: 0 | AM11: 0 | AN11: 0 | AP11: 16350 | AQ11: 0 | AR11: 0 | AS11: 16350 | AT11: 1041576.5 | AV11: -1020505.5 | AW11: 21071 | AY11: =F11-AD11 -> 0 | AZ11: =P11-AN11 -> 0 | BA11: =U11-AS11 -> 0 | BB11: =X11-AV11 -> 0
A12: 1600 | B12: Prepaid expenses | C12: =SUMIF('TB Mitiga LTD'!A:A,'HARKAVA '!A12,'TB Mitiga LTD'!D:D) -> 189723.68 | D12: =SUMIF('Adj Entries Ltd'!$B$4:$B$954,A12,'Adj Entries Ltd'!$D$4:$D$954) -> 11383.25 | E12: =SUMIF('Adj Entries Ltd'!$B$4:$B$954,A12,'Adj Entries Ltd'!$E$4:$E$954) -> 0 | F12: =(+C12+D12-E12) -> 201106.93 | H12: =SUMIF('TB US'!A:A,'HARKAVA '!A12,'TB US'!D:D) -> 0 | I12: =SUMIF('Adj. entries US'!B:B,'HARKAVA '!A12,'Adj. entries US'!D:D) -> 0 | J12: =SUMIF('Adj. entries US'!B:B,'HARKAVA '!A12,'Adj. entries US'!E:E) -> 0 | K12: =H12+I12-J12 -> 0 | M12: =SUMIF('TB UK'!A:A,'HARKAVA '!A12,'TB UK'!E:E) -> 6166.63 | N12: =SUMIF('Adj. Entries UK'!B:B,'HARKAVA '!A12,'Adj. Entries UK'!D:D) -> 0 | O12: =SUMIF('Adj. Entries UK'!B:B,'HARKAVA '!A12,'Adj. Entries UK'!E:E) -> 0 | P12: =M12+N12-O12 -> 6166.63 | R12: =SUMIF('TB security'!A:A,'HARKAVA '!A12,'TB security'!D:D) -> 49885.48 | S12: =SUMIF('Adj. Entries security'!B:B,'HARKAVA '!A12,'Adj. Entries security'!D:D) -> 0 | T12: =SUMIF('Adj. Entries security'!B:B,'HARKAVA '!A12,'Adj. Entries security'!E:E) -> 0 | U12: =R12+S12-T12 -> 49885.48 | V12: =P12+F12+U12+K12 -> 257159.04 | Y12: =V12+X12 -> 257159.04 | Z12: =LEFT(A12,2) -> 16 | AD12: 189723.68 | AF12: 0 | AG12: 0 | AH12: 0 | AI12: 0 | AK12: 6166.63 | AL12: 0 | AM12: 0 | AN12: 6166.63 | AP12: 49885.48 | AQ12: 0 | AR12: 0 | AS12: 49885.48 | AT12: 245775.79 | AW12: 245775.79 | AY12: =F12-AD12 -> 11383.25 | AZ12: =P12-AN12 -> 0 | BA12: =U12-AS12 -> 0 | BB12: =X12-AV12 -> 0
A13: 1610 | B13: Government of Israel-tax | C13: =SUMIF('TB Mitiga LTD'!A:A,'HARKAVA '!A13,'TB Mitiga LTD'!D:D) -> 14985.11 | D13: =SUMIF('Adj Entries Ltd'!$B$4:$B$954,A13,'Adj Entries Ltd'!$D$4:$D$954) -> 0 | E13: =SUMIF('Adj Entries Ltd'!$B$4:$B$954,A13,'Adj Entries Ltd'!$E$4:$E$954) -> 0 | F13: =(+C13+D13-E13) -> 14985.11 | H13: =SUMIF('TB US'!A:A,'HARKAVA '!A13,'TB US'!D:D) -> 0 | I13: =SUMIF('Adj. entries US'!B:B,'HARKAVA '!A13,'Adj. entries US'!D:D) -> 0 | J13: =SUMIF('Adj. entries US'!B:B,'HARKAVA '!A13,'Adj. entries US'!E:E) -> 0 | K13: =H13+I13-J13 -> 0 | M13: =SUMIF('TB UK'!A:A,'HARKAVA '!A13,'TB UK'!E:E) -> 5611.91 | N13: =SUMIF('Adj. Entries UK'!B:B,'HARKAVA '!A13,'Adj. Entries UK'!D:D) -> 0 | O13: =SUMIF('Adj. Entries UK'!B:B,'HARKAVA '!A13,'Adj. Entries UK'!E:E) -> 0 | P13: =M13+N13-O13 -> 5611.91 | R13: =SUMIF('TB security'!A:A,'HARKAVA '!A13,'TB security'!D:D) -> 0 | S13: =SUMIF('Adj. Entries security'!B:B,'HARKAVA '!A13,'Adj. Entries security'!D:D) -> 0 | T13: =SUMIF('Adj. Entries security'!B:B,'HARKAVA '!A13,'Adj. Entries security'!E:E) -> 0 | U13: =R13+S13-T13 -> 0 | V13: =P13+F13+U13+K13 -> 20597.02 | Y13: =V13+X13 -> 20597.02 | Z13: =LEFT(A13,2) -> 16 | AD13: 14985.11 | AF13: 0 | AG13: 0 | AH13: 0 | AI13: 0 | AK13: 5611.91 | AL13: 0 | AM13: 0 | AN13: 5611.91 | AP13: 0 | AQ13: 0 | AR13: 0 | AS13: 0 | AT13: 20597.02 | AW13: 20597.02 | AY13: =F13-AD13 -> 0 | AZ13: =P13-AN13 -> 0 | BA13: =U13-AS13 -> 0 | BB13: =X13-AV13 -> 0
A14: 1620 | B14: AR-government of Israel-VAT (net) | C14: =SUMIF('TB Mitiga LTD'!A:A,'HARKAVA '!A14,'TB Mitiga LTD'!D:D) -> 237762.45 | D14: =SUMIF('Adj Entries Ltd'!$B$4:$B$954,A14,'Adj Entries Ltd'!$D$4:$D$954) -> 0 | E14: =SUMIF('Adj Entries Ltd'!$B$4:$B$954,A14,'Adj Entries Ltd'!$E$4:$E$954) -> 0 | F14: =(+C14+D14-E14) -> 237762.45 | H14: =SUMIF('TB US'!A:A,'HARKAVA '!A14,'TB US'!D:D) -> 0 | I14: =SUMIF('Adj. entries US'!B:B,'HARKAVA '!A14,'Adj. entries US'!D:D) -> 0 | J14: =SUMIF('Adj. entries US'!B:B,'HARKAVA '!A14,'Adj. entries US'!E:E) -> 0 | K14: =H14+I14-J14 -> 0 | M14: =SUMIF('TB UK'!A:A,'HARKAVA '!A14,'TB UK'!E:E) -> 0 | N14: =SUMIF('Adj. Entries UK'!B:B,'HARKAVA '!A14,'Adj. Entries UK'!D:D) -> 0 | O14: =SUMIF('Adj. Entries UK'!B:B,'HARKAVA '!A14,'Adj. Entries UK'!E:E) -> 0 | P14: =M14+N14-O14 -> 0 | R14: =SUMIF('TB security'!A:A,'HARKAVA '!A14,'TB security'!D:D) -> 0 | S14: =SUMIF('Adj. Entries security'!B:B,'HARKAVA '!A14,'Adj. Entries security'!D:D) -> 0 | T14: =SUMIF('Adj. Entries security'!B:B,'HARKAVA '!A14,'Adj. Entries security'!E:E) -> 0 | U14: =R14+S14-T14 -> 0 | V14: =P14+F14+U14+K14 -> 237762.45 | Y14: =V14+X14 -> 237762.45 | Z14: =LEFT(A14,2) -> 16 | AD14: 237762.45 | AF14: 0 | AG14: 0 | AH14: 0 | AI14: 0 | AK14: 0 | AL14: 0 | AM14: 0 | AN14: 0 | AP14: 0 | AQ14: 0 | AR14: 0 | AS14: 0 | AT14: 237762.45 | AW14: 237762.45 | AY14: =F14-AD14 -> 0 | AZ14: =P14-AN14 -> 0 | BA14: =U14-AS14 -> 0 | BB14: =X14-AV14 -> 0
A15: 1630 | B15: DEFERRED_TAXES_CUR | C15: =SUMIF('TB Mitiga LTD'!A:A,'HARKAVA '!A15,'TB Mitiga LTD'!D:D) -> 0 | D15: =SUMIF('Adj Entries Ltd'!$B$4:$B$954,A15,'Adj Entries Ltd'!$D$4:$D$954) -> 0 | E15: =SUMIF('Adj Entries Ltd'!$B$4:$B$954,A15,'Adj Entries Ltd'!$E$4:$E$954) -> 0 | F15: =(+C15+D15-E15) -> 0 | H15: =SUMIF('TB US'!A:A,'HARKAVA '!A15,'TB US'!D:D) -> 0 | I15: =SUMIF('Adj. entries US'!B:B,'HARKAVA '!A15,'Adj. entries US'!D:D) -> 0 | J15: =SUMIF('Adj. entries US'!B:B,'HARKAVA '!A15,'Adj. entries US'!E:E) -> 0 | K15: =H15+I15-J15 -> 0 | M15: =SUMIF('TB UK'!A:A,'HARKAVA '!A15,'TB UK'!E:E) -> 0 | N15: =SUMIF('Adj. Entries UK'!B:B,'HARKAVA '!A15,'Adj. Entries UK'!D:D) -> 0 | O15: =SUMIF('Adj. Entries UK'!B:B,'HARKAVA '!A15,'Adj. Entries UK'!E:E) -> 0 | P15: =M15+N15-O15 -> 0 | R15: =SUMIF('TB security'!A:A,'HARKAVA '!A15,'TB security'!D:D) -> 0 | S15: =SUMIF('Adj. Entries security'!B:B,'HARKAVA '!A15,'Adj. Entries security'!D:D) -> 0 | T15: =SUMIF('Adj. Entries security'!B:B,'HARKAVA '!A15,'Adj. Entries security'!E:E) -> 0 | U15: =R15+S15-T15 -> 0 | V15: =P15+F15+U15+K15 -> 0 | Y15: =V15+X15 -> 0 | Z15: =LEFT(A15,2) -> 16 | AD15: 0 | AF15: 0 | AG15: 0 | AH15: 0 | AI15: 0 | AK15: 0 | AL15: 0 | AM15: 0 | AN15: 0 | AP15: 0 | AQ15: 0 | AR15: 0 | AS15: 0 | AT15: 0 | AW15: 0 | AY15: =F15-AD15 -> 0 | AZ15: =P15-AN15 -> 0 | BA15: =U15-AS15 -> 0 | BB15: =X15-AV15 -> 0
A16: 1640 | B16: AR-short term leasing deposits | C16: =SUMIF('TB Mitiga LTD'!A:A,'HARKAVA '!A16,'TB Mitiga LTD'!D:D) -> 294311 | D16: =SUMIF('Adj Entries Ltd'!$B$4:$B$954,A16,'Adj Entries Ltd'!$D$4:$D$954) -> 0 | E16: =SUMIF('Adj Entries Ltd'!$B$4:$B$954,A16,'Adj Entries Ltd'!$E$4:$E$954) -> 0 | F16: =(+C16+D16-E16) -> 294311 | H16: =SUMIF('TB US'!A:A,'HARKAVA '!A16,'TB US'!D:D) -> 0 | I16: =SUMIF('Adj. entries US'!B:B,'HARKAVA '!A16,'Adj. entries US'!D:D) -> 0 | J16: =SUMIF('Adj. entries US'!B:B,'HARKAVA '!A16,'Adj. entries US'!E:E) -> 0 | K16: =H16+I16-J16 -> 0 | M16: =SUMIF('TB UK'!A:A,'HARKAVA '!A16,'TB UK'!E:E) -> 0 | N16: =SUMIF('Adj. Entries UK'!B:B,'HARKAVA '!A16,'Adj. Entries UK'!D:D) -> 0 | O16: =SUMIF('Adj. Entries UK'!B:B,'HARKAVA '!A16,'Adj. Entries UK'!E:E) -> 0 | P16: =M16+N16-O16 -> 0 | R16: =SUMIF('TB security'!A:A,'HARKAVA '!A16,'TB security'!D:D) -> 0 | S16: =SUMIF('Adj. Entries security'!B:B,'HARKAVA '!A16,'Adj. Entries security'!D:D) -> 0 | T16: =SUMIF('Adj. Entries security'!B:B,'HARKAVA '!A16,'Adj. Entries security'!E:E) -> 0 | U16: =R16+S16-T16 -> 0 | V16: =P16+F16+U16+K16 -> 294311 | Y16: =V16+X16 -> 294311 | Z16: =LEFT(A16,2) -> 16 | AD16: 294311 | AF16: 0 | AG16: 0 | AH16: 0 | AI16: 0 | AK16: 0 | AL16: 0 | AM16: 0 | AN16: 0 | AP16: 0 | AQ16: 0 | AR16: 0 | AS16: 0 | AT16: 294311 | AW16: 294311 | AY16: =F16-AD16 -> 0 | AZ16: =P16-AN16 -> 0 | BA16: =U16-AS16 -> 0 | BB16: =X16-AV16 -> 0
A17: 1650 | B17: AR others | C17: =SUMIF('TB Mitiga LTD'!A:A,'HARKAVA '!A17,'TB Mitiga LTD'!D:D) -> 929980.71 | D17: =SUMIF('Adj Entries Ltd'!$B$4:$B$954,A17,'Adj Entries Ltd'!$D$4:$D$954) -> 0 | E17: =SUMIF('Adj Entries Ltd'!$B$4:$B$954,A17,'Adj Entries Ltd'!$E$4:$E$954) -> 0 | F17: =(+C17+D17-E17) -> 929980.71 | H17: =SUMIF('TB US'!A:A,'HARKAVA '!A17,'TB US'!D:D) -> 0 | I17: =SUMIF('Adj. entries US'!B:B,'HARKAVA '!A17,'Adj. entries US'!D:D) -> 0 | J17: =SUMIF('Adj. entries US'!B:B,'HARKAVA '!A17,'Adj. entries US'!E:E) -> 0 | K17: =H17+I17-J17 -> 0 | M17: =SUMIF('TB UK'!A:A,'HARKAVA '!A17,'TB UK'!E:E) -> 0 | N17: =SUMIF('Adj. Entries UK'!B:B,'HARKAVA '!A17,'Adj. Entries UK'!D:D) -> 0 | O17: =SUMIF('Adj. Entries UK'!B:B,'HARKAVA '!A17,'Adj. Entries UK'!E:E) -> 0 | P17: =M17+N17-O17 -> 0 | R17: =SUMIF('TB security'!A:A,'HARKAVA '!A17,'TB security'!D:D) -> 0 | S17: =SUMIF('Adj. Entries security'!B:B,'HARKAVA '!A17,'Adj. Entries security'!D:D) -> 0 | T17: =SUMIF('Adj. Entries security'!B:B,'HARKAVA '!A17,'Adj. Entries security'!E:E) -> 0 | U17: =R17+S17-T17 -> 0 | V17: =P17+F17+U17+K17 -> 929980.71 | Y17: =V17+X17 -> 929980.71 | Z17: 16 | AD17: 929980.71 | AF17: 0 | AG17: 0 | AH17: 0 | AI17: 0 | AK17: 0 | AL17: 0 | AM17: 0 | AN17: 0 | AP17: 0 | AQ17: 0 | AR17: 0 | AS17: 0 | AT17: 929980.71 | AW17: 929980.71 | AY17: =F17-AD17 -> 0 | AZ17: =P17-AN17 -> 0 | BA17: =U17-AS17 -> 0 | BB17: =X17-AV17 -> 0
A18: 1660 | B18: Leasehold assets - short term | C18: =SUMIF('TB Mitiga LTD'!A:A,'HARKAVA '!A18,'TB Mitiga LTD'!D:D) -> 0 | D18: =SUMIF('Adj Entries Ltd'!$B$4:$B$954,A18,'Adj Entries Ltd'!$D$4:$D$954) -> 0 | E18: =SUMIF('Adj Entries Ltd'!$B$4:$B$954,A18,'Adj Entries Ltd'!$E$4:$E$954) -> 0 | F18: =(+C18+D18-E18) -> 0 | H18: =SUMIF('TB US'!A:A,'HARKAVA '!A18,'TB US'!D:D) -> 0 | I18: =SUMIF('Adj. entries US'!B:B,'HARKAVA '!A18,'Adj. entries US'!D:D) -> 0 | J18: =SUMIF('Adj. entries US'!B:B,'HARKAVA '!A18,'Adj. entries US'!E:E) -> 0 | K18: =H18+I18-J18 -> 0 | M18: =SUMIF('TB UK'!A:A,'HARKAVA '!A18,'TB UK'!E:E) -> 0 | N18: =SUMIF('Adj. Entries UK'!B:B,'HARKAVA '!A18,'Adj. Entries UK'!D:D) -> 0 | O18: =SUMIF('Adj. Entries UK'!B:B,'HARKAVA '!A18,'Adj. Entries UK'!E:E) -> 0 | P18: =M18+N18-O18 -> 0 | R18: =SUMIF('TB security'!A:A,'HARKAVA '!A18,'TB security'!D:D) -> 0 | S18: =SUMIF('Adj. Entries security'!B:B,'HARKAVA '!A18,'Adj. Entries security'!D:D) -> 0 | T18: =SUMIF('Adj. Entries security'!B:B,'HARKAVA '!A18,'Adj. Entries security'!E:E) -> 0 | U18: =R18+S18-T18 -> 0 | V18: =P18+F18+U18+K18 -> 0 | Y18: =V18+X18 -> 0 | Z18: 19 | AD18: 0 | AF18: 0 | AG18: 0 | AH18: 0 | AI18: 0 | AK18: 0 | AL18: 0 | AM18: 0 | AN18: 0 | AP18: 0 | AQ18: 0 | AR18: 0 | AS18: 0 | AT18: 0 | AW18: 0 | AY18: =F18-AD18 -> 0 | AZ18: =P18-AN18 -> 0 | BA18: =U18-AS18 -> 0 | BB18: =X18-AV18 -> 0
A19: 1700 | B19: Deferred taxes | C19: =SUMIF('TB Mitiga LTD'!A:A,'HARKAVA '!A19,'TB Mitiga LTD'!D:D) -> 0 | D19: =SUMIF('Adj Entries Ltd'!$B$4:$B$954,A19,'Adj Entries Ltd'!$D$4:$D$954) -> 0 | E19: =SUMIF('Adj Entries Ltd'!$B$4:$B$954,A19,'Adj Entries Ltd'!$E$4:$E$954) -> 0 | F19: =(+C19+D19-E19) -> 0 | H19: =SUMIF('TB US'!A:A,'HARKAVA '!A19,'TB US'!D:D) -> 0 | I19: =SUMIF('Adj. entries US'!B:B,'HARKAVA '!A19,'Adj. entries US'!D:D) -> 0 | J19: =SUMIF('Adj. entries US'!B:B,'HARKAVA '!A19,'Adj. entries US'!E:E) -> 0 | K19: =H19+I19-J19 -> 0 | M19: =SUMIF('TB UK'!A:A,'HARKAVA '!A19,'TB UK'!E:E) -> 0 | N19: =SUMIF('Adj. Entries UK'!B:B,'HARKAVA '!A19,'Adj. Entries UK'!D:D) -> 0 | O19: =SUMIF('Adj. Entries UK'!B:B,'HARKAVA '!A19,'Adj. Entries UK'!E:E) -> 0 | P19: =M19+N19-O19 -> 0 | R19: =SUMIF('TB security'!A:A,'HARKAVA '!A19,'TB security'!D:D) -> 0 | S19: =SUMIF('Adj. Entries security'!B:B,'HARKAVA '!A19,'Adj. Entries security'!D:D) -> 0 | T19: =SUMIF('Adj. Entries security'!B:B,'HARKAVA '!A19,'Adj. Entries security'!E:E) -> 0 | U19: =R19+S19-T19 -> 0 | V19: =P19+F19+U19+K19 -> 0 | Y19: =V19+X19 -> 0 | Z19: =LEFT(A19,2) -> 17 | AD19: 0 | AF19: 0 | AG19: 0 | AH19: 0 | AI19: 0 | AK19: 0 | AL19: 0 | AM19: 0 | AN19: 0 | AP19: 0 | AQ19: 0 | AR19: 0 | AS19: 0 | AT19: 0 | AW19: 0 | AY19: =F19-AD19 -> 0 | AZ19: =P19-AN19 -> 0 | BA19: =U19-AS19 -> 0 | BB19: =X19-AV19 -> 0
A20: 2100 | B20: Intercompany Capital notes | C20: =SUMIF('TB Mitiga LTD'!A:A,'HARKAVA '!A20,'TB Mitiga LTD'!D:D) -> 0 | D20: =SUMIF('Adj Entries Ltd'!$B$4:$B$954,A20,'Adj Entries Ltd'!$D$4:$D$954) -> 0 | E20: =SUMIF('Adj Entries Ltd'!$B$4:$B$954,A20,'Adj Entries Ltd'!$E$4:$E$954) -> 0 | F20: =(+C20+D20-E20) -> 0 | H20: =SUMIF('TB US'!A:A,'HARKAVA '!A20,'TB US'!D:D) -> 0 | I20: =SUMIF('Adj. entries US'!B:B,'HARKAVA '!A20,'Adj. entries US'!D:D) -> 0 | J20: =SUMIF('Adj. entries US'!B:B,'HARKAVA '!A20,'Adj. entries US'!E:E) -> 0 | K20: =H20+I20-J20 -> 0 | M20: =SUMIF('TB UK'!A:A,'HARKAVA '!A20,'TB UK'!E:E) -> 0 | N20: =SUMIF('Adj. Entries UK'!B:B,'HARKAVA '!A20,'Adj. Entries UK'!D:D) -> 0 | O20: =SUMIF('Adj. Entries UK'!B:B,'HARKAVA '!A20,'Adj. Entries UK'!E:E) -> 0 | P20: =M20+N20-O20 -> 0 | R20: =SUMIF('TB security'!A:A,'HARKAVA '!A20,'TB security'!D:D) -> 0 | S20: =SUMIF('Adj. Entries security'!B:B,'HARKAVA '!A20,'Adj. Entries security'!D:D) -> 0 | T20: =SUMIF('Adj. Entries security'!B:B,'HARKAVA '!A20,'Adj. Entries security'!E:E) -> 0 | U20: =R20+S20-T20 -> 0 | V20: =P20+F20+U20+K20 -> 0 | Y20: =V20+X20 -> 0 | Z20: =LEFT(A20,2) -> 21 | AD20: 0 | AF20: 0 | AG20: 0 | AH20: 0 | AI20: 0 | AK20: 0 | AL20: 0 | AM20: 0 | AN20: 0 | AP20: 0 | AQ20: 0 | AR20: 0 | AS20: 0 | AT20: 0 | AW20: 0 | AY20: =F20-AD20 -> 0 | AZ20: =P20-AN20 -> 0 | BA20: =U20-AS20 -> 0 | BB20: =X20-AV20 -> 0
A21: 2200 | B21: AR-long term leasing deposits | C21: =SUMIF('TB Mitiga LTD'!A:A,'HARKAVA '!A21,'TB Mitiga LTD'!D:D) -> 0 | D21: =SUMIF('Adj Entries Ltd'!$B$4:$B$954,A21,'Adj Entries Ltd'!$D$4:$D$954) -> 0 | E21: =SUMIF('Adj Entries Ltd'!$B$4:$B$954,A21,'Adj Entries Ltd'!$E$4:$E$954) -> 0 | F21: =(+C21+D21-E21) -> 0 | H21: =SUMIF('TB US'!A:A,'HARKAVA '!A21,'TB US'!D:D) -> 0 | I21: =SUMIF('Adj. entries US'!B:B,'HARKAVA '!A21,'Adj. entries US'!D:D) -> 0 | J21: =SUMIF('Adj. entries US'!B:B,'HARKAVA '!A21,'Adj. entries US'!E:E) -> 0 | K21: =H21+I21-J21 -> 0 | M21: =SUMIF('TB UK'!A:A,'HARKAVA '!A21,'TB UK'!E:E) -> 0 | N21: =SUMIF('Adj. Entries UK'!B:B,'HARKAVA '!A21,'Adj. Entries UK'!D:D) -> 0 | O21: =SUMIF('Adj. Entries UK'!B:B,'HARKAVA '!A21,'Adj. Entries UK'!E:E) -> 0 | P21: =M21+N21-O21 -> 0 | R21: =SUMIF('TB security'!A:A,'HARKAVA '!A21,'TB security'!D:D) -> 0 | S21: =SUMIF('Adj. Entries security'!B:B,'HARKAVA '!A21,'Adj. Entries security'!D:D) -> 0 | T21: =SUMIF('Adj. Entries security'!B:B,'HARKAVA '!A21,'Adj. Entries security'!E:E) -> 0 | U21: =R21+S21-T21 -> 0 | V21: =P21+F21+U21+K21 -> 0 | Y21: =V21+X21 -> 0 | Z21: =LEFT(A21,2) -> 22 | AD21: 0 | AF21: 0 | AG21: 0 | AH21: 0 | AI21: 0 | AK21: 0 | AL21: 0 | AM21: 0 | AN21: 0 | AP21: 0 | AQ21: 0 | AR21: 0 | AS21: 0 | AT21: 0 | AW21: 0 | AY21: =F21-AD21 -> 0 | AZ21: =P21-AN21 -> 0 | BA21: =U21-AS21 -> 0 | BB21: =X21-AV21 -> 0
A22: 2300 | B22: Deferred taxes- Long term | C22: =SUMIF('TB Mitiga LTD'!A:A,'HARKAVA '!A22,'TB Mitiga LTD'!D:D) -> 0 | D22: =SUMIF('Adj Entries Ltd'!$B$4:$B$954,A22,'Adj Entries Ltd'!$D$4:$D$954) -> 0 | E22: =SUMIF('Adj Entries Ltd'!$B$4:$B$954,A22,'Adj Entries Ltd'!$E$4:$E$954) -> 0 | F22: =(+C22+D22-E22) -> 0 | H22: =SUMIF('TB US'!A:A,'HARKAVA '!A22,'TB US'!D:D) -> 0 | I22: =SUMIF('Adj. entries US'!B:B,'HARKAVA '!A22,'Adj. entries US'!D:D) -> 0 | J22: =SUMIF('Adj. entries US'!B:B,'HARKAVA '!A22,'Adj. entries US'!E:E) -> 0 | K22: =H22+I22-J22 -> 0 | M22: =SUMIF('TB UK'!A:A,'HARKAVA '!A22,'TB UK'!E:E) -> 0 | N22: =SUMIF('Adj. Entries UK'!B:B,'HARKAVA '!A22,'Adj. Entries UK'!D:D) -> 0 | O22: =SUMIF('Adj. Entries UK'!B:B,'HARKAVA '!A22,'Adj. Entries UK'!E:E) -> 0 | P22: =M22+N22-O22 -> 0 | R22: =SUMIF('TB security'!A:A,'HARKAVA '!A22,'TB security'!D:D) -> 0 | S22: =SUMIF('Adj. Entries security'!B:B,'HARKAVA '!A22,'Adj. Entries security'!D:D) -> 0 | T22: =SUMIF('Adj. Entries security'!B:B,'HARKAVA '!A22,'Adj. Entries security'!E:E) -> 0 | U22: =R22+S22-T22 -> 0 | V22: =P22+F22+U22+K22 -> 0 | Y22: =V22+X22 -> 0 | Z22: =LEFT(A22,2) -> 23 | AD22: 0 | AF22: 0 | AG22: 0 | AH22: 0 | AI22: 0 | AK22: 0 | AL22: 0 | AM22: 0 | AN22: 0 | AP22: 0 | AQ22: 0 | AR22: 0 | AS22: 0 | AT22: 0 | AW22: 0 | AY22: =F22-AD22 -> 0 | AZ22: =P22-AN22 -> 0 | BA22: =U22-AS22 -> 0 | BB22: =X22-AV22 -> 0
A23: 2350 | B23: Leasehold assets | C23: =SUMIF('TB Mitiga LTD'!A:A,'HARKAVA '!A23,'TB Mitiga LTD'!D:D) -> 0 | D23: =SUMIF('Adj Entries Ltd'!$B$4:$B$954,A23,'Adj Entries Ltd'!$D$4:$D$954) -> 0 | E23: =SUMIF('Adj Entries Ltd'!$B$4:$B$954,A23,'Adj Entries Ltd'!$E$4:$E$954) -> 0 | F23: =(+C23+D23-E23) -> 0 | H23: =SUMIF('TB US'!A:A,'HARKAVA '!A23,'TB US'!D:D) -> 0 | I23: =SUMIF('Adj. entries US'!B:B,'HARKAVA '!A23,'Adj. entries US'!D:D) -> 0 | J23: =SUMIF('Adj. entries US'!B:B,'HARKAVA '!A23,'Adj. entries US'!E:E) -> 0 | K23: =H23+I23-J23 -> 0 | M23: =SUMIF('TB UK'!A:A,'HARKAVA '!A23,'TB UK'!E:E) -> 0 | N23: =SUMIF('Adj. Entries UK'!B:B,'HARKAVA '!A23,'Adj. Entries UK'!D:D) -> 0 | O23: =SUMIF('Adj. Entries UK'!B:B,'HARKAVA '!A23,'Adj. Entries UK'!E:E) -> 0 | P23: =M23+N23-O23 -> 0 | R23: =SUMIF('TB security'!A:A,'HARKAVA '!A23,'TB security'!D:D) -> 0 | S23: =SUMIF('Adj. Entries security'!B:B,'HARKAVA '!A23,'Adj. Entries security'!D:D) -> 0 | T23: =SUMIF('Adj. Entries security'!B:B,'HARKAVA '!A23,'Adj. Entries security'!E:E) -> 0 | U23: =R23+S23-T23 -> 0 | V23: =P23+F23+U23+K23 -> 0 | Y23: =V23+X23 -> 0 | Z23: 25 | AD23: 0 | AF23: 0 | AG23: 0 | AH23: 0 | AI23: 0 | AK23: 0 | AL23: 0 | AM23: 0 | AN23: 0 | AP23: 0 | AQ23: 0 | AR23: 0 | AS23: 0 | AT23: 0 | AW23: 0 | AY23: =F23-AD23 -> 0 | AZ23: =P23-AN23 -> 0 | BA23: =U23-AS23 -> 0 | BB23: =X23-AV23 -> 0
A24: 2400 | B24: Investment in subsidiary | C24: =SUMIF('TB Mitiga LTD'!A:A,'HARKAVA '!A24,'TB Mitiga LTD'!D:D) -> 129.64 | D24: =SUMIF('Adj Entries Ltd'!$B$4:$B$954,A24,'Adj Entries Ltd'!$D$4:$D$954) -> 0 | E24: =SUMIF('Adj Entries Ltd'!$B$4:$B$954,A24,'Adj Entries Ltd'!$E$4:$E$954) -> 0 | F24: =(+C24+D24-E24) -> 129.64 | H24: =SUMIF('TB US'!A:A,'HARKAVA '!A24,'TB US'!D:D) -> 0 | I24: =SUMIF('Adj. entries US'!B:B,'HARKAVA '!A24,'Adj. entries US'!D:D) -> 0 | J24: =SUMIF('Adj. entries US'!B:B,'HARKAVA '!A24,'Adj. entries US'!E:E) -> 0 | K24: =H24+I24-J24 -> 0 | M24: =SUMIF('TB UK'!A:A,'HARKAVA '!A24,'TB UK'!E:E) -> 0 | N24: =SUMIF('Adj. Entries UK'!B:B,'HARKAVA '!A24,'Adj. Entries UK'!D:D) -> 0 | O24: =SUMIF('Adj. Entries UK'!B:B,'HARKAVA '!A24,'Adj. Entries UK'!E:E) -> 0 | P24: =M24+N24-O24 -> 0 | R24: =SUMIF('TB security'!A:A,'HARKAVA '!A24,'TB security'!D:D) -> 320 | S24: =SUMIF('Adj. Entries security'!B:B,'HARKAVA '!A24,'Adj. Entries security'!D:D) -> 0 | T24: =SUMIF('Adj. Entries security'!B:B,'HARKAVA '!A24,'Adj. Entries security'!E:E) -> 0 | U24: =R24+S24-T24 -> 320 | V24: =P24+F24+U24+K24 -> 449.64 | X24: =-V24 -> -449.64 | Y24: =V24+X24 -> 0 | Z24: =LEFT(A24,2) -> 24 | AD24: 129.64 | AF24: 0 | AG24: 0 | AH24: 0 | AI24: 0 | AK24: 0 | AL24: 0 | AM24: 0 | AN24: 0 | AP24: 320 | AQ24: 0 | AR24: 0 | AS24: 320 | AT24: 449.64 | AV24: -449.64 | AW24: 0 | AY24: =F24-AD24 -> 0 | AZ24: =P24-AN24 -> 0 | BA24: =U24-AS24 -> 0 | BB24: =X24-AV24 -> 0
A25: 3100 | B25: Fixed assets-cost | C25: =SUMIF('TB Mitiga LTD'!A:A,'HARKAVA '!A25,'TB Mitiga LTD'!D:D) -> 1431538.9 | D25: =SUMIF('Adj Entries Ltd'!$B$4:$B$954,A25,'Adj Entries Ltd'!$D$4:$D$954) -> 0 | E25: =SUMIF('Adj Entries Ltd'!$B$4:$B$954,A25,'Adj Entries Ltd'!$E$4:$E$954) -> 11383.25 | F25: =(+C25+D25-E25) -> 1420155.7 | H25: =SUMIF('TB US'!A:A,'HARKAVA '!A25,'TB US'!D:D) -> 0 | I25: =SUMIF('Adj. entries US'!B:B,'HARKAVA '!A25,'Adj. entries US'!D:D) -> 0 | J25: =SUMIF('Adj. entries US'!B:B,'HARKAVA '!A25,'Adj. entries US'!E:E) -> 0 | K25: =H25+I25-J25 -> 0 | M25: =SUMIF('TB UK'!A:A,'HARKAVA '!A25,'TB UK'!E:E) -> 26887.96 | N25: =SUMIF('Adj. Entries UK'!B:B,'HARKAVA '!A25,'Adj. Entries UK'!D:D) -> 0 | O25: =SUMIF('Adj. Entries UK'!B:B,'HARKAVA '!A25,'Adj. Entries UK'!E:E) -> 0 | P25: =M25+N25-O25 -> 26887.96 | R25: =SUMIF('TB security'!A:A,'HARKAVA '!A25,'TB security'!D:D) -> 50601.48 | S25: =SUMIF('Adj. Entries security'!B:B,'HARKAVA '!A25,'Adj. Entries security'!D:D) -> 0 | T25: =SUMIF('Adj. Entries security'!B:B,'HARKAVA '!A25,'Adj. Entries security'!E:E) -> 0 | U25: =R25+S25-T25 -> 50601.48 | V25: =P25+F25+U25+K25 -> 1497645.1 | Y25: =V25+X25 -> 1497645.1 | Z25: =LEFT(A25,2) -> 31 | AD25: 1431538.9 | AF25: 0 | AG25: 0 | AH25: 0 | AI25: 0 | AK25: 26887.96 | AL25: 0 | AM25: 0 | AN25: 26887.96 | AP25: 50601.48 | AQ25: 0 | AR25: 0 | AS25: 50601.48 | AT25: 1509028.4 | AW25: 1509028.4 | AY25: =F25-AD25 -> -11383.25 | AZ25: =P25-AN25 -> 0 | BA25: =U25-AS25 -> 0 | BB25: =X25-AV25 -> 0
A26: 3110 | B26: Fixed assets-accumulated dep. | C26: =SUMIF('TB Mitiga LTD'!A:A,'HARKAVA '!A26,'TB Mitiga LTD'!D:D) -> -93369 | D26: =SUMIF('Adj Entries Ltd'!$B$4:$B$954,A26,'Adj Entries Ltd'!$D$4:$D$954) -> 0 | E26: =SUMIF('Adj Entries Ltd'!$B$4:$B$954,A26,'Adj Entries Ltd'!$E$4:$E$954) -> 0 | F26: =(+C26+D26-E26) -> -93369 | H26: =SUMIF('TB US'!A:A,'HARKAVA '!A26,'TB US'!D:D) -> 0 | I26: =SUMIF('Adj. entries US'!B:B,'HARKAVA '!A26,'Adj. entries US'!D:D) -> 0 | J26: =SUMIF('Adj. entries US'!B:B,'HARKAVA '!A26,'Adj. entries US'!E:E) -> 0 | K26: =H26+I26-J26 -> 0 | M26: =SUMIF('TB UK'!A:A,'HARKAVA '!A26,'TB UK'!E:E) -> -9443 | N26: =SUMIF('Adj. Entries UK'!B:B,'HARKAVA '!A26,'Adj. Entries UK'!D:D) -> 0 | O26: =SUMIF('Adj. Entries UK'!B:B,'HARKAVA '!A26,'Adj. Entries UK'!E:E) -> 0 | P26: =M26+N26-O26 -> -9443 | R26: =SUMIF('TB security'!A:A,'HARKAVA '!A26,'TB security'!D:D) -> -3702 | S26: =SUMIF('Adj. Entries security'!B:B,'HARKAVA '!A26,'Adj. Entries security'!D:D) -> 0 | T26: =SUMIF('Adj. Entries security'!B:B,'HARKAVA '!A26,'Adj. Entries security'!E:E) -> 0 | U26: =R26+S26-T26 -> -3702 | V26: =P26+F26+U26+K26 -> -106514 | Y26: =V26+X26 -> -106514 | Z26: =LEFT(A26,2) -> 31 | AD26: -93369 | AF26: 0 | AG26: 0 | AH26: 0 | AI26: 0 | AK26: -9443 | AL26: 0 | AM26: 0 | AN26: -9443 | AP26: -3702 | AQ26: 0 | AR26: 0 | AS26: -3702 | AT26: -106514 | AW26: -106514 | AY26: =F26-AD26 -> 0 | AZ26: =P26-AN26 -> 0 | BA26: =U26-AS26 -> 0 | BB26: =X26-AV26 -> 0
A27: 3200 | B27: In Process R&DS | C27: =SUMIF('TB Mitiga LTD'!A:A,'HARKAVA '!A27,'TB Mitiga LTD'!D:D) -> 0 | D27: =SUMIF('Adj Entries Ltd'!$B$4:$B$954,A27,'Adj Entries Ltd'!$D$4:$D$954) -> 0 | E27: =SUMIF('Adj Entries Ltd'!$B$4:$B$954,A27,'Adj Entries Ltd'!$E$4:$E$954) -> 0 | F27: =(+C27+D27-E27) -> 0 | H27: =SUMIF('TB US'!A:A,'HARKAVA '!A27,'TB US'!D:D) -> 0 | I27: =SUMIF('Adj. entries US'!B:B,'HARKAVA '!A27,'Adj. entries US'!D:D) -> 0 | J27: =SUMIF('Adj. entries US'!B:B,'HARKAVA '!A27,'Adj. entries US'!E:E) -> 0 | K27: =H27+I27-J27 -> 0 | M27: =SUMIF('TB UK'!A:A,'HARKAVA '!A27,'TB UK'!E:E) -> 0 | N27: =SUMIF('Adj. Entries UK'!B:B,'HARKAVA '!A27,'Adj. Entries UK'!D:D) -> 0 | O27: =SUMIF('Adj. Entries UK'!B:B,'HARKAVA '!A27,'Adj. Entries UK'!E:E) -> 0 | P27: =M27+N27-O27 -> 0 | R27: =SUMIF('TB security'!A:A,'HARKAVA '!A27,'TB security'!D:D) -> 0 | S27: =SUMIF('Adj. Entries security'!B:B,'HARKAVA '!A27,'Adj. Entries security'!D:D) -> 0 | T27: =SUMIF('Adj. Entries security'!B:B,'HARKAVA '!A27,'Adj. Entries security'!E:E) -> 0 | U27: =R27+S27-T27 -> 0 | V27: =P27+F27+U27+K27 -> 0 | Y27: =V27+X27 -> 0 | Z27: =LEFT(A27,2) -> 32 | AD27: 0 | AF27: 0 | AG27: 0 | AH27: 0 | AI27: 0 | AK27: 0 | AL27: 0 | AM27: 0 | AN27: 0 | AP27: 0 | AQ27: 0 | AR27: 0 | AS27: 0 | AT27: 0 | AW27: 0 | AY27: =F27-AD27 -> 0 | AZ27: =P27-AN27 -> 0 | BA27: =U27-AS27 -> 0 | BB27: =X27-AV27 -> 0
C28: =SUM(C6:C27) -> 5552403.7 | D28: =SUM(D6:D27) -> 3011383.2 | E28: =SUM(E6:E27) -> 11383.25 | F28: =SUM(F6:F27) -> 8552403.7 | H28: =SUM(H6:H27) -> 67042.28 | I28: =SUM(I6:I27) -> 0 | J28: =SUM(J6:J27) -> 0 | K28: =SUM(K6:K27) -> 67042.28 | M28: =SUM(M6:M27) -> 683194.86 | N28: =SUM(N6:N27) -> 0 | O28: =SUM(O6:O27) -> 0 | P28: =SUM(P6:P27) -> 683194.86 | R28: =SUM(R6:R27) -> 14917461 | S28: =SUM(S6:S27) -> 0 | T28: =SUM(T6:T27) -> 0 | U28: =SUM(U6:U27) -> 14917461 | V28: =SUM(V6:V27) -> 24220102 | X28: =SUM(X6:X27) -> -1020955.2 | Y28: =SUM(Y6:Y27) -> 23199147 | Z28: =LEFT(A28,2) | AD28: 8622653.7 | AF28: 67042.28 | AG28: 0 | AH28: 0 | AI28: 67042.28 | AK28: 683194.86 | AL28: 0 | AM28: 0 | AN28: 683194.86 | AP28: 14847211 | AQ28: 0 | AR28: 0 | AS28: 14847211 | AT28: 24220102 | AV28: -648038.19 | AW28: 23572064 | AY28: =F28-AD28 -> -70250 | AZ28: =P28-AN28 -> 0 | BA28: =U28-AS28 -> 70250 | BB28: =X28-AV28 -> -372917
AY29: =F29-AD29 -> 0 | AZ29: =P29-AN29 -> 0 | BA29: =U29-AS29 -> 0 | BB29: =X29-AV29 -> 0
AY30: =F30-AD30 -> 0 | AZ30: =P30-AN30 -> 0 | BA30: =U30-AS30 -> 0 | BB30: =X30-AV30 -> 0
Z31: =LEFT(A31,2) | AY31: =F31-AD31 -> 0 | AZ31: =P31-AN31 -> 0 | BA31: =U31-AS31 -> 0 | BB31: =X31-AV31 -> 0
A32: 3300 | B32: Short term bank credit | C32: =SUMIF('TB Mitiga LTD'!A:A,'HARKAVA '!A32,'TB Mitiga LTD'!D:D) -> 0 | D32: =SUMIF('Adj Entries Ltd'!$B$4:$B$954,A32,'Adj Entries Ltd'!$D$4:$D$954) -> 0 | E32: =SUMIF('Adj Entries Ltd'!$B$4:$B$954,A32,'Adj Entries Ltd'!$E$4:$E$954) -> 0 | F32: =(+C32+D32-E32) -> 0 | H32: =SUMIF('TB US'!A:A,'HARKAVA '!A32,'TB US'!D:D) -> 0 | I32: =SUMIF('Adj. entries US'!B:B,'HARKAVA '!A32,'Adj. entries US'!D:D) -> 0 | J32: =SUMIF('Adj. entries US'!B:B,'HARKAVA '!A32,'Adj. entries US'!E:E) -> 0 | K32: =H32+I32-J32 -> 0 | M32: =SUMIF('TB UK'!A:A,'HARKAVA '!A32,'TB UK'!E:E) -> 0 | N32: =SUMIF('Adj. Entries UK'!B:B,'HARKAVA '!A32,'Adj. Entries UK'!D:D) -> 0 | O32: =SUMIF('Adj. Entries UK'!B:B,'HARKAVA '!A32,'Adj. Entries UK'!E:E) -> 0 | P32: =M32+N32-O32 -> 0 | R32: =SUMIF('TB security'!A:A,'HARKAVA '!A32,'TB security'!D:D) -> 0 | S32: =SUMIF('Adj. Entries security'!B:B,'HARKAVA '!A32,'Adj. Entries security'!D:D) -> 0 | T32: =SUMIF('Adj. Entries security'!B:B,'HARKAVA '!A32,'Adj. Entries security'!E:E) -> 0 | U32: =R32+S32-T32 -> 0 | V32: =P32+F32+U32+K32 -> 0 | Y32: =V32+X32 -> 0 | Z32: 33 | AD32: 0 | AF32: 0 | AG32: 0 | AH32: 0 | AI32: 0 | AK32: 0 | AL32: 0 | AM32: 0 | AN32: 0 | AP32: 0 | AQ32: 0 | AR32: 0 | AS32: 0 | AT32: 0 | AW32: 0 | AY32: =F32-AD32 -> 0 | AZ32: =P32-AN32 -> 0 | BA32: =U32-AS32 -> 0 | BB32: =X32-AV32 -> 0
A33: 3400 | B33: Trade payables | C33: =SUMIF('TB Mitiga LTD'!A:A,'HARKAVA '!A33,'TB Mitiga LTD'!D:D) -> -552171.51 | D33: =SUMIF('Adj Entries Ltd'!$B$4:$B$954,A33,'Adj Entries Ltd'!$D$4:$D$954) -> 0 | E33: =SUMIF('Adj Entries Ltd'!$B$4:$B$954,A33,'Adj Entries Ltd'!$E$4:$E$954) -> 2081.9936 | F33: =(+C33+D33-E33) -> -554253.5 | H33: =SUMIF('TB US'!A:A,'HARKAVA '!A33,'TB US'!D:D) -> 0 | I33: =SUMIF('Adj. entries US'!B:B,'HARKAVA '!A33,'Adj. entries US'!D:D) -> 0 | J33: =SUMIF('Adj. entries US'!B:B,'HARKAVA '!A33,'Adj. entries US'!E:E) -> 0 | K33: =H33+I33-J33 -> 0 | M33: =SUMIF('TB UK'!A:A,'HARKAVA '!A33,'TB UK'!E:E) -> -2567.03 | N33: =SUMIF('Adj. Entries UK'!B:B,'HARKAVA '!A33,'Adj. Entries UK'!D:D) -> 0 | O33: =SUMIF('Adj. Entries UK'!B:B,'HARKAVA '!A33,'Adj. Entries UK'!E:E) -> 0 | P33: =M33+N33-O33 -> -2567.03 | R33: =SUMIF('TB security'!A:A,'HARKAVA '!A33,'TB security'!D:D) -> -115788.09 | S33: =SUMIF('Adj. Entries security'!B:B,'HARKAVA '!A33,'Adj. Entries security'!D:D) -> 0 | T33: =SUMIF('Adj. Entries security'!B:B,'HARKAVA '!A33,'Adj. Entries security'!E:E) -> 0 | U33: =R33+S33-T33 -> -115788.09 | V33: =P33+F33+U33+K33 -> -672608.62 | Y33: =V33+X33 -> -672608.62 | Z33: =LEFT(A33,2) -> 34 | AD33: -554253.5 | AF33: 0 | AG33: 0 | AH33: 0 | AI33: 0 | AK33: -2567.03 | AL33: 0 | AM33: 0 | AN33: -2567.03 | AP33: -115788.09 | AQ33: 0 | AR33: 0 | AS33: -115788.09 | AT33: -672608.62 | AW33: -672608.62 | AY33: =F33-AD33 -> 0 | AZ33: =P33-AN33 -> 0 | BA33: =U33-AS33 -> 0 | BB33: =X33-AV33 -> 0
A34: 3500 | B34: consolidated company | C34: =SUMIF('TB Mitiga LTD'!A:A,'HARKAVA '!A34,'TB Mitiga LTD'!D:D) -> -5950440.4 | D34: =SUMIF('Adj Entries Ltd'!$B$4:$B$954,A34,'Adj Entries Ltd'!$D$4:$D$954) -> 61840 | E34: =SUMIF('Adj Entries Ltd'!$B$4:$B$954,A34,'Adj Entries Ltd'!$E$4:$E$954) -> 5771962 | F34: =(+C34+D34-E34) -> -11660562 | H34: =SUMIF('TB US'!A:A,'HARKAVA '!A34,'TB US'!D:D) -> -2502.03 | I34: =SUMIF('Adj. entries US'!B:B,'HARKAVA '!A34,'Adj. entries US'!D:D) -> 0 | J34: =SUMIF('Adj. entries US'!B:B,'HARKAVA '!A34,'Adj. entries US'!E:E) -> 61840 | K34: =H34+I34-J34 -> -64342.03 | M34: =SUMIF('TB UK'!A:A,'HARKAVA '!A34,'TB UK'!E:E) -> -1602566.1 | N34: =SUMIF('Adj. Entries UK'!B:B,'HARKAVA '!A34,'Adj. Entries UK'!D:D) -> 1265642.5 | O34: =SUMIF('Adj. Entries UK'!B:B,'HARKAVA '!A34,'Adj. Entries UK'!E:E) -> 0 | P34: =M34+N34-O34 -> -336923.62 | R34: =SUMIF('TB security'!A:A,'HARKAVA '!A34,'TB security'!D:D) -> 9535002.3 | S34: =SUMIF('Adj. Entries security'!B:B,'HARKAVA '!A34,'Adj. Entries security'!D:D) -> 1877446 | T34: =SUMIF('Adj. Entries security'!B:B,'HARKAVA '!A34,'Adj. Entries security'!E:E) -> 414915 | U34: =R34+S34-T34 -> 10997533 | V34: =P34+F34+U34+K34 -> -1064294.7 | X34: =-V34 -> 1064294.7 | Y34: =V34+X34 -> 0 | Z34: 36 | AD34: -11546524 | AF34: -2502.03 | AG34: 0 | AH34: 61840 | AI34: -64342.03 | AK34: -1602566.1 | AL34: 1149913 | AM34: 0 | AN34: -452653.15 | AP34: 9535002.3 | AQ34: 1922926 | AR34: 414915 | AS34: 11043013 | AT34: -1020506.3 | AV34: 1020506.3 | AW34: 0 | AY34: =F34-AD34 -> -114038 | AZ34: =P34-AN34 -> 115729.52 | BA34: =U34-AS34 -> -45480 | BB34: =X34-AV34 -> 43788.475 | BC34: See TP wp
A35: 3600 | B35: AP-employees and emp. Instit. | C35: =SUMIF('TB Mitiga LTD'!A:A,'HARKAVA '!A35,'TB Mitiga LTD'!D:D) -> -1008607.2 | D35: =SUMIF('Adj Entries Ltd'!$B$4:$B$954,A35,'Adj Entries Ltd'!$D$4:$D$954) -> 0 | E35: =SUMIF('Adj Entries Ltd'!$B$4:$B$954,A35,'Adj Entries Ltd'!$E$4:$E$954) -> 0 | F35: =(+C35+D35-E35) -> -1008607.2 | H35: =SUMIF('TB US'!A:A,'HARKAVA '!A35,'TB US'!D:D) -> 0 | I35: =SUMIF('Adj. entries US'!B:B,'HARKAVA '!A35,'Adj. entries US'!D:D) -> 0 | J35: =SUMIF('Adj. entries US'!B:B,'HARKAVA '!A35,'Adj. entries US'!E:E) -> 0 | K35: =H35+I35-J35 -> 0 | M35: =SUMIF('TB UK'!A:A,'HARKAVA '!A35,'TB UK'!E:E) -> -233604.76 | N35: =SUMIF('Adj. Entries UK'!B:B,'HARKAVA '!A35,'Adj. Entries UK'!D:D) -> 0 | O35: =SUMIF('Adj. Entries UK'!B:B,'HARKAVA '!A35,'Adj. Entries UK'!E:E) -> 0 | P35: =M35+N35-O35 -> -233604.76 | R35: =SUMIF('TB security'!A:A,'HARKAVA '!A35,'TB security'!D:D) -> -287579 | S35: =SUMIF('Adj. Entries security'!B:B,'HARKAVA '!A35,'Adj. Entries security'!D:D) -> 0 | T35: =SUMIF('Adj. Entries security'!B:B,'HARKAVA '!A35,'Adj. Entries security'!E:E) -> 0 | U35: =R35+S35-T35 -> -287579 | V35: =P35+F35+U35+K35 -> -1529790.9 | Y35: =V35+X35 -> -1529790.9 | Z35: =LEFT(A35,2) -> 36 | AD35: -1008607.2 | AF35: 0 | AG35: 0 | AH35: 0 | AI35: 0 | AK35: -233604.76 | AL35: 0 | AM35: 0 | AN35: -233604.76 | AP35: -287579 | AQ35: 0 | AR35: 0 | AS35: -287579 | AT35: -1529790.9 | AW35: -1529790.9 | AY35: =F35-AD35 -> 0 | AZ35: =P35-AN35 -> 0 | BA35: =U35-AS35 -> 0 | BB35: =X35-AV35 -> 0
A36: 3650 | B36: AP- VAT | C36: =SUMIF('TB Mitiga LTD'!A:A,'HARKAVA '!A36,'TB Mitiga LTD'!D:D) -> 0 | D36: =SUMIF('Adj Entries Ltd'!$B$4:$B$954,A36,'Adj Entries Ltd'!$D$4:$D$954) -> 0 | E36: =SUMIF('Adj Entries Ltd'!$B$4:$B$954,A36,'Adj Entries Ltd'!$E$4:$E$954) -> 0 | F36: =(+C36+D36-E36) -> 0 | H36: =SUMIF('TB US'!A:A,'HARKAVA '!A36,'TB US'!D:D) -> 0 | I36: =SUMIF('Adj. entries US'!B:B,'HARKAVA '!A36,'Adj. entries US'!D:D) -> 0 | J36: =SUMIF('Adj. entries US'!B:B,'HARKAVA '!A36,'Adj. entries US'!E:E) -> 0 | K36: =H36+I36-J36 -> 0 | M36: =SUMIF('TB UK'!A:A,'HARKAVA '!A36,'TB UK'!E:E) -> -7196.95 | N36: =SUMIF('Adj. Entries UK'!B:B,'HARKAVA '!A36,'Adj. Entries UK'!D:D) -> 0 | O36: =SUMIF('Adj. Entries UK'!B:B,'HARKAVA '!A36,'Adj. Entries UK'!E:E) -> 0 | P36: =M36+N36-O36 -> -7196.95 | R36: =SUMIF('TB security'!A:A,'HARKAVA '!A36,'TB security'!D:D) -> 0 | S36: =SUMIF('Adj. Entries security'!B:B,'HARKAVA '!A36,'Adj. Entries security'!D:D) -> 0 | T36: =SUMIF('Adj. Entries security'!B:B,'HARKAVA '!A36,'Adj. Entries security'!E:E) -> 0 | U36: =R36+S36-T36 -> 0 | V36: =P36+F36+U36+K36 -> -7196.95 | Y36: =V36+X36 -> -7196.95 | Z36: 36 | AD36: 0 | AF36: 0 | AG36: 0 | AH36: 0 | AI36: 0 | AK36: -7196.95 | AL36: 0 | AM36: 0 | AN36: -7196.95 | AP36: 0 | AQ36: 0 | AR36: 0 | AS36: 0 | AT36: -7196.95 | AW36: -7196.95 | AY36: =F36-AD36 -> 0 | AZ36: =P36-AN36 -> 0 | BA36: =U36-AS36 -> 0 | BB36: =X36-AV36 -> 0
A37: 3800 | B37: Deferred income | C37: =SUMIF('TB Mitiga LTD'!A:A,'HARKAVA '!A37,'TB Mitiga LTD'!D:D) -> -53416 | D37: =SUMIF('Adj Entries Ltd'!$B$4:$B$954,A37,'Adj Entries Ltd'!$D$4:$D$954) -> 0 | E37: =SUMIF('Adj Entries Ltd'!$B$4:$B$954,A37,'Adj Entries Ltd'!$E$4:$E$954) -> 0 | F37: =(+C37+D37-E37) -> -53416 | H37: =SUMIF('TB US'!A:A,'HARKAVA '!A37,'TB US'!D:D) -> 0 | I37: =SUMIF('Adj. entries US'!B:B,'HARKAVA '!A37,'Adj. entries US'!D:D) -> 0 | J37: =SUMIF('Adj. entries US'!B:B,'HARKAVA '!A37,'Adj. entries US'!E:E) -> 0 | K37: =H37+I37-J37 -> 0 | M37: =SUMIF('TB UK'!A:A,'HARKAVA '!A37,'TB UK'!E:E) -> -123540 | N37: =SUMIF('Adj. Entries UK'!B:B,'HARKAVA '!A37,'Adj. Entries UK'!D:D) -> 0 | O37: =SUMIF('Adj. Entries UK'!B:B,'HARKAVA '!A37,'Adj. Entries UK'!E:E) -> 0 | P37: =M37+N37-O37 -> -123540 | R37: =SUMIF('TB security'!A:A,'HARKAVA '!A37,'TB security'!D:D) -> -376253 | S37: =SUMIF('Adj. Entries security'!B:B,'HARKAVA '!A37,'Adj. Entries security'!D:D) -> 0 | T37: =SUMIF('Adj. Entries security'!B:B,'HARKAVA '!A37,'Adj. Entries security'!E:E) -> 0 | U37: =R37+S37-T37 -> -376253 | V37: =P37+F37+U37+K37 -> -553209 | Y37: =V37+X37 -> -553209 | Z37: 38 | AD37: -53416 | AF37: 0 | AG37: 0 | AH37: 0 | AI37: 0 | AK37: 0 | AL37: 0 | AM37: 0 | AN37: 0 | AP37: -376253 | AQ37: 0 | AR37: 0 | AS37: -376253 | AT37: -429669 | AV37: -372917 | AW37: -802586 | AY37: =F37-AD37 -> 0 | AZ37: =P37-AN37 -> -123540 | BA37: =U37-AS37 -> 0 | BB37: =X37-AV37 -> 372917 | BC37: Pushed any GUS revenue that was recorded initially from April 2021 to March 2022
A38: 3900 | B38: Related parties | C38: =SUMIF('TB Mitiga LTD'!A:A,'HARKAVA '!A38,'TB Mitiga LTD'!D:D) -> 23616.2 | D38: =SUMIF('Adj Entries Ltd'!$B$4:$B$954,A38,'Adj Entries Ltd'!$D$4:$D$954) -> 0 | E38: =SUMIF('Adj Entries Ltd'!$B$4:$B$954,A38,'Adj Entries Ltd'!$E$4:$E$954) -> 25401.929 | F38: =(+C38+D38-E38) -> -1785.7293 | H38: =SUMIF('TB US'!A:A,'HARKAVA '!A38,'TB US'!D:D) -> 0 | I38: =SUMIF('Adj. entries US'!B:B,'HARKAVA '!A38,'Adj. entries US'!D:D) -> 0 | J38: =SUMIF('Adj. entries US'!B:B,'HARKAVA '!A38,'Adj. entries US'!E:E) -> 0 | K38: =H38+I38-J38 -> 0 | M38: =SUMIF('TB UK'!A:A,'HARKAVA '!A38,'TB UK'!E:E) -> -12422.61 | N38: =SUMIF('Adj. Entries UK'!B:B,'HARKAVA '!A38,'Adj. Entries UK'!D:D) -> 0 | O38: =SUMIF('Adj. Entries UK'!B:B,'HARKAVA '!A38,'Adj. Entries UK'!E:E) -> 0 | P38: =M38+N38-O38 -> -12422.61 | R38: =SUMIF('TB security'!A:A,'HARKAVA '!A38,'TB security'!D:D) -> 0 | S38: =SUMIF('Adj. Entries security'!B:B,'HARKAVA '!A38,'Adj. Entries security'!D:D) -> 0 | T38: =SUMIF('Adj. Entries security'!B:B,'HARKAVA '!A38,'Adj. Entries security'!E:E) -> 0 | U38: =R38+S38-T38 -> 0 | V38: =P38+F38+U38+K38 -> -14208.339 | Y38: =V38+X38 -> -14208.339 | Z38: 36 | AD38: -1785.7293 | AF38: 0 | AG38: 0 | AH38: 0 | AI38: 0 | AK38: -12422.61 | AL38: 0 | AM38: 0 | AN38: -12422.61 | AP38: 0 | AQ38: 0 | AR38: 0 | AS38: 0 | AT38: -14208.339 | AW38: -14208.339 | AY38: =F38-AD38 -> 0 | AZ38: =P38-AN38 -> 0 | BA38: =U38-AS38 -> 0 | BB38: =X38-AV38 -> 0
A39: 3910 | B39: Accrued expenses | C39: =SUMIF('TB Mitiga LTD'!A:A,'HARKAVA '!A39,'TB Mitiga LTD'!D:D) -> -148353.23 | D39: =SUMIF('Adj Entries Ltd'!$B$4:$B$954,A39,'Adj Entries Ltd'!$D$4:$D$954) -> 27483.923 | E39: =SUMIF('Adj Entries Ltd'!$B$4:$B$954,A39,'Adj Entries Ltd'!$E$4:$E$954) -> 0 | F39: =(+C39+D39-E39) -> -120869.31 | H39: =SUMIF('TB US'!A:A,'HARKAVA '!A39,'TB US'!D:D) -> 0 | I39: =SUMIF('Adj. entries US'!B:B,'HARKAVA '!A39,'Adj. entries US'!D:D) -> 0 | J39: =SUMIF('Adj. entries US'!B:B,'HARKAVA '!A39,'Adj. entries US'!E:E) -> 0 | K39: =H39+I39-J39 -> 0 | M39: =SUMIF('TB UK'!A:A,'HARKAVA '!A39,'TB UK'!E:E) -> -1935.99 | N39: =SUMIF('Adj. Entries UK'!B:B,'HARKAVA '!A39,'Adj. Entries UK'!D:D) -> 0 | O39: =SUMIF('Adj. Entries UK'!B:B,'HARKAVA '!A39,'Adj. Entries UK'!E:E) -> 0 | P39: =M39+N39-O39 -> -1935.99 | R39: =SUMIF('TB security'!A:A,'HARKAVA '!A39,'TB security'!D:D) -> -77992.19 | S39: =SUMIF('Adj. Entries security'!B:B,'HARKAVA '!A39,'Adj. Entries security'!D:D) -> 0 | T39: =SUMIF('Adj. Entries security'!B:B,'HARKAVA '!A39,'Adj. Entries security'!E:E) -> 0 | U39: =R39+S39-T39 -> -77992.19 | V39: =P39+F39+U39+K39 -> -200797.49 | Y39: =V39+X39 -> -200797.49 | Z39: 36 | AD39: -120869.31 | AF39: 0 | AG39: 0 | AH39: 0 | AI39: 0 | AK39: -1935.99 | AL39: 0 | AM39: 0 | AN39: -1935.99 | AP39: -52792.19 | AQ39: 0 | AR39: 0 | AS39: -52792.19 | AT39: -175597.49 | AW39: -175597.49 | AY39: =F39-AD39 -> 0 | AZ39: =P39-AN39 -> 0 | BA39: =U39-AS39 -> -25200 | BB39: =X39-AV39 -> 0 | BC39: Accrual recorded for 2021 Delaware franchise tax that was paid in March 2022
A40: 3915 | B40: Leasehold liablities - short term | C40: =SUMIF('TB Mitiga LTD'!A:A,'HARKAVA '!A40,'TB Mitiga LTD'!D:D) -> 0 | D40: =SUMIF('Adj Entries Ltd'!$B$4:$B$954,A40,'Adj Entries Ltd'!$D$4:$D$954) -> 0 | E40: =SUMIF('Adj Entries Ltd'!$B$4:$B$954,A40,'Adj Entries Ltd'!$E$4:$E$954) -> 0 | F40: =(+C40+D40-E40) -> 0 | H40: =SUMIF('TB US'!A:A,'HARKAVA '!A40,'TB US'!D:D) -> 0 | I40: =SUMIF('Adj. entries US'!B:B,'HARKAVA '!A40,'Adj. entries US'!D:D) -> 0 | J40: =SUMIF('Adj. entries US'!B:B,'HARKAVA '!A40,'Adj. entries US'!E:E) -> 0 | K40: =H40+I40-J40 -> 0 | M40: =SUMIF('TB UK'!A:A,'HARKAVA '!A40,'TB UK'!E:E) -> 0 | N40: =SUMIF('Adj. Entries UK'!B:B,'HARKAVA '!A40,'Adj. Entries UK'!D:D) -> 0 | O40: =SUMIF('Adj. Entries UK'!B:B,'HARKAVA '!A40,'Adj. Entries UK'!E:E) -> 0 | P40: =M40+N40-O40 -> 0 | R40: =SUMIF('TB security'!A:A,'HARKAVA '!A40,'TB security'!D:D) -> 0 | S40: =SUMIF('Adj. Entries security'!B:B,'HARKAVA '!A40,'Adj. Entries security'!D:D) -> 0 | T40: =SUMIF('Adj. Entries security'!B:B,'HARKAVA '!A40,'Adj. Entries security'!E:E) -> 0 | U40: =R40+S40-T40 -> 0 | V40: =P40+F40+U40+K40 -> 0 | Y40: =V40+X40 -> 0 | Z40: 40 | AD40: 0 | AF40: 0 | AG40: 0 | AH40: 0 | AI40: 0 | AK40: 0 | AL40: 0 | AM40: 0 | AN40: 0 | AP40: 0 | AQ40: 0 | AR40: 0 | AS40: 0 | AT40: 0 | AW40: 0 | AY40: =F40-AD40 -> 0 | AZ40: =P40-AN40 -> 0 | BA40: =U40-AS40 -> 0 | BB40: =X40-AV40 -> 0
...

Sheet intercompany
B1: Security | C1: Ltd. | D1: UK | E1: USA
A2: Security | C2: 200000 | E2: 600 | F2: =SUM(B2:E2) -> 200600
A3: Ltd. | B3: -200000 | D3: =-113464-506459 -> -619923 | E3: -5000 | F3: =SUM(B3:E3) -> -824923
A4: UK | C4: =113464+506459 -> 619923 | E4: -2502.03 | F4: =SUM(B4:E4) -> 617420.97
A5: USA | B5: -600 | C5: 5000 | D5: 2502 | F5: =SUM(B5:E5) -> 6902
B6: =SUM(B2:B5) -> -200600 | C6: =SUM(C2:C5) -> 824923 | D6: =SUM(D2:D5) -> -617421 | E6: =SUM(E2:E5) -> -6902.03 | F6: =SUM(F2:F5) -> -0.03
A13: TP
B15: Security | C15: Ltd. | D15: USA | E15: UK | H15: =1050905 -> 1050905
A16: Security | C16: -323155 | E16: 346161 | F16: 23006 | H16: 669316
A17: Ltd. | B17: 323155 | D17: -36948 | E17: -344641 | F17: -58434 | H17: =H15-H16 -> 381589
A18: USA | C18: 36948 | F18: 36948
A19: UK | B19: -346161 | C19: 344641 | F19: -1520
B20: -23006 | C20: 58434 | D20: -36948 | E20: 1520 | F20: 0

Sheet budget
I2: 2021
I3: Q1 | M3: Q2
I4: Jan | J4: Feb | K4: Mar | L4: Q1 | M4: Apr | N4: May | O4: Jun | P4: Q2 | Q4: Jul | R4: Aug | S4: Sep | T4: Q3 | U4: code | V4: Oct | W4: Nov | X4: Dec | Y4: Q4 total
B5: Role/Function | C5: Name/Vendor | D5: Salary | E5: Cost | F5: Bonus | G5: Comment
B7: Head count | I7: =I182+I135+I26 -> 18.8 | J7: =J182+J135+J26 -> 20.8 | K7: =K182+K135+K26 -> 21.8 | M7: =M182+M135+M26 -> 25.8 | N7: =N182+N135+N26 -> 26.8 | O7: =O182+O135+O26 -> 29.8 | R7: 45.8 | S7: 46.8 | V7: 53.8 | W7: 53.8 | X7: 53.8
B9: Founders, Management & General
B10: Founders
A11: * | B11: CEO | C11: Tal Mozes | D11: 185000 | E11: =D11*[4]Assumptions!B15*[4]Assumptions!B13/12 -> 26979.167 | F11: 100K | I11: 23664.773 | J11: 23664.773 | K11: 23664.773 | L11: =SUM(I11:K11) -> 70994.318 | M11: 23664.773 | N11: 23664.773 | O11: 23664.773 | P11: =SUM(M11:O11) -> 70994.318 | Q11: 26979.167 | R11: 26979.167 | S11: 26979.167 | T11: =SUM(Q11:S11) -> 80937.5 | U11: 5600 | V11: 26979.167 | W11: 26979.167 | X11: 126979.17 | Y11: =+SUM(V11:X11) -> 180937.5
A12: * | B12: Chief Delivery Officer | C12: Ariel Parnes | D12: 280000 | E12: =D12*[4]Assumptions!B14/12 -> 28000 | F12: 100K | G12: 50% G&A (50% Delivery) | I12: =19727.2727272727*0.5 -> 9863.6364 | J12: =I12 -> 9863.6364 | K12: =J12 -> 9863.6364 | L12: =SUM(I12:K12) -> 29590.909 | M12: =K12 -> 9863.6364 | N12: =M12 -> 9863.6364 | O12: =N12 -> 9863.6364 | P12: =SUM(M12:O12) -> 29590.909 | Q12: 14000 | R12: 14000 | S12: 14000 | T12: =SUM(Q12:S12) -> 42000 | U12: 5600 | V12: 14000 | W12: 14000 | X12: 64000 | Y12: =+SUM(V12:X12) -> 92000
A13: * | B13: CTO | C13: Ofer Maor | D13: 55000 | E13: =D13*[4]Assumptions!B11/[4]Assumptions!B12 -> 21666.667 | F13: 100K | G13: 20% G&A (80% R&D) | I13: =I12*2*0.2 -> 3945.4545 | J13: =I13 -> 3945.4545 | K13: =J13 -> 3945.4545 | L13: =SUM(I13:K13) -> 11836.364 | M13: =K13 -> 3945.4545 | N13: =M13 -> 3945.4545 | O13: =N13 -> 3945.4545 | P13: =SUM(M13:O13) -> 11836.364 | Q13: 4333.3333 | R13: 4333.3333 | S13: 4333.3333 | T13: =SUM(Q13:S13) -> 13000 | U13: 5600 | V13: 4333.3333 | W13: 4333.3333 | X13: 24333.333 | Y13: =+SUM(V13:X13) -> 33000
A14: * | B14: CFO | D14: 225000 | E14: =D14*[4]Assumptions!B14/12 -> 22500 | F14: 0.15 | I14: 0 | J14: =I14 -> 0 | K14: =J14 -> 0 | L14: =SUM(I14:K14) -> 0 | M14: =K14 -> 0 | N14: =M14 -> 0 | O14: =275*19 -> 5225 | P14: =SUM(M14:O14) -> 5225 | Q14: 27500 | R14: 27500 | S14: 27500 | T14: =SUM(Q14:S14) -> 82500 | U14: 5610 | V14: 27500 | W14: 27500 | X14: 27500 | Y14: =+SUM(V14:X14) -> 82500
B15: VP HR | C15: TBD | D15: 50000 | E15: =D15*[4]Assumptions!B11/[4]Assumptions!B12 -> 19696.97 | F15: 0.1 | I15: =15000*[4]Assumptions!$B$11/[4]Assumptions!$B$12 -> 5909.0909 | J15: =21000*[4]Assumptions!$B$11/[4]Assumptions!$B$12 -> 8272.7273 | K15: =J15 -> 8272.7273 | L15: =SUM(I15:K15) -> 22454.545 | M15: =K15 -> 8272.7273 | N15: =M15 -> 8272.7273 | O15: =N15 -> 8272.7273 | P15: =SUM(M15:O15) -> 24818.182 | Q15: 19696.97 | R15: 19696.97 | S15: 19696.97 | T15: =SUM(Q15:S15) -> 59090.909 | U15: 5600 | V15: 19696.97 | W15: 19696.97 | X15: 36242.424 | Y15: =+SUM(V15:X15) -> 75636.364
B16: Director Operations | C16: TBD | D16: 175000 | E16: =D16*[4]Assumptions!B14/12 -> 17500 | F16: 0.1 | L16: =SUM(I16:K16) -> 0 | P16: =SUM(M16:O16) -> 0
L17: =SUM(I17:K17) -> 0 | P17: =SUM(M17:O17) -> 0
B18: Other G&A Staff | L18: =SUM(I18:K18) -> 0 | P18: =SUM(M18:O18) -> 0
A19: * | B19: Operation/Finance Staff | C19: Noa | E19: 7500 | F19: 0.15 | I19: 6204.5455 | J19: 6204.5455 | K19: 6204.5455 | L19: =SUM(I19:K19) -> 18613.636 | M19: 6204.5455 | N19: =M19 -> 6204.5455 | O19: =N19 -> 6204.5455 | P19: =SUM(M19:O19) -> 18613.636 | Q19: 7500 | R19: 7500 | S19: 7500 | T19: =SUM(Q19:S19) -> 22500 | U19: 5600 | V19: 7500 | W19: 7500 | X19: 19834.091 | Y19: =+SUM(V19:X19) -> 34834.091
Q20: 1 | R20: 1 | V20: 1 | W20: 1 | X20: 1
A21: * | B21: Admins | C21: Eden | E21: 6000 | I21: 0 | J21: =I21 -> 0 | K21: =J21 -> 0 | L21: =SUM(I21:K21) -> 0 | M21: =K21 -> 0 | N21: 1970 | O21: 1970 | P21: =SUM(M21:O21) -> 3940 | Q21: 6000 | R21: 6000 | S21: 6000 | T21: =SUM(Q21:S21) -> 18000 | U21: 5600 | V21: 6000 | W21: 6000 | X21: 6000 | Y21: =+SUM(V21:X21) -> 18000
L22: =SUM(I22:K22) -> 0 | Q22: 1 | R22: 1 | V22: 1 | W22: 1 | X22: 1
B23: Recruiters/HR Staff | C23: Shiran | E23: 10000 | L23: =SUM(I23:K23) -> 0 | O23: 7879 | P23: =SUM(M23:O23) -> 7879 | Q23: 20000 | R23: 20000 | S23: 20000 | T23: =SUM(Q23:S23) -> 60000 | U23: 5600 | V23: 20000 | W23: 20000 | X23: 20000 | Y23: =+SUM(V23:X23) -> 60000
Q24: 2 | R24: 2 | V24: 2 | W24: 2 | X24: 2
P25: =SUM(M25:O25) -> 0
B26: ------------------------------------- | C26: ------------------------- | D26: -------------- | G26: Employee Count | I26: =COUNTIF(I11:I19,">0")+I22+I24 -> 5 | J26: =COUNTIF(J11:J19,">0")+J22+J24 -> 5 | K26: =COUNTIF(K11:K19,">0")+K22+K24 -> 5 | M26: =COUNTIF(M11:M19,">0")+M22+M24 -> 5 | N26: =COUNTIF(N11:N19,">0")+N22+N24 -> 5 | O26: =COUNTIF(O11:O19,">0")+O22+O24 -> 6 | Q26: 9 | R26: 9 | V26: 9 | W26: 9 | X26: 9
G27: Subtotal FMG Salaries | I27: =SUBTOTAL(9,I11:I19)+I21+I23 -> 49587.5 | J27: =SUBTOTAL(9,J11:J19)+J21+J23 -> 51951.136 | K27: =SUBTOTAL(9,K11:K19)+K21+K23 -> 51951.136 | L27: =SUBTOTAL(9,L11:L19)+L21+L23 -> 153489.77 | M27: =SUBTOTAL(9,M11:M19)+M21+M23 -> 51951.136 | N27: =SUBTOTAL(9,N11:N19)+N21+N23 -> 53921.136 | O27: =SUBTOTAL(9,O11:O19)+O21+O23 -> 67025.136 | P27: =SUBTOTAL(9,P11:P19)+P21+P23 -> 172897.41 | ... T27: =SUBTOTAL(9,T11:T19)+T21+T23 -> 378028.41 | V27: 126009.47 | W27: 126009.47 | X27: 324889.02 | Y27: =SUBTOTAL(9,Y11:Y19)+Y21+Y23 -> 576907.95
B28: Expenses | L28: =SUM(I28:K28) -> 0
B29: IT (Laptop, Phone, etc.) | C29: Dell/Apple | E29: 150 | G29: Monthly per Employee | I29: =$E$29*I26 -> 750 | J29: =$E$29*J26 -> 750 | K29: =$E$29*K26 -> 750 | L29: =SUM(I29:K29) -> 2250 | M29: =$E$29*M26 -> 750 | N29: 825 | O29: 1125 | P29: =SUM(M29:O29) -> 2700 | Q29: 1350 | R29: 1350 | S29: 1350 | T29: =SUM(Q29:S29) -> 4050 | U29: 5660 | V29: 1350 | W29: 1350 | X29: 1350 | Y29: =SUM(V29:X29) -> 4050
B30: Welfare (10Bis, Misc.) | E30: 500 | G30: Monthly per Employee | I30: =$E$30*I26 -> 2500 | J30: =$E$30*J26 -> 2500 | K30: =$E$30*K26 -> 2500 | L30: =SUM(I30:K30) -> 7500 | M30: =$E$30*M26 -> 2500 | N30: 2750 | O30: 3750 | P30: =SUM(M30:O30) -> 9000 | Q30: 4500 | R30: 4500 | S30: 4500 | T30: =SUM(Q30:S30) -> 13500 | U30: 5660 | V30: 4500 | W30: 4500 | X30: 4500 | Y30: =SUM(V30:X30) -> 13500
B31: Licensing, Phone Plans, etc. | C31: 150$/Month/Employee | E31: 150 | G31: Monthly per Employee | I31: =I26*$E31 -> 750 | J31: =J26*$E31 -> 750 | K31: =K26*$E31 -> 750 | L31: =SUM(I31:K31) -> 2250 | M31: =M26*$E31 -> 750 | N31: 825 | O31: 1125 | P31: =SUM(M31:O31) -> 2700 | Q31: 1350 | R31: 1350 | S31: 1350 | T31: =SUM(Q31:S31) -> 4050 | U31: 5660 | V31: 1350 | W31: 1350 | X31: 1350 | Y31: =SUM(V31:X31) -> 4050
B32: ------------------------------------- | C32: ------------------------- | D32: -------------- | L32: =SUM(I32:K32) -> 0 | P32: =SUM(M32:O32) -> 0
B33: Offices, Israel | C33: BE ALL | G33: Inc. all (Parking, cleaning, etc). | I33: 16000 | J33: 16000 | K33: 16000 | L33: =SUM(I33:K33) -> 48000 | M33: 17500 | N33: 17500 | O33: 17500 | P33: =SUM(M33:O33) -> 52500 | Q33: 20000 | R33: 20000 | S33: 20000 | T33: =SUM(Q33:S33) -> 60000 | U33: 5620 | V33: 25000 | W33: 25000 | X33: 25000 | Y33: =SUM(V33:X33) -> 75000
B34: Relocation expenses - Ariel | K34: =70000/7 -> 10000 | L34: =SUM(I34:K34) -> 10000 | M34: =70000/7 -> 10000 | N34: =70000/7 -> 10000 | O34: =70000/7 -> 10000 | P34: =SUM(M34:O34) -> 30000 | Q34: 10000 | R34: 10000 | S34: 10000 | T34: =SUM(Q34:S34) -> 30000 | U34: 5660 | V34: 10000 | W34: 10000 | X34: 10000 | Y34: =SUM(V34:X34) -> 30000
B35: Relocation professional advise | L35: =SUM(I35:K35) -> 0 | P35: =SUM(M35:O35) -> 0
B36: Ofice Expenses, Israel | I36: 0 | J36: 0 | K36: 0 | L36: =SUM(I36:K36) -> 0 | M36: 0 | N36: 0 | O36: 0 | P36: =SUM(M36:O36) -> 0 | Q36: 0 | R36: 0 | S36: 0 | T36: =SUM(Q36:S36) -> 0 | Y36: =SUM(V36:X36) -> 0
B37: Offices, UK | G37: Inc. all (Parking, cleaning, etc). | I37: 2500 | J37: 2500 | K37: 2500 | L37: =SUM(I37:K37) -> 7500 | M37: 2500 | N37: 2500 | O37: 2500 | P37: =SUM(M37:O37) -> 7500 | Q37: 2500 | R37: 2500 | S37: 2500 | T37: =SUM(Q37:S37) -> 7500 | U37: 5620 | V37: 2500 | W37: 2500 | X37: 2500 | Y37: =SUM(V37:X37) -> 7500
B38: Offices, US | G38: Inc. all (Parking, cleaning, etc). | I38: 3000 | J38: 3000 | K38: 3000 | L38: =SUM(I38:K38) -> 9000 | M38: 3000 | N38: 3000 | O38: 3000 | P38: =SUM(M38:O38) -> 9000 | Q38: 10000 | R38: 10000 | S38: 10000 | T38: =SUM(Q38:S38) -> 30000 | U38: 5620 | V38: 10000 | W38: 10000 | X38: 10000 | Y38: =SUM(V38:X38) -> 30000
B39: Travel (Non Sales/Billable) | I39: 0 | J39: 0 | K39: 0 | L39: =SUM(I39:K39) -> 0 | M39: =10000/3 -> 3333.3333 | N39: =10000/3 -> 3333.3333 | O39: =10000/3 -> 3333.3333 | P39: =SUM(M39:O39) -> 10000 | Q39: 5000 | R39: 5000 | S39: 5000 | T39: =SUM(Q39:S39) -> 15000 | U39: 5680 | V39: 8333.3333 | W39: 8333.3333 | X39: 8333.3333 | Y39: =SUM(V39:X39) -> 25000
B40: IT retainer | L40: =SUM(I40:K40) -> 0 | P40: =SUM(M40:O40) -> 0 | S40: 0
